{
    "registryname": "aesir_resonator",
    "localizedname": "Aesir Resonator",
	"color": "76c1d6",
    "parts": [
        {
            "x": 1,
            "y": 1,
            "z": 3,
            "elements": [
                "botania:livingrock@1"
            ]
        },
        {
            "x": -1,
            "y": 5,
            "z": 1,
            "elements": [
                "divinerpg:arcanium_block@0"
            ]
        },
        {
            "x": -1,
            "y": 4,
            "z": -1,
            "elements": [
                "botania:elfglass@0"
            ]
        },
        {
            "x": -3,
            "y": 0,
            "z": 1,
            "elements": [
                "botania:livingrock@1"
            ]
        },
        {
            "x": 0,
            "y": 5,
            "z": 2,
            "elements": [
                "unlimitedchiselworks:chisel_stonebrick2_botania_livingrock_1@3"
            ]
        },
        {
            "x": 2,
            "y": 7,
            "z": -1,
            "elements": [
                "botania:elfglass@0"
            ]
        },
        {
            "x": 0,
            "y": 6,
            "z": 2,
            "elements": [
                "unlimitedchiselworks:chisel_stonebrick2_botania_livingrock_1@6"
            ]
        },
        {
            "x": 1,
            "y": 2,
            "z": -3,
            "elements": [
                "contenttweaker:gaia_spirit_block@0"
            ]
        },
        {
            "x": 2,
            "y": 7,
            "z": 1,
            "elements": [
                "botania:elfglass@0"
            ]
        },
        {
            "x": 2,
            "y": 6,
            "z": -1,
            "elements": [
                "unlimitedchiselworks:chisel_stonebrick2_botania_livingrock_1@3"
            ]
        },
        {
            "x": 2,
            "y": 0,
            "z": -1,
            "elements": [
                "botania:livingrock1stairs@0"
            ]
        },
        {
            "x": -1,
            "y": 5,
            "z": -1,
            "elements": [
                "divinerpg:arcanium_block@0"
            ]
        },
        {
            "x": 0,
            "y": -1,
            "z": 0,
            "elements": [
                "unlimitedchiselworks:chisel_stonebrick1_botania_livingrock_1@0"
            ]
        },
        {
            "x": 1,
            "y": 1,
            "z": -3,
            "elements": [
                "botania:livingrock@1"
            ]
        },
        {
            "x": 1,
            "y": 7,
            "z": -2,
            "elements": [
                "botania:elfglass@0"
            ]
        },
        {
            "x": -3,
            "y": 2,
            "z": -1,
            "elements": [
                "contenttweaker:gaia_spirit_block@0"
            ]
        },
        {
            "x": -3,
            "y": -1,
            "z": 1,
            "elements": [
                "unlimitedchiselworks:chisel_stonebrick1_botania_livingrock_1@0"
            ]
        },
        {
            "x": 1,
            "y": 8,
            "z": -1,
            "elements": [
                "botania:elfglass@0"
            ]
        },
        {
            "x": -1,
            "y": 4,
            "z": 1,
            "elements": [
                "botania:elfglass@0"
            ]
        },
        {
            "x": -3,
            "y": -1,
            "z": -2,
            "elements": [
                "unlimitedchiselworks:chisel_stonebrick1_botania_livingrock_1@0"
            ]
        },
        {
            "x": -3,
            "y": 1,
            "z": 1,
            "elements": [
                "botania:livingrock@1"
            ]
        },
        {
            "x": 2,
            "y": 6,
            "z": 1,
            "elements": [
                "unlimitedchiselworks:chisel_stonebrick2_botania_livingrock_1@3"
            ]
        },
        {
            "x": 0,
            "y": 7,
            "z": 2,
            "elements": [
                "unlimitedchiselworks:chisel_stonebrick2_botania_livingrock_1@3"
            ]
        },
        {
            "x": 0,
            "y": 6,
            "z": -2,
            "elements": [
                "unlimitedchiselworks:chisel_stonebrick2_botania_livingrock_1@6"
            ]
        },
        {
            "x": -3,
            "y": 1,
            "z": -1,
            "elements": [
                "botania:livingrock@1"
            ]
        },
        {
            "x": -1,
            "y": 0,
            "z": -3,
            "elements": [
                "botania:livingrock@1"
            ]
        },
        {
            "x": -1,
            "y": 6,
            "z": -1,
            "elements": [
                "divinerpg:arcanium_block@0"
            ]
        },
        {
            "x": 3,
            "y": -1,
            "z": 2,
            "elements": [
                "unlimitedchiselworks:chisel_stonebrick1_botania_livingrock_1@0"
            ]
        },
        {
            "x": -1,
            "y": 4,
            "z": 0,
            "elements": [
                "unlimitedchiselworks:chisel_stonebrick2_botania_livingrock_1@3"
            ]
        },
        {
            "x": -1,
            "y": 6,
            "z": 2,
            "elements": [
                "unlimitedchiselworks:chisel_stonebrick2_botania_livingrock_1@3"
            ]
        },
        {
            "x": 0,
            "y": -1,
            "z": 3,
            "elements": [
                "unlimitedchiselworks:chisel_stonebrick1_botania_livingrock_1@0"
            ]
        },
        {
            "x": 2,
            "y": 5,
            "z": 1,
            "elements": [
                "botania:elfglass@0"
            ]
        },
        {
            "x": -3,
            "y": 2,
            "z": 1,
            "elements": [
                "contenttweaker:gaia_spirit_block@0"
            ]
        },
        {
            "x": -1,
            "y": 7,
            "z": 1,
            "elements": [
                "divinerpg:arcanium_block@0"
            ]
        },
        {
            "x": -1,
            "y": -1,
            "z": -1,
            "elements": [
                "botania:livingrock@1"
            ]
        },
        {
            "x": 1,
            "y": -1,
            "z": 0,
            "elements": [
                "unlimitedchiselworks:chisel_stonebrick1_botania_livingrock_1@0"
            ]
        },
        {
            "x": 1,
            "y": 5,
            "z": -2,
            "elements": [
                "botania:elfglass@0"
            ]
        },
        {
            "x": 0,
            "y": 7,
            "z": -2,
            "elements": [
                "unlimitedchiselworks:chisel_stonebrick2_botania_livingrock_1@3"
            ]
        },
        {
            "x": 1,
            "y": 0,
            "z": 3,
            "elements": [
                "botania:livingrock@1"
            ]
        },
        {
            "x": -2,
            "y": -1,
            "z": -3,
            "elements": [
                "unlimitedchiselworks:chisel_stonebrick1_botania_livingrock_1@0"
            ]
        },
        {
            "x": -1,
            "y": 7,
            "z": 2,
            "elements": [
                "botania:elfglass@0"
            ]
        },
        {
            "x": -1,
            "y": 7,
            "z": -1,
            "elements": [
                "divinerpg:arcanium_block@0"
            ]
        },
        {
            "x": 2,
            "y": 5,
            "z": -1,
            "elements": [
                "botania:elfglass@0"
            ]
        },
        {
            "x": -1,
            "y": 6,
            "z": 1,
            "elements": [
                "divinerpg:arcanium_block@0"
            ]
        },
        {
            "x": 2,
            "y": -1,
            "z": 1,
            "elements": [
                "modularmachineryaddons:blockmeessentiainputbus@0"
            ]
        },
        {
            "x": -3,
            "y": 0,
            "z": -1,
            "elements": [
                "botania:livingrock@1"
            ]
        },
        {
            "x": 0,
            "y": -1,
            "z": -1,
            "elements": [
                "unlimitedchiselworks:chisel_stonebrick1_botania_livingrock_1@0"
            ]
        },
        {
            "x": -1,
            "y": 6,
            "z": -2,
            "elements": [
                "unlimitedchiselworks:chisel_stonebrick2_botania_livingrock_1@3"
            ]
        },
        {
            "x": -2,
            "y": 7,
            "z": 0,
            "elements": [
                "unlimitedchiselworks:chisel_stonebrick2_botania_livingrock_1@3"
            ]
        },
        {
            "x": 1,
            "y": -1,
            "z": 3,
            "elements": [
                "unlimitedchiselworks:chisel_stonebrick1_botania_livingrock_1@0"
            ]
        },
        {
            "x": 2,
            "y": -1,
            "z": 2,
            "elements": [
                "unlimitedchiselworks:chisel_stonebrick1_botania_livingrock_1@0"
            ]
        },
        {
            "x": -1,
            "y": 5,
            "z": -2,
            "elements": [
                "botania:elfglass@0"
            ]
        },
        {
            "x": -2,
            "y": -1,
            "z": 0,
            "elements": [
                "unlimitedchiselworks:chisel_stonebrick1_botania_livingrock_1@0"
            ]
        },
        {
            "x": -1,
            "y": -1,
            "z": 1,
            "elements": [
                "botania:livingrock@1"
            ]
        },
        {
            "x": -1,
            "y": 7,
            "z": -2,
            "elements": [
                "botania:elfglass@0"
            ]
        },
        {
            "x": -1,
            "y": -1,
            "z": -2,
            "elements": [
                "modularmachinery:blockoutputbus@0"
            ]
        },
        {
            "x": 2,
            "y": -1,
            "z": -2,
            "elements": [
                "unlimitedchiselworks:chisel_stonebrick1_botania_livingrock_1@0"
            ]
        },
        {
            "x": -2,
            "y": 0,
            "z": 1,
            "elements": [
                "botania:livingrock1stairs@1"
            ]
        },
        {
            "x": 1,
            "y": -1,
            "z": -1,
            "elements": [
                "botania:livingrock@1"
            ]
        },
        {
            "x": 1,
            "y": 8,
            "z": 1,
            "elements": [
                "botania:elfglass@0"
            ]
        },
        {
            "x": -1,
            "y": 5,
            "z": 2,
            "elements": [
                "botania:elfglass@0"
            ]
        },
        {
            "x": 2,
            "y": -1,
            "z": 3,
            "elements": [
                "unlimitedchiselworks:chisel_stonebrick1_botania_livingrock_1@0"
            ]
        },
        {
            "x": 1,
            "y": 4,
            "z": 0,
            "elements": [
                "unlimitedchiselworks:chisel_stonebrick2_botania_livingrock_1@3"
            ]
        },
        {
            "x": 1,
            "y": 2,
            "z": 3,
            "elements": [
                "contenttweaker:gaia_spirit_block@0"
            ]
        },
        {
            "x": -2,
            "y": 6,
            "z": 0,
            "elements": [
                "unlimitedchiselworks:chisel_stonebrick2_botania_livingrock_1@6"
            ]
        },
        {
            "x": 0,
            "y": -1,
            "z": 1,
            "elements": [
                "unlimitedchiselworks:chisel_stonebrick1_botania_livingrock_1@0"
            ]
        },
        {
            "x": -3,
            "y": -1,
            "z": 2,
            "elements": [
                "unlimitedchiselworks:chisel_stonebrick1_botania_livingrock_1@0"
            ]
        },
        {
            "x": -2,
            "y": 5,
            "z": 0,
            "elements": [
                "unlimitedchiselworks:chisel_stonebrick2_botania_livingrock_1@3"
            ]
        },
        {
            "x": 1,
            "y": -1,
            "z": -2,
            "elements": [
                "modularmachinery:blockoutputbus@0"
            ]
        },
        {
            "x": 0,
            "y": 7,
            "z": 0,
            "elements": [
                "divinerpg:arcanium_block@0"
            ]
        },
        {
            "x": -2,
            "y": 6,
            "z": -1,
            "elements": [
                "unlimitedchiselworks:chisel_stonebrick2_botania_livingrock_1@3"
            ]
        },
        {
            "x": -1,
            "y": -1,
            "z": 3,
            "elements": [
                "unlimitedchiselworks:chisel_stonebrick1_botania_livingrock_1@0"
            ]
        },
        {
            "x": 1,
            "y": 6,
            "z": 0,
            "elements": [
                "divinerpg:arcanium_block@0"
            ]
        },
        {
            "x": -2,
            "y": 0,
            "z": -1,
            "elements": [
                "botania:livingrock1stairs@1"
            ]
        },
        {
            "x": 3,
            "y": -1,
            "z": 0,
            "elements": [
                "unlimitedchiselworks:chisel_stonebrick1_botania_livingrock_1@0"
            ]
        },
        {
            "x": -2,
            "y": 7,
            "z": 1,
            "elements": [
                "botania:elfglass@0"
            ]
        },
        {
            "x": -2,
            "y": -1,
            "z": -1,
            "elements": [
                "modularmachineryaddons:blockmeessentiainputbus@0"
            ]
        },
        {
            "x": -2,
            "y": 6,
            "z": 1,
            "elements": [
                "unlimitedchiselworks:chisel_stonebrick2_botania_livingrock_1@3"
            ]
        },
        {
            "x": -1,
            "y": 0,
            "z": -2,
            "elements": [
                "botania:livingrock1stairs@3"
            ]
        },
        {
            "x": 1,
            "y": -1,
            "z": 1,
            "elements": [
                "botania:livingrock@1"
            ]
        },
        {
            "x": 0,
            "y": -1,
            "z": 2,
            "elements": [
                "unlimitedchiselworks:chisel_stonebrick1_botania_livingrock_1@0"
            ]
        },
        {
            "x": 0,
            "y": 8,
            "z": 0,
            "elements": [
                "unlimitedchiselworks:chisel_stonebrick2_botania_livingrock_1@6"
            ]
        },
        {
            "x": -1,
            "y": -1,
            "z": -3,
            "elements": [
                "unlimitedchiselworks:chisel_stonebrick1_botania_livingrock_1@0"
            ]
        },
        {
            "x": -2,
            "y": 7,
            "z": -1,
            "elements": [
                "botania:elfglass@0"
            ]
        },
        {
            "x": 1,
            "y": 5,
            "z": 0,
            "elements": [
                "divinerpg:arcanium_block@0"
            ]
        },
        {
            "x": -2,
            "y": 5,
            "z": 1,
            "elements": [
                "botania:elfglass@0"
            ]
        },
        {
            "x": 3,
            "y": -1,
            "z": -1,
            "elements": [
                "unlimitedchiselworks:chisel_stonebrick1_botania_livingrock_1@0"
            ]
        },
        {
            "x": 1,
            "y": 7,
            "z": 0,
            "elements": [
                "divinerpg:arcanium_block@0"
            ]
        },
        {
            "x": -2,
            "y": 5,
            "z": -1,
            "elements": [
                "botania:elfglass@0"
            ]
        },
        {
            "x": 0,
            "y": 6,
            "z": 0,
            "elements": [
                "contenttweaker:asgard_furnace_brick@0"
            ]
        },
        {
            "x": -2,
            "y": -1,
            "z": 1,
            "elements": [
                "modularmachineryaddons:blockmeessentiainputbus@0"
            ]
        },
        {
            "x": -1,
            "y": -1,
            "z": 2,
            "elements": [
                "modularmachinery:blockinputbus@0"
            ]
        },
        {
            "x": -3,
            "y": -1,
            "z": 0,
            "elements": [
                "unlimitedchiselworks:chisel_stonebrick1_botania_livingrock_1@0"
            ]
        },
        {
            "x": 1,
            "y": 8,
            "z": 0,
            "elements": [
                "unlimitedchiselworks:chisel_stonebrick2_botania_livingrock_1@3"
            ]
        },
        {
            "x": 0,
            "y": 8,
            "z": -1,
            "elements": [
                "unlimitedchiselworks:chisel_stonebrick2_botania_livingrock_1@3"
            ]
        },
        {
            "x": 0,
            "y": 8,
            "z": 1,
            "elements": [
                "unlimitedchiselworks:chisel_stonebrick2_botania_livingrock_1@3"
            ]
        },
        {
            "x": 2,
            "y": -1,
            "z": -3,
            "elements": [
                "unlimitedchiselworks:chisel_stonebrick1_botania_livingrock_1@0"
            ]
        },
        {
            "x": -1,
            "y": 0,
            "z": 2,
            "elements": [
                "botania:livingrock1stairs@2"
            ]
        },
        {
            "x": 0,
            "y": -1,
            "z": -2,
            "elements": [
                "unlimitedchiselworks:chisel_stonebrick1_botania_livingrock_1@0"
            ]
        },
        {
            "x": 0,
            "y": 5,
            "z": 0,
            "elements": [
                "divinerpg:arcanium_block@0"
            ]
        },
        {
            "x": 1,
            "y": 4,
            "z": -1,
            "elements": [
                "botania:elfglass@0"
            ]
        },
        {
            "x": 3,
            "y": -1,
            "z": -2,
            "elements": [
                "unlimitedchiselworks:chisel_stonebrick1_botania_livingrock_1@0"
            ]
        },
        {
            "x": 1,
            "y": 5,
            "z": 1,
            "elements": [
                "divinerpg:arcanium_block@0"
            ]
        },
        {
            "x": -1,
            "y": 2,
            "z": -3,
            "elements": [
                "contenttweaker:gaia_spirit_block@0"
            ]
        },
        {
            "x": -1,
            "y": 1,
            "z": 3,
            "elements": [
                "botania:livingrock@1"
            ]
        },
        {
            "x": 2,
            "y": 7,
            "z": 0,
            "elements": [
                "unlimitedchiselworks:chisel_stonebrick2_botania_livingrock_1@3"
            ]
        },
        {
            "x": 0,
            "y": 7,
            "z": 1,
            "elements": [
                "divinerpg:arcanium_block@0"
            ]
        },
        {
            "x": 0,
            "y": 4,
            "z": 0,
            "elements": [
                "unlimitedchiselworks:chisel_stonebrick2_botania_livingrock_1@6"
            ]
        },
        {
            "x": 3,
            "y": 0,
            "z": 1,
            "elements": [
                "botania:livingrock@1"
            ]
        },
        {
            "x": 0,
            "y": 6,
            "z": -1,
            "elements": [
                "divinerpg:arcanium_block@0"
            ]
        },
        {
            "x": -2,
            "y": -1,
            "z": 2,
            "elements": [
                "unlimitedchiselworks:chisel_stonebrick1_botania_livingrock_1@0"
            ]
        },
        {
            "x": -1,
            "y": 6,
            "z": 0,
            "elements": [
                "divinerpg:arcanium_block@0"
            ]
        },
        {
            "x": 1,
            "y": 4,
            "z": 1,
            "elements": [
                "botania:elfglass@0"
            ]
        },
        {
            "x": 1,
            "y": 0,
            "z": -2,
            "elements": [
                "botania:livingrock1stairs@3"
            ]
        },
        {
            "x": -1,
            "y": 2,
            "z": 3,
            "elements": [
                "contenttweaker:gaia_spirit_block@0"
            ]
        },
        {
            "x": -1,
            "y": 5,
            "z": 0,
            "elements": [
                "divinerpg:arcanium_block@0"
            ]
        },
        {
            "x": 1,
            "y": -1,
            "z": -3,
            "elements": [
                "unlimitedchiselworks:chisel_stonebrick1_botania_livingrock_1@0"
            ]
        },
        {
            "x": 3,
            "y": 1,
            "z": 1,
            "elements": [
                "botania:livingrock@1"
            ]
        },
        {
            "x": -1,
            "y": 8,
            "z": -1,
            "elements": [
                "botania:elfglass@0"
            ]
        },
        {
            "x": 3,
            "y": 1,
            "z": -1,
            "elements": [
                "botania:livingrock@1"
            ]
        },
        {
            "x": 0,
            "y": 7,
            "z": -1,
            "elements": [
                "divinerpg:arcanium_block@0"
            ]
        },
        {
            "x": 1,
            "y": 5,
            "z": 2,
            "elements": [
                "botania:elfglass@0"
            ]
        },
        {
            "x": -1,
            "y": 8,
            "z": 1,
            "elements": [
                "botania:elfglass@0"
            ]
        },
        {
            "x": -1,
            "y": 1,
            "z": -3,
            "elements": [
                "botania:livingrock@1"
            ]
        },
        {
            "x": 0,
            "y": 6,
            "z": 1,
            "elements": [
                "divinerpg:arcanium_block@0"
            ]
        },
        {
            "x": 1,
            "y": 5,
            "z": -1,
            "elements": [
                "divinerpg:arcanium_block@0"
            ]
        },
        {
            "x": 3,
            "y": -1,
            "z": 1,
            "elements": [
                "unlimitedchiselworks:chisel_stonebrick1_botania_livingrock_1@0"
            ]
        },
        {
            "x": -1,
            "y": 7,
            "z": 0,
            "elements": [
                "divinerpg:arcanium_block@0"
            ]
        },
        {
            "x": 2,
            "y": 5,
            "z": 0,
            "elements": [
                "unlimitedchiselworks:chisel_stonebrick2_botania_livingrock_1@3"
            ]
        },
        {
            "x": 0,
            "y": 5,
            "z": 1,
            "elements": [
                "divinerpg:arcanium_block@0"
            ]
        },
        {
            "x": 0,
            "y": 4,
            "z": -1,
            "elements": [
                "unlimitedchiselworks:chisel_stonebrick2_botania_livingrock_1@3"
            ]
        },
        {
            "x": 1,
            "y": 6,
            "z": -1,
            "elements": [
                "divinerpg:arcanium_block@0"
            ]
        },
        {
            "x": 0,
            "y": 5,
            "z": -2,
            "elements": [
                "unlimitedchiselworks:chisel_stonebrick2_botania_livingrock_1@3"
            ]
        },
        {
            "x": 1,
            "y": 0,
            "z": -3,
            "elements": [
                "botania:livingrock@1"
            ]
        },
        {
            "x": 1,
            "y": 7,
            "z": 1,
            "elements": [
                "divinerpg:arcanium_block@0"
            ]
        },
        {
            "x": -2,
            "y": -1,
            "z": 3,
            "elements": [
                "unlimitedchiselworks:chisel_stonebrick1_botania_livingrock_1@0"
            ]
        },
        {
            "x": 1,
            "y": 6,
            "z": 2,
            "elements": [
                "unlimitedchiselworks:chisel_stonebrick2_botania_livingrock_1@3"
            ]
        },
        {
            "x": 2,
            "y": 0,
            "z": 1,
            "elements": [
                "botania:livingrock1stairs@0"
            ]
        },
        {
            "x": 3,
            "y": 2,
            "z": -1,
            "elements": [
                "contenttweaker:gaia_spirit_block@0"
            ]
        },
        {
            "x": 1,
            "y": -1,
            "z": 2,
            "elements": [
                "modularmachinery:blockinputbus@0"
            ]
        },
        {
            "x": -3,
            "y": -1,
            "z": -1,
            "elements": [
                "unlimitedchiselworks:chisel_stonebrick1_botania_livingrock_1@0"
            ]
        },
        {
            "x": 2,
            "y": -1,
            "z": 0,
            "elements": [
                "unlimitedchiselworks:chisel_stonebrick1_botania_livingrock_1@0"
            ]
        },
        {
            "x": 3,
            "y": 2,
            "z": 1,
            "elements": [
                "contenttweaker:gaia_spirit_block@0"
            ]
        },
        {
            "x": 3,
            "y": 0,
            "z": -1,
            "elements": [
                "botania:livingrock@1"
            ]
        },
        {
            "x": -1,
            "y": -1,
            "z": 0,
            "elements": [
                "unlimitedchiselworks:chisel_stonebrick1_botania_livingrock_1@0"
            ]
        },
        {
            "x": 2,
            "y": 6,
            "z": 0,
            "elements": [
                "unlimitedchiselworks:chisel_stonebrick2_botania_livingrock_1@6"
            ]
        },
        {
            "x": -1,
            "y": 0,
            "z": 3,
            "elements": [
                "botania:livingrock@1"
            ]
        },
        {
            "x": 0,
            "y": -1,
            "z": -3,
            "elements": [
                "unlimitedchiselworks:chisel_stonebrick1_botania_livingrock_1@0"
            ]
        },
        {
            "x": 0,
            "y": 4,
            "z": 1,
            "elements": [
                "unlimitedchiselworks:chisel_stonebrick2_botania_livingrock_1@3"
            ]
        },
        {
            "x": -1,
            "y": 8,
            "z": 0,
            "elements": [
                "unlimitedchiselworks:chisel_stonebrick2_botania_livingrock_1@3"
            ]
        },
        {
            "x": 1,
            "y": 7,
            "z": -1,
            "elements": [
                "divinerpg:arcanium_block@0"
            ]
        },
        {
            "x": 2,
            "y": -1,
            "z": -1,
            "elements": [
                "modularmachineryaddons:blockmeessentiainputbus@0"
            ]
        },
        {
            "x": 1,
            "y": 6,
            "z": 1,
            "elements": [
                "divinerpg:arcanium_block@0"
            ]
        },
        {
            "x": -2,
            "y": -1,
            "z": -2,
            "elements": [
                "unlimitedchiselworks:chisel_stonebrick1_botania_livingrock_1@0"
            ]
        },
        {
            "x": 1,
            "y": 0,
            "z": 2,
            "elements": [
                "botania:livingrock1stairs@2"
            ]
        },
        {
            "x": 1,
            "y": 7,
            "z": 2,
            "elements": [
                "botania:elfglass@0"
            ]
        },
        {
            "x": 0,
            "y": 5,
            "z": -1,
            "elements": [
                "divinerpg:arcanium_block@0"
            ]
        },
        {
            "x": 1,
            "y": 6,
            "z": -2,
            "elements": [
                "unlimitedchiselworks:chisel_stonebrick2_botania_livingrock_1@3"
            ]
        }
    ]}