{
    "registryname": "altar_to_the_name_of_names",
    "localizedname": "Altar to the Name of Names",
	"color": "695000",
    "parts": [
        {
            "x": -14,
            "y": 3,
            "z": -13,
            "elements": [
                "railcraft:sandy@1"
            ]
        },
        {
            "x": -14,
            "y": 3,
            "z": -14,
            "elements": [
                "railcraft:sandy@1"
            ]
        },
        {
            "x": -14,
            "y": 3,
            "z": -11,
            "elements": [
                "railcraft:sandy@1"
            ]
        },
        {
            "x": -14,
            "y": 3,
            "z": -12,
            "elements": [
                "railcraft:sandy@1"
            ]
        },
        {
            "x": -14,
            "y": 3,
            "z": -9,
            "elements": [
                "railcraft:sandy@1"
            ]
        },
        {
            "x": -14,
            "y": 3,
            "z": -10,
            "elements": [
                "railcraft:sandy@1"
            ]
        },
        {
            "x": -14,
            "y": 3,
            "z": -7,
            "elements": [
                "railcraft:sandy@1"
            ]
        },
        {
            "x": -14,
            "y": 3,
            "z": -8,
            "elements": [
                "railcraft:sandy@1"
            ]
        },
        {
            "x": -14,
            "y": 3,
            "z": -21,
            "elements": [
                "railcraft:sandy@1"
            ]
        },
        {
            "x": -14,
            "y": 3,
            "z": -22,
            "elements": [
                "railcraft:sandy@1"
            ]
        },
        {
            "x": -14,
            "y": 3,
            "z": -19,
            "elements": [
                "railcraft:sandy@1"
            ]
        },
        {
            "x": -14,
            "y": 3,
            "z": -20,
            "elements": [
                "railcraft:sandy@1"
            ]
        },
        {
            "x": -14,
            "y": 3,
            "z": -17,
            "elements": [
                "railcraft:sandy@1"
            ]
        },
        {
            "x": -14,
            "y": 3,
            "z": -18,
            "elements": [
                "railcraft:sandy@1"
            ]
        },
        {
            "x": -14,
            "y": 3,
            "z": -15,
            "elements": [
                "railcraft:sandy@1"
            ]
        },
        {
            "x": -14,
            "y": 3,
            "z": -16,
            "elements": [
                "railcraft:sandy@1"
            ]
        },
        {
            "x": -14,
            "y": 3,
            "z": -23,
            "elements": [
                "railcraft:sandy@1"
            ]
        },
        {
            "x": -14,
            "y": 3,
            "z": -24,
            "elements": [
                "chisel:sandstoneyellow1@7"
            ]
        },
        {
            "x": -14,
            "y": 3,
            "z": 3,
            "elements": [
                "railcraft:sandy@1"
            ]
        },
        {
            "x": -14,
            "y": 3,
            "z": 2,
            "elements": [
                "railcraft:sandy@1"
            ]
        },
        {
            "x": -14,
            "y": 3,
            "z": 5,
            "elements": [
                "railcraft:sandy@1"
            ]
        },
        {
            "x": -14,
            "y": 3,
            "z": 4,
            "elements": [
                "railcraft:sandy@1"
            ]
        },
        {
            "x": -14,
            "y": 3,
            "z": 6,
            "elements": [
                "chisel:sandstoneyellow1@7"
            ]
        },
        {
            "x": -14,
            "y": 3,
            "z": -5,
            "elements": [
                "railcraft:sandy@1"
            ]
        },
        {
            "x": -14,
            "y": 3,
            "z": -6,
            "elements": [
                "railcraft:sandy@1"
            ]
        },
        {
            "x": -14,
            "y": 3,
            "z": -3,
            "elements": [
                "railcraft:sandy@1"
            ]
        },
        {
            "x": -14,
            "y": 3,
            "z": -4,
            "elements": [
                "railcraft:sandy@1"
            ]
        },
        {
            "x": -14,
            "y": 3,
            "z": -1,
            "elements": [
                "railcraft:sandy@1"
            ]
        },
        {
            "x": -14,
            "y": 3,
            "z": -2,
            "elements": [
                "railcraft:sandy@1"
            ]
        },
        {
            "x": -14,
            "y": 3,
            "z": 1,
            "elements": [
                "railcraft:sandy@1"
            ]
        },
        {
            "x": -14,
            "y": 3,
            "z": 0,
            "elements": [
                "railcraft:sandy@1"
            ]
        },
        {
            "x": -9,
            "y": 10,
            "z": -5,
            "elements": [
                "enderio:block_alloy@6"
            ]
        },
        {
            "x": -9,
            "y": 10,
            "z": -4,
            "elements": [
                "aether_legacy:angelic_wall@0"
            ]
        },
        {
            "x": -9,
            "y": 10,
            "z": -3,
            "elements": [
                "railcraft:sandy@1"
            ]
        },
        {
            "x": -9,
            "y": 10,
            "z": -18,
            "elements": [
                "railcraft:sandy@1"
            ]
        },
        {
            "x": -9,
            "y": 10,
            "z": -17,
            "elements": [
                "aether_legacy:angelic_wall@0"
            ]
        },
        {
            "x": -9,
            "y": 10,
            "z": -16,
            "elements": [
                "enderio:block_alloy@6"
            ]
        },
        {
            "x": 5,
            "y": -1,
            "z": 5,
            "elements": [
                "railcraft:sandy@1"
            ]
        },
        {
            "x": 5,
            "y": -1,
            "z": 6,
            "elements": [
                "aether_legacy:angelic_wall@0"
            ]
        },
        {
            "x": 11,
            "y": 9,
            "z": -19,
            "elements": [
                "minecraft:stone_slab@9"
            ]
        },
        {
            "x": 11,
            "y": 9,
            "z": -18,
            "elements": [
                "railcraft:sandy@1"
            ]
        },
        {
            "x": 11,
            "y": 9,
            "z": -21,
            "elements": [
                "aether_legacy:angelic_wall@0"
            ]
        },
        {
            "x": 11,
            "y": 9,
            "z": -20,
            "elements": [
                "railcraft:sandy@1"
            ]
        },
        {
            "x": -9,
            "y": 10,
            "z": -2,
            "elements": [
                "minecraft:stone_slab@9"
            ]
        },
        {
            "x": -9,
            "y": 10,
            "z": -1,
            "elements": [
                "railcraft:sandy@1"
            ]
        },
        {
            "x": -9,
            "y": 10,
            "z": 0,
            "elements": [
                "aether_legacy:angelic_wall@0"
            ]
        },
        {
            "x": 11,
            "y": 9,
            "z": -17,
            "elements": [
                "aether_legacy:angelic_wall@0"
            ]
        },
        {
            "x": -9,
            "y": 10,
            "z": 1,
            "elements": [
                "enderio:block_alloy@6"
            ]
        },
        {
            "x": 11,
            "y": 9,
            "z": -3,
            "elements": [
                "railcraft:sandy@1"
            ]
        },
        {
            "x": -5,
            "y": 14,
            "z": -15,
            "elements": [
                "botania:livingrock0stairs@1"
            ]
        },
        {
            "x": 11,
            "y": 9,
            "z": -2,
            "elements": [
                "minecraft:stone_slab@9"
            ]
        },
        {
            "x": -5,
            "y": 14,
            "z": -18,
            "elements": [
                "chisel:concrete_brown@1"
            ]
        },
        {
            "x": -5,
            "y": 14,
            "z": -17,
            "elements": [
                "contenttweaker:abyssal_flesh@0"
            ]
        },
        {
            "x": 11,
            "y": 9,
            "z": -4,
            "elements": [
                "aether_legacy:angelic_wall@0"
            ]
        },
        {
            "x": 11,
            "y": 9,
            "z": -1,
            "elements": [
                "railcraft:sandy@1"
            ]
        },
        {
            "x": 11,
            "y": 9,
            "z": 0,
            "elements": [
                "aether_legacy:angelic_wall@0"
            ]
        },
        {
            "x": -9,
            "y": 10,
            "z": -22,
            "elements": [
                "enderio:block_alloy@6"
            ]
        },
        {
            "x": -5,
            "y": 14,
            "z": -7,
            "elements": [
                "contenttweaker:abyssal_flesh@0"
            ]
        },
        {
            "x": -9,
            "y": 10,
            "z": -21,
            "elements": [
                "aether_legacy:angelic_wall@0"
            ]
        },
        {
            "x": -9,
            "y": 10,
            "z": -20,
            "elements": [
                "railcraft:sandy@1"
            ]
        },
        {
            "x": -9,
            "y": 10,
            "z": -19,
            "elements": [
                "minecraft:stone_slab@9"
            ]
        },
        {
            "x": -5,
            "y": 14,
            "z": -9,
            "elements": [
                "botania:livingrock0stairs@1"
            ]
        },
        {
            "x": 5,
            "y": -1,
            "z": -23,
            "elements": [
                "railcraft:sandy@1"
            ]
        },
        {
            "x": -2,
            "y": 44,
            "z": -13,
            "elements": [
                "minecraft:stained_glass@3"
            ]
        },
        {
            "x": -5,
            "y": 14,
            "z": -6,
            "elements": [
                "chisel:concrete_brown@1"
            ]
        },
        {
            "x": 5,
            "y": -1,
            "z": -24,
            "elements": [
                "aether_legacy:angelic_wall@0"
            ]
        },
        {
            "x": -2,
            "y": 44,
            "z": -11,
            "elements": [
                "minecraft:stained_glass@3"
            ]
        },
        {
            "x": -13,
            "y": 6,
            "z": -20,
            "elements": [
                "enderio:block_alloy@6"
            ]
        },
        {
            "x": -13,
            "y": 6,
            "z": -19,
            "elements": [
                "enderio:block_alloy@6"
            ]
        },
        {
            "x": -13,
            "y": 6,
            "z": -22,
            "elements": [
                "enderio:block_alloy@6"
            ]
        },
        {
            "x": -13,
            "y": 6,
            "z": -21,
            "elements": [
                "enderio:block_alloy@6"
            ]
        },
        {
            "x": -13,
            "y": 6,
            "z": -16,
            "elements": [
                "enderio:block_alloy@6"
            ]
        },
        {
            "x": -13,
            "y": 6,
            "z": -18,
            "elements": [
                "enderio:block_alloy@6"
            ]
        },
        {
            "x": -13,
            "y": 6,
            "z": -17,
            "elements": [
                "enderio:block_alloy@6"
            ]
        },
        {
            "x": -12,
            "y": 30,
            "z": -19,
            "elements": [
                "biomesoplenty:flesh@0"
            ]
        },
        {
            "x": -12,
            "y": 30,
            "z": -18,
            "elements": [
                "biomesoplenty:flesh@0"
            ]
        },
        {
            "x": -12,
            "y": 30,
            "z": -17,
            "elements": [
                "contenttweaker:abyssal_flesh@0"
            ]
        },
        {
            "x": -12,
            "y": 30,
            "z": -16,
            "elements": [
                "chisel:concrete_brown@1"
            ]
        },
        {
            "x": -12,
            "y": 30,
            "z": -22,
            "elements": [
                "chisel:concrete_brown@1"
            ]
        },
        {
            "x": -12,
            "y": 30,
            "z": -21,
            "elements": [
                "contenttweaker:abyssal_flesh@0"
            ]
        },
        {
            "x": -12,
            "y": 30,
            "z": -20,
            "elements": [
                "biomesoplenty:flesh@0"
            ]
        },
        {
            "x": -12,
            "y": 30,
            "z": 1,
            "elements": [
                "chisel:concrete_brown@1"
            ]
        },
        {
            "x": -13,
            "y": 6,
            "z": -4,
            "elements": [
                "enderio:block_alloy@6"
            ]
        },
        {
            "x": -13,
            "y": 6,
            "z": -3,
            "elements": [
                "enderio:block_alloy@6"
            ]
        },
        {
            "x": -13,
            "y": 6,
            "z": -5,
            "elements": [
                "enderio:block_alloy@6"
            ]
        },
        {
            "x": -12,
            "y": 30,
            "z": -3,
            "elements": [
                "biomesoplenty:flesh@0"
            ]
        },
        {
            "x": -12,
            "y": 30,
            "z": -2,
            "elements": [
                "biomesoplenty:flesh@0"
            ]
        },
        {
            "x": -12,
            "y": 30,
            "z": -1,
            "elements": [
                "biomesoplenty:flesh@0"
            ]
        },
        {
            "x": -12,
            "y": 30,
            "z": 0,
            "elements": [
                "contenttweaker:abyssal_flesh@0"
            ]
        },
        {
            "x": -12,
            "y": 30,
            "z": -5,
            "elements": [
                "chisel:concrete_brown@1"
            ]
        },
        {
            "x": -12,
            "y": 30,
            "z": -4,
            "elements": [
                "contenttweaker:abyssal_flesh@0"
            ]
        },
        {
            "x": -13,
            "y": 6,
            "z": 0,
            "elements": [
                "enderio:block_alloy@6"
            ]
        },
        {
            "x": -13,
            "y": 6,
            "z": 1,
            "elements": [
                "enderio:block_alloy@6"
            ]
        },
        {
            "x": -13,
            "y": 6,
            "z": -2,
            "elements": [
                "enderio:block_alloy@6"
            ]
        },
        {
            "x": -13,
            "y": 6,
            "z": -1,
            "elements": [
                "enderio:block_alloy@6"
            ]
        },
        {
            "x": -10,
            "y": 7,
            "z": 1,
            "elements": [
                "enderio:block_alloy@6"
            ]
        },
        {
            "x": -10,
            "y": 7,
            "z": -1,
            "elements": [
                "minecraft:stone_slab@9"
            ]
        },
        {
            "x": -10,
            "y": 7,
            "z": -2,
            "elements": [
                "divinerpg:blaze_lamp@0"
            ]
        },
        {
            "x": -10,
            "y": 7,
            "z": -3,
            "elements": [
                "minecraft:stone_slab@9"
            ]
        },
        {
            "x": -10,
            "y": 7,
            "z": -5,
            "elements": [
                "enderio:block_alloy@6"
            ]
        },
        {
            "x": -14,
            "y": 32,
            "z": -5,
            "elements": [
                "enderio:block_alloy@7"
            ]
        },
        {
            "x": -14,
            "y": 32,
            "z": -4,
            "elements": [
                "enderio:block_alloy@7"
            ]
        },
        {
            "x": 6,
            "y": 2,
            "z": 6,
            "elements": [
                "minecraft:sandstone_stairs@7"
            ]
        },
        {
            "x": 6,
            "y": 2,
            "z": 5,
            "elements": [
                "minecraft:stone_slab@1"
            ]
        },
        {
            "x": 6,
            "y": 2,
            "z": 4,
            "elements": [
                "divinerpg:blaze_lamp@0"
            ]
        },
        {
            "x": -14,
            "y": 32,
            "z": 0,
            "elements": [
                "enderio:block_alloy@7"
            ]
        },
        {
            "x": -14,
            "y": 32,
            "z": 1,
            "elements": [
                "enderio:block_alloy@7"
            ]
        },
        {
            "x": -14,
            "y": 32,
            "z": -22,
            "elements": [
                "enderio:block_alloy@7"
            ]
        },
        {
            "x": -14,
            "y": 32,
            "z": -21,
            "elements": [
                "enderio:block_alloy@7"
            ]
        },
        {
            "x": -5,
            "y": 43,
            "z": -13,
            "elements": [
                "enderio:block_alloy@7"
            ]
        },
        {
            "x": -5,
            "y": 43,
            "z": -12,
            "elements": [
                "enderio:block_alloy@7"
            ]
        },
        {
            "x": -14,
            "y": 32,
            "z": -17,
            "elements": [
                "enderio:block_alloy@7"
            ]
        },
        {
            "x": -14,
            "y": 32,
            "z": -16,
            "elements": [
                "enderio:block_alloy@7"
            ]
        },
        {
            "x": 12,
            "y": 12,
            "z": -21,
            "elements": [
                "chisel:sandstoneyellow2@4"
            ]
        },
        {
            "x": 12,
            "y": 12,
            "z": -20,
            "elements": [
                "aether_legacy:angelic_wall@0"
            ]
        },
        {
            "x": -5,
            "y": 43,
            "z": -11,
            "elements": [
                "enderio:block_alloy@7"
            ]
        },
        {
            "x": 12,
            "y": 12,
            "z": -18,
            "elements": [
                "aether_legacy:angelic_wall@0"
            ]
        },
        {
            "x": 12,
            "y": 12,
            "z": -17,
            "elements": [
                "chisel:sandstoneyellow2@4"
            ]
        },
        {
            "x": 6,
            "y": 2,
            "z": -22,
            "elements": [
                "divinerpg:blaze_lamp@0"
            ]
        },
        {
            "x": 6,
            "y": 2,
            "z": -23,
            "elements": [
                "minecraft:stone_slab@1"
            ]
        },
        {
            "x": 6,
            "y": 2,
            "z": -24,
            "elements": [
                "minecraft:sandstone_stairs@6"
            ]
        },
        {
            "x": -4,
            "y": 17,
            "z": -19,
            "elements": [
                "enderio:block_alloy@7"
            ]
        },
        {
            "x": 12,
            "y": 12,
            "z": -4,
            "elements": [
                "chisel:sandstoneyellow2@4"
            ]
        },
        {
            "x": -4,
            "y": 17,
            "z": -17,
            "elements": [
                "botania:livingrock0stairs@1"
            ]
        },
        {
            "x": 12,
            "y": 12,
            "z": -3,
            "elements": [
                "aether_legacy:angelic_wall@0"
            ]
        },
        {
            "x": 12,
            "y": 12,
            "z": -1,
            "elements": [
                "aether_legacy:angelic_wall@0"
            ]
        },
        {
            "x": 12,
            "y": 12,
            "z": 0,
            "elements": [
                "chisel:sandstoneyellow2@4"
            ]
        },
        {
            "x": -10,
            "y": 7,
            "z": -16,
            "elements": [
                "enderio:block_alloy@6"
            ]
        },
        {
            "x": -3,
            "y": 41,
            "z": -11,
            "elements": [
                "minecraft:stained_glass@3"
            ]
        },
        {
            "x": -10,
            "y": 7,
            "z": -18,
            "elements": [
                "minecraft:stone_slab@9"
            ]
        },
        {
            "x": -3,
            "y": 41,
            "z": -13,
            "elements": [
                "minecraft:stained_glass@3"
            ]
        },
        {
            "x": -10,
            "y": 7,
            "z": -19,
            "elements": [
                "divinerpg:blaze_lamp@0"
            ]
        },
        {
            "x": -10,
            "y": 7,
            "z": -20,
            "elements": [
                "minecraft:stone_slab@9"
            ]
        },
        {
            "x": -10,
            "y": 7,
            "z": -22,
            "elements": [
                "enderio:block_alloy@6"
            ]
        },
        {
            "x": -4,
            "y": 17,
            "z": -7,
            "elements": [
                "botania:livingrock0stairs@1"
            ]
        },
        {
            "x": -4,
            "y": 17,
            "z": -5,
            "elements": [
                "enderio:block_alloy@7"
            ]
        },
        {
            "x": 1,
            "y": 45,
            "z": -11,
            "elements": [
                "minecraft:stained_glass@3"
            ]
        },
        {
            "x": 1,
            "y": 45,
            "z": -13,
            "elements": [
                "minecraft:stained_glass@3"
            ]
        },
        {
            "x": 3,
            "y": 1,
            "z": 1,
            "elements": [
                "railcraft:sandy@1"
            ]
        },
        {
            "x": 3,
            "y": 1,
            "z": 2,
            "elements": [
                "railcraft:sandy@1"
            ]
        },
        {
            "x": -12,
            "y": 9,
            "z": -20,
            "elements": [
                "aether_legacy:angelic_wall@0"
            ]
        },
        {
            "x": -12,
            "y": 9,
            "z": -21,
            "elements": [
                "chisel:sandstoneyellow2@4"
            ]
        },
        {
            "x": 3,
            "y": 1,
            "z": 0,
            "elements": [
                "chisel:sandstoneyellow2@4"
            ]
        },
        {
            "x": -12,
            "y": 9,
            "z": -17,
            "elements": [
                "chisel:sandstoneyellow2@4"
            ]
        },
        {
            "x": -12,
            "y": 9,
            "z": -18,
            "elements": [
                "aether_legacy:angelic_wall@0"
            ]
        },
        {
            "x": 3,
            "y": 1,
            "z": -23,
            "elements": [
                "railcraft:sandy@1"
            ]
        },
        {
            "x": 3,
            "y": 1,
            "z": -24,
            "elements": [
                "chisel:sandstoneyellow2@4"
            ]
        },
        {
            "x": 6,
            "y": 31,
            "z": -17,
            "elements": [
                "enderio:block_alloy@7"
            ]
        },
        {
            "x": 6,
            "y": 31,
            "z": -18,
            "elements": [
                "enderio:block_alloy@7"
            ]
        },
        {
            "x": 6,
            "y": 31,
            "z": -20,
            "elements": [
                "enderio:block_alloy@7"
            ]
        },
        {
            "x": 6,
            "y": 31,
            "z": -21,
            "elements": [
                "enderio:block_alloy@7"
            ]
        },
        {
            "x": 6,
            "y": 31,
            "z": 0,
            "elements": [
                "enderio:block_alloy@7"
            ]
        },
        {
            "x": 6,
            "y": 31,
            "z": -1,
            "elements": [
                "enderio:block_alloy@7"
            ]
        },
        {
            "x": 3,
            "y": 1,
            "z": 5,
            "elements": [
                "railcraft:sandy@1"
            ]
        },
        {
            "x": 6,
            "y": 31,
            "z": -3,
            "elements": [
                "enderio:block_alloy@7"
            ]
        },
        {
            "x": 6,
            "y": 31,
            "z": -4,
            "elements": [
                "enderio:block_alloy@7"
            ]
        },
        {
            "x": 3,
            "y": 1,
            "z": 6,
            "elements": [
                "chisel:sandstoneyellow2@4"
            ]
        },
        {
            "x": 3,
            "y": 1,
            "z": 3,
            "elements": [
                "railcraft:sandy@1"
            ]
        },
        {
            "x": 3,
            "y": 1,
            "z": 4,
            "elements": [
                "railcraft:sandy@1"
            ]
        },
        {
            "x": -12,
            "y": 9,
            "z": -3,
            "elements": [
                "aether_legacy:angelic_wall@0"
            ]
        },
        {
            "x": -12,
            "y": 9,
            "z": -4,
            "elements": [
                "chisel:sandstoneyellow2@4"
            ]
        },
        {
            "x": -12,
            "y": 9,
            "z": 0,
            "elements": [
                "chisel:sandstoneyellow2@4"
            ]
        },
        {
            "x": -1,
            "y": -3,
            "z": -24,
            "elements": [
                "chisel:sandstoneyellow1@7"
            ]
        },
        {
            "x": -1,
            "y": -3,
            "z": -23,
            "elements": [
                "railcraft:sandy@1"
            ]
        },
        {
            "x": -12,
            "y": 9,
            "z": -1,
            "elements": [
                "aether_legacy:angelic_wall@0"
            ]
        },
        {
            "x": -7,
            "y": 16,
            "z": -16,
            "elements": [
                "chisel:concrete_brown@1"
            ]
        },
        {
            "x": -7,
            "y": 16,
            "z": -8,
            "elements": [
                "chisel:concrete_brown@1"
            ]
        },
        {
            "x": -7,
            "y": 8,
            "z": -10,
            "elements": [
                "iceandfire:sea_serpent_scale_block_bronze@0"
            ]
        },
        {
            "x": 10,
            "y": 35,
            "z": -2,
            "elements": [
                "minecraft:stained_glass@3"
            ]
        },
        {
            "x": -7,
            "y": 8,
            "z": -14,
            "elements": [
                "iceandfire:sea_serpent_scale_block_bronze@0"
            ]
        },
        {
            "x": -7,
            "y": 8,
            "z": -13,
            "elements": [
                "iceandfire:sea_serpent_scale_block_bronze@0"
            ]
        },
        {
            "x": -7,
            "y": 8,
            "z": -12,
            "elements": [
                "iceandfire:sea_serpent_scale_block_bronze@0"
            ]
        },
        {
            "x": -7,
            "y": 8,
            "z": -11,
            "elements": [
                "iceandfire:sea_serpent_scale_block_bronze@0"
            ]
        },
        {
            "x": 10,
            "y": 35,
            "z": -19,
            "elements": [
                "minecraft:stained_glass@3"
            ]
        },
        {
            "x": 8,
            "y": 29,
            "z": -20,
            "elements": [
                "chisel:concrete_brown@1"
            ]
        },
        {
            "x": 2,
            "y": -2,
            "z": 0,
            "elements": [
                "modularmachinery:blockfluidinputhatch@7"
            ]
        },
        {
            "x": 8,
            "y": 29,
            "z": -19,
            "elements": [
                "chisel:concrete_brown@1"
            ]
        },
        {
            "x": 2,
            "y": -2,
            "z": 2,
            "elements": [
                "enderio:block_alloy@7"
            ]
        },
        {
            "x": 8,
            "y": 29,
            "z": -22,
            "elements": [
                "chisel:concrete_brown@1"
            ]
        },
        {
            "x": 8,
            "y": 29,
            "z": -21,
            "elements": [
                "chisel:concrete_brown@1"
            ]
        },
        {
            "x": 2,
            "y": -2,
            "z": 1,
            "elements": [
                "enderio:block_alloy@7"
            ]
        },
        {
            "x": 2,
            "y": -2,
            "z": 4,
            "elements": [
                "enderio:block_alloy@7"
            ]
        },
        {
            "x": 8,
            "y": 29,
            "z": -16,
            "elements": [
                "chisel:concrete_brown@1"
            ]
        },
        {
            "x": 2,
            "y": -2,
            "z": 3,
            "elements": [
                "enderio:block_alloy@7"
            ]
        },
        {
            "x": 8,
            "y": 29,
            "z": -18,
            "elements": [
                "chisel:concrete_brown@1"
            ]
        },
        {
            "x": 8,
            "y": 29,
            "z": -17,
            "elements": [
                "chisel:concrete_brown@1"
            ]
        },
        {
            "x": 2,
            "y": -2,
            "z": 5,
            "elements": [
                "minecraft:sandstone_stairs@3"
            ]
        },
        {
            "x": -11,
            "y": 12,
            "z": -21,
            "elements": [
                "aether_legacy:angelic_wall@0"
            ]
        },
        {
            "x": -11,
            "y": 12,
            "z": -19,
            "elements": [
                "minecraft:stone_slab@9"
            ]
        },
        {
            "x": -11,
            "y": 12,
            "z": -20,
            "elements": [
                "railcraft:sandy@1"
            ]
        },
        {
            "x": 8,
            "y": 29,
            "z": -4,
            "elements": [
                "chisel:concrete_brown@1"
            ]
        },
        {
            "x": 8,
            "y": 29,
            "z": -3,
            "elements": [
                "chisel:concrete_brown@1"
            ]
        },
        {
            "x": 8,
            "y": 29,
            "z": -5,
            "elements": [
                "chisel:concrete_brown@1"
            ]
        },
        {
            "x": 8,
            "y": 29,
            "z": 0,
            "elements": [
                "chisel:concrete_brown@1"
            ]
        },
        {
            "x": 8,
            "y": 29,
            "z": 1,
            "elements": [
                "chisel:concrete_brown@1"
            ]
        },
        {
            "x": 8,
            "y": 29,
            "z": -2,
            "elements": [
                "chisel:concrete_brown@1"
            ]
        },
        {
            "x": 8,
            "y": 29,
            "z": -1,
            "elements": [
                "chisel:concrete_brown@1"
            ]
        },
        {
            "x": 2,
            "y": -2,
            "z": -24,
            "elements": [
                "minecraft:stone_slab@1"
            ]
        },
        {
            "x": 2,
            "y": -2,
            "z": -23,
            "elements": [
                "railcraft:sandy@1"
            ]
        },
        {
            "x": -11,
            "y": 12,
            "z": -1,
            "elements": [
                "railcraft:sandy@1"
            ]
        },
        {
            "x": -11,
            "y": 12,
            "z": -2,
            "elements": [
                "minecraft:stone_slab@9"
            ]
        },
        {
            "x": -14,
            "y": 24,
            "z": -2,
            "elements": [
                "enderio:block_alloy@7"
            ]
        },
        {
            "x": -11,
            "y": 12,
            "z": 0,
            "elements": [
                "aether_legacy:angelic_wall@0"
            ]
        },
        {
            "x": -3,
            "y": 12,
            "z": -6,
            "elements": [
                "iceandfire:sea_serpent_scale_block_bronze@0"
            ]
        },
        {
            "x": -3,
            "y": 12,
            "z": -8,
            "elements": [
                "botania:livingrock0stairs@2"
            ]
        },
        {
            "x": -3,
            "y": 12,
            "z": -7,
            "elements": [
                "biomesoplenty:flesh@0"
            ]
        },
        {
            "x": -11,
            "y": 12,
            "z": -17,
            "elements": [
                "aether_legacy:angelic_wall@0"
            ]
        },
        {
            "x": -11,
            "y": 12,
            "z": -18,
            "elements": [
                "railcraft:sandy@1"
            ]
        },
        {
            "x": -14,
            "y": 24,
            "z": -19,
            "elements": [
                "enderio:block_alloy@7"
            ]
        },
        {
            "x": -3,
            "y": 12,
            "z": -16,
            "elements": [
                "botania:livingrock0stairs@3"
            ]
        },
        {
            "x": -3,
            "y": 12,
            "z": -18,
            "elements": [
                "iceandfire:sea_serpent_scale_block_bronze@0"
            ]
        },
        {
            "x": -3,
            "y": 12,
            "z": -17,
            "elements": [
                "biomesoplenty:flesh@0"
            ]
        },
        {
            "x": -11,
            "y": 12,
            "z": -3,
            "elements": [
                "railcraft:sandy@1"
            ]
        },
        {
            "x": -11,
            "y": 12,
            "z": -4,
            "elements": [
                "aether_legacy:angelic_wall@0"
            ]
        },
        {
            "x": 11,
            "y": 30,
            "z": 1,
            "elements": [
                "biomesoplenty:flesh@0"
            ]
        },
        {
            "x": 11,
            "y": 30,
            "z": 0,
            "elements": [
                "biomesoplenty:flesh@0"
            ]
        },
        {
            "x": 11,
            "y": 30,
            "z": -1,
            "elements": [
                "biomesoplenty:flesh@0"
            ]
        },
        {
            "x": 11,
            "y": 30,
            "z": -2,
            "elements": [
                "biomesoplenty:flesh@0"
            ]
        },
        {
            "x": 11,
            "y": 30,
            "z": 2,
            "elements": [
                "enderio:block_alloy@7"
            ]
        },
        {
            "x": -8,
            "y": 13,
            "z": -20,
            "elements": [
                "aether_legacy:angelic_wall@0"
            ]
        },
        {
            "x": -8,
            "y": 13,
            "z": -21,
            "elements": [
                "chisel:sandstoneyellow2@4"
            ]
        },
        {
            "x": 11,
            "y": 30,
            "z": -3,
            "elements": [
                "biomesoplenty:flesh@0"
            ]
        },
        {
            "x": 11,
            "y": 30,
            "z": -4,
            "elements": [
                "biomesoplenty:flesh@0"
            ]
        },
        {
            "x": 11,
            "y": 30,
            "z": -5,
            "elements": [
                "biomesoplenty:flesh@0"
            ]
        },
        {
            "x": -8,
            "y": 13,
            "z": -18,
            "elements": [
                "aether_legacy:angelic_wall@0"
            ]
        },
        {
            "x": -8,
            "y": 13,
            "z": -17,
            "elements": [
                "chisel:sandstoneyellow2@4"
            ]
        },
        {
            "x": 11,
            "y": 30,
            "z": -6,
            "elements": [
                "enderio:block_alloy@7"
            ]
        },
        {
            "x": 11,
            "y": 30,
            "z": -15,
            "elements": [
                "enderio:block_alloy@7"
            ]
        },
        {
            "x": 11,
            "y": 30,
            "z": -16,
            "elements": [
                "biomesoplenty:flesh@0"
            ]
        },
        {
            "x": 11,
            "y": 30,
            "z": -17,
            "elements": [
                "biomesoplenty:flesh@0"
            ]
        },
        {
            "x": 11,
            "y": 30,
            "z": -18,
            "elements": [
                "biomesoplenty:flesh@0"
            ]
        },
        {
            "x": -1,
            "y": -3,
            "z": 0,
            "elements": [
                "enderio:block_alloy@7"
            ]
        },
        {
            "x": -1,
            "y": -3,
            "z": 1,
            "elements": [
                "enderio:block_alloy@7"
            ]
        },
        {
            "x": -1,
            "y": -3,
            "z": 2,
            "elements": [
                "enderio:block_alloy@7"
            ]
        },
        {
            "x": -1,
            "y": -3,
            "z": 3,
            "elements": [
                "enderio:block_alloy@7"
            ]
        },
        {
            "x": -8,
            "y": 13,
            "z": -4,
            "elements": [
                "chisel:sandstoneyellow2@4"
            ]
        },
        {
            "x": 11,
            "y": 30,
            "z": -23,
            "elements": [
                "enderio:block_alloy@7"
            ]
        },
        {
            "x": -8,
            "y": 13,
            "z": -3,
            "elements": [
                "aether_legacy:angelic_wall@0"
            ]
        },
        {
            "x": -1,
            "y": -3,
            "z": 4,
            "elements": [
                "enderio:block_alloy@7"
            ]
        },
        {
            "x": -1,
            "y": -3,
            "z": 5,
            "elements": [
                "enderio:block_alloy@7"
            ]
        },
        {
            "x": -1,
            "y": -3,
            "z": 6,
            "elements": [
                "minecraft:sandstone_stairs@3"
            ]
        },
        {
            "x": -8,
            "y": 13,
            "z": 0,
            "elements": [
                "chisel:sandstoneyellow2@4"
            ]
        },
        {
            "x": 11,
            "y": 30,
            "z": -19,
            "elements": [
                "biomesoplenty:flesh@0"
            ]
        },
        {
            "x": 11,
            "y": 30,
            "z": -20,
            "elements": [
                "biomesoplenty:flesh@0"
            ]
        },
        {
            "x": 11,
            "y": 30,
            "z": -21,
            "elements": [
                "biomesoplenty:flesh@0"
            ]
        },
        {
            "x": -8,
            "y": 13,
            "z": -1,
            "elements": [
                "aether_legacy:angelic_wall@0"
            ]
        },
        {
            "x": 11,
            "y": 30,
            "z": -22,
            "elements": [
                "biomesoplenty:flesh@0"
            ]
        },
        {
            "x": -6,
            "y": 11,
            "z": -15,
            "elements": [
                "iceandfire:sea_serpent_scale_block_bronze@0"
            ]
        },
        {
            "x": -6,
            "y": 11,
            "z": -16,
            "elements": [
                "iceandfire:sea_serpent_scale_block_bronze@0"
            ]
        },
        {
            "x": -6,
            "y": 11,
            "z": -9,
            "elements": [
                "iceandfire:sea_serpent_scale_block_bronze@0"
            ]
        },
        {
            "x": -6,
            "y": 11,
            "z": -10,
            "elements": [
                "biomesoplenty:flesh@0"
            ]
        },
        {
            "x": -6,
            "y": 11,
            "z": -8,
            "elements": [
                "iceandfire:sea_serpent_scale_block_bronze@0"
            ]
        },
        {
            "x": -6,
            "y": 11,
            "z": -13,
            "elements": [
                "botania:livingrock0stairs@0"
            ]
        },
        {
            "x": -6,
            "y": 11,
            "z": -14,
            "elements": [
                "biomesoplenty:flesh@0"
            ]
        },
        {
            "x": -6,
            "y": 11,
            "z": -11,
            "elements": [
                "botania:livingrock0stairs@0"
            ]
        },
        {
            "x": -6,
            "y": 11,
            "z": -12,
            "elements": [
                "contenttweaker:abyssal_flesh@0"
            ]
        },
        {
            "x": -10,
            "y": 28,
            "z": -19,
            "elements": [
                "railcraft:sandy@1"
            ]
        },
        {
            "x": -10,
            "y": 28,
            "z": -18,
            "elements": [
                "railcraft:sandy@1"
            ]
        },
        {
            "x": -10,
            "y": 28,
            "z": -17,
            "elements": [
                "minecraft:stone_slab@9"
            ]
        },
        {
            "x": -4,
            "y": 9,
            "z": -17,
            "elements": [
                "biomesoplenty:flesh@0"
            ]
        },
        {
            "x": -10,
            "y": 28,
            "z": -15,
            "elements": [
                "enderio:block_alloy@7"
            ]
        },
        {
            "x": -4,
            "y": 9,
            "z": -18,
            "elements": [
                "iceandfire:sea_serpent_scale_block_bronze@0"
            ]
        },
        {
            "x": -4,
            "y": 9,
            "z": -16,
            "elements": [
                "contenttweaker:abyssal_flesh@0"
            ]
        },
        {
            "x": -10,
            "y": 28,
            "z": -23,
            "elements": [
                "enderio:block_alloy@7"
            ]
        },
        {
            "x": 11,
            "y": 1,
            "z": 5,
            "elements": [
                "railcraft:sandy@1"
            ]
        },
        {
            "x": -4,
            "y": 9,
            "z": -7,
            "elements": [
                "biomesoplenty:flesh@0"
            ]
        },
        {
            "x": -10,
            "y": 28,
            "z": -21,
            "elements": [
                "minecraft:stone_slab@9"
            ]
        },
        {
            "x": -10,
            "y": 28,
            "z": -20,
            "elements": [
                "railcraft:sandy@1"
            ]
        },
        {
            "x": -4,
            "y": 9,
            "z": -8,
            "elements": [
                "contenttweaker:abyssal_flesh@0"
            ]
        },
        {
            "x": 11,
            "y": 1,
            "z": 6,
            "elements": [
                "aether_legacy:angelic_wall@0"
            ]
        },
        {
            "x": -10,
            "y": 28,
            "z": -3,
            "elements": [
                "railcraft:sandy@1"
            ]
        },
        {
            "x": -10,
            "y": 28,
            "z": -2,
            "elements": [
                "railcraft:sandy@1"
            ]
        },
        {
            "x": -4,
            "y": 9,
            "z": -6,
            "elements": [
                "iceandfire:sea_serpent_scale_block_bronze@0"
            ]
        },
        {
            "x": -10,
            "y": 28,
            "z": -1,
            "elements": [
                "railcraft:sandy@1"
            ]
        },
        {
            "x": -1,
            "y": 39,
            "z": -13,
            "elements": [
                "minecraft:stained_glass@3"
            ]
        },
        {
            "x": -10,
            "y": 28,
            "z": 0,
            "elements": [
                "minecraft:stone_slab@9"
            ]
        },
        {
            "x": -10,
            "y": 28,
            "z": 2,
            "elements": [
                "enderio:block_alloy@7"
            ]
        },
        {
            "x": -1,
            "y": 39,
            "z": -11,
            "elements": [
                "minecraft:stained_glass@3"
            ]
        },
        {
            "x": -10,
            "y": 28,
            "z": -6,
            "elements": [
                "enderio:block_alloy@7"
            ]
        },
        {
            "x": -10,
            "y": 28,
            "z": -4,
            "elements": [
                "minecraft:stone_slab@9"
            ]
        },
        {
            "x": 0,
            "y": 0,
            "z": 3,
            "elements": [
                "minecraft:sandstone_stairs@3"
            ]
        },
        {
            "x": 10,
            "y": 27,
            "z": -23,
            "elements": [
                "enderio:block_alloy@7"
            ]
        },
        {
            "x": 0,
            "y": 0,
            "z": 2,
            "elements": [
                "enderio:block_alloy@7"
            ]
        },
        {
            "x": 0,
            "y": 0,
            "z": 1,
            "elements": [
                "enderio:block_alloy@7"
            ]
        },
        {
            "x": 14,
            "y": 31,
            "z": -1,
            "elements": [
                "enderio:block_alloy@7"
            ]
        },
        {
            "x": 11,
            "y": 1,
            "z": -24,
            "elements": [
                "aether_legacy:angelic_wall@0"
            ]
        },
        {
            "x": -10,
            "y": 15,
            "z": -18,
            "elements": [
                "minecraft:stone_slab@9"
            ]
        },
        {
            "x": 14,
            "y": 31,
            "z": 0,
            "elements": [
                "enderio:block_alloy@7"
            ]
        },
        {
            "x": 11,
            "y": 1,
            "z": -23,
            "elements": [
                "railcraft:sandy@1"
            ]
        },
        {
            "x": -10,
            "y": 15,
            "z": -20,
            "elements": [
                "minecraft:stone_slab@9"
            ]
        },
        {
            "x": -10,
            "y": 15,
            "z": -19,
            "elements": [
                "divinerpg:blaze_lamp@0"
            ]
        },
        {
            "x": 14,
            "y": 31,
            "z": -4,
            "elements": [
                "enderio:block_alloy@7"
            ]
        },
        {
            "x": 14,
            "y": 31,
            "z": -3,
            "elements": [
                "enderio:block_alloy@7"
            ]
        },
        {
            "x": 14,
            "y": 31,
            "z": -18,
            "elements": [
                "enderio:block_alloy@7"
            ]
        },
        {
            "x": 14,
            "y": 31,
            "z": -17,
            "elements": [
                "enderio:block_alloy@7"
            ]
        },
        {
            "x": -10,
            "y": 15,
            "z": -2,
            "elements": [
                "divinerpg:blaze_lamp@0"
            ]
        },
        {
            "x": -10,
            "y": 15,
            "z": -1,
            "elements": [
                "minecraft:stone_slab@9"
            ]
        },
        {
            "x": 14,
            "y": 31,
            "z": -21,
            "elements": [
                "enderio:block_alloy@7"
            ]
        },
        {
            "x": -10,
            "y": 15,
            "z": -3,
            "elements": [
                "minecraft:stone_slab@9"
            ]
        },
        {
            "x": 14,
            "y": 31,
            "z": -20,
            "elements": [
                "enderio:block_alloy@7"
            ]
        },
        {
            "x": 0,
            "y": 0,
            "z": -22,
            "elements": [
                "divinerpg:blaze_lamp@0"
            ]
        },
        {
            "x": 0,
            "y": 0,
            "z": -23,
            "elements": [
                "minecraft:stone_slab@1"
            ]
        },
        {
            "x": 10,
            "y": 27,
            "z": 2,
            "elements": [
                "enderio:block_alloy@7"
            ]
        },
        {
            "x": 9,
            "y": 11,
            "z": 1,
            "elements": [
                "enderio:block_alloy@6"
            ]
        },
        {
            "x": 10,
            "y": 27,
            "z": -2,
            "elements": [
                "divinerpg:blaze_lamp@0"
            ]
        },
        {
            "x": 9,
            "y": 11,
            "z": 0,
            "elements": [
                "aether_legacy:angelic_wall@0"
            ]
        },
        {
            "x": 9,
            "y": 11,
            "z": -1,
            "elements": [
                "railcraft:sandy@1"
            ]
        },
        {
            "x": 10,
            "y": 27,
            "z": -1,
            "elements": [
                "minecraft:stone_slab@9"
            ]
        },
        {
            "x": 9,
            "y": 11,
            "z": -2,
            "elements": [
                "minecraft:stone_slab@9"
            ]
        },
        {
            "x": 9,
            "y": 11,
            "z": -3,
            "elements": [
                "railcraft:sandy@1"
            ]
        },
        {
            "x": 10,
            "y": 27,
            "z": -3,
            "elements": [
                "minecraft:stone_slab@9"
            ]
        },
        {
            "x": 10,
            "y": 27,
            "z": -6,
            "elements": [
                "enderio:block_alloy@7"
            ]
        },
        {
            "x": 9,
            "y": 11,
            "z": -4,
            "elements": [
                "aether_legacy:angelic_wall@0"
            ]
        },
        {
            "x": 9,
            "y": 11,
            "z": -5,
            "elements": [
                "enderio:block_alloy@6"
            ]
        },
        {
            "x": -13,
            "y": -2,
            "z": 5,
            "elements": [
                "railcraft:sandy@1"
            ]
        },
        {
            "x": 12,
            "y": 41,
            "z": -1,
            "elements": [
                "minecraft:stained_glass@3"
            ]
        },
        {
            "x": -13,
            "y": -2,
            "z": 3,
            "elements": [
                "divinerpg:blaze_lamp@0"
            ]
        },
        {
            "x": 12,
            "y": 41,
            "z": -2,
            "elements": [
                "minecraft:stained_glass@9"
            ]
        },
        {
            "x": 12,
            "y": 41,
            "z": -3,
            "elements": [
                "minecraft:stained_glass@3"
            ]
        },
        {
            "x": 10,
            "y": 27,
            "z": -15,
            "elements": [
                "enderio:block_alloy@7"
            ]
        },
        {
            "x": 10,
            "y": 27,
            "z": -18,
            "elements": [
                "minecraft:stone_slab@9"
            ]
        },
        {
            "x": -11,
            "y": 41,
            "z": -21,
            "elements": [
                "minecraft:stained_glass@3"
            ]
        },
        {
            "x": -11,
            "y": 41,
            "z": -20,
            "elements": [
                "minecraft:stained_glass@9"
            ]
        },
        {
            "x": -11,
            "y": 41,
            "z": -19,
            "elements": [
                "minecraft:stained_glass@11"
            ]
        },
        {
            "x": 10,
            "y": 27,
            "z": -20,
            "elements": [
                "minecraft:stone_slab@9"
            ]
        },
        {
            "x": -11,
            "y": 41,
            "z": -18,
            "elements": [
                "minecraft:stained_glass@9"
            ]
        },
        {
            "x": 10,
            "y": 27,
            "z": -19,
            "elements": [
                "divinerpg:blaze_lamp@0"
            ]
        },
        {
            "x": -11,
            "y": 41,
            "z": -17,
            "elements": [
                "minecraft:stained_glass@3"
            ]
        },
        {
            "x": -13,
            "y": -2,
            "z": 6,
            "elements": [
                "minecraft:sandstone@1"
            ]
        },
        {
            "x": 12,
            "y": 41,
            "z": -18,
            "elements": [
                "minecraft:stained_glass@3"
            ]
        },
        {
            "x": 12,
            "y": 41,
            "z": -19,
            "elements": [
                "minecraft:stained_glass@9"
            ]
        },
        {
            "x": -13,
            "y": -2,
            "z": -15,
            "elements": [
                "divinerpg:blaze_lamp@0"
            ]
        },
        {
            "x": 12,
            "y": 41,
            "z": -20,
            "elements": [
                "minecraft:stained_glass@3"
            ]
        },
        {
            "x": -13,
            "y": -2,
            "z": -3,
            "elements": [
                "divinerpg:blaze_lamp@0"
            ]
        },
        {
            "x": -11,
            "y": 41,
            "z": -4,
            "elements": [
                "minecraft:stained_glass@3"
            ]
        },
        {
            "x": -11,
            "y": 41,
            "z": -3,
            "elements": [
                "minecraft:stained_glass@9"
            ]
        },
        {
            "x": -11,
            "y": 41,
            "z": -2,
            "elements": [
                "minecraft:stained_glass@11"
            ]
        },
        {
            "x": -13,
            "y": -2,
            "z": -9,
            "elements": [
                "divinerpg:blaze_lamp@0"
            ]
        },
        {
            "x": -11,
            "y": 41,
            "z": -1,
            "elements": [
                "minecraft:stained_glass@9"
            ]
        },
        {
            "x": -11,
            "y": 41,
            "z": 0,
            "elements": [
                "minecraft:stained_glass@3"
            ]
        },
        {
            "x": 9,
            "y": 11,
            "z": -22,
            "elements": [
                "enderio:block_alloy@6"
            ]
        },
        {
            "x": 9,
            "y": 11,
            "z": -16,
            "elements": [
                "enderio:block_alloy@6"
            ]
        },
        {
            "x": -13,
            "y": -2,
            "z": -21,
            "elements": [
                "divinerpg:blaze_lamp@0"
            ]
        },
        {
            "x": 9,
            "y": 11,
            "z": -17,
            "elements": [
                "aether_legacy:angelic_wall@0"
            ]
        },
        {
            "x": 9,
            "y": 11,
            "z": -18,
            "elements": [
                "railcraft:sandy@1"
            ]
        },
        {
            "x": -13,
            "y": -2,
            "z": -23,
            "elements": [
                "railcraft:sandy@1"
            ]
        },
        {
            "x": -13,
            "y": -2,
            "z": -24,
            "elements": [
                "minecraft:sandstone@1"
            ]
        },
        {
            "x": 9,
            "y": 11,
            "z": -19,
            "elements": [
                "minecraft:stone_slab@9"
            ]
        },
        {
            "x": 9,
            "y": 11,
            "z": -20,
            "elements": [
                "railcraft:sandy@1"
            ]
        },
        {
            "x": 9,
            "y": 11,
            "z": -21,
            "elements": [
                "aether_legacy:angelic_wall@0"
            ]
        },
        {
            "x": 10,
            "y": -2,
            "z": 5,
            "elements": [
                "railcraft:sandy@1"
            ]
        },
        {
            "x": -5,
            "y": 6,
            "z": -14,
            "elements": [
                "biomesoplenty:flesh@0"
            ]
        },
        {
            "x": 10,
            "y": -2,
            "z": 6,
            "elements": [
                "minecraft:stone_slab@1"
            ]
        },
        {
            "x": -5,
            "y": 6,
            "z": -13,
            "elements": [
                "biomesoplenty:flesh@0"
            ]
        },
        {
            "x": -5,
            "y": 6,
            "z": -12,
            "elements": [
                "biomesoplenty:flesh@0"
            ]
        },
        {
            "x": -5,
            "y": 6,
            "z": -11,
            "elements": [
                "biomesoplenty:flesh@0"
            ]
        },
        {
            "x": -5,
            "y": 6,
            "z": -18,
            "elements": [
                "enderio:block_alloy@6"
            ]
        },
        {
            "x": -5,
            "y": 6,
            "z": -17,
            "elements": [
                "chisel:concrete_brown@1"
            ]
        },
        {
            "x": 0,
            "y": 42,
            "z": -9,
            "elements": [
                "minecraft:stained_glass@3"
            ]
        },
        {
            "x": 0,
            "y": 42,
            "z": -10,
            "elements": [
                "minecraft:stained_glass@9"
            ]
        },
        {
            "x": -5,
            "y": 6,
            "z": -16,
            "elements": [
                "biomesoplenty:flesh@0"
            ]
        },
        {
            "x": 0,
            "y": 42,
            "z": -11,
            "elements": [
                "minecraft:stained_glass@11"
            ]
        },
        {
            "x": -5,
            "y": 6,
            "z": -15,
            "elements": [
                "biomesoplenty:flesh@0"
            ]
        },
        {
            "x": -5,
            "y": 6,
            "z": -6,
            "elements": [
                "enderio:block_alloy@6"
            ]
        },
        {
            "x": 0,
            "y": 42,
            "z": -12,
            "elements": [
                "contenttweaker:heart_of_the_desert@0"
            ]
        },
        {
            "x": 0,
            "y": 42,
            "z": -13,
            "elements": [
                "minecraft:stained_glass@11"
            ]
        },
        {
            "x": -9,
            "y": 31,
            "z": -19,
            "elements": [
                "botania:livingrock0stairs@0"
            ]
        },
        {
            "x": 0,
            "y": 42,
            "z": -14,
            "elements": [
                "minecraft:stained_glass@9"
            ]
        },
        {
            "x": -9,
            "y": 31,
            "z": -17,
            "elements": [
                "botania:livingrock0stairs@2"
            ]
        },
        {
            "x": 0,
            "y": 42,
            "z": -15,
            "elements": [
                "minecraft:stained_glass@3"
            ]
        },
        {
            "x": -5,
            "y": 6,
            "z": -10,
            "elements": [
                "biomesoplenty:flesh@0"
            ]
        },
        {
            "x": -5,
            "y": 6,
            "z": -9,
            "elements": [
                "biomesoplenty:flesh@0"
            ]
        },
        {
            "x": -9,
            "y": 31,
            "z": -23,
            "elements": [
                "enderio:block_alloy@7"
            ]
        },
        {
            "x": -5,
            "y": 6,
            "z": -8,
            "elements": [
                "biomesoplenty:flesh@0"
            ]
        },
        {
            "x": -9,
            "y": 31,
            "z": -21,
            "elements": [
                "botania:livingrock0stairs@3"
            ]
        },
        {
            "x": -5,
            "y": 6,
            "z": -7,
            "elements": [
                "chisel:concrete_brown@1"
            ]
        },
        {
            "x": -9,
            "y": 31,
            "z": -15,
            "elements": [
                "enderio:block_alloy@7"
            ]
        },
        {
            "x": -9,
            "y": 31,
            "z": -2,
            "elements": [
                "botania:livingrock0stairs@0"
            ]
        },
        {
            "x": -9,
            "y": 31,
            "z": 0,
            "elements": [
                "botania:livingrock0stairs@2"
            ]
        },
        {
            "x": -9,
            "y": 31,
            "z": -6,
            "elements": [
                "enderio:block_alloy@7"
            ]
        },
        {
            "x": 9,
            "y": 24,
            "z": -21,
            "elements": [
                "aether_legacy:angelic_wall@0"
            ]
        },
        {
            "x": -9,
            "y": 31,
            "z": -4,
            "elements": [
                "botania:livingrock0stairs@3"
            ]
        },
        {
            "x": 9,
            "y": 24,
            "z": -19,
            "elements": [
                "minecraft:stone_slab@9"
            ]
        },
        {
            "x": 9,
            "y": 24,
            "z": -20,
            "elements": [
                "railcraft:sandy@1"
            ]
        },
        {
            "x": 1,
            "y": 3,
            "z": -3,
            "elements": [
                "chisel:sandstoneyellow1@1"
            ]
        },
        {
            "x": 1,
            "y": 3,
            "z": -2,
            "elements": [
                "chisel:sandstoneyellow2@1"
            ]
        },
        {
            "x": 1,
            "y": 3,
            "z": -5,
            "elements": [
                "minecraft:sandstone@0"
            ]
        },
        {
            "x": -9,
            "y": 18,
            "z": -17,
            "elements": [
                "aether_legacy:angelic_wall@0"
            ]
        },
        {
            "x": -9,
            "y": 18,
            "z": -18,
            "elements": [
                "railcraft:sandy@1"
            ]
        },
        {
            "x": 1,
            "y": 3,
            "z": -4,
            "elements": [
                "chisel:sandstoneyellow2@1"
            ]
        },
        {
            "x": -9,
            "y": 31,
            "z": 2,
            "elements": [
                "enderio:block_alloy@7"
            ]
        },
        {
            "x": 1,
            "y": 3,
            "z": -1,
            "elements": [
                "railcraft:sandy@1"
            ]
        },
        {
            "x": 1,
            "y": 3,
            "z": 0,
            "elements": [
                "minecraft:sandstone_stairs@3"
            ]
        },
        {
            "x": 1,
            "y": 3,
            "z": -11,
            "elements": [
                "minecraft:sandstone@0"
            ]
        },
        {
            "x": 1,
            "y": 3,
            "z": -10,
            "elements": [
                "minecraft:sandstone@0"
            ]
        },
        {
            "x": 1,
            "y": 3,
            "z": -13,
            "elements": [
                "minecraft:sandstone@0"
            ]
        },
        {
            "x": 1,
            "y": 3,
            "z": -12,
            "elements": [
                "minecraft:sandstone@0"
            ]
        },
        {
            "x": -9,
            "y": 18,
            "z": -19,
            "elements": [
                "minecraft:stone_slab@9"
            ]
        },
        {
            "x": 1,
            "y": 3,
            "z": -7,
            "elements": [
                "minecraft:sandstone@0"
            ]
        },
        {
            "x": 10,
            "y": -2,
            "z": -23,
            "elements": [
                "railcraft:sandy@1"
            ]
        },
        {
            "x": -9,
            "y": 18,
            "z": -20,
            "elements": [
                "railcraft:sandy@1"
            ]
        },
        {
            "x": 1,
            "y": 3,
            "z": -6,
            "elements": [
                "minecraft:sandstone@0"
            ]
        },
        {
            "x": 1,
            "y": 3,
            "z": -9,
            "elements": [
                "minecraft:sandstone@0"
            ]
        },
        {
            "x": -9,
            "y": 18,
            "z": -21,
            "elements": [
                "aether_legacy:angelic_wall@0"
            ]
        },
        {
            "x": 10,
            "y": -2,
            "z": -24,
            "elements": [
                "minecraft:stone_slab@1"
            ]
        },
        {
            "x": 1,
            "y": 3,
            "z": -8,
            "elements": [
                "minecraft:sandstone@0"
            ]
        },
        {
            "x": 1,
            "y": 3,
            "z": -19,
            "elements": [
                "minecraft:sandstone@0"
            ]
        },
        {
            "x": -9,
            "y": 18,
            "z": 0,
            "elements": [
                "aether_legacy:angelic_wall@0"
            ]
        },
        {
            "x": 1,
            "y": 3,
            "z": -18,
            "elements": [
                "minecraft:sandstone@0"
            ]
        },
        {
            "x": -9,
            "y": 18,
            "z": -1,
            "elements": [
                "railcraft:sandy@1"
            ]
        },
        {
            "x": 1,
            "y": 3,
            "z": -21,
            "elements": [
                "chisel:sandstoneyellow1@1"
            ]
        },
        {
            "x": 1,
            "y": 3,
            "z": -20,
            "elements": [
                "chisel:sandstoneyellow2@1"
            ]
        },
        {
            "x": -9,
            "y": 18,
            "z": -2,
            "elements": [
                "minecraft:stone_slab@9"
            ]
        },
        {
            "x": 1,
            "y": 3,
            "z": -15,
            "elements": [
                "minecraft:sandstone@0"
            ]
        },
        {
            "x": 1,
            "y": 3,
            "z": -14,
            "elements": [
                "minecraft:sandstone@0"
            ]
        },
        {
            "x": 1,
            "y": 3,
            "z": -17,
            "elements": [
                "minecraft:sandstone@0"
            ]
        },
        {
            "x": 1,
            "y": 3,
            "z": -16,
            "elements": [
                "minecraft:sandstone@0"
            ]
        },
        {
            "x": 1,
            "y": 3,
            "z": -23,
            "elements": [
                "railcraft:sandy@1"
            ]
        },
        {
            "x": -9,
            "y": 18,
            "z": -3,
            "elements": [
                "railcraft:sandy@1"
            ]
        },
        {
            "x": -9,
            "y": 18,
            "z": -4,
            "elements": [
                "aether_legacy:angelic_wall@0"
            ]
        },
        {
            "x": 1,
            "y": 3,
            "z": -22,
            "elements": [
                "chisel:sandstoneyellow2@1"
            ]
        },
        {
            "x": 1,
            "y": 3,
            "z": -24,
            "elements": [
                "chisel:sandstoneyellow1@7"
            ]
        },
        {
            "x": 10,
            "y": 14,
            "z": -3,
            "elements": [
                "minecraft:stone_slab@9"
            ]
        },
        {
            "x": 10,
            "y": 14,
            "z": -2,
            "elements": [
                "divinerpg:blaze_lamp@0"
            ]
        },
        {
            "x": -10,
            "y": 44,
            "z": -20,
            "elements": [
                "minecraft:stained_glass@11"
            ]
        },
        {
            "x": -10,
            "y": 44,
            "z": -21,
            "elements": [
                "minecraft:stained_glass@9"
            ]
        },
        {
            "x": 10,
            "y": 14,
            "z": -1,
            "elements": [
                "minecraft:stone_slab@9"
            ]
        },
        {
            "x": 11,
            "y": 38,
            "z": -2,
            "elements": [
                "minecraft:stained_glass@9"
            ]
        },
        {
            "x": 11,
            "y": 38,
            "z": -1,
            "elements": [
                "minecraft:stained_glass@3"
            ]
        },
        {
            "x": -10,
            "y": 44,
            "z": -18,
            "elements": [
                "minecraft:stained_glass@11"
            ]
        },
        {
            "x": -10,
            "y": 44,
            "z": -19,
            "elements": [
                "contenttweaker:arc_reactor_coil@0"
            ]
        },
        {
            "x": -10,
            "y": 44,
            "z": -17,
            "elements": [
                "minecraft:stained_glass@9"
            ]
        },
        {
            "x": 9,
            "y": 24,
            "z": -17,
            "elements": [
                "aether_legacy:angelic_wall@0"
            ]
        },
        {
            "x": 9,
            "y": 24,
            "z": -18,
            "elements": [
                "railcraft:sandy@1"
            ]
        },
        {
            "x": -10,
            "y": 44,
            "z": -4,
            "elements": [
                "minecraft:stained_glass@9"
            ]
        },
        {
            "x": 11,
            "y": 38,
            "z": -3,
            "elements": [
                "minecraft:stained_glass@3"
            ]
        },
        {
            "x": 11,
            "y": 38,
            "z": -18,
            "elements": [
                "minecraft:stained_glass@3"
            ]
        },
        {
            "x": -10,
            "y": 44,
            "z": -2,
            "elements": [
                "contenttweaker:arc_reactor_coil@0"
            ]
        },
        {
            "x": -10,
            "y": 44,
            "z": -3,
            "elements": [
                "minecraft:stained_glass@11"
            ]
        },
        {
            "x": 9,
            "y": 24,
            "z": -3,
            "elements": [
                "railcraft:sandy@1"
            ]
        },
        {
            "x": -10,
            "y": 44,
            "z": 0,
            "elements": [
                "minecraft:stained_glass@9"
            ]
        },
        {
            "x": -10,
            "y": 44,
            "z": -1,
            "elements": [
                "minecraft:stained_glass@11"
            ]
        },
        {
            "x": 9,
            "y": 24,
            "z": -4,
            "elements": [
                "aether_legacy:angelic_wall@0"
            ]
        },
        {
            "x": 9,
            "y": 24,
            "z": -1,
            "elements": [
                "railcraft:sandy@1"
            ]
        },
        {
            "x": 9,
            "y": 24,
            "z": -2,
            "elements": [
                "minecraft:stone_slab@9"
            ]
        },
        {
            "x": 9,
            "y": 24,
            "z": 0,
            "elements": [
                "aether_legacy:angelic_wall@0"
            ]
        },
        {
            "x": 11,
            "y": 38,
            "z": -20,
            "elements": [
                "minecraft:stained_glass@3"
            ]
        },
        {
            "x": 11,
            "y": 38,
            "z": -19,
            "elements": [
                "minecraft:stained_glass@9"
            ]
        },
        {
            "x": 10,
            "y": 14,
            "z": -20,
            "elements": [
                "minecraft:stone_slab@9"
            ]
        },
        {
            "x": 10,
            "y": 14,
            "z": -19,
            "elements": [
                "divinerpg:blaze_lamp@0"
            ]
        },
        {
            "x": 10,
            "y": 14,
            "z": -18,
            "elements": [
                "minecraft:stone_slab@9"
            ]
        },
        {
            "x": -6,
            "y": 3,
            "z": -8,
            "elements": [
                "minecraft:sandstone@0"
            ]
        },
        {
            "x": -6,
            "y": 3,
            "z": -7,
            "elements": [
                "chisel:sandstoneyellow2@1"
            ]
        },
        {
            "x": -6,
            "y": 3,
            "z": -10,
            "elements": [
                "minecraft:sandstone@0"
            ]
        },
        {
            "x": 13,
            "y": 7,
            "z": -17,
            "elements": [
                "enderio:block_alloy@6"
            ]
        },
        {
            "x": -6,
            "y": 3,
            "z": -9,
            "elements": [
                "minecraft:sandstone@0"
            ]
        },
        {
            "x": 13,
            "y": 7,
            "z": -16,
            "elements": [
                "enderio:block_alloy@6"
            ]
        },
        {
            "x": 13,
            "y": 7,
            "z": -19,
            "elements": [
                "enderio:block_alloy@6"
            ]
        },
        {
            "x": -6,
            "y": 3,
            "z": -12,
            "elements": [
                "minecraft:sandstone@0"
            ]
        },
        {
            "x": 13,
            "y": 7,
            "z": -18,
            "elements": [
                "enderio:block_alloy@6"
            ]
        },
        {
            "x": -6,
            "y": 3,
            "z": -11,
            "elements": [
                "minecraft:sandstone@0"
            ]
        },
        {
            "x": 13,
            "y": 7,
            "z": -21,
            "elements": [
                "enderio:block_alloy@6"
            ]
        },
        {
            "x": -6,
            "y": 3,
            "z": -14,
            "elements": [
                "minecraft:sandstone@0"
            ]
        },
        {
            "x": 13,
            "y": 7,
            "z": -20,
            "elements": [
                "enderio:block_alloy@6"
            ]
        },
        {
            "x": -6,
            "y": 3,
            "z": -13,
            "elements": [
                "minecraft:sandstone@0"
            ]
        },
        {
            "x": -6,
            "y": 3,
            "z": 0,
            "elements": [
                "railcraft:sandy@1"
            ]
        },
        {
            "x": 13,
            "y": 7,
            "z": -22,
            "elements": [
                "enderio:block_alloy@6"
            ]
        },
        {
            "x": -6,
            "y": 3,
            "z": 1,
            "elements": [
                "railcraft:sandy@1"
            ]
        },
        {
            "x": -6,
            "y": 3,
            "z": -2,
            "elements": [
                "railcraft:sandy@1"
            ]
        },
        {
            "x": -6,
            "y": 3,
            "z": -1,
            "elements": [
                "railcraft:sandy@1"
            ]
        },
        {
            "x": -6,
            "y": 3,
            "z": -4,
            "elements": [
                "railcraft:sandy@1"
            ]
        },
        {
            "x": -6,
            "y": 3,
            "z": -3,
            "elements": [
                "railcraft:sandy@1"
            ]
        },
        {
            "x": -6,
            "y": 3,
            "z": -6,
            "elements": [
                "railcraft:sandy@1"
            ]
        },
        {
            "x": -6,
            "y": 3,
            "z": -5,
            "elements": [
                "railcraft:sandy@1"
            ]
        },
        {
            "x": -6,
            "y": 3,
            "z": 6,
            "elements": [
                "chisel:sandstoneyellow1@7"
            ]
        },
        {
            "x": 8,
            "y": 21,
            "z": -23,
            "elements": [
                "enderio:block_alloy@7"
            ]
        },
        {
            "x": -6,
            "y": 3,
            "z": 4,
            "elements": [
                "chisel:sandstoneyellow1@1"
            ]
        },
        {
            "x": -6,
            "y": 3,
            "z": 5,
            "elements": [
                "railcraft:sandy@1"
            ]
        },
        {
            "x": -6,
            "y": 3,
            "z": 2,
            "elements": [
                "railcraft:sandy@1"
            ]
        },
        {
            "x": -6,
            "y": 3,
            "z": 3,
            "elements": [
                "chisel:sandstoneyellow2@1"
            ]
        },
        {
            "x": 8,
            "y": 21,
            "z": -20,
            "elements": [
                "aether_legacy:angelic_wall@0"
            ]
        },
        {
            "x": 8,
            "y": 21,
            "z": -21,
            "elements": [
                "chisel:sandstoneyellow2@4"
            ]
        },
        {
            "x": 8,
            "y": 21,
            "z": -15,
            "elements": [
                "enderio:block_alloy@7"
            ]
        },
        {
            "x": 8,
            "y": 21,
            "z": -17,
            "elements": [
                "chisel:sandstoneyellow2@4"
            ]
        },
        {
            "x": 8,
            "y": 21,
            "z": -18,
            "elements": [
                "aether_legacy:angelic_wall@0"
            ]
        },
        {
            "x": 2,
            "y": 6,
            "z": -9,
            "elements": [
                "biomesoplenty:flesh@0"
            ]
        },
        {
            "x": -8,
            "y": 21,
            "z": -21,
            "elements": [
                "chisel:sandstoneyellow2@4"
            ]
        },
        {
            "x": 2,
            "y": 6,
            "z": -8,
            "elements": [
                "biomesoplenty:flesh@0"
            ]
        },
        {
            "x": -8,
            "y": 21,
            "z": -20,
            "elements": [
                "aether_legacy:angelic_wall@0"
            ]
        },
        {
            "x": 2,
            "y": 6,
            "z": -7,
            "elements": [
                "biomesoplenty:flesh@0"
            ]
        },
        {
            "x": 2,
            "y": 6,
            "z": -6,
            "elements": [
                "biomesoplenty:flesh@0"
            ]
        },
        {
            "x": 2,
            "y": 6,
            "z": -5,
            "elements": [
                "iceandfire:sea_serpent_scale_block_bronze@0"
            ]
        },
        {
            "x": -8,
            "y": 21,
            "z": -18,
            "elements": [
                "aether_legacy:angelic_wall@0"
            ]
        },
        {
            "x": -8,
            "y": 21,
            "z": -17,
            "elements": [
                "chisel:sandstoneyellow2@4"
            ]
        },
        {
            "x": 2,
            "y": 6,
            "z": -4,
            "elements": [
                "enderio:block_alloy@6"
            ]
        },
        {
            "x": -8,
            "y": 21,
            "z": -15,
            "elements": [
                "enderio:block_alloy@7"
            ]
        },
        {
            "x": 2,
            "y": 6,
            "z": -17,
            "elements": [
                "biomesoplenty:flesh@0"
            ]
        },
        {
            "x": 2,
            "y": 6,
            "z": -16,
            "elements": [
                "biomesoplenty:flesh@0"
            ]
        },
        {
            "x": 2,
            "y": 6,
            "z": -15,
            "elements": [
                "biomesoplenty:flesh@0"
            ]
        },
        {
            "x": 2,
            "y": 6,
            "z": -14,
            "elements": [
                "contenttweaker:abyssal_flesh@0"
            ]
        },
        {
            "x": 2,
            "y": 6,
            "z": -12,
            "elements": [
                "botania:livingrock0stairs@3"
            ]
        },
        {
            "x": -8,
            "y": 21,
            "z": -23,
            "elements": [
                "enderio:block_alloy@7"
            ]
        },
        {
            "x": 2,
            "y": 6,
            "z": -10,
            "elements": [
                "contenttweaker:abyssal_flesh@0"
            ]
        },
        {
            "x": -6,
            "y": 3,
            "z": -24,
            "elements": [
                "chisel:sandstoneyellow1@7"
            ]
        },
        {
            "x": -8,
            "y": 21,
            "z": -6,
            "elements": [
                "enderio:block_alloy@7"
            ]
        },
        {
            "x": 13,
            "y": 7,
            "z": 1,
            "elements": [
                "enderio:block_alloy@6"
            ]
        },
        {
            "x": -6,
            "y": 3,
            "z": -23,
            "elements": [
                "railcraft:sandy@1"
            ]
        },
        {
            "x": -8,
            "y": 21,
            "z": -4,
            "elements": [
                "chisel:sandstoneyellow2@4"
            ]
        },
        {
            "x": 13,
            "y": 7,
            "z": -1,
            "elements": [
                "enderio:block_alloy@6"
            ]
        },
        {
            "x": 13,
            "y": 7,
            "z": 0,
            "elements": [
                "enderio:block_alloy@6"
            ]
        },
        {
            "x": -8,
            "y": 21,
            "z": -3,
            "elements": [
                "aether_legacy:angelic_wall@0"
            ]
        },
        {
            "x": 13,
            "y": 7,
            "z": -3,
            "elements": [
                "enderio:block_alloy@6"
            ]
        },
        {
            "x": -8,
            "y": 21,
            "z": -1,
            "elements": [
                "aether_legacy:angelic_wall@0"
            ]
        },
        {
            "x": 2,
            "y": 6,
            "z": -20,
            "elements": [
                "enderio:block_alloy@6"
            ]
        },
        {
            "x": 13,
            "y": 7,
            "z": -2,
            "elements": [
                "enderio:block_alloy@6"
            ]
        },
        {
            "x": -8,
            "y": 21,
            "z": 0,
            "elements": [
                "chisel:sandstoneyellow2@4"
            ]
        },
        {
            "x": 13,
            "y": 7,
            "z": -5,
            "elements": [
                "enderio:block_alloy@6"
            ]
        },
        {
            "x": 2,
            "y": 6,
            "z": -19,
            "elements": [
                "iceandfire:sea_serpent_scale_block_bronze@0"
            ]
        },
        {
            "x": 2,
            "y": 6,
            "z": -18,
            "elements": [
                "biomesoplenty:flesh@0"
            ]
        },
        {
            "x": 13,
            "y": 7,
            "z": -4,
            "elements": [
                "enderio:block_alloy@6"
            ]
        },
        {
            "x": -6,
            "y": 3,
            "z": -16,
            "elements": [
                "minecraft:sandstone@0"
            ]
        },
        {
            "x": -6,
            "y": 3,
            "z": -15,
            "elements": [
                "minecraft:sandstone@0"
            ]
        },
        {
            "x": -6,
            "y": 3,
            "z": -18,
            "elements": [
                "railcraft:sandy@1"
            ]
        },
        {
            "x": -6,
            "y": 3,
            "z": -17,
            "elements": [
                "railcraft:sandy@1"
            ]
        },
        {
            "x": -6,
            "y": 3,
            "z": -20,
            "elements": [
                "railcraft:sandy@1"
            ]
        },
        {
            "x": -6,
            "y": 3,
            "z": -19,
            "elements": [
                "railcraft:sandy@1"
            ]
        },
        {
            "x": -6,
            "y": 3,
            "z": -22,
            "elements": [
                "railcraft:sandy@1"
            ]
        },
        {
            "x": -6,
            "y": 3,
            "z": -21,
            "elements": [
                "railcraft:sandy@1"
            ]
        },
        {
            "x": -11,
            "y": 4,
            "z": 6,
            "elements": [
                "minecraft:stone_slab@1"
            ]
        },
        {
            "x": -8,
            "y": 21,
            "z": 2,
            "elements": [
                "enderio:block_alloy@7"
            ]
        },
        {
            "x": -11,
            "y": 4,
            "z": -4,
            "elements": [
                "minecraft:sandstone@1"
            ]
        },
        {
            "x": -11,
            "y": 4,
            "z": -3,
            "elements": [
                "railcraft:sandy@1"
            ]
        },
        {
            "x": -11,
            "y": 4,
            "z": 0,
            "elements": [
                "minecraft:sandstone@1"
            ]
        },
        {
            "x": -11,
            "y": 4,
            "z": -2,
            "elements": [
                "railcraft:sandy@1"
            ]
        },
        {
            "x": -11,
            "y": 4,
            "z": -1,
            "elements": [
                "railcraft:sandy@1"
            ]
        },
        {
            "x": -11,
            "y": 4,
            "z": -24,
            "elements": [
                "minecraft:stone_slab@1"
            ]
        },
        {
            "x": -11,
            "y": 4,
            "z": -20,
            "elements": [
                "railcraft:sandy@1"
            ]
        },
        {
            "x": -11,
            "y": 4,
            "z": -19,
            "elements": [
                "railcraft:sandy@1"
            ]
        },
        {
            "x": -11,
            "y": 4,
            "z": -21,
            "elements": [
                "minecraft:sandstone@1"
            ]
        },
        {
            "x": 8,
            "y": 21,
            "z": -3,
            "elements": [
                "aether_legacy:angelic_wall@0"
            ]
        },
        {
            "x": 8,
            "y": 21,
            "z": -4,
            "elements": [
                "chisel:sandstoneyellow2@4"
            ]
        },
        {
            "x": -11,
            "y": 4,
            "z": -18,
            "elements": [
                "railcraft:sandy@1"
            ]
        },
        {
            "x": 8,
            "y": 21,
            "z": -6,
            "elements": [
                "enderio:block_alloy@7"
            ]
        },
        {
            "x": -11,
            "y": 4,
            "z": -17,
            "elements": [
                "minecraft:sandstone@1"
            ]
        },
        {
            "x": 8,
            "y": 21,
            "z": 0,
            "elements": [
                "chisel:sandstoneyellow2@4"
            ]
        },
        {
            "x": 8,
            "y": 21,
            "z": -1,
            "elements": [
                "aether_legacy:angelic_wall@0"
            ]
        },
        {
            "x": 8,
            "y": 21,
            "z": 2,
            "elements": [
                "enderio:block_alloy@7"
            ]
        },
        {
            "x": 7,
            "y": 5,
            "z": -13,
            "elements": [
                "chisel:concrete_brown@1"
            ]
        },
        {
            "x": 7,
            "y": 5,
            "z": -12,
            "elements": [
                "enderio:block_alloy@7"
            ]
        },
        {
            "x": 7,
            "y": 5,
            "z": -11,
            "elements": [
                "chisel:concrete_brown@1"
            ]
        },
        {
            "x": 7,
            "y": 5,
            "z": -10,
            "elements": [
                "chisel:concrete_brown@1"
            ]
        },
        {
            "x": 7,
            "y": 5,
            "z": -14,
            "elements": [
                "chisel:concrete_brown@1"
            ]
        },
        {
            "x": 12,
            "y": 4,
            "z": -4,
            "elements": [
                "chisel:sandstoneyellow2@4"
            ]
        },
        {
            "x": -7,
            "y": 0,
            "z": 5,
            "elements": [
                "railcraft:sandy@1"
            ]
        },
        {
            "x": 12,
            "y": 4,
            "z": -2,
            "elements": [
                "minecraft:stone_slab@1"
            ]
        },
        {
            "x": 12,
            "y": 4,
            "z": -3,
            "elements": [
                "minecraft:sandstone@1"
            ]
        },
        {
            "x": 12,
            "y": 4,
            "z": 0,
            "elements": [
                "chisel:sandstoneyellow2@4"
            ]
        },
        {
            "x": 12,
            "y": 4,
            "z": -1,
            "elements": [
                "minecraft:sandstone@1"
            ]
        },
        {
            "x": 12,
            "y": 4,
            "z": 6,
            "elements": [
                "minecraft:sandstone_stairs@2"
            ]
        },
        {
            "x": 14,
            "y": -3,
            "z": -23,
            "elements": [
                "railcraft:sandy@1"
            ]
        },
        {
            "x": 14,
            "y": -3,
            "z": -24,
            "elements": [
                "chisel:sandstoneyellow1@7"
            ]
        },
        {
            "x": 14,
            "y": -3,
            "z": -21,
            "elements": [
                "railcraft:sandy@1"
            ]
        },
        {
            "x": 14,
            "y": -3,
            "z": -22,
            "elements": [
                "railcraft:sandy@1"
            ]
        },
        {
            "x": 14,
            "y": -3,
            "z": -19,
            "elements": [
                "railcraft:sandy@1"
            ]
        },
        {
            "x": 14,
            "y": -3,
            "z": -20,
            "elements": [
                "railcraft:sandy@1"
            ]
        },
        {
            "x": -7,
            "y": 0,
            "z": 6,
            "elements": [
                "aether_legacy:angelic_wall@0"
            ]
        },
        {
            "x": 14,
            "y": -3,
            "z": -17,
            "elements": [
                "railcraft:sandy@1"
            ]
        },
        {
            "x": 14,
            "y": -3,
            "z": -18,
            "elements": [
                "railcraft:sandy@1"
            ]
        },
        {
            "x": 14,
            "y": -3,
            "z": -15,
            "elements": [
                "railcraft:sandy@1"
            ]
        },
        {
            "x": 14,
            "y": -3,
            "z": -16,
            "elements": [
                "railcraft:sandy@1"
            ]
        },
        {
            "x": 14,
            "y": -3,
            "z": -13,
            "elements": [
                "railcraft:sandy@1"
            ]
        },
        {
            "x": 14,
            "y": -3,
            "z": -14,
            "elements": [
                "railcraft:sandy@1"
            ]
        },
        {
            "x": 3,
            "y": 9,
            "z": -17,
            "elements": [
                "biomesoplenty:flesh@0"
            ]
        },
        {
            "x": 3,
            "y": 9,
            "z": -18,
            "elements": [
                "iceandfire:sea_serpent_scale_block_bronze@0"
            ]
        },
        {
            "x": 3,
            "y": 9,
            "z": -6,
            "elements": [
                "iceandfire:sea_serpent_scale_block_bronze@0"
            ]
        },
        {
            "x": 3,
            "y": 9,
            "z": -7,
            "elements": [
                "biomesoplenty:flesh@0"
            ]
        },
        {
            "x": 12,
            "y": 4,
            "z": -24,
            "elements": [
                "minecraft:sandstone_stairs@3"
            ]
        },
        {
            "x": 12,
            "y": 4,
            "z": -20,
            "elements": [
                "minecraft:sandstone@1"
            ]
        },
        {
            "x": 12,
            "y": 4,
            "z": -21,
            "elements": [
                "chisel:sandstoneyellow2@4"
            ]
        },
        {
            "x": 12,
            "y": 4,
            "z": -18,
            "elements": [
                "minecraft:sandstone@1"
            ]
        },
        {
            "x": 12,
            "y": 4,
            "z": -19,
            "elements": [
                "minecraft:stone_slab@1"
            ]
        },
        {
            "x": 12,
            "y": 4,
            "z": -17,
            "elements": [
                "chisel:sandstoneyellow2@4"
            ]
        },
        {
            "x": -7,
            "y": 0,
            "z": -23,
            "elements": [
                "railcraft:sandy@1"
            ]
        },
        {
            "x": -7,
            "y": 0,
            "z": -24,
            "elements": [
                "aether_legacy:angelic_wall@0"
            ]
        },
        {
            "x": 8,
            "y": 8,
            "z": 0,
            "elements": [
                "chisel:sandstoneyellow2@4"
            ]
        },
        {
            "x": 8,
            "y": 8,
            "z": -1,
            "elements": [
                "aether_legacy:angelic_wall@0"
            ]
        },
        {
            "x": 8,
            "y": 8,
            "z": -4,
            "elements": [
                "chisel:sandstoneyellow2@4"
            ]
        },
        {
            "x": 8,
            "y": 8,
            "z": -3,
            "elements": [
                "aether_legacy:angelic_wall@0"
            ]
        },
        {
            "x": -12,
            "y": 38,
            "z": -19,
            "elements": [
                "minecraft:stained_glass@3"
            ]
        },
        {
            "x": -12,
            "y": 1,
            "z": 5,
            "elements": [
                "minecraft:stone_slab@1"
            ]
        },
        {
            "x": -12,
            "y": 1,
            "z": 4,
            "elements": [
                "divinerpg:blaze_lamp@0"
            ]
        },
        {
            "x": -12,
            "y": 1,
            "z": -22,
            "elements": [
                "divinerpg:blaze_lamp@0"
            ]
        },
        {
            "x": -12,
            "y": 38,
            "z": -2,
            "elements": [
                "minecraft:stained_glass@3"
            ]
        },
        {
            "x": 8,
            "y": 8,
            "z": -17,
            "elements": [
                "chisel:sandstoneyellow2@4"
            ]
        },
        {
            "x": -12,
            "y": 1,
            "z": -23,
            "elements": [
                "minecraft:stone_slab@1"
            ]
        },
        {
            "x": 8,
            "y": 8,
            "z": -20,
            "elements": [
                "aether_legacy:angelic_wall@0"
            ]
        },
        {
            "x": 8,
            "y": 8,
            "z": -21,
            "elements": [
                "chisel:sandstoneyellow2@4"
            ]
        },
        {
            "x": 8,
            "y": 8,
            "z": -18,
            "elements": [
                "aether_legacy:angelic_wall@0"
            ]
        },
        {
            "x": -8,
            "y": -3,
            "z": 6,
            "elements": [
                "chisel:sandstoneyellow1@7"
            ]
        },
        {
            "x": -11,
            "y": 20,
            "z": -17,
            "elements": [
                "aether_legacy:angelic_wall@0"
            ]
        },
        {
            "x": -11,
            "y": 20,
            "z": -18,
            "elements": [
                "railcraft:sandy@1"
            ]
        },
        {
            "x": -8,
            "y": -3,
            "z": 5,
            "elements": [
                "railcraft:sandy@1"
            ]
        },
        {
            "x": -11,
