{
    "registryname": "berserker_forge",
    "localizedname": "Berserker Forge",
	"color": "545454",
    "parts": [
        {
            "x": 1,
            "y": 5,
            "z": 3,
            "elements": [
                "contenttweaker:berserker_steel@0"
            ]
        },
        {
            "x": -3,
            "y": 0,
            "z": 2,
            "elements": [
                "chisel:bloodmagic@1"
            ]
        },
        {
            "x": -3,
            "y": 0,
            "z": 3,
            "elements": [
                "chisel:bloodmagic@1"
            ]
        },
        {
            "x": -3,
            "y": 0,
            "z": 4,
            "elements": [
                "chisel:bloodmagic@1"
            ]
        },
        {
            "x": 2,
            "y": 3,
            "z": 1,
            "elements": [
                "unlimitedchiselworks:chisel_stonebrick2_railcraft_brick_bloodstained_0@2"
            ]
        },
        {
            "x": 1,
            "y": 5,
            "z": 6,
            "elements": [
                "railcraft:brick_bloodstained@1"
            ]
        },
        {
            "x": 3,
            "y": 1,
            "z": 2,
            "elements": [
                "railcraft:brick_bloodstained@1"
            ]
        },
        {
            "x": 2,
            "y": 3,
            "z": 5,
            "elements": [
                "unlimitedchiselworks:chisel_stonebrick2_railcraft_brick_bloodstained_0@2"
            ]
        },
        {
            "x": -1,
            "y": 6,
            "z": 4,
            "elements": [
                "chisel:bloodmagic@5"
            ]
        },
        {
            "x": 3,
            "y": 4,
            "z": 2,
            "elements": [
                "chisel:bloodmagic@5"
            ]
        },
        {
            "x": -1,
            "y": 6,
            "z": 5,
            "elements": [
                "chisel:bloodmagic@5"
            ]
        },
        {
            "x": -1,
            "y": 6,
            "z": 2,
            "elements": [
                "chisel:bloodmagic@5"
            ]
        },
        {
            "x": -1,
            "y": 6,
            "z": 3,
            "elements": [
                "chisel:bloodmagic@3"
            ]
        },
        {
            "x": -2,
            "y": 1,
            "z": 5,
            "elements": [
                "unlimitedchiselworks:chisel_stonebrick2_railcraft_brick_bloodstained_0@2"
            ]
        },
        {
            "x": -1,
            "y": 6,
            "z": 6,
            "elements": [
                "chisel:bloodmagic@1"
            ]
        },
        {
            "x": 3,
            "y": 4,
            "z": 4,
            "elements": [
                "chisel:bloodmagic@5"
            ]
        },
        {
            "x": -2,
            "y": 1,
            "z": 1,
            "elements": [
                "unlimitedchiselworks:chisel_stonebrick2_railcraft_brick_bloodstained_0@2"
            ]
        },
        {
            "x": 2,
            "y": 6,
            "z": 1,
            "elements": [
                "chisel:bloodmagic@1"
            ]
        },
        {
            "x": 2,
            "y": 6,
            "z": 2,
            "elements": [
                "chisel:bloodmagic@5"
            ]
        },
        {
            "x": 2,
            "y": 6,
            "z": 3,
            "elements": [
                "chisel:bloodmagic@5"
            ]
        },
        {
            "x": -1,
            "y": 6,
            "z": 0,
            "elements": [
                "chisel:bloodmagic@1"
            ]
        },
        {
            "x": 2,
            "y": 6,
            "z": 4,
            "elements": [
                "chisel:bloodmagic@5"
            ]
        },
        {
            "x": -1,
            "y": 6,
            "z": 1,
            "elements": [
                "chisel:bloodmagic@5"
            ]
        },
        {
            "x": 1,
            "y": 5,
            "z": 0,
            "elements": [
                "railcraft:brick_bloodstained@1"
            ]
        },
        {
            "x": 2,
            "y": 6,
            "z": 5,
            "elements": [
                "chisel:bloodmagic@1"
            ]
        },
        {
            "x": 0,
            "y": 0,
            "z": 4,
            "elements": [
                "chisel:bloodmagic@3"
            ]
        },
        {
            "x": 0,
            "y": 0,
            "z": 3,
            "elements": [
                "chisel:bloodmagic@3"
            ]
        },
        {
            "x": 0,
            "y": 0,
            "z": 6,
            "elements": [
                "chisel:bloodmagic@1"
            ]
        },
        {
            "x": 0,
            "y": 0,
            "z": 5,
            "elements": [
                "chisel:bloodmagic@5"
            ]
        },
        {
            "x": 1,
            "y": 2,
            "z": 6,
            "elements": [
                "chisel:bloodmagic@5"
            ]
        },
        {
            "x": 0,
            "y": 0,
            "z": 2,
            "elements": [
                "chisel:bloodmagic@3"
            ]
        },
        {
            "x": 0,
            "y": 0,
            "z": 1,
            "elements": [
                "chisel:bloodmagic@5"
            ]
        },
        {
            "x": -2,
            "y": 4,
            "z": 5,
            "elements": [
                "unlimitedchiselworks:chisel_stonebrick2_railcraft_brick_bloodstained_0@2"
            ]
        },
        {
            "x": 1,
            "y": 2,
            "z": 0,
            "elements": [
                "chisel:bloodmagic@5"
            ]
        },
        {
            "x": -1,
            "y": 3,
            "z": 0,
            "elements": [
                "chisel:bloodmagic@5"
            ]
        },
        {
            "x": -2,
            "y": 4,
            "z": 1,
            "elements": [
                "unlimitedchiselworks:chisel_stonebrick2_railcraft_brick_bloodstained_0@2"
            ]
        },
        {
            "x": -1,
            "y": 3,
            "z": 6,
            "elements": [
                "chisel:bloodmagic@5"
            ]
        },
        {
            "x": 3,
            "y": 1,
            "z": 3,
            "elements": [
                "chisel:bloodmagic@3"
            ]
        },
        {
            "x": 3,
            "y": 1,
            "z": 4,
            "elements": [
                "railcraft:brick_bloodstained@1"
            ]
        },
        {
            "x": 3,
            "y": 5,
            "z": 4,
            "elements": [
                "railcraft:brick_bloodstained@1"
            ]
        },
        {
            "x": 3,
            "y": 5,
            "z": 3,
            "elements": [
                "chisel:bloodmagic@3"
            ]
        },
        {
            "x": 0,
            "y": 3,
            "z": 3,
            "elements": [
                "bloodmagic:demon_extras@12"
            ]
        },
        {
            "x": 3,
            "y": 5,
            "z": 2,
            "elements": [
                "railcraft:brick_bloodstained@1"
            ]
        },
        {
            "x": 1,
            "y": 1,
            "z": 0,
            "elements": [
                "railcraft:brick_bloodstained@1"
            ]
        },
        {
            "x": 1,
            "y": 1,
            "z": 6,
            "elements": [
                "railcraft:brick_bloodstained@1"
            ]
        },
        {
            "x": 3,
            "y": 2,
            "z": 4,
            "elements": [
                "chisel:bloodmagic@5"
            ]
        },
        {
            "x": 3,
            "y": 2,
            "z": 2,
            "elements": [
                "chisel:bloodmagic@5"
            ]
        },
        {
            "x": 0,
            "y": 5,
            "z": 2,
            "elements": [
                "contenttweaker:berserker_steel@0"
            ]
        },
        {
            "x": -2,
            "y": 5,
            "z": 1,
            "elements": [
                "unlimitedchiselworks:chisel_stonebrick2_railcraft_brick_bloodstained_0@2"
            ]
        },
        {
            "x": 0,
            "y": 5,
            "z": 3,
            "elements": [
                "bloodmagic:demon_extras@10"
            ]
        },
        {
            "x": 2,
            "y": 0,
            "z": 5,
            "elements": [
                "berserker_forge_input"
            ]
        },
        {
            "x": 0,
            "y": 5,
            "z": 4,
            "elements": [
                "contenttweaker:berserker_steel@0"
            ]
        },
        {
            "x": 0,
            "y": 5,
            "z": 6,
            "elements": [
                "chisel:bloodmagic@3"
            ]
        },
        {
            "x": -3,
            "y": 3,
            "z": 4,
            "elements": [
                "chisel:bloodmagic@5"
            ]
        },
        {
            "x": -2,
            "y": 5,
            "z": 5,
            "elements": [
                "unlimitedchiselworks:chisel_stonebrick2_railcraft_brick_bloodstained_0@2"
            ]
        },
        {
            "x": 0,
            "y": 5,
            "z": 0,
            "elements": [
                "chisel:bloodmagic@3"
            ]
        },
        {
            "x": -3,
            "y": 3,
            "z": 2,
            "elements": [
                "chisel:bloodmagic@5"
            ]
        },
        {
            "x": -3,
            "y": 6,
            "z": 3,
            "elements": [
                "chisel:bloodmagic@1"
            ]
        },
        {
            "x": 1,
            "y": 4,
            "z": 0,
            "elements": [
                "chisel:bloodmagic@5"
            ]
        },
        {
            "x": -3,
            "y": 6,
            "z": 2,
            "elements": [
                "chisel:bloodmagic@1"
            ]
        },
        {
            "x": 1,
            "y": 4,
            "z": 6,
            "elements": [
                "chisel:bloodmagic@5"
            ]
        },
        {
            "x": -2,
            "y": 2,
            "z": 1,
            "elements": [
                "unlimitedchiselworks:chisel_stonebrick2_railcraft_brick_bloodstained_0@2"
            ]
        },
        {
            "x": 2,
            "y": 0,
            "z": 2,
            "elements": [
                "chisel:bloodmagic@5"
            ]
        },
        {
            "x": 2,
            "y": 0,
            "z": 1,
            "elements": [
                "berserker_forge_input"
            ]
        },
        {
            "x": 2,
            "y": 0,
            "z": 4,
            "elements": [
                "chisel:bloodmagic@5"
            ]
        },
        {
            "x": -3,
            "y": 6,
            "z": 4,
            "elements": [
                "chisel:bloodmagic@1"
            ]
        },
        {
            "x": -2,
            "y": 2,
            "z": 5,
            "elements": [
                "unlimitedchiselworks:chisel_stonebrick2_railcraft_brick_bloodstained_0@2"
            ]
        },
        {
            "x": 2,
            "y": 0,
            "z": 3,
            "elements": [
                "chisel:bloodmagic@5"
            ]
        },
        {
            "x": 1,
            "y": 0,
            "z": 5,
            "elements": [
                "chisel:bloodmagic@5"
            ]
        },
        {
            "x": 1,
            "y": 0,
            "z": 4,
            "elements": [
                "chisel:bloodmagic@5"
            ]
        },
        {
            "x": 1,
            "y": 0,
            "z": 3,
            "elements": [
                "chisel:bloodmagic@3"
            ]
        },
        {
            "x": 1,
            "y": 0,
            "z": 2,
            "elements": [
                "chisel:bloodmagic@5"
            ]
        },
        {
            "x": -3,
            "y": 5,
            "z": 4,
            "elements": [
                "railcraft:brick_bloodstained@1"
            ]
        },
        {
            "x": 1,
            "y": 0,
            "z": 1,
            "elements": [
                "chisel:bloodmagic@5"
            ]
        },
        {
            "x": -3,
            "y": 5,
            "z": 3,
            "elements": [
                "chisel:bloodmagic@3"
            ]
        },
        {
            "x": 1,
            "y": 0,
            "z": 0,
            "elements": [
                "modularmachinery:blockwillproviderinput@0"
            ]
        },
        {
            "x": -3,
            "y": 5,
            "z": 2,
            "elements": [
                "railcraft:brick_bloodstained@1"
            ]
        },
        {
            "x": 3,
            "y": 6,
            "z": 3,
            "elements": [
                "chisel:bloodmagic@1"
            ]
        },
        {
            "x": 3,
            "y": 6,
            "z": 2,
            "elements": [
                "chisel:bloodmagic@1"
            ]
        },
        {
            "x": 3,
            "y": 6,
            "z": 4,
            "elements": [
                "chisel:bloodmagic@1"
            ]
        },
        {
            "x": 1,
            "y": 0,
            "z": 6,
            "elements": [
                "chisel:bloodmagic@1"
            ]
        },
        {
            "x": -2,
            "y": 6,
            "z": 4,
            "elements": [
                "chisel:bloodmagic@5"
            ]
        },
        {
            "x": -1,
            "y": 1,
            "z": 6,
            "elements": [
                "railcraft:brick_bloodstained@1"
            ]
        },
        {
            "x": -2,
            "y": 6,
            "z": 3,
            "elements": [
                "chisel:bloodmagic@5"
            ]
        },
        {
            "x": -2,
            "y": 6,
            "z": 5,
            "elements": [
                "chisel:bloodmagic@1"
            ]
        },
        {
            "x": 2,
            "y": 1,
            "z": 5,
            "elements": [
                "unlimitedchiselworks:chisel_stonebrick2_railcraft_brick_bloodstained_0@2"
            ]
        },
        {
            "x": -1,
            "y": 1,
            "z": 0,
            "elements": [
                "railcraft:brick_bloodstained@1"
            ]
        },
        {
            "x": -1,
            "y": 4,
            "z": 0,
            "elements": [
                "chisel:bloodmagic@5"
            ]
        },
        {
            "x": -1,
            "y": 4,
            "z": 6,
            "elements": [
                "chisel:bloodmagic@5"
            ]
        },
        {
            "x": 1,
            "y": 3,
            "z": 6,
            "elements": [
                "chisel:bloodmagic@5"
            ]
        },
        {
            "x": 2,
            "y": 1,
            "z": 1,
            "elements": [
                "unlimitedchiselworks:chisel_stonebrick2_railcraft_brick_bloodstained_0@2"
            ]
        },
        {
            "x": -2,
            "y": 3,
            "z": 5,
            "elements": [
                "unlimitedchiselworks:chisel_stonebrick2_railcraft_brick_bloodstained_0@2"
            ]
        },
        {
            "x": 0,
            "y": 2,
            "z": 3,
            "elements": [
                "bloodmagic:demon_extras@13"
            ]
        },
        {
            "x": -2,
            "y": 3,
            "z": 1,
            "elements": [
                "unlimitedchiselworks:chisel_stonebrick2_railcraft_brick_bloodstained_0@2"
            ]
        },
        {
            "x": -2,
            "y": 0,
            "z": 3,
            "elements": [
                "chisel:bloodmagic@5"
            ]
        },
        {
            "x": 2,
            "y": 5,
            "z": 5,
            "elements": [
                "unlimitedchiselworks:chisel_stonebrick2_railcraft_brick_bloodstained_0@2"
            ]
        },
        {
            "x": -2,
            "y": 0,
            "z": 4,
            "elements": [
                "chisel:bloodmagic@5"
            ]
        },
        {
            "x": -2,
            "y": 0,
            "z": 1,
            "elements": [
                "berserker_forge_input"
            ]
        },
        {
            "x": -2,
            "y": 0,
            "z": 2,
            "elements": [
                "chisel:bloodmagic@5"
            ]
        },
        {
            "x": 2,
            "y": 5,
            "z": 1,
            "elements": [
                "unlimitedchiselworks:chisel_stonebrick2_railcraft_brick_bloodstained_0@2"
            ]
        },
        {
            "x": -2,
            "y": 0,
            "z": 5,
            "elements": [
                "berserker_forge_input"
            ]
        },
        {
            "x": 1,
            "y": 3,
            "z": 0,
            "elements": [
                "chisel:bloodmagic@5"
            ]
        },
        {
            "x": 0,
            "y": 6,
            "z": 0,
            "elements": [
                "chisel:bloodmagic@1"
            ]
        },
        {
            "x": 1,
            "y": 6,
            "z": 6,
            "elements": [
                "chisel:bloodmagic@1"
            ]
        },
        {
            "x": 0,
            "y": 6,
            "z": 5,
            "elements": [
                "chisel:bloodmagic@5"
            ]
        },
        {
            "x": 0,
            "y": 6,
            "z": 6,
            "elements": [
                "chisel:bloodmagic@1"
            ]
        },
        {
            "x": 1,
            "y": 6,
            "z": 4,
            "elements": [
                "chisel:bloodmagic@5"
            ]
        },
        {
            "x": 1,
            "y": 6,
            "z": 5,
            "elements": [
                "chisel:bloodmagic@5"
            ]
        },
        {
            "x": 1,
            "y": 6,
            "z": 2,
            "elements": [
                "chisel:bloodmagic@5"
            ]
        },
        {
            "x": 0,
            "y": 6,
            "z": 1,
            "elements": [
                "chisel:bloodmagic@5"
            ]
        },
        {
            "x": 1,
            "y": 6,
            "z": 3,
            "elements": [
                "chisel:bloodmagic@3"
            ]
        },
        {
            "x": 0,
            "y": 6,
            "z": 2,
            "elements": [
                "chisel:bloodmagic@3"
            ]
        },
        {
            "x": -3,
            "y": 1,
            "z": 2,
            "elements": [
                "railcraft:brick_bloodstained@1"
            ]
        },
        {
            "x": 0,
            "y": 6,
            "z": 3,
            "elements": [
                "chisel:bloodmagic@3"
            ]
        },
        {
            "x": 1,
            "y": 6,
            "z": 0,
            "elements": [
                "chisel:bloodmagic@1"
            ]
        },
        {
            "x": 2,
            "y": 2,
            "z": 1,
            "elements": [
                "unlimitedchiselworks:chisel_stonebrick2_railcraft_brick_bloodstained_0@2"
            ]
        },
        {
            "x": -3,
            "y": 1,
            "z": 3,
            "elements": [
                "chisel:bloodmagic@3"
            ]
        },
        {
            "x": 0,
            "y": 6,
            "z": 4,
            "elements": [
                "chisel:bloodmagic@3"
            ]
        },
        {
            "x": 1,
            "y": 6,
            "z": 1,
            "elements": [
                "chisel:bloodmagic@5"
            ]
        },
        {
            "x": -3,
            "y": 1,
            "z": 4,
            "elements": [
                "railcraft:brick_bloodstained@1"
            ]
        },
        {
            "x": -1,
            "y": 0,
            "z": 3,
            "elements": [
                "chisel:bloodmagic@3"
            ]
        },
        {
            "x": -1,
            "y": 0,
            "z": 2,
            "elements": [
                "chisel:bloodmagic@5"
            ]
        },
        {
            "x": -1,
            "y": 5,
            "z": 0,
            "elements": [
                "railcraft:brick_bloodstained@1"
            ]
        },
        {
            "x": 3,
            "y": 0,
            "z": 4,
            "elements": [
                "chisel:bloodmagic@1"
            ]
        },
        {
            "x": -1,
            "y": 0,
            "z": 1,
            "elements": [
                "chisel:bloodmagic@5"
            ]
        },
        {
            "x": -1,
            "y": 0,
            "z": 0,
            "elements": [
                "modularmachinery:blockoutputbus@0"
            ]
        },
        {
            "x": -1,
            "y": 0,
            "z": 6,
            "elements": [
                "chisel:bloodmagic@1"
            ]
        },
        {
            "x": -1,
            "y": 0,
            "z": 5,
            "elements": [
                "chisel:bloodmagic@5"
            ]
        },
        {
            "x": -1,
            "y": 0,
            "z": 4,
            "elements": [
                "chisel:bloodmagic@5"
            ]
        },
        {
            "x": -3,
            "y": 4,
            "z": 4,
            "elements": [
                "chisel:bloodmagic@5"
            ]
        },
        {
            "x": 2,
            "y": 2,
            "z": 5,
            "elements": [
                "unlimitedchiselworks:chisel_stonebrick2_railcraft_brick_bloodstained_0@2"
            ]
        },
        {
            "x": -3,
            "y": 4,
            "z": 2,
            "elements": [
                "chisel:bloodmagic@5"
            ]
        },
        {
            "x": 3,
            "y": 0,
            "z": 2,
            "elements": [
                "chisel:bloodmagic@1"
            ]
        },
        {
            "x": 3,
            "y": 0,
            "z": 3,
            "elements": [
                "chisel:bloodmagic@1"
            ]
        },
        {
            "x": 2,
            "y": 4,
            "z": 1,
            "elements": [
                "unlimitedchiselworks:chisel_stonebrick2_railcraft_brick_bloodstained_0@2"
            ]
        },
        {
            "x": 2,
            "y": 4,
            "z": 5,
            "elements": [
                "unlimitedchiselworks:chisel_stonebrick2_railcraft_brick_bloodstained_0@2"
            ]
        },
        {
            "x": -1,
            "y": 2,
            "z": 6,
            "elements": [
                "chisel:bloodmagic@5"
            ]
        },
        {
            "x": -1,
            "y": 2,
            "z": 0,
            "elements": [
                "chisel:bloodmagic@5"
            ]
        },
        {
            "x": -3,
            "y": 2,
            "z": 2,
            "elements": [
                "chisel:bloodmagic@5"
            ]
        },
        {
            "x": -3,
            "y": 2,
            "z": 4,
            "elements": [
                "chisel:bloodmagic@5"
            ]
        },
        {
            "x": 0,
            "y": 4,
            "z": 3,
            "elements": [
                "bloodmagic:demon_extras@11"
            ]
        },
        {
            "x": -2,
            "y": 6,
            "z": 2,
            "elements": [
                "chisel:bloodmagic@5"
            ]
        },
        {
            "x": -2,
            "y": 6,
            "z": 1,
            "elements": [
                "chisel:bloodmagic@1"
            ]
        },
        {
            "x": 0,
            "y": 1,
            "z": 6,
            "elements": [
                "chisel:bloodmagic@3"
            ]
        },
        {
            "x": 0,
            "y": 1,
            "z": 0,
            "elements": [
                "chisel:bloodmagic@3"
            ]
        },
        {
            "x": 0,
            "y": 1,
            "z": 3,
            "elements": [
                "bloodmagic:demon_extras@14"
            ]
        },
        {
            "x": -1,
            "y": 5,
            "z": 6,
            "elements": [
                "railcraft:brick_bloodstained@1"
            ]
        },
        {
            "x": 3,
            "y": 3,
            "z": 4,
            "elements": [
                "chisel:bloodmagic@5"
            ]
        },
        {
            "x": -1,
            "y": 5,
            "z": 3,
            "elements": [
                "contenttweaker:berserker_steel@0"
            ]
        },
        {
            "x": 3,
            "y": 3,
            "z": 2,
            "elements": [
                "chisel:bloodmagic@5"
            ]
        }
    ]}