{
    "registryname": "blood_altar_ziggurat",
    "localizedname": "Blood Altar Ziggurat",
	"color": "ff0000",
    "parts": [
        {
            "x": -3,
            "y": -2,
            "z": 5,
            "elements": [
                "bloodmagic:blood_rune@0"
            ]
        },
        {
            "x": 5,
            "y": -2,
            "z": 1,
            "elements": [
                "bloodmagic:blood_rune@0"
            ]
        },
        {
            "x": 5,
            "y": -2,
            "z": -2,
            "elements": [
                "bloodmagic:blood_rune@0"
            ]
        },
        {
            "x": -8,
            "y": -4,
            "z": -11,
            "elements": [
                "bloodmagic:blood_rune@0"
            ]
        },
        {
            "x": -6,
            "y": -3,
            "z": 8,
            "elements": [
                "bloodmagic:blood_rune@0"
            ]
        },
        {
            "x": 2,
            "y": -2,
            "z": -5,
            "elements": [
                "bloodmagic:blood_rune@0"
            ]
        },
        {
            "x": 6,
            "y": -4,
            "z": 11,
            "elements": [
                "bloodmagic:blood_rune@0"
            ]
        },
        {
            "x": 11,
            "y": -3,
            "z": -11,
            "elements": [
                "minecraft:stonebrick@0"
            ]
        },
        {
            "x": -11,
            "y": -4,
            "z": -2,
            "elements": [
                "bloodmagic:blood_rune@0"
            ]
        },
        {
            "x": 11,
            "y": -4,
            "z": 2,
            "elements": [
                "bloodmagic:blood_rune@0"
            ]
        },
        {
            "x": 1,
            "y": 0,
            "z": 0,
            "elements": [
                "bloodmagic:blood_rune@0"
            ]
        },
        {
            "x": -5,
            "y": 3,
            "z": 5,
            "elements": [
                "bloodmagic:decorative_brick@1"
            ]
        },
        {
            "x": 11,
            "y": -2,
            "z": -11,
            "elements": [
                "minecraft:stonebrick@0"
            ]
        },
        {
            "x": -5,
            "y": -2,
            "z": 2,
            "elements": [
                "bloodmagic:blood_rune@0"
            ]
        },
        {
            "x": -7,
            "y": -4,
            "z": 11,
            "elements": [
                "bloodmagic:blood_rune@0"
            ]
        },
        {
            "x": -8,
            "y": -3,
            "z": -4,
            "elements": [
                "bloodmagic:blood_rune@0"
            ]
        },
        {
            "x": -11,
            "y": -4,
            "z": 2,
            "elements": [
                "bloodmagic:blood_rune@0"
            ]
        },
        {
            "x": -5,
            "y": -4,
            "z": -11,
            "elements": [
                "bloodmagic:blood_rune@0"
            ]
        },
        {
            "x": -6,
            "y": -3,
            "z": -8,
            "elements": [
                "bloodmagic:blood_rune@0"
            ]
        },
        {
            "x": 11,
            "y": -4,
            "z": 7,
            "elements": [
                "bloodmagic:blood_rune@0"
            ]
        },
        {
            "x": 1,
            "y": -2,
            "z": -5,
            "elements": [
                "bloodmagic:blood_rune@0"
            ]
        },
        {
            "x": 11,
            "y": -1,
            "z": -11,
            "elements": [
                "minecraft:stonebrick@0"
            ]
        },
        {
            "x": 9,
            "y": -4,
            "z": 11,
            "elements": [
                "bloodmagic:blood_rune@0"
            ]
        },
        {
            "x": 8,
            "y": -3,
            "z": -4,
            "elements": [
                "bloodmagic:blood_rune@0"
            ]
        },
        {
            "x": 3,
            "y": 1,
            "z": 3,
            "elements": [
                "minecraft:stonebrick@0"
            ]
        },
        {
            "x": 1,
            "y": -1,
            "z": 3,
            "elements": [
                "bloodmagic:blood_rune@0"
            ]
        },
        {
            "x": -1,
            "y": -2,
            "z": 5,
            "elements": [
                "bloodmagic:blood_rune@0"
            ]
        },
        {
            "x": -5,
            "y": 0,
            "z": 5,
            "elements": [
                "minecraft:stonebrick@0"
            ]
        },
        {
            "x": -11,
            "y": -4,
            "z": -5,
            "elements": [
                "bloodmagic:blood_rune@0"
            ]
        },
        {
            "x": -11,
            "y": -4,
            "z": 9,
            "elements": [
                "bloodmagic:blood_rune@0"
            ]
        },
        {
            "x": 0,
            "y": -4,
            "z": 11,
            "elements": [
                "bloodmagic:blood_rune@0"
            ]
        },
        {
            "x": 11,
            "y": -4,
            "z": -4,
            "elements": [
                "bloodmagic:blood_rune@0"
            ]
        },
        {
            "x": 11,
            "y": -4,
            "z": 3,
            "elements": [
                "bloodmagic:blood_rune@0"
            ]
        },
        {
            "x": -11,
            "y": 4,
            "z": 11,
            "elements": [
                "bloodmagic:decorative_brick@3"
            ]
        },
        {
            "x": -5,
            "y": 2,
            "z": 5,
            "elements": [
                "minecraft:stonebrick@0"
            ]
        },
        {
            "x": -5,
            "y": 1,
            "z": 5,
            "elements": [
                "minecraft:stonebrick@0"
            ]
        },
        {
            "x": -8,
            "y": -3,
            "z": 4,
            "elements": [
                "bloodmagic:blood_rune@0"
            ]
        },
        {
            "x": 2,
            "y": -4,
            "z": -11,
            "elements": [
                "bloodmagic:blood_rune@0"
            ]
        },
        {
            "x": -1,
            "y": 0,
            "z": 0,
            "elements": [
                "bloodmagic:blood_rune@0"
            ]
        },
        {
            "x": 0,
            "y": -3,
            "z": 8,
            "elements": [
                "bloodmagic:blood_rune@0"
            ]
        },
        {
            "x": 1,
            "y": -3,
            "z": -8,
            "elements": [
                "bloodmagic:blood_rune@0"
            ]
        },
        {
            "x": 8,
            "y": -3,
            "z": 1,
            "elements": [
                "bloodmagic:blood_rune@0"
            ]
        },
        {
            "x": 8,
            "y": -4,
            "z": -11,
            "elements": [
                "bloodmagic:blood_rune@0"
            ]
        },
        {
            "x": 8,
            "y": -3,
            "z": -1,
            "elements": [
                "bloodmagic:blood_rune@0"
            ]
        },
        {
            "x": 5,
            "y": 1,
            "z": -5,
            "elements": [
                "minecraft:stonebrick@0"
            ]
        },
        {
            "x": -5,
            "y": -2,
            "z": 3,
            "elements": [
                "bloodmagic:blood_rune@0"
            ]
        },
        {
            "x": -3,
            "y": 0,
            "z": -3,
            "elements": [
                "minecraft:stonebrick@0"
            ]
        },
        {
            "x": 2,
            "y": -1,
            "z": 3,
            "elements": [
                "bloodmagic:blood_rune@0"
            ]
        },
        {
            "x": 3,
            "y": 0,
            "z": 3,
            "elements": [
                "minecraft:stonebrick@0"
            ]
        },
        {
            "x": 5,
            "y": 0,
            "z": -5,
            "elements": [
                "minecraft:stonebrick@0"
            ]
        },
        {
            "x": -8,
            "y": -3,
            "z": 1,
            "elements": [
                "bloodmagic:blood_rune@0"
            ]
        },
        {
            "x": 0,
            "y": -3,
            "z": -8,
            "elements": [
                "bloodmagic:blood_rune@0"
            ]
        },
        {
            "x": -8,
            "y": -3,
            "z": -1,
            "elements": [
                "bloodmagic:blood_rune@0"
            ]
        },
        {
            "x": -1,
            "y": -4,
            "z": 11,
            "elements": [
                "bloodmagic:blood_rune@0"
            ]
        },
        {
            "x": 1,
            "y": -4,
            "z": -11,
            "elements": [
                "bloodmagic:blood_rune@0"
            ]
        },
        {
            "x": 11,
            "y": 4,
            "z": 11,
            "elements": [
                "bloodmagic:decorative_brick@3"
            ]
        },
        {
            "x": 1,
            "y": -3,
            "z": 8,
            "elements": [
                "bloodmagic:blood_rune@0"
            ]
        },
        {
            "x": 5,
            "y": -2,
            "z": 2,
            "elements": [
                "bloodmagic:blood_rune@0"
            ]
        },
        {
            "x": -1,
            "y": -2,
            "z": -5,
            "elements": [
                "bloodmagic:blood_rune@0"
            ]
        },
        {
            "x": 11,
            "y": -4,
            "z": -7,
            "elements": [
                "bloodmagic:blood_rune@0"
            ]
        },
        {
            "x": 7,
            "y": -4,
            "z": -11,
            "elements": [
                "bloodmagic:blood_rune@0"
            ]
        },
        {
            "x": 11,
            "y": 2,
            "z": 11,
            "elements": [
                "minecraft:stonebrick@0"
            ]
        },
        {
            "x": 1,
            "y": -2,
            "z": 5,
            "elements": [
                "bloodmagic:blood_rune@0"
            ]
        },
        {
            "x": 11,
            "y": 3,
            "z": 11,
            "elements": [
                "minecraft:stonebrick@0"
            ]
        },
        {
            "x": 1,
            "y": 0,
            "z": 1,
            "elements": [
                "bloodmagic:blood_rune@0"
            ]
        },
        {
            "x": 3,
            "y": -1,
            "z": 0,
            "elements": [
                "bloodmagic:blood_rune@0"
            ]
        },
        {
            "x": -6,
            "y": -4,
            "z": 11,
            "elements": [
                "bloodmagic:blood_rune@0"
            ]
        },
        {
            "x": -11,
            "y": -4,
            "z": 3,
            "elements": [
                "bloodmagic:blood_rune@0"
            ]
        },
        {
            "x": 11,
            "y": -4,
            "z": -1,
            "elements": [
                "bloodmagic:blood_rune@0"
            ]
        },
        {
            "x": -11,
            "y": -4,
            "z": 4,
            "elements": [
                "bloodmagic:blood_rune@0"
            ]
        },
        {
            "x": -2,
            "y": -3,
            "z": 8,
            "elements": [
                "bloodmagic:blood_rune@0"
            ]
        },
        {
            "x": 4,
            "y": -4,
            "z": -11,
            "elements": [
                "bloodmagic:blood_rune@0"
            ]
        },
        {
            "x": 3,
            "y": -3,
            "z": -8,
            "elements": [
                "bloodmagic:blood_rune@0"
            ]
        },
        {
            "x": -11,
            "y": 3,
            "z": -11,
            "elements": [
                "minecraft:stonebrick@0"
            ]
        },
        {
            "x": 11,
            "y": 0,
            "z": 11,
            "elements": [
                "minecraft:stonebrick@0"
            ]
        },
        {
            "x": 11,
            "y": -4,
            "z": 5,
            "elements": [
                "bloodmagic:blood_rune@0"
            ]
        },
        {
            "x": 8,
            "y": -3,
            "z": 4,
            "elements": [
                "bloodmagic:blood_rune@0"
            ]
        },
        {
            "x": 3,
            "y": 2,
            "z": 3,
            "elements": [
                "minecraft:glowstone@0"
            ]
        },
        {
            "x": -9,
            "y": -4,
            "z": -11,
            "elements": [
                "bloodmagic:blood_rune@0"
            ]
        },
        {
            "x": 5,
            "y": -2,
            "z": 3,
            "elements": [
                "bloodmagic:blood_rune@0"
            ]
        },
        {
            "x": -3,
            "y": -4,
            "z": 11,
            "elements": [
                "bloodmagic:blood_rune@0"
            ]
        },
        {
            "x": -3,
            "y": -1,
            "z": 0,
            "elements": [
                "bloodmagic:blood_rune@0"
            ]
        },
        {
            "x": 11,
            "y": 1,
            "z": 11,
            "elements": [
                "minecraft:stonebrick@0"
            ]
        },
        {
            "x": -5,
            "y": -3,
            "z": 8,
            "elements": [
                "bloodmagic:blood_rune@0"
            ]
        },
        {
            "x": -5,
            "y": -2,
            "z": -1,
            "elements": [
                "bloodmagic:blood_rune@0"
            ]
        },
        {
            "x": -11,
            "y": -4,
            "z": -4,
            "elements": [
                "bloodmagic:blood_rune@0"
            ]
        },
        {
            "x": 6,
            "y": -3,
            "z": -8,
            "elements": [
                "bloodmagic:blood_rune@0"
            ]
        },
        {
            "x": -3,
            "y": -2,
            "z": -5,
            "elements": [
                "bloodmagic:blood_rune@0"
            ]
        },
        {
            "x": -11,
            "y": 1,
            "z": -11,
            "elements": [
                "minecraft:stonebrick@0"
            ]
        },
        {
            "x": 3,
            "y": -1,
            "z": -2,
            "elements": [
                "bloodmagic:blood_rune@0"
            ]
        },
        {
            "x": 8,
            "y": -3,
            "z": 3,
            "elements": [
                "bloodmagic:blood_rune@0"
            ]
        },
        {
            "x": 11,
            "y": -4,
            "z": -6,
            "elements": [
                "bloodmagic:blood_rune@0"
            ]
        },
        {
            "x": -5,
            "y": 3,
            "z": -5,
            "elements": [
                "bloodmagic:decorative_brick@1"
            ]
        },
        {
            "x": -11,
            "y": -1,
            "z": -11,
            "elements": [
                "minecraft:stonebrick@0"
            ]
        },
        {
            "x": 11,
            "y": -4,
            "z": -3,
            "elements": [
                "bloodmagic:blood_rune@0"
            ]
        },
        {
            "x": -4,
            "y": -4,
            "z": 11,
            "elements": [
                "bloodmagic:blood_rune@0"
            ]
        },
        {
            "x": -11,
            "y": -4,
            "z": -1,
            "elements": [
                "bloodmagic:blood_rune@0"
            ]
        },
        {
            "x": -5,
            "y": -1,
            "z": 5,
            "elements": [
                "minecraft:stonebrick@0"
            ]
        },
        {
            "x": -8,
            "y": -3,
            "z": 3,
            "elements": [
                "bloodmagic:blood_rune@0"
            ]
        },
        {
            "x": 11,
            "y": -3,
            "z": 11,
            "elements": [
                "minecraft:stonebrick@0"
            ]
        },
        {
            "x": -5,
            "y": 2,
            "z": -5,
            "elements": [
                "minecraft:stonebrick@0"
            ]
        },
        {
            "x": -11,
            "y": -2,
            "z": -11,
            "elements": [
                "minecraft:stonebrick@0"
            ]
        },
        {
            "x": -11,
            "y": 0,
            "z": -11,
            "elements": [
                "minecraft:stonebrick@0"
            ]
        },
        {
            "x": -4,
            "y": -3,
            "z": 8,
            "elements": [
                "bloodmagic:blood_rune@0"
            ]
        },
        {
            "x": 8,
            "y": -3,
            "z": -3,
            "elements": [
                "bloodmagic:blood_rune@0"
            ]
        },
        {
            "x": 5,
            "y": -3,
            "z": -8,
            "elements": [
                "bloodmagic:blood_rune@0"
            ]
        },
        {
            "x": 11,
            "y": -2,
            "z": 11,
            "elements": [
                "minecraft:stonebrick@0"
            ]
        },
        {
            "x": 0,
            "y": -2,
            "z": -5,
            "elements": [
                "bloodmagic:blood_rune@0"
            ]
        },
        {
            "x": 3,
            "y": -1,
            "z": 1,
            "elements": [
                "bloodmagic:blood_rune@0"
            ]
        },
        {
            "x": -2,
            "y": -2,
            "z": 5,
            "elements": [
                "bloodmagic:blood_rune@0"
            ]
        },
        {
            "x": -11,
            "y": -3,
            "z": -11,
            "elements": [
                "minecraft:stonebrick@0"
            ]
        },
        {
            "x": -11,
            "y": -4,
            "z": 7,
            "elements": [
                "bloodmagic:blood_rune@0"
            ]
        },
        {
            "x": -5,
            "y": -4,
            "z": 11,
            "elements": [
                "bloodmagic:blood_rune@0"
            ]
        },
        {
            "x": -11,
            "y": 2,
            "z": -11,
            "elements": [
                "minecraft:stonebrick@0"
            ]
        },
        {
            "x": 5,
            "y": -2,
            "z": -1,
            "elements": [
                "bloodmagic:blood_rune@0"
            ]
        },
        {
            "x": 11,
            "y": -1,
            "z": 11,
            "elements": [
                "minecraft:stonebrick@0"
            ]
        },
        {
            "x": -3,
            "y": -3,
            "z": 8,
            "elements": [
                "bloodmagic:blood_rune@0"
            ]
        },
        {
            "x": 5,
            "y": -4,
            "z": -11,
            "elements": [
                "bloodmagic:blood_rune@0"
            ]
        },
        {
            "x": 3,
            "y": -2,
            "z": -5,
            "elements": [
                "bloodmagic:blood_rune@0"
            ]
        },
        {
            "x": 11,
            "y": -4,
            "z": 4,
            "elements": [
                "bloodmagic:blood_rune@0"
            ]
        },
        {
            "x": 4,
            "y": -3,
            "z": -8,
            "elements": [
                "bloodmagic:blood_rune@0"
            ]
        },
        {
            "x": 11,
            "y": -4,
            "z": -9,
            "elements": [
                "bloodmagic:blood_rune@0"
            ]
        },
        {
            "x": -11,
            "y": -4,
            "z": -8,
            "elements": [
                "bloodmagic:blood_rune@0"
            ]
        },
        {
            "x": 5,
            "y": -3,
            "z": 8,
            "elements": [
                "bloodmagic:blood_rune@0"
            ]
        },
        {
            "x": 5,
            "y": 1,
            "z": 5,
            "elements": [
                "minecraft:stonebrick@0"
            ]
        },
        {
            "x": -8,
            "y": -3,
            "z": 6,
            "elements": [
                "bloodmagic:blood_rune@0"
            ]
        },
        {
            "x": 5,
            "y": 2,
            "z": 5,
            "elements": [
                "minecraft:stonebrick@0"
            ]
        },
        {
            "x": -11,
            "y": -4,
            "z": 6,
            "elements": [
                "bloodmagic:blood_rune@0"
            ]
        },
        {
            "x": 11,
            "y": -4,
            "z": -5,
            "elements": [
                "bloodmagic:blood_rune@0"
            ]
        },
        {
            "x": 5,
            "y": 0,
            "z": 5,
            "elements": [
                "minecraft:stonebrick@0"
            ]
        },
        {
            "x": 8,
            "y": -3,
            "z": 0,
            "elements": [
                "bloodmagic:blood_rune@0"
            ]
        },
        {
            "x": -1,
            "y": -3,
            "z": -8,
            "elements": [
                "bloodmagic:blood_rune@0"
            ]
        },
        {
            "x": -2,
            "y": -4,
            "z": 11,
            "elements": [
                "bloodmagic:blood_rune@0"
            ]
        },
        {
            "x": 8,
            "y": -3,
            "z": 6,
            "elements": [
                "bloodmagic:blood_rune@0"
            ]
        },
        {
            "x": -3,
            "y": -1,
            "z": 1,
            "elements": [
                "bloodmagic:blood_rune@0"
            ]
        },
        {
            "x": 0,
            "y": -4,
            "z": -11,
            "elements": [
                "bloodmagic:blood_rune@0"
            ]
        },
        {
            "x": 5,
            "y": -1,
            "z": 5,
            "elements": [
                "minecraft:stonebrick@0"
            ]
        },
        {
            "x": -3,
            "y": -1,
            "z": -2,
            "elements": [
                "bloodmagic:blood_rune@0"
            ]
        },
        {
            "x": -5,
            "y": -2,
            "z": -3,
            "elements": [
                "bloodmagic:blood_rune@0"
            ]
        },
        {
            "x": -11,
            "y": -4,
            "z": 8,
            "elements": [
                "bloodmagic:blood_rune@0"
            ]
        },
        {
            "x": 2,
            "y": -3,
            "z": 8,
            "elements": [
                "bloodmagic:blood_rune@0"
            ]
        },
        {
            "x": 6,
            "y": -4,
            "z": -11,
            "elements": [
                "bloodmagic:blood_rune@0"
            ]
        },
        {
            "x": -5,
            "y": 1,
            "z": -5,
            "elements": [
                "minecraft:stonebrick@0"
            ]
        },
        {
            "x": -8,
            "y": -3,
            "z": 5,
            "elements": [
                "bloodmagic:blood_rune@0"
            ]
        },
        {
            "x": 0,
            "y": -1,
            "z": 3,
            "elements": [
                "bloodmagic:blood_rune@0"
            ]
        },
        {
            "x": -8,
            "y": -3,
            "z": -3,
            "elements": [
                "bloodmagic:blood_rune@0"
            ]
        },
        {
            "x": -11,
            "y": -4,
            "z": -9,
            "elements": [
                "bloodmagic:blood_rune@0"
            ]
        },
        {
            "x": 3,
            "y": -1,
            "z": 2,
            "elements": [
                "bloodmagic:blood_rune@0"
            ]
        },
        {
            "x": 0,
            "y": 0,
            "z": 1,
            "elements": [
                "bloodmagic:blood_rune@0"
            ]
        },
        {
            "x": 11,
            "y": 4,
            "z": -11,
            "elements": [
                "bloodmagic:decorative_brick@3"
            ]
        },
        {
            "x": 11,
            "y": -4,
            "z": 8,
            "elements": [
                "bloodmagic:blood_rune@0"
            ]
        },
        {
            "x": -2,
            "y": -1,
            "z": -3,
            "elements": [
                "bloodmagic:blood_rune@0"
            ]
        },
        {
            "x": 1,
            "y": -4,
            "z": 11,
            "elements": [
                "bloodmagic:blood_rune@0"
            ]
        },
        {
            "x": -1,
            "y": -3,
            "z": 8,
            "elements": [
                "bloodmagic:blood_rune@0"
            ]
        },
        {
            "x": 3,
            "y": -4,
            "z": -11,
            "elements": [
                "bloodmagic:blood_rune@0"
            ]
        },
        {
            "x": -5,
            "y": 0,
            "z": -5,
            "elements": [
                "minecraft:stonebrick@0"
            ]
        },
        {
            "x": 2,
            "y": -3,
            "z": -8,
            "elements": [
                "bloodmagic:blood_rune@0"
            ]
        },
        {
            "x": -8,
            "y": -3,
            "z": 0,
            "elements": [
                "bloodmagic:blood_rune@0"
            ]
        },
        {
            "x": 9,
            "y": -4,
            "z": -11,
            "elements": [
                "bloodmagic:blood_rune@0"
            ]
        },
        {
            "x": -1,
            "y": 0,
            "z": 1,
            "elements": [
                "bloodmagic:blood_rune@0"
            ]
        },
        {
            "x": -8,
            "y": -2,
            "z": 8,
            "elements": [
                "minecraft:beacon@0"
            ]
        },
        {
            "x": -8,
            "y": -4,
            "z": 11,
            "elements": [
                "bloodmagic:blood_rune@0"
            ]
        },
        {
            "x": 0,
            "y": 0,
            "z": -1,
            "elements": [
                "bloodmagic:blood_rune@0"
            ]
        },
        {
            "x": 3,
            "y": 2,
            "z": -3,
            "elements": [
                "minecraft:glowstone@0"
            ]
        },
        {
            "x": 8,
            "y": -2,
            "z": -8,
            "elements": [
                "minecraft:beacon@0"
            ]
        },
        {
            "x": -11,
            "y": -4,
            "z": 5,
            "elements": [
                "bloodmagic:blood_rune@0"
            ]
        },
        {
            "x": -6,
            "y": -4,
            "z": -11,
            "elements": [
                "bloodmagic:blood_rune@0"
            ]
        },
        {
            "x": 8,
            "y": -4,
            "z": 11,
            "elements": [
                "bloodmagic:blood_rune@0"
            ]
        },
        {
            "x": 8,
            "y": -3,
            "z": 5,
            "elements": [
                "bloodmagic:blood_rune@0"
            ]
        },
        {
            "x": 3,
            "y": 1,
            "z": -3,
            "elements": [
                "minecraft:stonebrick@0"
            ]
        },
        {
            "x": -8,
            "y": -2,
            "z": -8,
            "elements": [
                "minecraft:beacon@0"
            ]
        },
        {
            "x": 2,
            "y": -2,
            "z": 5,
            "elements": [
                "bloodmagic:blood_rune@0"
            ]
        },
        {
            "x": 11,
            "y": -4,
            "z": 6,
            "elements": [
                "bloodmagic:blood_rune@0"
            ]
        },
        {
            "x": -8,
            "y": -3,
            "z": -6,
            "elements": [
                "bloodmagic:blood_rune@0"
            ]
        },
        {
            "x": -11,
            "y": 4,
            "z": -11,
            "elements": [
                "bloodmagic:decorative_brick@3"
            ]
        },
        {
            "x": 8,
            "y": -3,
            "z": -6,
            "elements": [
                "bloodmagic:blood_rune@0"
            ]
        },
        {
            "x": -5,
            "y": -2,
            "z": 0,
            "elements": [
                "bloodmagic:blood_rune@0"
            ]
        },
        {
            "x": -9,
            "y": -4,
            "z": 11,
            "elements": [
                "bloodmagic:blood_rune@0"
            ]
        },
        {
            "x": 11,
            "y": -4,
            "z": 9,
            "elements": [
                "bloodmagic:blood_rune@0"
            ]
        },
        {
            "x": 5,
            "y": -2,
            "z": -3,
            "elements": [
                "bloodmagic:blood_rune@0"
            ]
        },
        {
            "x": -7,
            "y": -4,
            "z": -11,
            "elements": [
                "bloodmagic:blood_rune@0"
            ]
        },
        {
            "x": 5,
            "y": 2,
            "z": -5,
            "elements": [
                "minecraft:stonebrick@0"
            ]
        },
        {
            "x": -3,
            "y": -1,
            "z": 2,
            "elements": [
                "bloodmagic:blood_rune@0"
            ]
        },
        {
            "x": -1,
            "y": 0,
            "z": -1,
            "elements": [
                "bloodmagic:blood_rune@0"
            ]
        },
        {
            "x": 5,
            "y": 3,
            "z": 5,
            "elements": [
                "bloodmagic:decorative_brick@1"
            ]
        },
        {
            "x": 8,
            "y": -2,
            "z": 8,
            "elements": [
                "minecraft:beacon@0"
            ]
        },
        {
            "x": 5,
            "y": 3,
            "z": -5,
            "elements": [
                "bloodmagic:decorative_brick@1"
            ]
        },
        {
            "x": 7,
            "y": -4,
            "z": 11,
            "elements": [
                "bloodmagic:blood_rune@0"
            ]
        },
        {
            "x": 8,
            "y": -3,
            "z": -2,
            "elements": [
                "bloodmagic:blood_rune@0"
            ]
        },
        {
            "x": -3,
            "y": 1,
            "z": 3,
            "elements": [
                "minecraft:stonebrick@0"
            ]
        },
        {
            "x": -11,
            "y": 1,
            "z": 11,
            "elements": [
                "minecraft:stonebrick@0"
            ]
        },
        {
            "x": -1,
            "y": -1,
            "z": 3,
            "elements": [
                "bloodmagic:blood_rune@0"
            ]
        },
        {
            "x": -11,
            "y": -1,
            "z": 11,
            "elements": [
                "minecraft:stonebrick@0"
            ]
        },
        {
            "x": -11,
            "y": -2,
            "z": 11,
            "elements": [
                "minecraft:stonebrick@0"
            ]
        },
        {
            "x": -3,
            "y": 2,
            "z": -3,
            "elements": [
                "minecraft:glowstone@0"
            ]
        },
        {
            "x": -4,
            "y": -4,
            "z": -11,
            "elements": [
                "bloodmagic:blood_rune@0"
            ]
        },
        {
            "x": -3,
            "y": 2,
            "z": 3,
            "elements": [
                "minecraft:glowstone@0"
            ]
        },
        {
            "x": -1,
            "y": -1,
            "z": -3,
            "elements": [
                "bloodmagic:blood_rune@0"
            ]
        },
        {
            "x": -8,
            "y": -3,
            "z": -2,
            "elements": [
                "bloodmagic:blood_rune@0"
            ]
        },
        {
            "x": -11,
            "y": -4,
            "z": 0,
            "elements": [
                "bloodmagic:blood_rune@0"
            ]
        },
        {
            "x": -5,
            "y": -3,
            "z": -8,
            "elements": [
                "bloodmagic:blood_rune@0"
            ]
        },
        {
            "x": 2,
            "y": -4,
            "z": 11,
            "elements": [
                "bloodmagic:blood_rune@0"
            ]
        },
        {
            "x": -3,
            "y": 1,
            "z": -3,
            "elements": [
                "minecraft:stonebrick@0"
            ]
        },
        {
            "x": -2,
            "y": -2,
            "z": -5,
            "elements": [
                "bloodmagic:blood_rune@0"
            ]
        },
        {
            "x": -11,
            "y": 0,
            "z": 11,
            "elements": [
                "minecraft:stonebrick@0"
            ]
        },
        {
            "x": 3,
            "y": -1,
            "z": -1,
            "elements": [
                "bloodmagic:blood_rune@0"
            ]
        },
        {
            "x": 6,
            "y": -3,
            "z": 8,
            "elements": [
                "bloodmagic:blood_rune@0"
            ]
        },
        {
            "x": -11,
            "y": 3,
            "z": 11,
            "elements": [
                "minecraft:stonebrick@0"
            ]
        },
        {
            "x": 0,
            "y": -2,
            "z": 5,
            "elements": [
                "bloodmagic:blood_rune@0"
            ]
        },
        {
            "x": 5,
            "y": -1,
            "z": -5,
            "elements": [
                "minecraft:stonebrick@0"
            ]
        },
        {
            "x": 11,
            "y": -4,
            "z": -8,
            "elements": [
                "bloodmagic:blood_rune@0"
            ]
        },
        {
            "x": 8,
            "y": -3,
            "z": 2,
            "elements": [
                "bloodmagic:blood_rune@0"
            ]
        },
        {
            "x": 3,
            "y": 0,
            "z": -3,
            "elements": [
                "minecraft:stonebrick@0"
            ]
        },
        {
            "x": -11,
            "y": 2,
            "z": 11,
            "elements": [
                "minecraft:stonebrick@0"
            ]
        },
        {
            "x": -2,
            "y": -3,
            "z": -8,
            "elements": [
                "bloodmagic:blood_rune@0"
            ]
        },
        {
            "x": 1,
            "y": 0,
            "z": -1,
            "elements": [
                "bloodmagic:blood_rune@0"
            ]
        },
        {
            "x": -11,
            "y": -3,
            "z": 11,
            "elements": [
                "minecraft:stonebrick@0"
            ]
        },
        {
            "x": -11,
            "y": -4,
            "z": -7,
            "elements": [
                "bloodmagic:blood_rune@0"
            ]
        },
        {
            "x": -1,
            "y": -4,
            "z": -11,
            "elements": [
                "bloodmagic:blood_rune@0"
            ]
        },
        {
            "x": -11,
            "y": -4,
            "z": -3,
            "elements": [
                "bloodmagic:blood_rune@0"
            ]
        },
        {
            "x": 2,
            "y": -1,
            "z": -3,
            "elements": [
                "bloodmagic:blood_rune@0"
            ]
        },
        {
            "x": -5,
            "y": -2,
            "z": 1,
            "elements": [
                "bloodmagic:blood_rune@0"
            ]
        },
        {
            "x": -3,
            "y": 0,
            "z": 3,
            "elements": [
                "minecraft:stonebrick@0"
            ]
        },
        {
            "x": 5,
            "y": -4,
            "z": 11,
            "elements": [
                "bloodmagic:blood_rune@0"
            ]
        },
        {
            "x": 3,
            "y": -3,
            "z": 8,
            "elements": [
                "bloodmagic:blood_rune@0"
            ]
        },
        {
            "x": -8,
            "y": -3,
            "z": 2,
            "elements": [
                "bloodmagic:blood_rune@0"
            ]
        },
        {
            "x": 11,
            "y": -4,
            "z": 0,
            "elements": [
                "bloodmagic:blood_rune@0"
            ]
        },
        {
            "x": 11,
            "y": 3,
            "z": -11,
            "elements": [
                "minecraft:stonebrick@0"
            ]
        },
        {
            "x": -5,
            "y": -2,
            "z": -2,
            "elements": [
                "bloodmagic:blood_rune@0"
            ]
        },
        {
            "x": 3,
            "y": -2,
            "z": 5,
            "elements": [
                "bloodmagic:blood_rune@0"
            ]
        },
        {
            "x": -8,
            "y": -3,
            "z": -5,
            "elements": [
                "bloodmagic:blood_rune@0"
            ]
        },
        {
            "x": -11,
            "y": -4,
            "z": 1,
            "elements": [
                "bloodmagic:blood_rune@0"
            ]
        },
        {
            "x": -3,
            "y": -3,
            "z": -8,
            "elements": [
                "bloodmagic:blood_rune@0"
            ]
        },
        {
            "x": 4,
            "y": -4,
            "z": 11,
            "elements": [
                "bloodmagic:blood_rune@0"
            ]
        },
        {
            "x": 11,
            "y": 2,
            "z": -11,
            "elements": [
                "minecraft:stonebrick@0"
            ]
        },
        {
            "x": -2,
            "y": -4,
            "z": -11,
            "elements": [
                "bloodmagic:blood_rune@0"
            ]
        },
        {
            "x": 1,
            "y": -1,
            "z": -3,
            "elements": [
                "bloodmagic:blood_rune@0"
            ]
        },
        {
            "x": 8,
            "y": -3,
            "z": -5,
            "elements": [
                "bloodmagic:blood_rune@0"
            ]
        },
        {
            "x": 5,
            "y": -2,
            "z": 0,
            "elements": [
                "bloodmagic:blood_rune@0"
            ]
        },
        {
            "x": 4,
            "y": -3,
            "z": 8,
            "elements": [
                "bloodmagic:blood_rune@0"
            ]
        },
        {
            "x": -2,
            "y": -1,
            "z": 3,
            "elements": [
                "bloodmagic:blood_rune@0"
            ]
        },
        {
            "x": 11,
            "y": 1,
            "z": -11,
            "elements": [
                "minecraft:stonebrick@0"
            ]
        },
        {
            "x": 11,
            "y": 0,
            "z": -11,
            "elements": [
                "minecraft:stonebrick@0"
            ]
        },
        {
            "x": -5,
            "y": -1,
            "z": -5,
            "elements": [
                "minecraft:stonebrick@0"
            ]
        },
        {
            "x": -3,
            "y": -1,
            "z": -1,
            "elements": [
                "bloodmagic:blood_rune@0"
            ]
        },
        {
            "x": -11,
            "y": -4,
            "z": -6,
            "elements": [
                "bloodmagic:blood_rune@0"
            ]
        },
        {
            "x": 11,
            "y": -4,
            "z": 1,
            "elements": [
                "bloodmagic:blood_rune@0"
            ]
        },
        {
            "x": -3,
            "y": -4,
            "z": -11,
            "elements": [
                "bloodmagic:blood_rune@0"
            ]
        },
        {
            "x": 11,
            "y": -4,
            "z": -2,
            "elements": [
                "bloodmagic:blood_rune@0"
            ]
        },
        {
            "x": 0,
            "y": -1,
            "z": -3,
            "elements": [
                "bloodmagic:blood_rune@0"
            ]
        },
        {
            "x": -4,
            "y": -3,
            "z": -8,
            "elements": [
                "bloodmagic:blood_rune@0"
            ]
        },
        {
            "x": 3,
            "y": -4,
            "z": 11,
            "elements": [
                "bloodmagic:blood_rune@0"
            ]
        }
    ]}