{
    "registryname": "induction_electrolyzer",
    "localizedname": "感应电解机",
	"color": "636363",
    "parts": [
        {
            "x": 1,
            "y": 0,
            "z": 4,
            "elements": [
                "nuclearcraft:fission_block@0"
            ]
        },
        {
            "x": 1,
            "y": 0,
            "z": 3,
            "elements": [
                "both_item_fluid_output"
            ]
        },
        {
            "x": 1,
            "y": 0,
            "z": 2,
            "elements": [
                "nuclearcraft:fission_block@0"
            ]
        },
        {
            "x": 1,
            "y": 0,
            "z": 1,
            "elements": [
                "both_item_fluid_output"
            ]
        },
        {
            "x": 1,
            "y": 0,
            "z": 0,
            "elements": [
                "nuclearcraft:fission_block@0"
            ]
        },
        {
            "x": -1,
            "y": 1,
            "z": 3,
            "nbt": {"id":"nuclearcraft:fusion_electromagnet""ForgeCaps":{"abyssalcraft:itemtransfer":{"configurations":[]"isRunning":"0b"}"nuclearcraft:capability_default_radiation_resistance":{"radiationResistance":"0.0d"}},"isRedstonePowered":"0b","alternateComparator":"0b","redstoneControl":"0b","radiationLevel":"0.0d","energy":"0","capacity":"256000","maxTransfer":"64000","energyConnections0":"0","energyConnections1":"0","energyConnections2":"0","energyConnections3":"0","energyConnections4":"0","energyConnections5":"0","tank0":{"fluidAmount":"0""fluidName":"nullFluid"},"fluidConnection0":{"sorption0":"3"},"fluidConnection1":{"sorption0":"3"},"fluidConnection2":{"sorption0":"3"},"fluidConnection3":{"sorption0":"3"},"fluidConnection4":{"sorption0":"3"},"fluidConnection5":{"sorption0":"3"},"inputTanksSeparated":"0b","voidUnusableFluidInput0":"0b","tankOutputSetting0":"0","Items":[],"inventoryConnection0":{"sorption0":"3"},"inventoryConnection1":{"sorption0":"3"},"inventoryConnection2":{"sorption0":"3"},"inventoryConnection3":{"sorption0":"3"},"inventoryConnection4":{"sorption0":"3"},"inventoryConnection5":{"sorption0":"3"},"itemOutputSetting0":"0","isRunning":"0b","energyBool":"0b","stackBool":"0b","fluidBool":"0b"},
            "elements": [
                "nuclearcraft:fusion_electromagnet_idle@0"
            ]
        },
        {
            "x": -1,
            "y": 1,
            "z": 2,
            "nbt": {"id":"nuclearcraft:fusion_electromagnet""ForgeCaps":{"abyssalcraft:itemtransfer":{"configurations":[]"isRunning":"0b"}"nuclearcraft:capability_default_radiation_resistance":{"radiationResistance":"0.0d"}},"isRedstonePowered":"0b","alternateComparator":"0b","redstoneControl":"0b","radiationLevel":"0.0d","energy":"0","capacity":"256000","maxTransfer":"64000","energyConnections0":"0","energyConnections1":"0","energyConnections2":"0","energyConnections3":"0","energyConnections4":"0","energyConnections5":"0","tank0":{"fluidAmount":"0""fluidName":"nullFluid"},"fluidConnection0":{"sorption0":"3"},"fluidConnection1":{"sorption0":"3"},"fluidConnection2":{"sorption0":"3"},"fluidConnection3":{"sorption0":"3"},"fluidConnection4":{"sorption0":"3"},"fluidConnection5":{"sorption0":"3"},"inputTanksSeparated":"0b","voidUnusableFluidInput0":"0b","tankOutputSetting0":"0","Items":[],"inventoryConnection0":{"sorption0":"3"},"inventoryConnection1":{"sorption0":"3"},"inventoryConnection2":{"sorption0":"3"},"inventoryConnection3":{"sorption0":"3"},"inventoryConnection4":{"sorption0":"3"},"inventoryConnection5":{"sorption0":"3"},"itemOutputSetting0":"0","isRunning":"0b","energyBool":"0b","stackBool":"0b","fluidBool":"0b"},
            "elements": [
                "nuclearcraft:fusion_electromagnet_idle@0"
            ]
        },
        {
            "x": -1,
            "y": 1,
            "z": 1,
            "nbt": {"id":"nuclearcraft:fusion_electromagnet""ForgeCaps":{"abyssalcraft:itemtransfer":{"configurations":[]"isRunning":"0b"}"nuclearcraft:capability_default_radiation_resistance":{"radiationResistance":"0.0d"}},"isRedstonePowered":"0b","alternateComparator":"0b","redstoneControl":"0b","radiationLevel":"0.0d","energy":"0","capacity":"256000","maxTransfer":"64000","energyConnections0":"0","energyConnections1":"0","energyConnections2":"0","energyConnections3":"0","energyConnections4":"0","energyConnections5":"0","tank0":{"fluidAmount":"0""fluidName":"nullFluid"},"fluidConnection0":{"sorption0":"3"},"fluidConnection1":{"sorption0":"3"},"fluidConnection2":{"sorption0":"3"},"fluidConnection3":{"sorption0":"3"},"fluidConnection4":{"sorption0":"3"},"fluidConnection5":{"sorption0":"3"},"inputTanksSeparated":"0b","voidUnusableFluidInput0":"0b","tankOutputSetting0":"0","Items":[],"inventoryConnection0":{"sorption0":"3"},"inventoryConnection1":{"sorption0":"3"},"inventoryConnection2":{"sorption0":"3"},"inventoryConnection3":{"sorption0":"3"},"inventoryConnection4":{"sorption0":"3"},"inventoryConnection5":{"sorption0":"3"},"itemOutputSetting0":"0","isRunning":"0b","energyBool":"0b","stackBool":"0b","fluidBool":"0b"},
            "elements": [
                "nuclearcraft:fusion_electromagnet_idle@0"
            ]
        },
        {
            "x": 0,
            "y": 2,
            "z": 2,
            "elements": [
                "nuclearcraft:fission_block@0"
            ]
        },
        {
            "x": 0,
            "y": 2,
            "z": 1,
            "elements": [
                "contenttweaker:highly_advanced_machine_casing@0"
            ]
        },
        {
            "x": 0,
            "y": 2,
            "z": 4,
            "elements": [
                "nuclearcraft:fission_block@0"
            ]
        },
        {
            "x": 0,
            "y": 2,
            "z": 3,
            "elements": [
                "contenttweaker:highly_advanced_machine_casing@0"
            ]
        },
        {
            "x": 0,
            "y": 2,
            "z": 0,
            "elements": [
                "nuclearcraft:fission_block@0"
            ]
        },
        {
            "x": -2,
            "y": 0,
            "z": 3,
            "elements": [
                "nuclearcraft:fission_block@0"
            ]
        },
        {
            "x": 0,
            "y": 0,
            "z": 4,
            "elements": [
                "nuclearcraft:fission_block@0"
            ]
        },
        {
            "x": 0,
            "y": 0,
            "z": 3,
            "nbt": {"id":"minecraft:tileenergyinputhatch""ForgeCaps":{"abyssalcraft:itemtransfer":{"configurations":[]"isRunning":"0b"}"nuclearcraft:capability_default_radiation_resistance":{"radiationResistance":"0.0d"}},"casingColor":"16730368","energy":"0L","hatchSize":"0"},
            "elements": [
                "modularmachinery:blockenergyinputhatch@0"
            ]
        },
        {
            "x": -2,
            "y": 0,
            "z": 4,
            "elements": [
                "nuclearcraft:fission_block@0"
            ]
        },
        {
            "x": -2,
            "y": 0,
            "z": 1,
            "elements": [
                "nuclearcraft:fission_block@0"
            ]
        },
        {
            "x": -2,
            "y": 0,
            "z": 2,
            "elements": [
                "nuclearcraft:fission_block@0"
            ]
        },
        {
            "x": 0,
            "y": 0,
            "z": 2,
            "elements": [
                "nuclearcraft:fission_block@0"
            ]
        },
        {
            "x": 1,
            "y": 2,
            "z": 4,
            "elements": [
                "nuclearcraft:fission_block@0"
            ]
        },
        {
            "x": 0,
            "y": 0,
            "z": 1,
            "nbt": {"id":"minecraft:tileiteminputbus""ForgeCaps":{"abyssalcraft:itemtransfer":{"configurations":[]"isRunning":"0b"}"nuclearcraft:capability_default_radiation_resistance":{"radiationResistance":"0.0d"}},"casingColor":"16730368","inventory":{"inSlots":"outSlots":,"miscSlots":,"inventoryArray":[{"holderId":"0""holderEmpty":"1b"}],"sides":},"busSize":"0"},
            "elements": [
                "modularmachinery:blockinputbus@0"
            ]
        },
        {
            "x": 1,
            "y": 2,
            "z": 3,
            "elements": [
                "contenttweaker:highly_advanced_machine_casing@0"
            ]
        },
        {
            "x": 1,
            "y": 2,
            "z": 2,
            "elements": [
                "contenttweaker:highly_advanced_machine_casing@0"
            ]
        },
        {
            "x": 1,
            "y": 2,
            "z": 1,
            "elements": [
                "contenttweaker:highly_advanced_machine_casing@0"
            ]
        },
        {
            "x": 1,
            "y": 2,
            "z": 0,
            "elements": [
                "nuclearcraft:fission_block@0"
            ]
        },
        {
            "x": -2,
            "y": 0,
            "z": 0,
            "elements": [
                "nuclearcraft:fission_block@0"
            ]
        },
        {
            "x": 2,
            "y": 2,
            "z": 0,
            "elements": [
                "nuclearcraft:fission_block@0"
            ]
        },
        {
            "x": 2,
            "y": 2,
            "z": 1,
            "elements": [
                "nuclearcraft:fission_block@0"
            ]
        },
        {
            "x": 2,
            "y": 2,
            "z": 2,
            "elements": [
                "nuclearcraft:fission_block@0"
            ]
        },
        {
            "x": -1,
            "y": 0,
            "z": 3,
            "nbt": {"id":"minecraft:tileitemoutputbus""ForgeCaps":{"abyssalcraft:itemtransfer":{"configurations":[]"isRunning":"0b"}"nuclearcraft:capability_default_radiation_resistance":{"radiationResistance":"0.0d"}},"casingColor":"16730368","inventory":{"inSlots":"outSlots":,"miscSlots":,"inventoryArray":[{"holderId":"0""holderEmpty":"1b"}],"sides":},"busSize":"0"},
            "elements": [
                "modularmachinery:blockoutputbus@0"
            ]
        },
        {
            "x": -1,
            "y": 0,
            "z": 2,
            "elements": [
                "nuclearcraft:fission_block@0"
            ]
        },
        {
            "x": -1,
            "y": 0,
            "z": 1,
            "nbt": {"id":"minecraft:tileitemoutputbus""ForgeCaps":{"abyssalcraft:itemtransfer":{"configurations":[]"isRunning":"0b"}"nuclearcraft:capability_default_radiation_resistance":{"radiationResistance":"0.0d"}},"casingColor":"16730368","inventory":{"inSlots":"outSlots":,"miscSlots":,"inventoryArray":[{"holderId":"0""holderEmpty":"1b"}],"sides":},"busSize":"0"},
            "elements": [
                "modularmachinery:blockoutputbus@0"
            ]
        },
        {
            "x": -1,
            "y": 0,
            "z": 0,
            "elements": [
                "nuclearcraft:fission_block@0"
            ]
        },
        {
            "x": -1,
            "y": 0,
            "z": 4,
            "elements": [
                "nuclearcraft:fission_block@0"
            ]
        },
        {
            "x": 2,
            "y": 2,
            "z": 3,
            "elements": [
                "nuclearcraft:fission_block@0"
            ]
        },
        {
            "x": 2,
            "y": 2,
            "z": 4,
            "elements": [
                "nuclearcraft:fission_block@0"
            ]
        },
        {
            "x": 1,
            "y": 1,
            "z": 3,
            "nbt": {"id":"nuclearcraft:fusion_electromagnet""ForgeCaps":{"abyssalcraft:itemtransfer":{"configurations":[]"isRunning":"0b"}"nuclearcraft:capability_default_radiation_resistance":{"radiationResistance":"0.0d"}},"isRedstonePowered":"0b","alternateComparator":"0b","redstoneControl":"0b","radiationLevel":"0.0d","energy":"0","capacity":"256000","maxTransfer":"64000","energyConnections0":"0","energyConnections1":"0","energyConnections2":"0","energyConnections3":"0","energyConnections4":"0","energyConnections5":"0","tank0":{"fluidAmount":"0""fluidName":"nullFluid"},"fluidConnection0":{"sorption0":"3"},"fluidConnection1":{"sorption0":"3"},"fluidConnection2":{"sorption0":"3"},"fluidConnection3":{"sorption0":"3"},"fluidConnection4":{"sorption0":"3"},"fluidConnection5":{"sorption0":"3"},"inputTanksSeparated":"0b","voidUnusableFluidInput0":"0b","tankOutputSetting0":"0","Items":[],"inventoryConnection0":{"sorption0":"3"},"inventoryConnection1":{"sorption0":"3"},"inventoryConnection2":{"sorption0":"3"},"inventoryConnection3":{"sorption0":"3"},"inventoryConnection4":{"sorption0":"3"},"inventoryConnection5":{"sorption0":"3"},"itemOutputSetting0":"0","isRunning":"0b","energyBool":"0b","stackBool":"0b","fluidBool":"0b"},
            "elements": [
                "nuclearcraft:fusion_electromagnet_idle@0"
            ]
        },
        {
            "x": 1,
            "y": 1,
            "z": 2,
            "nbt": {"id":"nuclearcraft:fusion_electromagnet""ForgeCaps":{"abyssalcraft:itemtransfer":{"configurations":[]"isRunning":"0b"}"nuclearcraft:capability_default_radiation_resistance":{"radiationResistance":"0.0d"}},"isRedstonePowered":"0b","alternateComparator":"0b","redstoneControl":"0b","radiationLevel":"0.0d","energy":"0","capacity":"256000","maxTransfer":"64000","energyConnections0":"0","energyConnections1":"0","energyConnections2":"0","energyConnections3":"0","energyConnections4":"0","energyConnections5":"0","tank0":{"fluidAmount":"0""fluidName":"nullFluid"},"fluidConnection0":{"sorption0":"3"},"fluidConnection1":{"sorption0":"3"},"fluidConnection2":{"sorption0":"3"},"fluidConnection3":{"sorption0":"3"},"fluidConnection4":{"sorption0":"3"},"fluidConnection5":{"sorption0":"3"},"inputTanksSeparated":"0b","voidUnusableFluidInput0":"0b","tankOutputSetting0":"0","Items":[],"inventoryConnection0":{"sorption0":"3"},"inventoryConnection1":{"sorption0":"3"},"inventoryConnection2":{"sorption0":"3"},"inventoryConnection3":{"sorption0":"3"},"inventoryConnection4":{"sorption0":"3"},"inventoryConnection5":{"sorption0":"3"},"itemOutputSetting0":"0","isRunning":"0b","energyBool":"0b","stackBool":"0b","fluidBool":"0b"},
            "elements": [
                "nuclearcraft:fusion_electromagnet_idle@0"
            ]
        },
        {
            "x": 1,
            "y": 1,
            "z": 1,
            "nbt": {"id":"nuclearcraft:fusion_electromagnet""ForgeCaps":{"abyssalcraft:itemtransfer":{"configurations":[]"isRunning":"0b"}"nuclearcraft:capability_default_radiation_resistance":{"radiationResistance":"0.0d"}},"isRedstonePowered":"0b","alternateComparator":"0b","redstoneControl":"0b","radiationLevel":"0.0d","energy":"0","capacity":"256000","maxTransfer":"64000","energyConnections0":"0","energyConnections1":"0","energyConnections2":"0","energyConnections3":"0","energyConnections4":"0","energyConnections5":"0","tank0":{"fluidAmount":"0""fluidName":"nullFluid"},"fluidConnection0":{"sorption0":"3"},"fluidConnection1":{"sorption0":"3"},"fluidConnection2":{"sorption0":"3"},"fluidConnection3":{"sorption0":"3"},"fluidConnection4":{"sorption0":"3"},"fluidConnection5":{"sorption0":"3"},"inputTanksSeparated":"0b","voidUnusableFluidInput0":"0b","tankOutputSetting0":"0","Items":[],"inventoryConnection0":{"sorption0":"3"},"inventoryConnection1":{"sorption0":"3"},"inventoryConnection2":{"sorption0":"3"},"inventoryConnection3":{"sorption0":"3"},"inventoryConnection4":{"sorption0":"3"},"inventoryConnection5":{"sorption0":"3"},"itemOutputSetting0":"0","isRunning":"0b","energyBool":"0b","stackBool":"0b","fluidBool":"0b"},
            "elements": [
                "nuclearcraft:fusion_electromagnet_idle@0"
            ]
        },
        {
            "x": -1,
            "y": 2,
            "z": 1,
            "elements": [
                "contenttweaker:highly_advanced_machine_casing@0"
            ]
        },
        {
            "x": -1,
            "y": 2,
            "z": 0,
            "elements": [
                "nuclearcraft:fission_block@0"
            ]
        },
        {
            "x": -1,
            "y": 2,
            "z": 4,
            "elements": [
                "nuclearcraft:fission_block@0"
            ]
        },
        {
            "x": -1,
            "y": 2,
            "z": 3,
            "elements": [
                "contenttweaker:highly_advanced_machine_casing@0"
            ]
        },
        {
            "x": -1,
            "y": 2,
            "z": 2,
            "elements": [
                "contenttweaker:highly_advanced_machine_casing@0"
            ]
        },
        {
            "x": -2,
            "y": 2,
            "z": 0,
            "elements": [
                "nuclearcraft:fission_block@0"
            ]
        },
        {
            "x": 0,
            "y": 1,
            "z": 1,
            "nbt": {"id":"nuclearcraft:fusion_electromagnet""ForgeCaps":{"abyssalcraft:itemtransfer":{"configurations":[]"isRunning":"0b"}"nuclearcraft:capability_default_radiation_resistance":{"radiationResistance":"0.0d"}},"isRedstonePowered":"0b","alternateComparator":"0b","redstoneControl":"0b","radiationLevel":"0.0d","energy":"0","capacity":"256000","maxTransfer":"64000","energyConnections0":"0","energyConnections1":"0","energyConnections2":"0","energyConnections3":"0","energyConnections4":"0","energyConnections5":"0","tank0":{"fluidAmount":"0""fluidName":"nullFluid"},"fluidConnection0":{"sorption0":"3"},"fluidConnection1":{"sorption0":"3"},"fluidConnection2":{"sorption0":"3"},"fluidConnection3":{"sorption0":"3"},"fluidConnection4":{"sorption0":"3"},"fluidConnection5":{"sorption0":"3"},"inputTanksSeparated":"0b","voidUnusableFluidInput0":"0b","tankOutputSetting0":"0","Items":[],"inventoryConnection0":{"sorption0":"3"},"inventoryConnection1":{"sorption0":"3"},"inventoryConnection2":{"sorption0":"3"},"inventoryConnection3":{"sorption0":"3"},"inventoryConnection4":{"sorption0":"3"},"inventoryConnection5":{"sorption0":"3"},"itemOutputSetting0":"0","isRunning":"0b","energyBool":"0b","stackBool":"0b","fluidBool":"0b"},
            "elements": [
                "nuclearcraft:fusion_electromagnet_idle@0"
            ]
        },
        {
            "x": 2,
            "y": 0,
            "z": 0,
            "elements": [
                "nuclearcraft:fission_block@0"
            ]
        },
        {
            "x": -2,
            "y": 2,
            "z": 2,
            "elements": [
                "nuclearcraft:fission_block@0"
            ]
        },
        {
            "x": -2,
            "y": 2,
            "z": 1,
            "elements": [
                "nuclearcraft:fission_block@0"
            ]
        },
        {
            "x": -2,
            "y": 2,
            "z": 4,
            "elements": [
                "nuclearcraft:fission_block@0"
            ]
        },
        {
            "x": 2,
            "y": 0,
            "z": 2,
            "elements": [
                "nuclearcraft:fission_block@0"
            ]
        },
        {
            "x": 0,
            "y": 1,
            "z": 3,
            "nbt": {"id":"nuclearcraft:fusion_electromagnet""ForgeCaps":{"abyssalcraft:itemtransfer":{"configurations":[]"isRunning":"0b"}"nuclearcraft:capability_default_radiation_resistance":{"radiationResistance":"0.0d"}},"isRedstonePowered":"0b","alternateComparator":"0b","redstoneControl":"0b","radiationLevel":"0.0d","energy":"0","capacity":"256000","maxTransfer":"64000","energyConnections0":"0","energyConnections1":"0","energyConnections2":"0","energyConnections3":"0","energyConnections4":"0","energyConnections5":"0","tank0":{"fluidAmount":"0""fluidName":"nullFluid"},"fluidConnection0":{"sorption0":"3"},"fluidConnection1":{"sorption0":"3"},"fluidConnection2":{"sorption0":"3"},"fluidConnection3":{"sorption0":"3"},"fluidConnection4":{"sorption0":"3"},"fluidConnection5":{"sorption0":"3"},"inputTanksSeparated":"0b","voidUnusableFluidInput0":"0b","tankOutputSetting0":"0","Items":[],"inventoryConnection0":{"sorption0":"3"},"inventoryConnection1":{"sorption0":"3"},"inventoryConnection2":{"sorption0":"3"},"inventoryConnection3":{"sorption0":"3"},"inventoryConnection4":{"sorption0":"3"},"inventoryConnection5":{"sorption0":"3"},"itemOutputSetting0":"0","isRunning":"0b","energyBool":"0b","stackBool":"0b","fluidBool":"0b"},
            "elements": [
                "nuclearcraft:fusion_electromagnet_idle@0"
            ]
        },
        {
            "x": 0,
            "y": 1,
            "z": 2,
            "elements": [
                "nuclearcraft:fission_block@0"
            ]
        },
        {
            "x": -2,
            "y": 2,
            "z": 3,
            "elements": [
                "nuclearcraft:fission_block@0"
            ]
        },
        {
            "x": 2,
            "y": 0,
            "z": 1,
            "elements": [
                "nuclearcraft:fission_block@0"
            ]
        },
        {
            "x": 2,
            "y": 0,
            "z": 4,
            "elements": [
                "nuclearcraft:fission_block@0"
            ]
        },
        {
            "x": 2,
            "y": 0,
            "z": 3,
            "elements": [
                "nuclearcraft:fission_block@0"
            ]
        }
    ]}