{
    "registryname": "megelium_detonator",
    "localizedname": "Megelium Detonator",
	"color": "d98cff",
    "parts": [
        {
            "x": -1,
            "y": 10,
            "z": -10,
            "elements": [
                "bnkrblks:megelium_polished@0"
            ]
        },
        {
            "x": -3,
            "y": 12,
            "z": 3,
            "elements": [
                "bnkrblks:megelium_glass@0"
            ]
        },
        {
            "x": 2,
            "y": 13,
            "z": -3,
            "elements": [
                "bnkrblks:megelium_glass@0"
            ]
        },
        {
            "x": -7,
            "y": 13,
            "z": 0,
            "elements": [
                "bnkrblks:megelium_polished@0"
            ]
        },
        {
            "x": -5,
            "y": 10,
            "z": 0,
            "elements": [
                "draconicevolution:reactor_component@0"
            ]
        },
        {
            "x": 3,
            "y": 10,
            "z": 7,
            "elements": [
                "bnkrblks:megelium_polished@0"
            ]
        },
        {
            "x": -2,
            "y": 3,
            "z": 0,
            "elements": [
                "bnkrblks:megelium_polished@0"
            ]
        },
        {
            "x": -3,
            "y": 5,
            "z": 0,
            "elements": [
                "bnkrblks:megelium_polished@0"
            ]
        },
        {
            "x": -4,
            "y": 10,
            "z": -5,
            "elements": [
                "bnkrblks:megelium_polished@0"
            ]
        },
        {
            "x": 1,
            "y": 16,
            "z": 2,
            "elements": [
                "bnkrblks:megelium_glass@0"
            ]
        },
        {
            "x": -3,
            "y": 11,
            "z": 4,
            "elements": [
                "avaritia:block_resource@0"
            ]
        },
        {
            "x": 3,
            "y": 8,
            "z": 3,
            "elements": [
                "bnkrblks:megelium_glass@0"
            ]
        },
        {
            "x": 1,
            "y": 0,
            "z": 0,
            "elements": [
                "bnkrblks:megelium_polished@0"
            ]
        },
        {
            "x": -1,
            "y": 8,
            "z": -6,
            "elements": [
                "bnkrblks:megelium_glass@0"
            ]
        },
        {
            "x": -1,
            "y": 13,
            "z": -4,
            "elements": [
                "avaritia:block_resource@0"
            ]
        },
        {
            "x": -2,
            "y": 2,
            "z": 0,
            "elements": [
                "bnkrblks:megelium_polished@0"
            ]
        },
        {
            "x": -1,
            "y": 11,
            "z": 8,
            "elements": [
                "bnkrblks:megelium_glass@0"
            ]
        },
        {
            "x": 0,
            "y": 15,
            "z": 3,
            "elements": [
                "bnkrblks:megelium_polished@0"
            ]
        },
        {
            "x": -1,
            "y": 14,
            "z": -3,
            "elements": [
                "avaritia:block_resource@0"
            ]
        },
        {
            "x": 7,
            "y": 10,
            "z": -2,
            "elements": [
                "bnkrblks:megelium_polished@0"
            ]
        },
        {
            "x": 2,
            "y": 5,
            "z": 1,
            "elements": [
                "avaritia:block_resource@0"
            ]
        },
        {
            "x": -4,
            "y": 6,
            "z": 0,
            "elements": [
                "bnkrblks:megelium_polished@0"
            ]
        },
        {
            "x": -2,
            "y": 10,
            "z": 9,
            "elements": [
                "bnkrblks:megelium_polished@0"
            ]
        },
        {
            "x": 5,
            "y": 10,
            "z": -3,
            "elements": [
                "bnkrblks:megelium_polished@0"
            ]
        },
        {
            "x": -2,
            "y": 9,
            "z": -5,
            "elements": [
                "avaritia:block_resource@0"
            ]
        },
        {
            "x": 2,
            "y": 4,
            "z": 1,
            "elements": [
                "bnkrblks:megelium_glass@0"
            ]
        },
        {
            "x": -1,
            "y": 11,
            "z": -7,
            "elements": [
                "bnkrblks:megelium_glass@0"
            ]
        },
        {
            "x": -2,
            "y": 1,
            "z": 0,
            "elements": [
                "bnkrblks:megelium_polished@0"
            ]
        },
        {
            "x": -6,
            "y": 10,
            "z": 0,
            "elements": [
                "draconicevolution:draconium_block@1"
            ]
        },
        {
            "x": 5,
            "y": 10,
            "z": -4,
            "elements": [
                "bnkrblks:megelium_polished@0"
            ]
        },
        {
            "x": -4,
            "y": 5,
            "z": 0,
            "elements": [
                "bnkrblks:megelium_polished@0"
            ]
        },
        {
            "x": 3,
            "y": 9,
            "z": 4,
            "elements": [
                "avaritia:block_resource@0"
            ]
        },
        {
            "x": 0,
            "y": 14,
            "z": 4,
            "elements": [
                "bnkrblks:megelium_polished@0"
            ]
        },
        {
            "x": 2,
            "y": 10,
            "z": -7,
            "elements": [
                "bnkrblks:megelium_polished@0"
            ]
        },
        {
            "x": 4,
            "y": 12,
            "z": 2,
            "elements": [
                "bnkrblks:megelium_glass@0"
            ]
        },
        {
            "x": -1,
            "y": 13,
            "z": 4,
            "elements": [
                "avaritia:block_resource@0"
            ]
        },
        {
            "x": -1,
            "y": 8,
            "z": -5,
            "elements": [
                "avaritia:block_resource@0"
            ]
        },
        {
            "x": -3,
            "y": 8,
            "z": 3,
            "elements": [
                "bnkrblks:megelium_glass@0"
            ]
        },
        {
            "x": 3,
            "y": 11,
            "z": -4,
            "elements": [
                "avaritia:block_resource@0"
            ]
        },
        {
            "x": 2,
            "y": 7,
            "z": -3,
            "elements": [
                "bnkrblks:megelium_glass@0"
            ]
        },
        {
            "x": -1,
            "y": 12,
            "z": -6,
            "elements": [
                "bnkrblks:megelium_glass@0"
            ]
        },
        {
            "x": -2,
            "y": 11,
            "z": -5,
            "elements": [
                "avaritia:block_resource@0"
            ]
        },
        {
            "x": 0,
            "y": 17,
            "z": 3,
            "elements": [
                "bnkrblks:megelium_polished@0"
            ]
        },
        {
            "x": 3,
            "y": 12,
            "z": 3,
            "elements": [
                "bnkrblks:megelium_glass@0"
            ]
        },
        {
            "x": 4,
            "y": 8,
            "z": -2,
            "elements": [
                "bnkrblks:megelium_glass@0"
            ]
        },
        {
            "x": -5,
            "y": 6,
            "z": 0,
            "elements": [
                "bnkrblks:megelium_polished@0"
            ]
        },
        {
            "x": 3,
            "y": 10,
            "z": 6,
            "elements": [
                "bnkrblks:megelium_polished@0"
            ]
        },
        {
            "x": 0,
            "y": 12,
            "z": 7,
            "elements": [
                "bnkrblks:megelium_polished@0"
            ]
        },
        {
            "x": 6,
            "y": 10,
            "z": 3,
            "elements": [
                "bnkrblks:megelium_polished@0"
            ]
        },
        {
            "x": 0,
            "y": 16,
            "z": 3,
            "elements": [
                "bnkrblks:megelium_polished@0"
            ]
        },
        {
            "x": -3,
            "y": 10,
            "z": 7,
            "elements": [
                "bnkrblks:megelium_polished@0"
            ]
        },
        {
            "x": 0,
            "y": 5,
            "z": 3,
            "elements": [
                "bnkrblks:megelium_polished@0"
            ]
        },
        {
            "x": 0,
            "y": 9,
            "z": -10,
            "elements": [
                "bnkrblks:megelium_polished@0"
            ]
        },
        {
            "x": -8,
            "y": 12,
            "z": 0,
            "elements": [
                "bnkrblks:megelium_polished@0"
            ]
        },
        {
            "x": 3,
            "y": 9,
            "z": -4,
            "elements": [
                "avaritia:block_resource@0"
            ]
        },
        {
            "x": 0,
            "y": 14,
            "z": -4,
            "elements": [
                "bnkrblks:megelium_polished@0"
            ]
        },
        {
            "x": -1,
            "y": 0,
            "z": 0,
            "elements": [
                "bnkrblks:megelium_polished@0"
            ]
        },
        {
            "x": 4,
            "y": 8,
            "z": 2,
            "elements": [
                "bnkrblks:megelium_glass@0"
            ]
        },
        {
            "x": 2,
            "y": 9,
            "z": -6,
            "elements": [
                "bnkrblks:megelium_glass@0"
            ]
        },
        {
            "x": 0,
            "y": 10,
            "z": -10,
            "elements": [
                "modularmachinery:blockenergyinputhatch"
            ]
        },
        {
            "x": 1,
            "y": 15,
            "z": 2,
            "elements": [
                "avaritia:block_resource@0"
            ]
        },
        {
            "x": 0,
            "y": 4,
            "z": 3,
            "elements": [
                "bnkrblks:megelium_polished@0"
            ]
        },
        {
            "x": -6,
            "y": 13,
            "z": 0,
            "elements": [
                "bnkrblks:megelium_polished@0"
            ]
        },
        {
            "x": 4,
            "y": 12,
            "z": -2,
            "elements": [
                "bnkrblks:megelium_glass@0"
            ]
        },
        {
            "x": 0,
            "y": 15,
            "z": -4,
            "elements": [
                "bnkrblks:megelium_polished@0"
            ]
        },
        {
            "x": 2,
            "y": 8,
            "z": 4,
            "elements": [
                "bnkrblks:megelium_glass@0"
            ]
        },
        {
            "x": 2,
            "y": 12,
            "z": -4,
            "elements": [
                "bnkrblks:megelium_glass@0"
            ]
        },
        {
            "x": 0,
            "y": 11,
            "z": -10,
            "elements": [
                "bnkrblks:megelium_polished@0"
            ]
        },
        {
            "x": 0,
            "y": 10,
            "z": 7,
            "elements": [
                "draconicevolution:draconium_block@1"
            ]
        },
        {
            "x": 2,
            "y": 10,
            "z": 8,
            "elements": [
                "bnkrblks:megelium_polished@0"
            ]
        },
        {
            "x": -8,
            "y": 10,
            "z": 0,
            "elements": [
                "draconicevolution:draconium_block@1"
            ]
        },
        {
            "x": 0,
            "y": 13,
            "z": 7,
            "elements": [
                "bnkrblks:megelium_polished@0"
            ]
        },
        {
            "x": -5,
            "y": 7,
            "z": 0,
            "elements": [
                "bnkrblks:megelium_polished@0"
            ]
        },
        {
            "x": 7,
            "y": 10,
            "z": 2,
            "elements": [
                "bnkrblks:megelium_polished@0"
            ]
        },
        {
            "x": 0,
            "y": 3,
            "z": 3,
            "elements": [
                "bnkrblks:megelium_polished@0"
            ]
        },
        {
            "x": 1,
            "y": 16,
            "z": -2,
            "elements": [
                "bnkrblks:megelium_glass@0"
            ]
        },
        {
            "x": 1,
            "y": 8,
            "z": -5,
            "elements": [
                "avaritia:block_resource@0"
            ]
        },
        {
            "x": -2,
            "y": 9,
            "z": 6,
            "elements": [
                "bnkrblks:megelium_glass@0"
            ]
        },
        {
            "x": -10,
            "y": 11,
            "z": 0,
            "elements": [
                "bnkrblks:megelium_polished@0"
            ]
        },
        {
            "x": -4,
            "y": 14,
            "z": 0,
            "elements": [
                "bnkrblks:megelium_polished@0"
            ]
        },
        {
            "x": -8,
            "y": 8,
            "z": 0,
            "elements": [
                "bnkrblks:megelium_polished@0"
            ]
        },
        {
            "x": -1,
            "y": 19,
            "z": 1,
            "elements": [
                "bnkrblks:megelium_glass@0"
            ]
        },
        {
            "x": -3,
            "y": 10,
            "z": 6,
            "elements": [
                "bnkrblks:megelium_polished@0"
            ]
        },
        {
            "x": -1,
            "y": 12,
            "z": -5,
            "elements": [
                "avaritia:block_resource@0"
            ]
        },
        {
            "x": 0,
            "y": 13,
            "z": 6,
            "elements": [
                "bnkrblks:megelium_polished@0"
            ]
        },
        {
            "x": 2,
            "y": 11,
            "z": -6,
            "elements": [
                "bnkrblks:megelium_glass@0"
            ]
        },
        {
            "x": -1,
            "y": 18,
            "z": 1,
            "elements": [
                "bnkrblks:megelium_glass@0"
            ]
        },
        {
            "x": 8,
            "y": 9,
            "z": 1,
            "elements": [
                "bnkrblks:megelium_glass@0"
            ]
        },
        {
            "x": 2,
            "y": 3,
            "z": 0,
            "elements": [
                "bnkrblks:megelium_polished@0"
            ]
        },
        {
            "x": 1,
            "y": 9,
            "z": 9,
            "elements": [
                "bnkrblks:megelium_glass@0"
            ]
        },
        {
            "x": -4,
            "y": 10,
            "z": 5,
            "elements": [
                "bnkrblks:megelium_polished@0"
            ]
        },
        {
            "x": 0,
            "y": 8,
            "z": 7,
            "elements": [
                "bnkrblks:megelium_polished@0"
            ]
        },
        {
            "x": 2,
            "y": 15,
            "z": 1,
            "elements": [
                "avaritia:block_resource@0"
            ]
        },
        {
            "x": 0,
            "y": 6,
            "z": 5,
            "elements": [
                "bnkrblks:megelium_polished@0"
            ]
        },
        {
            "x": -1,
            "y": 17,
            "z": 1,
            "elements": [
                "bnkrblks:megelium_glass@0"
            ]
        },
        {
            "x": 2,
            "y": 2,
            "z": 0,
            "elements": [
                "bnkrblks:megelium_polished@0"
            ]
        },
        {
            "x": 3,
            "y": 6,
            "z": -1,
            "elements": [
                "avaritia:block_resource@0"
            ]
        },
        {
            "x": 1,
            "y": 11,
            "z": -9,
            "elements": [
                "bnkrblks:megelium_glass@0"
            ]
        },
        {
            "x": -7,
            "y": 8,
            "z": 0,
            "elements": [
                "bnkrblks:megelium_polished@0"
            ]
        },
        {
            "x": 2,
            "y": 9,
            "z": -5,
            "elements": [
                "avaritia:block_resource@0"
            ]
        },
        {
            "x": 5,
            "y": 12,
            "z": 1,
            "elements": [
                "avaritia:block_resource@0"
            ]
        },
        {
            "x": -6,
            "y": 12,
            "z": -1,
            "elements": [
                "bnkrblks:megelium_glass@0"
            ]
        },
        {
            "x": 0,
            "y": 7,
            "z": 7,
            "elements": [
                "bnkrblks:megelium_polished@0"
            ]
        },
        {
            "x": -10,
            "y": 10,
            "z": 0,
            "elements": [
                "modularmachinery:blockenergyinputhatch"
            ]
        },
        {
            "x": -4,
            "y": 15,
            "z": 0,
            "elements": [
                "bnkrblks:megelium_polished@0"
            ]
        },
        {
            "x": 0,
            "y": 10,
            "z": 6,
            "elements": [
                "draconicevolution:draconium_block@1"
            ]
        },
        {
            "x": 2,
            "y": 1,
            "z": 0,
            "elements": [
                "bnkrblks:megelium_polished@0"
            ]
        },
        {
            "x": 1,
            "y": 11,
            "z": 9,
            "elements": [
                "bnkrblks:megelium_glass@0"
            ]
        },
        {
            "x": -7,
            "y": 7,
            "z": 0,
            "elements": [
                "bnkrblks:megelium_polished@0"
            ]
        },
        {
            "x": -3,
            "y": 10,
            "z": 5,
            "elements": [
                "bnkrblks:megelium_polished@0"
            ]
        },
        {
            "x": 8,
            "y": 11,
            "z": 1,
            "elements": [
                "bnkrblks:megelium_glass@0"
            ]
        },
        {
            "x": -10,
            "y": 9,
            "z": 0,
            "elements": [
                "bnkrblks:megelium_polished@0"
            ]
        },
        {
            "x": 9,
            "y": 10,
            "z": 2,
            "elements": [
                "bnkrblks:megelium_polished@0"
            ]
        },
        {
            "x": 2,
            "y": 11,
            "z": -5,
            "elements": [
                "avaritia:block_resource@0"
            ]
        },
        {
            "x": 3,
            "y": 14,
            "z": -1,
            "elements": [
                "avaritia:block_resource@0"
            ]
        },
        {
            "x": 1,
            "y": 10,
            "z": -10,
            "elements": [
                "bnkrblks:megelium_polished@0"
            ]
        },
        {
            "x": 8,
            "y": 10,
            "z": -2,
            "elements": [
                "bnkrblks:megelium_polished@0"
            ]
        },
        {
            "x": 0,
            "y": 6,
            "z": 4,
            "elements": [
                "bnkrblks:megelium_polished@0"
            ]
        },
        {
            "x": 0,
            "y": 7,
            "z": 5,
            "elements": [
                "bnkrblks:megelium_polished@0"
            ]
        },
        {
            "x": -7,
            "y": 10,
            "z": 0,
            "elements": [
                "draconicevolution:draconium_block@1"
            ]
        },
        {
            "x": 2,
            "y": 16,
            "z": 1,
            "elements": [
                "bnkrblks:megelium_glass@0"
            ]
        },
        {
            "x": 0,
            "y": 5,
            "z": 4,
            "elements": [
                "bnkrblks:megelium_polished@0"
            ]
        },
        {
            "x": -4,
            "y": 13,
            "z": 1,
            "elements": [
                "avaritia:block_resource@0"
            ]
        },
        {
            "x": -9,
            "y": 9,
            "z": -1,
            "elements": [
                "bnkrblks:megelium_glass@0"
            ]
        },
        {
            "x": 8,
            "y": 10,
            "z": 2,
            "elements": [
                "bnkrblks:megelium_polished@0"
            ]
        },
        {
            "x": -9,
            "y": 11,
            "z": -1,
            "elements": [
                "bnkrblks:megelium_glass@0"
            ]
        },
        {
            "x": 5,
            "y": 8,
            "z": 1,
            "elements": [
                "avaritia:block_resource@0"
            ]
        },
        {
            "x": 0,
            "y": 7,
            "z": 6,
            "elements": [
                "bnkrblks:megelium_polished@0"
            ]
        },
        {
            "x": 1,
            "y": 8,
            "z": 6,
            "elements": [
                "bnkrblks:megelium_glass@0"
            ]
        },
        {
            "x": 6,
            "y": 8,
            "z": -1,
            "elements": [
                "bnkrblks:megelium_glass@0"
            ]
        },
        {
            "x": -7,
            "y": 12,
            "z": 0,
            "elements": [
                "bnkrblks:megelium_polished@0"
            ]
        },
        {
            "x": -3,
            "y": 14,
            "z": -1,
            "elements": [
                "avaritia:block_resource@0"
            ]
        },
        {
            "x": -2,
            "y": 11,
            "z": 6,
            "elements": [
                "bnkrblks:megelium_glass@0"
            ]
        },
        {
            "x": -3,
            "y": 9,
            "z": 4,
            "elements": [
                "avaritia:block_resource@0"
            ]
        },
        {
            "x": 3,
            "y": 8,
            "z": -3,
            "elements": [
                "bnkrblks:megelium_glass@0"
            ]
        },
        {
            "x": 6,
            "y": 12,
            "z": -1,
            "elements": [
                "bnkrblks:megelium_glass@0"
            ]
        },
        {
            "x": 9,
            "y": 9,
            "z": -1,
            "elements": [
                "bnkrblks:megelium_glass@0"
            ]
        },
        {
            "x": -3,
            "y": 12,
            "z": -3,
            "elements": [
                "bnkrblks:megelium_glass@0"
            ]
        },
        {
            "x": 5,
            "y": 9,
            "z": 2,
            "elements": [
                "avaritia:block_resource@0"
            ]
        },
        {
            "x": -3,
            "y": 9,
            "z": -4,
            "elements": [
                "avaritia:block_resource@0"
            ]
        },
        {
            "x": -1,
            "y": 9,
            "z": -9,
            "elements": [
                "bnkrblks:megelium_glass@0"
            ]
        },
        {
            "x": 6,
            "y": 12,
            "z": 1,
            "elements": [
                "bnkrblks:megelium_glass@0"
            ]
        },
        {
            "x": -2,
            "y": 18,
            "z": 0,
            "elements": [
                "bnkrblks:megelium_polished@0"
            ]
        },
        {
            "x": 7,
            "y": 11,
            "z": -1,
            "elements": [
                "bnkrblks:megelium_glass@0"
            ]
        },
        {
            "x": -1,
            "y": 12,
            "z": 5,
            "elements": [
                "avaritia:block_resource@0"
            ]
        },
        {
            "x": 0,
            "y": 10,
            "z": 5,
            "elements": [
                "draconicevolution:reactor_component@0"
            ]
        },
        {
            "x": 6,
            "y": 9,
            "z": -2,
            "elements": [
                "bnkrblks:megelium_glass@0"
            ]
        },
        {
            "x": -2,
            "y": 17,
            "z": 0,
            "elements": [
                "bnkrblks:megelium_polished@0"
            ]
        },
        {
            "x": 7,
            "y": 11,
            "z": 1,
            "elements": [
                "bnkrblks:megelium_glass@0"
            ]
        },
        {
            "x": 0,
            "y": 5,
            "z": -3,
            "elements": [
                "bnkrblks:megelium_polished@0"
            ]
        },
        {
            "x": 4,
            "y": 5,
            "z": 0,
            "elements": [
                "bnkrblks:megelium_polished@0"
            ]
        },
        {
            "x": 1,
            "y": 6,
            "z": 3,
            "elements": [
                "avaritia:block_resource@0"
            ]
        },
        {
            "x": -2,
            "y": 19,
            "z": 0,
            "elements": [
                "bnkrblks:megelium_polished@0"
            ]
        },
        {
            "x": 0,
            "y": 6,
            "z": -4,
            "elements": [
                "bnkrblks:megelium_polished@0"
            ]
        },
        {
            "x": -4,
            "y": 12,
            "z": 2,
            "elements": [
                "bnkrblks:megelium_glass@0"
            ]
        },
        {
            "x": 1,
            "y": 12,
            "z": 6,
            "elements": [
                "bnkrblks:megelium_glass@0"
            ]
        },
        {
            "x": 5,
            "y": 11,
            "z": 2,
            "elements": [
                "avaritia:block_resource@0"
            ]
        },
        {
            "x": -5,
            "y": 10,
            "z": 4,
            "elements": [
                "bnkrblks:megelium_polished@0"
            ]
        },
        {
            "x": 0,
            "y": 5,
            "z": -4,
            "elements": [
                "bnkrblks:megelium_polished@0"
            ]
        },
        {
            "x": 4,
            "y": 6,
            "z": 0,
            "elements": [
                "bnkrblks:megelium_polished@0"
            ]
        },
        {
            "x": 2,
            "y": 10,
            "z": 7,
            "elements": [
                "bnkrblks:megelium_polished@0"
            ]
        },
        {
            "x": 6,
            "y": 11,
            "z": -2,
            "elements": [
                "bnkrblks:megelium_glass@0"
            ]
        },
        {
            "x": -6,
            "y": 10,
            "z": -3,
            "elements": [
                "bnkrblks:megelium_polished@0"
            ]
        },
        {
            "x": -3,
            "y": 11,
            "z": -4,
            "elements": [
                "avaritia:block_resource@0"
            ]
        },
        {
            "x": 7,
            "y": 9,
            "z": 1,
            "elements": [
                "bnkrblks:megelium_glass@0"
            ]
        },
        {
            "x": -2,
            "y": 10,
            "z": -9,
            "elements": [
                "bnkrblks:megelium_polished@0"
            ]
        },
        {
            "x": 3,
            "y": 10,
            "z": -5,
            "elements": [
                "bnkrblks:megelium_polished@0"
            ]
        },
        {
            "x": -5,
            "y": 10,
            "z": 3,
            "elements": [
                "bnkrblks:megelium_polished@0"
            ]
        },
        {
            "x": -3,
            "y": 13,
            "z": -2,
            "elements": [
                "bnkrblks:megelium_glass@0"
            ]
        },
        {
            "x": 9,
            "y": 11,
            "z": 1,
            "elements": [
                "bnkrblks:megelium_glass@0"
            ]
        },
        {
            "x": -2,
            "y": 8,
            "z": -4,
            "elements": [
                "bnkrblks:megelium_glass@0"
            ]
        },
        {
            "x": 0,
            "y": 19,
            "z": -2,
            "elements": [
                "bnkrblks:megelium_polished@0"
            ]
        },
        {
            "x": 2,
            "y": 9,
            "z": 5,
            "elements": [
                "avaritia:block_resource@0"
            ]
        },
        {
            "x": -5,
            "y": 10,
            "z": -4,
            "elements": [
                "bnkrblks:megelium_polished@0"
            ]
        },
        {
            "x": 2,
            "y": 6,
            "z": 2,
            "elements": [
                "bnkrblks:megelium_glass@0"
            ]
        },
        {
            "x": 1,
            "y": 9,
            "z": -9,
            "elements": [
                "bnkrblks:megelium_glass@0"
            ]
        },
        {
            "x": 9,
            "y": 11,
            "z": -1,
            "elements": [
                "bnkrblks:megelium_glass@0"
            ]
        },
        {
            "x": 0,
            "y": 14,
            "z": -5,
            "elements": [
                "bnkrblks:megelium_polished@0"
            ]
        },
        {
            "x": 0,
            "y": 11,
            "z": 10,
            "elements": [
                "bnkrblks:megelium_polished@0"
            ]
        },
        {
            "x": -1,
            "y": 8,
            "z": 5,
            "elements": [
                "avaritia:block_resource@0"
            ]
        },
        {
            "x": -1,
            "y": 5,
            "z": 2,
            "elements": [
                "avaritia:block_resource@0"
            ]
        },
        {
            "x": 10,
            "y": 10,
            "z": -1,
            "elements": [
                "bnkrblks:megelium_polished@0"
            ]
        },
        {
            "x": 0,
            "y": 9,
            "z": 10,
            "elements": [
                "bnkrblks:megelium_polished@0"
            ]
        },
        {
            "x": -4,
            "y": 8,
            "z": 2,
            "elements": [
                "bnkrblks:megelium_glass@0"
            ]
        },
        {
            "x": 0,
            "y": 10,
            "z": 10,
            "elements": [
                "modularmachinery:blockenergyinputhatch"
            ]
        },
        {
            "x": 9,
            "y": 10,
            "z": -2,
            "elements": [
                "bnkrblks:megelium_polished@0"
            ]
        },
        {
            "x": 10,
            "y": 10,
            "z": 1,
            "elements": [
                "bnkrblks:megelium_polished@0"
            ]
        },
        {
            "x": 0,
            "y": 17,
            "z": -2,
            "elements": [
                "bnkrblks:megelium_polished@0"
            ]
        },
        {
            "x": -4,
            "y": 10,
            "z": -4,
            "elements": [
                "bnkrblks:megelium_polished@0"
            ]
        },
        {
            "x": -1,
            "y": 4,
            "z": 2,
            "elements": [
                "bnkrblks:megelium_glass@0"
            ]
        },
        {
            "x": 3,
            "y": 13,
            "z": -2,
            "elements": [
                "bnkrblks:megelium_glass@0"
            ]
        },
        {
            "x": -2,
            "y": 7,
            "z": 3,
            "elements": [
                "bnkrblks:megelium_glass@0"
            ]
        },
        {
            "x": 9,
            "y": 9,
            "z": 1,
            "elements": [
                "bnkrblks:megelium_glass@0"
            ]
        },
        {
            "x": 0,
            "y": 18,
            "z": -2,
            "elements": [
                "bnkrblks:megelium_polished@0"
            ]
        },
        {
            "x": -1,
            "y": 7,
            "z": 4,
            "elements": [
                "avaritia:block_resource@0"
            ]
        },
        {
            "x": -4,
            "y": 10,
            "z": 4,
            "elements": [
                "bnkrblks:megelium_polished@0"
            ]
        },
        {
            "x": -1,
            "y": 18,
            "z": -1,
            "elements": [
                "bnkrblks:megelium_glass@0"
            ]
        },
        {
            "x": 4,
            "y": 14,
            "z": 0,
            "elements": [
                "bnkrblks:megelium_polished@0"
            ]
        },
        {
            "x": -4,
            "y": 9,
            "z": 3,
            "elements": [
                "avaritia:block_resource@0"
            ]
        },
        {
            "x": 5,
            "y": 8,
            "z": -1,
            "elements": [
                "avaritia:block_resource@0"
            ]
        },
        {
            "x": 0,
            "y": 12,
            "z": 8,
            "elements": [
                "bnkrblks:megelium_polished@0"
            ]
        },
        {
            "x": -4,
            "y": 11,
            "z": 3,
            "elements": [
                "avaritia:block_resource@0"
            ]
        },
        {
            "x": -7,
            "y": 10,
            "z": -3,
            "elements": [
                "bnkrblks:megelium_polished@0"
            ]
        },
        {
            "x": 0,
            "y": 10,
            "z": -5,
            "elements": [
                "draconicevolution:reactor_component@0"
            ]
        },
        {
            "x": -1,
            "y": 19,
            "z": -1,
            "elements": [
                "bnkrblks:megelium_glass@0"
            ]
        },
        {
            "x": -1,
            "y": 6,
            "z": -3,
            "elements": [
                "avaritia:block_resource@0"
            ]
        },
        {
            "x": 1,
            "y": 20,
            "z": 0,
            "elements": [
                "bnkrblks:megelium_polished@0"
            ]
        },
        {
            "x": 5,
            "y": 12,
            "z": -1,
            "elements": [
                "avaritia:block_resource@0"
            ]
        },
        {
            "x": -1,
            "y": 15,
            "z": 2,
            "elements": [
                "avaritia:block_resource@0"
            ]
        },
        {
            "x": 0,
            "y": 13,
            "z": -5,
            "elements": [
                "bnkrblks:megelium_polished@0"
            ]
        },
        {
            "x": 2,
            "y": 11,
            "z": 5,
            "elements": [
                "avaritia:block_resource@0"
            ]
        },
        {
            "x": -5,
            "y": 14,
            "z": 0,
            "elements": [
                "bnkrblks:megelium_polished@0"
            ]
        },
        {
            "x": 8,
            "y": 9,
            "z": -1,
            "elements": [
                "bnkrblks:megelium_glass@0"
            ]
        },
        {
            "x": 8,
            "y": 11,
            "z": -1,
            "elements": [
                "bnkrblks:megelium_glass@0"
            ]
        },
        {
            "x": -4,
            "y": 11,
            "z": -3,
            "elements": [
                "avaritia:block_resource@0"
            ]
        },
        {
            "x": 2,
            "y": 15,
            "z": -1,
            "elements": [
                "avaritia:block_resource@0"
            ]
        },
        {
            "x": 0,
            "y": 10,
            "z": 8,
            "elements": [
                "draconicevolution:draconium_block@1"
            ]
        },
        {
            "x": -1,
            "y": 7,
            "z": -4,
            "elements": [
                "avaritia:block_resource@0"
            ]
        },
        {
            "x": 2,
            "y": 10,
            "z": -9,
            "elements": [
                "bnkrblks:megelium_polished@0"
            ]
        },
        {
            "x": 4,
            "y": 15,
            "z": 0,
            "elements": [
                "bnkrblks:megelium_polished@0"
            ]
        },
        {
            "x": -1,
            "y": 17,
            "z": -1,
            "elements": [
                "bnkrblks:megelium_glass@0"
            ]
        },
        {
            "x": 4,
            "y": 13,
            "z": 1,
            "elements": [
                "avaritia:block_resource@0"
            ]
        },
        {
            "x": 0,
            "y": 3,
            "z": -3,
            "elements": [
                "bnkrblks:megelium_polished@0"
            ]
        },
        {
            "x": 6,
            "y": 8,
            "z": 1,
            "elements": [
                "bnkrblks:megelium_glass@0"
            ]
        },
        {
            "x": 0,
            "y": 6,
            "z": -5,
            "elements": [
                "bnkrblks:megelium_polished@0"
            ]
        },
        {
            "x": 7,
            "y": 12,
            "z": 0,
            "elements": [
                "bnkrblks:megelium_polished@0"
            ]
        },
        {
            "x": 2,
            "y": 16,
            "z": -1,
            "elements": [
                "bnkrblks:megelium_glass@0"
            ]
        },
        {
            "x": -5,
            "y": 13,
            "z": 0,
            "elements": [
                "bnkrblks:megelium_polished@0"
            ]
        },
        {
            "x": -2,
            "y": 7,
            "z": -3,
            "elements": [
                "bnkrblks:megelium_glass@0"
            ]
        },
        {
            "x": 0,
            "y": 4,
            "z": -3,
            "elements": [
                "bnkrblks:megelium_polished@0"
            ]
        },
        {
            "x": 2,
            "y": 8,
            "z": -4,
            "elements": [
                "bnkrblks:megelium_glass@0"
            ]
        },
        {
            "x": 1,
            "y": 19,
            "z": 1,
            "elements": [
                "bnkrblks:megelium_glass@0"
            ]
        },
        {
            "x": 0,
            "y": 20,
            "z": -1,
            "elements": [
                "bnkrblks:megelium_polished@0"
            ]
        },
        {
            "x": 0,
            "y": 7,
            "z": -5,
            "elements": [
                "bnkrblks:megelium_polished@0"
            ]
        },
        {
            "x": 3,
            "y": 14,
            "z": 1,
            "elements": [
                "avaritia:block_resource@0"
            ]
        },
        {
            "x": 2,
            "y": 14,
            "z": 2,
            "elements": [
                "bnkrblks:megelium_glass@0"
            ]
        },
        {
            "x": 3,
            "y": 7,
            "z": -2,
            "elements": [
                "bnkrblks:megelium_glass@0"
            ]
        },
        {
            "x": -1,
            "y": 16,
            "z": 2,
            "elements": [
                "bnkrblks:megelium_glass@0"
            ]
        },
        {
            "x": 1,
            "y": 18,
            "z": 1,
            "elements": [
                "bnkrblks:megelium_glass@0"
            ]
        },
        {
            "x": -6,
            "y": 10,
            "z": 3,
            "elements": [
                "bnkrblks:megelium_polished@0"
            ]
        },
        {
            "x": 0,
            "y": 20,
            "z": 1,
            "elements": [
                "bnkrblks:megelium_polished@0"
            ]
        },
        {
            "x": -7,
            "y": 10,
            "z": 3,
            "elements": [
                "bnkrblks:megelium_polished@0"
            ]
        },
        {
            "x": 7,
            "y": 10,
            "z": 0,
            "elements": [
                "draconicevolution:draconium_block@1"
            ]
        },
        {
            "x": -4,
            "y": 9,
            "z": -3,
            "elements": [
                "avaritia:block_resource@0"
            ]
        },
        {
            "x": -5,
            "y": 10,
            "z": -3,
            "elements": [
                "bnkrblks:megelium_polished@0"
            ]
        },
        {
            "x": -1,
            "y": 11,
            "z": -9,
            "elements": [
                "bnkrblks:megelium_glass@0"
            ]
        },
        {
            "x": 7,
            "y": 7,
            "z": 0,
            "elements": [
                "bnkrblks:megelium_polished@0"
            ]
        },
        {
            "x": 1,
            "y": 17,
            "z": 1,
            "elements": [
                "bnkrblks:megelium_glass@0"
            ]
        },
        {
            "x": 0,
            "y": 8,
            "z": 8,
            "elements": [
                "bnkrblks:megelium_polished@0"
            ]
        },
        {
            "x": -1,
            "y": 9,
            "z": 8,
            "elements": [
                "bnkrblks:megelium_glass@0"
            ]
        },
        {
            "x": -3,
            "y": 10,
            "z": -5,
            "elements": [
                "bnkrblks:megelium_polished@0"
            ]
        },
        {
            "x": -3,
            "y": 8,
            "z": -3,
            "elements": [
                "bnkrblks:megelium_glass@0"
            ]
        },
        {
            "x": 7,
            "y": 8,
            "z": 0,
            "elements": [
                "bnkrblks:megelium_polished@0"
            ]
        },
        {
            "x": 10,
            "y": 10,
            "z": 0,
            "elements": [
                "modularmachinery:blockenergyinputhatch"
            ]
        },
        {
            "x": 2,
            "y": 9,
            "z": 6,
            "elements": [
                "bnkrblks:megelium_glass@0"
            ]
        },
        {
            "x": 0,
            "y": 8,
            "z": 9,
            "elements": [
                "bnkrblks:megelium_polished@0"
            ]
        },
        {
            "x": 9,
            "y": 12,
            "z": 0,
            "elements": [
                "bnkrblks:megelium_polished@0"
            ]
        },
        {
            "x": 1,
            "y": 9,
            "z": -7,
            "elements": [
                "bnkrblks:megelium_glass@0"
            ]
        },
        {
            "x": 10,
            "y": 9,
            "z": 0,
            "elements": [
                "bnkrblks:megelium_polished@0"
            ]
        },
        {
            "x": 1,
            "y": 4,
            "z": -2,
            "elements": [
                "bnkrblks:megelium_glass@0"
            ]
        },
        {
            "x": -2,
            "y": 15,
            "z": 1,
            "elements": [
                "avaritia:block_resource@0"
            ]
        },
        {
            "x": 2,
            "y": 4,
            "z": -1,
            "elements": [
                "bnkrblks:megelium_glass@0"
            ]
        },
        {
            "x": 9,
            "y": 10,
            "z": 0,
            "elements": [
                "draconicevolution:draconium_block@1"
            ]
        },
        {
            "x": -1,
            "y": 8,
            "z": 6,
            "elements": [
                "bnkrblks:megelium_glass@0"
            ]
        },
        {
            "x": 1,
            "y": 5,
            "z": -2,
            "elements": [
                "avaritia:block_resource@0"
            ]
        },
        {
            "x": -2,
            "y": 15,
            "z": -1,
            "elements": [
                "avaritia:block_resource@0"
            ]
        },
        {
            "x": 1,
            "y": 4,
            "z": 2,
            "elements": [
                "bnkrblks:megelium_glass@0"
            ]
        },
        {
            "x": -9,
            "y": 10,
            "z": -2,
            "elements": [
                "bnkrblks:megelium_polished@0"
            ]
        },
        {
            "x": 10,
            "y": 11,
            "z": 0,
            "elements": [
                "bnkrblks:megelium_polished@0"
            ]
        },
        {
            "x": 2,
            "y": 5,
            "z": -1,
            "elements": [
                "avaritia:block_resource@0"
            ]
        },
        {
            "x": 7,
            "y": 13,
            "z": 0,
            "elements": [
                "bnkrblks:megelium_polished@0"
            ]
        },
        {
            "x": 4,
            "y": 7,
            "z": -1,
            "elements": [
                "avaritia:block_resource@0"
            ]
        },
        {
            "x": -2,
            "y": 16,
            "z": -1,
            "elements": [
                "bnkrblks:megelium_glass@0"
            ]
        },
        {
            "x": 8,
            "y": 10,
            "z": 0,
            "elements": [
                "draconicevolution:draconium_block@1"
            ]
        },
        {
            "x": -2,
            "y": 14,
            "z": -2,
            "elements": [
                "bnkrblks:megelium_glass@0"
            ]
        },
        {
            "x": 0,
            "y": 1,
            "z": 2,
            "elements": [
                "bnkrblks:megelium_polished@0"
            ]
        },
        {
            "x": -2,
            "y": 16,
            "z": 1,
            "elements": [
                "bnkrblks:megelium_glass@0"
            ]
        },
        {
            "x": 1,
            "y": 7,
            "z": 4,
            "elements": [
                "avaritia:block_resource@0"
            ]
        },
        {
            "x": 0,
            "y": 10,
            "z": -6,
            "elements": [
                "draconicevolution:draconium_block@1"
            ]
        },
        {
            "x": -2,
            "y": 12,
            "z": 4,
            "elements": [
                "bnkrblks:megelium_glass@0"
            ]
        },
        {
            "x": 1,
            "y": 6,
            "z": -3,
            "elements": [
                "avaritia:block_resource@0"
            ]
        },
        {
            "x": -1,
            "y": 9,
            "z": 9,
            "elements": [
                "bnkrblks:megelium_glass@0"
            ]
        },
        {
            "x": -2,
            "y": 14,
            "z": 2,
            "elements": [
                "bnkrblks:megelium_glass@0"
            ]
        },
        {
            "x": 1,
            "y": 13,
            "z": -4,
            "elements": [
                "avaritia:block_resource@0"
            ]
        },
        {
            "x": 0,
            "y": 3,
            "z": 2,
            "elements": [
                "bnkrblks:megelium_polished@0"
            ]
        },
        {
            "x": -1,
            "y": 6,
            "z": 3,
            "elements": [
                "avaritia:block_resource@0"
            ]
        },
        {
            "x": 5,
            "y": 14,
            "z": 0,
            "elements": [
                "bnkrblks:megelium_polished@0"
            ]
        },
        {
            "x": 8,
            "y": 12,
            "z": 0,
            "elements": [
                "bnkrblks:megelium_polished@0"
            ]
        },
        {
            "x": -9,
            "y": 10,
            "z": 2,
            "elements": [
                "bnkrblks:megelium_polished@0"
            ]
        },
        {
            "x": 2,
            "y": 10,
            "z": -8,
            "elements": [
                "bnkrblks:megelium_polished@0"
            ]
        },
        {
            "x": -1,
            "y": 11,
            "z": 9,
            "elements": [
                "bnkrblks:megelium_glass@0"
            ]
        },
        {
            "x": 4,
            "y": 7,
            "z": 1,
            "elements": [
                "avaritia:block_resource@0"
            ]
        },
        {
            "x": 2,
            "y": 11,
            "z": 6,
            "elements": [
                "bnkrblks:megelium_glass@0"
            ]
        },
        {
            "x": 0,
            "y": 2,
            "z": 2,
            "elements": [
                "bnkrblks:megelium_polished@0"
            ]
        },
        {
            "x": -3,
            "y": 7,
            "z": 2,
            "elements": [
                "bnkrblks:megelium_glass@0"
            ]
        },
        {
            "x": 0,
            "y": 12,
            "z": -8,
            "elements": [
                "bnkrblks:megelium_polished@0"
            ]
        },
        {
            "x": 0,
            "y": 13,
            "z": -6,
            "elements": [
                "bnkrblks:megelium_polished@0"
            ]
        },
        {
            "x": 5,
            "y": 13,
            "z": 0,
            "elements": [
                "bnkrblks:megelium_polished@0"
            ]
        },
        {
            "x": -5,
            "y": 11,
            "z": -2,
            "elements": [
                "avaritia:block_resource@0"
            ]
        },
        {
            "x": 1,
            "y": 13,
            "z": 4,
            "elements": [
                "avaritia:block_resource@0"
            ]
        },
        {
            "x": 6,
            "y": 10,
            "z": 0,
            "elements": [
                "draconicevolution:draconium_block@1"
            ]
        },
        {
            "x": 0,
            "y": 17,
            "z": -3,
            "elements": [
                "bnkrblks:megelium_polished@0"
            ]
        },
        {
            "x": -1,
            "y": 11,
            "z": 7,
            "elements": [
                "bnkrblks:megelium_glass@0"
            ]
        },
        {
            "x": 4,
            "y": 9,
            "z": 3,
            "elements": [
                "avaritia:block_resource@0"
            ]
        },
        {
            "x": 0,
            "y": 8,
            "z": -8,
            "elements": [
                "bnkrblks:megelium_polished@0"
            ]
        },
        {
            "x": -6,
            "y": 9,
            "z": -2,
            "elements": [
                "bnkrblks:megelium_glass@0"
            ]
        },
        {
            "x": 0,
            "y": 3,
            "z": -2,
            "elements": [
                "bnkrblks:megelium_polished@0"
            ]
        },
        {
            "x": 1,
            "y": 10,
            "z": 10,
            "elements": [
                "bnkrblks:megelium_polished@0"
            ]
        },
        {
            "x": -8,
            "y": 11,
            "z": 1,
            "elements": [
                "bnkrblks:megelium_glass@0"
            ]
        },
        {
            "x": 1,
            "y": 14,
            "z": 3,
            "elements": [
                "avaritia:block_resource@0"
            ]
        },
        {
            "x": -3,
            "y": 7,
            "z": -2,
            "elements": [
                "bnkrblks:megelium_glass@0"
            ]
        },
        {
            "x": 4,
            "y": 9,
            "z": -3,
            "elements": [
                "avaritia:block_resource@0"
            ]
        },
        {
            "x": -6,
            "y": 11,
            "z": 2,
            "elements": [
                "bnkrblks:megelium_glass@0"
            ]
        },
        {
            "x": -2,
            "y": 13,
            "z": -3,
            "elements": [
                "bnkrblks:megelium_glass@0"
            ]
        },
        {
            "x": 0,
            "y": 12,
            "z": -9,
            "elements": [
                "bnkrblks:megelium_polished@0"
            ]
        },
        {
            "x": 3,
            "y": 16,
            "z": 0,
            "elements": [
                "bnkrblks:megelium_polished@0"
            ]
        },
        {
            "x": 4,
            "y": 10,
            "z": -4,
            "elements": [
                "bnkrblks:megelium_polished@0"
            ]
        },
        {
            "x": 0,
            "y": 2,
            "z": -2,
            "elements": [
                "bnkrblks:megelium_polished@0"
            ]
        },
        {
            "x": 3,
            "y": 15,
            "z": 0,
            "elements": [
                "bnkrblks:megelium_polished@0"
            ]
        },
        {
            "x": 1,
            "y": 1,
            "z": 1,
            "elements": [
                "bnkrblks:megelium_glass@0"
            ]
        },
        {
            "x": 4,
            "y": 11,
            "z": 3,
            "elements": [
                "avaritia:block_resource@0"
            ]
        },
        {
            "x": 8,
            "y": 8,
            "z": 0,
            "elements": [
                "bnkrblks:megelium_polished@0"
            ]
        },
        {
            "x": -2,
            "y": 5,
            "z": 1,
            "elements": [
                "avaritia:block_resource@0"
            ]
        },
        {
            "x": 2,
            "y": 10,
            "z": 9,
            "elements": [
                "bnkrblks:megelium_polished@0"
            ]
        },
        {
            "x": 5,
            "y": 10,
            "z": 0,
            "elements": [
                "draconicevolution:reactor_component@0"
            ]
        },
        {
            "x": 0,
            "y": 1,
            "z": -2,
            "elements": [
                "bnkrblks:megelium_polished@0"
            ]
        },
        {
            "x": 1,
            "y": 3,
            "z": 1,
            "elements": [
                "bnkrblks:megelium_glass@0"
            ]
        },
        {
            "x": -6,
            "y": 11,
            "z": -2,
            "elements": [
                "bnkrblks:megelium_glass@0"
            ]
        },
        {
            "x": 1,
            "y": 9,
            "z": 7,
            "elements": [
                "bnkrblks:megelium_glass@0"
            ]
        },
        {
            "x": 0,
            "y": 10,
            "z": -8,
            "elements": [
                "draconicevolution:draconium_block@1"
            ]
        },
        {
            "x": -8,
            "y": 9,
            "z": 1,
            "elements": [
                "bnkrblks:megelium_glass@0"
            ]
        },
        {
            "x": 1,
            "y": 2,
            "z": 1,
            "elements": [
                "bnkrblks:megelium_glass@0"
            ]
        },
        {
            "x": -5,
            "y": 9,
            "z": -2,
            "elements": [
                "avaritia:block_resource@0"
            ]
        },
        {
            "x": -7,
            "y": 10,
            "z": 2,
            "elements": [
                "bnkrblks:megelium_polished@0"
            ]
        },
        {
            "x": -2,
            "y": 4,
            "z": 1,
            "elements": [
                "bnkrblks:megelium_glass@0"
            ]
        },
        {
            "x": -2,
            "y": 10,
            "z": 7,
            "elements": [
                "bnkrblks:megelium_polished@0"
            ]
        },
        {
            "x": 4,
            "y": 11,
            "z": -3,
            "elements": [
                "avaritia:block_resource@0"
            ]
        },
        {
            "x": -2,
            "y": 13,
            "z": 3,
            "elements": [
                "bnkrblks:megelium_glass@0"
            ]
        },
        {
            "x": 9,
            "y": 8,
            "z": 0,
            "elements": [
                "bnkrblks:megelium_polished@0"
            ]
        },
        {
            "x": -6,
            "y": 9,
            "z": 2,
            "elements": [
                "bnkrblks:megelium_glass@0"
            ]
        },
        {
            "x": -1,
            "y": 11,
            "z": -8,
            "elements": [
                "bnkrblks:megelium_glass@0"
            ]
        },
        {
            "x": 0,
            "y": 13,
            "z": 5,
            "elements": [
                "bnkrblks:megelium_polished@0"
            ]
        },
        {
            "x": 1,
            "y": 19,
            "z": -1,
            "elements": [
                "bnkrblks:megelium_glass@0"
            ]
        },
        {
            "x": 0,
            "y": 8,
            "z": -9,
            "elements": [
                "bnkrblks:megelium_polished@0"
            ]
        },
        {
            "x": 0,
            "y": 17,
            "z": 0,
            "elements": [
                "draconicevolution:draconium_block@1"
            ]
        },
        {
            "x": 1,
            "y": 11,
            "z": 7,
            "elements": [
                "bnkrblks:megelium_glass@0"
            ]
        },
        {
            "x": -10,
            "y": 10,
            "z": -1,
            "elements": [
                "bnkrblks:megelium_polished@0"
            ]
        },
        {
            "x": 3,
            "y": 12,
            "z": -3,
            "elements": [
                "bnkrblks:megelium_glass@0"
            ]
        },
        {
            "x": 7,
            "y": 9,
            "z": -1,
            "elements": [
                "bnkrblks:megelium_glass@0"
            ]
        },
        {
            "x": -2,
            "y": 6,
            "z": 2,
            "elements": [
                "bnkrblks:megelium_glass@0"
            ]
        },
        {
            "x": 0,
            "y": 14,
            "z": 5,
            "elements": [
                "bnkrblks:megelium_polished@0"
            ]
        },
        {
            "x": 1,
            "y": 18,
            "z": -1,
            "elements": [
                "bnkrblks:megelium_glass@0"
            ]
        },
        {
            "x": -8,
            "y": 10,
            "z": 2,
            "elements": [
                "bnkrblks:megelium_polished@0"
            ]
        },
        {
            "x": -1,
            "y": 14,
            "z": 3,
            "elements": [
                "avaritia:block_resource@0"
            ]
        },
        {
            "x": -1,
            "y": 9,
            "z": -8,
            "elements": [
                "bnkrblks:megelium_glass@0"
            ]
        },
        {
            "x": 4,
            "y": 13,
            "z": -1,
            "elements": [
                "avaritia:block_resource@0"
            ]
        },
        {
            "x": 0,
            "y": 18,
            "z": 0,
            "elements": [
                "draconicevolution:draconium_block@1"
            ]
        },
        {
            "x": -8,
            "y": 10,
            "z": -2,
            "elements": [
                "bnkrblks:megelium_polished@0"
            ]
        },
        {
            "x": -5,
            "y": 9,
            "z": 2,
            "elements": [
                "avaritia:block_resource@0"
            ]
        },
        {
            "x": 6,
            "y": 13,
            "z": 0,
            "elements": [
                "bnkrblks:megelium_polished@0"
            ]
        },
        {
            "x": -2,
            "y": 6,
            "z": -2,
            "elements": [
                "bnkrblks:megelium_glass@0"
            ]
        },
        {
            "x": -2,
            "y": 8,
            "z": 4,
            "elements": [
                "bnkrblks:megelium_glass@0"
            ]
        },
        {
            "x": 0,
            "y": 19,
            "z": 0,
            "elements": [
                "draconicevolution:draconium_block@1"
            ]
        },
        {
            "x": 3,
            "y": 17,
            "z": 0,
            "elements": [
                "bnkrblks:megelium_polished@0"
            ]
        },
        {
            "x": -5,
            "y": 12,
            "z": 1,
            "elements": [
                "avaritia:block_resource@0"
            ]
        },
        {
            "x": -1,
            "y": 12,
            "z": 6,
            "elements": [
                "bnkrblks:megelium_glass@0"
            ]
        },
        {
            "x": -2,
            "y": 10,
            "z": -8,
            "elements": [
                "bnkrblks:megelium_polished@0"
            ]
        },
        {
            "x": 0,
            "y": 15,
            "z": -3,
            "elements": [
                "bnkrblks:megelium_polished@0"
            ]
        },
        {
            "x": -1,
            "y": 9,
            "z": 7,
            "elements": [
                "bnkrblks:megelium_glass@0"
            ]
        },
        {
            "x": 1,
            "y": 11,
            "z": -7,
            "elements": [
                "bnkrblks:megelium_glass@0"
            ]
        },
        {
            "x": 2,
            "y": 7,
            "z": 3,
            "elements": [
                "bnkrblks:megelium_glass@0"
            ]
        },
        {
            "x": -5,
            "y": 11,
            "z": 2,
            "elements": [
                "avaritia:block_resource@0"
            ]
        },
        {
            "x": 1,
            "y": 7,
            "z": -4,
            "elements": [
                "avaritia:block_resource@0"
            ]
        },
        {
            "x": -2,
            "y": 12,
            "z": -4,
            "elements": [
                "bnkrblks:megelium_glass@0"
            ]
        },
        {
            "x": 3,
            "y": 10,
            "z": 5,
            "elements": [
                "bnkrblks:megelium_polished@0"
            ]
        },
        {
            "x": 4,
            "y": 10,
            "z": 4,
            "elements": [
                "bnkrblks:megelium_polished@0"
            ]
        },
        {
            "x": 3,
            "y": 10,
            "z": -6,
            "elements": [
                "bnkrblks:megelium_polished@0"
            ]
        },
        {
            "x": 1,
            "y": 14,
            "z": -3,
            "elements": [
                "avaritia:block_resource@0"
            ]
        },
        {
            "x": 1,
            "y": 17,
            "z": -1,
            "elements": [
                "bnkrblks:megelium_glass@0"
            ]
        },
        {
            "x": 0,
            "y": 10,
            "z": -9,
            "elements": [
                "draconicevolution:draconium_block@1"
            ]
        },
        {
            "x": 0,
            "y": 16,
            "z": -3,
            "elements": [
                "bnkrblks:megelium_polished@0"
            ]
        },
        {
            "x": 0,
            "y": 20,
            "z": 0,
            "elements": [
                "modularmachineryaddons:blockbiomeproviderinput@0"
            ]
        },
        {
            "x": 3,
            "y": 13,
            "z": 2,
            "elements": [
                "bnkrblks:megelium_glass@0"
            ]
        },
        {
            "x": -2,
            "y": 11,
            "z": -6,
            "elements": [
                "bnkrblks:megelium_glass@0"
            ]
        },
        {
            "x": -7,
            "y": 9,
            "z": 1,
            "elements": [
                "bnkrblks:megelium_glass@0"
            ]
        },
        {
            "x": 1,
            "y": 12,
            "z": -6,
            "elements": [
                "bnkrblks:megelium_glass@0"
            ]
        },
        {
            "x": 6,
            "y": 11,
            "z": 2,
            "elements": [
                "bnkrblks:megelium_glass@0"
            ]
        },
        {
            "x": 4,
            "y": 10,
            "z": -5,
            "elements": [
                "bnkrblks:megelium_polished@0"
            ]
        },
        {
            "x": -5,
            "y": 12,
            "z": -1,
            "elements": [
                "avaritia:block_resource@0"
            ]
        },
        {
            "x": 0,
            "y": 12,
            "z": -7,
            "elements": [
                "bnkrblks:megelium_polished@0"
            ]
        },
        {
            "x": 5,
            "y": 6,
            "z": 0,
            "elements": [
                "bnkrblks:megelium_polished@0"
            ]
        },
        {
            "x": 0,
            "y": 17,
            "z": 2,
            "elements": [
                "bnkrblks:megelium_polished@0"
            ]
        },
        {
            "x": 1,
            "y": 9,
            "z": -8,
            "elements": [
                "bnkrblks:megelium_glass@0"
            ]
        },
        {
            "x": -7,
            "y": 9,
            "z": -1,
            "elements": [
                "bnkrblks:megelium_glass@0"
            ]
        },
        {
            "x": 1,
            "y": 8,
            "z": 5,
            "elements": [
                "avaritia:block_resource@0"
            ]
        },
        {
            "x": 0,
            "y": 18,
            "z": 2,
            "elements": [
                "bnkrblks:megelium_polished@0"
            ]
        },
        {
            "x": 0,
            "y": 13,
            "z": -7,
            "elements": [
                "bnkrblks:megelium_polished@0"
            ]
        },
        {
            "x": -7,
            "y": 11,
            "z": -1,
            "elements": [
                "bnkrblks:megelium_glass@0"
            ]
        },
        {
            "x": 0,
            "y": 16,
            "z": 0,
            "elements": [
                "draconicevolution:draconium_block@1"
            ]
        },
        {
            "x": -2,
            "y": 11,
            "z": 5,
            "elements": [
                "avaritia:block_resource@0"
            ]
        },
        {
            "x": 5,
            "y": 7,
            "z": 0,
            "elements": [
                "bnkrblks:megelium_polished@0"
            ]
        },
        {
            "x": 6,
            "y": 9,
            "z": 2,
            "elements": [
                "bnkrblks:megelium_glass@0"
            ]
        },
        {
            "x": 0,
            "y": 0,
            "z": 1,
            "elements": [
                "bnkrblks:megelium_polished@0"
            ]
        },
        {
            "x": 0,
            "y": 19,
            "z": 2,
            "elements": [
                "bnkrblks:megelium_polished@0"
            ]
        },
        {
            "x": -3,
            "y": 17,
            "z": 0,
            "elements": [
                "bnkrblks:megelium_polished@0"
            ]
        },
        {
            "x": 1,
            "y": 9,
            "z": 8,
            "elements": [
                "bnkrblks:megelium_glass@0"
            ]
        },
        {
            "x": 0,
            "y": 15,
            "z": 0,
            "elements": [
                "draconicevolution:reactor_component@0"
            ]
        },
        {
            "x": 2,
            "y": 13,
            "z": 3,
            "elements": [
                "bnkrblks:megelium_glass@0"
            ]
        },
        {
            "x": 3,
            "y": 5,
            "z": 0,
            "elements": [
                "bnkrblks:megelium_polished@0"
            ]
        },
        {
            "x": -4,
            "y": 8,
            "z": -2,
            "elements": [
                "bnkrblks:megelium_glass@0"
            ]
        },
        {
            "x": 1,
            "y": 12,
            "z": -5,
            "elements": [
                "avaritia:block_resource@0"
            ]
        },
        {
            "x": 6,
            "y": 10,
            "z": -3,
            "elements": [
                "bnkrblks:megelium_polished@0"
            ]
        },
        {
            "x": 6,
            "y": 7,
            "z": 0,
            "elements": [
                "bnkrblks:megelium_polished@0"
            ]
        },
        {
            "x": -5,
            "y": 8,
            "z": -1,
            "elements": [
                "avaritia:block_resource@0"
            ]
        },
        {
            "x": -4,
            "y": 7,
            "z": 1,
            "elements": [
                "avaritia:block_resource@0"
            ]
        },
        {
            "x": -1,
            "y": 5,
            "z": -2,
            "elements": [
                "avaritia:block_resource@0"
            ]
        },
        {
            "x": -7,
            "y": 11,
            "z": 1,
            "elements": [
                "bnkrblks:megelium_glass@0"
            ]
        },
        {
            "x": -3,
            "y": 16,
            "z": 0,
            "elements": [
                "bnkrblks:megelium_polished@0"
            ]
        },
        {
            "x": 0,
            "y": 0,
            "z": -1,
            "elements": [
                "bnkrblks:megelium_polished@0"
            ]
        },
        {
            "x": -1,
            "y": 20,
            "z": 0,
            "elements": [
                "bnkrblks:megelium_polished@0"
            ]
        },
        {
            "x": 1,
            "y": 12,
            "z": 5,
            "elements": [
                "avaritia:block_resource@0"
            ]
        },
        {
            "x": -3,
            "y": 15,
            "z": 0,
            "elements": [
                "bnkrblks:megelium_polished@0"
            ]
        },
        {
            "x": -1,
            "y": 2,
            "z": -1,
            "elements": [
                "bnkrblks:megelium_glass@0"
            ]
        },
        {
            "x": -5,
            "y": 8,
            "z": 1,
            "elements": [
                "avaritia:block_resource@0"
            ]
        },
        {
            "x": 3,
            "y": 10,
            "z": -7,
            "elements": [
                "bnkrblks:megelium_polished@0"
            ]
        },
        {
            "x": -1,
            "y": 1,
            "z": 1,
            "elements": [
                "bnkrblks:megelium_glass@0"
            ]
        },
        {
            "x": 1,
            "y": 8,
            "z": -6,
            "elements": [
                "bnkrblks:megelium_glass@0"
            ]
        },
        {
            "x": -4,
            "y": 7,
            "z": -1,
            "elements": [
                "avaritia:block_resource@0"
            ]
        },
        {
            "x": -1,
            "y": 4,
            "z": -2,
            "elements": [
                "bnkrblks:megelium_glass@0"
            ]
        },
        {
            "x": 1,
            "y": 11,
            "z": 8,
            "elements": [
                "bnkrblks:megelium_glass@0"
            ]
        },
        {
            "x": -1,
            "y": 1,
            "z": -1,
            "elements": [
                "bnkrblks:megelium_glass@0"
            ]
        },
        {
            "x": -1,
            "y": 3,
            "z": 1,
            "elements": [
                "bnkrblks:megelium_glass@0"
            ]
        },
        {
            "x": 2,
            "y": 6,
            "z": -2,
            "elements": [
                "bnkrblks:megelium_glass@0"
            ]
        },
        {
            "x": 0,
            "y": 8,
            "z": -7,
            "elements": [
                "bnkrblks:megelium_polished@0"
            ]
        },
        {
            "x": -1,
            "y": 2,
            "z": 1,
            "elements": [
                "bnkrblks:megelium_glass@0"
            ]
        },
        {
            "x": 7,
            "y": 10,
            "z": -3,
            "elements": [
                "bnkrblks:megelium_polished@0"
            ]
        },
        {
            "x": -6,
            "y": 8,
            "z": -1,
            "elements": [
                "bnkrblks:megelium_glass@0"
            ]
        },
        {
            "x": -3,
            "y": 6,
            "z": -1,
            "elements": [
                "avaritia:block_resource@0"
            ]
        },
        {
            "x": 0,
            "y": 7,
            "z": -7,
            "elements": [
                "bnkrblks:megelium_polished@0"
            ]
        },
        {
            "x": -3,
            "y": 6,
            "z": 1,
            "elements": [
                "avaritia:block_resource@0"
            ]
        },
        {
            "x": -4,
            "y": 12,
            "z": -2,
            "elements": [
                "bnkrblks:megelium_glass@0"
            ]
        },
        {
            "x": 5,
            "y": 10,
            "z": 3,
            "elements": [
                "bnkrblks:megelium_polished@0"
            ]
        },
        {
            "x": -1,
            "y": 3,
            "z": -1,
            "elements": [
                "bnkrblks:megelium_glass@0"
            ]
        },
        {
            "x": -7,
            "y": 10,
            "z": -2,
            "elements": [
                "bnkrblks:megelium_polished@0"
            ]
        },
        {
            "x": 0,
            "y": 10,
            "z": -7,
            "elements": [
                "draconicevolution:draconium_block@1"
            ]
        },
        {
            "x": -6,
            "y": 8,
            "z": 1,
            "elements": [
                "bnkrblks:megelium_glass@0"
            ]
        },
        {
            "x": 1,
            "y": 11,
            "z": -8,
            "elements": [
                "bnkrblks:megelium_glass@0"
            ]
        },
        {
            "x": 0,
            "y": 10,
            "z": 0,
            "elements": [
                "draconicevolution:reactor_core@0"
            ]
        },
        {
            "x": -8,
            "y": 11,
            "z": -1,
            "elements": [
                "bnkrblks:megelium_glass@0"
            ]
        },
        {
            "x": -6,
            "y": 12,
            "z": 1,
            "elements": [
                "bnkrblks:megelium_glass@0"
            ]
        },
        {
            "x": 2,
            "y": 17,
            "z": 0,
            "elements": [
                "bnkrblks:megelium_polished@0"
            ]
        },
        {
            "x": 0,
            "y": 7,
            "z": -6,
            "elements": [
                "bnkrblks:megelium_polished@0"
            ]
        },
        {
            "x": -3,
            "y": 14,
            "z": 1,
            "elements": [
                "avaritia:block_resource@0"
            ]
        },
        {
            "x": 2,
            "y": 18,
            "z": 0,
            "elements": [
                "bnkrblks:megelium_polished@0"
            ]
        },
        {
            "x": -9,
            "y": 10,
            "z": 0,
            "elements": [
                "draconicevolution:draconium_block@1"
            ]
        },
        {
            "x": 1,
            "y": 15,
            "z": -2,
            "elements": [
                "avaritia:block_resource@0"
            ]
        },
        {
            "x": 4,
            "y": 10,
            "z": 5,
            "elements": [
                "bnkrblks:megelium_polished@0"
            ]
        },
        {
            "x": -3,
            "y": 10,
            "z": -7,
            "elements": [
                "bnkrblks:megelium_polished@0"
            ]
        },
        {
            "x": 2,
            "y": 19,
            "z": 0,
            "elements": [
                "bnkrblks:megelium_polished@0"
            ]
        },
        {
            "x": -2,
            "y": 4,
            "z": -1,
            "elements": [
                "bnkrblks:megelium_glass@0"
            ]
        },
        {
            "x": 1,
            "y": 1,
            "z": -1,
            "elements": [
                "bnkrblks:megelium_glass@0"
            ]
        },
        {
            "x": 1,
            "y": 2,
            "z": -1,
            "elements": [
                "bnkrblks:megelium_glass@0"
            ]
        },
        {
            "x": -3,
            "y": 10,
            "z": -6,
            "elements": [
                "bnkrblks:megelium_polished@0"
            ]
        },
        {
            "x": 3,
            "y": 4,
            "z": 0,
            "elements": [
                "bnkrblks:megelium_polished@0"
            ]
        },
        {
            "x": -2,
            "y": 5,
            "z": -1,
            "elements": [
                "avaritia:block_resource@0"
            ]
        },
        {
            "x": 7,
            "y": 10,
            "z": 3,
            "elements": [
                "bnkrblks:megelium_polished@0"
            ]
        },
        {
            "x": -1,
            "y": 9,
            "z": -7,
            "elements": [
                "bnkrblks:megelium_glass@0"
            ]
        },
        {
            "x": -8,
            "y": 9,
            "z": -1,
            "elements": [
                "bnkrblks:megelium_glass@0"
            ]
        },
        {
            "x": -2,
            "y": 10,
            "z": -7,
            "elements": [
                "bnkrblks:megelium_polished@0"
            ]
        },
        {
            "x": 3,
            "y": 6,
            "z": 1,
            "elements": [
                "avaritia:block_resource@0"
            ]
        },
        {
            "x": -9,
            "y": 12,
            "z": 0,
            "elements": [
                "bnkrblks:megelium_polished@0"
            ]
        },
        {
            "x": 1,
            "y": 3,
            "z": -1,
            "elements": [
                "bnkrblks:megelium_glass@0"
            ]
        },
        {
            "x": 3,
            "y": 3,
            "z": 0,
            "elements": [
                "bnkrblks:megelium_polished@0"
            ]
        },
        {
            "x": 3,
            "y": 7,
            "z": 2,
            "elements": [
                "bnkrblks:megelium_glass@0"
            ]
        },
        {
            "x": 0,
            "y": 5,
            "z": 0,
            "elements": [
                "draconicevolution:reactor_component@0"
            ]
        },
        {
            "x": -1,
            "y": 16,
            "z": -2,
            "elements": [
                "bnkrblks:megelium_glass@0"
            ]
        },
        {
            "x": 0,
            "y": 12,
            "z": 9,
            "elements": [
                "bnkrblks:megelium_polished@0"
            ]
        },
        {
            "x": 0,
            "y": 4,
            "z": 0,
            "elements": [
                "draconicevolution:draconium_block@1"
            ]
        },
        {
            "x": 0,
            "y": 15,
            "z": 4,
            "elements": [
                "bnkrblks:megelium_polished@0"
            ]
        },
        {
            "x": 2,
            "y": 14,
            "z": -2,
            "elements": [
                "bnkrblks:megelium_glass@0"
            ]
        },
        {
            "x": -1,
            "y": 10,
            "z": 10,
            "elements": [
                "bnkrblks:megelium_polished@0"
            ]
        },
        {
            "x": -9,
            "y": 9,
            "z": 1,
            "elements": [
                "bnkrblks:megelium_glass@0"
            ]
        },
        {
            "x": -2,
            "y": 10,
            "z": 8,
            "elements": [
                "bnkrblks:megelium_polished@0"
            ]
        },
        {
            "x": -3,
            "y": 13,
            "z": 2,
            "elements": [
                "bnkrblks:megelium_glass@0"
            ]
        },
        {
            "x": -2,
            "y": 9,
            "z": 5,
            "elements": [
                "avaritia:block_resource@0"
            ]
        },
        {
            "x": 2,
            "y": 12,
            "z": 4,
            "elements": [
                "bnkrblks:megelium_glass@0"
            ]
        },
        {
            "x": -1,
            "y": 15,
            "z": -2,
            "elements": [
                "avaritia:block_resource@0"
            ]
        },
        {
            "x": 0,
            "y": 3,
            "z": 0,
            "elements": [
                "draconicevolution:draconium_block@1"
            ]
        },
        {
            "x": -10,
            "y": 10,
            "z": 1,
            "elements": [
                "bnkrblks:megelium_polished@0"
            ]
        },
        {
            "x": 5,
            "y": 10,
            "z": 4,
            "elements": [
                "bnkrblks:megelium_polished@0"
            ]
        },
        {
            "x": 5,
            "y": 11,
            "z": -2,
            "elements": [
                "avaritia:block_resource@0"
            ]
        },
        {
            "x": 1,
            "y": 5,
            "z": 2,
            "elements": [
                "avaritia:block_resource@0"
            ]
        },
        {
            "x": -6,
            "y": 7,
            "z": 0,
            "elements": [
                "bnkrblks:megelium_polished@0"
            ]
        },
        {
            "x": 3,
            "y": 11,
            "z": 4,
            "elements": [
                "avaritia:block_resource@0"
            ]
        },
        {
            "x": 0,
            "y": 10,
            "z": 9,
            "elements": [
                "draconicevolution:draconium_block@1"
            ]
        },
        {
            "x": 0,
            "y": 2,
            "z": 0,
            "elements": [
                "draconicevolution:draconium_block@1"
            ]
        },
        {
            "x": -3,
            "y": 4,
            "z": 0,
            "elements": [
                "bnkrblks:megelium_polished@0"
            ]
        },
        {
            "x": -9,
            "y": 11,
            "z": 1,
            "elements": [
                "bnkrblks:megelium_glass@0"
            ]
        },
        {
            "x": -2,
            "y": 9,
            "z": -6,
            "elements": [
                "bnkrblks:megelium_glass@0"
            ]
        },
        {
            "x": -4,
            "y": 13,
            "z": -1,
            "elements": [
                "avaritia:block_resource@0"
            ]
        },
        {
            "x": -9,
            "y": 8,
            "z": 0,
            "elements": [
                "bnkrblks:megelium_polished@0"
            ]
        },
        {
            "x": 0,
            "y": 1,
            "z": 0,
            "elements": [
                "draconicevolution:draconium_block@1"
            ]
        },
        {
            "x": -3,
            "y": 3,
            "z": 0,
            "elements": [
                "bnkrblks:megelium_polished@0"
            ]
        },
        {
            "x": 5,
            "y": 9,
            "z": -2,
            "elements": [
                "avaritia:block_resource@0"
            ]
        }
    ]}