{
    "registryname": "mythic_processor_muon_extractor",
    "localizedname": "Mythic Processor: Muon Extractor",
	"color": "464f47",
    "modifiers": [
        {
            "elements": "contenttweaker:mythic_coil_t3@0",
            "x": 0,
            "y": 3,
            "z": 1,
            "description": "x16并行",
            "modifiers": [{
                "io": "output",
                "target": "modularmachinery:item",
                "operation": 1,
                "multiplier": 16
            },
            {
                "io": "input",
                "target": "modularmachinery:item",
                "operation": 1,
                "multiplier": 16
            }]
        }
    ],
    "parts": [
        {
            "x": -1,
            "y": 0,
            "z": 0,
            "elements": [
                "nuclearcraft:fission_block@0"
            ]
        },
        {
            "x": -1,
            "y": 0,
            "z": 1,
            "elements": [
                "nuclearcraft:fission_block@0"
            ]
        },
        {
            "x": 0,
            "y": 2,
            "z": 2,
            "elements": [
                "contenttweaker:awakened_electromagnet@0"
            ]
        },
        {
            "x": 1,
            "y": 2,
            "z": 1,
            "elements": [
                "contenttweaker:awakened_electromagnet@0"
            ]
        },
        {
            "x": 0,
            "y": 0,
            "z": 1,
            "elements": [
                "modularmachinery:blockenergyinputhatch"
            ]
        },
        {
            "x": 1,
            "y": 0,
            "z": 0,
            "elements": [
                "nuclearcraft:fission_block@0"
            ]
        },
        {
            "x": -1,
            "y": 0,
            "z": 2,
            "elements": [
                "nuclearcraft:fission_block@0"
            ]
        },
        {
            "x": 1,
            "y": 2,
            "z": 2,
            "elements": [
                "contenttweaker:awakened_electromagnet@0"
            ]
        },
        {
            "x": 1,
            "y": 0,
            "z": 1,
            "elements": [
                "nuclearcraft:fission_block@0"
            ]
        },
        {
            "x": 0,
            "y": 0,
            "z": 2,
            "elements": [
                "generalized_input_item"
            ]
        },
        {
            "x": 1,
            "y": 0,
            "z": 2,
            "elements": [
                "nuclearcraft:fission_block@0"
            ]
        },
        {
            "x": -1,
            "y": 3,
            "z": 0,
            "elements": [
                "nuclearcraft:fission_block@0"
            ]
        },
        {
            "x": 0,
            "y": 3,
            "z": 0,
            "elements": [
                "contenttweaker:muon_extractor"
            ]
        },
        {
            "x": -1,
            "y": 3,
            "z": 1,
            "elements": [
                "nuclearcraft:fission_block@0"
            ]
        },
        {
            "x": 0,
            "y": 3,
            "z": 1,
            "elements": [
                "contenttweaker:mythic_coil_t2@0"
            ]
        },
        {
            "x": 1,
            "y": 3,
            "z": 0,
            "elements": [
                "nuclearcraft:fission_block@0"
            ]
        },
        {
            "x": -1,
            "y": 1,
            "z": 0,
            "elements": [
                "contenttweaker:awakened_electromagnet@0"
            ]
        },
        {
            "x": -1,
            "y": 3,
            "z": 2,
            "elements": [
                "nuclearcraft:fission_block@0"
            ]
        },
        {
            "x": 0,
            "y": 3,
            "z": 2,
            "elements": [
                "generalized_output_item"
            ]
        },
        {
            "x": 1,
            "y": 3,
            "z": 1,
            "elements": [
                "nuclearcraft:fission_block@0"
            ]
        },
        {
            "x": 0,
            "y": 1,
            "z": 0,
            "elements": [
                "contenttweaker:awakened_electromagnet@0"
            ]
        },
        {
            "x": -1,
            "y": 1,
            "z": 1,
            "elements": [
                "contenttweaker:awakened_electromagnet@0"
            ]
        },
        {
            "x": 1,
            "y": 3,
            "z": 2,
            "elements": [
                "nuclearcraft:fission_block@0"
            ]
        },
        {
            "x": 1,
            "y": 1,
            "z": 0,
            "elements": [
                "contenttweaker:awakened_electromagnet@0"
            ]
        },
        {
            "x": -1,
            "y": 1,
            "z": 2,
            "elements": [
                "contenttweaker:awakened_electromagnet@0"
            ]
        },
        {
            "x": 0,
            "y": 1,
            "z": 2,
            "elements": [
                "contenttweaker:awakened_electromagnet@0"
            ]
        },
        {
            "x": 1,
            "y": 1,
            "z": 1,
            "elements": [
                "contenttweaker:awakened_electromagnet@0"
            ]
        },
        {
            "x": 1,
            "y": 1,
            "z": 2,
            "elements": [
                "contenttweaker:awakened_electromagnet@0"
            ]
        },
        {
            "x": -1,
            "y": 2,
            "z": 0,
            "elements": [
                "contenttweaker:awakened_electromagnet@0"
            ]
        },
        {
            "x": -1,
            "y": 2,
            "z": 1,
            "elements": [
                "contenttweaker:awakened_electromagnet@0"
            ]
        },
        {
            "x": 0,
            "y": 2,
            "z": 0,
            "elements": [
                "contenttweaker:awakened_electromagnet@0"
            ]
        },
        {
            "x": -1,
            "y": 2,
            "z": 2,
            "elements": [
                "contenttweaker:awakened_electromagnet@0"
            ]
        },
        {
            "x": 1,
            "y": 2,
            "z": 0,
            "elements": [
                "contenttweaker:awakened_electromagnet@0"
            ]
        }
    ]}