{
    "registryname": "orb_of_infinite_wishes",
    "localizedname": "Orb of Infinite Wishes",
	"color": "474647",
    "parts": [
        {
            "x": 5,
            "y": 0,
            "z": 9,
            "elements": [
                "chisel:energizedvoidstone@1"
            ]
        },
        {
            "x": 8,
            "y": 4,
            "z": -6,
            "elements": [
                "chisel:arcane_stone1@12"
            ]
        },
        {
            "x": 5,
            "y": 0,
            "z": 3,
            "elements": [
                "chisel:energizedvoidstone@1"
            ]
        },
        {
            "x": 5,
            "y": 0,
            "z": 0,
            "elements": [
                "chisel:arcane_stone1@12"
            ]
        },
        {
            "x": 5,
            "y": 0,
            "z": -1,
            "elements": [
                "chisel:arcane_stone1@12"
            ]
        },
        {
            "x": 5,
            "y": 0,
            "z": -4,
            "elements": [
                "chisel:energizedvoidstone@1"
            ]
        },
        {
            "x": 3,
            "y": -2,
            "z": 1,
            "elements": [
                "chisel:arcane_stone1@12"
            ]
        },
        {
            "x": 11,
            "y": 8,
            "z": 3,
            "elements": [
                "astralsorcery:blockcelestialcollectorcrystal"
            ]
        },
        {
            "x": 3,
            "y": -2,
            "z": 0,
            "elements": [
                "chisel:energizedvoidstone@1"
            ]
        },
        {
            "x": 3,
            "y": -2,
            "z": -1,
            "elements": [
                "chisel:arcane_stone1@12"
            ]
        },
        {
            "x": 3,
            "y": -2,
            "z": -2,
            "elements": [
                "chisel:energizedvoidstone@1"
            ]
        },
        {
            "x": 3,
            "y": -2,
            "z": 5,
            "elements": [
                "chisel:energizedvoidstone@1"
            ]
        },
        {
            "x": 3,
            "y": -2,
            "z": 4,
            "elements": [
                "chisel:arcane_stone1@12"
            ]
        },
        {
            "x": 3,
            "y": -2,
            "z": 3,
            "elements": [
                "chisel:arcane_stone1@12"
            ]
        },
        {
            "x": 3,
            "y": -2,
            "z": 2,
            "elements": [
                "chisel:arcane_stone1@12"
            ]
        },
        {
            "x": 3,
            "y": -2,
            "z": 9,
            "elements": [
                "chisel:arcane_stone1@12"
            ]
        },
        {
            "x": 3,
            "y": -2,
            "z": 8,
            "elements": [
                "chisel:arcane_stone1@12"
            ]
        },
        {
            "x": 3,
            "y": -2,
            "z": 7,
            "elements": [
                "chisel:energizedvoidstone@1"
            ]
        },
        {
            "x": 3,
            "y": -2,
            "z": 6,
            "elements": [
                "chisel:energizedvoidstone@1"
            ]
        },
        {
            "x": 3,
            "y": -2,
            "z": 10,
            "elements": [
                "chisel:arcane_stone1@10"
            ]
        },
        {
            "x": 9,
            "y": 5,
            "z": -6,
            "elements": [
                "chisel:arcane_stone1@12"
            ]
        },
        {
            "x": 7,
            "y": 3,
            "z": -5,
            "elements": [
                "chisel:arcane_stone1@12"
            ]
        },
        {
            "x": 3,
            "y": -2,
            "z": -3,
            "elements": [
                "chisel:arcane_stone1@12"
            ]
        },
        {
            "x": 3,
            "y": -2,
            "z": -4,
            "elements": [
                "chisel:arcane_stone1@10"
            ]
        },
        {
            "x": 5,
            "y": 0,
            "z": 10,
            "elements": [
                "chisel:energizedvoidstone@1"
            ]
        },
        {
            "x": 5,
            "y": 0,
            "z": 11,
            "elements": [
                "chisel:arcane_stone1@12"
            ]
        },
        {
            "x": 4,
            "y": -2,
            "z": 1,
            "elements": [
                "chisel:energizedvoidstone@1"
            ]
        },
        {
            "x": 9,
            "y": 6,
            "z": -6,
            "elements": [
                "chisel:arcane_stone1@12"
            ]
        },
        {
            "x": 4,
            "y": -2,
            "z": 2,
            "elements": [
                "chisel:energizedvoidstone@1"
            ]
        },
        {
            "x": 4,
            "y": -2,
            "z": 3,
            "elements": [
                "modularmachinery:blockenergyinputhatch@7"
            ]
        },
        {
            "x": 4,
            "y": -2,
            "z": 4,
            "elements": [
                "chisel:arcane_stone1@10"
            ]
        },
        {
            "x": 4,
            "y": -2,
            "z": -3,
            "elements": [
                "chisel:energizedvoidstone@1"
            ]
        },
        {
            "x": 4,
            "y": -2,
            "z": -2,
            "elements": [
                "chisel:energizedvoidstone@1"
            ]
        },
        {
            "x": 4,
            "y": -2,
            "z": -1,
            "elements": [
                "chisel:energizedvoidstone@1"
            ]
        },
        {
            "x": 4,
            "y": -2,
            "z": 0,
            "elements": [
                "chisel:arcane_stone1@12"
            ]
        },
        {
            "x": 4,
            "y": -2,
            "z": -5,
            "elements": [
                "chisel:arcane_stone1@10"
            ]
        },
        {
            "x": 4,
            "y": -2,
            "z": -4,
            "elements": [
                "chisel:arcane_stone1@12"
            ]
        },
        {
            "x": 7,
            "y": 2,
            "z": 1,
            "elements": [
                "chisel:arcane_stone1@12"
            ]
        },
        {
            "x": 5,
            "y": -1,
            "z": 3,
            "elements": [
                "chisel:arcane_stone1@12"
            ]
        },
        {
            "x": 5,
            "y": -1,
            "z": 9,
            "elements": [
                "chisel:arcane_stone1@12"
            ]
        },
        {
            "x": 7,
            "y": 2,
            "z": 3,
            "elements": [
                "chisel:arcane_stone1@12"
            ]
        },
        {
            "x": 5,
            "y": -1,
            "z": 10,
            "elements": [
                "chisel:arcane_stone1@12"
            ]
        },
        {
            "x": 4,
            "y": -2,
            "z": 9,
            "elements": [
                "modularmachinery:blockinputbus@0"
            ]
        },
        {
            "x": 4,
            "y": -2,
            "z": 10,
            "elements": [
                "chisel:arcane_stone1@12"
            ]
        },
        {
            "x": 5,
            "y": -1,
            "z": 11,
            "elements": [
                "chisel:arcane_stone1@12"
            ]
        },
        {
            "x": 4,
            "y": -2,
            "z": 11,
            "elements": [
                "chisel:arcane_stone1@10"
            ]
        },
        {
            "x": 7,
            "y": 2,
            "z": -5,
            "elements": [
                "chisel:arcane_stone1@12"
            ]
        },
        {
            "x": 4,
            "y": -2,
            "z": 5,
            "elements": [
                "chisel:arcane_stone1@12"
            ]
        },
        {
            "x": 4,
            "y": 0,
            "z": -4,
            "elements": [
                "chisel:energizedvoidstone@1"
            ]
        },
        {
            "x": 4,
            "y": -2,
            "z": 6,
            "elements": [
                "chisel:arcane_stone1@12"
            ]
        },
        {
            "x": 4,
            "y": -2,
            "z": 7,
            "elements": [
                "chisel:arcane_stone1@12"
            ]
        },
        {
            "x": 7,
            "y": 2,
            "z": -3,
            "elements": [
                "chisel:arcane_stone1@12"
            ]
        },
        {
            "x": 7,
            "y": 2,
            "z": -4,
            "elements": [
                "chisel:arcane_stone1@12"
            ]
        },
        {
            "x": 4,
            "y": -2,
            "z": 8,
            "elements": [
                "chisel:arcane_stone1@12"
            ]
        },
        {
            "x": 6,
            "y": 1,
            "z": -5,
            "elements": [
                "chisel:energizedvoidstone@1"
            ]
        },
        {
            "x": 6,
            "y": 1,
            "z": -2,
            "elements": [
                "chisel:arcane_stone1@12"
            ]
        },
        {
            "x": 5,
            "y": -1,
            "z": -3,
            "elements": [
                "chisel:energizedvoidstone@1"
            ]
        },
        {
            "x": 6,
            "y": 1,
            "z": 3,
            "elements": [
                "chisel:arcane_stone1@12"
            ]
        },
        {
            "x": 5,
            "y": -1,
            "z": -2,
            "elements": [
                "chisel:energizedvoidstone@1"
            ]
        },
        {
            "x": 6,
            "y": 1,
            "z": 1,
            "elements": [
                "chisel:arcane_stone1@12"
            ]
        },
        {
            "x": 5,
            "y": -1,
            "z": -4,
            "elements": [
                "chisel:arcane_stone1@12"
            ]
        },
        {
            "x": 5,
            "y": -1,
            "z": 1,
            "elements": [
                "chisel:energizedvoidstone@1"
            ]
        },
        {
            "x": 5,
            "y": -1,
            "z": 2,
            "elements": [
                "chisel:energizedvoidstone@1"
            ]
        },
        {
            "x": 5,
            "y": -1,
            "z": -1,
            "elements": [
                "chisel:arcane_stone1@12"
            ]
        },
        {
            "x": 5,
            "y": -1,
            "z": 0,
            "elements": [
                "chisel:arcane_stone1@12"
            ]
        },
        {
            "x": 8,
            "y": 4,
            "z": -5,
            "elements": [
                "chisel:arcane_stone1@12"
            ]
        },
        {
            "x": 11,
            "y": 6,
            "z": 3,
            "elements": [
                "chisel:arcane_stone1@12"
            ]
        },
        {
            "x": 7,
            "y": 1,
            "z": -4,
            "elements": [
                "chisel:energizedvoidstone@1"
            ]
        },
        {
            "x": 7,
            "y": 1,
            "z": -5,
            "elements": [
                "chisel:energizedvoidstone@1"
            ]
        },
        {
            "x": 7,
            "y": 1,
            "z": -3,
            "elements": [
                "chisel:energizedvoidstone@1"
            ]
        },
        {
            "x": 3,
            "y": -1,
            "z": 9,
            "elements": [
                "chisel:arcane_stone1@12"
            ]
        },
        {
            "x": 3,
            "y": -1,
            "z": 7,
            "elements": [
                "chisel:energizedvoidstone@1"
            ]
        },
        {
            "x": 3,
            "y": -1,
            "z": 8,
            "elements": [
                "chisel:arcane_stone1@12"
            ]
        },
        {
            "x": 3,
            "y": -1,
            "z": 5,
            "elements": [
                "chisel:energizedvoidstone@1"
            ]
        },
        {
            "x": 3,
            "y": -1,
            "z": 6,
            "elements": [
                "chisel:energizedvoidstone@1"
            ]
        },
        {
            "x": 3,
            "y": -1,
            "z": 3,
            "elements": [
                "chisel:arcane_stone1@12"
            ]
        },
        {
            "x": 3,
            "y": -1,
            "z": 4,
            "elements": [
                "chisel:arcane_stone1@12"
            ]
        },
        {
            "x": 3,
            "y": -1,
            "z": 1,
            "elements": [
                "chisel:arcane_stone1@12"
            ]
        },
        {
            "x": 3,
            "y": -1,
            "z": 2,
            "elements": [
                "chisel:arcane_stone1@12"
            ]
        },
        {
            "x": 3,
            "y": -1,
            "z": -1,
            "elements": [
                "chisel:arcane_stone1@12"
            ]
        },
        {
            "x": 3,
            "y": -1,
            "z": 0,
            "elements": [
                "chisel:energizedvoidstone@1"
            ]
        },
        {
            "x": 3,
            "y": -1,
            "z": -3,
            "elements": [
                "chisel:arcane_stone1@12"
            ]
        },
        {
            "x": 3,
            "y": -1,
            "z": -2,
            "elements": [
                "chisel:energizedvoidstone@1"
            ]
        },
        {
            "x": 4,
            "y": 0,
            "z": 7,
            "elements": [
                "chisel:energizedvoidstone@1"
            ]
        },
        {
            "x": 4,
            "y": 0,
            "z": 8,
            "elements": [
                "chisel:energizedvoidstone@1"
            ]
        },
        {
            "x": 4,
            "y": 1,
            "z": -4,
            "elements": [
                "chisel:arcane_stone1@12"
            ]
        },
        {
            "x": 4,
            "y": 0,
            "z": 10,
            "elements": [
                "chisel:energizedvoidstone@1"
            ]
        },
        {
            "x": 4,
            "y": 0,
            "z": 3,
            "elements": [
                "chisel:arcane_stone1@12"
            ]
        },
        {
            "x": 4,
            "y": 0,
            "z": 5,
            "elements": [
                "chisel:arcane_stone1@12"
            ]
        },
        {
            "x": 4,
            "y": 0,
            "z": 6,
            "elements": [
                "chisel:energizedvoidstone@1"
            ]
        },
        {
            "x": 4,
            "y": 1,
            "z": 3,
            "elements": [
                "chisel:arcane_stone1@12"
            ]
        },
        {
            "x": 4,
            "y": 1,
            "z": 5,
            "elements": [
                "chisel:arcane_stone1@12"
            ]
        },
        {
            "x": 4,
            "y": 1,
            "z": 6,
            "elements": [
                "chisel:arcane_stone1@12"
            ]
        },
        {
            "x": 4,
            "y": 1,
            "z": 7,
            "elements": [
                "chisel:arcane_stone1@12"
            ]
        },
        {
            "x": 4,
            "y": 1,
            "z": 8,
            "elements": [
                "chisel:energizedvoidstone@1"
            ]
        },
        {
            "x": -11,
            "y": 8,
            "z": 3,
            "elements": [
                "astralsorcery:blockcelestialcollectorcrystal"
            ]
        },
        {
            "x": -11,
            "y": 5,
            "z": 3,
            "elements": [
                "chisel:arcane_stone1@12"
            ]
        },
        {
            "x": 8,
            "y": 3,
            "z": -6,
            "elements": [
                "chisel:arcane_stone1@12"
            ]
        },
        {
            "x": 8,
            "y": 3,
            "z": -5,
            "elements": [
                "chisel:arcane_stone1@12"
            ]
        },
        {
            "x": 2,
            "y": -1,
            "z": -3,
            "elements": [
                "chisel:arcane_stone1@12"
            ]
        },
        {
            "x": 2,
            "y": -1,
            "z": 3,
            "elements": [
                "chisel:arcane_stone1@12"
            ]
        },
        {
            "x": 2,
            "y": -1,
            "z": 2,
            "elements": [
                "chisel:arcane_stone1@12"
            ]
        },
        {
            "x": 2,
            "y": -1,
            "z": 5,
            "elements": [
                "chisel:energizedvoidstone@1"
            ]
        },
        {
            "x": 6,
            "y": -1,
            "z": 3,
            "elements": [
                "chisel:arcane_stone1@12"
            ]
        },
        {
            "x": 6,
            "y": -1,
            "z": 2,
            "elements": [
                "chisel:energizedvoidstone@1"
            ]
        },
        {
            "x": 2,
            "y": -1,
            "z": 4,
            "elements": [
                "chisel:energizedvoidstone@1"
            ]
        },
        {
            "x": 2,
            "y": -1,
            "z": -1,
            "elements": [
                "chisel:arcane_stone1@12"
            ]
        },
        {
            "x": 2,
            "y": -1,
            "z": -2,
            "elements": [
                "chisel:arcane_stone1@12"
            ]
        },
        {
            "x": 2,
            "y": -1,
            "z": 1,
            "elements": [
                "chisel:energizedvoidstone@1"
            ]
        },
        {
            "x": 2,
            "y": -1,
            "z": 0,
            "elements": [
                "chisel:arcane_stone1@12"
            ]
        },
        {
            "x": 6,
            "y": -1,
            "z": -3,
            "elements": [
                "chisel:energizedvoidstone@1"
            ]
        },
        {
            "x": 6,
            "y": -1,
            "z": -4,
            "elements": [
                "chisel:energizedvoidstone@1"
            ]
        },
        {
            "x": 6,
            "y": -1,
            "z": -5,
            "elements": [
                "chisel:arcane_stone1@12"
            ]
        },
        {
            "x": 6,
            "y": -1,
            "z": 1,
            "elements": [
                "chisel:arcane_stone1@12"
            ]
        },
        {
            "x": 2,
            "y": -1,
            "z": 7,
            "elements": [
                "chisel:arcane_stone1@12"
            ]
        },
        {
            "x": 2,
            "y": -1,
            "z": 6,
            "elements": [
                "chisel:energizedvoidstone@1"
            ]
        },
        {
            "x": 6,
            "y": -1,
            "z": -2,
            "elements": [
                "chisel:arcane_stone1@12"
            ]
        },
        {
            "x": 6,
            "y": 2,
            "z": -5,
            "elements": [
                "chisel:arcane_stone1@12"
            ]
        },
        {
            "x": -9,
            "y": 6,
            "z": -6,
            "elements": [
                "chisel:arcane_stone1@12"
            ]
        },
        {
            "x": 7,
            "y": 1,
            "z": 3,
            "elements": [
                "chisel:arcane_stone1@12"
            ]
        },
        {
            "x": 7,
            "y": 1,
            "z": 1,
            "elements": [
                "chisel:arcane_stone1@12"
            ]
        },
        {
            "x": 10,
            "y": 3,
            "z": 3,
            "elements": [
                "chisel:arcane_stone1@12"
            ]
        },
        {
            "x": 4,
            "y": 2,
            "z": 10,
            "elements": [
                "chisel:energizedvoidstone@1"
            ]
        },
        {
            "x": 4,
            "y": 2,
            "z": 7,
            "elements": [
                "chisel:arcane_stone1@12"
            ]
        },
        {
            "x": 4,
            "y": 2,
            "z": 8,
            "elements": [
                "chisel:arcane_stone1@12"
            ]
        },
        {
            "x": 3,
            "y": 1,
            "z": -3,
            "elements": [
                "chisel:arcane_stone1@12"
            ]
        },
        {
            "x": 5,
            "y": 3,
            "z": 0,
            "elements": [
                "astralsorcery:blockcelestialcollectorcrystal"
            ]
        },
        {
            "x": 5,
            "y": 3,
            "z": 10,
            "elements": [
                "chisel:arcane_stone1@12"
            ]
        },
        {
            "x": 5,
            "y": 3,
            "z": 9,
            "elements": [
                "chisel:arcane_stone1@12"
            ]
        },
        {
            "x": 5,
            "y": 3,
            "z": 11,
            "elements": [
                "chisel:arcane_stone1@12"
            ]
        },
        {
            "x": 3,
            "y": 1,
            "z": 9,
            "elements": [
                "chisel:energizedvoidstone@1"
            ]
        },
        {
            "x": 9,
            "y": 2,
            "z": 2,
            "elements": [
                "chisel:arcane_stone1@12"
            ]
        },
        {
            "x": 3,
            "y": 1,
            "z": 8,
            "elements": [
                "chisel:energizedvoidstone@1"
            ]
        },
        {
            "x": 9,
            "y": 2,
            "z": 3,
            "elements": [
                "chisel:arcane_stone1@12"
            ]
        },
        {
            "x": 11,
            "y": 4,
            "z": 3,
            "elements": [
                "chisel:arcane_stone1@12"
            ]
        },
        {
            "x": -2,
            "y": 14,
            "z": 0,
            "elements": [
                "thaumicaugmentation:fortified_glass@0"
            ]
        },
        {
            "x": -2,
            "y": 14,
            "z": 1,
            "elements": [
                "thaumicaugmentation:fortified_glass@0"
            ]
        },
        {
            "x": -2,
            "y": 14,
            "z": 2,
            "elements": [
                "thaumicaugmentation:fortified_glass@0"
            ]
        },
        {
            "x": 3,
            "y": 1,
            "z": 4,
            "elements": [
                "chisel:arcane_stone1@12"
            ]
        },
        {
            "x": 9,
            "y": 2,
            "z": -6,
            "elements": [
                "chisel:arcane_stone1@12"
            ]
        },
        {
            "x": 4,
            "y": 3,
            "z": 3,
            "elements": [
                "astralsorcery:blockcelestialcollectorcrystal"
            ]
        },
        {
            "x": -1,
            "y": 15,
            "z": 1,
            "elements": [
                "thaumicaugmentation:fortified_glass@0"
            ]
        },
        {
            "x": 4,
            "y": 1,
            "z": 10,
            "elements": [
                "chisel:energizedvoidstone@1"
            ]
        },
        {
            "x": 4,
            "y": 3,
            "z": 10,
            "elements": [
                "chisel:arcane_stone1@12"
            ]
        },
        {
            "x": 10,
            "y": 4,
            "z": 3,
            "elements": [
                "chisel:arcane_stone1@12"
            ]
        },
        {
            "x": -9,
            "y": 5,
            "z": -6,
            "elements": [
                "chisel:arcane_stone1@12"
            ]
        },
        {
            "x": 10,
            "y": 2,
            "z": 3,
            "elements": [
                "chisel:energizedvoidstone@1"
            ]
        },
        {
            "x": 9,
            "y": 8,
            "z": -6,
            "elements": [
                "astralsorcery:blockcelestialcollectorcrystal"
            ]
        },
        {
            "x": 2,
            "y": -2,
            "z": 0,
            "elements": [
                "chisel:arcane_stone1@12"
            ]
        },
        {
            "x": 2,
            "y": -2,
            "z": -1,
            "elements": [
                "chisel:arcane_stone1@12"
            ]
        },
        {
            "x": 2,
            "y": -2,
            "z": 2,
            "elements": [
                "chisel:arcane_stone1@12"
            ]
        },
        {
            "x": 2,
            "y": -2,
            "z": 1,
            "elements": [
                "chisel:energizedvoidstone@1"
            ]
        },
        {
            "x": 2,
            "y": -2,
            "z": 4,
            "elements": [
                "chisel:energizedvoidstone@1"
            ]
        },
        {
            "x": 2,
            "y": -2,
            "z": 3,
            "elements": [
                "chisel:arcane_stone1@12"
            ]
        },
        {
            "x": 0,
            "y": -1,
            "z": -9,
            "elements": [
                "chisel:arcane_stone1@12"
            ]
        },
        {
            "x": 2,
            "y": -2,
            "z": 6,
            "elements": [
                "chisel:energizedvoidstone@1"
            ]
        },
        {
            "x": 5,
            "y": 5,
            "z": 11,
            "elements": [
                "chisel:arcane_stone1@12"
            ]
        },
        {
            "x": 0,
            "y": -1,
            "z": -10,
            "elements": [
                "chisel:arcane_stone1@12"
            ]
        },
        {
            "x": 2,
            "y": -2,
            "z": 5,
            "elements": [
                "chisel:energizedvoidstone@1"
            ]
        },
        {
            "x": -2,
            "y": 13,
            "z": 0,
            "elements": [
                "contenttweaker:fractallite_taint"
            ]
        },
        {
            "x": 0,
            "y": -1,
            "z": -7,
            "elements": [
                "chisel:energizedvoidstone@1"
            ]
        },
        {
            "x": 0,
            "y": -1,
            "z": -8,
            "elements": [
                "chisel:arcane_stone1@12"
            ]
        },
        {
            "x": -2,
            "y": 13,
            "z": 1,
            "elements": [
                "contenttweaker:fractallite_taint"
            ]
        },
        {
            "x": 0,
            "y": -1,
            "z": -5,
            "elements": [
                "chisel:energizedvoidstone@1"
            ]
        },
        {
            "x": -2,
            "y": 13,
            "z": 2,
            "elements": [
                "contenttweaker:fractallite_taint"
            ]
        },
        {
            "x": 2,
            "y": -2,
            "z": -6,
            "elements": [
                "chisel:arcane_stone1@10"
            ]
        },
        {
            "x": 0,
            "y": -1,
            "z": -6,
            "elements": [
                "chisel:energizedvoidstone@1"
            ]
        },
        {
            "x": 2,
            "y": -2,
            "z": -7,
            "elements": [
                "chisel:arcane_stone1@10"
            ]
        },
        {
            "x": -2,
            "y": 13,
            "z": 3,
            "elements": [
                "thaumicaugmentation:fortified_glass@0"
            ]
        },
        {
            "x": 2,
            "y": -2,
            "z": -4,
            "elements": [
                "chisel:arcane_stone1@10"
            ]
        },
        {
            "x": 0,
            "y": -1,
            "z": -3,
            "elements": [
                "chisel:energizedvoidstone@1"
            ]
        },
        {
            "x": 2,
            "y": -2,
            "z": -5,
            "elements": [
                "chisel:arcane_stone1@10"
            ]
        },
        {
            "x": 0,
            "y": -1,
            "z": -4,
            "elements": [
                "chisel:energizedvoidstone@1"
            ]
        },
        {
            "x": 2,
            "y": -2,
            "z": -2,
            "elements": [
                "chisel:arcane_stone1@12"
            ]
        },
        {
            "x": -2,
            "y": 13,
            "z": -2,
            "elements": [
                "thaumicaugmentation:fortified_glass@0"
            ]
        },
        {
            "x": 0,
            "y": -1,
            "z": -1,
            "elements": [
                "chisel:energizedvoidstone@1"
            ]
        },
        {
            "x": 2,
            "y": -2,
            "z": -3,
            "elements": [
                "modularmachinery:blockwillproviderinput@0"
            ]
        },
        {
            "x": 0,
            "y": -1,
            "z": -2,
            "elements": [
                "chisel:arcane_stone1@12"
            ]
        },
        {
            "x": -2,
            "y": 13,
            "z": -1,
            "elements": [
                "thaumicaugmentation:fortified_glass@0"
            ]
        },
        {
            "x": -2,
            "y": 13,
            "z": 4,
            "elements": [
                "thaumicaugmentation:fortified_glass@0"
            ]
        },
        {
            "x": -3,
            "y": 12,
            "z": 4,
            "elements": [
                "thaumicaugmentation:fortified_glass@0"
            ]
        },
        {
            "x": -3,
            "y": 12,
            "z": 2,
            "elements": [
                "contenttweaker:fractallite_taint"
            ]
        },
        {
            "x": -3,
            "y": 12,
            "z": 3,
            "elements": [
                "thaumicaugmentation:fortified_glass@0"
            ]
        },
        {
            "x": -3,
            "y": 12,
            "z": 0,
            "elements": [
                "contenttweaker:fractallite_taint"
            ]
        },
        {
            "x": -3,
            "y": 12,
            "z": 1,
            "elements": [
                "contenttweaker:fractallite_taint"
            ]
        },
        {
            "x": 6,
            "y": 0,
            "z": 3,
            "elements": [
                "chisel:energizedvoidstone@1"
            ]
        },
        {
            "x": -3,
            "y": 12,
            "z": -2,
            "elements": [
                "thaumicaugmentation:fortified_glass@0"
            ]
        },
        {
            "x": 6,
            "y": 0,
            "z": 1,
            "elements": [
                "chisel:arcane_stone1@12"
            ]
        },
        {
            "x": -3,
            "y": 12,
            "z": -1,
            "elements": [
                "thaumicaugmentation:fortified_glass@0"
            ]
        },
        {
            "x": 0,
            "y": -1,
            "z": 1,
            "elements": [
                "chisel:energizedvoidstone@1"
            ]
        },
        {
            "x": -3,
            "y": 11,
            "z": 1,
            "elements": [
                "contenttweaker:fractallite_taint"
            ]
        },
        {
            "x": 0,
            "y": -1,
            "z": 0,
            "elements": [
                "chisel:energizedvoidstone@1"
            ]
        },
        {
            "x": -3,
            "y": 11,
            "z": 2,
            "elements": [
                "contenttweaker:fractallite_taint"
            ]
        },
        {
            "x": 0,
            "y": -1,
            "z": 3,
            "elements": [
                "chisel:arcane_stone1@12"
            ]
        },
        {
            "x": -3,
            "y": 11,
            "z": -1,
            "elements": [
                "contenttweaker:fractallite_taint"
            ]
        },
        {
            "x": 0,
            "y": -1,
            "z": 2,
            "elements": [
                "chisel:energizedvoidstone@1"
            ]
        },
        {
            "x": -9,
            "y": 4,
            "z": -6,
            "elements": [
                "chisel:arcane_stone1@12"
            ]
        },
        {
            "x": -3,
            "y": 11,
            "z": 0,
            "elements": [
                "contenttweaker:fractallite_taint"
            ]
        },
        {
            "x": 0,
            "y": -1,
            "z": 5,
            "elements": [
                "chisel:arcane_stone1@12"
            ]
        },
        {
            "x": 8,
            "y": -1,
            "z": 3,
            "elements": [
                "chisel:arcane_stone1@12"
            ]
        },
        {
            "x": 8,
            "y": -1,
            "z": 2,
            "elements": [
                "chisel:arcane_stone1@12"
            ]
        },
        {
            "x": 0,
            "y": -1,
            "z": 4,
            "elements": [
                "chisel:energizedvoidstone@1"
            ]
        },
        {
            "x": -3,
            "y": 11,
            "z": 3,
            "elements": [
                "contenttweaker:fractallite_taint"
            ]
        },
        {
            "x": -3,
            "y": 11,
            "z": 4,
            "elements": [
                "thaumicaugmentation:fortified_glass@0"
            ]
        },
        {
            "x": 2,
            "y": -2,
            "z": 8,
            "elements": [
                "chisel:arcane_stone1@10"
            ]
        },
        {
            "x": 2,
            "y": -2,
            "z": 7,
            "elements": [
                "chisel:arcane_stone1@12"
            ]
        },
        {
            "x": 6,
            "y": 0,
            "z": -2,
            "elements": [
                "chisel:energizedvoidstone@1"
            ]
        },
        {
            "x": 2,
            "y": -2,
            "z": 9,
            "elements": [
                "chisel:arcane_stone1@10"
            ]
        },
        {
            "x": 8,
            "y": -1,
            "z": -5,
            "elements": [
                "chisel:arcane_stone1@12"
            ]
        },
        {
            "x": 6,
            "y": 0,
            "z": -5,
            "elements": [
                "chisel:energizedvoidstone@1"
            ]
        },
        {
            "x": 8,
            "y": -1,
            "z": -6,
            "elements": [
                "chisel:arcane_stone1@12"
            ]
        },
        {
            "x": -10,
            "y": 2,
            "z": 3,
            "elements": [
                "chisel:energizedvoidstone@1"
            ]
        },
        {
            "x": 3,
            "y": 0,
            "z": 4,
            "elements": [
                "chisel:arcane_stone1@12"
            ]
        },
        {
            "x": 9,
            "y": 1,
            "z": 2,
            "elements": [
                "chisel:energizedvoidstone@1"
            ]
        },
        {
            "x": 9,
            "y": 1,
            "z": 3,
            "elements": [
                "chisel:arcane_stone1@12"
            ]
        },
        {
            "x": 3,
            "y": 0,
            "z": 8,
            "elements": [
                "chisel:energizedvoidstone@1"
            ]
        },
        {
            "x": 3,
            "y": 0,
            "z": 9,
            "elements": [
                "chisel:energizedvoidstone@1"
            ]
        },
        {
            "x": 5,
            "y": 4,
            "z": 11,
            "elements": [
                "chisel:arcane_stone1@12"
            ]
        },
        {
            "x": 5,
            "y": 4,
            "z": 10,
            "elements": [
                "chisel:arcane_stone1@12"
            ]
        },
        {
            "x": 3,
            "y": 0,
            "z": -3,
            "elements": [
                "chisel:arcane_stone1@12"
            ]
        },
        {
            "x": -11,
            "y": 6,
            "z": 3,
            "elements": [
                "chisel:arcane_stone1@12"
            ]
        },
        {
            "x": 5,
            "y": -2,
            "z": -5,
            "elements": [
                "chisel:arcane_stone1@10"
            ]
        },
        {
            "x": 9,
            "y": 1,
            "z": -6,
            "elements": [
                "chisel:arcane_stone1@12"
            ]
        },
        {
            "x": 11,
            "y": 5,
            "z": 3,
            "elements": [
                "chisel:arcane_stone1@12"
            ]
        },
        {
            "x": 5,
            "y": -2,
            "z": 2,
            "elements": [
                "chisel:energizedvoidstone@1"
            ]
        },
        {
            "x": 5,
            "y": -2,
            "z": 3,
            "elements": [
                "chisel:arcane_stone1@12"
            ]
        },
        {
            "x": 5,
            "y": -2,
            "z": 0,
            "elements": [
                "modularmachinery:blockwillproviderinput@0"
            ]
        },
        {
            "x": 5,
            "y": -2,
            "z": 1,
            "elements": [
                "chisel:energizedvoidstone@1"
            ]
        },
        {
            "x": 5,
            "y": -2,
            "z": -2,
            "elements": [
                "chisel:energizedvoidstone@1"
            ]
        },
        {
            "x": 5,
            "y": -2,
            "z": -1,
            "elements": [
                "chisel:arcane_stone1@12"
            ]
        },
        {
            "x": 5,
            "y": -2,
            "z": -4,
            "elements": [
                "chisel:arcane_stone1@12"
            ]
        },
        {
            "x": 5,
            "y": -2,
            "z": -3,
            "elements": [
                "chisel:energizedvoidstone@1"
            ]
        },
        {
            "x": 5,
            "y": -2,
            "z": 10,
            "elements": [
                "chisel:arcane_stone1@12"
            ]
        },
        {
            "x": 5,
            "y": -2,
            "z": 11,
            "elements": [
                "modularmachinery:blockfluidinputhatch@7"
            ]
        },
        {
            "x": 5,
            "y": -2,
            "z": 8,
            "elements": [
                "chisel:arcane_stone1@10"
            ]
        },
        {
            "x": 5,
            "y": -2,
            "z": 9,
            "elements": [
                "chisel:arcane_stone1@12"
            ]
        },
        {
            "x": 5,
            "y": -2,
            "z": 6,
            "elements": [
                "chisel:arcane_stone1@10"
            ]
        },
        {
            "x": 5,
            "y": -2,
            "z": 7,
            "elements": [
                "chisel:arcane_stone1@10"
            ]
        },
        {
            "x": 5,
            "y": -2,
            "z": 4,
            "elements": [
                "chisel:arcane_stone1@10"
            ]
        },
        {
            "x": 5,
            "y": -2,
            "z": 5,
            "elements": [
                "chisel:arcane_stone1@10"
            ]
        },
        {
            "x": 5,
            "y": -2,
            "z": 12,
            "elements": [
                "chisel:arcane_stone1@10"
            ]
        },
        {
            "x": -2,
            "y": -2,
            "z": -3,
            "elements": [
                "modularmachinery:blockwillproviderinput@0"
            ]
        },
        {
            "x": -3,
            "y": 10,
            "z": -2,
            "elements": [
                "thaumicaugmentation:fortified_glass@0"
            ]
        },
        {
            "x": -2,
            "y": -2,
            "z": -2,
            "elements": [
                "chisel:arcane_stone1@12"
            ]
        },
        {
            "x": -3,
            "y": 10,
            "z": -1,
            "elements": [
                "contenttweaker:fractallite_taint"
            ]
        },
        {
            "x": -2,
            "y": -2,
            "z": -5,
            "elements": [
                "chisel:arcane_stone1@10"
            ]
        },
        {
            "x": -2,
            "y": -2,
            "z": -4,
            "elements": [
                "chisel:arcane_stone1@10"
            ]
        },
        {
            "x": 1,
            "y": 15,
            "z": 1,
            "elements": [
                "thaumicaugmentation:fortified_glass@0"
            ]
        },
        {
            "x": -2,
            "y": -2,
            "z": 1,
            "elements": [
                "chisel:energizedvoidstone@1"
            ]
        },
        {
            "x": -2,
            "y": -2,
            "z": 2,
            "elements": [
                "chisel:arcane_stone1@12"
            ]
        },
        {
            "x": -2,
            "y": -2,
            "z": -1,
            "elements": [
                "chisel:arcane_stone1@12"
            ]
        },
        {
            "x": -2,
            "y": -2,
            "z": 0,
            "elements": [
                "chisel:arcane_stone1@12"
            ]
        },
        {
            "x": -2,
            "y": -2,
            "z": 5,
            "elements": [
                "chisel:energizedvoidstone@1"
            ]
        },
        {
            "x": -2,
            "y": -2,
            "z": 6,
            "elements": [
                "chisel:energizedvoidstone@1"
            ]
        },
        {
            "x": -2,
            "y": -2,
            "z": 3,
            "elements": [
                "chisel:arcane_stone1@12"
            ]
        },
        {
            "x": -3,
            "y": 10,
            "z": 4,
            "elements": [
                "thaumicaugmentation:fortified_glass@0"
            ]
        },
        {
            "x": -11,
            "y": 0,
            "z": 3,
            "elements": [
                "chisel:arcane_stone1@12"
            ]
        },
        {
            "x": -2,
            "y": -2,
            "z": 4,
            "elements": [
                "chisel:energizedvoidstone@1"
            ]
        },
        {
            "x": -3,
            "y": 10,
            "z": 2,
            "elements": [
                "contenttweaker:fractallite_taint"
            ]
        },
        {
            "x": 11,
            "y": 1,
            "z": 3,
            "elements": [
                "chisel:arcane_stone1@12"
            ]
        },
        {
            "x": -2,
            "y": -2,
            "z": 9,
            "elements": [
                "chisel:arcane_stone1@10"
            ]
        },
        {
            "x": -3,
            "y": 10,
            "z": 3,
            "elements": [
                "contenttweaker:fractallite_taint"
            ]
        },
        {
            "x": -2,
            "y": -2,
            "z": 7,
            "elements": [
                "chisel:arcane_stone1@12"
            ]
        },
        {
            "x": -3,
            "y": 10,
            "z": 0,
            "elements": [
                "contenttweaker:fractallite_taint"
            ]
        },
        {
            "x": -2,
            "y": -2,
            "z": 8,
            "elements": [
                "chisel:arcane_stone1@10"
            ]
        },
        {
            "x": -3,
            "y": 10,
            "z": 1,
            "elements": [
                "contenttweaker:fractallite_taint"
            ]
        },
        {
            "x": -1,
            "y": -1,
            "z": 1,
            "elements": [
                "chisel:energizedvoidstone@1"
            ]
        },
        {
            "x": 1,
            "y": 2,
            "z": -6,
            "elements": [
                "chisel:arcane_stone1@12"
            ]
        },
        {
            "x": -1,
            "y": -1,
            "z": 2,
            "elements": [
                "chisel:energizedvoidstone@1"
            ]
        },
        {
            "x": 1,
            "y": 2,
            "z": -7,
            "elements": [
                "chisel:arcane_stone1@12"
            ]
        },
        {
            "x": -1,
            "y": -1,
            "z": 3,
            "elements": [
                "chisel:arcane_stone1@12"
            ]
        },
        {
            "x": -1,
            "y": -1,
            "z": 4,
            "elements": [
                "chisel:arcane_stone1@12"
            ]
        },
        {
            "x": 0,
            "y": 14,
            "z": 0,
            "elements": [
                "contenttweaker:fractallite_taint"
            ]
        },
        {
            "x": -4,
            "y": 9,
            "z": -1,
            "elements": [
                "thaumicaugmentation:fortified_glass@0"
            ]
        },
        {
            "x": -1,
            "y": -1,
            "z": 5,
            "elements": [
                "chisel:energizedvoidstone@1"
            ]
        },
        {
            "x": -1,
            "y": -1,
            "z": 6,
            "elements": [
                "chisel:arcane_stone1@12"
            ]
        },
        {
            "x": 0,
            "y": 14,
            "z": -1,
            "elements": [
                "thaumicaugmentation:fortified_glass@0"
            ]
        },
        {
            "x": -4,
            "y": 9,
            "z": 1,
            "elements": [
                "contenttweaker:fractallite_taint"
            ]
        },
        {
            "x": -4,
            "y": 9,
            "z": 0,
            "elements": [
                "thaumicaugmentation:fortified_glass@0"
            ]
        },
        {
            "x": -4,
            "y": 9,
            "z": 3,
            "elements": [
                "thaumicaugmentation:fortified_glass@0"
            ]
        },
        {
            "x": -1,
            "y": -1,
            "z": -7,
            "elements": [
                "chisel:arcane_stone1@12"
            ]
        },
        {
            "x": -1,
            "y": -1,
            "z": -6,
            "elements": [
                "chisel:arcane_stone1@12"
            ]
        },
        {
            "x": -4,
            "y": 9,
            "z": 2,
            "elements": [
                "thaumicaugmentation:fortified_glass@0"
            ]
        },
        {
            "x": 0,
            "y": 14,
            "z": 3,
            "elements": [
                "thaumicaugmentation:fortified_glass@0"
            ]
        },
        {
            "x": -1,
            "y": -1,
            "z": -5,
            "elements": [
                "chisel:arcane_stone1@12"
            ]
        },
        {
            "x": 0,
            "y": 14,
            "z": 2,
            "elements": [
                "contenttweaker:fractallite_taint"
            ]
        },
        {
            "x": 0,
            "y": 14,
            "z": 1,
            "elements": [
                "contenttweaker:fractallite_taint"
            ]
        },
        {
            "x": -1,
            "y": -1,
            "z": -4,
            "elements": [
                "chisel:arcane_stone1@12"
            ]
        },
        {
            "x": -1,
            "y": -1,
            "z": -3,
            "elements": [
                "chisel:energizedvoidstone@1"
            ]
        },
        {
            "x": -2,
            "y": -2,
            "z": -7,
            "elements": [
                "chisel:arcane_stone1@10"
            ]
        },
        {
            "x": -1,
            "y": -1,
            "z": -2,
            "elements": [
                "chisel:arcane_stone1@12"
            ]
        },
        {
            "x": -2,
            "y": -2,
            "z": -6,
            "elements": [
                "chisel:arcane_stone1@10"
            ]
        },
        {
            "x": -1,
            "y": -1,
            "z": -1,
            "elements": [
                "chisel:energizedvoidstone@1"
            ]
        },
        {
            "x": -1,
            "y": -1,
            "z": 0,
            "elements": [
                "chisel:energizedvoidstone@1"
            ]
        },
        {
            "x": 9,
            "y": -2,
            "z": 4,
            "elements": [
                "chisel:arcane_stone1@10"
            ]
        },
        {
            "x": 9,
            "y": -1,
            "z": -6,
            "elements": [
                "chisel:arcane_stone1@12"
            ]
        },
        {
            "x": 0,
            "y": 0,
            "z": 5,
            "elements": [
                "chisel:arcane_stone1@12"
            ]
        },
        {
            "x": 9,
            "y": -2,
            "z": 1,
            "elements": [
                "chisel:arcane_stone1@10"
            ]
        },
        {
            "x": 9,
            "y": -2,
            "z": 3,
            "elements": [
                "chisel:arcane_stone1@12"
            ]
        },
        {
            "x": 0,
            "y": 0,
            "z": 2,
            "elements": [
                "modularmachinery:blocklifeessenceproviderinput@0"
            ]
        },
        {
            "x": 9,
            "y": -2,
            "z": 2,
            "elements": [
                "modularmachinery:blockinputbus@0"
            ]
        },
        {
            "x": 0,
            "y": 0,
            "z": 1,
            "elements": [
                "chisel:energizedvoidstone@1"
            ]
        },
        {
            "x": 9,
            "y": -2,
            "z": -7,
            "elements": [
                "chisel:arcane_stone1@10"
            ]
        },
        {
            "x": 0,
            "y": 0,
            "z": -8,
            "elements": [
                "chisel:energizedvoidstone@1"
            ]
        },
        {
            "x": 0,
            "y": 0,
            "z": -9,
            "elements": [
                "chisel:energizedvoidstone@1"
            ]
        },
        {
            "x": 9,
            "y": -2,
            "z": -5,
            "elements": [
                "chisel:arcane_stone1@10"
            ]
        },
        {
            "x": 9,
            "y": -2,
            "z": -6,
            "elements": [
                "modularmachinery:blockfluidinputhatch@7"
            ]
        },
        {
            "x": -2,
            "y": 11,
            "z": 2,
            "elements": [
                "contenttweaker:fractallite_taint"
            ]
        },
        {
            "x": -2,
            "y": 11,
            "z": 3,
            "elements": [
                "contenttweaker:fractallite_taint"
            ]
        },
        {
            "x": 0,
            "y": 0,
            "z": -10,
            "elements": [
                "chisel:arcane_stone1@12"
            ]
        },
        {
            "x": -2,
            "y": 11,
            "z": 4,
            "elements": [
                "contenttweaker:fractallite_taint"
            ]
        },
        {
            "x": -2,
            "y": 11,
            "z": 5,
            "elements": [
                "thaumicaugmentation:fortified_glass@0"
            ]
        },
        {
            "x": -2,
            "y": 11,
            "z": -2,
            "elements": [
                "contenttweaker:fractallite_taint"
            ]
        },
        {
            "x": 0,
            "y": 13,
            "z": 4,
            "elements": [
                "thaumicaugmentation:fortified_glass@0"
            ]
        },
        {
            "x": -2,
            "y": 11,
            "z": -1,
            "elements": [
                "contenttweaker:fractallite_taint"
            ]
        },
        {
            "x": -2,
            "y": 11,
            "z": 0,
            "elements": [
                "contenttweaker:fractallite_taint"
            ]
        },
        {
            "x": 0,
            "y": 13,
            "z": 3,
            "elements": [
                "contenttweaker:fractallite_taint"
            ]
        },
        {
            "x": 0,
            "y": 13,
            "z": 2,
            "elements": [
                "contenttweaker:fractallite_taint"
            ]
        },
        {
            "x": -2,
            "y": 11,
            "z": 1,
            "elements": [
                "contenttweaker:fractallite_taint"
            ]
        },
        {
            "x": -1,
            "y": 0,
            "z": -5,
            "elements": [
                "chisel:energizedvoidstone@1"
            ]
        },
        {
            "x": -1,
            "y": 0,
            "z": -6,
            "elements": [
                "chisel:energizedvoidstone@1"
            ]
        },
        {
            "x": -1,
            "y": 0,
            "z": -7,
            "elements": [
                "chisel:energizedvoidstone@1"
            ]
        },
        {
            "x": -2,
            "y": 11,
            "z": -3,
            "elements": [
                "thaumicaugmentation:fortified_glass@0"
            ]
        },
        {
            "x": -1,
            "y": 0,
            "z": -4,
            "elements": [
                "chisel:arcane_stone1@12"
            ]
        },
        {
            "x": 8,
            "y": -2,
            "z": 4,
            "elements": [
                "chisel:arcane_stone1@10"
            ]
        },
        {
            "x": 8,
            "y": -2,
            "z": 3,
            "elements": [
                "chisel:arcane_stone1@12"
            ]
        },
        {
            "x": 8,
            "y": -2,
            "z": 2,
            "elements": [
                "chisel:arcane_stone1@12"
            ]
        },
        {
            "x": 8,
            "y": -2,
            "z": 1,
            "elements": [
                "chisel:arcane_stone1@10"
            ]
        },
        {
            "x": -3,
            "y": 9,
            "z": 4,
            "elements": [
                "thaumicaugmentation:fortified_glass@0"
            ]
        },
        {
            "x": 0,
            "y": 13,
            "z": 1,
            "elements": [
                "contenttweaker:fractallite_taint"
            ]
        },
        {
            "x": 0,
            "y": 13,
            "z": 0,
            "elements": [
                "contenttweaker:fractallite_taint"
            ]
        },
        {
            "x": -3,
            "y": 9,
            "z": 3,
            "elements": [
                "contenttweaker:fractallite_taint"
            ]
        },
        {
            "x": -3,
            "y": 9,
            "z": 2,
            "elements": [
                "contenttweaker:fractallite_taint"
            ]
        },
        {
            "x": 0,
            "y": 13,
            "z": -1,
            "elements": [
                "contenttweaker:fractallite_taint"
            ]
        },
        {
            "x": -3,
            "y": 9,
            "z": 1,
            "elements": [
                "contenttweaker:fractallite_taint"
            ]
        },
        {
            "x": 0,
            "y": 13,
            "z": -2,
            "elements": [
                "thaumicaugmentation:fortified_glass@0"
            ]
        },
        {
            "x": -3,
            "y": 11,
            "z": -2,
            "elements": [
                "thaumicaugmentation:fortified_glass@0"
            ]
        },
        {
            "x": 10,
            "y": -1,
            "z": 3,
            "elements": [
                "chisel:arcane_stone1@12"
            ]
        },
        {
            "x": -3,
            "y": 9,
            "z": 0,
            "elements": [
                "contenttweaker:fractallite_taint"
            ]
        },
        {
            "x": -3,
            "y": 9,
            "z": -1,
            "elements": [
                "contenttweaker:fractallite_taint"
            ]
        },
        {
            "x": -3,
            "y": 9,
            "z": -2,
            "elements": [
                "thaumicaugmentation:fortified_glass@0"
            ]
        },
        {
            "x": 11,
            "y": 0,
            "z": 3,
            "elements": [
                "chisel:arcane_stone1@12"
            ]
        },
        {
            "x": 8,
            "y": -2,
            "z": -4,
            "elements": [
                "chisel:arcane_stone1@10"
            ]
        },
        {
            "x": 8,
            "y": -2,
            "z": -5,
            "elements": [
                "chisel:arcane_stone1@12"
            ]
        },
        {
            "x": 8,
            "y": -2,
            "z": -6,
            "elements": [
                "chisel:arcane_stone1@12"
            ]
        },
        {
            "x": 8,
            "y": -2,
            "z": -7,
            "elements": [
                "chisel:arcane_stone1@10"
            ]
        },
        {
            "x": 8,
            "y": -2,
            "z": -3,
            "elements": [
                "chisel:arcane_stone1@10"
            ]
        },
        {
            "x": -1,
            "y": -2,
            "z": -2,
            "elements": [
                "chisel:arcane_stone1@12"
            ]
        },
        {
            "x": -1,
            "y": -2,
            "z": -1,
            "elements": [
                "chisel:energizedvoidstone@1"
            ]
        },
        {
            "x": -1,
            "y": -2,
            "z": 0,
            "elements": [
                "chisel:energizedvoidstone@1"
            ]
        },
        {
            "x": -1,
            "y": 12,
            "z": 4,
            "elements": [
                "contenttweaker:fractallite_taint"
            ]
        },
        {
            "x": -1,
            "y": 12,
            "z": 5,
            "elements": [
                "thaumicaugmentation:fortified_glass@0"
            ]
        },
        {
            "x": -1,
            "y": -2,
            "z": 1,
            "elements": [
                "chisel:energizedvoidstone@1"
            ]
        },
        {
            "x": -1,
            "y": -2,
            "z": -6,
            "elements": [
                "chisel:arcane_stone1@12"
            ]
        },
        {
            "x": -1,
            "y": -2,
            "z": -5,
            "elements": [
                "chisel:arcane_stone1@12"
            ]
        },
        {
            "x": -1,
            "y": -2,
            "z": -4,
            "elements": [
                "chisel:arcane_stone1@12"
            ]
        },
        {
            "x": -1,
            "y": -2,
            "z": -3,
            "elements": [
                "chisel:energizedvoidstone@1"
            ]
        },
        {
            "x": -1,
            "y": -2,
            "z": -10,
            "elements": [
                "chisel:arcane_stone1@10"
            ]
        },
        {
            "x": -1,
            "y": -2,
            "z": -9,
            "elements": [
                "chisel:arcane_stone1@10"
            ]
        },
        {
            "x": -1,
            "y": -2,
            "z": -8,
            "elements": [
                "chisel:arcane_stone1@10"
            ]
        },
        {
            "x": -2,
            "y": -1,
            "z": 6,
            "elements": [
                "chisel:energizedvoidstone@1"
            ]
        },
        {
            "x": -2,
            "y": -1,
            "z": 7,
            "elements": [
                "chisel:arcane_stone1@12"
            ]
        },
        {
            "x": -1,
            "y": -2,
            "z": -7,
            "elements": [
                "chisel:arcane_stone1@12"
            ]
        },
        {
            "x": -2,
            "y": -1,
            "z": 4,
            "elements": [
                "chisel:energizedvoidstone@1"
            ]
        },
        {
            "x": -2,
            "y": -1,
            "z": 5,
            "elements": [
                "chisel:energizedvoidstone@1"
            ]
        },
        {
            "x": -2,
            "y": -1,
            "z": 2,
            "elements": [
                "chisel:arcane_stone1@12"
            ]
        },
        {
            "x": -2,
            "y": -1,
            "z": 3,
            "elements": [
                "chisel:arcane_stone1@12"
            ]
        },
        {
            "x": -2,
            "y": -1,
            "z": 0,
            "elements": [
                "chisel:arcane_stone1@12"
            ]
        },
        {
            "x": 9,
            "y": 0,
            "z": -6,
            "elements": [
                "chisel:arcane_stone1@12"
            ]
        },
        {
            "x": -2,
            "y": -1,
            "z": 1,
            "elements": [
                "chisel:energizedvoidstone@1"
            ]
        },
        {
            "x": -2,
            "y": -1,
            "z": -2,
            "elements": [
                "chisel:arcane_stone1@12"
            ]
        },
        {
            "x": -2,
            "y": -1,
            "z": -1,
            "elements": [
                "chisel:arcane_stone1@12"
            ]
        },
        {
            "x": -2,
            "y": -1,
            "z": -3,
            "elements": [
                "chisel:arcane_stone1@12"
            ]
        },
        {
            "x": 9,
            "y": 0,
            "z": 2,
            "elements": [
                "chisel:energizedvoidstone@1"
            ]
        },
        {
            "x": -1,
            "y": 12,
            "z": -2,
            "elements": [
                "contenttweaker:fractallite_taint"
            ]
        },
        {
            "x": -1,
            "y": -2,
            "z": 6,
            "elements": [
                "chisel:arcane_stone1@12"
            ]
        },
        {
            "x": -1,
            "y": -2,
            "z": 7,
            "elements": [
                "chisel:arcane_stone1@10"
            ]
        },
        {
            "x": 9,
            "y": 0,
            "z": 3,
            "elements": [
                "chisel:energizedvoidstone@1"
            ]
        },
        {
            "x": -1,
            "y": 12,
            "z": -1,
            "elements": [
                "contenttweaker:fractallite_taint"
            ]
        },
        {
            "x": -1,
            "y": 12,
            "z": -3,
            "elements": [
                "thaumicaugmentation:fortified_glass@0"
            ]
        },
        {
            "x": -1,
            "y": -2,
            "z": 2,
            "elements": [
                "chisel:energizedvoidstone@1"
            ]
        },
        {
            "x": -1,
            "y": 12,
            "z": 2,
            "elements": [
                "contenttweaker:fractallite_taint"
            ]
        },
        {
            "x": -1,
            "y": 12,
            "z": 3,
            "elements": [
                "contenttweaker:fractallite_taint"
            ]
        },
        {
            "x": -1,
            "y": -2,
            "z": 3,
            "elements": [
                "chisel:arcane_stone1@12"
            ]
        },
        {
            "x": -1,
            "y": -2,
            "z": 4,
            "elements": [
                "chisel:arcane_stone1@12"
            ]
        },
        {
            "x": -1,
            "y": 12,
            "z": 0,
            "elements": [
                "contenttweaker:fractallite_taint"
            ]
        },
        {
            "x": -1,
            "y": 12,
            "z": 1,
            "elements": [
                "contenttweaker:fractallite_taint"
            ]
        },
        {
            "x": -1,
            "y": -2,
            "z": 5,
            "elements": [
                "chisel:energizedvoidstone@1"
            ]
        },
        {
            "x": 10,
            "y": -2,
            "z": 3,
            "elements": [
                "chisel:arcane_stone1@12"
            ]
        },
        {
            "x": 10,
            "y": -2,
            "z": 4,
            "elements": [
                "chisel:arcane_stone1@10"
            ]
        },
        {
            "x": 10,
            "y": -2,
            "z": 2,
            "elements": [
                "chisel:arcane_stone1@10"
            ]
        },
        {
            "x": -1,
            "y": 14,
            "z": 3,
            "elements": [
                "thaumicaugmentation:fortified_glass@0"
            ]
        },
        {
            "x": -1,
            "y": 14,
            "z": 2,
            "elements": [
                "thaumicaugmentation:fortified_glass@0"
            ]
        },
        {
            "x": -10,
            "y": 3,
            "z": 3,
            "elements": [
                "chisel:arcane_stone1@12"
            ]
        },
        {
            "x": -1,
            "y": 11,
            "z": 3,
            "elements": [
                "contenttweaker:fractallite_taint"
            ]
        },
        {
            "x": -1,
            "y": 11,
            "z": 4,
            "elements": [
                "contenttweaker:fractallite_taint"
            ]
        },
        {
            "x": -1,
            "y": 11,
            "z": 1,
            "elements": [
                "contenttweaker:fractallite_taint"
            ]
        },
        {
            "x": -1,
            "y": 11,
            "z": 2,
            "elements": [
                "contenttweaker:fractallite_taint"
            ]
        },
        {
            "x": -1,
            "y": 11,
            "z": -1,
            "elements": [
                "contenttweaker:fractallite_taint"
            ]
        },
        {
            "x": -1,
            "y": 11,
            "z": 0,
            "elements": [
                "contenttweaker:fractallite_taint"
            ]
        },
        {
            "x": -1,
            "y": 11,
            "z": -3,
            "elements": [
                "thaumicaugmentation:fortified_glass@0"
            ]
        },
        {
            "x": -1,
            "y": 11,
            "z": -2,
            "elements": [
                "contenttweaker:fractallite_taint"
            ]
        },
        {
            "x": -3,
            "y": -2,
            "z": 4,
            "elements": [
                "chisel:arcane_stone1@12"
            ]
        },
        {
            "x": -5,
            "y": 6,
            "z": 11,
            "elements": [
                "chisel:arcane_stone1@12"
            ]
        },
        {
            "x": -3,
            "y": -2,
            "z": 5,
            "elements": [
                "chisel:energizedvoidstone@1"
            ]
        },
        {
            "x": -3,
            "y": -2,
            "z": 6,
            "elements": [
                "chisel:energizedvoidstone@1"
            ]
        },
        {
            "x": -3,
            "y": -2,
            "z": 7,
            "elements": [
                "chisel:energizedvoidstone@1"
            ]
        },
        {
            "x": -3,
            "y": -2,
            "z": 8,
            "elements": [
                "chisel:arcane_stone1@12"
            ]
        },
        {
            "x": -3,
            "y": -2,
            "z": 9,
            "elements": [
                "chisel:arcane_stone1@12"
            ]
        },
        {
            "x": -3,
            "y": -2,
            "z": 10,
            "elements": [
                "chisel:arcane_stone1@10"
            ]
        },
        {
            "x": -1,
            "y": 11,
            "z": 5,
            "elements": [
                "thaumicaugmentation:fortified_glass@0"
            ]
        },
        {
            "x": -3,
            "y": -2,
            "z": -4,
            "elements": [
                "chisel:arcane_stone1@10"
            ]
        },
        {
            "x": -3,
            "y": -2,
            "z": -3,
            "elements": [
                "chisel:arcane_stone1@12"
            ]
        },
        {
            "x": -11,
            "y": 2,
            "z": 3,
            "elements": [
                "chisel:arcane_stone1@12"
            ]
        },
        {
            "x": -3,
            "y": -2,
            "z": -2,
            "elements": [
                "chisel:energizedvoidstone@1"
            ]
        },
        {
            "x": -3,
            "y": -2,
            "z": -1,
            "elements": [
                "chisel:arcane_stone1@12"
            ]
        },
        {
            "x": -2,
            "y": 0,
            "z": 7,
            "elements": [
                "chisel:energizedvoidstone@1"
            ]
        },
        {
            "x": -3,
            "y": -2,
            "z": 0,
            "elements": [
                "chisel:energizedvoidstone@1"
            ]
        },
        {
            "x": -3,
            "y": -2,
            "z": 1,
            "elements": [
                "chisel:arcane_stone1@12"
            ]
        },
        {
            "x": 10,
            "y": 1,
            "z": 3,
            "elements": [
                "chisel:energizedvoidstone@1"
            ]
        },
        {
            "x": -3,
            "y": -2,
            "z": 2,
            "elements": [
                "chisel:arcane_stone1@12"
            ]
        },
        {
            "x": -3,
            "y": -2,
            "z": 3,
            "elements": [
                "chisel:arcane_stone1@12"
            ]
        },
        {
            "x": -11,
            "y": 1,
            "z": 3,
            "elements": [
                "chisel:arcane_stone1@12"
            ]
        },
        {
            "x": -2,
            "y": 0,
            "z": -3,
            "elements": [
                "chisel:arcane_stone1@12"
            ]
        },
        {
            "x": -1,
            "y": 14,
            "z": -1,
            "elements": [
                "thaumicaugmentation:fortified_glass@0"
            ]
        },
        {
            "x": -1,
            "y": 14,
            "z": 1,
            "elements": [
                "contenttweaker:fractallite_taint"
            ]
        },
        {
            "x": -1,
            "y": 14,
            "z": 0,
            "elements": [
                "thaumicaugmentation:fortified_glass@0"
            ]
        },
        {
            "x": -5,
            "y": 5,
            "z": 11,
            "elements": [
                "chisel:arcane_stone1@12"
            ]
        },
        {
            "x": 10,
            "y": -2,
            "z": -6,
            "elements": [
                "chisel:arcane_stone1@10"
            ]
        },
        {
            "x": -4,
            "y": 8,
            "z": 0,
            "elements": [
                "thaumicaugmentation:fortified_glass@0"
            ]
        },
        {
            "x": -2,
            "y": 12,
            "z": -2,
            "elements": [
                "thaumicaugmentation:fortified_glass@0"
            ]
        },
        {
            "x": -4,
            "y": 8,
            "z": 2,
            "elements": [
                "thaumicaugmentation:fortified_glass@0"
            ]
        },
        {
            "x": -2,
            "y": 12,
            "z": -1,
            "elements": [
                "contenttweaker:fractallite_taint"
            ]
        },
        {
            "x": -4,
            "y": 8,
            "z": 1,
            "elements": [
                "thaumicaugmentation:fortified_glass@0"
            ]
        },
        {
            "x": -2,
            "y": 12,
            "z": 0,
            "elements": [
                "contenttweaker:fractallite_taint"
            ]
        },
        {
            "x": -2,
            "y": 12,
            "z": 1,
            "elements": [
                "contenttweaker:fractallite_taint"
            ]
        },
        {
            "x": -2,
            "y": 12,
            "z": 2,
            "elements": [
                "contenttweaker:fractallite_taint"
            ]
        },
        {
            "x": -2,
            "y": 12,
            "z": 3,
            "elements": [
                "contenttweaker:fractallite_taint"
            ]
        },
        {
            "x": -2,
            "y": 12,
            "z": 4,
            "elements": [
                "thaumicaugmentation:fortified_glass@0"
            ]
        },
        {
            "x": 9,
            "y": -1,
            "z": 2,
            "elements": [
                "chisel:arcane_stone1@12"
            ]
        },
        {
            "x": 9,
            "y": -1,
            "z": 3,
            "elements": [
                "chisel:arcane_stone1@12"
            ]
        },
        {
            "x": 0,
            "y": 1,
            "z": -9,
            "elements": [
                "chisel:energizedvoidstone@1"
            ]
        },
        {
            "x": 0,
            "y": 1,
            "z": -10,
            "elements": [
                "chisel:arcane_stone1@12"
            ]
        },
        {
            "x": 0,
            "y": 1,
            "z": -8,
            "elements": [
                "chisel:energizedvoidstone@1"
            ]
        },
        {
            "x": -1,
            "y": 2,
            "z": -7,
            "elements": [
                "chisel:arcane_stone1@12"
            ]
        },
        {
            "x": -2,
            "y": 9,
            "z": -3,
            "elements": [
                "thaumicaugmentation:fortified_glass@0"
            ]
        },
        {
            "x": -2,
            "y": 9,
            "z": -2,
            "elements": [
                "contenttweaker:fractallite_taint"
            ]
        },
        {
            "x": -2,
            "y": 9,
            "z": -1,
            "elements": [
                "contenttweaker:fractallite_taint"
            ]
        },
        {
            "x": -1,
            "y": 2,
            "z": -6,
            "elements": [
                "chisel:arcane_stone1@12"
            ]
        },
        {
            "x": -2,
            "y": 9,
            "z": 4,
            "elements": [
                "contenttweaker:fractallite_taint"
            ]
        },
        {
            "x": -2,
            "y": 9,
            "z": 5,
            "elements": [
                "thaumicaugmentation:fortified_glass@0"
            ]
        },
        {
            "x": 0,
            "y": 1,
            "z": 1,
            "elements": [
                "chisel:energizedvoidstone@1"
            ]
        },
        {
            "x": 0,
            "y": 1,
            "z": 0,
            "elements": [
                "thaumcraft:stairs_arcane_brick@2"
            ]
        },
        {
            "x": -2,
            "y": 9,
            "z": 0,
            "elements": [
                "contenttweaker:fractallite_taint"
            ]
        },
        {
            "x": 0,
            "y": 1,
            "z": 2,
            "elements": [
                "thaumcraft:stairs_arcane_brick@3"
            ]
        },
        {
            "x": -2,
            "y": 9,
            "z": 1,
            "elements": [
                "contenttweaker:fractallite_taint"
            ]
        },
        {
            "x": -2,
            "y": 9,
            "z": 2,
            "elements": [
                "contenttweaker:fractallite_taint"
            ]
        },
        {
            "x": 0,
            "y": 1,
            "z": 5,
            "elements": [
                "chisel:arcane_stone1@12"
            ]
        },
        {
            "x": -2,
            "y": 9,
            "z": 3,
            "elements": [
                "contenttweaker:fractallite_taint"
            ]
        },
        {
            "x": 1,
            "y": 5,
            "z": 1,
            "elements": [
                "thaumicaugmentation:fortified_glass@0"
            ]
        },
        {
            "x": -5,
            "y": 4,
            "z": 10,
            "elements": [
                "chisel:arcane_stone1@12"
            ]
        },
        {
            "x": -5,
            "y": 4,
            "z": 11,
            "elements": [
                "chisel:arcane_stone1@12"
            ]
        },
        {
            "x": 0,
            "y": 4,
            "z": -9,
            "elements": [
                "chisel:arcane_stone1@12"
            ]
        },
        {
            "x": 2,
            "y": 6,
            "z": 0,
            "elements": [
                "thaumicaugmentation:fortified_glass@0"
            ]
        },
        {
            "x": 2,
            "y": 6,
            "z": 1,
            "elements": [
                "thaumicaugmentation:fortified_glass@0"
            ]
        },
        {
            "x": 2,
            "y": 6,
            "z": 2,
            "elements": [
                "thaumicaugmentation:fortified_glass@0"
            ]
        },
        {
            "x": -3,
            "y": 7,
            "z": 2,
            "elements": [
                "thaumicaugmentation:fortified_glass@0"
            ]
        },
        {
            "x": -3,
            "y": 7,
            "z": 1,
            "elements": [
                "thaumicaugmentation:fortified_glass@0"
            ]
        },
        {
            "x": -3,
            "y": 7,
            "z": 0,
            "elements": [
                "thaumicaugmentation:fortified_glass@0"
            ]
        },
        {
            "x": 0,
            "y": 4,
            "z": -10,
            "elements": [
                "chisel:arcane_stone1@12"
            ]
        },
        {
            "x": -3,
            "y": 7,
            "z": -1,
            "elements": [
                "thaumicaugmentation:fortified_glass@0"
            ]
        },
        {
            "x": 3,
            "y": 8,
            "z": -1,
            "elements": [
                "thaumicaugmentation:fortified_glass@0"
            ]
        },
        {
            "x": -3,
            "y": 7,
            "z": 3,
            "elements": [
                "thaumicaugmentation:fortified_glass@0"
            ]
        },
        {
            "x": 3,
            "y": 8,
            "z": -2,
            "elements": [
                "thaumicaugmentation:fortified_glass@0"
            ]
        },
        {
            "x": 3,
            "y": 8,
            "z": 1,
            "elements": [
                "contenttweaker:fractallite_taint"
            ]
        },
        {
            "x": 3,
            "y": 8,
            "z": 0,
            "elements": [
                "contenttweaker:fractallite_taint"
            ]
        },
        {
            "x": 3,
            "y": 8,
            "z": 3,
            "elements": [
                "thaumicaugmentation:fortified_glass@0"
            ]
        },
        {
            "x": 3,
            "y": 8,
            "z": 2,
            "elements": [
                "contenttweaker:fractallite_taint"
            ]
        },
        {
            "x": -10,
            "y": 4,
            "z": 3,
            "elements": [
                "chisel:arcane_stone1@12"
            ]
        },
        {
            "x": 3,
            "y": 8,
            "z": 4,
            "elements": [
                "thaumicaugmentation:fortified_glass@0"
            ]
        },
        {
            "x": 0,
            "y": 3,
            "z": 5,
            "elements": [
                "astralsorcery:blockcelestialcollectorcrystal"
            ]
        },
        {
            "x": -11,
            "y": 4,
            "z": 3,
            "elements": [
                "chisel:arcane_stone1@12"
            ]
        },
        {
            "x": 11,
            "y": 3,
            "z": 3,
            "elements": [
                "chisel:arcane_stone1@12"
            ]
        },
        {
            "x": 5,
            "y": 2,
            "z": 9,
            "elements": [
                "chisel:arcane_stone1@12"
            ]
        },
        {
            "x": 5,
            "y": 2,
            "z": 11,
            "elements": [
                "chisel:arcane_stone1@12"
            ]
        },
        {
            "x": 5,
            "y": 2,
            "z": 10,
            "elements": [
                "chisel:energizedvoidstone@1"
            ]
        },
        {
            "x": -5,
            "y": 3,
            "z": 0,
            "elements": [
                "astralsorcery:blockcelestialcollectorcrystal"
            ]
        },
        {
            "x": -5,
            "y": 3,
            "z": 9,
            "elements": [
                "chisel:arcane_stone1@12"
            ]
        },
        {
            "x": 5,
            "y": 2,
            "z": -4,
            "elements": [
                "chisel:arcane_stone1@12"
            ]
        },
        {
            "x": -5,
            "y": 3,
            "z": 10,
            "elements": [
                "chisel:arcane_stone1@12"
            ]
        },
        {
            "x": -5,
            "y": 3,
            "z": 11,
            "elements": [
                "chisel:arcane_stone1@12"
            ]
        },
        {
            "x": -7,
            "y": 0,
            "z": 1,
            "elements": [
                "chisel:energizedvoidstone@1"
            ]
        },
        {
            "x": -7,
            "y": 0,
            "z": 3,
            "elements": [
                "chisel:energizedvoidstone@1"
            ]
        },
        {
            "x": -7,
            "y": 0,
            "z": -5,
            "elements": [
                "chisel:energizedvoidstone@1"
            ]
        },
        {
            "x": -7,
            "y": 0,
            "z": -3,
            "elements": [
                "chisel:energizedvoidstone@1"
            ]
        },
        {
            "x": -7,
            "y": 0,
            "z": -4,
            "elements": [
                "chisel:energizedvoidstone@1"
            ]
        },
        {
            "x": -1,
            "y": 1,
            "z": 6,
            "elements": [
                "chisel:arcane_stone1@12"
            ]
        },
        {
            "x": 3,
            "y": 9,
            "z": 0,
            "elements": [
                "contenttweaker:fractallite_taint"
            ]
        },
        {
            "x": 3,
            "y": 9,
            "z": -1,
            "elements": [
                "contenttweaker:fractallite_taint"
            ]
        },
        {
            "x": 3,
            "y": 9,
            "z": 2,
            "elements": [
                "contenttweaker:fractallite_taint"
            ]
        },
        {
            "x": 3,
            "y": 9,
            "z": 1,
            "elements": [
                "contenttweaker:fractallite_taint"
            ]
        },
        {
            "x": 0,
            "y": 2,
            "z": -10,
            "elements": [
                "chisel:arcane_stone1@12"
            ]
        },
        {
            "x": -1,
            "y": 1,
            "z": 2,
            "elements": [
                "modularmachinery:blockaspectproviderinput@0"
            ]
        },
        {
            "x": -1,
            "y": 1,
            "z": 1,
            "elements": [
                "thaumcraft:stairs_arcane_brick@0"
            ]
        },
        {
            "x": -1,
            "y": 1,
            "z": 0,
            "elements": [
                "modularmachinery:blockaspectproviderinput@0"
            ]
        },
        {
            "x": 3,
            "y": 9,
            "z": -2,
            "elements": [
                "thaumicaugmentation:fortified_glass@0"
            ]
        },
        {
            "x": 0,
            "y": 2,
            "z": -8,
            "elements": [
                "chisel:arcane_stone1@12"
            ]
        },
        {
            "x": 0,
            "y": 2,
            "z": -9,
            "elements": [
                "chisel:energizedvoidstone@1"
            ]
        },
        {
            "x": 0,
            "y": 2,
            "z": 1,
            "elements": [
                "modularmachinery:blockstarlightproviderinput@0"
            ]
        },
        {
            "x": -1,
            "y": 1,
            "z": -4,
            "elements": [
                "chisel:arcane_stone1@12"
            ]
        },
        {
            "x": -1,
            "y": 1,
            "z": -5,
            "elements": [
                "chisel:arcane_stone1@12"
            ]
        },
        {
            "x": -1,
            "y": 1,
            "z": -6,
            "elements": [
                "chisel:energizedvoidstone@1"
            ]
        },
        {
            "x": 3,
            "y": 9,
            "z": 4,
            "elements": [
                "thaumicaugmentation:fortified_glass@0"
            ]
        },
        {
            "x": -1,
            "y": 1,
            "z": -7,
            "elements": [
                "chisel:energizedvoidstone@1"
            ]
        },
        {
            "x": 3,
            "y": 9,
            "z": 3,
            "elements": [
                "contenttweaker:fractallite_taint"
            ]
        },
        {
            "x": -2,
            "y": 10,
            "z": -3,
            "elements": [
                "thaumicaugmentation:fortified_glass@0"
            ]
        },
        {
            "x": -2,
            "y": 10,
            "z": -2,
            "elements": [
                "contenttweaker:fractallite_taint"
            ]
        },
        {
            "x": -2,
            "y": 10,
            "z": -1,
            "elements": [
                "contenttweaker:fractallite_taint"
            ]
        },
        {
            "x": -2,
            "y": 10,
            "z": 0,
            "elements": [
                "contenttweaker:fractallite_taint"
            ]
        },
        {
            "x": -2,
            "y": 10,
            "z": 1,
            "elements": [
                "contenttweaker:fractallite_taint"
            ]
        },
        {
            "x": -2,
            "y": 10,
            "z": 2,
            "elements": [
                "contenttweaker:fractallite_taint"
            ]
        },
        {
            "x": -2,
            "y": 10,
            "z": 3,
            "elements": [
                "contenttweaker:fractallite_taint"
            ]
        },
        {
            "x": -2,
            "y": 10,
            "z": 4,
            "elements": [
                "contenttweaker:fractallite_taint"
            ]
        },
        {
            "x": -2,
            "y": 10,
            "z": 5,
            "elements": [
                "thaumicaugmentation:fortified_glass@0"
            ]
        },
        {
            "x": 4,
            "y": 11,
            "z": -1,
            "elements": [
                "thaumicaugmentation:fortified_glass@0"
            ]
        },
        {
            "x": -9,
            "y": 8,
            "z": -6,
            "elements": [
                "astralsorcery:blockcelestialcollectorcrystal"
            ]
        },
        {
            "x": 4,
            "y": 11,
            "z": 2,
            "elements": [
                "thaumicaugmentation:fortified_glass@0"
            ]
        },
        {
            "x": 4,
            "y": 11,
            "z": 3,
            "elements": [
                "thaumicaugmentation:fortified_glass@0"
            ]
        },
        {
            "x": -3,
            "y": 8,
            "z": 4,
            "elements": [
                "thaumicaugmentation:fortified_glass@0"
            ]
        },
        {
            "x": -3,
            "y": 8,
            "z": 3,
            "elements": [
                "thaumicaugmentation:fortified_glass@0"
            ]
        },
        {
            "x": 4,
            "y": 11,
            "z": 0,
            "elements": [
                "thaumicaugmentation:fortified_glass@0"
            ]
        },
        {
            "x": 4,
            "y": 11,
            "z": 1,
            "elements": [
                "contenttweaker:fractallite_taint"
            ]
        },
        {
            "x": -3,
            "y": 8,
            "z": 2,
            "elements": [
                "contenttweaker:fractallite_taint"
            ]
        },
        {
            "x": -3,
            "y": 8,
            "z": 1,
            "elements": [
                "contenttweaker:fractallite_taint"
            ]
        },
        {
            "x": -3,
            "y": 8,
            "z": 0,
            "elements": [
                "contenttweaker:fractallite_taint"
            ]
        },
        {
            "x": -3,
            "y": 8,
            "z": -1,
            "elements": [
                "thaumicaugmentation:fortified_glass@0"
            ]
        },
        {
            "x": 0,
            "y": 3,
            "z": -9,
            "elements": [
                "chisel:arcane_stone1@12"
            ]
        },
        {
            "x": 0,
            "y": 3,
            "z": -10,
            "elements": [
                "chisel:arcane_stone1@12"
            ]
        },
        {
            "x": -3,
            "y": 8,
            "z": -2,
            "elements": [
                "thaumicaugmentation:fortified_glass@0"
            ]
        },
        {
            "x": 0,
            "y": 3,
            "z": -8,
            "elements": [
                "chisel:arcane_stone1@12"
            ]
        },
        {
            "x": -1,
            "y": 0,
            "z": 2,
            "elements": [
                "chisel:arcane_stone1@12"
            ]
        },
        {
            "x": 5,
            "y": 1,
            "z": -4,
            "elements": [
                "chisel:arcane_stone1@12"
            ]
        },
        {
            "x": -1,
            "y": 0,
            "z": 1,
            "elements": [
                "modularmachinery:blockmanaproviderinput@0"
            ]
        },
        {
            "x": -1,
            "y": 0,
            "z": 0,
            "elements": [
                "chisel:arcane_stone1@12"
            ]
        },
        {
            "x": -1,
            "y": 0,
            "z": 6,
            "elements": [
                "chisel:arcane_stone1@12"
            ]
        },
        {
            "x": 5,
            "y": 1,
            "z": 0,
            "elements": [
                "chisel:arcane_stone1@12"
            ]
        },
        {
            "x": 5,
            "y": 1,
            "z": -1,
            "elements": [
                "chisel:arcane_stone1@12"
            ]
        },
        {
            "x": -6,
            "y": 2,
            "z": -5,
            "elements": [
                "chisel:arcane_stone1@12"
            ]
        },
        {
            "x": 5,
            "y": 1,
            "z": 10,
            "elements": [
                "chisel:energizedvoidstone@1"
            ]
        },
        {
            "x": 5,
            "y": 1,
            "z": 9,
            "elements": [
                "chisel:energizedvoidstone@1"
            ]
        },
        {
            "x": 5,
            "y": 1,
            "z": 11,
            "elements": [
                "chisel:arcane_stone1@12"
            ]
        },
        {
            "x": -1,
            "y": 13,
            "z": 4,
            "elements": [
                "thaumicaugmentation:fortified_glass@0"
            ]
        },
        {
            "x": -1,
            "y": 13,
            "z": 3,
            "elements": [
                "contenttweaker:fractallite_taint"
            ]
        },
        {
            "x": -1,
            "y": 13,
            "z": 0,
            "elements": [
                "contenttweaker:fractallite_taint"
            ]
        },
        {
            "x": -1,
            "y": 13,
            "z": -1,
            "elements": [
                "contenttweaker:fractallite_taint"
            ]
        },
        {
            "x": -1,
            "y": 13,
            "z": 2,
            "elements": [
                "contenttweaker:fractallite_taint"
            ]
        },
        {
            "x": -1,
            "y": 13,
            "z": 1,
            "elements": [
                "contenttweaker:fractallite_taint"
            ]
        },
        {
            "x": 5,
            "y": 1,
            "z": 3,
            "elements": [
                "chisel:arcane_stone1@12"
            ]
        },
        {
            "x": -1,
            "y": 13,
            "z": -2,
            "elements": [
                "thaumicaugmentation:fortified_glass@0"
            ]
        },
        {
            "x": 10,
            "y": 0,
            "z": 3,
            "elements": [
                "chisel:energizedvoidstone@1"
            ]
        },
        {
            "x": 4,
            "y": -1,
            "z": 5,
            "elements": [
                "chisel:arcane_stone1@12"
            ]
        },
        {
            "x": 11,
            "y": 2,
            "z": 3,
            "elements": [
                "chisel:arcane_stone1@12"
            ]
        },
        {
            "x": 4,
            "y": -1,
            "z": 6,
            "elements": [
                "chisel:arcane_stone1@12"
            ]
        },
        {
            "x": -11,
            "y": 3,
            "z": 3,
            "elements": [
                "chisel:arcane_stone1@12"
            ]
        },
        {
            "x": 4,
            "y": -1,
            "z": 7,
            "elements": [
                "chisel:arcane_stone1@12"
            ]
        },
        {
            "x": 4,
            "y": -1,
            "z": 8,
            "elements": [
                "chisel:arcane_stone1@12"
            ]
        },
        {
            "x": 4,
            "y": -1,
            "z": 9,
            "elements": [
                "chisel:energizedvoidstone@1"
            ]
        },
        {
            "x": 4,
            "y": -1,
            "z": 10,
            "elements": [
                "chisel:arcane_stone1@12"
            ]
        },
        {
            "x": 4,
            "y": -1,
            "z": -4,
            "elements": [
                "chisel:arcane_stone1@12"
            ]
        },
        {
            "x": 2,
            "y": 7,
            "z": 1,
            "elements": [
                "contenttweaker:fractallite_taint"
            ]
        },
        {
            "x": 4,
            "y": -1,
            "z": -3,
            "elements": [
                "chisel:energizedvoidstone@1"
            ]
        },
        {
            "x": 2,
            "y": 7,
            "z": 0,
            "elements": [
                "contenttweaker:fractallite_taint"
            ]
        },
        {
            "x": 4,
            "y": -1,
            "z": -2,
            "elements": [
                "chisel:energizedvoidstone@1"
            ]
        },
        {
            "x": 2,
            "y": 7,
            "z": -1,
            "elements": [
                "thaumicaugmentation:fortified_glass@0"
            ]
        },
        {
            "x": 2,
            "y": 7,
            "z": -2,
            "elements": [
                "thaumicaugmentation:fortified_glass@0"
            ]
        },
        {
            "x": 4,
            "y": -1,
            "z": -1,
            "elements": [
                "chisel:energizedvoidstone@1"
            ]
        },
        {
            "x": 4,
            "y": -1,
            "z": 0,
            "elements": [
                "chisel:arcane_stone1@12"
            ]
        },
        {
            "x": 0,
            "y": 15,
            "z": 2,
            "elements": [
                "thaumicaugmentation:fortified_glass@0"
            ]
        },
        {
            "x": 4,
            "y": -1,
            "z": 1,
            "elements": [
                "chisel:energizedvoidstone@1"
            ]
        },
        {
            "x": 2,
            "y": 7,
            "z": 4,
            "elements": [
                "thaumicaugmentation:fortified_glass@0"
            ]
        },
        {
            "x": 0,
            "y": 15,
            "z": 1,
            "elements": [
                "thaumicaugmentation:fortified_glass@0"
            ]
        },
        {
            "x": 4,
            "y": -1,
            "z": 2,
            "elements": [
                "chisel:energizedvoidstone@1"
            ]
        },
        {
            "x": 2,
            "y": 7,
            "z": 3,
            "elements": [
                "thaumicaugmentation:fortified_glass@0"
            ]
        },
        {
            "x": 0,
            "y": 15,
            "z": 0,
            "elements": [
                "thaumicaugmentation:fortified_glass@0"
            ]
        },
        {
            "x": 2,
            "y": 7,
            "z": 2,
            "elements": [
                "contenttweaker:fractallite_taint"
            ]
        },
        {
            "x": 4,
            "y": -1,
            "z": 3,
            "elements": [
                "chisel:arcane_stone1@12"
            ]
        },
        {
            "x": -4,
            "y": 2,
            "z": 7,
            "elements": [
                "chisel:arcane_stone1@12"
            ]
        },
        {
            "x": -4,
            "y": 2,
            "z": 8,
            "elements": [
                "chisel:arcane_stone1@12"
            ]
        },
        {
            "x": -5,
            "y": 1,
            "z": 3,
            "elements": [
                "chisel:arcane_stone1@12"
            ]
        },
        {
            "x": -1,
            "y": 6,
            "z": 2,
            "elements": [
                "thaumicaugmentation:fortified_glass@0"
