
{
    "registryname": "philosophers_unifier",
    "localizedname": "Philosopher's Unifier",
	"color": "3b0d06",
    "modifiers": [
        {
            "elements": "projectex:power_flower@1",
            "x": 0,
            "y": 2,
            "z": 2,
            "description": "10X Processing, 4X power",
            "modifiers": [
            {
                "io": "input",
                "target": "modularmachinery:item",
                "operation": 1,
                "multiplier": 10
            },
            {
                "io": "input",
                "target": "modularmachinery:energy",
                "operation": 1,
                "multiplier": 4
            },
            {
                "io": "output",
                "target": "modularmachinery:item",
                "operation": 1,
                "multiplier": 10
            }]
        },
        {
            "elements": "projectex:power_flower@2",
            "x": 0,
            "y": 2,
            "z": 2,
            "description": "100X Processing, 16X power",
            "modifiers": [
            {
                "io": "input",
                "target": "modularmachinery:item",
                "operation": 1,
                "multiplier": 100
            },
            {
                "io": "input",
                "target": "modularmachinery:energy",
                "operation": 1,
                "multiplier": 16
            },
            {
                "io": "output",
                "target": "modularmachinery:item",
                "operation": 1,
                "multiplier": 100
            }]
        },
        {
            "elements": "projectex:power_flower@3",
            "x": 0,
            "y": 2,
            "z": 2,
            "description": "1000X Processing, 64X power",
            "modifiers": [
            {
                "io": "input",
                "target": "modularmachinery:item",
                "operation": 1,
                "multiplier": 1000
            },
            {
                "io": "input",
                "target": "modularmachinery:energy",
                "operation": 1,
                "multiplier": 64
            },
            {
                "io": "output",
                "target": "modularmachinery:item",
                "operation": 1,
                "multiplier": 1000
            }]
        },
        {
            "elements": "projectex:power_flower@4",
            "x": 0,
            "y": 2,
            "z": 2,
            "description": "10000X Processing, 256X power",
            "modifiers": [
            {
                "io": "input",
                "target": "modularmachinery:item",
                "operation": 1,
                "multiplier": 10000
            },
            {
                "io": "input",
                "target": "modularmachinery:energy",
                "operation": 1,
                "multiplier": 256
            },
            {
                "io": "output",
                "target": "modularmachinery:item",
                "operation": 1,
                "multiplier": 10000
            }]
        },
        {
            "elements": "projectex:power_flower@5",
            "x": 0,
            "y": 2,
            "z": 2,
            "description": "100000X Processing, 1024X power",
            "modifiers": [
            {
                "io": "input",
                "target": "modularmachinery:item",
                "operation": 1,
                "multiplier": 100000
            },
            {
                "io": "input",
                "target": "modularmachinery:energy",
                "operation": 1,
                "multiplier": 1024
            },
            {
                "io": "output",
                "target": "modularmachinery:item",
                "operation": 1,
                "multiplier": 100000
            }]
        },
        {
            "elements": "projectex:power_flower@6",
            "x": 0,
            "y": 2,
            "z": 2,
            "description": "1000000X Processing, 4096X power",
            "modifiers": [
            {
                "io": "input",
                "target": "modularmachinery:item",
                "operation": 1,
                "multiplier": 1000000
            },
            {
                "io": "input",
                "target": "modularmachinery:energy",
                "operation": 1,
                "multiplier": 4096
            },
            {
                "io": "output",
                "target": "modularmachinery:item",
                "operation": 1,
                "multiplier": 1000000
            }]
        },
        {
            "elements": "projectex:power_flower@7",
            "x": 0,
            "y": 2,
            "z": 2,
            "description": "10000000X Processing, 16384X power",
            "modifiers": [
            {
                "io": "input",
                "target": "modularmachinery:item",
                "operation": 1,
                "multiplier": 10000000
            },
            {
                "io": "input",
                "target": "modularmachinery:energy",
                "operation": 1,
                "multiplier": 16384
            },
            {
                "io": "output",
                "target": "modularmachinery:item",
                "operation": 1,
                "multiplier": 10000000
            }]
        },
        {
            "elements": "projectex:power_flower@8",
            "x": 0,
            "y": 2,
            "z": 2,
            "description": "100000000X Processing, 65536X power",
            "modifiers": [
            {
                "io": "input",
                "target": "modularmachinery:item",
                "operation": 1,
                "multiplier": 100000000
            },
            {
                "io": "input",
                "target": "modularmachinery:energy",
                "operation": 1,
                "multiplier": 65536
            },
            {
                "io": "output",
                "target": "modularmachinery:item",
                "operation": 1,
                "multiplier": 100000000
            }]
        },
        {
            "elements": "projectex:power_flower@9",
            "x": 0,
            "y": 2,
            "z": 2,
            "description": "1000000000X Processing, 262144X power",
            "modifiers": [
            {
                "io": "input",
                "target": "modularmachinery:item",
                "operation": 1,
                "multiplier": 1000000000
            },
            {
                "io": "input",
                "target": "modularmachinery:energy",
                "operation": 1,
                "multiplier": 262144
            },
            {
                "io": "output",
                "target": "modularmachinery:item",
                "operation": 1,
                "multiplier": 1000000000
            }]
        }
    ],
    "parts": [
        {
            "x": 1,
            "y": 1,
            "z": 3,
            "elements": [
                "projecte:matter_block@0"
            ]
        },
        {
            "x": 0,
            "y": 3,
            "z": 1,
            "elements": [
                "projecte:matter_block@1"
            ]
        },
        {
            "x": -3,
            "y": 0,
            "z": 1,
            "elements": [
                "projecte:matter_block@1"
            ]
        },
        {
            "x": 0,
            "y": -2,
            "z": 0,
            "elements": [
                "projecte:fuel_block@2"
            ]
        },
        {
            "x": 2,
            "y": 1,
            "z": 2,
            "elements": [
                "projecte:matter_block@1"
            ]
        },
        {
            "x": 0,
            "y": 2,
            "z": 1,
            "elements": [
                "projecte:matter_block@1"
            ]
        },
        {
            "x": -1,
            "y": 1,
            "z": 0,
            "elements": [
                "projecte:matter_block@0"
            ]
        },
        {
            "x": 0,
            "y": -1,
            "z": 0,
            "elements": [
                "projecte:matter_block@1"
            ]
        },
        {
            "x": -1,
            "y": 0,
            "z": 4,
            "elements": [
                "projecte:matter_block@1"
            ]
        },
        {
            "x": 2,
            "y": 0,
            "z": 2,
            "elements": [
                "casings_item"
            ]
        },
        {
            "x": 1,
            "y": 0,
            "z": 0,
            "elements": [
                "projecte:matter_block@1"
            ]
        },
        {
            "x": -1,
            "y": 1,
            "z": 4,
            "elements": [
                "projecte:matter_block@0"
            ]
        },
        {
            "x": 3,
            "y": 1,
            "z": 2,
            "elements": [
                "projecte:matter_block@1"
            ]
        },
        {
            "x": 0,
            "y": -1,
            "z": 3,
            "elements": [
                "projecte:matter_block@1"
            ]
        },
        {
            "x": 3,
            "y": -1,
            "z": 2,
            "elements": [
                "projecte:matter_block@1"
            ]
        },
        {
            "x": 0,
            "y": 0,
            "z": 1,
            "elements": [
                "projecte:fuel_block@2"
            ]
        },
        {
            "x": 1,
            "y": -1,
            "z": 0,
            "elements": [
                "projecte:matter_block@0"
            ]
        },
        {
            "x": 2,
            "y": 2,
            "z": 2,
            "elements": [
                "projecte:fuel_block@2"
            ]
        },
        {
            "x": 1,
            "y": 0,
            "z": 3,
            "elements": [
                "projecte:matter_block@1"
            ]
        },
        {
            "x": -1,
            "y": -2,
            "z": 1,
            "elements": [
                "projecte:matter_block@0"
            ]
        },
        {
            "x": 1,
            "y": -2,
            "z": 3,
            "elements": [
                "projecte:matter_block@0"
            ]
        },
        {
            "x": 0,
            "y": 1,
            "z": 1,
            "elements": [
                "projecte:matter_block@1"
            ]
        },
        {
            "x": 2,
            "y": -1,
            "z": 1,
            "elements": [
                "projecte:matter_block@0"
            ]
        },
        {
            "x": 2,
            "y": 0,
            "z": 0,
            "elements": [
                "projecte:fuel_block@2"
            ]
        },
        {
            "x": 0,
            "y": -1,
            "z": -1,
            "elements": [
                "projecte:matter_block@1"
            ]
        },
        {
            "x": -1,
            "y": 0,
            "z": 1,
            "elements": [
                "projecte:matter_block@1"
            ]
        },
        {
            "x": 2,
            "y": -2,
            "z": 2,
            "elements": [
                "projecte:fuel_block@2"
            ]
        },
        {
            "x": 1,
            "y": -1,
            "z": 3,
            "elements": [
                "projecte:matter_block@0"
            ]
        },
        {
            "x": 0,
            "y": 1,
            "z": -1,
            "elements": [
                "projecte:matter_block@1"
            ]
        },
        {
            "x": 0,
            "y": -2,
            "z": 4,
            "elements": [
                "projecte:fuel_block@2"
            ]
        },
        {
            "x": 2,
            "y": -1,
            "z": 2,
            "elements": [
                "projecte:matter_block@1"
            ]
        },
        {
            "x": 0,
            "y": 1,
            "z": 2,
            "elements": [
                "projecte:fuel_block@2"
            ]
        },
        {
            "x": 1,
            "y": 1,
            "z": 0,
            "elements": [
                "projecte:matter_block@0"
            ]
        },
        {
            "x": -1,
            "y": -1,
            "z": 1,
            "elements": [
                "projecte:matter_block@0"
            ]
        },
        {
            "x": 0,
            "y": -3,
            "z": 1,
            "elements": [
                "projecte:matter_block@1"
            ]
        },
        {
            "x": 2,
            "y": 0,
            "z": 3,
            "elements": [
                "projecte:matter_block@1"
            ]
        },
        {
            "x": -1,
            "y": 1,
            "z": 1,
            "elements": [
                "projecte:matter_block@0"
            ]
        },
        {
            "x": 0,
            "y": 0,
            "z": 2,
            "elements": [
                "projecte:fuel_block@2"
            ]
        },
        {
            "x": -1,
            "y": 0,
            "z": 0,
            "elements": [
                "projecte:matter_block@1"
            ]
        },
        {
            "x": -2,
            "y": 0,
            "z": 1,
            "elements": [
                "projecte:matter_block@1"
            ]
        },
        {
            "x": 2,
            "y": 1,
            "z": 3,
            "elements": [
                "projecte:matter_block@0"
            ]
        },
        {
            "x": 0,
            "y": -2,
            "z": 1,
            "elements": [
                "projecte:matter_block@1"
            ]
        },
        {
            "x": 2,
            "y": -1,
            "z": 3,
            "elements": [
                "projecte:matter_block@0"
            ]
        },
        {
            "x": -1,
            "y": 2,
            "z": 1,
            "elements": [
                "projecte:matter_block@0"
            ]
        },
        {
            "x": -3,
            "y": 1,
            "z": 2,
            "elements": [
                "projecte:matter_block@1"
            ]
        },
        {
            "x": 1,
            "y": 2,
            "z": 3,
            "elements": [
                "projecte:matter_block@0"
            ]
        },
        {
            "x": 0,
            "y": -1,
            "z": 1,
            "elements": [
                "projecte:matter_block@1"
            ]
        },
        {
            "x": -3,
            "y": -1,
            "z": 2,
            "elements": [
                "projecte:matter_block@1"
            ]
        },
        {
            "x": 3,
            "y": 0,
            "z": 3,
            "elements": [
                "projecte:matter_block@1"
            ]
        },
        {
            "x": -1,
            "y": 0,
            "z": -1,
            "elements": [
                "projecte:matter_block@1"
            ]
        },
        {
            "x": -2,
            "y": 0,
            "z": 4,
            "elements": [
                "projecte:fuel_block@2"
            ]
        },
        {
            "x": 0,
            "y": 2,
            "z": 2,
            "elements": [
                "projectex:power_flower@0"
            ]
        },
        {
            "x": 0,
            "y": 3,
            "z": 3,
            "elements": [
                "projecte:matter_block@1"
            ]
        },
        {
            "x": -2,
            "y": 1,
            "z": 1,
            "elements": [
                "projecte:matter_block@0"
            ]
        },
        {
            "x": 0,
            "y": 1,
            "z": 5,
            "elements": [
                "projecte:matter_block@1"
            ]
        },
        {
            "x": 0,
            "y": -2,
            "z": 2,
            "elements": [
                "modularmachinery:blockenergyinputhatch"
            ]
        },
        {
            "x": -2,
            "y": 0,
            "z": 2,
            "elements": [
                "casings_item"
            ]
        },
        {
            "x": 1,
            "y": -2,
            "z": 1,
            "elements": [
                "projecte:matter_block@0"
            ]
        },
        {
            "x": -1,
            "y": 3,
            "z": 2,
            "elements": [
                "projecte:matter_block@1"
            ]
        },
        {
            "x": 1,
            "y": 0,
            "z": 5,
            "elements": [
                "projecte:matter_block@1"
            ]
        },
        {
            "x": -1,
            "y": -1,
            "z": 3,
            "elements": [
                "projecte:matter_block@0"
            ]
        },
        {
            "x": -2,
            "y": 1,
            "z": 2,
            "elements": [
                "projecte:matter_block@1"
            ]
        },
        {
            "x": 1,
            "y": 0,
            "z": 1,
            "elements": [
                "projecte:matter_block@1"
            ]
        },
        {
            "x": 0,
            "y": 1,
            "z": 4,
            "elements": [
                "projecte:matter_block@1"
            ]
        },
        {
            "x": 1,
            "y": -1,
            "z": 1,
            "elements": [
                "projecte:matter_block@0"
            ]
        },
        {
            "x": 0,
            "y": -1,
            "z": 2,
            "elements": [
                "projecte:fuel_block@2"
            ]
        },
        {
            "x": -1,
            "y": -3,
            "z": 2,
            "elements": [
                "projecte:matter_block@1"
            ]
        },
        {
            "x": 0,
            "y": 0,
            "z": 3,
            "elements": [
                "projecte:fuel_block@2"
            ]
        },
        {
            "x": -1,
            "y": -1,
            "z": 4,
            "elements": [
                "projecte:matter_block@0"
            ]
        },
        {
            "x": -1,
            "y": 2,
            "z": 2,
            "elements": [
                "projecte:matter_block@1"
            ]
        },
        {
            "x": 1,
            "y": 1,
            "z": 1,
            "elements": [
                "projecte:matter_block@0"
            ]
        },
        {
            "x": 0,
            "y": 2,
            "z": 4,
            "elements": [
                "projecte:fuel_block@2"
            ]
        },
        {
            "x": 0,
            "y": 1,
            "z": 3,
            "elements": [
                "projecte:matter_block@1"
            ]
        },
        {
            "x": -1,
            "y": -2,
            "z": 2,
            "elements": [
                "projecte:matter_block@1"
            ]
        },
        {
            "x": 1,
            "y": 2,
            "z": 1,
            "elements": [
                "projecte:matter_block@0"
            ]
        },
        {
            "x": -1,
            "y": 1,
            "z": 2,
            "elements": [
                "projecte:matter_block@1"
            ]
        },
        {
            "x": -2,
            "y": -1,
            "z": 1,
            "elements": [
                "projecte:matter_block@0"
            ]
        },
        {
            "x": -1,
            "y": -1,
            "z": 2,
            "elements": [
                "projecte:matter_block@1"
            ]
        },
        {
            "x": 0,
            "y": 2,
            "z": 3,
            "elements": [
                "projecte:matter_block@1"
            ]
        },
        {
            "x": 1,
            "y": 0,
            "z": -1,
            "elements": [
                "projecte:matter_block@1"
            ]
        },
        {
            "x": -2,
            "y": 2,
            "z": 2,
            "elements": [
                "projecte:fuel_block@2"
            ]
        },
        {
            "x": -3,
            "y": 0,
            "z": 3,
            "elements": [
                "projecte:matter_block@1"
            ]
        },
        {
            "x": 0,
            "y": -1,
            "z": 5,
            "elements": [
                "projecte:matter_block@1"
            ]
        },
        {
            "x": 0,
            "y": 0,
            "z": 4,
            "elements": [
                "modularmachinery:blockenergyinputhatch"
            ]
        },
        {
            "x": -1,
            "y": 0,
            "z": 2,
            "elements": [
                "projecte:fuel_block@2"
            ]
        },
        {
            "x": -2,
            "y": 0,
            "z": 0,
            "elements": [
                "projecte:fuel_block@2"
            ]
        },
        {
            "x": -2,
            "y": -2,
            "z": 2,
            "elements": [
                "projecte:fuel_block@2"
            ]
        },
        {
            "x": -1,
            "y": 1,
            "z": 3,
            "elements": [
                "projecte:matter_block@0"
            ]
        },
        {
            "x": 1,
            "y": 3,
            "z": 2,
            "elements": [
                "projecte:matter_block@1"
            ]
        },
        {
            "x": 0,
            "y": -1,
            "z": 4,
            "elements": [
                "projecte:matter_block@1"
            ]
        },
        {
            "x": 0,
            "y": -3,
            "z": 3,
            "elements": [
                "projecte:matter_block@1"
            ]
        },
        {
            "x": -1,
            "y": 0,
            "z": 5,
            "elements": [
                "projecte:matter_block@1"
            ]
        },
        {
            "x": 3,
            "y": 0,
            "z": 1,
            "elements": [
                "projecte:matter_block@1"
            ]
        },
        {
            "x": -2,
            "y": -1,
            "z": 2,
            "elements": [
                "projecte:matter_block@1"
            ]
        },
        {
            "x": -1,
            "y": 2,
            "z": 3,
            "elements": [
                "projecte:matter_block@0"
            ]
        },
        {
            "x": 1,
            "y": -3,
            "z": 2,
            "elements": [
                "projecte:matter_block@1"
            ]
        },
        {
            "x": -2,
            "y": 0,
            "z": 3,
            "elements": [
                "projecte:matter_block@1"
            ]
        },
        {
            "x": 1,
            "y": 2,
            "z": 2,
            "elements": [
                "projecte:matter_block@1"
            ]
        },
        {
            "x": 1,
            "y": 0,
            "z": 4,
            "elements": [
                "projecte:matter_block@1"
            ]
        },
        {
            "x": 0,
            "y": -2,
            "z": 3,
            "elements": [
                "projecte:matter_block@1"
            ]
        },
        {
            "x": 1,
            "y": -2,
            "z": 2,
            "elements": [
                "projecte:matter_block@1"
            ]
        },
        {
            "x": 0,
            "y": 2,
            "z": 0,
            "elements": [
                "projecte:fuel_block@2"
            ]
        },
        {
            "x": -2,
            "y": 1,
            "z": 3,
            "elements": [
                "projecte:matter_block@0"
            ]
        },
        {
            "x": 1,
            "y": -1,
            "z": 4,
            "elements": [
                "projecte:matter_block@0"
            ]
        },
        {
            "x": -2,
            "y": -1,
            "z": 3,
            "elements": [
                "projecte:matter_block@0"
            ]
        },
        {
            "x": 1,
            "y": 1,
            "z": 2,
            "elements": [
                "projecte:matter_block@1"
            ]
        },
        {
            "x": 1,
            "y": -1,
            "z": 2,
            "elements": [
                "projecte:matter_block@1"
            ]
        },
        {
            "x": 2,
            "y": 0,
            "z": 1,
            "elements": [
                "projecte:matter_block@1"
            ]
        },
        {
            "x": 1,
            "y": 1,
            "z": 4,
            "elements": [
                "projecte:matter_block@0"
            ]
        },
        {
            "x": 0,
            "y": 1,
            "z": 0,
            "elements": [
                "projecte:matter_block@1"
            ]
        },
        {
            "x": -1,
            "y": -1,
            "z": 0,
            "elements": [
                "projecte:matter_block@0"
            ]
        },
        {
            "x": -1,
            "y": 0,
            "z": 3,
            "elements": [
                "projecte:matter_block@1"
            ]
        },
        {
            "x": -1,
            "y": -2,
            "z": 3,
            "elements": [
                "projecte:matter_block@0"
            ]
        },
        {
            "x": 2,
            "y": 1,
            "z": 1,
            "elements": [
                "projecte:matter_block@0"
            ]
        },
        {
            "x": 2,
            "y": 0,
            "z": 4,
            "elements": [
                "projecte:fuel_block@2"
            ]
        },
        {
            "x": 1,
            "y": 0,
            "z": 2,
            "elements": [
                "projecte:fuel_block@2"
            ]
        }
    ]}