{
    "registryname": "presbytery_of_the_threefold_love",
    "localizedname": "Presbytery of the Threefold Love",
	"color": "ffffff",
    "parts": [
        {
            "x": 10,
            "y": 1,
            "z": 2,
            "elements": [
                "astralsorcery:blockblackmarble@0"
            ]
        },
        {
            "x": -1,
            "y": 2,
            "z": 0,
            "elements": [
                "astralsorcery:blockmarble@1"
            ]
        },
        {
            "x": -3,
            "y": 0,
            "z": 5,
            "elements": [
                "astralsorcery:blockblackmarble@0"
            ]
        },
        {
            "x": 12,
            "y": 2,
            "z": 3,
            "elements": [
                "astralsorcery:blockmarble@1"
            ]
        },
        {
            "x": -2,
            "y": 4,
            "z": 0,
            "elements": [
                "astralsorcery:blockmarble@2"
            ]
        },
        {
            "x": -6,
            "y": 0,
            "z": 10,
            "elements": [
                "astralsorcery:blockblackmarble@0"
            ]
        },
        {
            "x": -1,
            "y": 0,
            "z": 19,
            "elements": [
                "astralsorcery:blockblackmarble@0"
            ]
        },
        {
            "x": 10,
            "y": 2,
            "z": 2,
            "elements": [
                "astralsorcery:blockblackmarble@0"
            ]
        },
        {
            "x": -3,
            "y": 2,
            "z": 5,
            "elements": [
                "astralsorcery:blockblackmarble@0"
            ]
        },
        {
            "x": -5,
            "y": 2,
            "z": 10,
            "elements": [
                "astralsorcery:blockblackmarble@0"
            ]
        },
        {
            "x": 3,
            "y": 10,
            "z": 7,
            "elements": [
                "divinerpg:arcanium_block@0"
            ]
        },
        {
            "x": 10,
            "y": 0,
            "z": 2,
            "elements": [
                "astralsorcery:blockblackmarble@0"
            ]
        },
        {
            "x": -6,
            "y": 0,
            "z": -1,
            "elements": [
                "astralsorcery:blockmarble@1"
            ]
        },
        {
            "x": 1,
            "y": 0,
            "z": 0,
            "elements": [
                "astralsorcery:blockmarble@1"
            ]
        },
        {
            "x": -5,
            "y": 0,
            "z": 15,
            "elements": [
                "astralsorcery:blockmarble@1"
            ]
        },
        {
            "x": -2,
            "y": 2,
            "z": 0,
            "elements": [
                "astralsorcery:blockmarble@4"
            ]
        },
        {
            "x": 2,
            "y": 0,
            "z": 22,
            "elements": [
                "astralsorcery:blockmarble@4"
            ]
        },
        {
            "x": 12,
            "y": 0,
            "z": 3,
            "elements": [
                "modularmachinery:blockinputbus@0"
            ]
        },
        {
            "x": -2,
            "y": 0,
            "z": 5,
            "elements": [
                "astralsorcery:blockblackmarble@0"
            ]
        },
        {
            "x": 9,
            "y": 0,
            "z": 7,
            "elements": [
                "astralsorcery:blockmarble@1"
            ]
        },
        {
            "x": 6,
            "y": 3,
            "z": 7,
            "elements": [
                "astralsorcery:blockmarblestairs@1"
            ]
        },
        {
            "x": 6,
            "y": 2,
            "z": 7,
            "elements": [
                "astralsorcery:blockblackmarble@0"
            ]
        },
        {
            "x": 2,
            "y": 3,
            "z": 17,
            "elements": [
                "astralsorcery:blockmarblestairs@1"
            ]
        },
        {
            "x": 5,
            "y": 0,
            "z": 17,
            "elements": [
                "astralsorcery:blockmarble@1"
            ]
        },
        {
            "x": -6,
            "y": 2,
            "z": 10,
            "elements": [
                "astralsorcery:blockblackmarble@0"
            ]
        },
        {
            "x": -6,
            "y": 2,
            "z": -1,
            "elements": [
                "astralsorcery:blockmarble@1"
            ]
        },
        {
            "x": -12,
            "y": 1,
            "z": 4,
            "elements": [
                "astralsorcery:blockmarble@2"
            ]
        },
        {
            "x": -2,
            "y": 2,
            "z": 5,
            "elements": [
                "astralsorcery:blockblackmarble@0"
            ]
        },
        {
            "x": -5,
            "y": 0,
            "z": 10,
            "elements": [
                "astralsorcery:blockblackmarble@0"
            ]
        },
        {
            "x": 9,
            "y": 3,
            "z": 2,
            "elements": [
                "astralsorcery:blockmarblestairs@1"
            ]
        },
        {
            "x": 9,
            "y": 2,
            "z": 7,
            "elements": [
                "astralsorcery:blockmarble@1"
            ]
        },
        {
            "x": 6,
            "y": 3,
            "z": 4,
            "elements": [
                "astralsorcery:blockblackmarble@0"
            ]
        },
        {
            "x": 2,
            "y": 2,
            "z": 17,
            "elements": [
                "astralsorcery:blockblackmarble@0"
            ]
        },
        {
            "x": 0,
            "y": 8,
            "z": 3,
            "elements": [
                "divinerpg:arcanium_block@0"
            ]
        },
        {
            "x": 0,
            "y": 3,
            "z": 14,
            "elements": [
                "astralsorcery:blockblackmarble@0"
            ]
        },
        {
            "x": -7,
            "y": 10,
            "z": 5,
            "elements": [
                "divinerpg:arcanium_block@0"
            ]
        },
        {
            "x": 6,
            "y": 1,
            "z": 4,
            "elements": [
                "astralsorcery:blockblackmarble@0"
            ]
        },
        {
            "x": 2,
            "y": 0,
            "z": 0,
            "elements": [
                "astralsorcery:blockmarble@4"
            ]
        },
        {
            "x": 6,
            "y": 3,
            "z": 1,
            "elements": [
                "astralsorcery:blockmarblestairs@2"
            ]
        },
        {
            "x": 2,
            "y": 1,
            "z": 17,
            "elements": [
                "astralsorcery:blockblackmarble@0"
            ]
        },
        {
            "x": 3,
            "y": 3,
            "z": 4,
            "elements": [
                "astralsorcery:blockblackmarble@0"
            ]
        },
        {
            "x": 1,
            "y": 2,
            "z": 0,
            "elements": [
                "astralsorcery:blockmarble@1"
            ]
        },
        {
            "x": -5,
            "y": 0,
            "z": 5,
            "elements": [
                "astralsorcery:blockblackmarble@0"
            ]
        },
        {
            "x": 9,
            "y": 0,
            "z": 3,
            "elements": [
                "astralsorcery:blockblackmarble@0"
            ]
        },
        {
            "x": 6,
            "y": 2,
            "z": -1,
            "elements": [
                "astralsorcery:blockmarble@1"
            ]
        },
        {
            "x": 3,
            "y": 10,
            "z": 6,
            "elements": [
                "divinerpg:arcanium_block@0"
            ]
        },
        {
            "x": -12,
            "y": 5,
            "z": 4,
            "elements": [
                "astralsorcery:blockmarble@2"
            ]
        },
        {
            "x": 6,
            "y": 2,
            "z": 1,
            "elements": [
                "astralsorcery:blockblackmarble@0"
            ]
        },
        {
            "x": -7,
            "y": 2,
            "z": 10,
            "elements": [
                "astralsorcery:blockblackmarble@0"
            ]
        },
        {
            "x": 2,
            "y": 0,
            "z": 17,
            "elements": [
                "astralsorcery:blockblackmarble@0"
            ]
        },
        {
            "x": -4,
            "y": 0,
            "z": 10,
            "elements": [
                "astralsorcery:blockblackmarble@0"
            ]
        },
        {
            "x": -9,
            "y": 1,
            "z": 1,
            "elements": [
                "astralsorcery:blockblackmarble@0"
            ]
        },
        {
            "x": -12,
            "y": 3,
            "z": 4,
            "elements": [
                "astralsorcery:blockmarble@2"
            ]
        },
        {
            "x": -5,
            "y": 2,
            "z": 5,
            "elements": [
                "astralsorcery:blockblackmarble@0"
            ]
        },
        {
            "x": -9,
            "y": 1,
            "z": 4,
            "elements": [
                "astralsorcery:blockblackmarble@0"
            ]
        },
        {
            "x": -3,
            "y": 10,
            "z": 7,
            "elements": [
                "divinerpg:arcanium_block@0"
            ]
        },
        {
            "x": -9,
            "y": 2,
            "z": -1,
            "elements": [
                "astralsorcery:blockmarble@1"
            ]
        },
        {
            "x": -3,
            "y": 3,
            "z": 11,
            "elements": [
                "astralsorcery:blockmarblestairs@0"
            ]
        },
        {
            "x": -1,
            "y": 0,
            "z": 0,
            "elements": [
                "astralsorcery:blockmarble@1"
            ]
        },
        {
            "x": -9,
            "y": 2,
            "z": 1,
            "elements": [
                "astralsorcery:blockblackmarble@0"
            ]
        },
        {
            "x": -4,
            "y": 2,
            "z": 0,
            "elements": [
                "astralsorcery:blockblackmarble@0"
            ]
        },
        {
            "x": -2,
            "y": 1,
            "z": 11,
            "elements": [
                "astralsorcery:blockblackmarble@0"
            ]
        },
        {
            "x": 9,
            "y": 2,
            "z": 3,
            "elements": [
                "astralsorcery:blockblackmarble@0"
            ]
        },
        {
            "x": 6,
            "y": 1,
            "z": 1,
            "elements": [
                "astralsorcery:blockblackmarble@0"
            ]
        },
        {
            "x": 6,
            "y": 0,
            "z": 1,
            "elements": [
                "astralsorcery:blockblackmarble@0"
            ]
        },
        {
            "x": 6,
            "y": 0,
            "z": -1,
            "elements": [
                "astralsorcery:blockmarble@1"
            ]
        },
        {
            "x": 0,
            "y": 0,
            "z": 5,
            "elements": [
                "astralsorcery:blockblackmarble@0"
            ]
        },
        {
            "x": -7,
            "y": 0,
            "z": 10,
            "elements": [
                "astralsorcery:blockblackmarble@0"
            ]
        },
        {
            "x": 0,
            "y": 2,
            "z": 5,
            "elements": [
                "astralsorcery:blockblackmarble@0"
            ]
        },
        {
            "x": -2,
            "y": 6,
            "z": 0,
            "elements": [
                "astralsorcery:blockcelestialcollectorcrystal"
            ]
        },
        {
            "x": 3,
            "y": 0,
            "z": 3,
            "elements": [
                "astralsorcery:blockblackmarble@0"
            ]
        },
        {
            "x": -4,
            "y": 2,
            "z": 10,
            "elements": [
                "astralsorcery:blockblackmarble@0"
            ]
        },
        {
            "x": 4,
            "y": 9,
            "z": 2,
            "elements": [
                "divinerpg:arcanium_block@0"
            ]
        },
        {
            "x": -9,
            "y": 0,
            "z": 1,
            "elements": [
                "astralsorcery:blockblackmarble@0"
            ]
        },
        {
            "x": -4,
            "y": 1,
            "z": 16,
            "elements": [
                "astralsorcery:blockblackmarble@0"
            ]
        },
        {
            "x": -9,
            "y": 0,
            "z": -1,
            "elements": [
                "astralsorcery:blockmarble@1"
            ]
        },
        {
            "x": -2,
            "y": 3,
            "z": 11,
            "elements": [
                "astralsorcery:blockblackmarble@0"
            ]
        },
        {
            "x": -9,
            "y": 3,
            "z": 1,
            "elements": [
                "astralsorcery:blockmarblestairs@2"
            ]
        },
        {
            "x": -7,
            "y": 0,
            "z": 5,
            "elements": [
                "astralsorcery:blockblackmarble@0"
            ]
        },
        {
            "x": -3,
            "y": 11,
            "z": 14,
            "elements": [
                "divinerpg:arcanium_block@0"
            ]
        },
        {
            "x": -5,
            "y": 2,
            "z": 0,
            "elements": [
                "astralsorcery:blockblackmarble@0"
            ]
        },
        {
            "x": -3,
            "y": 1,
            "z": 11,
            "elements": [
                "astralsorcery:blockblackmarble@0"
            ]
        },
        {
            "x": 4,
            "y": 0,
            "z": 0,
            "elements": [
                "astralsorcery:blockblackmarble@0"
            ]
        },
        {
            "x": 2,
            "y": 2,
            "z": 19,
            "elements": [
                "astralsorcery:blockblackmarble@0"
            ]
        },
        {
            "x": 6,
            "y": 2,
            "z": 6,
            "elements": [
                "astralsorcery:blockblackmarble@0"
            ]
        },
        {
            "x": -12,
            "y": 2,
            "z": 1,
            "elements": [
                "astralsorcery:blockmarble@1"
            ]
        },
        {
            "x": 2,
            "y": 1,
            "z": 12,
            "elements": [
                "astralsorcery:blockblackmarble@0"
            ]
        },
        {
            "x": 9,
            "y": 0,
            "z": -1,
            "elements": [
                "astralsorcery:blockmarble@1"
            ]
        },
        {
            "x": 2,
            "y": 10,
            "z": 17,
            "elements": [
                "divinerpg:arcanium_block@0"
            ]
        },
        {
            "x": 2,
            "y": 4,
            "z": 0,
            "elements": [
                "astralsorcery:blockmarble@2"
            ]
        },
        {
            "x": -3,
            "y": 3,
            "z": 4,
            "elements": [
                "astralsorcery:blockblackmarble@0"
            ]
        },
        {
            "x": 3,
            "y": 2,
            "z": 7,
            "elements": [
                "astralsorcery:blockblackmarble@0"
            ]
        },
        {
            "x": 3,
            "y": 4,
            "z": -1,
            "elements": [
                "astralsorcery:blockmarble@2"
            ]
        },
        {
            "x": 0,
            "y": 1,
            "z": 4,
            "elements": [
                "astralsorcery:blockblackmarble@0"
            ]
        },
        {
            "x": -3,
            "y": 10,
            "z": 6,
            "elements": [
                "divinerpg:arcanium_block@0"
            ]
        },
        {
            "x": -4,
            "y": 0,
            "z": 19,
            "elements": [
                "astralsorcery:blockmarble@1"
            ]
        },
        {
            "x": -7,
            "y": 2,
            "z": 5,
            "elements": [
                "astralsorcery:blockblackmarble@0"
            ]
        },
        {
            "x": -1,
            "y": 1,
            "z": 16,
            "elements": [
                "astralsorcery:blockblackmarble@0"
            ]
        },
        {
            "x": 2,
            "y": 0,
            "z": 12,
            "elements": [
                "astralsorcery:blockblackmarble@0"
            ]
        },
        {
            "x": -11,
            "y": 2,
            "z": 3,
            "elements": [
                "astralsorcery:blockblackmarble@0"
            ]
        },
        {
            "x": 2,
            "y": 1,
            "z": 19,
            "elements": [
                "astralsorcery:blockblackmarble@0"
            ]
        },
        {
            "x": -2,
            "y": 1,
            "z": 9,
            "elements": [
                "astralsorcery:blockblackmarble@0"
            ]
        },
        {
            "x": 3,
            "y": 5,
            "z": -1,
            "elements": [
                "astralsorcery:blockcelestialcollectorcrystal"
            ]
        },
        {
            "x": -8,
            "y": 0,
            "z": 3,
            "elements": [
                "astralsorcery:blockblackmarble@0"
            ]
        },
        {
            "x": 3,
            "y": 3,
            "z": 7,
            "elements": [
                "astralsorcery:blockblackmarble@0"
            ]
        },
        {
            "x": 7,
            "y": 1,
            "z": 9,
            "elements": [
                "astralsorcery:blockblackmarble@0"
            ]
        },
        {
            "x": 9,
            "y": 2,
            "z": -1,
            "elements": [
                "astralsorcery:blockmarble@1"
            ]
        },
        {
            "x": -11,
            "y": 0,
            "z": 3,
            "elements": [
                "astralsorcery:blockblackmarble@0"
            ]
        },
        {
            "x": 5,
            "y": 0,
            "z": 0,
            "elements": [
                "astralsorcery:blockblackmarble@0"
            ]
        },
        {
            "x": 9,
            "y": 2,
            "z": 8,
            "elements": [
                "astralsorcery:blockmarble@1"
            ]
        },
        {
            "x": -2,
            "y": 3,
            "z": 9,
            "elements": [
                "astralsorcery:blockblackmarble@0"
            ]
        },
        {
            "x": 2,
            "y": 2,
            "z": 0,
            "elements": [
                "astralsorcery:blockmarble@4"
            ]
        },
        {
            "x": 3,
            "y": 2,
            "z": 3,
            "elements": [
                "astralsorcery:blockblackmarble@0"
            ]
        },
        {
            "x": 3,
            "y": 1,
            "z": 4,
            "elements": [
                "astralsorcery:blockblackmarble@0"
            ]
        },
        {
            "x": 2,
            "y": 2,
            "z": 5,
            "elements": [
                "astralsorcery:blockblackmarble@0"
            ]
        },
        {
            "x": 2,
            "y": 0,
            "z": 5,
            "elements": [
                "astralsorcery:blockblackmarble@0"
            ]
        },
        {
            "x": 1,
            "y": 3,
            "z": 16,
            "elements": [
                "astralsorcery:blockblackmarble@0"
            ]
        },
        {
            "x": -6,
            "y": 3,
            "z": 4,
            "elements": [
                "astralsorcery:blockblackmarble@0"
            ]
        },
        {
            "x": 2,
            "y": 1,
            "z": 16,
            "elements": [
                "astralsorcery:blockblackmarble@0"
            ]
        },
        {
            "x": 2,
            "y": 3,
            "z": 12,
            "elements": [
                "astralsorcery:blockblackmarble@0"
            ]
        },
        {
            "x": 12,
            "y": 2,
            "z": 2,
            "elements": [
                "astralsorcery:blockmarble@1"
            ]
        },
        {
            "x": 12,
            "y": 0,
            "z": 2,
            "elements": [
                "modularmachinery:blockinputbus@0"
            ]
        },
        {
            "x": 9,
            "y": 10,
            "z": 2,
            "elements": [
                "divinerpg:arcanium_block@0"
            ]
        },
        {
            "x": 9,
            "y": 1,
            "z": 4,
            "elements": [
                "astralsorcery:blockblackmarble@0"
            ]
        },
        {
            "x": -8,
            "y": 2,
            "z": 3,
            "elements": [
                "astralsorcery:blockblackmarble@0"
            ]
        },
        {
            "x": -3,
            "y": 10,
            "z": 5,
            "elements": [
                "divinerpg:arcanium_block@0"
            ]
        },
        {
            "x": 6,
            "y": 11,
            "z": 8,
            "elements": [
                "divinerpg:arcanium_block@0"
            ]
        },
        {
            "x": 2,
            "y": 2,
            "z": 12,
            "elements": [
                "astralsorcery:blockblackmarble@0"
            ]
        },
        {
            "x": -2,
            "y": 0,
            "z": 0,
            "elements": [
                "astralsorcery:blockmarble@4"
            ]
        },
        {
            "x": 6,
            "y": 2,
            "z": 3,
            "elements": [
                "astralsorcery:blockblackmarble@0"
            ]
        },
        {
            "x": 6,
            "y": 1,
            "z": 7,
            "elements": [
                "astralsorcery:blockblackmarble@0"
            ]
        },
        {
            "x": 6,
            "y": 1,
            "z": 6,
            "elements": [
                "astralsorcery:blockblackmarble@0"
            ]
        },
        {
            "x": -1,
            "y": 0,
            "z": 22,
            "elements": [
                "modularmachinery:blockinputbus@0"
            ]
        },
        {
            "x": 1,
            "y": 3,
            "z": 9,
            "elements": [
                "astralsorcery:blockblackmarble@0"
            ]
        },
        {
            "x": 4,
            "y": 1,
            "z": 9,
            "elements": [
                "astralsorcery:blockblackmarble@0"
            ]
        },
        {
            "x": -2,
            "y": 0,
            "z": 15,
            "elements": [
                "astralsorcery:blockblackmarble@0"
            ]
        },
        {
            "x": 6,
            "y": 0,
            "z": 7,
            "elements": [
                "astralsorcery:blockblackmarble@0"
            ]
        },
        {
            "x": -5,
            "y": 1,
            "z": 11,
            "elements": [
                "astralsorcery:blockblackmarble@0"
            ]
        },
        {
            "x": 6,
            "y": 0,
            "z": 3,
            "elements": [
                "astralsorcery:blockblackmarble@0"
            ]
        },
        {
            "x": 5,
            "y": 2,
            "z": 0,
            "elements": [
                "astralsorcery:blockblackmarble@0"
            ]
        },
        {
            "x": 3,
            "y": 1,
            "z": -1,
            "elements": [
                "astralsorcery:blockmarble@2"
            ]
        },
        {
            "x": -1,
            "y": 0,
            "z": 5,
            "elements": [
                "astralsorcery:blockblackmarble@0"
            ]
        },
        {
            "x": -4,
            "y": 2,
            "z": 19,
            "elements": [
                "astralsorcery:blockmarble@1"
            ]
        },
        {
            "x": -6,
            "y": 2,
            "z": 1,
            "elements": [
                "astralsorcery:blockblackmarble@0"
            ]
        },
        {
            "x": -1,
            "y": 3,
            "z": 12,
            "elements": [
                "astralsorcery:blockblackmarble@0"
            ]
        },
        {
            "x": -3,
            "y": 2,
            "z": 10,
            "elements": [
                "astralsorcery:blockblackmarble@0"
            ]
        },
        {
            "x": -2,
            "y": 3,
            "z": 16,
            "elements": [
                "astralsorcery:blockmarblestairs@0"
            ]
        },
        {
            "x": 0,
            "y": 0,
            "z": 10,
            "elements": [
                "modularmachinery:blockinputbus@0"
            ]
        },
        {
            "x": -1,
            "y": 2,
            "z": 5,
            "elements": [
                "astralsorcery:blockblackmarble@0"
            ]
        },
        {
            "x": 1,
            "y": 1,
            "z": 16,
            "elements": [
                "astralsorcery:blockblackmarble@0"
            ]
        },
        {
            "x": -1,
            "y": 3,
            "z": 19,
            "elements": [
                "astralsorcery:blockmarblestairs@0"
            ]
        },
        {
            "x": 3,
            "y": 0,
            "z": 7,
            "elements": [
                "astralsorcery:blockblackmarble@0"
            ]
        },
        {
            "x": -5,
            "y": 0,
            "z": 0,
            "elements": [
                "astralsorcery:blockblackmarble@0"
            ]
        },
        {
            "x": -5,
            "y": 9,
            "z": 9,
            "elements": [
                "divinerpg:arcanium_block@0"
            ]
        },
        {
            "x": -1,
            "y": 2,
            "z": 12,
            "elements": [
                "astralsorcery:blockblackmarble@0"
            ]
        },
        {
            "x": -1,
            "y": 2,
            "z": 22,
            "elements": [
                "astralsorcery:blockmarble@1"
            ]
        },
        {
            "x": -12,
            "y": 0,
            "z": 1,
            "elements": [
                "modularmachinery:blockinputbus@0"
            ]
        },
        {
            "x": -9,
            "y": 2,
            "z": 3,
            "elements": [
                "astralsorcery:blockblackmarble@0"
            ]
        },
        {
            "x": 6,
            "y": 0,
            "z": 6,
            "elements": [
                "astralsorcery:blockblackmarble@0"
            ]
        },
        {
            "x": 5,
            "y": 2,
            "z": 17,
            "elements": [
                "astralsorcery:blockmarble@1"
            ]
        },
        {
            "x": -6,
            "y": 3,
            "z": 1,
            "elements": [
                "astralsorcery:blockmarblestairs@2"
            ]
        },
        {
            "x": 4,
            "y": 3,
            "z": 9,
            "elements": [
                "astralsorcery:blockmarblestairs@3"
            ]
        },
        {
            "x": 3,
            "y": 2,
            "z": 6,
            "elements": [
                "astralsorcery:blockblackmarble@0"
            ]
        },
        {
            "x": 0,
            "y": 3,
            "z": 4,
            "elements": [
                "astralsorcery:blockblackmarble@0"
            ]
        },
        {
            "x": -4,
            "y": 0,
            "z": 5,
            "elements": [
                "astralsorcery:blockblackmarble@0"
            ]
        },
        {
            "x": -6,
            "y": 0,
            "z": 1,
            "elements": [
                "astralsorcery:blockblackmarble@0"
            ]
        },
        {
            "x": -3,
            "y": 0,
            "z": 15,
            "elements": [
                "astralsorcery:blockblackmarble@0"
            ]
        },
        {
            "x": 1,
            "y": 1,
            "z": 9,
            "elements": [
                "astralsorcery:blockblackmarble@0"
            ]
        },
        {
            "x": -6,
            "y": 1,
            "z": 11,
            "elements": [
                "astralsorcery:blockblackmarble@0"
            ]
        },
        {
            "x": 3,
            "y": 2,
            "z": -1,
            "elements": [
                "astralsorcery:blockmarble@4"
            ]
        },
        {
            "x": 0,
            "y": 2,
            "z": 7,
            "elements": [
                "astralsorcery:blockblackmarble@0"
            ]
        },
        {
            "x": 0,
            "y": 12,
            "z": 3,
            "elements": [
                "divinerpg:arcanium_block@0"
            ]
        },
        {
            "x": -1,
            "y": 1,
            "z": 12,
            "elements": [
                "astralsorcery:blockblackmarble@0"
            ]
        },
        {
            "x": -1,
            "y": 2,
            "z": 19,
            "elements": [
                "astralsorcery:blockblackmarble@0"
            ]
        },
        {
            "x": 3,
            "y": 0,
            "z": -1,
            "elements": [
                "astralsorcery:blockmarble@4"
            ]
        },
        {
            "x": 2,
            "y": 6,
            "z": 0,
            "elements": [
                "astralsorcery:blockcelestialcollectorcrystal"
            ]
        },
        {
            "x": 2,
            "y": 0,
            "z": 19,
            "elements": [
                "astralsorcery:blockblackmarble@0"
            ]
        },
        {
            "x": -1,
            "y": 10,
            "z": 17,
            "elements": [
                "divinerpg:arcanium_block@0"
            ]
        },
        {
            "x": -1,
            "y": 3,
            "z": 16,
            "elements": [
                "astralsorcery:blockblackmarble@0"
            ]
        },
        {
            "x": -4,
            "y": 2,
            "z": 5,
            "elements": [
                "astralsorcery:blockblackmarble@0"
            ]
        },
        {
            "x": -6,
            "y": 1,
            "z": 1,
            "elements": [
                "astralsorcery:blockblackmarble@0"
            ]
        },
        {
            "x": -3,
            "y": 8,
            "z": 10,
            "elements": [
                "divinerpg:arcanium_block@0"
            ]
        },
        {
            "x": -6,
            "y": 1,
            "z": 4,
            "elements": [
                "astralsorcery:blockblackmarble@0"
            ]
        },
        {
            "x": -1,
            "y": 0,
            "z": 12,
            "elements": [
                "astralsorcery:blockblackmarble@0"
            ]
        },
        {
            "x": -3,
            "y": 0,
            "z": 10,
            "elements": [
                "astralsorcery:blockblackmarble@0"
            ]
        },
        {
            "x": 3,
            "y": 3,
            "z": 6,
            "elements": [
                "astralsorcery:blockblackmarble@0"
            ]
        },
        {
            "x": 3,
            "y": 1,
            "z": 7,
            "elements": [
                "astralsorcery:blockblackmarble@0"
            ]
        },
        {
            "x": -5,
            "y": 2,
            "z": 15,
            "elements": [
                "astralsorcery:blockmarble@1"
            ]
        },
        {
            "x": 3,
            "y": 3,
            "z": -1,
            "elements": [
                "astralsorcery:blockmarble@2"
            ]
        },
        {
            "x": -9,
            "y": 0,
            "z": 3,
            "elements": [
                "astralsorcery:blockblackmarble@0"
            ]
        },
        {
            "x": 0,
            "y": 3,
            "z": 7,
            "elements": [
                "astralsorcery:blockblackmarble@0"
            ]
        },
        {
            "x": -1,
            "y": 1,
            "z": 19,
            "elements": [
                "astralsorcery:blockblackmarble@0"
            ]
        },
        {
            "x": 0,
            "y": 2,
            "z": 10,
            "elements": [
                "astralsorcery:blockblackmarble@0"
            ]
        },
        {
            "x": 0,
            "y": 1,
            "z": 8,
            "elements": [
                "astralsorcery:blockblackmarble@0"
            ]
        },
        {
            "x": -8,
            "y": 10,
            "z": 3,
            "elements": [
                "divinerpg:arcanium_block@0"
            ]
        },
        {
            "x": 5,
            "y": 2,
            "z": 12,
            "elements": [
                "astralsorcery:blockblackmarble@0"
            ]
        },
        {
            "x": 8,
            "y": 0,
            "z": 0,
            "elements": [
                "astralsorcery:blockblackmarble@0"
            ]
        },
        {
            "x": -5,
            "y": 3,
            "z": 9,
            "elements": [
                "astralsorcery:blockmarblestairs@3"
            ]
        },
        {
            "x": 7,
            "y": 10,
            "z": 1,
            "elements": [
                "divinerpg:arcanium_block@0"
            ]
        },
        {
            "x": 5,
            "y": 2,
            "z": 5,
            "elements": [
                "astralsorcery:blockblackmarble@0"
            ]
        },
        {
            "x": -7,
            "y": 3,
            "z": 4,
            "elements": [
                "astralsorcery:blockblackmarble@0"
            ]
        },
        {
            "x": 7,
            "y": 2,
            "z": 0,
            "elements": [
                "astralsorcery:blockblackmarble@0"
            ]
        },
        {
            "x": -4,
            "y": 1,
            "z": 4,
            "elements": [
                "astralsorcery:blockblackmarble@0"
            ]
        },
        {
            "x": 5,
            "y": 0,
            "z": 5,
            "elements": [
                "astralsorcery:blockblackmarble@0"
            ]
        },
        {
            "x": 4,
            "y": 2,
            "z": 3,
            "elements": [
                "astralsorcery:blockblackmarble@0"
            ]
        },
        {
            "x": -3,
            "y": 11,
            "z": 13,
            "elements": [
                "divinerpg:arcanium_block@0"
            ]
        },
        {
            "x": -3,
            "y": 3,
            "z": 8,
            "elements": [
                "astralsorcery:blockblackmarble@0"
            ]
        },
        {
            "x": 4,
            "y": 0,
            "z": 3,
            "elements": [
                "astralsorcery:blockblackmarble@0"
            ]
        },
        {
            "x": 6,
            "y": 3,
            "z": 13,
            "elements": [
                "astralsorcery:blockmarble@2"
            ]
        },
        {
            "x": 3,
            "y": 0,
            "z": 8,
            "elements": [
                "astralsorcery:blockblackmarble@0"
            ]
        },
        {
            "x": 2,
            "y": 0,
            "z": 18,
            "elements": [
                "astralsorcery:blockblackmarble@0"
            ]
        },
        {
            "x": 3,
            "y": 2,
            "z": 10,
            "elements": [
                "astralsorcery:blockblackmarble@0"
            ]
        },
        {
            "x": -7,
            "y": 0,
            "z": 0,
            "elements": [
                "astralsorcery:blockblackmarble@0"
            ]
        },
        {
            "x": -8,
            "y": 2,
            "z": 0,
            "elements": [
                "astralsorcery:blockblackmarble@0"
            ]
        },
        {
            "x": -1,
            "y": 3,
            "z": 18,
            "elements": [
                "astralsorcery:blockmarblestairs@0"
            ]
        },
        {
            "x": 0,
            "y": 2,
            "z": 8,
            "elements": [
                "astralsorcery:blockblackmarble@0"
            ]
        },
        {
            "x": -6,
            "y": 1,
            "z": 9,
            "elements": [
                "astralsorcery:blockblackmarble@0"
            ]
        },
        {
            "x": -3,
            "y": 1,
            "z": 8,
            "elements": [
                "astralsorcery:blockblackmarble@0"
            ]
        },
        {
            "x": -2,
            "y": 3,
            "z": 4,
            "elements": [
                "astralsorcery:blockblackmarble@0"
            ]
        },
        {
            "x": -1,
            "y": 1,
            "z": 4,
            "elements": [
                "astralsorcery:blockblackmarble@0"
            ]
        },
        {
            "x": 6,
            "y": 2,
            "z": 5,
            "elements": [
                "astralsorcery:blockblackmarble@0"
            ]
        },
        {
            "x": 3,
            "y": 9,
            "z": 13,
            "elements": [
                "divinerpg:arcanium_block@0"
            ]
        },
        {
            "x": 0,
            "y": 3,
            "z": 8,
            "elements": [
                "astralsorcery:blockblackmarble@0"
            ]
        },
        {
            "x": -3,
            "y": 12,
            "z": 10,
            "elements": [
                "divinerpg:arcanium_block@0"
            ]
        },
        {
            "x": 5,
            "y": 1,
            "z": 12,
            "elements": [
                "astralsorcery:blockblackmarble@0"
            ]
        },
        {
            "x": -3,
            "y": 2,
            "z": 8,
            "elements": [
                "astralsorcery:blockblackmarble@0"
            ]
        },
        {
            "x": 6,
            "y": 0,
            "z": 5,
            "elements": [
                "astralsorcery:blockblackmarble@0"
            ]
        },
        {
            "x": 1,
            "y": 0,
            "z": 3,
            "elements": [
                "astralsorcery:blockblackmarble@0"
            ]
        },
        {
            "x": -1,
            "y": 0,
            "z": 18,
            "elements": [
                "astralsorcery:blockblackmarble@0"
            ]
        },
        {
            "x": -4,
            "y": 2,
            "z": 18,
            "elements": [
                "astralsorcery:blockmarble@1"
            ]
        },
        {
            "x": -2,
            "y": 1,
            "z": 16,
            "elements": [
                "astralsorcery:blockblackmarble@0"
            ]
        },
        {
            "x": 6,
            "y": 0,
            "z": 8,
            "elements": [
                "astralsorcery:blockblackmarble@0"
            ]
        },
        {
            "x": 5,
            "y": 0,
            "z": 12,
            "elements": [
                "astralsorcery:blockblackmarble@0"
            ]
        },
        {
            "x": -6,
            "y": 3,
            "z": 9,
            "elements": [
                "astralsorcery:blockmarblestairs@0"
            ]
        },
        {
            "x": 3,
            "y": 0,
            "z": 10,
            "elements": [
                "astralsorcery:blockblackmarble@0"
            ]
        },
        {
            "x": -5,
            "y": 1,
            "z": 9,
            "elements": [
                "astralsorcery:blockblackmarble@0"
            ]
        },
        {
            "x": 10,
            "y": 0,
            "z": 0,
            "elements": [
                "astralsorcery:blockblackmarble@0"
            ]
        },
        {
            "x": 9,
            "y": 0,
            "z": 6,
            "elements": [
                "astralsorcery:blockblackmarble@0"
            ]
        },
        {
            "x": 9,
            "y": 10,
            "z": 1,
            "elements": [
                "divinerpg:arcanium_block@0"
            ]
        },
        {
            "x": 6,
            "y": 0,
            "z": 13,
            "elements": [
                "astralsorcery:blockmarble@4"
            ]
        },
        {
            "x": -1,
            "y": 1,
            "z": 18,
            "elements": [
                "astralsorcery:blockblackmarble@0"
            ]
        },
        {
            "x": -3,
            "y": 3,
            "z": 9,
            "elements": [
                "astralsorcery:blockblackmarble@0"
            ]
        },
        {
            "x": 6,
            "y": 1,
            "z": 8,
            "elements": [
                "astralsorcery:blockblackmarble@0"
            ]
        },
        {
            "x": -2,
            "y": 1,
            "z": 4,
            "elements": [
                "astralsorcery:blockblackmarble@0"
            ]
        },
        {
            "x": 5,
            "y": 2,
            "z": 13,
            "elements": [
                "astralsorcery:blockmarble@1"
            ]
        },
        {
            "x": 3,
            "y": 2,
            "z": 5,
            "elements": [
                "astralsorcery:blockblackmarble@0"
            ]
        },
        {
            "x": 3,
            "y": 0,
            "z": 5,
            "elements": [
                "astralsorcery:blockblackmarble@0"
            ]
        },
        {
            "x": -5,
            "y": 3,
            "z": 4,
            "elements": [
                "astralsorcery:blockblackmarble@0"
            ]
        },
        {
            "x": -6,
            "y": 0,
            "z": 8,
            "elements": [
                "astralsorcery:blockblackmarble@0"
            ]
        },
        {
            "x": -3,
            "y": 0,
            "z": 20,
            "elements": [
                "astralsorcery:blockmarble@1"
            ]
        },
        {
            "x": 3,
            "y": 9,
            "z": 14,
            "elements": [
                "divinerpg:arcanium_block@0"
            ]
        },
        {
            "x": -6,
            "y": 9,
            "z": 8,
            "elements": [
                "divinerpg:arcanium_block@0"
            ]
        },
        {
            "x": -2,
            "y": 8,
            "z": 10,
            "elements": [
                "divinerpg:arcanium_block@0"
            ]
        },
        {
            "x": -1,
            "y": 2,
            "z": 18,
            "elements": [
                "astralsorcery:blockblackmarble@0"
            ]
        },
        {
            "x": 9,
            "y": 1,
            "z": 6,
            "elements": [
                "astralsorcery:blockblackmarble@0"
            ]
        },
        {
            "x": 2,
            "y": 10,
            "z": 5,
            "elements": [
                "divinerpg:arcanium_block@0"
            ]
        },
        {
            "x": -5,
            "y": 2,
            "z": 3,
            "elements": [
                "astralsorcery:blockblackmarble@0"
            ]
        },
        {
            "x": 6,
            "y": 2,
            "z": 8,
            "elements": [
                "astralsorcery:blockblackmarble@0"
            ]
        },
        {
            "x": 6,
            "y": 1,
            "z": 11,
            "elements": [
                "astralsorcery:blockblackmarble@0"
            ]
        },
        {
            "x": -10,
            "y": 2,
            "z": 0,
            "elements": [
                "astralsorcery:blockblackmarble@0"
            ]
        },
        {
            "x": 9,
            "y": 0,
            "z": 8,
            "elements": [
                "generalized_input_fluid"
            ]
        },
        {
            "x": 4,
            "y": 0,
            "z": 10,
            "elements": [
                "astralsorcery:blockblackmarble@0"
            ]
        },
        {
            "x": 1,
            "y": 2,
            "z": 10,
            "elements": [
                "astralsorcery:blockblackmarble@0"
            ]
        },
        {
            "x": -6,
            "y": 0,
            "z": 3,
            "elements": [
                "astralsorcery:blockblackmarble@0"
            ]
        },
        {
            "x": 5,
            "y": 0,
            "z": 13,
            "elements": [
                "astralsorcery:blockmarble@1"
            ]
        },
        {
            "x": 8,
            "y": 2,
            "z": 5,
            "elements": [
                "astralsorcery:blockblackmarble@0"
            ]
        },
        {
            "x": 7,
            "y": 0,
            "z": 0,
            "elements": [
                "astralsorcery:blockblackmarble@0"
            ]
        },
        {
            "x": -3,
            "y": 2,
            "z": 20,
            "elements": [
                "astralsorcery:blockmarble@1"
            ]
        },
        {
            "x": 6,
            "y": 3,
            "z": 6,
            "elements": [
                "astralsorcery:blockblackmarble@0"
            ]
        },
        {
            "x": 4,
            "y": 2,
            "z": 0,
            "elements": [
                "astralsorcery:blockblackmarble@0"
            ]
        },
        {
            "x": -3,
            "y": 1,
            "z": 4,
            "elements": [
                "astralsorcery:blockblackmarble@0"
            ]
        },
        {
            "x": 1,
            "y": 2,
            "z": 3,
            "elements": [
                "astralsorcery:blockblackmarble@0"
            ]
        },
        {
            "x": -4,
            "y": 3,
            "z": 4,
            "elements": [
                "astralsorcery:blockblackmarble@0"
            ]
        },
        {
            "x": 8,
            "y": 0,
            "z": 5,
            "elements": [
                "astralsorcery:blockblackmarble@0"
            ]
        },
        {
            "x": 6,
            "y": 2,
            "z": 13,
            "elements": [
                "astralsorcery:blockmarble@4"
            ]
        },
        {
            "x": 6,
            "y": 3,
            "z": 8,
            "elements": [
                "astralsorcery:blockmarblestairs@1"
            ]
        },
        {
            "x": 1,
            "y": 0,
            "z": 10,
            "elements": [
                "astralsorcery:blockmarble@1"
            ]
        },
        {
            "x": -1,
            "y": 10,
            "z": 19,
            "elements": [
                "divinerpg:arcanium_block@0"
            ]
        },
        {
            "x": -6,
            "y": 2,
            "z": 3,
            "elements": [
                "astralsorcery:blockblackmarble@0"
            ]
        },
        {
            "x": 0,
            "y": 0,
            "z": 8,
            "elements": [
                "modularmachinery:blockinputbus@0"
            ]
        },
        {
            "x": 6,
            "y": 1,
            "z": 13,
            "elements": [
                "astralsorcery:blockmarble@2"
            ]
        },
        {
            "x": -9,
            "y": 2,
            "z": 8,
            "elements": [
                "astralsorcery:blockmarble@1"
            ]
        },
        {
            "x": -5,
            "y": 0,
            "z": 3,
            "elements": [
                "astralsorcery:blockblackmarble@0"
            ]
        },
        {
            "x": -3,
            "y": 1,
            "z": 9,
            "elements": [
                "astralsorcery:blockblackmarble@0"
            ]
        },
        {
            "x": 4,
            "y": 2,
            "z": 10,
            "elements": [
                "astralsorcery:blockblackmarble@0"
            ]
        },
        {
            "x": -4,
            "y": 0,
            "z": 0,
            "elements": [
                "astralsorcery:blockblackmarble@0"
            ]
        },
        {
            "x": -1,
            "y": 2,
            "z": 15,
            "elements": [
                "astralsorcery:blockblackmarble@0"
            ]
        },
        {
            "x": -7,
            "y": 2,
            "z": 0,
            "elements": [
                "astralsorcery:blockblackmarble@0"
            ]
        },
        {
            "x": 3,
            "y": 3,
            "z": 13,
            "elements": [
                "astralsorcery:blockmarblestairs@1"
            ]
        },
        {
            "x": -9,
            "y": 2,
            "z": 2,
            "elements": [
                "astralsorcery:blockblackmarble@0"
            ]
        },
        {
            "x": -1,
            "y": 3,
            "z": 9,
            "elements": [
                "astralsorcery:blockblackmarble@0"
            ]
        },
        {
            "x": 9,
            "y": 1,
            "z": 1,
            "elements": [
                "astralsorcery:blockblackmarble@0"
            ]
        },
        {
            "x": -4,
            "y": 0,
            "z": 15,
            "elements": [
                "astralsorcery:blockblackmarble@0"
            ]
        },
        {
            "x": 3,
            "y": 0,
            "z": 20,
            "elements": [
                "astralsorcery:blockmarble@1"
            ]
        },
        {
            "x": -9,
            "y": 3,
            "z": 2,
            "elements": [
                "astralsorcery:blockmarblestairs@0"
            ]
        },
        {
            "x": -1,
            "y": 3,
            "z": 17,
            "elements": [
                "astralsorcery:blockmarblestairs@3"
            ]
        },
        {
            "x": -3,
            "y": 1,
            "z": 21,
            "elements": [
                "astralsorcery:blockmarble@2"
            ]
        },
        {
            "x": -1,
            "y": 2,
            "z": 17,
            "elements": [
                "astralsorcery:blockblackmarble@0"
            ]
        },
        {
            "x": -3,
            "y": 2,
            "z": 3,
            "elements": [
                "astralsorcery:blockblackmarble@0"
            ]
        },
        {
            "x": 9,
            "y": 2,
            "z": 6,
            "elements": [
                "astralsorcery:blockblackmarble@0"
            ]
        },
        {
            "x": 3,
            "y": 3,
            "z": 11,
            "elements": [
                "astralsorcery:blockmarblestairs@1"
            ]
        },
        {
            "x": 0,
            "y": 0,
            "z": 3,
            "elements": [
                "astralsorcery:blockblackmarble@0"
            ]
        },
        {
            "x": 9,
            "y": 0,
            "z": 1,
            "elements": [
                "astralsorcery:blockblackmarble@0"
            ]
        },
        {
            "x": -2,
            "y": 0,
            "z": 10,
            "elements": [
                "astralsorcery:blockblackmarble@0"
            ]
        },
        {
            "x": -4,
            "y": 2,
            "z": 15,
            "elements": [
                "astralsorcery:blockblackmarble@0"
            ]
        },
        {
            "x": 12,
            "y": 2,
            "z": 1,
            "elements": [
                "astralsorcery:blockmarble@1"
            ]
        },
        {
            "x": 6,
            "y": 11,
            "z": 7,
            "elements": [
                "divinerpg:arcanium_block@0"
            ]
        },
        {
            "x": 0,
            "y": 2,
            "z": 20,
            "elements": [
                "astralsorcery:blockblackmarble@0"
            ]
        },
        {
            "x": 0,
            "y": 1,
            "z": 11,
            "elements": [
                "astralsorcery:blockblackmarble@0"
            ]
        },
        {
            "x": -9,
            "y": 10,
            "z": 3,
            "elements": [
                "divinerpg:arcanium_block@0"
            ]
        },
        {
            "x": 0,
            "y": 0,
            "z": 20,
            "elements": [
                "astralsorcery:blockblackmarble@0"
            ]
        },
        {
            "x": 3,
            "y": 3,
            "z": 14,
            "elements": [
                "astralsorcery:blockmarblestairs@1"
            ]
        },
        {
            "x": -9,
            "y": 0,
            "z": 2,
            "elements": [
                "astralsorcery:blockblackmarble@0"
            ]
        },
        {
            "x": -6,
            "y": 0,
            "z": 5,
            "elements": [
                "astralsorcery:blockblackmarble@0"
            ]
        },
        {
            "x": -1,
            "y": 0,
            "z": 15,
            "elements": [
                "astralsorcery:blockblackmarble@0"
            ]
        },
        {
            "x": 2,
            "y": 3,
            "z": 4,
            "elements": [
                "astralsorcery:blockblackmarble@0"
            ]
        },
        {
            "x": -5,
            "y": 1,
            "z": 4,
            "elements": [
                "astralsorcery:blockblackmarble@0"
            ]
        },
        {
            "x": -9,
            "y": 0,
            "z": 8,
            "elements": [
                "generalized_input_fluid"
            ]
        },
        {
            "x": 9,
            "y": 3,
            "z": 1,
            "elements": [
                "astralsorcery:blockmarblestairs@2"
            ]
        },
        {
            "x": 12,
            "y": 0,
            "z": 1,
            "elements": [
                "modularmachinery:blockinputbus@0"
            ]
        },
        {
            "x": 10,
            "y": 2,
            "z": 0,
            "elements": [
                "astralsorcery:blockblackmarble@0"
            ]
        },
        {
            "x": 9,
            "y": 2,
            "z": 1,
            "elements": [
                "astralsorcery:blockblackmarble@0"
            ]
        },
        {
            "x": 3,
            "y": 2,
            "z": 20,
            "elements": [
                "astralsorcery:blockmarble@1"
            ]
        },
        {
            "x": 2,
            "y": 0,
            "z": 15,
            "elements": [
                "astralsorcery:blockblackmarble@0"
            ]
        },
        {
            "x": 0,
            "y": 2,
            "z": 3,
            "elements": [
                "astralsorcery:blockblackmarble@0"
            ]
        },
        {
            "x": -9,
            "y": 1,
            "z": 2,
            "elements": [
                "astralsorcery:blockblackmarble@0"
            ]
        },
        {
            "x": -10,
            "y": 0,
            "z": 0,
            "elements": [
                "astralsorcery:blockblackmarble@0"
            ]
        },
        {
            "x": -3,
            "y": 3,
            "z": 21,
            "elements": [
                "astralsorcery:blockmarble@2"
            ]
        },
        {
            "x": -8,
            "y": 1,
            "z": 4,
            "elements": [
                "astralsorcery:blockblackmarble@0"
            ]
        },
        {
            "x": -6,
            "y": 2,
            "z": 5,
            "elements": [
                "astralsorcery:blockblackmarble@0"
            ]
        },
        {
            "x": -1,
            "y": 1,
            "z": 9,
            "elements": [
                "astralsorcery:blockblackmarble@0"
            ]
        },
        {
            "x": 0,
            "y": 3,
            "z": 11,
            "elements": [
                "astralsorcery:blockblackmarble@0"
            ]
        },
        {
            "x": -3,
            "y": 0,
            "z": 3,
            "elements": [
                "astralsorcery:blockblackmarble@0"
            ]
        },
        {
            "x": -6,
            "y": 9,
            "z": 9,
            "elements": [
                "divinerpg:arcanium_block@0"
            ]
        },
        {
            "x": -1,
            "y": 10,
            "z": 18,
            "elements": [
                "divinerpg:arcanium_block@0"
            ]
        },
        {
            "x": -2,
            "y": 2,
            "z": 10,
            "elements": [
                "astralsorcery:blockblackmarble@0"
            ]
        },
        {
            "x": 3,
            "y": 1,
            "z": 11,
            "elements": [
                "astralsorcery:blockblackmarble@0"
            ]
        },
        {
            "x": -1,
            "y": 9,
            "z": 4,
            "elements": [
                "divinerpg:arcanium_block@0"
            ]
        },
        {
            "x": -1,
            "y": 3,
            "z": 4,
            "elements": [
                "astralsorcery:blockblackmarble@0"
            ]
        },
        {
            "x": -9,
            "y": 0,
            "z": 5,
            "elements": [
                "astralsorcery:blockblackmarble@0"
            ]
        },
        {
            "x": 6,
            "y": 5,
            "z": 13,
            "elements": [
                "astralsorcery:blockmarble@2"
            ]
        },
        {
            "x": 3,
            "y": 9,
            "z": 12,
            "elements": [
                "divinerpg:arcanium_block@0"
            ]
        },
        {
            "x": 3,
            "y": 3,
            "z": 8,
            "elements": [
                "astralsorcery:blockblackmarble@0"
            ]
        },
        {
            "x": -12,
            "y": 0,
            "z": 2,
            "elements": [
                "modularmachinery:blockinputbus@0"
            ]
        },
        {
            "x": -8,
            "y": 0,
            "z": 10,
            "elements": [
                "astralsorcery:blockmarble@1"
            ]
        },
        {
            "x": 3,
            "y": 0,
            "z": 14,
            "elements": [
                "astralsorcery:blockblackmarble@0"
            ]
        },
        {
            "x": 2,
            "y": 2,
            "z": 18,
            "elements": [
                "astralsorcery:blockblackmarble@0"
            ]
        },
        {
            "x": 2,
            "y": 1,
            "z": 4,
            "elements": [
                "astralsorcery:blockblackmarble@0"
            ]
        },
        {
            "x": 6,
            "y": 6,
            "z": 13,
            "elements": [
                "astralsorcery:blockcelestialcollectorcrystal"
            ]
        },
        {
            "x": -3,
            "y": 5,
            "z": 21,
            "elements": [
                "astralsorcery:blockmarble@2"
            ]
        },
        {
            "x": -1,
            "y": 2,
            "z": 3,
            "elements": [
                "astralsorcery:blockblackmarble@0"
            ]
        },
        {
            "x": 6,
            "y": 9,
            "z": 1,
            "elements": [
                "divinerpg:arcanium_block@0"
            ]
        },
        {
            "x": 1,
            "y": 3,
            "z": 11,
            "elements": [
                "astralsorcery:blockblackmarble@0"
            ]
        },
        {
            "x": -9,
            "y": 2,
            "z": 5,
            "elements": [
                "astralsorcery:blockblackmarble@0"
            ]
        },
        {
            "x": -2,
            "y": 0,
            "z": 3,
            "elements": [
                "astralsorcery:blockblackmarble@0"
            ]
        },
        {
            "x": 5,
            "y": 0,
            "z": 15,
            "elements": [
                "astralsorcery:blockmarble@1"
            ]
        },
        {
            "x": -4,
            "y": 1,
            "z": 9,
            "elements": [
                "astralsorcery:blockblackmarble@0"
            ]
        },
        {
            "x": 2,
            "y": 2,
            "z": 15,
            "elements": [
                "astralsorcery:blockblackmarble@0"
            ]
        },
        {
            "x": 2,
            "y": 1,
            "z": 18,
            "elements": [
                "astralsorcery:blockblackmarble@0"
            ]
        },
        {
            "x": -4,
            "y": 3,
            "z": 9,
            "elements": [
                "astralsorcery:blockmarblestairs@3"
            ]
        },
        {
            "x": -12,
            "y": 2,
            "z": 2,
            "elements": [
                "astralsorcery:blockmarble@1"
            ]
        },
        {
            "x": 6,
            "y": 10,
            "z": 1,
            "elements": [
                "divinerpg:arcanium_block@0"
            ]
        },
        {
            "x": -8,
            "y": 3,
            "z": 4,
            "elements": [
                "astralsorcery:blockmarblestairs@0"
            ]
        },
        {
            "x": 3,
            "y": 8,
            "z": 12,
            "elements": [
                "divinerpg:arcanium_block@0"
            ]
        },
        {
            "x": 3,
            "y": 2,
            "z": 14,
            "elements": [
                "astralsorcery:blockblackmarble@0"
            ]
        },
        {
            "x": 3,
            "y": 1,
            "z": 8,
            "elements": [
                "astralsorcery:blockblackmarble@0"
            ]
        },
        {
            "x": 1,
            "y": 1,
            "z": 4,
            "elements": [
                "astralsorcery:blockblackmarble@0"
            ]
        },
        {
            "x": -2,
            "y": 2,
            "z": 3,
            "elements": [
                "astralsorcery:blockblackmarble@0"
            ]
        },
        {
            "x": -1,
            "y": 0,
            "z": 3,
            "elements": [
                "astralsorcery:blockblackmarble@0"
            ]
        },
        {
            "x": 6,
            "y": 4,
            "z": 13,
            "elements": [
                "astralsorcery:blockmarble@2"
            ]
        },
        {
            "x": -8,
            "y": 2,
            "z": 10,
            "elements": [
                "astralsorcery:blockmarble@1"
            ]
        },
        {
            "x": 0,
            "y": 1,
            "z": 21,
            "elements": [
                "astralsorcery:blockblackmarble@0"
            ]
        },
        {
            "x": 4,
            "y": 1,
            "z": 4,
            "elements": [
                "astralsorcery:blockblackmarble@0"
            ]
        },
        {
            "x": 3,
            "y": 2,
            "z": 8,
            "elements": [
                "astralsorcery:blockblackmarble@0"
            ]
        },
        {
            "x": 3,
            "y": 1,
            "z": 14,
            "elements": [
                "astralsorcery:blockblackmarble@0"
            ]
        },
        {
            "x": 1,
            "y": 1,
            "z": 11,
            "elements": [
                "astralsorcery:blockblackmarble@0"
            ]
        },
        {
            "x": -7,
            "y": 1,
            "z": 9,
            "elements": [
                "astralsorcery:blockblackmarble@0"
            ]
        },
        {
            "x": 3,
            "y": 3,
            "z": 2,
            "elements": [
                "astralsorcery:blockmarblestairs@2"
            ]
        },
        {
            "x": 1,
            "y": 3,
            "z": 4,
            "elements": [
                "astralsorcery:blockblackmarble@0"
            ]
        },
        {
            "x": 0,
            "y": 2,
            "z": 16,
            "elements": [
                "astralsorcery:blockblackmarble@0"
            ]
        },
        {
            "x": 2,
            "y": 2,
            "z": 6,
            "elements": [
                "astralsorcery:blockblackmarble@0"
            ]
        },
        {
            "x": -8,
            "y": 2,
            "z": 1,
            "elements": [
                "astralsorcery:blockblackmarble@0"
            ]
        },
        {
            "x": 7,
            "y": 2,
            "z": 11,
            "elements": [
                "astralsorcery:blockmarble@1"
            ]
        },
        {
            "x": 2,
            "y": 2,
            "z": 21,
            "elements": [
                "astralsorcery:blockmarble@1"
            ]
        },
        {
            "x": -3,
            "y": 3,
            "z": 12,
            "elements": [
                "astralsorcery:blockmarblestairs@0"
            ]
        },
        {
            "x": 7,
            "y": 0,
            "z": 4,
            "elements": [
                "astralsorcery:blockblackmarble@0"
            ]
        },
        {
            "x": 4,
            "y": 0,
            "z": 11,
            "elements": [
                "astralsorcery:blockblackmarble@0"
            ]
        },
        {
            "x": 3,
            "y": 0,
            "z": 16,
            "elements": [
                "astralsorcery:blockblackmarble@0"
            ]
        },
        {
            "x": -8,
            "y": 0,
            "z": 8,
            "elements": [
                "astralsorcery:blockblackmarble@0"
            ]
        },
        {
            "x": 3,
            "y": 3,
            "z": 9,
            "elements": [
                "astralsorcery:blockblackmarble@0"
            ]
        },
        {
            "x": 0,
            "y": 3,
            "z": 16,
            "elements": [
                "astralsorcery:blockblackmarble@0"
            ]
        },
        {
            "x": -7,
            "y": 1,
            "z": 7,
            "elements": [
                "astralsorcery:blockblackmarble@0"
            ]
        },
        {
            "x": 4,
            "y": 2,
            "z": 4,
            "elements": [
                "astralsorcery:blockblackmarble@0"
            ]
        },
        {
            "x": 3,
            "y": 1,
            "z": 16,
            "elements": [
                "astralsorcery:blockblackmarble@0"
            ]
        },
        {
            "x": -6,
            "y": 1,
            "z": 2,
            "elements": [
                "astralsorcery:blockblackmarble@0"
            ]
        },
        {
            "x": -7,
            "y": 10,
            "z": 6,
            "elements": [
                "divinerpg:arcanium_block@0"
            ]
        },
        {
            "x": -8,
            "y": 2,
            "z": 8,
            "elements": [
                "astralsorcery:blockblackmarble@0"
            ]
        },
        {
            "x": -4,
            "y": 12,
            "z": 8,
            "elements": [
                "divinerpg:arcanium_block@0"
            ]
        },
        {
            "x": 4,
            "y": 1,
            "z": 11,
            "elements": [
                "astralsorcery:blockblackmarble@0"
            ]
        },
        {
            "x": 8,
            "y": 1,
            "z": 7,
            "elements": [
                "astralsorcery:blockblackmarble@0"
            ]
        },
        {
            "x": -1,
            "y": 3,
            "z": 7,
            "elements": [
                "astralsorcery:blockblackmarble@0"
            ]
        },
        {
            "x": 8,
            "y": 0,
            "z": 6,
            "elements": [
                "astralsorcery:blockblackmarble@0"
            ]
        },
        {
            "x": 7,
            "y": 1,
            "z": 4,
            "elements": [
                "astralsorcery:blockblackmarble@0"
            ]
        },
        {
            "x": 2,
            "y": 1,
            "z": 14,
            "elements": [
                "astralsorcery:blockblackmarble@0"
            ]
        },
        {
            "x": -2,
            "y": 1,
            "z": 19,
            "elements": [
                "astralsorcery:blockblackmarble@0"
            ]
        },
        {
            "x": -1,
            "y": 3,
            "z": 14,
            "elements": [
                "astralsorcery:blockblackmarble@0"
            ]
        },
        {
            "x": 5,
            "y": 2,
            "z": 6,
            "elements": [
                "astralsorcery:blockblackmarble@0"
            ]
        },
        {
            "x": 3,
            "y": 1,
            "z": 9,
            "elements": [
                "astralsorcery:blockblackmarble@0"
            ]
        },
        {
            "x": 2,
            "y": 0,
            "z": 21,
            "elements": [
                "astralsorcery:blockmarble@1"
            ]
        },
        {
            "x": -11,
            "y": 2,
            "z": 1,
            "elements": [
                "astralsorcery:blockblackmarble@0"
            ]
        },
        {
            "x": -3,
            "y": 2,
            "z": 16,
            "elements": [
                "astralsorcery:blockblackmarble@0"
            ]
        },
        {
            "x": -3,
            "y": 1,
            "z": 12,
            "elements": [
                "astralsorcery:blockblackmarble@0"
            ]
        },
        {
            "x": -8,
            "y": 0,
            "z": 1,
            "elements": [
                "astralsorcery:blockblackmarble@0"
            ]
        },
        {
            "x": 7,
            "y": 0,
            "z": 11,
            "elements": [
                "astralsorcery:blockmarble@1"
            ]
        },
        {
            "x": 4,
            "y": 2,
            "z": 11,
            "elements": [
                "astralsorcery:blockblackmarble@0"
            ]
        },
        {
            "x": 3,
            "y": 1,
            "z": 2,
            "elements": [
                "astralsorcery:blockblackmarble@0"
            ]
        },
        {
            "x": -6,
            "y": 3,
            "z": 2,
            "elements": [
                "astralsorcery:blockblackmarble@0"
            ]
        },
        {
            "x": -5,
            "y": 0,
            "z": 8,
            "elements": [
                "astralsorcery:blockblackmarble@0"
            ]
        },
        {
            "x": 3,
            "y": 2,
            "z": 9,
            "elements": [
                "astralsorcery:blockblackmarble@0"
            ]
        },
        {
            "x": -2,
            "y": 0,
            "z": 8,
            "elements": [
                "astralsorcery:blockblackmarble@0"
            ]
        },
        {
            "x": 7,
            "y": 2,
            "z": 4,
            "elements": [
                "astralsorcery:blockblackmarble@0"
            ]
        },
        {
            "x": -3,
            "y": 11,
            "z": 2,
            "elements": [
                "divinerpg:arcanium_block@0"
            ]
        },
        {
            "x": 8,
            "y": 2,
            "z": 6,
            "elements": [
                "astralsorcery:blockblackmarble@0"
            ]
        },
        {
            "x": -11,
            "y": 0,
            "z": 1,
            "elements": [
                "astralsorcery:blockblackmarble@0"
            ]
        },
        {
            "x": 4,
            "y": 0,
            "z": 4,
            "elements": [
                "astralsorcery:blockblackmarble@0"
            ]
        },
        {
            "x": -1,
            "y": 0,
            "z": 21,
            "elements": [
                "astralsorcery:blockblackmarble@0"
            ]
        },
        {
            "x": -10,
            "y": 2,
            "z": 1,
            "elements": [
                "astralsorcery:blockblackmarble@0"
            ]
        },
        {
            "x": 1,
            "y": 11,
            "z": 11,
            "elements": [
                "divinerpg:arcanium_block@0"
            ]
        },
        {
            "x": -3,
            "y": 0,
            "z": 16,
            "elements": [
                "astralsorcery:blockblackmarble@0"
            ]
        },
        {
            "x": -3,
            "y": 2,
            "z": 13,
            "elements": [
                "astralsorcery:blockblackmarble@0"
            ]
        },
        {
            "x": -1,
            "y": 1,
            "z": 7,
            "elements": [
                "astralsorcery:blockblackmarble@0"
            ]
        },
        {
            "x": 7,
            "y": 0,
            "z": 1,
            "elements": [
                "astralsorcery:blockblackmarble@0"
            ]
        },
        {
            "x": 3,
            "y": 0,
            "z": 9,
            "elements": [
                "astralsorcery:blockblackmarble@0"
            ]
        },
        {
            "x": 0,
            "y": 1,
            "z": 12,
            "elements": [
                "astralsorcery:blockblackmarble@0"
            ]
        },
        {
            "x": -3,
            "y": 3,
            "z": 2,
            "elements": [
                "astralsorcery:blockmarblestairs@2"
            ]
        },
        {
            "x": 0,
            "y": 1,
            "z": 2,
            "elements": [
                "astralsorcery:blockblackmarble@0"
            ]
        },
        {
            "x": -2,
            "y": 2,
            "z": 8,
            "elements": [
                "astralsorcery:blockblackmarble@0"
            ]
        },
        {
            "x": 3,
            "y": 3,
            "z": 12,
            "elements": [
                "astralsorcery:blockmarblestairs@1"
            ]
        },
        {
            "x": 2,
            "y": 1,
            "z": 7,
            "elements": [
                "astralsorcery:blockblackmarble@0"
            ]
        },
        {
            "x": 1,
            "y": 10,
            "z": 11,
            "elements": [
                "divinerpg:arcanium_block@0"
            ]
        },
        {
            "x": 1,
            "y": 0,
            "z": 8,
            "elements": [
                "astralsorcery:blockmarble@1"
            ]
        },
        {
            "x": -3,
            "y": 1,
            "z": 16,
            "elements": [
                "astralsorcery:blockblackmarble@0"
            ]
        },
        {
            "x": -1,
            "y": 1,
            "z": 21,
            "elements": [
                "astralsorcery:blockblackmarble@0"
            ]
        },
        {
            "x": 0,
            "y": 2,
            "z": 9,
            "elements": [
                "astralsorcery:blockblackmarble@0"
            ]
        },
        {
            "x": 0,
            "y": 1,
            "z": 19,
            "elements": [
                "astralsorcery:blockblackmarble@0"
            ]
        },
        {
            "x": 0,
            "y": 1,
            "z": 9,
            "elements": [
                "astralsorcery:blockblackmarble@0"
            ]
        },
        {
            "x": 7,
            "y": 2,
            "z": 10,
            "elements": [
                "astralsorcery:blockblackmarble@0"
            ]
        },
        {
            "x": 0,
            "y": 3,
            "z": 9,
            "elements": [
                "astralsorcery:blockblackmarble@0"
            ]
        },
        {
            "x": 3,
            "y": 12,
            "z": 10,
            "elements": [
                "divinerpg:arcanium_block@0"
            ]
        },
        {
            "x": -4,
            "y": 1,
            "z": 7,
            "elements": [
                "astralsorcery:blockblackmarble@0"
            ]
        },
        {
            "x": -7,
            "y": 3,
            "z": 7,
            "elements": [
                "astralsorcery:blockmarblestairs@0"
            ]
        },
        {
            "x": -1,
            "y": 1,
            "z": 17,
            "elements": [
                "astralsorcery:blockblackmarble@0"
            ]
        },
        {
            "x": 4,
            "y": 3,
            "z": 4,
            "elements": [
                "astralsorcery:blockblackmarble@0"
            ]
        },
        {
            "x": -1,
            "y": 2,
            "z": 21,
            "elements": [
                "astralsorcery:blockblackmarble@0"
            ]
        },
        {
            "x": 2,
            "y": 0,
            "z": 6,
            "elements": [
                "astralsorcery:blockblackmarble@0"
            ]
        },
        {
            "x": 0,
            "y": 3,
            "z": 12,
            "elements": [
                "astralsorcery:blockblackmarble@0"
            ]
        },
        {
            "x": -3,
            "y": 1,
            "z": 2,
            "elements": [
                "astralsorcery:blockblackmarble@0"
            ]
        },
        {
            "x": -1,
            "y": 2,
            "z": 6,
            "elements": [
                "astralsorcery:blockblackmarble@0"
            ]
        },
        {
            "x": 3,
            "y": 1,
            "z": 12,
            "elements": [
                "astralsorcery:blockblackmarble@0"
            ]
        },
        {
            "x": 7,
            "y": 2,
            "z": 1,
            "elements": [
                "astralsorcery:blockblackmarble@0"
            ]
        },
        {
            "x": 7,
            "y": 10,
            "z": 5,
            "elements": [
                "divinerpg:arcanium_block@0"
            ]
        },
        {
            "x": 6,
            "y": 0,
            "z": 9,
            "elements": [
                "astralsorcery:blockblackmarble@0"
            ]
        },
        {
            "x": 0,
            "y": 3,
            "z": 19,
            "elements": [
                "astralsorcery:blockmarblestairs@3"
            ]
        },
        {
            "x": -4,
            "y": 3,
            "z": 7,
            "elements": [
                "astralsorcery:blockblackmarble@0"
            ]
        },
        {
            "x": -1,
            "y": 1,
            "z": 14,
            "elements": [
                "astralsorcery:blockblackmarble@0"
            ]
        },
        {
            "x": -3,
            "y": 0,
            "z": 13,
            "elements": [
                "astralsorcery:blockblackmarble@0"
            ]
        },
        {
            "x": 3,
            "y": 2,
            "z": 16,
            "elements": [
                "astralsorcery:blockblackmarble@0"
            ]
        },
        {
            "x": -1,
            "y": 2,
            "z": 8,
            "elements": [
                "astralsorcery:blockblackmarble@0"
            ]
        },
        {
            "x": 2,
            "y": 3,
            "z": 14,
            "elements": [
                "astralsorcery:blockblackmarble@0"
            ]
        },
        {
            "x": 3,
            "y": 2,
            "z": 13,
            "elements": [
                "astralsorcery:blockblackmarble@0"
            ]
        },
        {
            "x": 6,
            "y": 2,
            "z": 10,
            "elements": [
                "astralsorcery:blockblackmarble@0"
            ]
        },
        {
            "x": -1,
            "y": 3,
            "z": 2,
            "elements": [
                "astralsorcery:blockmarblestairs@2"
            ]
        },
        {
            "x": 6,
            "y": 1,
            "z": 10,
            "elements": [
                "astralsorcery:blockblackmarble@0"
            ]
        },
        {
            "x": 1,
            "y": 12,
            "z": 3,
            "elements": [
                "divinerpg:arcanium_block@0"
            ]
        },
        {
            "x": -2,
            "y": 1,
            "z": 2,
            "elements": [
                "astralsorcery:blockblackmarble@0"
            ]
        },
        {
            "x": 11,
            "y": 2,
            "z": 0,
            "elements": [
                "astralsorcery:blockmarble@1"
            ]
        },
        {
            "x": 1,
            "y": 0,
            "z": 1,
            "elements": [
                "astralsorcery:blockblackmarble@0"
            ]
        },
        {
            "x": -4,
            "y": 2,
            "z": 8,
            "elements": [
                "astralsorcery:blockblackmarble@0"
            ]
        },
        {
            "x": -3,
            "y": 2,
            "z": 18,
            "elements": [
                "astralsorcery:blockblackmarble@0"
            ]
        },
        {
            "x": -9,
            "y": 0,
            "z": 6,
            "elements": [
                "astralsorcery:blockblackmarble@0"
            ]
        },
        {
            "x": -1,
            "y": 0,
            "z": 8,
            "elements": [
                "astralsorcery:blockmarble@1"
            ]
        },
        {
            "x": 4,
            "y": 8,
            "z": 10,
            "elements": [
                "divinerpg:arcanium_block@0"
            ]
        },
        {
            "x": -11,
            "y": 0,
            "z": 0,
            "elements": [
                "astralsorcery:blockmarble@1"
            ]
        },
        {
            "x": -10,
            "y": 2,
            "z": 6,
            "elements": [
                "astralsorcery:blockmarble@1"
            ]
        },
        {
            "x": 4,
            "y": 2,
            "z": 1,
            "elements": [
                "astralsorcery:blockblackmarble@0"
            ]
        },
        {
            "x": 3,
            "y": 6,
            "z": 21,
            "elements": [
                "astralsorcery:blockcelestialcollectorcrystal"
            ]
        },
        {
            "x": 0,
            "y": 0,
            "z": 13,
            "elements": [
                "astralsorcery:blockblackmarble@0"
            ]
        },
        {
            "x": -8,
            "y": 10,
            "z": 1,
            "elements": [
                "divinerpg:arcanium_block@0"
            ]
        },
        {
            "x": 6,
            "y": 0,
            "z": 10,
            "elements": [
                "astralsorcery:blockblackmarble@0"
            ]
        },
        {
            "x": 0,
            "y": 2,
            "z": 13,
            "elements": [
                "astralsorcery:blockblackmarble@0"
            ]
        },
        {
            "x": 3,
            "y": 0,
            "z": 13,
            "elements": [
                "astralsorcery:blockblackmarble@0"
            ]
        },
        {
            "x": 4,
            "y": 0,
            "z": 1,
            "elements": [
                "astralsorcery:blockblackmarble@0"
            ]
        },
        {
            "x": 1,
            "y": 11,
            "z": 4,
            "elements": [
                "divinerpg:arcanium_block@0"
            ]
        },
        {
            "x": -3,
            "y": 11,
            "z": 12,
            "elements": [
                "divinerpg:arcanium_block@0"
            ]
        },
        {
            "x": 3,
            "y": 5,
            "z": 21,
            "elements": [
                "astralsorcery:blockmarble@2"
            ]
        },
        {
            "x": 1,
            "y": 2,
            "z": 1,
            "elements": [
                "astralsorcery:blockblackmarble@0"
            ]
        },
        {
            "x": -2,
            "y": 3,
            "z": 2,
            "elements": [
                "astralsorcery:blockmarblestairs@2"
            ]
        },
        {
            "x": 0,
            "y": 0,
            "z": 9,
            "elements": [
                "generalized_output_item"
            ]
        },
        {
            "x": 7,
            "y": 1,
            "z": 10,
            "elements": [
                "astralsorcery:blockblackmarble@0"
            ]
        },
        {
            "x": -9,
            "y": 2,
            "z": 9,
            "elements": [
                "astralsorcery:blockmarble@1"
            ]
        },
        {
            "x": -1,
            "y": 1,
            "z": 2,
            "elements": [
                "astralsorcery:blockblackmarble@0"
            ]
        },
        {
            "x": 1,
            "y": 12,
            "z": 4,
            "elements": [
                "divinerpg:arcanium_block@0"
            ]
        },
        {
            "x": -7,
            "y": 2,
            "z": 8,
            "elements": [
                "astralsorcery:blockblackmarble@0"
            ]
        },
        {
            "x": 3,
            "y": 8,
            "z": 10,
            "elements": [
                "divinerpg:arcanium_block@0"
            ]
        },
        {
            "x": 7,
            "y": 0,
            "z": 10,
            "elements": [
                "astralsorcery:blockblackmarble@0"
            ]
        },
        {
            "x": 5,
            "y": 1,
            "z": 7,
            "elements": [
                "astralsorcery:blockblackmarble@0"
            ]
        },
        {
            "x": 3,
            "y": 4,
            "z": 21,
            "elements": [
                "astralsorcery:blockmarble@2"
            ]
        },
        {
            "x": 2,
            "y": 3,
            "z": 7,
            "elements": [
                "astralsorcery:blockblackmarble@0"
            ]
        },
        {
            "x": 5,
            "y": 0,
            "z": 6,
            "elements": [
                "astralsorcery:blockblackmarble@0"
            ]
        },
        {
            "x": 10,
            "y": 1,
            "z": 4,
            "elements": [
                "astralsorcery:blockblackmarble@0"
            ]
        },
        {
            "x": 2,
            "y": 0,
            "z": 13,
            "elements": [
                "astralsorcery:blockblackmarble@0"
            ]
        },
        {
            "x": 4,
            "y": 12,
            "z": 10,
            "elements": [
                "divinerpg:arcanium_block@0"
            ]
        },
        {
            "x": -5,
            "y": 0,
            "z": 1,
            "elements": [
                "astralsorcery:blockblackmarble@0"
            ]
        },
        {
            "x": -9,
            "y": 0,
            "z": 9,
            "elements": [
                "astralsorcery:blockmarble@1"
            ]
        },
        {
            "x": 3,
            "y": 0,
            "z": 21,
            "elements": [
                "astralsorcery:blockmarble@4"
            ]
        },
        {
            "x": 1,
            "y": 3,
            "z": 2,
            "elements": [
                "astralsorcery:blockmarblestairs@2"
            ]
        },
        {
            "x": 10,
            "y": 2,
            "z": 4,
            "elements": [
                "astralsorcery:blockblackmarble@0"
            ]
        },
        {
            "x": 10,
            "y": 2,
            "z": 1,
            "elements": [
                "astralsorcery:blockblackmarble@0"
            ]
        },
        {
            "x": 5,
            "y": 3,
            "z": 7,
            "elements": [
                "astralsorcery:blockblackmarble@0"
            ]
        },
        {
            "x": -3,
            "y": 0,
            "z": 8,
            "elements": [
                "astralsorcery:blockblackmarble@0"
            ]
        },
        {
            "x": -4,
            "y": 1,
            "z": 2,
            "elements": [
                "astralsorcery:blockblackmarble@0"
            ]
        },
        {
            "x": -6,
            "y": 2,
            "z": 8,
            "elements": [
                "astralsorcery:blockblackmarble@0"
            ]
        },
        {
            "x": 7,
            "y": 3,
            "z": 4,
            "elements": [
                "astralsorcery:blockblackmarble@0"
            ]
        },
        {
            "x": 2,
            "y": 2,
            "z": 20,
            "elements": [
                "astralsorcery:blockblackmarble@0"
            ]
        },
        {
            "x": -4,
            "y": 0,
            "z": 18,
            "elements": [
                "astralsorcery:blockmarble@1"
            ]
        },
        {
            "x": 3,
            "y": 1,
            "z": 21,
            "elements": [
                "astralsorcery:blockmarble@2"
            ]
        },
        {
            "x": -2,
            "y": 9,
            "z": 4,
            "elements": [
                "divinerpg:arcanium_block@0"
            ]
        },
        {
            "x": 1,
            "y": 8,
            "z": 3,
            "elements": [
                "divinerpg:arcanium_block@0"
            ]
        },
        {
            "x": -6,
            "y": 0,
            "z": 9,
            "elements": [
                "astralsorcery:blockblackmarble@0"
            ]
        },
        {
            "x": 2,
            "y": 2,
            "z": 13,
            "elements": [
                "astralsorcery:blockblackmarble@0"
            ]
        },
        {
            "x": 2,
            "y": 0,
            "z": 20,
            "elements": [
                "astralsorcery:blockblackmarble@0"
            ]
        },
        {
            "x": 11,
            "y": 0,
            "z": 0,
            "elements": [
                "astralsorcery:blockmarble@1"
            ]
        },
        {
            "x": 3,
            "y": 2,
            "z": 21,
            "elements": [
                "astralsorcery:blockmarble@4"
            ]
        },
        {
            "x": -4,
            "y": 3,
            "z": 2,
            "elements": [
                "astralsorcery:blockmarblestairs@1"
            ]
        },
        {
            "x": 0,
            "y": 0,
            "z": 16,
            "elements": [
                "astralsorcery:blockblackmarble@0"
            ]
        },
        {
            "x": 1,
            "y": 1,
            "z": 2,
            "elements": [
                "astralsorcery:blockblackmarble@0"
            ]
        },
        {
            "x": -4,
            "y": 11,
            "z": 7,
            "elements": [
                "divinerpg:arcanium_block@0"
            ]
        },
        {
            "x": 10,
            "y": 0,
            "z": 4,
            "elements": [
                "astralsorcery:blockblackmarble@0"
            ]
        },
        {
            "x": -5,
            "y": 2,
            "z": 1,
            "elements": [
                "astralsorcery:blockblackmarble@0"
            ]
        },
        {
            "x": 8,
            "y": 2,
            "z": 0,
            "elements": [
                "astralsorcery:blockblackmarble@0"
            ]
        },
        {
            "x": 10,
            "y": 0,
            "z": 1,
            "elements": [
                "astralsorcery:blockblackmarble@0"
            ]
        },
        {
            "x": 3,
            "y": 3,
            "z": 21,
            "elements": [
                "astralsorcery:blockmarble@2"
            ]
        },
        {
            "x": -4,
            "y": 0,
            "z": 8,
            "elements": [
                "astralsorcery:blockblackmarble@0"
            ]
        },
        {
            "x": -10,
            "y": 0,
            "z": 6,
            "elements": [
                "astralsorcery:blockmarble@1"
            ]
        },
        {
            "x": 2,
            "y": 1,
            "z": 20,
            "elements": [
                "astralsorcery:blockblackmarble@0"
            ]
        },
        {
            "x": -5,
            "y": 2,
            "z": 8,
            "elements": [
                "astralsorcery:blockblackmarble@0"
            ]
        },
        {
            "x": 0,
            "y": 1,
            "z": 16,
            "elements": [
                "astralsorcery:blockblackmarble@0"
            ]
        },
        {
            "x": 3,
            "y": 3,
            "z": 10,
            "elements": [
                "astralsorcery:blockmarblestairs@3"
            ]
        },
        {
            "x": 8,
            "y": 1,
            "z": 0,
            "elements": [
                "astralsorcery:blockblackmarble@0"
            ]
        },
        {
            "x": -8,
            "y": 0,
            "z": 0,
            "elements": [
                "astralsorcery:blockblackmarble@0"
            ]
        },
        {
            "x": -11,
            "y": 2,
            "z": 0,
            "elements": [
                "astralsorcery:blockmarble@1"
            ]
        },
        {
            "x": -3,
            "y": 0,
            "z": 18,
            "elements": [
                "astralsorcery:blockblackmarble@0"
            ]
        },
        {
            "x": 4,
            "y": 3,
            "z": 3,
            "elements": [
                "astralsorcery:blockblackmarble@0"
            ]
        },
        {
            "x": 7,
            "y": 0,
            "z": 3,
            "elements": [
                "astralsorcery:blockblackmarble@0"
            ]
        },
        {
            "x": 0,
            "y": 3,
            "z": 15,
            "elements": [
                "astralsorcery:blockblackmarble@0"
            ]
        },
        {
            "x": -12,
            "y": 0,
            "z": 3,
            "elements": [
                "modularmachinery:blockinputbus@0"
            ]
        },
        {
            "x": -1,
            "y": 0,
            "z": 20,
            "elements": [
                "astralsorcery:blockblackmarble@0"
            ]
        },
        {
            "x": 1,
            "y": 1,
            "z": 7,
            "elements": [
                "astralsorcery:blockblackmarble@0"
            ]
        },
        {
            "x": -3,
            "y": 0,
            "z": 1,
            "elements": [
                "astralsorcery:blockblackmarble@0"
            ]
        },
        {
            "x": -2,
            "y": 1,
            "z": 12,
            "elements": [
                "astralsorcery:blockblackmarble@0"
            ]
        },
        {
            "x": -3,
            "y": 3,
            "z": -1,
            "elements": [
                "astralsorcery:blockmarble@2"
            ]
        },
        {
            "x": -1,
            "y": 2,
            "z": 13,
            "elements": [
                "astralsorcery:blockblackmarble@0"
            ]
        },
        {
            "x": 0,
            "y": 0,
            "z": 15,
            "elements": [
                "astralsorcery:blockblackmarble@0"
            ]
        },
        {
            "x": 6,
            "y": 11,
            "z": 9,
            "elements": [
                "divinerpg:arcanium_block@0"
            ]
        },
        {
            "x": -5,
            "y": 3,
            "z": 2,
            "elements": [
                "astralsorcery:blockblackmarble@0"
            ]
        },
        {
            "x": -6,
            "y": 2,
            "z": 6,
            "elements": [
                "astralsorcery:blockblackmarble@0"
            ]
        },
        {
            "x": 0,
            "y": 2,
            "z": 1,
            "elements": [
                "astralsorcery:blockblackmarble@0"
            ]
        },
        {
            "x": 3,
            "y": 1,
            "z": 15,
            "elements": [
                "astralsorcery:blockblackmarble@0"
            ]
        },
        {
            "x": -8,
            "y": 5,
            "z": 2,
            "elements": [
                "astralsorcery:blockmarble@2"
            ]
        },
        {
            "x": 3,
            "y": 0,
            "z": 6,
            "elements": [
                "astralsorcery:blockblackmarble@0"
            ]
        },
        {
            "x": -11,
            "y": 1,
            "z": 5,
            "elements": [
                "astralsorcery:blockmarble@2"
            ]
        },
        {
            "x": -4,
            "y": 0,
            "z": 13,
            "elements": [
                "astralsorcery:blockblackmarble@0"
            ]
        },
        {
            "x": -1,
            "y": 1,
            "z": 20,
            "elements": [
                "astralsorcery:blockblackmarble@0"
            ]
        },
        {
            "x": -11,
            "y": 2,
            "z": 5,
            "elements": [
                "astralsorcery:blockmarble@4"
            ]
        },
        {
            "x": 4,
            "y": 3,
            "z": 5,
            "elements": [
                "astralsorcery:blockblackmarble@0"
            ]
        },
        {
            "x": 3,
            "y": 0,
            "z": 15,
            "elements": [
                "astralsorcery:blockblackmarble@0"
            ]
        },
        {
            "x": 0,
            "y": 2,
            "z": 15,
            "elements": [
                "astralsorcery:blockblackmarble@0"
            ]
        },
        {
            "x": -6,
            "y": 1,
            "z": 7,
            "elements": [
                "astralsorcery:blockblackmarble@0"
            ]
        },
        {
            "x": -3,
            "y": 1,
            "z": -1,
            "elements": [
                "astralsorcery:blockmarble@2"
            ]
        },
        {
            "x": -1,
            "y": 2,
            "z": 20,
            "elements": [
                "astralsorcery:blockblackmarble@0"
            ]
        },
        {
            "x": -4,
            "y": 2,
            "z": 13,
            "elements": [
                "astralsorcery:blockblackmarble@0"
            ]
        },
        {
            "x": -8,
            "y": 7,
