{
    "registryname": "shrine_of_the_sentient_meatballs",
    "localizedname": "感知肉丸神龛",
	"color": "0d5c66",
    "parts": [
        {
            "x": 5,
            "y": 0,
            "z": 8,
            "elements": [
                "chisel:sandstonered@4"
            ]
        },
        {
            "x": 5,
            "y": 0,
            "z": 9,
            "elements": [
                "chisel:sandstonered@4"
            ]
        },
        {
            "x": 5,
            "y": 0,
            "z": 6,
            "elements": [
                "chisel:sandstonered@4"
            ]
        },
        {
            "x": 5,
            "y": 0,
            "z": 7,
            "elements": [
                "chisel:sandstonered@4"
            ]
        },
        {
            "x": 5,
            "y": 0,
            "z": 4,
            "elements": [
                "chisel:sandstonered@4"
            ]
        },
        {
            "x": 5,
            "y": 0,
            "z": 5,
            "elements": [
                "chisel:sandstonered@4"
            ]
        },
        {
            "x": 5,
            "y": 0,
            "z": 2,
            "elements": [
                "chisel:sandstonered@4"
            ]
        },
        {
            "x": 5,
            "y": 0,
            "z": 3,
            "elements": [
                "chisel:sandstonered@4"
            ]
        },
        {
            "x": 9,
            "y": 5,
            "z": 16,
            "elements": [
                "contenttweaker:prophetic_sentient_meatball@0"
            ]
        },
        {
            "x": 5,
            "y": 0,
            "z": 0,
            "elements": [
                "railcraft:pearlized@0"
            ]
        },
        {
            "x": 5,
            "y": 0,
            "z": 1,
            "elements": [
                "chisel:sandstonered@4"
            ]
        },
        {
            "x": -12,
            "y": 5,
            "z": 12,
            "elements": [
                "tconstruct:slime_congealed@3"
            ]
        },
        {
            "x": 5,
            "y": 0,
            "z": 20,
            "elements": [
                "railcraft:pearlized@0"
            ]
        },
        {
            "x": 5,
            "y": 0,
            "z": 18,
            "elements": [
                "chisel:sandstonered@4"
            ]
        },
        {
            "x": -12,
            "y": 5,
            "z": 8,
            "elements": [
                "tconstruct:slime_congealed@3"
            ]
        },
        {
            "x": 5,
            "y": 0,
            "z": 19,
            "elements": [
                "chisel:sandstonered@4"
            ]
        },
        {
            "x": 5,
            "y": 0,
            "z": 16,
            "elements": [
                "chisel:sandstonered@4"
            ]
        },
        {
            "x": 5,
            "y": 0,
            "z": 17,
            "elements": [
                "chisel:sandstonered@4"
            ]
        },
        {
            "x": 7,
            "y": 2,
            "z": 22,
            "elements": [
                "railcraft:pearlized@0"
            ]
        },
        {
            "x": 5,
            "y": 0,
            "z": 14,
            "elements": [
                "chisel:sandstonered@4"
            ]
        },
        {
            "x": 5,
            "y": 0,
            "z": 15,
            "elements": [
                "chisel:sandstonered@4"
            ]
        },
        {
            "x": 9,
            "y": 5,
            "z": 4,
            "elements": [
                "contenttweaker:vegetarian_sentient_meatball@0"
            ]
        },
        {
            "x": 5,
            "y": 0,
            "z": 12,
            "elements": [
                "chisel:sandstonered@4"
            ]
        },
        {
            "x": 5,
            "y": 0,
            "z": 13,
            "elements": [
                "chisel:sandstonered@4"
            ]
        },
        {
            "x": 5,
            "y": 0,
            "z": 10,
            "elements": [
                "chisel:sandstonered@4"
            ]
        },
        {
            "x": 5,
            "y": 0,
            "z": 11,
            "elements": [
                "chisel:sandstonered@4"
            ]
        },
        {
            "x": 5,
            "y": -1,
            "z": 20,
            "elements": [
                "railcraft:pearlized@0"
            ]
        },
        {
            "x": 7,
            "y": 2,
            "z": -2,
            "elements": [
                "railcraft:pearlized@0"
            ]
        },
        {
            "x": -14,
            "y": 2,
            "z": 12,
            "elements": [
                "railcraft:pearlized@0"
            ]
        },
        {
            "x": -14,
            "y": 2,
            "z": 13,
            "elements": [
                "railcraft:pearlized@0"
            ]
        },
        {
            "x": -14,
            "y": 2,
            "z": 8,
            "elements": [
                "railcraft:pearlized@0"
            ]
        },
        {
            "x": -14,
            "y": 2,
            "z": 7,
            "elements": [
                "railcraft:pearlized@0"
            ]
        },
        {
            "x": 4,
            "y": 0,
            "z": 1,
            "elements": [
                "generalized_input_fluid"
            ]
        },
        {
            "x": 4,
            "y": 0,
            "z": 2,
            "elements": [
                "chisel:sandstonered@4"
            ]
        },
        {
            "x": 6,
            "y": 1,
            "z": -1,
            "elements": [
                "railcraft:pearlized@0"
            ]
        },
        {
            "x": -15,
            "y": 1,
            "z": 7,
            "elements": [
                "railcraft:pearlized@1"
            ]
        },
        {
            "x": 6,
            "y": 1,
            "z": 4,
            "elements": [
                "railcraft:pearlized@0"
            ]
        },
        {
            "x": -15,
            "y": 1,
            "z": 13,
            "elements": [
                "railcraft:pearlized@1"
            ]
        },
        {
            "x": 5,
            "y": -1,
            "z": 0,
            "elements": [
                "railcraft:pearlized@0"
            ]
        },
        {
            "x": 6,
            "y": 1,
            "z": 16,
            "elements": [
                "railcraft:pearlized@0"
            ]
        },
        {
            "x": 6,
            "y": 1,
            "z": 21,
            "elements": [
                "railcraft:pearlized@0"
            ]
        },
        {
            "x": -14,
            "y": 1,
            "z": 13,
            "elements": [
                "railcraft:pearlized@0"
            ]
        },
        {
            "x": 3,
            "y": -1,
            "z": 19,
            "elements": [
                "railcraft:pearlized@0"
            ]
        },
        {
            "x": -14,
            "y": 1,
            "z": 12,
            "elements": [
                "railcraft:pearlized@0"
            ]
        },
        {
            "x": 3,
            "y": -1,
            "z": 20,
            "elements": [
                "railcraft:pearlized@0"
            ]
        },
        {
            "x": 7,
            "y": 1,
            "z": -2,
            "elements": [
                "railcraft:pearlized@0"
            ]
        },
        {
            "x": 3,
            "y": -1,
            "z": 18,
            "elements": [
                "railcraft:pearlized@0"
            ]
        },
        {
            "x": 3,
            "y": -1,
            "z": 1,
            "elements": [
                "railcraft:pearlized@0"
            ]
        },
        {
            "x": 3,
            "y": -1,
            "z": 2,
            "elements": [
                "railcraft:pearlized@0"
            ]
        },
        {
            "x": 3,
            "y": -1,
            "z": -1,
            "elements": [
                "railcraft:pearlized@0"
            ]
        },
        {
            "x": 3,
            "y": -1,
            "z": 0,
            "elements": [
                "railcraft:pearlized@0"
            ]
        },
        {
            "x": 3,
            "y": -1,
            "z": -3,
            "elements": [
                "railcraft:pearlized@0"
            ]
        },
        {
            "x": 3,
            "y": -1,
            "z": -2,
            "elements": [
                "railcraft:pearlized@0"
            ]
        },
        {
            "x": 3,
            "y": -1,
            "z": -5,
            "elements": [
                "railcraft:pearlized@0"
            ]
        },
        {
            "x": 3,
            "y": -1,
            "z": -4,
            "elements": [
                "railcraft:pearlized@0"
            ]
        },
        {
            "x": 4,
            "y": 0,
            "z": 7,
            "elements": [
                "chisel:sandstonered@4"
            ]
        },
        {
            "x": 6,
            "y": -1,
            "z": 21,
            "elements": [
                "railcraft:pearlized@0"
            ]
        },
        {
            "x": 4,
            "y": 0,
            "z": 8,
            "elements": [
                "chisel:sandstonered@4"
            ]
        },
        {
            "x": 10,
            "y": 5,
            "z": 8,
            "elements": [
                "contenttweaker:sentient_meatball@0"
            ]
        },
        {
            "x": 4,
            "y": 0,
            "z": 9,
            "elements": [
                "chisel:sandstonered@4"
            ]
        },
        {
            "x": 4,
            "y": 0,
            "z": 10,
            "elements": [
                "chisel:sandstonered@4"
            ]
        },
        {
            "x": 4,
            "y": 0,
            "z": 3,
            "elements": [
                "chisel:sandstonered@4"
            ]
        },
        {
            "x": 4,
            "y": 0,
            "z": 4,
            "elements": [
                "chisel:sandstonered@4"
            ]
        },
        {
            "x": 10,
            "y": 5,
            "z": 12,
            "elements": [
                "contenttweaker:chaotic_sentient_meatball@0"
            ]
        },
        {
            "x": 4,
            "y": 0,
            "z": 5,
            "elements": [
                "chisel:sandstonered@4"
            ]
        },
        {
            "x": 4,
            "y": 0,
            "z": 6,
            "elements": [
                "chisel:sandstonered@4"
            ]
        },
        {
            "x": 4,
            "y": 1,
            "z": 1,
            "elements": [
                "railcraft:pearlized@0"
            ]
        },
        {
            "x": 4,
            "y": 0,
            "z": 15,
            "elements": [
                "chisel:sandstonered@4"
            ]
        },
        {
            "x": 4,
            "y": 0,
            "z": 16,
            "elements": [
                "chisel:sandstonered@4"
            ]
        },
        {
            "x": 4,
            "y": 0,
            "z": 17,
            "elements": [
                "chisel:sandstonered@4"
            ]
        },
        {
            "x": -11,
            "y": 5,
            "z": 17,
            "elements": [
                "tconstruct:slime_congealed@3"
            ]
        },
        {
            "x": 4,
            "y": 0,
            "z": 18,
            "elements": [
                "chisel:sandstonered@4"
            ]
        },
        {
            "x": 4,
            "y": 0,
            "z": 11,
            "elements": [
                "chisel:sandstonered@4"
            ]
        },
        {
            "x": 4,
            "y": 1,
            "z": 6,
            "elements": [
                "railcraft:pearlized@0"
            ]
        },
        {
            "x": 4,
            "y": 0,
            "z": 12,
            "elements": [
                "chisel:sandstonered@4"
            ]
        },
        {
            "x": 4,
            "y": 1,
            "z": 7,
            "elements": [
                "railcraft:pearlized@0"
            ]
        },
        {
            "x": 6,
            "y": -1,
            "z": 16,
            "elements": [
                "railcraft:pearlized@0"
            ]
        },
        {
            "x": 4,
            "y": 0,
            "z": 13,
            "elements": [
                "chisel:sandstonered@4"
            ]
        },
        {
            "x": 4,
            "y": 0,
            "z": 14,
            "elements": [
                "chisel:sandstonered@4"
            ]
        },
        {
            "x": 4,
            "y": 0,
            "z": 19,
            "elements": [
                "modularmachinery:blockwillproviderinput@0"
            ]
        },
        {
            "x": -11,
            "y": 5,
            "z": 3,
            "elements": [
                "tconstruct:slime_congealed@3"
            ]
        },
        {
            "x": -15,
            "y": -1,
            "z": 7,
            "elements": [
                "railcraft:pearlized@0"
            ]
        },
        {
            "x": 8,
            "y": 3,
            "z": -2,
            "elements": [
                "railcraft:pearlized_slab@1"
            ]
        },
        {
            "x": -15,
            "y": -1,
            "z": 13,
            "elements": [
                "railcraft:pearlized@0"
            ]
        },
        {
            "x": 2,
            "y": -1,
            "z": -3,
            "elements": [
                "railcraft:pearlized@0"
            ]
        },
        {
            "x": 6,
            "y": 2,
            "z": 4,
            "elements": [
                "railcraft:pearlized_slab@1"
            ]
        },
        {
            "x": 2,
            "y": -1,
            "z": -4,
            "elements": [
                "railcraft:pearlized@0"
            ]
        },
        {
            "x": 6,
            "y": 2,
            "z": -1,
            "elements": [
                "railcraft:pearlized_slab@1"
            ]
        },
        {
            "x": 6,
            "y": -1,
            "z": 4,
            "elements": [
                "railcraft:pearlized@0"
            ]
        },
        {
            "x": -15,
            "y": 2,
            "z": 13,
            "elements": [
                "railcraft:pearlized@0"
            ]
        },
        {
            "x": 6,
            "y": 2,
            "z": 21,
            "elements": [
                "railcraft:pearlized_slab@1"
            ]
        },
        {
            "x": 6,
            "y": -1,
            "z": -1,
            "elements": [
                "railcraft:pearlized@0"
            ]
        },
        {
            "x": 6,
            "y": 2,
            "z": 16,
            "elements": [
                "railcraft:pearlized_slab@1"
            ]
        },
        {
            "x": -15,
            "y": 2,
            "z": 7,
            "elements": [
                "railcraft:pearlized@0"
            ]
        },
        {
            "x": 7,
            "y": 1,
            "z": 19,
            "elements": [
                "railcraft:pearlized@0"
            ]
        },
        {
            "x": 7,
            "y": 1,
            "z": 22,
            "elements": [
                "railcraft:pearlized@0"
            ]
        },
        {
            "x": 7,
            "y": 1,
            "z": 21,
            "elements": [
                "biomesoplenty:blood@0"
            ]
        },
        {
            "x": 2,
            "y": -1,
            "z": 23,
            "elements": [
                "railcraft:pearlized@0"
            ]
        },
        {
            "x": 8,
            "y": 3,
            "z": 22,
            "elements": [
                "railcraft:pearlized_slab@1"
            ]
        },
        {
            "x": 7,
            "y": 1,
            "z": 18,
            "elements": [
                "railcraft:pearlized@0"
            ]
        },
        {
            "x": 7,
            "y": 1,
            "z": 17,
            "elements": [
                "railcraft:pearlized@0"
            ]
        },
        {
            "x": 2,
            "y": -1,
            "z": 24,
            "elements": [
                "railcraft:pearlized@0"
            ]
        },
        {
            "x": 7,
            "y": 1,
            "z": 3,
            "elements": [
                "railcraft:pearlized@0"
            ]
        },
        {
            "x": -14,
            "y": 1,
            "z": 7,
            "elements": [
                "railcraft:pearlized@0"
            ]
        },
        {
            "x": -14,
            "y": 1,
            "z": 8,
            "elements": [
                "railcraft:pearlized@0"
            ]
        },
        {
            "x": 7,
            "y": 1,
            "z": -1,
            "elements": [
                "biomesoplenty:blood@0"
            ]
        },
        {
            "x": 7,
            "y": 1,
            "z": 2,
            "elements": [
                "railcraft:pearlized@0"
            ]
        },
        {
            "x": 7,
            "y": 1,
            "z": 1,
            "elements": [
                "railcraft:pearlized@0"
            ]
        },
        {
            "x": 4,
            "y": 2,
            "z": 14,
            "elements": [
                "railcraft:pearlized@0"
            ]
        },
        {
            "x": 3,
            "y": 1,
            "z": 1,
            "elements": [
                "railcraft:pearlized@0"
            ]
        },
        {
            "x": 3,
            "y": 1,
            "z": 2,
            "elements": [
                "railcraft:pearlized@0"
            ]
        },
        {
            "x": 4,
            "y": 2,
            "z": 6,
            "elements": [
                "railcraft:pearlized@0"
            ]
        },
        {
            "x": 3,
            "y": 1,
            "z": -1,
            "elements": [
                "railcraft:pearlized@0"
            ]
        },
        {
            "x": 3,
            "y": 1,
            "z": 0,
            "elements": [
                "railcraft:pearlized@0"
            ]
        },
        {
            "x": 3,
            "y": 1,
            "z": -3,
            "elements": [
                "railcraft:pearlized@0"
            ]
        },
        {
            "x": 3,
            "y": 1,
            "z": -2,
            "elements": [
                "railcraft:pearlized@0"
            ]
        },
        {
            "x": 3,
            "y": 1,
            "z": -5,
            "elements": [
                "railcraft:pearlized@1"
            ]
        },
        {
            "x": 3,
            "y": 1,
            "z": -4,
            "elements": [
                "railcraft:pearlized@0"
            ]
        },
        {
            "x": 3,
            "y": 1,
            "z": 25,
            "elements": [
                "railcraft:pearlized@1"
            ]
        },
        {
            "x": -14,
            "y": -1,
            "z": 7,
            "elements": [
                "railcraft:pearlized@0"
            ]
        },
        {
            "x": 3,
            "y": 1,
            "z": 23,
            "elements": [
                "railcraft:pearlized@0"
            ]
        },
        {
            "x": 3,
            "y": 1,
            "z": 24,
            "elements": [
                "railcraft:pearlized@0"
            ]
        },
        {
            "x": -14,
            "y": -1,
            "z": 8,
            "elements": [
                "railcraft:pearlized@0"
            ]
        },
        {
            "x": 3,
            "y": 1,
            "z": 21,
            "elements": [
                "railcraft:pearlized@0"
            ]
        },
        {
            "x": 3,
            "y": 1,
            "z": 22,
            "elements": [
                "railcraft:pearlized@0"
            ]
        },
        {
            "x": 3,
            "y": 1,
            "z": 19,
            "elements": [
                "railcraft:pearlized@0"
            ]
        },
        {
            "x": -14,
            "y": -1,
            "z": 13,
            "elements": [
                "railcraft:pearlized@0"
            ]
        },
        {
            "x": 3,
            "y": 1,
            "z": 20,
            "elements": [
                "railcraft:pearlized@0"
            ]
        },
        {
            "x": -14,
            "y": -1,
            "z": 12,
            "elements": [
                "railcraft:pearlized@0"
            ]
        },
        {
            "x": 9,
            "y": 2,
            "z": 10,
            "elements": [
                "railcraft:pearlized_slab@1"
            ]
        },
        {
            "x": 3,
            "y": 1,
            "z": 9,
            "elements": [
                "railcraft:pearlized@0"
            ]
        },
        {
            "x": 9,
            "y": 1,
            "z": 13,
            "elements": [
                "railcraft:pearlized@0"
            ]
        },
        {
            "x": 9,
            "y": 1,
            "z": 14,
            "elements": [
                "railcraft:pearlized@0"
            ]
        },
        {
            "x": 3,
            "y": 1,
            "z": 7,
            "elements": [
                "chisel:sandstonered@4"
            ]
        },
        {
            "x": 3,
            "y": 1,
            "z": 8,
            "elements": [
                "railcraft:pearlized@0"
            ]
        },
        {
            "x": 9,
            "y": 1,
            "z": 17,
            "elements": [
                "railcraft:pearlized@0"
            ]
        },
        {
            "x": 3,
            "y": 1,
            "z": 6,
            "elements": [
                "railcraft:pearlized@0"
            ]
        },
        {
            "x": 3,
            "y": 1,
            "z": 18,
            "elements": [
                "railcraft:pearlized@0"
            ]
        },
        {
            "x": 3,
            "y": 1,
            "z": 13,
            "elements": [
                "chisel:sandstonered@4"
            ]
        },
        {
            "x": 3,
            "y": 1,
            "z": 14,
            "elements": [
                "railcraft:pearlized@0"
            ]
        },
        {
            "x": 3,
            "y": 1,
            "z": 11,
            "elements": [
                "railcraft:pearlized@0"
            ]
        },
        {
            "x": 3,
            "y": 1,
            "z": 12,
            "elements": [
                "railcraft:pearlized@0"
            ]
        },
        {
            "x": 10,
            "y": 2,
            "z": 18,
            "elements": [
                "railcraft:pearlized_slab@1"
            ]
        },
        {
            "x": -9,
            "y": 5,
            "z": 4,
            "elements": [
                "contenttweaker:gluttonous_sentient_meatball@0"
            ]
        },
        {
            "x": 10,
            "y": 2,
            "z": 2,
            "elements": [
                "railcraft:pearlized_slab@1"
            ]
        },
        {
            "x": -14,
            "y": 0,
            "z": 12,
            "elements": [
                "railcraft:pearlized@0"
            ]
        },
        {
            "x": 4,
            "y": 1,
            "z": 13,
            "elements": [
                "railcraft:pearlized@0"
            ]
        },
        {
            "x": 4,
            "y": 1,
            "z": 14,
            "elements": [
                "railcraft:pearlized@0"
            ]
        },
        {
            "x": -14,
            "y": 0,
            "z": 8,
            "elements": [
                "railcraft:pearlized@0"
            ]
        },
        {
            "x": -12,
            "y": 3,
            "z": 2,
            "elements": [
                "railcraft:pearlized_slab@1"
            ]
        },
        {
            "x": -14,
            "y": 0,
            "z": 7,
            "elements": [
                "railcraft:pearlized@0"
            ]
        },
        {
            "x": 4,
            "y": 1,
            "z": 19,
            "elements": [
                "railcraft:pearlized@0"
            ]
        },
        {
            "x": -14,
            "y": 0,
            "z": 13,
            "elements": [
                "railcraft:pearlized@0"
            ]
        },
        {
            "x": -13,
            "y": 1,
            "z": 13,
            "elements": [
                "railcraft:pearlized@0"
            ]
        },
        {
            "x": -13,
            "y": 1,
            "z": 12,
            "elements": [
                "railcraft:pearlized@0"
            ]
        },
        {
            "x": -12,
            "y": 3,
            "z": 18,
            "elements": [
                "railcraft:pearlized_slab@1"
            ]
        },
        {
            "x": -13,
            "y": 1,
            "z": 8,
            "elements": [
                "railcraft:pearlized@0"
            ]
        },
        {
            "x": -13,
            "y": 1,
            "z": 7,
            "elements": [
                "railcraft:pearlized@0"
            ]
        },
        {
            "x": -9,
            "y": 5,
            "z": 16,
            "elements": [
                "contenttweaker:burly_sentient_meatball@0"
            ]
        },
        {
            "x": 3,
            "y": -1,
            "z": 25,
            "elements": [
                "railcraft:pearlized@0"
            ]
        },
        {
            "x": 3,
            "y": -1,
            "z": 23,
            "elements": [
                "railcraft:pearlized@0"
            ]
        },
        {
            "x": 3,
            "y": -1,
            "z": 24,
            "elements": [
                "railcraft:pearlized@0"
            ]
        },
        {
            "x": 3,
            "y": -1,
            "z": 21,
            "elements": [
                "railcraft:pearlized@0"
            ]
        },
        {
            "x": 3,
            "y": -1,
            "z": 22,
            "elements": [
                "railcraft:pearlized@0"
            ]
        },
        {
            "x": 9,
            "y": 0,
            "z": 10,
            "elements": [
                "railcraft:pearlized@0"
            ]
        },
        {
            "x": 9,
            "y": 0,
            "z": 11,
            "elements": [
                "chisel:sandstonered@4"
            ]
        },
        {
            "x": 9,
            "y": 0,
            "z": 12,
            "elements": [
                "chisel:sandstonered@4"
            ]
        },
        {
            "x": 9,
            "y": 0,
            "z": 13,
            "elements": [
                "railcraft:pearlized@0"
            ]
        },
        {
            "x": 9,
            "y": 0,
            "z": 6,
            "elements": [
                "modularmachinery:blockenergyinputhatch"
            ]
        },
        {
            "x": 9,
            "y": 0,
            "z": 7,
            "elements": [
                "railcraft:pearlized@0"
            ]
        },
        {
            "x": -15,
            "y": 3,
            "z": 13,
            "elements": [
                "railcraft:pearlized_slab@1"
            ]
        },
        {
            "x": 9,
            "y": 0,
            "z": 8,
            "elements": [
                "chisel:sandstonered@4"
            ]
        },
        {
            "x": 9,
            "y": 0,
            "z": 9,
            "elements": [
                "chisel:sandstonered@4"
            ]
        },
        {
            "x": -15,
            "y": 3,
            "z": 7,
            "elements": [
                "railcraft:pearlized_slab@1"
            ]
        },
        {
            "x": 9,
            "y": 0,
            "z": 14,
            "elements": [
                "modularmachinery:blockwillproviderinput@0"
            ]
        },
        {
            "x": 9,
            "y": 0,
            "z": 15,
            "elements": [
                "chisel:sandstonered@4"
            ]
        },
        {
            "x": 9,
            "y": 0,
            "z": 16,
            "elements": [
                "chisel:sandstonered@4"
            ]
        },
        {
            "x": 9,
            "y": 0,
            "z": 17,
            "elements": [
                "railcraft:pearlized@0"
            ]
        },
        {
            "x": 5,
            "y": 5,
            "z": 3,
            "elements": [
                "tconstruct:slime_congealed@3"
            ]
        },
        {
            "x": 6,
            "y": 6,
            "z": 10,
            "elements": [
                "tconstruct:slime_congealed@3"
            ]
        },
        {
            "x": 6,
            "y": 0,
            "z": 8,
            "elements": [
                "chisel:sandstonered@4"
            ]
        },
        {
            "x": 8,
            "y": 5,
            "z": 8,
            "elements": [
                "tconstruct:slime_congealed@3"
            ]
        },
        {
            "x": 6,
            "y": 0,
            "z": 7,
            "elements": [
                "chisel:sandstonered@4"
            ]
        },
        {
            "x": 8,
            "y": -1,
            "z": 22,
            "elements": [
                "railcraft:pearlized@0"
            ]
        },
        {
            "x": 6,
            "y": 0,
            "z": 6,
            "elements": [
                "chisel:sandstonered@4"
            ]
        },
        {
            "x": 8,
            "y": -1,
            "z": 21,
            "elements": [
                "railcraft:pearlized@0"
            ]
        },
        {
            "x": 0,
            "y": -1,
            "z": 19,
            "elements": [
                "railcraft:pearlized@0"
            ]
        },
        {
            "x": 6,
            "y": 0,
            "z": 5,
            "elements": [
                "chisel:sandstonered@4"
            ]
        },
        {
            "x": 8,
            "y": -1,
            "z": 20,
            "elements": [
                "railcraft:pearlized@0"
            ]
        },
        {
            "x": 6,
            "y": 0,
            "z": 4,
            "elements": [
                "railcraft:pearlized@0"
            ]
        },
        {
            "x": 6,
            "y": 0,
            "z": 3,
            "elements": [
                "chisel:sandstonered@4"
            ]
        },
        {
            "x": 0,
            "y": -1,
            "z": 20,
            "elements": [
                "railcraft:pearlized@0"
            ]
        },
        {
            "x": 6,
            "y": 0,
            "z": 2,
            "elements": [
                "chisel:sandstonered@4"
            ]
        },
        {
            "x": 8,
            "y": -1,
            "z": 17,
            "elements": [
                "railcraft:pearlized@0"
            ]
        },
        {
            "x": 6,
            "y": 0,
            "z": 1,
            "elements": [
                "chisel:sandstonered@4"
            ]
        },
        {
            "x": 6,
            "y": 0,
            "z": 16,
            "elements": [
                "railcraft:pearlized@0"
            ]
        },
        {
            "x": 6,
            "y": 0,
            "z": 15,
            "elements": [
                "chisel:sandstonered@4"
            ]
        },
        {
            "x": -13,
            "y": 2,
            "z": 8,
            "elements": [
                "railcraft:pearlized_slab@1"
            ]
        },
        {
            "x": 6,
            "y": 0,
            "z": 14,
            "elements": [
                "chisel:sandstonered@4"
            ]
        },
        {
            "x": 8,
            "y": -1,
            "z": 13,
            "elements": [
                "railcraft:pearlized@0"
            ]
        },
        {
            "x": -13,
            "y": 2,
            "z": 7,
            "elements": [
                "railcraft:pearlized_slab@1"
            ]
        },
        {
            "x": 6,
            "y": 0,
            "z": 13,
            "elements": [
                "chisel:sandstonered@4"
            ]
        },
        {
            "x": 6,
            "y": 0,
            "z": 12,
            "elements": [
                "chisel:sandstonered@4"
            ]
        },
        {
            "x": 8,
            "y": 5,
            "z": 12,
            "elements": [
                "tconstruct:slime_congealed@3"
            ]
        },
        {
            "x": 6,
            "y": 0,
            "z": 11,
            "elements": [
                "chisel:sandstonered@4"
            ]
        },
        {
            "x": 6,
            "y": 0,
            "z": 10,
            "elements": [
                "chisel:sandstonered@4"
            ]
        },
        {
            "x": 6,
            "y": 0,
            "z": 9,
            "elements": [
                "chisel:sandstonered@4"
            ]
        },
        {
            "x": 8,
            "y": -1,
            "z": 7,
            "elements": [
                "railcraft:pearlized@0"
            ]
        },
        {
            "x": 0,
            "y": -1,
            "z": 1,
            "elements": [
                "railcraft:pearlized@0"
            ]
        },
        {
            "x": 0,
            "y": -1,
            "z": 0,
            "elements": [
                "railcraft:pearlized@0"
            ]
        },
        {
            "x": 8,
            "y": -1,
            "z": 3,
            "elements": [
                "railcraft:pearlized@0"
            ]
        },
        {
            "x": -13,
            "y": 2,
            "z": 13,
            "elements": [
                "railcraft:pearlized_slab@1"
            ]
        },
        {
            "x": -13,
            "y": 2,
            "z": 12,
            "elements": [
                "railcraft:pearlized_slab@1"
            ]
        },
        {
            "x": 8,
            "y": -1,
            "z": 0,
            "elements": [
                "railcraft:pearlized@0"
            ]
        },
        {
            "x": 6,
            "y": 0,
            "z": 0,
            "elements": [
                "chisel:sandstonered@4"
            ]
        },
        {
            "x": 8,
            "y": -1,
            "z": -1,
            "elements": [
                "railcraft:pearlized@0"
            ]
        },
        {
            "x": 6,
            "y": 0,
            "z": -1,
            "elements": [
                "railcraft:pearlized@0"
            ]
        },
        {
            "x": 8,
            "y": -1,
            "z": -2,
            "elements": [
                "railcraft:pearlized@0"
            ]
        },
        {
            "x": 3,
            "y": 0,
            "z": 6,
            "elements": [
                "chisel:sandstonered@4"
            ]
        },
        {
            "x": 3,
            "y": 0,
            "z": 7,
            "elements": [
                "chisel:sandstonered@4"
            ]
        },
        {
            "x": 3,
            "y": 0,
            "z": 4,
            "elements": [
                "chisel:sandstonered@4"
            ]
        },
        {
            "x": 3,
            "y": 0,
            "z": 5,
            "elements": [
                "chisel:sandstonered@4"
            ]
        },
        {
            "x": 3,
            "y": 0,
            "z": 10,
            "elements": [
                "chisel:sandstonered@4"
            ]
        },
        {
            "x": 3,
            "y": 0,
            "z": 11,
            "elements": [
                "chisel:sandstonered@4"
            ]
        },
        {
            "x": 3,
            "y": 0,
            "z": 8,
            "elements": [
                "chisel:sandstonered@4"
            ]
        },
        {
            "x": 9,
            "y": 1,
            "z": 3,
            "elements": [
                "railcraft:pearlized@0"
            ]
        },
        {
            "x": 3,
            "y": 0,
            "z": 9,
            "elements": [
                "chisel:sandstonered@4"
            ]
        },
        {
            "x": -10,
            "y": 2,
            "z": 2,
            "elements": [
                "railcraft:pearlized_slab@1"
            ]
        },
        {
            "x": 3,
            "y": 0,
            "z": -2,
            "elements": [
                "railcraft:pearlized@0"
            ]
        },
        {
            "x": 3,
            "y": 0,
            "z": -1,
            "elements": [
                "railcraft:pearlized@0"
            ]
        },
        {
            "x": 11,
            "y": 5,
            "z": 17,
            "elements": [
                "tconstruct:slime_congealed@3"
            ]
        },
        {
            "x": 9,
            "y": 1,
            "z": 6,
            "elements": [
                "railcraft:pearlized@0"
            ]
        },
        {
            "x": 3,
            "y": 0,
            "z": -4,
            "elements": [
                "railcraft:pearlized@0"
            ]
        },
        {
            "x": 9,
            "y": 1,
            "z": 7,
            "elements": [
                "railcraft:pearlized@0"
            ]
        },
        {
            "x": 3,
            "y": 0,
            "z": -3,
            "elements": [
                "railcraft:pearlized@0"
            ]
        },
        {
            "x": 3,
            "y": 0,
            "z": 2,
            "elements": [
                "railcraft:pearlized@0"
            ]
        },
        {
            "x": 3,
            "y": 0,
            "z": 3,
            "elements": [
                "chisel:sandstonered@4"
            ]
        },
        {
            "x": 9,
            "y": 1,
            "z": 10,
            "elements": [
                "railcraft:pearlized@0"
            ]
        },
        {
            "x": 3,
            "y": 0,
            "z": 0,
            "elements": [
                "railcraft:pearlized@0"
            ]
        },
        {
            "x": 3,
            "y": 0,
            "z": 1,
            "elements": [
                "railcraft:pearlized@0"
            ]
        },
        {
            "x": 3,
            "y": 0,
            "z": 22,
            "elements": [
                "railcraft:pearlized@0"
            ]
        },
        {
            "x": 3,
            "y": 0,
            "z": 23,
            "elements": [
                "railcraft:pearlized@0"
            ]
        },
        {
            "x": 3,
            "y": 0,
            "z": 20,
            "elements": [
                "railcraft:pearlized@0"
            ]
        },
        {
            "x": 3,
            "y": 0,
            "z": 21,
            "elements": [
                "railcraft:pearlized@0"
            ]
        },
        {
            "x": 6,
            "y": 0,
            "z": 21,
            "elements": [
                "railcraft:pearlized@0"
            ]
        },
        {
            "x": 6,
            "y": 0,
            "z": 20,
            "elements": [
                "chisel:sandstonered@4"
            ]
        },
        {
            "x": 6,
            "y": 0,
            "z": 19,
            "elements": [
                "chisel:sandstonered@4"
            ]
        },
        {
            "x": 3,
            "y": 0,
            "z": 24,
            "elements": [
                "railcraft:pearlized@0"
            ]
        },
        {
            "x": 6,
            "y": 0,
            "z": 18,
            "elements": [
                "chisel:sandstonered@4"
            ]
        },
        {
            "x": 3,
            "y": 0,
            "z": 25,
            "elements": [
                "railcraft:pearlized@1"
            ]
        },
        {
            "x": 6,
            "y": 0,
            "z": 17,
            "elements": [
                "chisel:sandstonered@4"
            ]
        },
        {
            "x": 3,
            "y": 0,
            "z": 14,
            "elements": [
                "chisel:sandstonered@4"
            ]
        },
        {
            "x": 3,
            "y": 0,
            "z": 15,
            "elements": [
                "chisel:sandstonered@4"
            ]
        },
        {
            "x": 3,
            "y": 0,
            "z": 12,
            "elements": [
                "chisel:sandstonered@4"
            ]
        },
        {
            "x": 3,
            "y": 0,
            "z": 13,
            "elements": [
                "chisel:sandstonered@4"
            ]
        },
        {
            "x": 3,
            "y": 0,
            "z": 18,
            "elements": [
                "railcraft:pearlized@0"
            ]
        },
        {
            "x": 3,
            "y": 0,
            "z": 19,
            "elements": [
                "railcraft:pearlized@0"
            ]
        },
        {
            "x": 3,
            "y": 0,
            "z": 16,
            "elements": [
                "chisel:sandstonered@4"
            ]
        },
        {
            "x": 3,
            "y": 0,
            "z": 17,
            "elements": [
                "chisel:sandstonered@4"
            ]
        },
        {
            "x": 11,
            "y": 5,
            "z": 3,
            "elements": [
                "tconstruct:slime_congealed@3"
            ]
        },
        {
            "x": 3,
            "y": 0,
            "z": -5,
            "elements": [
                "railcraft:pearlized@1"
            ]
        },
        {
            "x": -10,
            "y": 2,
            "z": 18,
            "elements": [
                "railcraft:pearlized_slab@1"
            ]
        },
        {
            "x": 12,
            "y": 2,
            "z": 18,
            "elements": [
                "railcraft:pearlized@0"
            ]
        },
        {
            "x": 12,
            "y": 2,
            "z": 17,
            "elements": [
                "railcraft:pearlized@0"
            ]
        },
        {
            "x": 11,
            "y": 1,
            "z": 2,
            "elements": [
                "railcraft:pearlized@0"
            ]
        },
        {
            "x": -1,
            "y": -1,
            "z": 21,
            "elements": [
                "railcraft:pearlized@0"
            ]
        },
        {
            "x": -1,
            "y": -1,
            "z": 22,
            "elements": [
                "railcraft:pearlized@0"
            ]
        },
        {
            "x": -11,
            "y": 0,
            "z": 4,
            "elements": [
                "railcraft:pearlized@0"
            ]
        },
        {
            "x": 11,
            "y": 1,
            "z": 7,
            "elements": [
                "railcraft:pearlized@0"
            ]
        },
        {
            "x": -11,
            "y": 0,
            "z": 2,
            "elements": [
                "railcraft:pearlized@0"
            ]
        },
        {
            "x": 11,
            "y": 1,
            "z": 9,
            "elements": [
                "railcraft:pearlized@0"
            ]
        },
        {
            "x": -11,
            "y": 0,
            "z": 3,
            "elements": [
                "chisel:sandstonered@4"
            ]
        },
        {
            "x": -11,
            "y": 0,
            "z": 8,
            "elements": [
                "chisel:sandstonered@4"
            ]
        },
        {
            "x": 11,
            "y": 1,
            "z": 3,
            "elements": [
                "biomesoplenty:blood@0"
            ]
        },
        {
            "x": -11,
            "y": 0,
            "z": 9,
            "elements": [
                "railcraft:pearlized@0"
            ]
        },
        {
            "x": 11,
            "y": 1,
            "z": 4,
            "elements": [
                "railcraft:pearlized@0"
            ]
        },
        {
            "x": -11,
            "y": 0,
            "z": 7,
            "elements": [
                "railcraft:pearlized@0"
            ]
        },
        {
            "x": 0,
            "y": 0,
            "z": 20,
            "elements": [
                "modularmachinery:blockwillproviderinput@0"
            ]
        },
        {
            "x": -11,
            "y": 0,
            "z": 12,
            "elements": [
                "chisel:sandstonered@4"
            ]
        },
        {
            "x": -11,
            "y": 0,
            "z": 13,
            "elements": [
                "railcraft:pearlized@0"
            ]
        },
        {
            "x": 0,
            "y": 0,
            "z": 19,
            "elements": [
                "railcraft:pearlized@0"
            ]
        },
        {
            "x": 11,
            "y": 1,
            "z": 16,
            "elements": [
                "railcraft:pearlized@0"
            ]
        },
        {
            "x": 11,
            "y": 1,
            "z": 17,
            "elements": [
                "biomesoplenty:blood@0"
            ]
        },
        {
            "x": -11,
            "y": 0,
            "z": 11,
            "elements": [
                "railcraft:pearlized@0"
            ]
        },
        {
            "x": 11,
            "y": 1,
            "z": 18,
            "elements": [
                "railcraft:pearlized@0"
            ]
        },
        {
            "x": -11,
            "y": 0,
            "z": 16,
            "elements": [
                "railcraft:pearlized@0"
            ]
        },
        {
            "x": 0,
            "y": 0,
            "z": 16,
            "elements": [
                "chisel:sandstonered@4"
            ]
        },
        {
            "x": 11,
            "y": 1,
            "z": 11,
            "elements": [
                "railcraft:pearlized@0"
            ]
        },
        {
            "x": -11,
            "y": 0,
            "z": 17,
            "elements": [
                "chisel:sandstonered@4"
            ]
        },
        {
            "x": 0,
            "y": 0,
            "z": 15,
            "elements": [
                "chisel:sandstonered@4"
            ]
        },
        {
            "x": 0,
            "y": 0,
            "z": 18,
            "elements": [
                "chisel:sandstonered@4"
            ]
        },
        {
            "x": 11,
            "y": 1,
            "z": 13,
            "elements": [
                "railcraft:pearlized@0"
            ]
        },
        {
            "x": 0,
            "y": 0,
            "z": 17,
            "elements": [
                "chisel:sandstonered@4"
            ]
        },
        {
            "x": 0,
            "y": 0,
            "z": 12,
            "elements": [
                "chisel:sandstonered@4"
            ]
        },
        {
            "x": 0,
            "y": 0,
            "z": 11,
            "elements": [
                "chisel:sandstonered@4"
            ]
        },
        {
            "x": -11,
            "y": 0,
            "z": 18,
            "elements": [
                "railcraft:pearlized@0"
            ]
        },
        {
            "x": 0,
            "y": 0,
            "z": 14,
            "elements": [
                "chisel:sandstonered@4"
            ]
        },
        {
            "x": 0,
            "y": 0,
            "z": 13,
            "elements": [
                "chisel:sandstonered@4"
            ]
        },
        {
            "x": 0,
            "y": 0,
            "z": 8,
            "elements": [
                "chisel:sandstonered@4"
            ]
        },
        {
            "x": 0,
            "y": 0,
            "z": 7,
            "elements": [
                "chisel:sandstonered@4"
            ]
        },
        {
            "x": -1,
            "y": -1,
            "z": -2,
            "elements": [
                "railcraft:pearlized@0"
            ]
        },
        {
            "x": 0,
            "y": 0,
            "z": 10,
            "elements": [
                "chisel:sandstonered@4"
            ]
        },
        {
            "x": -1,
            "y": -1,
            "z": -1,
            "elements": [
                "railcraft:pearlized@0"
            ]
        },
        {
            "x": 0,
            "y": 0,
            "z": 9,
            "elements": [
                "chisel:sandstonered@4"
            ]
        },
        {
            "x": 0,
            "y": 0,
            "z": 4,
            "elements": [
                "chisel:sandstonered@4"
            ]
        },
        {
            "x": -12,
            "y": -1,
            "z": 9,
            "elements": [
                "railcraft:pearlized@0"
            ]
        },
        {
            "x": 0,
            "y": 0,
            "z": 3,
            "elements": [
                "chisel:sandstonered@4"
            ]
        },
        {
            "x": 0,
            "y": 0,
            "z": 6,
            "elements": [
                "chisel:sandstonered@4"
            ]
        },
        {
            "x": -12,
            "y": -1,
            "z": 11,
            "elements": [
                "railcraft:pearlized@0"
            ]
        },
        {
            "x": 0,
            "y": 0,
            "z": 5,
            "elements": [
                "chisel:sandstonered@4"
            ]
        },
        {
            "x": 1,
            "y": 2,
            "z": 7,
            "elements": [
                "railcraft:pearlized@0"
            ]
        },
        {
            "x": 0,
            "y": 0,
            "z": 2,
            "elements": [
                "chisel:sandstonered@4"
            ]
        },
        {
            "x": -12,
            "y": -1,
            "z": 7,
            "elements": [
                "railcraft:pearlized@0"
            ]
        },
        {
            "x": 0,
            "y": 0,
            "z": 1,
            "elements": [
                "railcraft:pearlized@0"
            ]
        },
        {
            "x": -12,
            "y": -1,
            "z": 3,
            "elements": [
                "railcraft:pearlized@0"
            ]
        },
        {
            "x": -12,
            "y": -1,
            "z": 2,
            "elements": [
                "railcraft:pearlized@0"
            ]
        },
        {
            "x": -1,
            "y": 0,
            "z": -1,
            "elements": [
                "railcraft:pearlized@0"
            ]
        },
        {
            "x": -1,
            "y": 0,
            "z": -2,
            "elements": [
                "railcraft:pearlized@0"
            ]
        },
        {
            "x": 1,
            "y": 2,
            "z": 13,
            "elements": [
                "railcraft:pearlized@0"
            ]
        },
        {
            "x": 11,
            "y": 0,
            "z": 12,
            "elements": [
                "chisel:sandstonered@4"
            ]
        },
        {
            "x": 11,
            "y": 0,
            "z": 13,
            "elements": [
                "railcraft:pearlized@0"
            ]
        },
        {
            "x": 11,
            "y": 0,
            "z": 16,
            "elements": [
                "railcraft:pearlized@0"
            ]
        },
        {
            "x": 11,
            "y": 0,
            "z": 17,
            "elements": [
                "chisel:sandstonered@4"
            ]
        },
        {
            "x": 11,
            "y": 0,
            "z": 18,
            "elements": [
                "railcraft:pearlized@0"
            ]
        },
        {
            "x": 11,
            "y": 0,
            "z": 4,
            "elements": [
                "railcraft:pearlized@0"
            ]
        },
        {
            "x": 11,
            "y": 0,
            "z": 7,
            "elements": [
                "railcraft:pearlized@0"
            ]
        },
        {
            "x": 11,
            "y": 0,
            "z": 8,
            "elements": [
                "chisel:sandstonered@4"
            ]
        },
        {
            "x": 11,
            "y": 0,
            "z": 9,
            "elements": [
                "railcraft:pearlized@0"
            ]
        },
        {
            "x": 10,
            "y": -1,
            "z": 5,
            "elements": [
                "railcraft:pearlized@0"
            ]
        },
        {
            "x": 10,
            "y": -1,
            "z": 2,
            "elements": [
                "railcraft:pearlized@0"
            ]
        },
        {
            "x": 11,
            "y": 0,
            "z": 11,
            "elements": [
                "railcraft:pearlized@0"
            ]
        },
        {
            "x": 11,
            "y": 0,
            "z": 2,
            "elements": [
                "railcraft:pearlized@0"
            ]
        },
        {
            "x": 11,
            "y": 0,
            "z": 3,
            "elements": [
                "chisel:sandstonered@4"
            ]
        },
        {
            "x": -12,
            "y": 0,
            "z": 2,
            "elements": [
                "railcraft:pearlized@1"
            ]
        },
        {
            "x": -12,
            "y": 0,
            "z": 12,
            "elements": [
                "chisel:sandstonered@4"
            ]
        },
        {
            "x": 12,
            "y": 2,
            "z": 2,
            "elements": [
                "railcraft:pearlized@0"
            ]
        },
        {
            "x": -12,
            "y": 0,
            "z": 11,
            "elements": [
                "railcraft:pearlized@0"
            ]
        },
        {
            "x": -12,
            "y": 0,
            "z": 13,
            "elements": [
                "railcraft:pearlized@0"
            ]
        },
        {
            "x": 10,
            "y": -1,
            "z": 7,
            "elements": [
                "railcraft:pearlized@0"
            ]
        },
        {
            "x": 12,
            "y": 2,
            "z": 3,
            "elements": [
                "railcraft:pearlized@0"
            ]
        },
        {
            "x": -2,
            "y": -1,
            "z": -4,
            "elements": [
                "railcraft:pearlized@0"
            ]
        },
        {
            "x": 10,
            "y": -1,
            "z": 13,
            "elements": [
                "railcraft:pearlized@0"
            ]
        },
        {
            "x": -2,
            "y": -1,
            "z": -3,
            "elements": [
                "railcraft:pearlized@0"
            ]
        },
        {
            "x": -12,
            "y": 0,
            "z": 18,
            "elements": [
                "railcraft:pearlized@1"
            ]
        },
        {
            "x": 10,
            "y": -1,
            "z": 10,
            "elements": [
                "railcraft:pearlized@0"
            ]
        },
        {
            "x": -12,
            "y": 0,
            "z": 17,
            "elements": [
                "railcraft:pearlized@0"
            ]
        },
        {
            "x": -12,
            "y": 0,
            "z": 3,
            "elements": [
                "railcraft:pearlized@0"
            ]
        },
        {
            "x": 9,
            "y": 0,
            "z": 3,
            "elements": [
                "railcraft:pearlized@0"
            ]
        },
        {
            "x": 9,
            "y": 0,
            "z": 4,
            "elements": [
                "chisel:sandstonered@4"
            ]
        },
        {
            "x": 9,
            "y": 0,
            "z": 5,
            "elements": [
                "chisel:sandstonered@4"
            ]
        },
        {
            "x": 10,
            "y": -1,
            "z": 15,
            "elements": [
                "railcraft:pearlized@0"
            ]
        },
        {
            "x": -12,
            "y": 0,
            "z": 8,
            "elements": [
                "chisel:sandstonered@4"
            ]
        },
        {
            "x": -12,
            "y": 0,
            "z": 7,
            "elements": [
                "railcraft:pearlized@0"
            ]
        },
        {
            "x": 10,
            "y": -1,
            "z": 18,
            "elements": [
                "railcraft:pearlized@0"
            ]
        },
        {
            "x": -12,
            "y": 0,
            "z": 9,
            "elements": [
                "railcraft:pearlized@0"
            ]
        },
        {
            "x": -2,
            "y": -1,
            "z": 24,
            "elements": [
                "railcraft:pearlized@0"
            ]
        },
        {
            "x": -2,
            "y": -1,
            "z": 23,
            "elements": [
                "railcraft:pearlized@0"
            ]
        },
        {
            "x": -2,
            "y": 0,
            "z": 3,
            "elements": [
                "chisel:sandstonered@4"
            ]
        },
        {
            "x": -11,
            "y": 2,
            "z": 2,
            "elements": [
                "railcraft:pearlized@0"
            ]
        },
        {
            "x": -2,
            "y": 0,
            "z": 4,
            "elements": [
                "chisel:sandstonered@4"
            ]
        },
        {
            "x": -11,
            "y": 1,
            "z": 16,
            "elements": [
                "railcraft:pearlized@0"
            ]
        },
        {
            "x": -2,
            "y": 0,
            "z": 1,
            "elements": [
                "chisel:sandstonered@4"
            ]
        },
        {
            "x": -11,
            "y": 1,
            "z": 13,
            "elements": [
                "railcraft:pearlized@0"
            ]
        },
        {
            "x": -2,
            "y": 0,
            "z": 2,
            "elements": [
                "chisel:sandstonered@4"
            ]
        },
        {
            "x": -2,
            "y": 0,
            "z": 7,
            "elements": [
                "chisel:sandstonered@4"
            ]
        },
        {
            "x": 2,
            "y": 5,
            "z": 0,
            "elements": [
                "contenttweaker:radioactive_sentient_meatball@0"
            ]
        },
        {
            "x": 10,
            "y": 1,
            "z": 2,
            "elements": [
                "railcraft:pearlized@0"
            ]
        },
        {
            "x": -11,
            "y": 1,
            "z": 11,
            "elements": [
                "railcraft:pearlized@0"
            ]
        },
        {
            "x": -2,
            "y": 0,
            "z": 8,
            "elements": [
                "chisel:sandstonered@4"
            ]
        },
        {
            "x": -2,
            "y": 0,
            "z": 5,
            "elements": [
                "chisel:sandstonered@4"
            ]
        },
        {
            "x": 2,
            "y": 5,
            "z": 2,
            "elements": [
                "tconstruct:slime_congealed@3"
            ]
        },
        {
            "x": -11,
            "y": 1,
            "z": 9,
            "elements": [
                "railcraft:pearlized@0"
            ]
        },
        {
            "x": -11,
            "y": 2,
            "z": 4,
            "elements": [
                "railcraft:pearlized_slab@1"
            ]
        },
        {
            "x": -2,
            "y": 0,
            "z": 6,
            "elements": [
                "chisel:sandstonered@4"
            ]
        },
        {
            "x": -11,
            "y": 1,
            "z": 7,
            "elements": [
                "railcraft:pearlized@0"
            ]
        },
        {
            "x": -2,
            "y": 0,
            "z": -4,
            "elements": [
                "railcraft:pearlized@0"
            ]
        },
        {
            "x": 2,
            "y": 5,
            "z": -2,
            "elements": [
                "tconstruct:slime_congealed@3"
            ]
        },
        {
            "x": -2,
            "y": 0,
            "z": -1,
            "elements": [
                "chisel:sandstonered@4"
            ]
        },
        {
            "x": -11,
            "y": 1,
            "z": 3,
            "elements": [
                "biomesoplenty:blood@0"
            ]
        },
        {
            "x": -2,
            "y": 0,
            "z": 0,
            "elements": [
                "chisel:sandstonered@4"
            ]
        },
        {
            "x": -11,
            "y": 1,
            "z": 4,
            "elements": [
                "railcraft:pearlized@0"
            ]
        },
        {
            "x": -2,
            "y": 0,
            "z": -3,
            "elements": [
                "railcraft:pearlized@0"
            ]
        },
        {
            "x": -2,
            "y": 0,
            "z": -2,
            "elements": [
                "chisel:sandstonered@4"
            ]
        },
        {
            "x": -11,
            "y": 1,
            "z": 2,
            "elements": [
                "railcraft:pearlized@0"
            ]
        },
        {
            "x": -2,
            "y": 0,
            "z": 19,
            "elements": [
                "chisel:sandstonered@4"
            ]
        },
        {
            "x": 2,
            "y": 5,
            "z": 20,
            "elements": [
                "contenttweaker:all_powerful_sentient_meatball@0"
            ]
        },
        {
            "x": -2,
            "y": 0,
            "z": 20,
            "elements": [
                "chisel:sandstonered@4"
            ]
        },
        {
            "x": 10,
            "y": 1,
            "z": 15,
            "elements": [
                "railcraft:pearlized@0"
            ]
        },
        {
            "x": -2,
            "y": 0,
            "z": 17,
            "elements": [
                "chisel:sandstonered@4"
            ]
        },
        {
            "x": 2,
            "y": 5,
            "z": 22,
            "elements": [
                "tconstruct:slime_congealed@3"
            ]
        },
        {
            "x": -5,
            "y": 5,
            "z": 17,
            "elements": [
                "tconstruct:slime_congealed@3"
            ]
        },
        {
            "x": -2,
            "y": 0,
            "z": 18,
            "elements": [
                "chisel:sandstonered@4"
            ]
        },
        {
            "x": 10,
            "y": 1,
            "z": 13,
            "elements": [
                "railcraft:pearlized@0"
            ]
        },
        {
            "x": -2,
            "y": 0,
            "z": 23,
            "elements": [
                "railcraft:pearlized@0"
            ]
        },
        {
            "x": 10,
            "y": 1,
            "z": 18,
            "elements": [
                "railcraft:pearlized@0"
            ]
        },
        {
            "x": -2,
            "y": 0,
            "z": 24,
            "elements": [
                "railcraft:pearlized@0"
            ]
        },
        {
            "x": -2,
            "y": 0,
            "z": 21,
            "elements": [
                "chisel:sandstonered@4"
            ]
        },
        {
            "x": 2,
            "y": 5,
            "z": 18,
            "elements": [
                "tconstruct:slime_congealed@3"
            ]
        },
        {
            "x": -2,
            "y": 0,
            "z": 22,
            "elements": [
                "chisel:sandstonered@4"
            ]
        },
        {
            "x": 12,
            "y": 3,
            "z": 18,
            "elements": [
                "railcraft:pearlized_slab@1"
            ]
        },
        {
            "x": -2,
            "y": 0,
            "z": 11,
            "elements": [
                "chisel:sandstonered@4"
            ]
        },
        {
            "x": -2,
            "y": 0,
            "z": 12,
            "elements": [
                "chisel:sandstonered@4"
            ]
        },
        {
            "x": 10,
            "y": 1,
            "z": 7,
            "elements": [
                "railcraft:pearlized@0"
            ]
        },
        {
            "x": -2,
            "y": 0,
            "z": 9,
            "elements": [
                "chisel:sandstonered@4"
            ]
        },
        {
            "x": -2,
            "y": 0,
            "z": 10,
            "elements": [
                "chisel:sandstonered@4"
            ]
        },
        {
            "x": 10,
            "y": 1,
            "z": 5,
            "elements": [
                "railcraft:pearlized@0"
            ]
        },
        {
            "x": -2,
            "y": 0,
            "z": 15,
            "elements": [
                "chisel:sandstonered@4"
            ]
        },
        {
            "x": 10,
            "y": 1,
            "z": 10,
            "elements": [
                "railcraft:pearlized@0"
            ]
        },
        {
            "x": -2,
            "y": 0,
            "z": 16,
            "elements": [
                "chisel:sandstonered@4"
            ]
        },
        {
            "x": -2,
            "y": 0,
            "z": 13,
            "elements": [
                "chisel:sandstonered@4"
            ]
        },
        {
            "x": -11,
            "y": 1,
            "z": 17,
            "elements": [
                "biomesoplenty:blood@0"
            ]
        },
        {
            "x": -2,
            "y": 0,
            "z": 14,
            "elements": [
                "chisel:sandstonered@4"
            ]
        },
        {
            "x": -11,
            "y": 1,
            "z": 18,
            "elements": [
                "railcraft:pearlized@0"
            ]
        },
        {
            "x": 12,
            "y": 3,
            "z": 2,
            "elements": [
                "railcraft:pearlized_slab@1"
            ]
        },
        {
            "x": 9,
            "y": -1,
            "z": 17,
            "elements": [
                "railcraft:pearlized@0"
            ]
        },
        {
            "x": 0,
            "y": 1,
            "z": 19,
            "elements": [
                "railcraft:pearlized@0"
            ]
        },
        {
            "x": 0,
            "y": 1,
            "z": 20,
            "elements": [
                "railcraft:pearlized@0"
            ]
        },
        {
            "x": 9,
            "y": -1,
            "z": 7,
            "elements": [
                "railcraft:pearlized@0"
            ]
        },
        {
            "x": 9,
            "y": -1,
            "z": 10,
            "elements": [
                "railcraft:pearlized@0"
            ]
        },
        {
            "x": -13,
            "y": 0,
            "z": 8,
            "elements": [
                "railcraft:pearlized@0"
            ]
        },
        {
            "x": -13,
            "y": 0,
            "z": 7,
            "elements": [
                "railcraft:pearlized@0"
            ]
        },
        {
            "x": 9,
            "y": -1,
            "z": 14,
            "elements": [
                "railcraft:pearlized@0"
            ]
        },
        {
            "x": 9,
            "y": -1,
            "z": 13,
            "elements": [
                "railcraft:pearlized@0"
            ]
        },
        {
            "x": -12,
            "y": -1,
            "z": 17,
            "elements": [
                "railcraft:pearlized@0"
            ]
        },
        {
            "x": -12,
            "y": -1,
            "z": 18,
            "elements": [
                "railcraft:pearlized@0"
            ]
        },
        {
            "x": -12,
            "y": -1,
            "z": 13,
            "elements": [
                "railcraft:pearlized@0"
            ]
        },
        {
            "x": 9,
            "y": -1,
            "z": 3,
            "elements": [
                "railcraft:pearlized@0"
            ]
        },
        {
            "x": 9,
            "y": -1,
            "z": 6,
            "elements": [
                "railcraft:pearlized@0"
            ]
        },
        {
            "x": -1,
            "y": 2,
            "z": 7,
            "elements": [
                "railcraft:pearlized@0"
            ]
        },
        {
            "x": -1,
            "y": 2,
            "z": 13,
            "elements": [
                "railcraft:pearlized@0"
            ]
        },
        {
            "x": 6,
            "y": 5,
            "z": 19,
            "elements": [
                "contenttweaker:world_corrupting_sentient_meatball@0"
            ]
        },
        {
            "x": -13,
            "y": 0,
            "z": 13,
            "elements": [
                "railcraft:pearlized@0"
            ]
        },
        {
            "x": -13,
            "y": 0,
            "z": 12,
            "elements": [
                "railcraft:pearlized@0"
            ]
        },
        {
            "x": 0,
            "y": 1,
            "z": 9,
            "elements": [
                "chisel:sandstonered@4"
            ]
        },
        {
            "x": 0,
            "y": 1,
            "z": 8,
            "elements": [
                "railcraft:pearlized@0"
            ]
        },
        {
            "x": 0,
            "y": 1,
            "z": 11,
            "elements": [
                "chisel:sandstonered@4"
            ]
        },
        {
            "x": 0,
            "y": 1,
            "z": 10,
            "elements": [
                "chisel:sandstonered@4"
            ]
        },
        {
            "x": 0,
            "y": 1,
            "z": 12,
            "elements": [
                "railcraft:pearlized@0"
            ]
        },
        {
            "x": 0,
            "y": 1,
            "z": 1,
            "elements": [
                "railcraft:pearlized@0"
            ]
        },
        {
            "x": 0,
            "y": 1,
            "z": 0,
            "elements": [
                "railcraft:pearlized@0"
            ]
        },
        {
            "x": 6,
            "y": 5,
            "z": 1,
            "elements": [
                "contenttweaker:diabetic_sentient_meatball@0"
            ]
        },
        {
            "x": -12,
            "y": 2,
            "z": 2,
            "elements": [
                "railcraft:pearlized@0"
            ]
        },
        {
            "x": -12,
            "y": 2,
            "z": 3,
            "elements": [
                "railcraft:pearlized@0"
            ]
        },
        {
            "x": -12,
            "y": 2,
            "z": 17,
            "elements": [
                "railcraft:pearlized@0"
            ]
        },
        {
            "x": -12,
            "y": 2,
            "z": 18,
            "elements": [
                "railcraft:pearlized@0"
            ]
        },
        {
            "x": -6,
            "y": 2,
            "z": 21,
            "elements": [
                "railcraft:pearlized_slab@1"
            ]
        },
        {
            "x": -6,
            "y": 2,
            "z": 16,
            "elements": [
                "railcraft:pearlized_slab@1"
            ]
        },
        {
            "x": -5,
            "y": 5,
            "z": 3,
            "elements": [
                "tconstruct:slime_congealed@3"
            ]
        },
        {
            "x": 7,
            "y": 5,
            "z": 5,
            "elements": [
                "tconstruct:slime_congealed@3"
            ]
        },
        {
            "x": 7,
            "y": 5,
            "z": -1,
            "elements": [
                "tconstruct:slime_congealed@3"
            ]
        },
        {
            "x": 0,
            "y": 3,
            "z": 8,
            "elements": [
                "biomesoplenty:blood@0"
            ]
        },
        {
            "x": -11,
            "y": 2,
            "z": 18,
            "elements": [
                "railcraft:pearlized@0"
            ]
        },
        {
            "x": 0,
            "y": 3,
            "z": 12,
            "elements": [
                "biomesoplenty:blood@0"
            ]
        },
        {
            "x": -11,
            "y": 2,
            "z": 16,
            "elements": [
                "railcraft:pearlized_slab@1"
            ]
        },
        {
            "x": 7,
            "y": 5,
            "z": 21,
            "elements": [
                "tconstruct:slime_congealed@3"
            ]
        },
        {
            "x": 7,
            "y": 5,
            "z": 15,
            "elements": [
                "tconstruct:slime_congealed@3"
            ]
        },
        {
            "x": -1,
            "y": 1,
            "z": 22,
            "elements": [
                "railcraft:pearlized@0"
            ]
        },
        {
            "x": -1,
            "y": 1,
            "z": 21,
            "elements": [
                "railcraft:pearlized@0"
            ]
        },
        {
            "x": 12,
            "y": 5,
            "z": 12,
            "elements": [
                "tconstruct:slime_congealed@3"
            ]
        },
        {
            "x": 12,
            "y": 5,
            "z": 8,
            "elements": [
                "tconstruct:slime_congealed@3"
            ]
        },
        {
            "x": -7,
            "y": 0,
            "z": 22,
            "elements": [
                "railcraft:pearlized@0"
            ]
        },
        {
            "x": -1,
            "y": 1,
            "z": 13,
            "elements": [
                "railcraft:pearlized@0"
            ]
        },
        {
            "x": -1,
            "y": 1,
            "z": 12,
            "elements": [
                "chisel:sandstonered@4"
            ]
        },
        {
            "x": -1,
            "y": 1,
            "z": 11,
            "elements": [
                "chisel:sandstonered@4"
            ]
        },
        {
            "x": -1,
            "y": 1,
            "z": 10,
            "elements": [
                "chisel:sandstonered@4"
            ]
        },
        {
            "x": -1,
            "y": 1,
            "z": 9,
            "elements": [
                "chisel:sandstonered@4"
            ]
        },
        {
            "x": -1,
            "y": 1,
            "z": 8,
            "elements": [
                "chisel:sandstonered@4"
            ]
        },
        {
            "x": -1,
            "y": 1,
            "z": 7,
            "elements": [
                "railcraft:pearlized@0"
            ]
        },
        {
            "x": -7,
            "y": 0,
            "z": -1,
            "elements": [
                "chisel:sandstonered@4"
            ]
        },
        {
            "x": -13,
            "y": -1,
            "z": 8,
            "elements": [
                "railcraft:pearlized@0"
            ]
        },
        {
            "x": -7,
            "y": 0,
            "z": -2,
            "elements": [
                "railcraft:pearlized@0"
            ]
        },
        {
            "x": -13,
            "y": -1,
            "z": 7,
            "elements": [
                "railcraft:pearlized@0"
            ]
        },
        {
            "x": -7,
            "y": 0,
            "z": 1,
            "elements": [
                "railcraft:pearlized@0"
            ]
        },
        {
            "x": 0,
            "y": 2,
            "z": 12,
            "elements": [
                "railcraft:pearlized@0"
            ]
        },
        {
            "x": -7,
            "y": 0,
            "z": 0,
            "elements": [
                "chisel:sandstonered@4"
            ]
        },
        {
            "x": -6,
            "y": 1,
            "z": 16,
            "elements": [
                "railcraft:pearlized@0"
            ]
        },
        {
            "x": -7,
            "y": 0,
            "z": 3,
            "elements": [
                "railcraft:pearlized@0"
            ]
        },
        {
            "x": -13,
            "y": -1,
            "z": 12,
            "elements": [
                "railcraft:pearlized@0"
            ]
        },
        {
            "x": -7,
            "y": 0,
            "z": 2,
            "elements": [
                "railcraft:pearlized@0"
            ]
        },
        {
            "x": -7,
            "y": 0,
            "z": 5,
            "elements": [
                "chisel:sandstonered@4"
            ]
        },
        {
            "x": 0,
            "y": 2,
            "z": 8,
            "elements": [
                "railcraft:pearlized@0"
            ]
        },
        {
            "x": -7,
            "y": 0,
            "z": 4,
            "elements": [
                "chisel:sandstonered@4"
            ]
        },
        {
            "x": -13,
            "y": -1,
            "z": 13,
            "elements": [
                "railcraft:pearlized@0"
            ]
        },
        {
            "x": 0,
            "y": 2,
            "z": 19,
            "elements": [
                "railcraft:pearlized_slab@1"
            ]
        },
        {
            "x": -6,
            "y": 1,
            "z": 4,
            "elements": [
                "railcraft:pearlized@0"
            ]
        },
        {
            "x": -7,
            "y": 0,
            "z": 15,
            "elements": [
                "chisel:sandstonered@4"
            ]
        },
        {
            "x": -7,
            "y": 0,
            "z": 14,
            "elements": [
                "chisel:sandstonered@4"
            ]
        },
        {
            "x": -7,
            "y": 0,
            "z": 17,
            "elements": [
                "railcraft:pearlized@0"
            ]
        },
        {
            "x": -7,
            "y": 0,
            "z": 16,
            "elements": [
                "chisel:sandstonered@4"
            ]
        },
        {
            "x": -7,
            "y": 0,
            "z": 19,
            "elements": [
                "railcraft:pearlized@0"
            ]
        },
        {
            "x": -7,
            "y": 0,
            "z": 18,
            "elements": [
                "railcraft:pearlized@0"
            ]
        },
        {
            "x": -7,
            "y": 0,
            "z": 21,
            "elements": [
                "chisel:sandstonered@4"
            ]
        },
        {
            "x": -7,
            "y": 0,
            "z": 20,
            "elements": [
                "chisel:sandstonered@4"
            ]
        },
        {
            "x": -1,
            "y": 1,
            "z": -1,
            "elements": [
                "railcraft:pearlized@0"
            ]
        },
        {
            "x": -7,
            "y": 0,
            "z": 7,
            "elements": [
                "chisel:sandstonered@4"
            ]
        },
        {
            "x": -1,
            "y": 1,
            "z": -2,
            "elements": [
                "railcraft:pearlized@0"
            ]
        },
        {
            "x": -7,
            "y": 0,
            "z": 6,
            "elements": [
                "chisel:sandstonered@4"
            ]
        },
        {
            "x": 0,
            "y": 2,
            "z": 1,
            "elements": [
                "railcraft:pearlized_slab@1"
            ]
        },
        {
            "x": -7,
            "y": 0,
            "z": 9,
            "elements": [
                "chisel:sandstonered@4"
            ]
        },
        {
            "x": -7,
            "y": 0,
            "z": 8,
            "elements": [
                "chisel:sandstonered@4"
            ]
        },
        {
            "x": -7,
            "y": 0,
            "z": 11,
            "elements": [
                "chisel:sandstonered@4"
            ]
        },
        {
            "x": -7,
            "y": 0,
            "z": 10,
            "elements": [
                "chisel:sandstonered@4"
            ]
        },
        {
            "x": -7,
            "y": 0,
            "z": 13,
            "elements": [
                "chisel:sandstonered@4"
            ]
        },
        {
            "x": -6,
            "y": 1,
            "z": 21,
            "elements": [
                "railcraft:pearlized@0"
            ]
        },
        {
            "x": -7,
            "y": 0,
            "z": 12,
            "elements": [
                "chisel:sandstonered@4"
            ]
        },
        {
            "x": -7,
            "y": -1,
            "z": 19,
            "elements": [
                "railcraft:pearlized@0"
            ]
        },
        {
            "x": -7,
            "y": -1,
            "z": 22,
            "elements": [
                "railcraft:pearlized@0"
            ]
        },
        {
            "x": -7,
            "y": -1,
            "z": 18,
            "elements": [
                "railcraft:pearlized@0"
            ]
        },
        {
            "x": -7,
            "y": -1,
            "z": 17,
            "elements": [
                "railcraft:pearlized@0"
            ]
        },
        {
            "x": -1,
            "y": 0,
            "z": 3,
            "elements": [
                "chisel:sandstonered@4"
            ]
        },
        {
            "x": -1,
            "y": 0,
            "z": 2,
            "elements": [
                "chisel:sandstonered@4"
            ]
        },
        {
            "x": -1,
            "y": 0,
            "z": 1,
            "elements": [
                "chisel:sandstonered@4"
            ]
        },
        {
            "x": -12,
            "y": 1,
            "z": 17,
            "elements": [
                "railcraft:pearlized@0"
            ]
        },
        {
            "x": -6,
            "y": 2,
            "z": 4,
            "elements": [
                "railcraft:pearlized_slab@1"
            ]
        },
        {
            "x": -1,
            "y": 0,
            "z": 0,
            "elements": [
                "chisel:sandstonered@4"
            ]
        },
        {
            "x": -1,
            "y": 0,
            "z": 7,
            "elements": [
                "chisel:sandstonered@4"
            ]
        },
        {
            "x": -4,
            "y": 6,
            "z": 14,
            "elements": [
                "tconstruct:slime_congealed@3"
            ]
        },
        {
            "x": -12,
            "y": 1,
            "z": 11,
            "elements": [
                "railcraft:pearlized@0"
            ]
        },
        {
            "x": -1,
            "y": 0,
            "z": 6,
            "elements": [
                "chisel:sandstonered@4"
            ]
        },
        {
            "x": -1,
            "y": 0,
            "z": 5,
            "elements": [
                "chisel:sandstonered@4"
            ]
        },
        {
            "x": 5,
            "y": 1,
            "z": 0,
            "elements": [
                "railcraft:pearlized@0"
            ]
        },
        {
            "x": -12,
            "y": 1,
            "z": 13,
            "elements": [
                "railcraft:pearlized@0"
            ]
        },
        {
            "x": -1,
            "y": 0,
            "z": 4,
            "elements": [
                "chisel:sandstonered@4"
            ]
        },
        {
            "x": -12,
            "y": 1,
            "z": 12,
            "elements": [
                "biomesoplenty:blood@0"
            ]
        },
        {
            "x": -1,
            "y": 0,
            "z": 11,
            "elements": [
                "chisel:sandstonered@4"
            ]
        },
        {
            "x": -1,
            "y": 0,
            "z": 10,
            "elements": [
                "chisel:sandstonered@4"
            ]
        },
        {
            "x": -1,
            "y": 0,
            "z": 9,
            "elements": [
                "chisel:sandstonered@4"
            ]
        },
        {
            "x": -1,
            "y": 0,
            "z": 8,
            "elements": [
                "chisel:sandstonered@4"
            ]
        },
        {
            "x": -1,
            "y": 0,
            "z": 15,
            "elements": [
                "chisel:sandstonered@4"
            ]
        },
        {
            "x": -4,
            "y": 6,
            "z": 6,
            "elements": [
                "tconstruct:slime_congealed@3"
            ]
        },
        {
            "x": -1,
            "y": 0,
            "z": 14,
            "elements": [
                "chisel:sandstonered@4"
            ]
        },
        {
            "x": -12,
            "y": 1,
            "z": 18,
            "elements": [
                "railcraft:pearlized@1"
            ]
        },
        {
            "x": -1,
            "y": 0,
            "z": 13,
            "elements": [
                "chisel:sandstonered@4"
            ]
        },
        {
            "x": -1,
            "y": 0,
            "z": 12,
            "elements": [
                "chisel:sandstonered@4"
            ]
        },
        {
            "x": -6,
            "y": 2,
            "z": -1,
            "elements": [
                "railcraft:pearlized_slab@1"
            ]
        },
        {
            "x": -1,
            "y": 0,
            "z": 19,
            "elements": [
                "chisel:sandstonered@4"
            ]
        },
        {
            "x": -1,
            "y": 0,
            "z": 18,
            "elements": [
                "chisel:sandstonered@4"
            ]
        },
        {
            "x": -1,
            "y": 0,
            "z": 17,
            "elements": [
                "chisel:sandstonered@4"
            ]
        },
        {
            "x": -1,
            "y": 0,
            "z": 16,
            "elements": [
                "chisel:sandstonered@4"
            ]
        },
        {
            "x": -10,
            "y": 5,
            "z": 8,
            "elements": [
                "contenttweaker:gambling_sentient_meatball@0"
            ]
        },
        {
            "x": -1,
            "y": 0,
            "z": 22,
            "elements": [
                "railcraft:pearlized@0"
            ]
        },
        {
            "x": -1,
            "y": 0,
            "z": 21,
            "elements": [
                "railcraft:pearlized@0"
            ]
        },
        {
            "x": -1,
            "y": 0,
            "z": 20,
            "elements": [
                "chisel:sandstonered@4"
            ]
        },
        {
            "x": -12,
            "y": 1,
            "z": 7,
            "elements": [
                "railcraft:pearlized@0"
            ]
        },
        {
            "x": 10,
            "y": 0,
            "z": 17,
            "elements": [
                "chisel:sandstonered@4"
            ]
        },
        {
            "x": -12,
            "y": 1,
            "z": 9,
            "elements": [
                "railcraft:pearlized@0"
            ]
        },
        {
            "x": 10,
            "y": 0,
            "z": 18,
            "elements": [
                "railcraft:pearlized@0"
            ]
        },
        {
            "x": -12,
            "y": 1,
            "z": 8,
            "elements": [
                "biomesoplenty:blood@0"
            ]
        },
        {
            "x": 10,
            "y": 0,
            "z": 15,
            "elements": [
                "railcraft:pearlized@0"
            ]
        },
        {
            "x": -12,
            "y": 1,
            "z": 3,
            "elements": [
                "railcraft:pearlized@0"
            ]
        },
        {
            "x": 10,
            "y": 0,
            "z": 16,
            "elements": [
                "chisel:sandstonered@4"
            ]
        },
        {
            "x": -12,
            "y": 1,
            "z": 2,
            "elements": [
                "railcraft:pearlized@1"
            ]
        },
        {
            "x": 10,
            "y": 0,
            "z": 13,
            "elements": [
                "railcraft:pearlized@0"
            ]
        },
        {
            "x": -10,
            "y": 5,
            "z": 12,
            "elements": [
                "contenttweaker:all_seeing_sentient_meatball@0"
            ]
        },
        {
            "x": 10,
            "y": 0,
            "z": 11,
            "elements": [
                "chisel:sandstonered@4"
            ]
        },
        {
            "x": 11,
            "y": 2,
            "z": 18,
            "elements": [
                "railcraft:pearlized@0"
            ]
        },
        {
            "x": 10,
            "y": 0,
            "z": 12,
            "elements": [
                "chisel:sandstonered@4"
            ]
        },
        {
            "x": 10,
            "y": 0,
            "z": 9,
            "elements": [
                "chisel:sandstonered@4"
            ]
        },
        {
            "x": 10,
            "y": 0,
            "z": 10,
            "elements": [
                "generalized_output_item"
            ]
        },
        {
            "x": 10,
            "y": 0,
            "z": 7,
            "elements": [
                "railcraft:pearlized@0"
            ]
        },
        {
            "x": 10,
            "y": 0,
            "z": 8,
            "elements": [
                "chisel:sandstonered@4"
            ]
        },
        {
            "x": 10,
            "y": 0,
            "z": 5,
            "elements": [
                "railcraft:pearlized@0"
            ]
        },
        {
            "x": 10,
            "y": 0,
            "z": 3,
            "elements": [
                "chisel:sandstonered@4"
            ]
        },
        {
            "x": 10,
            "y": 0,
            "z": 4,
            "elements": [
                "chisel:sandstonered@4"
            ]
        },
        {
            "x": 5,
            "y": 1,
            "z": 20,
            "elements": [
                "railcraft:pearlized@0"
            ]
        },
        {
            "x": 10,
            "y": 0,
            "z": 2,
            "elements": [
                "railcraft:pearlized@0"
            ]
        },
        {
            "x": 4,
            "y": -1,
            "z": 19,
            "elements": [
                "railcraft:pearlized@0"
            ]
        },
        {
            "x": 11,
            "y": 2,
            "z": 2,
            "elements": [
                "railcraft:pearlized@0"
            ]
        },
        {
            "x": 11,
            "y": 2,
            "z": 4,
            "elements": [
                "railcraft:pearlized_slab@1"
            ]
        },
        {
            "x": 4,
            "y": -1,
            "z": 1,
            "elements": [
                "railcraft:pearlized@0"
            ]
        },
        {
            "x": 11,
            "y": 2,
            "z": 16,
            "elements": [
                "railcraft:pearlized_slab@1"
            ]
        },
        {
            "x": -4,
            "y": 2,
            "z": 6,
            "elements": [
                "railcraft:pearlized@0"
            ]
        },
        {
            "x": -3,
            "y": 3,
            "z": 25,
            "elements": [
                "railcraft:pearlized_slab@1"
            ]
        },
        {
            "x": -1,
            "y": 6,
            "z": 7,
            "elements": [
                "tconstruct:slime_congealed@3"
            ]
        },
        {
            "x": 15,
            "y": -1,
            "z": 13,
            "elements": [
                "railcraft:pearlized@0"
            ]
        },
        {
            "x": -4,
            "y": 2,
            "z": 14,
            "elements": [
                "railcraft:pearlized@0"
            ]
        },
        {
            "x": -5,
            "y": 1,
            "z": 0,
            "elements": [
                "railcraft:pearlized@0"
            ]
        },
        {
            "x": -5,
            "y": 1,
            "z": 20,
            "elements": [
                "railcraft:pearlized@0"
            ]
        },
        {
            "x": -6,
            "y": -1,
            "z": 21,
            "elements": [
                "railcraft:pearlized@0"
            ]
        },
        {
            "x": -1,
            "y": 6,
            "z": 13,
            "elements": [
                "tconstruct:slime_congealed@3"
            ]
        },
        {
            "x": 15,
            "y": -1,
            "z": 7,
            "elements": [
                "railcraft:pearlized@0"
            ]
        },
        {
            "x": -6,
            "y": -1,
            "z": 16,
            "elements": [
                "railcraft:pearlized@0"
            ]
        },
        {
            "x": -6,
            "y": -1,
            "z": 4,
            "elements": [
                "railcraft:pearlized@0"
            ]
        },
        {
            "x": -6,
            "y": -1,
            "z": -1,
            "elements": [
                "railcraft:pearlized@0"
            ]
        },
        {
            "x": -5,
            "y": 0,
            "z": 1,
            "elements": [
                "chisel:sandstonered@4"
            ]
        },
        {
            "x": -5,
            "y": 0,
            "z": 0,
            "elements": [
                "railcraft:pearlized@0"
            ]
        },
        {
            "x": -5,
            "y": 0,
            "z": 3,
            "elements": [
                "chisel:sandstonered@4"
            ]
        },
        {
            "x": -5,
            "y": 0,
            "z": 2,
            "elements": [
                "chisel:sandstonered@4"
            ]
        },
        {
            "x": -7,
            "y": -1,
            "z": 3,
            "elements": [
                "railcraft:pearlized@0"
            ]
        },
        {
            "x": -7,
            "y": -1,
            "z": 2,
            "elements": [
                "railcraft:pearlized@0"
            ]
        },
        {
            "x": -7,
            "y": -1,
            "z": 1,
            "elements": [
                "railcraft:pearlized@0"
            ]
        },
        {
            "x": -7,
            "y": -1,
            "z": -2,
            "elements": [
                "railcraft:pearlized@0"
            ]
        },
        {
            "x": -3,
            "y": 3,
            "z": -5,
            "elements": [
                "railcraft:pearlized_slab@1"
            ]
        },
        {
            "x": -2,
            "y": 5,
            "z": 0,
            "elements": [
                "contenttweaker:tainted_sentient_meatball@0"
            ]
        },
        {
            "x": -2,
            "y": 5,
            "z": 2,
            "elements": [
                "tconstruct:slime_congealed@3"
            ]
        },
        {
            "x": -2,
            "y": 5,
            "z": -2,
            "elements": [
                "tconstruct:slime_congealed@3"
            ]
        },
        {
            "x": -5,
            "y": 0,
            "z": 20,
            "elements": [
                "railcraft:pearlized@0"
            ]
        },
        {
            "x": -5,
            "y": 0,
            "z": 17,
            "elements": [
                "chisel:sandstonered@4"
            ]
        },
        {
            "x": -5,
            "y": 0,
            "z": 16,
            "elements": [
                "chisel:sandstonered@4"
            ]
        },
        {
            "x": -5,
            "y": 0,
            "z": 19,
            "elements": [
                "chisel:sandstonered@4"
            ]
        },
        {
            "x": -5,
            "y": 0,
            "z": 18,
            "elements": [
                "chisel:sandstonered@4"
            ]
        },
        {
            "x": -2,
            "y": 5,
            "z": 18,
            "elements": [
                "tconstruct:slime_congealed@3"
            ]
        },
        {
            "x": -5,
            "y": 0,
            "z": 13,
            "elements": [
                "chisel:sandstonered@4"
            ]
        },
        {
            "x": -6,
            "y": 1,
            "z": -1,
            "elements": [
                "railcraft:pearlized@0"
            ]
        },
        {
            "x": -5,
            "y": 0,
            "z": 12,
            "elements": [
                "chisel:sandstonered@4"
            ]
        },
        {
            "x": -5,
            "y": 0,
            "z": 15,
            "elements": [
                "chisel:sandstonered@4"
            ]
        },
        {
            "x": -5,
            "y": 0,
            "z": 14,
            "elements": [
                "chisel:sandstonered@4"
            ]
        },
        {
            "x": -5,
            "y": 0,
            "z": 9,
            "elements": [
                "chisel:sandstonered@4"
            ]
        },
        {
            "x": -5,
            "y": 0,
            "z": 8,
            "elements": [
                "chisel:sandstonered@4"
            ]
        },
        {
            "x": -5,
            "y": 0,
            "z": 11,
            "elements": [
                "chisel:sandstonered@4"
            ]
        },
        {
