{
    "registryname": "thaumic_replicator",
    "localizedname": "Thaumic Replicator",
	"color": "ffffff",
    "modifiers": [
        {
            "elements": "contenttweaker:halite_bejewelled_ichorium_catalyst",
            "x": 0,
            "y": 2,
            "z": 0,
            "description": "Multiplies fluid produced by 2",
            "modifiers": [{
                "io": "output",
                "target": "modularmachinery:fluid",
                "operation": 1,
                "multiplier": 2
            }]
        },
        {
            "elements": "contenttweaker:catalyst_of_the_warrens",
            "x": 0,
            "y": 2,
            "z": 0,
            "description": "10X output, 10X speed",
            "modifiers": [{
                "io": "output",
                "target": "modularmachinery:fluid",
                "operation": 1,
                "multiplier": 10
            },
            {
                "io": "input",
                "target": "modularmachinery:duration",
                "operation": 1,
                "multiplier": 0.1
            }]
        },
        {
            "elements": "contenttweaker:trinuum_catalyst",
            "x": 0,
            "y": 2,
            "z": 0,
            "description": "50X output, 20X speed",
            "modifiers": [{
                "io": "output",
                "target": "modularmachinery:fluid",
                "operation": 1,
                "multiplier": 50
            },
            {
                "io": "input",
                "target": "modularmachinery:duration",
                "operation": 1,
                "multiplier": 0.05
            }]
        },
        {
            "elements": "contenttweaker:infinitely_wishful_catalyst",
            "x": 0,
            "y": 2,
            "z": 0,
            "description": "100X output, 40X speed",
            "modifiers": [{
                "io": "output",
                "target": "modularmachinery:fluid",
                "operation": 1,
                "multiplier": 100
            },
            {
                "io": "input",
                "target": "modularmachinery:duration",
                "operation": 1,
                "multiplier": 0.025
            }]
        }
    ],
    "parts": [
        {
            "x": -1,
            "y": 0,
            "z": 2,
            "elements": [
                "thaumadditions:taintwood_planks@0"
            ]
        },
        {
            "x": -1,
            "y": 0,
            "z": 1,
            "elements": [
                "twilightforest:castle_brick@0"
            ]
        },
        {
            "x": 1,
            "y": 0,
            "z": 2,
            "elements": [
                "thaumadditions:taintwood_planks@0"
            ]
        },
        {
            "x": -1,
            "y": 0,
            "z": 0,
            "elements": [
                "thaumadditions:taintwood_planks@0"
            ]
        },
        {
            "x": 0,
            "y": 3,
            "z": 1,
            "elements": [
                "twilightforest:castle_brick@0"
            ]
        },
        {
            "x": 1,
            "y": 0,
            "z": 1,
            "elements": [
                "twilightforest:castle_brick@0"
            ]
        },
        {
            "x": 1,
            "y": 0,
            "z": 0,
            "elements": [
                "thaumadditions:taintwood_planks@0"
            ]
        },
        {
            "x": 0,
            "y": 3,
            "z": 0,
            "elements": [
                "twilightforest:castle_brick@0"
            ]
        },
        {
            "x": 0,
            "y": 3,
            "z": 2,
            "elements": [
                "generalized_input_item"
            ]
        },
        {
            "x": 1,
            "y": 1,
            "z": 0,
            "elements": [
                "thaumadditions:taintwood_planks@0"
            ]
        },
        {
            "x": 1,
            "y": 1,
            "z": 2,
            "elements": [
                "thaumadditions:taintwood_planks@0"
            ]
        },
        {
            "x": 1,
            "y": 1,
            "z": 1,
            "elements": [
                "twilightforest:castle_brick@0"
            ]
        },
        {
            "x": -1,
            "y": 1,
            "z": 2,
            "elements": [
                "thaumadditions:taintwood_planks@0"
            ]
        },
        {
            "x": -1,
            "y": 1,
            "z": 1,
            "elements": [
                "twilightforest:castle_brick@0"
            ]
        },
        {
            "x": -1,
            "y": 1,
            "z": 0,
            "elements": [
                "thaumadditions:taintwood_planks@0"
            ]
        },
        {
            "x": 0,
            "y": 2,
            "z": 2,
            "elements": [
                "generalized_input_fluid"
            ]
        },
        {
            "x": 0,
            "y": 2,
            "z": 1,
            "elements": [
                "twilightforest:castle_brick@0"
            ]
        },
        {
            "x": 0,
            "y": 2,
            "z": 0,
            "elements": [
                "thaumadditions:adaminite_block@0"
            ]
        },
        {
            "x": 1,
            "y": 3,
            "z": 1,
            "elements": [
                "twilightforest:castle_brick@0"
            ]
        },
        {
            "x": 1,
            "y": 3,
            "z": 2,
            "elements": [
                "thaumadditions:taintwood_planks@0"
            ]
        },
        {
            "x": 0,
            "y": 0,
            "z": 2,
            "elements": [
				"generalized_input_essentia"
            ]
        },
        {
            "x": 0,
            "y": 0,
            "z": 1,
            "elements": [
                "generalized_output_fluid"
            ]
        },
        {
            "x": 1,
            "y": 3,
            "z": 0,
            "elements": [
                "thaumadditions:taintwood_planks@0"
            ]
        },
        {
            "x": -1,
            "y": 2,
            "z": 1,
            "elements": [
                "twilightforest:castle_brick@0"
            ]
        },
        {
            "x": 1,
            "y": 2,
            "z": 2,
            "elements": [
                "thaumadditions:taintwood_planks@0"
            ]
        },
        {
            "x": -1,
            "y": 2,
            "z": 0,
            "elements": [
                "thaumadditions:taintwood_planks@0"
            ]
        },
        {
            "x": 1,
            "y": 2,
            "z": 1,
            "elements": [
                "twilightforest:castle_brick@0"
            ]
        },
        {
            "x": -1,
            "y": 3,
            "z": 2,
            "elements": [
                "thaumadditions:taintwood_planks@0"
            ]
        },
        {
            "x": 1,
            "y": 2,
            "z": 0,
            "elements": [
                "thaumadditions:taintwood_planks@0"
            ]
        },
        {
            "x": -1,
            "y": 3,
            "z": 1,
            "elements": [
                "twilightforest:castle_brick@0"
            ]
        },
        {
            "x": -1,
            "y": 3,
            "z": 0,
            "elements": [
                "thaumadditions:taintwood_planks@0"
            ]
        },
        {
            "x": -1,
            "y": 2,
            "z": 2,
            "elements": [
                "thaumadditions:taintwood_planks@0"
            ]
        },
        {
            "x": 0,
            "y": 1,
            "z": 1,
            "elements": [
                "twilightforest:castle_brick@0"
            ]
        },
        {
            "x": 0,
            "y": 1,
            "z": 0,
            "elements": [
                "twilightforest:castle_brick@0"
            ]
        },
        {
            "x": 0,
            "y": 1,
            "z": 2,
            "elements": [
                "generalized_input_fluid"
            ]
        }
    ]}