
{
    "registryname": "the_cube",
    "localizedname": "The CUBE",
	"color": "787878",
    "parts": [
        {
            "x": 1,
            "y": -5,
            "z": 7,
            "elements": [
                "actuallyadditions:block_misc@9"
            ]
        },
        {
            "x": 1,
            "y": -5,
            "z": 8,
            "elements": [
                "twilightforest:aurora_block@0"
            ]
        },
        {
            "x": 1,
            "y": -5,
            "z": 3,
            "elements": [
                "actuallyadditions:block_misc@9"
            ]
        },
        {
            "x": 1,
            "y": -5,
            "z": 4,
            "elements": [
                "actuallyadditions:block_misc@9"
            ]
        },
        {
            "x": 1,
            "y": -5,
            "z": 5,
            "elements": [
                "actuallyadditions:block_misc@9"
            ]
        },
        {
            "x": 1,
            "y": -5,
            "z": 6,
            "elements": [
                "actuallyadditions:block_misc@9"
            ]
        },
        {
            "x": 1,
            "y": -5,
            "z": -1,
            "elements": [
                "actuallyadditions:block_misc@9"
            ]
        },
        {
            "x": 0,
            "y": -6,
            "z": -5,
            "elements": [
                "twilightforest:aurora_block@0"
            ]
        },
        {
            "x": 1,
            "y": -5,
            "z": 0,
            "elements": [
                "actuallyadditions:block_misc@9"
            ]
        },
        {
            "x": 0,
            "y": -6,
            "z": -4,
            "elements": [
                "twilightforest:aurora_block@0"
            ]
        },
        {
            "x": 1,
            "y": -5,
            "z": 1,
            "elements": [
                "actuallyadditions:block_misc@9"
            ]
        },
        {
            "x": 1,
            "y": -5,
            "z": 2,
            "elements": [
                "actuallyadditions:block_misc@9"
            ]
        },
        {
            "x": 0,
            "y": -6,
            "z": -6,
            "elements": [
                "twilightforest:aurora_block@0"
            ]
        },
        {
            "x": 1,
            "y": -5,
            "z": -5,
            "elements": [
                "actuallyadditions:block_misc@9"
            ]
        },
        {
            "x": 1,
            "y": -5,
            "z": -4,
            "elements": [
                "actuallyadditions:block_misc@9"
            ]
        },
        {
            "x": 1,
            "y": -5,
            "z": -3,
            "elements": [
                "actuallyadditions:block_misc@9"
            ]
        },
        {
            "x": 1,
            "y": -5,
            "z": -2,
            "elements": [
                "actuallyadditions:block_misc@9"
            ]
        },
        {
            "x": 1,
            "y": -5,
            "z": -6,
            "elements": [
                "twilightforest:aurora_block@0"
            ]
        },
        {
            "x": 7,
            "y": 3,
            "z": 2,
            "elements": [
                "twilightforest:aurora_block@0"
            ]
        },
        {
            "x": 7,
            "y": 3,
            "z": 1,
            "elements": [
                "twilightforest:aurora_block@0"
            ]
        },
        {
            "x": 7,
            "y": 3,
            "z": 4,
            "elements": [
                "twilightforest:aurora_block@0"
            ]
        },
        {
            "x": 7,
            "y": 3,
            "z": 3,
            "elements": [
                "twilightforest:aurora_block@0"
            ]
        },
        {
            "x": 7,
            "y": 3,
            "z": -2,
            "elements": [
                "twilightforest:aurora_block@0"
            ]
        },
        {
            "x": 7,
            "y": 3,
            "z": -3,
            "elements": [
                "twilightforest:aurora_block@0"
            ]
        },
        {
            "x": 3,
            "y": -3,
            "z": 8,
            "elements": [
                "twilightforest:aurora_block@0"
            ]
        },
        {
            "x": 7,
            "y": 3,
            "z": 0,
            "elements": [
                "twilightforest:aurora_block@0"
            ]
        },
        {
            "x": 7,
            "y": 3,
            "z": -1,
            "elements": [
                "twilightforest:aurora_block@0"
            ]
        },
        {
            "x": 3,
            "y": -3,
            "z": 7,
            "elements": [
                "actuallyadditions:block_misc@9"
            ]
        },
        {
            "x": 7,
            "y": 3,
            "z": 6,
            "elements": [
                "twilightforest:aurora_block@0"
            ]
        },
        {
            "x": 7,
            "y": 3,
            "z": 5,
            "elements": [
                "twilightforest:aurora_block@0"
            ]
        },
        {
            "x": 7,
            "y": 3,
            "z": 8,
            "elements": [
                "twilightforest:aurora_block@0"
            ]
        },
        {
            "x": 7,
            "y": 3,
            "z": 7,
            "elements": [
                "twilightforest:aurora_block@0"
            ]
        },
        {
            "x": 7,
            "y": 3,
            "z": -6,
            "elements": [
                "twilightforest:aurora_block@0"
            ]
        },
        {
            "x": 7,
            "y": 3,
            "z": -4,
            "elements": [
                "twilightforest:aurora_block@0"
            ]
        },
        {
            "x": 7,
            "y": 3,
            "z": -5,
            "elements": [
                "twilightforest:aurora_block@0"
            ]
        },
        {
            "x": 4,
            "y": -2,
            "z": -6,
            "elements": [
                "twilightforest:aurora_block@0"
            ]
        },
        {
            "x": 4,
            "y": -2,
            "z": -5,
            "elements": [
                "actuallyadditions:block_misc@9"
            ]
        },
        {
            "x": 4,
            "y": 0,
            "z": -6,
            "elements": [
                "twilightforest:aurora_block@0"
            ]
        },
        {
            "x": 5,
            "y": -1,
            "z": 7,
            "elements": [
                "actuallyadditions:block_misc@9"
            ]
        },
        {
            "x": 5,
            "y": -1,
            "z": 8,
            "elements": [
                "twilightforest:aurora_block@0"
            ]
        },
        {
            "x": 4,
            "y": 0,
            "z": -5,
            "elements": [
                "actuallyadditions:block_misc@9"
            ]
        },
        {
            "x": 4,
            "y": -2,
            "z": 7,
            "elements": [
                "actuallyadditions:block_misc@9"
            ]
        },
        {
            "x": 4,
            "y": -2,
            "z": 8,
            "elements": [
                "twilightforest:aurora_block@0"
            ]
        },
        {
            "x": 5,
            "y": -1,
            "z": -6,
            "elements": [
                "twilightforest:aurora_block@0"
            ]
        },
        {
            "x": 5,
            "y": -1,
            "z": -5,
            "elements": [
                "actuallyadditions:block_misc@9"
            ]
        },
        {
            "x": 0,
            "y": -6,
            "z": 3,
            "elements": [
                "twilightforest:aurora_block@0"
            ]
        },
        {
            "x": 0,
            "y": -6,
            "z": 4,
            "elements": [
                "twilightforest:aurora_block@0"
            ]
        },
        {
            "x": 0,
            "y": -6,
            "z": 1,
            "elements": [
                "twilightforest:aurora_block@0"
            ]
        },
        {
            "x": 0,
            "y": -6,
            "z": 2,
            "elements": [
                "twilightforest:aurora_block@0"
            ]
        },
        {
            "x": 0,
            "y": -6,
            "z": -1,
            "elements": [
                "twilightforest:aurora_block@0"
            ]
        },
        {
            "x": 0,
            "y": -6,
            "z": 0,
            "elements": [
                "twilightforest:aurora_block@0"
            ]
        },
        {
            "x": 0,
            "y": -6,
            "z": -3,
            "elements": [
                "twilightforest:aurora_block@0"
            ]
        },
        {
            "x": 0,
            "y": -6,
            "z": -2,
            "elements": [
                "twilightforest:aurora_block@0"
            ]
        },
        {
            "x": 0,
            "y": -6,
            "z": 7,
            "elements": [
                "twilightforest:aurora_block@0"
            ]
        },
        {
            "x": 0,
            "y": -6,
            "z": 8,
            "elements": [
                "twilightforest:aurora_block@0"
            ]
        },
        {
            "x": 0,
            "y": -6,
            "z": 5,
            "elements": [
                "twilightforest:aurora_block@0"
            ]
        },
        {
            "x": 0,
            "y": -6,
            "z": 6,
            "elements": [
                "twilightforest:aurora_block@0"
            ]
        },
        {
            "x": 7,
            "y": 1,
            "z": -4,
            "elements": [
                "twilightforest:aurora_block@0"
            ]
        },
        {
            "x": 7,
            "y": 1,
            "z": -5,
            "elements": [
                "twilightforest:aurora_block@0"
            ]
        },
        {
            "x": 7,
            "y": 1,
            "z": -2,
            "elements": [
                "twilightforest:aurora_block@0"
            ]
        },
        {
            "x": 7,
            "y": 1,
            "z": -3,
            "elements": [
                "twilightforest:aurora_block@0"
            ]
        },
        {
            "x": 7,
            "y": 1,
            "z": -6,
            "elements": [
                "twilightforest:aurora_block@0"
            ]
        },
        {
            "x": 3,
            "y": -1,
            "z": 7,
            "elements": [
                "actuallyadditions:block_misc@9"
            ]
        },
        {
            "x": 3,
            "y": -1,
            "z": 8,
            "elements": [
                "twilightforest:aurora_block@0"
            ]
        },
        {
            "x": 3,
            "y": -1,
            "z": 1,
            "elements": [
                "techreborn:machine_casing@0"
            ]
        },
        {
            "x": 3,
            "y": -1,
            "z": 2,
            "elements": [
                "techreborn:machine_casing@0"
            ]
        },
        {
            "x": 3,
            "y": -1,
            "z": 0,
            "elements": [
                "techreborn:machine_casing@0"
            ]
        },
        {
            "x": 3,
            "y": -1,
            "z": -5,
            "elements": [
                "actuallyadditions:block_misc@9"
            ]
        },
        {
            "x": 3,
            "y": -1,
            "z": -6,
            "elements": [
                "twilightforest:aurora_block@0"
            ]
        },
        {
            "x": 4,
            "y": 0,
            "z": 7,
            "elements": [
                "actuallyadditions:block_misc@9"
            ]
        },
        {
            "x": 4,
            "y": 0,
            "z": 8,
            "elements": [
                "twilightforest:aurora_block@0"
            ]
        },
        {
            "x": 3,
            "y": -5,
            "z": 8,
            "elements": [
                "twilightforest:aurora_block@0"
            ]
        },
        {
            "x": 3,
            "y": -5,
            "z": 7,
            "elements": [
                "actuallyadditions:block_misc@9"
            ]
        },
        {
            "x": 3,
            "y": -5,
            "z": 6,
            "elements": [
                "actuallyadditions:block_misc@9"
            ]
        },
        {
            "x": 3,
            "y": -5,
            "z": 5,
            "elements": [
                "actuallyadditions:block_misc@9"
            ]
        },
        {
            "x": 3,
            "y": -5,
            "z": 4,
            "elements": [
                "actuallyadditions:block_misc@9"
            ]
        },
        {
            "x": 3,
            "y": -5,
            "z": 3,
            "elements": [
                "actuallyadditions:block_misc@9"
            ]
        },
        {
            "x": 6,
            "y": 2,
            "z": 8,
            "elements": [
                "twilightforest:aurora_block@0"
            ]
        },
        {
            "x": 3,
            "y": -5,
            "z": 2,
            "elements": [
                "actuallyadditions:block_misc@9"
            ]
        },
        {
            "x": 6,
            "y": 2,
            "z": 7,
            "elements": [
                "actuallyadditions:block_misc@9"
            ]
        },
        {
            "x": 3,
            "y": -5,
            "z": 1,
            "elements": [
                "actuallyadditions:block_misc@9"
            ]
        },
        {
            "x": 3,
            "y": -5,
            "z": 0,
            "elements": [
                "actuallyadditions:block_misc@9"
            ]
        },
        {
            "x": 6,
            "y": 2,
            "z": 6,
            "elements": [
                "actuallyadditions:block_misc@9"
            ]
        },
        {
            "x": 3,
            "y": -5,
            "z": -1,
            "elements": [
                "actuallyadditions:block_misc@9"
            ]
        },
        {
            "x": 6,
            "y": 2,
            "z": 5,
            "elements": [
                "actuallyadditions:block_misc@9"
            ]
        },
        {
            "x": 3,
            "y": -5,
            "z": -2,
            "elements": [
                "actuallyadditions:block_misc@9"
            ]
        },
        {
            "x": 6,
            "y": 2,
            "z": 4,
            "elements": [
                "actuallyadditions:block_misc@9"
            ]
        },
        {
            "x": 3,
            "y": -5,
            "z": -3,
            "elements": [
                "actuallyadditions:block_misc@9"
            ]
        },
        {
            "x": 6,
            "y": 2,
            "z": 3,
            "elements": [
                "actuallyadditions:block_misc@9"
            ]
        },
        {
            "x": 3,
            "y": -5,
            "z": -4,
            "elements": [
                "actuallyadditions:block_misc@9"
            ]
        },
        {
            "x": 6,
            "y": 2,
            "z": 2,
            "elements": [
                "actuallyadditions:block_misc@9"
            ]
        },
        {
            "x": 3,
            "y": -5,
            "z": -5,
            "elements": [
                "actuallyadditions:block_misc@9"
            ]
        },
        {
            "x": 6,
            "y": 2,
            "z": 1,
            "elements": [
                "actuallyadditions:block_misc@9"
            ]
        },
        {
            "x": 6,
            "y": 2,
            "z": 0,
            "elements": [
                "actuallyadditions:block_misc@9"
            ]
        },
        {
            "x": 3,
            "y": -5,
            "z": -6,
            "elements": [
                "twilightforest:aurora_block@0"
            ]
        },
        {
            "x": 6,
            "y": 2,
            "z": -1,
            "elements": [
                "actuallyadditions:block_misc@9"
            ]
        },
        {
            "x": 5,
            "y": 3,
            "z": -6,
            "elements": [
                "twilightforest:aurora_block@0"
            ]
        },
        {
            "x": 5,
            "y": 3,
            "z": -5,
            "elements": [
                "actuallyadditions:block_misc@9"
            ]
        },
        {
            "x": 2,
            "y": -4,
            "z": -6,
            "elements": [
                "twilightforest:aurora_block@0"
            ]
        },
        {
            "x": 2,
            "y": -4,
            "z": -5,
            "elements": [
                "actuallyadditions:block_misc@9"
            ]
        },
        {
            "x": 2,
            "y": -4,
            "z": 8,
            "elements": [
                "twilightforest:aurora_block@0"
            ]
        },
        {
            "x": 2,
            "y": -4,
            "z": 7,
            "elements": [
                "actuallyadditions:block_misc@9"
            ]
        },
        {
            "x": 6,
            "y": 2,
            "z": -2,
            "elements": [
                "actuallyadditions:block_misc@9"
            ]
        },
        {
            "x": 1,
            "y": -3,
            "z": -5,
            "elements": [
                "actuallyadditions:block_misc@9"
            ]
        },
        {
            "x": 6,
            "y": 2,
            "z": -3,
            "elements": [
                "actuallyadditions:block_misc@9"
            ]
        },
        {
            "x": 6,
            "y": 2,
            "z": -4,
            "elements": [
                "actuallyadditions:block_misc@9"
            ]
        },
        {
            "x": 1,
            "y": -3,
            "z": -6,
            "elements": [
                "twilightforest:aurora_block@0"
            ]
        },
        {
            "x": 6,
            "y": 2,
            "z": -5,
            "elements": [
                "actuallyadditions:block_misc@9"
            ]
        },
        {
            "x": 6,
            "y": 2,
            "z": -6,
            "elements": [
                "twilightforest:aurora_block@0"
            ]
        },
        {
            "x": 7,
            "y": 1,
            "z": 8,
            "elements": [
                "twilightforest:aurora_block@0"
            ]
        },
        {
            "x": 1,
            "y": -3,
            "z": 0,
            "elements": [
                "modularmachinery:blockenergyinputhatch@7"
            ]
        },
        {
            "x": 7,
            "y": 1,
            "z": 7,
            "elements": [
                "twilightforest:aurora_block@0"
            ]
        },
        {
            "x": 7,
            "y": 1,
            "z": 4,
            "elements": [
                "twilightforest:aurora_block@0"
            ]
        },
        {
            "x": 7,
            "y": 1,
            "z": 3,
            "elements": [
                "twilightforest:aurora_block@0"
            ]
        },
        {
            "x": 7,
            "y": 1,
            "z": 6,
            "elements": [
                "twilightforest:aurora_block@0"
            ]
        },
        {
            "x": 1,
            "y": -3,
            "z": 2,
            "elements": [
                "generalized_input_fluid"
            ]
        },
        {
            "x": 1,
            "y": -3,
            "z": 1,
            "elements": [
                "techreborn:fusion_coil@0"
            ]
        },
        {
            "x": 7,
            "y": 1,
            "z": 5,
            "elements": [
                "twilightforest:aurora_block@0"
            ]
        },
        {
            "x": 1,
            "y": -3,
            "z": 8,
            "elements": [
                "twilightforest:aurora_block@0"
            ]
        },
        {
            "x": 7,
            "y": 1,
            "z": 0,
            "elements": [
                "twilightforest:aurora_block@0"
            ]
        },
        {
            "x": 1,
            "y": -3,
            "z": 7,
            "elements": [
                "actuallyadditions:block_misc@9"
            ]
        },
        {
            "x": 7,
            "y": 1,
            "z": -1,
            "elements": [
                "twilightforest:aurora_block@0"
            ]
        },
        {
            "x": 7,
            "y": 1,
            "z": 2,
            "elements": [
                "twilightforest:aurora_block@0"
            ]
        },
        {
            "x": 7,
            "y": 1,
            "z": 1,
            "elements": [
                "twilightforest:aurora_block@0"
            ]
        },
        {
            "x": 3,
            "y": 1,
            "z": -6,
            "elements": [
                "twilightforest:aurora_block@0"
            ]
        },
        {
            "x": 4,
            "y": 2,
            "z": 7,
            "elements": [
                "actuallyadditions:block_misc@9"
            ]
        },
        {
            "x": 4,
            "y": 2,
            "z": 8,
            "elements": [
                "twilightforest:aurora_block@0"
            ]
        },
        {
            "x": 3,
            "y": 1,
            "z": -5,
            "elements": [
                "actuallyadditions:block_misc@9"
            ]
        },
        {
            "x": 4,
            "y": 2,
            "z": -6,
            "elements": [
                "twilightforest:aurora_block@0"
            ]
        },
        {
            "x": 4,
            "y": 2,
            "z": -5,
            "elements": [
                "actuallyadditions:block_misc@9"
            ]
        },
        {
            "x": 5,
            "y": -3,
            "z": 7,
            "elements": [
                "actuallyadditions:block_misc@9"
            ]
        },
        {
            "x": 5,
            "y": 3,
            "z": 8,
            "elements": [
                "twilightforest:aurora_block@0"
            ]
        },
        {
            "x": 5,
            "y": -3,
            "z": 8,
            "elements": [
                "twilightforest:aurora_block@0"
            ]
        },
        {
            "x": 5,
            "y": 3,
            "z": 7,
            "elements": [
                "actuallyadditions:block_misc@9"
            ]
        },
        {
            "x": 3,
            "y": 1,
            "z": 7,
            "elements": [
                "actuallyadditions:block_misc@9"
            ]
        },
        {
            "x": 3,
            "y": 1,
            "z": 8,
            "elements": [
                "twilightforest:aurora_block@0"
            ]
        },
        {
            "x": 5,
            "y": -3,
            "z": -5,
            "elements": [
                "actuallyadditions:block_misc@9"
            ]
        },
        {
            "x": 5,
            "y": -3,
            "z": -6,
            "elements": [
                "twilightforest:aurora_block@0"
            ]
        },
        {
            "x": -2,
            "y": -6,
            "z": -6,
            "elements": [
                "twilightforest:aurora_block@0"
            ]
        },
        {
            "x": -2,
            "y": -6,
            "z": -2,
            "elements": [
                "twilightforest:aurora_block@0"
            ]
        },
        {
            "x": -2,
            "y": -6,
            "z": -3,
            "elements": [
                "twilightforest:aurora_block@0"
            ]
        },
        {
            "x": -2,
            "y": -6,
            "z": -4,
            "elements": [
                "twilightforest:aurora_block@0"
            ]
        },
        {
            "x": -2,
            "y": -6,
            "z": -5,
            "elements": [
                "twilightforest:aurora_block@0"
            ]
        },
        {
            "x": -2,
            "y": -6,
            "z": 2,
            "elements": [
                "twilightforest:aurora_block@0"
            ]
        },
        {
            "x": -2,
            "y": -6,
            "z": 1,
            "elements": [
                "twilightforest:aurora_block@0"
            ]
        },
        {
            "x": -2,
            "y": -6,
            "z": 0,
            "elements": [
                "twilightforest:aurora_block@0"
            ]
        },
        {
            "x": -2,
            "y": -6,
            "z": -1,
            "elements": [
                "twilightforest:aurora_block@0"
            ]
        },
        {
            "x": -2,
            "y": -6,
            "z": 6,
            "elements": [
                "twilightforest:aurora_block@0"
            ]
        },
        {
            "x": -2,
            "y": -6,
            "z": 5,
            "elements": [
                "twilightforest:aurora_block@0"
            ]
        },
        {
            "x": -2,
            "y": -6,
            "z": 4,
            "elements": [
                "twilightforest:aurora_block@0"
            ]
        },
        {
            "x": -2,
            "y": -6,
            "z": 3,
            "elements": [
                "twilightforest:aurora_block@0"
            ]
        },
        {
            "x": -2,
            "y": -6,
            "z": 8,
            "elements": [
                "twilightforest:aurora_block@0"
            ]
        },
        {
            "x": -2,
            "y": -6,
            "z": 7,
            "elements": [
                "twilightforest:aurora_block@0"
            ]
        },
        {
            "x": 6,
            "y": 6,
            "z": -6,
            "elements": [
                "twilightforest:aurora_block@0"
            ]
        },
        {
            "x": -7,
            "y": 8,
            "z": -6,
            "elements": [
                "twilightforest:aurora_block@0"
            ]
        },
        {
            "x": -2,
            "y": -4,
            "z": -5,
            "elements": [
                "actuallyadditions:block_misc@9"
            ]
        },
        {
            "x": -7,
            "y": 8,
            "z": -5,
            "elements": [
                "twilightforest:aurora_block@0"
            ]
        },
        {
            "x": -7,
            "y": 8,
            "z": -4,
            "elements": [
                "twilightforest:aurora_block@0"
            ]
        },
        {
            "x": -7,
            "y": 8,
            "z": -3,
            "elements": [
                "twilightforest:aurora_block@0"
            ]
        },
        {
            "x": -2,
            "y": -4,
            "z": -6,
            "elements": [
                "twilightforest:aurora_block@0"
            ]
        },
        {
            "x": -7,
            "y": 8,
            "z": 6,
            "elements": [
                "twilightforest:aurora_block@0"
            ]
        },
        {
            "x": -7,
            "y": 8,
            "z": 7,
            "elements": [
                "twilightforest:aurora_block@0"
            ]
        },
        {
            "x": -7,
            "y": 8,
            "z": 8,
            "elements": [
                "twilightforest:aurora_block@0"
            ]
        },
        {
            "x": -7,
            "y": 8,
            "z": -2,
            "elements": [
                "twilightforest:aurora_block@0"
            ]
        },
        {
            "x": -7,
            "y": 8,
            "z": -1,
            "elements": [
                "twilightforest:aurora_block@0"
            ]
        },
        {
            "x": -7,
            "y": 8,
            "z": 0,
            "elements": [
                "twilightforest:aurora_block@0"
            ]
        },
        {
            "x": -7,
            "y": 8,
            "z": 1,
            "elements": [
                "twilightforest:aurora_block@0"
            ]
        },
        {
            "x": -7,
            "y": 8,
            "z": 2,
            "elements": [
                "twilightforest:aurora_block@0"
            ]
        },
        {
            "x": -7,
            "y": 8,
            "z": 3,
            "elements": [
                "twilightforest:aurora_block@0"
            ]
        },
        {
            "x": -7,
            "y": 8,
            "z": 4,
            "elements": [
                "twilightforest:aurora_block@0"
            ]
        },
        {
            "x": -7,
            "y": 8,
            "z": 5,
            "elements": [
                "twilightforest:aurora_block@0"
            ]
        },
        {
            "x": 5,
            "y": 5,
            "z": 8,
            "elements": [
                "twilightforest:aurora_block@0"
            ]
        },
        {
            "x": 5,
            "y": 5,
            "z": 7,
            "elements": [
                "actuallyadditions:block_misc@9"
            ]
        },
        {
            "x": 2,
            "y": -2,
            "z": -6,
            "elements": [
                "twilightforest:aurora_block@0"
            ]
        },
        {
            "x": 2,
            "y": -2,
            "z": -5,
            "elements": [
                "actuallyadditions:block_misc@9"
            ]
        },
        {
            "x": 6,
            "y": 6,
            "z": 7,
            "elements": [
                "actuallyadditions:block_misc@9"
            ]
        },
        {
            "x": 6,
            "y": 6,
            "z": 8,
            "elements": [
                "twilightforest:aurora_block@0"
            ]
        },
        {
            "x": 6,
            "y": 6,
            "z": 5,
            "elements": [
                "actuallyadditions:block_misc@9"
            ]
        },
        {
            "x": 5,
            "y": 5,
            "z": -6,
            "elements": [
                "twilightforest:aurora_block@0"
            ]
        },
        {
            "x": 6,
            "y": 6,
            "z": 6,
            "elements": [
                "actuallyadditions:block_misc@9"
            ]
        },
        {
            "x": 6,
            "y": 6,
            "z": 3,
            "elements": [
                "actuallyadditions:block_misc@9"
            ]
        },
        {
            "x": 5,
            "y": 5,
            "z": -5,
            "elements": [
                "actuallyadditions:block_misc@9"
            ]
        },
        {
            "x": 6,
            "y": 6,
            "z": 4,
            "elements": [
                "actuallyadditions:block_misc@9"
            ]
        },
        {
            "x": 6,
            "y": 6,
            "z": 1,
            "elements": [
                "actuallyadditions:block_misc@9"
            ]
        },
        {
            "x": 6,
            "y": 6,
            "z": 2,
            "elements": [
                "actuallyadditions:block_misc@9"
            ]
        },
        {
            "x": 6,
            "y": 6,
            "z": -1,
            "elements": [
                "actuallyadditions:block_misc@9"
            ]
        },
        {
            "x": 6,
            "y": 6,
            "z": 0,
            "elements": [
                "actuallyadditions:block_misc@9"
            ]
        },
        {
            "x": 6,
            "y": 6,
            "z": -3,
            "elements": [
                "actuallyadditions:block_misc@9"
            ]
        },
        {
            "x": 6,
            "y": 6,
            "z": -2,
            "elements": [
                "actuallyadditions:block_misc@9"
            ]
        },
        {
            "x": 6,
            "y": 6,
            "z": -5,
            "elements": [
                "actuallyadditions:block_misc@9"
            ]
        },
        {
            "x": 6,
            "y": 6,
            "z": -4,
            "elements": [
                "actuallyadditions:block_misc@9"
            ]
        },
        {
            "x": 6,
            "y": 0,
            "z": 8,
            "elements": [
                "twilightforest:aurora_block@0"
            ]
        },
        {
            "x": 6,
            "y": 0,
            "z": 7,
            "elements": [
                "actuallyadditions:block_misc@9"
            ]
        },
        {
            "x": 6,
            "y": 0,
            "z": 6,
            "elements": [
                "actuallyadditions:block_misc@9"
            ]
        },
        {
            "x": 6,
            "y": 0,
            "z": 5,
            "elements": [
                "actuallyadditions:block_misc@9"
            ]
        },
        {
            "x": 6,
            "y": 0,
            "z": 4,
            "elements": [
                "actuallyadditions:block_misc@9"
            ]
        },
        {
            "x": 6,
            "y": 0,
            "z": 3,
            "elements": [
                "actuallyadditions:block_misc@9"
            ]
        },
        {
            "x": 6,
            "y": 0,
            "z": 2,
            "elements": [
                "actuallyadditions:block_misc@9"
            ]
        },
        {
            "x": 6,
            "y": 0,
            "z": 1,
            "elements": [
                "actuallyadditions:block_misc@9"
            ]
        },
        {
            "x": 6,
            "y": 0,
            "z": 0,
            "elements": [
                "actuallyadditions:block_misc@9"
            ]
        },
        {
            "x": 2,
            "y": -2,
            "z": 8,
            "elements": [
                "twilightforest:aurora_block@0"
            ]
        },
        {
            "x": 6,
            "y": 0,
            "z": -1,
            "elements": [
                "actuallyadditions:block_misc@9"
            ]
        },
        {
            "x": 2,
            "y": -2,
            "z": 7,
            "elements": [
                "actuallyadditions:block_misc@9"
            ]
        },
        {
            "x": 6,
            "y": 0,
            "z": -2,
            "elements": [
                "actuallyadditions:block_misc@9"
            ]
        },
        {
            "x": 6,
            "y": 0,
            "z": -3,
            "elements": [
                "actuallyadditions:block_misc@9"
            ]
        },
        {
            "x": 6,
            "y": 0,
            "z": -4,
            "elements": [
                "actuallyadditions:block_misc@9"
            ]
        },
        {
            "x": 6,
            "y": 0,
            "z": -5,
            "elements": [
                "actuallyadditions:block_misc@9"
            ]
        },
        {
            "x": 6,
            "y": 0,
            "z": -6,
            "elements": [
                "twilightforest:aurora_block@0"
            ]
        },
        {
            "x": -1,
            "y": -3,
            "z": -6,
            "elements": [
                "twilightforest:aurora_block@0"
            ]
        },
        {
            "x": -1,
            "y": -3,
            "z": -5,
            "elements": [
                "actuallyadditions:block_misc@9"
            ]
        },
        {
            "x": 4,
            "y": -4,
            "z": 8,
            "elements": [
                "twilightforest:aurora_block@0"
            ]
        },
        {
            "x": 4,
            "y": -4,
            "z": 7,
            "elements": [
                "actuallyadditions:block_misc@9"
            ]
        },
        {
            "x": -1,
            "y": -3,
            "z": 0,
            "elements": [
                "generalized_input_fluid"
            ]
        },
        {
            "x": -1,
            "y": -3,
            "z": 1,
            "elements": [
                "techreborn:fusion_coil@0"
            ]
        },
        {
            "x": -1,
            "y": -3,
            "z": 2,
            "elements": [
                "modularmachinery:blockenergyinputhatch@7"
            ]
        },
        {
            "x": -1,
            "y": -3,
            "z": 7,
            "elements": [
                "actuallyadditions:block_misc@9"
            ]
        },
        {
            "x": -1,
            "y": -3,
            "z": 8,
            "elements": [
                "twilightforest:aurora_block@0"
            ]
        },
        {
            "x": 4,
            "y": -4,
            "z": -5,
            "elements": [
                "actuallyadditions:block_misc@9"
            ]
        },
        {
            "x": 4,
            "y": -4,
            "z": -6,
            "elements": [
                "twilightforest:aurora_block@0"
            ]
        },
        {
            "x": -2,
            "y": -2,
            "z": -5,
            "elements": [
                "actuallyadditions:block_misc@9"
            ]
        },
        {
            "x": -2,
            "y": -2,
            "z": 7,
            "elements": [
                "actuallyadditions:block_misc@9"
            ]
        },
        {
            "x": -2,
            "y": -2,
            "z": 8,
            "elements": [
                "twilightforest:aurora_block@0"
            ]
        },
        {
            "x": -1,
            "y": -1,
            "z": 1,
            "elements": [
                "techreborn:machine_casing@0"
            ]
        },
        {
            "x": -3,
            "y": -3,
            "z": -6,
            "elements": [
                "twilightforest:aurora_block@0"
            ]
        },
        {
            "x": -1,
            "y": -1,
            "z": 2,
            "elements": [
                "techreborn:machine_casing@0"
            ]
        },
        {
            "x": -3,
            "y": -3,
            "z": -5,
            "elements": [
                "actuallyadditions:block_misc@9"
            ]
        },
        {
            "x": -1,
            "y": -1,
            "z": 3,
            "elements": [
                "techreborn:machine_casing@0"
            ]
        },
        {
            "x": -1,
            "y": -1,
            "z": 4,
            "elements": [
                "techreborn:machine_casing@0"
            ]
        },
        {
            "x": -1,
            "y": -1,
            "z": 7,
            "elements": [
                "actuallyadditions:block_misc@9"
            ]
        },
        {
            "x": -1,
            "y": -1,
            "z": 8,
            "elements": [
                "twilightforest:aurora_block@0"
            ]
        },
        {
            "x": -1,
            "y": -1,
            "z": -6,
            "elements": [
                "twilightforest:aurora_block@0"
            ]
        },
        {
            "x": -1,
            "y": -1,
            "z": -5,
            "elements": [
                "actuallyadditions:block_misc@9"
            ]
        },
        {
            "x": 0,
            "y": 0,
            "z": 8,
            "elements": [
                "twilightforest:aurora_block@0"
            ]
        },
        {
            "x": 0,
            "y": 0,
            "z": 7,
            "elements": [
                "actuallyadditions:block_misc@9"
            ]
        },
        {
            "x": -1,
            "y": -1,
            "z": -2,
            "elements": [
                "techreborn:machine_casing@0"
            ]
        },
        {
            "x": -2,
            "y": -2,
            "z": -6,
            "elements": [
                "twilightforest:aurora_block@0"
            ]
        },
        {
            "x": -1,
            "y": -1,
            "z": -1,
            "elements": [
                "techreborn:machine_casing@0"
            ]
        },
        {
            "x": -1,
            "y": -1,
            "z": 0,
            "elements": [
                "techreborn:machine_casing@0"
            ]
        },
        {
            "x": 0,
            "y": 0,
            "z": 2,
            "elements": [
                "generalized_output_item"
            ]
        },
        {
            "x": -3,
            "y": -3,
            "z": 7,
            "elements": [
                "actuallyadditions:block_misc@9"
            ]
        },
        {
            "x": -3,
            "y": -3,
            "z": 8,
            "elements": [
                "twilightforest:aurora_block@0"
            ]
        },
        {
            "x": 0,
            "y": 0,
            "z": 1,
            "elements": [
                "techreborn:machine_frame@2"
            ]
        },
        {
            "x": 0,
            "y": 0,
            "z": -5,
            "elements": [
                "actuallyadditions:block_misc@9"
            ]
        },
        {
            "x": 0,
            "y": 0,
            "z": -6,
            "elements": [
                "twilightforest:aurora_block@0"
            ]
        },
        {
            "x": -4,
            "y": -4,
            "z": -5,
            "elements": [
                "actuallyadditions:block_misc@9"
            ]
        },
        {
            "x": -4,
            "y": -4,
            "z": -6,
            "elements": [
                "twilightforest:aurora_block@0"
            ]
        },
        {
            "x": -4,
            "y": -4,
            "z": 8,
            "elements": [
                "twilightforest:aurora_block@0"
            ]
        },
        {
            "x": -4,
            "y": -4,
            "z": 7,
            "elements": [
                "actuallyadditions:block_misc@9"
            ]
        },
        {
            "x": -3,
            "y": -5,
            "z": 4,
            "elements": [
                "actuallyadditions:block_misc@9"
            ]
        },
        {
            "x": -4,
            "y": 7,
            "z": 5,
            "elements": [
                "actuallyadditions:block_misc@9"
            ]
        },
        {
            "x": -4,
            "y": 7,
            "z": 4,
            "elements": [
                "actuallyadditions:block_misc@9"
            ]
        },
        {
            "x": -3,
            "y": -5,
            "z": 3,
            "elements": [
                "actuallyadditions:block_misc@9"
            ]
        },
        {
            "x": -3,
            "y": -5,
            "z": 6,
            "elements": [
                "actuallyadditions:block_misc@9"
            ]
        },
        {
            "x": -4,
            "y": 7,
            "z": 7,
            "elements": [
                "actuallyadditions:block_misc@9"
            ]
        },
        {
            "x": -3,
            "y": -5,
            "z": 5,
            "elements": [
                "actuallyadditions:block_misc@9"
            ]
        },
        {
            "x": -4,
            "y": 7,
            "z": 6,
            "elements": [
                "actuallyadditions:block_misc@9"
            ]
        },
        {
            "x": -3,
            "y": -5,
            "z": 0,
            "elements": [
                "actuallyadditions:block_misc@9"
            ]
        },
        {
            "x": -3,
            "y": -5,
            "z": -1,
            "elements": [
                "actuallyadditions:block_misc@9"
            ]
        },
        {
            "x": -4,
            "y": 7,
            "z": 8,
            "elements": [
                "twilightforest:aurora_block@0"
            ]
        },
        {
            "x": -3,
            "y": -5,
            "z": 2,
            "elements": [
                "actuallyadditions:block_misc@9"
            ]
        },
        {
            "x": -3,
            "y": -5,
            "z": 1,
            "elements": [
                "actuallyadditions:block_misc@9"
            ]
        },
        {
            "x": -5,
            "y": 6,
            "z": -6,
            "elements": [
                "twilightforest:aurora_block@0"
            ]
        },
        {
            "x": -4,
            "y": 7,
            "z": -3,
            "elements": [
                "actuallyadditions:block_misc@9"
            ]
        },
        {
            "x": -5,
            "y": 6,
            "z": -5,
            "elements": [
                "actuallyadditions:block_misc@9"
            ]
        },
        {
            "x": -4,
            "y": 7,
            "z": -4,
            "elements": [
                "actuallyadditions:block_misc@9"
            ]
        },
        {
            "x": -4,
            "y": 7,
            "z": -1,
            "elements": [
                "actuallyadditions:block_misc@9"
            ]
        },
        {
            "x": -4,
            "y": 7,
            "z": -2,
            "elements": [
                "actuallyadditions:block_misc@9"
            ]
        },
        {
            "x": -3,
            "y": -5,
            "z": 8,
            "elements": [
                "twilightforest:aurora_block@0"
            ]
        },
        {
            "x": -4,
            "y": 7,
            "z": 1,
            "elements": [
                "actuallyadditions:block_misc@9"
            ]
        },
        {
            "x": -4,
            "y": 7,
            "z": 0,
            "elements": [
                "actuallyadditions:block_misc@9"
            ]
        },
        {
            "x": -3,
            "y": -5,
            "z": 7,
            "elements": [
                "actuallyadditions:block_misc@9"
            ]
        },
        {
            "x": -4,
            "y": 7,
            "z": 3,
            "elements": [
                "actuallyadditions:block_misc@9"
            ]
        },
        {
            "x": -4,
            "y": 7,
            "z": 2,
            "elements": [
                "actuallyadditions:block_misc@9"
            ]
        },
        {
            "x": -2,
            "y": -4,
            "z": 7,
            "elements": [
                "actuallyadditions:block_misc@9"
            ]
        },
        {
            "x": -2,
            "y": -4,
            "z": 8,
            "elements": [
                "twilightforest:aurora_block@0"
            ]
        },
        {
            "x": -3,
            "y": -5,
            "z": -4,
            "elements": [
                "actuallyadditions:block_misc@9"
            ]
        },
        {
            "x": -3,
            "y": -5,
            "z": -5,
            "elements": [
                "actuallyadditions:block_misc@9"
            ]
        },
        {
            "x": -3,
            "y": -5,
            "z": -2,
            "elements": [
                "actuallyadditions:block_misc@9"
            ]
        },
        {
            "x": -3,
            "y": -5,
            "z": -3,
            "elements": [
                "actuallyadditions:block_misc@9"
            ]
        },
        {
            "x": -5,
            "y": 6,
            "z": 7,
            "elements": [
                "actuallyadditions:block_misc@9"
            ]
        },
        {
            "x": -3,
            "y": -5,
            "z": -6,
            "elements": [
                "twilightforest:aurora_block@0"
            ]
        },
        {
            "x": -5,
            "y": 6,
            "z": 8,
            "elements": [
                "twilightforest:aurora_block@0"
            ]
        },
        {
            "x": 1,
            "y": 3,
            "z": 7,
            "elements": [
                "actuallyadditions:block_misc@9"
            ]
        },
        {
            "x": 1,
            "y": 3,
            "z": 8,
            "elements": [
                "twilightforest:aurora_block@0"
            ]
        },
        {
            "x": 1,
            "y": 3,
            "z": -5,
            "elements": [
                "actuallyadditions:block_misc@9"
            ]
        },
        {
            "x": -2,
            "y": 0,
            "z": 7,
            "elements": [
                "actuallyadditions:block_misc@9"
            ]
        },
        {
            "x": -2,
            "y": 0,
            "z": 8,
            "elements": [
                "twilightforest:aurora_block@0"
            ]
        },
        {
            "x": -2,
            "y": 0,
            "z": -5,
            "elements": [
                "actuallyadditions:block_misc@9"
            ]
        },
        {
            "x": -2,
            "y": 0,
            "z": -6,
            "elements": [
                "twilightforest:aurora_block@0"
            ]
        },
        {
            "x": 1,
            "y": 3,
            "z": -6,
            "elements": [
                "twilightforest:aurora_block@0"
            ]
        },
        {
            "x": 7,
            "y": -5,
            "z": 7,
            "elements": [
                "twilightforest:aurora_block@0"
            ]
        },
        {
            "x": 7,
            "y": -5,
            "z": 8,
            "elements": [
                "twilightforest:aurora_block@0"
            ]
        },
        {
            "x": 7,
            "y": -5,
            "z": 5,
            "elements": [
                "twilightforest:aurora_block@0"
            ]
        },
        {
            "x": 7,
            "y": -5,
            "z": 6,
            "elements": [
                "twilightforest:aurora_block@0"
            ]
        },
        {
            "x": 7,
            "y": -5,
            "z": -5,
            "elements": [
                "twilightforest:aurora_block@0"
            ]
        },
        {
            "x": 7,
            "y": 7,
            "z": -3,
            "elements": [
                "twilightforest:aurora_block@0"
            ]
        },
        {
            "x": 7,
            "y": -5,
            "z": -4,
            "elements": [
                "twilightforest:aurora_block@0"
            ]
        },
        {
            "x": 7,
            "y": 7,
            "z": -2,
            "elements": [
                "twilightforest:aurora_block@0"
            ]
        },
        {
            "x": 7,
            "y": 7,
            "z": -1,
            "elements": [
                "twilightforest:aurora_block@0"
            ]
        },
        {
            "x": 7,
            "y": 7,
            "z": 0,
            "elements": [
                "twilightforest:aurora_block@0"
            ]
        },
        {
            "x": 7,
            "y": -5,
            "z": -6,
            "elements": [
                "twilightforest:aurora_block@0"
            ]
        },
        {
            "x": 7,
            "y": 7,
            "z": -6,
            "elements": [
                "twilightforest:aurora_block@0"
            ]
        },
        {
            "x": 7,
            "y": 7,
            "z": -5,
            "elements": [
                "twilightforest:aurora_block@0"
            ]
        },
        {
            "x": 7,
            "y": 7,
            "z": -4,
            "elements": [
                "twilightforest:aurora_block@0"
            ]
        },
        {
            "x": 7,
            "y": -5,
            "z": 3,
            "elements": [
                "twilightforest:aurora_block@0"
            ]
        },
        {
            "x": 7,
            "y": 7,
            "z": 5,
            "elements": [
                "twilightforest:aurora_block@0"
            ]
        },
        {
            "x": 7,
            "y": -5,
            "z": 4,
            "elements": [
                "twilightforest:aurora_block@0"
            ]
        },
        {
            "x": 7,
            "y": 7,
            "z": 6,
            "elements": [
                "twilightforest:aurora_block@0"
            ]
        },
        {
            "x": 7,
            "y": 7,
            "z": 7,
            "elements": [
                "twilightforest:aurora_block@0"
            ]
        },
        {
            "x": 7,
            "y": -5,
            "z": 1,
            "elements": [
                "twilightforest:aurora_block@0"
            ]
        },
        {
            "x": 7,
            "y": 7,
            "z": 8,
            "elements": [
                "twilightforest:aurora_block@0"
            ]
        },
        {
            "x": 7,
            "y": -5,
            "z": 2,
            "elements": [
                "twilightforest:aurora_block@0"
            ]
        },
        {
            "x": 7,
            "y": -5,
            "z": -1,
            "elements": [
                "twilightforest:aurora_block@0"
            ]
        },
        {
            "x": 7,
            "y": 7,
            "z": 1,
            "elements": [
                "twilightforest:aurora_block@0"
            ]
        },
        {
            "x": 7,
            "y": 7,
            "z": 2,
            "elements": [
                "twilightforest:aurora_block@0"
            ]
        },
        {
            "x": 7,
            "y": -5,
            "z": 0,
            "elements": [
                "twilightforest:aurora_block@0"
            ]
        },
        {
            "x": 7,
            "y": -5,
            "z": -3,
            "elements": [
                "twilightforest:aurora_block@0"
            ]
        },
        {
            "x": 7,
            "y": 7,
            "z": 3,
            "elements": [
                "twilightforest:aurora_block@0"
            ]
        },
        {
            "x": 7,
            "y": 7,
            "z": 4,
            "elements": [
                "twilightforest:aurora_block@0"
            ]
        },
        {
            "x": 7,
            "y": -5,
            "z": -2,
            "elements": [
                "twilightforest:aurora_block@0"
            ]
        },
        {
            "x": -5,
            "y": 4,
            "z": 8,
            "elements": [
                "twilightforest:aurora_block@0"
            ]
        },
        {
            "x": 1,
            "y": 5,
            "z": 7,
            "elements": [
                "actuallyadditions:block_misc@9"
            ]
        },
        {
            "x": 1,
            "y": 5,
            "z": 8,
            "elements": [
                "twilightforest:aurora_block@0"
            ]
        },
        {
            "x": -6,
            "y": 3,
            "z": 0,
            "elements": [
                "actuallyadditions:block_misc@9"
            ]
        },
        {
            "x": -6,
            "y": 3,
            "z": 1,
            "elements": [
                "actuallyadditions:block_misc@9"
            ]
        },
        {
            "x": -6,
            "y": 3,
            "z": -2,
            "elements": [
                "actuallyadditions:block_misc@9"
            ]
        },
        {
            "x": -6,
            "y": 3,
            "z": -1,
            "elements": [
                "actuallyadditions:block_misc@9"
            ]
        },
        {
            "x": -5,
            "y": 4,
            "z": 7,
            "elements": [
                "actuallyadditions:block_misc@9"
            ]
        },
        {
            "x": -6,
            "y": 3,
            "z": -4,
            "elements": [
                "actuallyadditions:block_misc@9"
            ]
        },
        {
            "x": -6,
            "y": 3,
            "z": -3,
            "elements": [
                "actuallyadditions:block_misc@9"
            ]
        },
        {
            "x": -6,
            "y": 3,
            "z": -6,
            "elements": [
                "twilightforest:aurora_block@0"
            ]
        },
        {
            "x": -6,
            "y": 3,
            "z": -5,
            "elements": [
                "actuallyadditions:block_misc@9"
            ]
        },
        {
            "x": 2,
            "y": 6,
            "z": 7,
            "elements": [
                "actuallyadditions:block_misc@9"
            ]
        },
        {
            "x": -6,
            "y": 3,
            "z": 8,
            "elements": [
                "twilightforest:aurora_block@0"
            ]
        },
        {
            "x": 2,
            "y": 6,
            "z": 8,
            "elements": [
                "twilightforest:aurora_block@0"
            ]
        },
        {
            "x": -6,
            "y": 3,
            "z": 6,
            "elements": [
                "actuallyadditions:block_misc@9"
            ]
        },
        {
            "x": -6,
            "y": 3,
            "z": 7,
            "elements": [
                "actuallyadditions:block_misc@9"
            ]
        },
        {
            "x": -6,
            "y": 3,
            "z": 4,
            "elements": [
                "actuallyadditions:block_misc@9"
            ]
        },
        {
            "x": 0,
            "y": 4,
            "z": -5,
            "elements": [
                "actuallyadditions:block_misc@9"
            ]
        },
        {
            "x": -6,
            "y": 3,
            "z": 5,
            "elements": [
                "actuallyadditions:block_misc@9"
            ]
        },
        {
            "x": -6,
            "y": 3,
            "z": 2,
            "elements": [
                "actuallyadditions:block_misc@9"
            ]
        },
        {
            "x": -6,
            "y": 3,
            "z": 3,
            "elements": [
                "actuallyadditions:block_misc@9"
            ]
        },
        {
            "x": 1,
            "y": 5,
            "z": -5,
            "elements": [
                "actuallyadditions:block_misc@9"
            ]
        },
        {
            "x": 0,
            "y": 4,
            "z": -6,
            "elements": [
                "twilightforest:aurora_block@0"
            ]
        },
        {
            "x": 1,
            "y": 5,
            "z": -6,
            "elements": [
                "twilightforest:aurora_block@0"
            ]
        },
        {
            "x": 2,
            "y": 6,
            "z": -6,
            "elements": [
                "twilightforest:aurora_block@0"
            ]
        },
        {
            "x": 2,
            "y": 6,
            "z": -5,
            "elements": [
                "actuallyadditions:block_misc@9"
            ]
        },
        {
            "x": -4,
            "y": 5,
            "z": 8,
            "elements": [
                "twilightforest:aurora_block@0"
            ]
        },
        {
            "x": -4,
            "y": 5,
            "z": 7,
            "elements": [
                "actuallyadditions:block_misc@9"
            ]
        },
        {
            "x": -4,
            "y": 5,
            "z": -6,
            "elements": [
                "twilightforest:aurora_block@0"
            ]
        },
        {
            "x": -4,
            "y": 5,
            "z": -5,
            "elements": [
                "actuallyadditions:block_misc@9"
            ]
        },
        {
            "x": 7,
            "y": 5,
            "z": 7,
            "elements": [
                "twilightforest:aurora_block@0"
            ]
        },
        {
            "x": 7,
            "y": 5,
            "z": 8,
            "elements": [
                "twilightforest:aurora_block@0"
            ]
        },
        {
            "x": 7,
            "y": 5,
            "z": 3,
            "elements": [
                "twilightforest:aurora_block@0"
            ]
        },
        {
            "x": 7,
            "y": 5,
            "z": 4,
            "elements": [
                "twilightforest:aurora_block@0"
            ]
        },
        {
            "x": 7,
            "y": 5,
            "z": 5,
            "elements": [
                "twilightforest:aurora_block@0"
            ]
        },
        {
            "x": 2,
            "y": -6,
            "z": -6,
            "elements": [
                "twilightforest:aurora_block@0"
            ]
        },
        {
            "x": 7,
            "y": 5,
            "z": 6,
            "elements": [
                "twilightforest:aurora_block@0"
            ]
        },
        {
            "x": 7,
            "y": 5,
            "z": -1,
            "elements": [
                "twilightforest:aurora_block@0"
            ]
        },
        {
            "x": 6,
            "y": 4,
            "z": -4,
            "elements": [
                "actuallyadditions:block_misc@9"
            ]
        },
        {
            "x": 7,
            "y": 5,
            "z": 0,
            "elements": [
                "twilightforest:aurora_block@0"
            ]
        },
        {
            "x": 6,
            "y": 4,
            "z": -5,
            "elements": [
                "actuallyadditions:block_misc@9"
            ]
        },
        {
            "x": 6,
            "y": 4,
            "z": -6,
            "elements": [
                "twilightforest:aurora_block@0"
            ]
        },
        {
            "x": 7,
            "y": 5,
            "z": 1,
            "elements": [
                "twilightforest:aurora_block@0"
            ]
        },
        {
            "x": 7,
            "y": 5,
            "z": 2,
            "elements": [
                "twilightforest:aurora_block@0"
            ]
        },
        {
            "x": 7,
            "y": 5,
            "z": -5,
            "elements": [
                "twilightforest:aurora_block@0"
            ]
        },
        {
            "x": 7,
            "y": 5,
            "z": -4,
            "elements": [
                "twilightforest:aurora_block@0"
            ]
        },
        {
            "x": 7,
            "y": 5,
            "z": -3,
            "elements": [
                "twilightforest:aurora_block@0"
            ]
        },
        {
            "x": 7,
            "y": 5,
            "z": -2,
            "elements": [
                "twilightforest:aurora_block@0"
            ]
        },
        {
            "x": 2,
            "y": -6,
            "z": 4,
            "elements": [
                "twilightforest:aurora_block@0"
            ]
        },
        {
            "x": 6,
            "y": 4,
            "z": 4,
            "elements": [
                "actuallyadditions:block_misc@9"
            ]
        },
        {
            "x": 2,
            "y": -6,
            "z": 3,
            "elements": [
                "twilightforest:aurora_block@0"
            ]
        },
        {
            "x": 6,
            "y": 4,
            "z": 3,
            "elements": [
                "actuallyadditions:block_misc@9"
            ]
        },
        {
            "x": 6,
            "y": 4,
            "z": 2,
            "elements": [
                "actuallyadditions:block_misc@9"
            ]
        },
        {
            "x": 2,
            "y": -6,
            "z": 6,
            "elements": [
                "twilightforest:aurora_block@0"
            ]
        },
        {
            "x": 2,
            "y": -6,
            "z": 5,
            "elements": [
                "twilightforest:aurora_block@0"
            ]
        },
        {
            "x": 6,
            "y": 4,
            "z": 1,
            "elements": [
                "actuallyadditions:block_misc@9"
            ]
        },
        {
            "x": 6,
            "y": 4,
            "z": 0,
            "elements": [
                "actuallyadditions:block_misc@9"
            ]
        },
        {
            "x": 2,
            "y": -6,
            "z": 8,
            "elements": [
                "twilightforest:aurora_block@0"
            ]
        },
        {
            "x": 6,
            "y": 4,
            "z": -1,
            "elements": [
                "actuallyadditions:block_misc@9"
            ]
        },
        {
            "x": 2,
            "y": -6,
            "z": 7,
            "elements": [
                "twilightforest:aurora_block@0"
            ]
        },
        {
            "x": 6,
            "y": 4,
            "z": -2,
            "elements": [
                "actuallyadditions:block_misc@9"
            ]
        },
        {
            "x": 6,
            "y": 4,
            "z": -3,
            "elements": [
                "actuallyadditions:block_misc@9"
            ]
        },
        {
            "x": 2,
            "y": -6,
            "z": -4,
            "elements": [
                "twilightforest:aurora_block@0"
            ]
        },
        {
            "x": 2,
            "y": -6,
            "z": -5,
            "elements": [
                "twilightforest:aurora_block@0"
            ]
        },
        {
            "x": 2,
            "y": -6,
            "z": -2,
            "elements": [
                "twilightforest:aurora_block@0"
            ]
        },
        {
            "x": 2,
            "y": -6,
            "z": -3,
            "elements": [
                "twilightforest:aurora_block@0"
            ]
        },
        {
            "x": 2,
            "y": -6,
            "z": 0,
            "elements": [
                "twilightforest:aurora_block@0"
            ]
        },
        {
            "x": 6,
            "y": 4,
            "z": 8,
            "elements": [
                "twilightforest:aurora_block@0"
            ]
        },
        {
            "x": 6,
            "y": 4,
            "z": 7,
            "elements": [
                "actuallyadditions:block_misc@9"
            ]
        },
        {
            "x": 2,
            "y": -6,
            "z": -1,
            "elements": [
                "twilightforest:aurora_block@0"
            ]
        },
        {
            "x": 2,
            "y": -6,
            "z": 2,
            "elements": [
                "twilightforest:aurora_block@0"
            ]
        },
        {
            "x": 6,
            "y": 4,
            "z": 6,
            "elements": [
                "actuallyadditions:block_misc@9"
            ]
        },
        {
            "x": 6,
            "y": 4,
            "z": 5,
            "elements": [
                "actuallyadditions:block_misc@9"
            ]
        },
        {
            "x": 2,
            "y": -6,
            "z": 1,
            "elements": [
                "twilightforest:aurora_block@0"
            ]
        },
        {
            "x": -1,
            "y": 1,
            "z": 8,
            "elements": [
                "twilightforest:aurora_block@0"
            ]
        },
        {
            "x": -1,
            "y": 1,
            "z": 7,
            "elements": [
                "actuallyadditions:block_misc@9"
            ]
        },
        {
            "x": 7,
            "y": 5,
            "z": -6,
            "elements": [
                "twilightforest:aurora_block@0"
            ]
        },
        {
            "x": -4,
            "y": 7,
            "z": -5,
            "elements": [
                "actuallyadditions:block_misc@9"
            ]
        },
        {
            "x": -4,
            "y": 7,
            "z": -6,
            "elements": [
                "twilightforest:aurora_block@0"
            ]
        },
        {
            "x": -7,
            "y": 0,
            "z": -1,
            "elements": [
                "twilightforest:aurora_block@0"
            ]
        },
        {
            "x": -7,
            "y": 0,
            "z": -2,
            "elements": [
                "twilightforest:aurora_block@0"
            ]
        },
        {
            "x": -7,
            "y": 0,
            "z": 1,
            "elements": [
                "twilightforest:aurora_block@0"
            ]
        },
        {
            "x": -7,
            "y": 0,
            "z": 0,
            "elements": [
                "twilightforest:aurora_block@0"
            ]
        },
        {
            "x": -7,
            "y": 0,
            "z": 3,
            "elements": [
                "twilightforest:aurora_block@0"
            ]
        },
        {
            "x": -7,
            "y": 0,
            "z": 2,
            "elements": [
                "twilightforest:aurora_block@0"
            ]
        },
        {
            "x": 0,
            "y": 2,
            "z": 8,
            "elements": [
                "twilightforest:aurora_block@0"
            ]
        },
        {
            "x": -7,
            "y": 0,
            "z": 5,
            "elements": [
                "twilightforest:aurora_block@0"
            ]
        },
        {
            "x": 0,
            "y": 2,
            "z": 7,
            "elements": [
                "actuallyadditions:block_misc@9"
            ]
        },
        {
            "x": -7,
            "y": 0,
            "z": 4,
            "elements": [
                "twilightforest:aurora_block@0"
            ]
        },
        {
            "x": -6,
            "y": 1,
            "z": 8,
            "elements": [
                "twilightforest:aurora_block@0"
            ]
        },
        {
            "x": -7,
            "y": 0,
            "z": -5,
            "elements": [
                "twilightforest:aurora_block@0"
            ]
        },
        {
            "x": -6,
            "y": 1,
            "z": 7,
            "elements": [
                "actuallyadditions:block_misc@9"
            ]
        },
        {
            "x": -7,
            "y": 0,
            "z": -6,
            "elements": [
                "twilightforest:aurora_block@0"
            ]
        },
        {
            "x": -6,
            "y": 1,
            "z": 6,
            "elements": [
                "actuallyadditions:block_misc@9"
            ]
        },
        {
            "x": -6,
            "y": 1,
            "z": 5,
            "elements": [
                "actuallyadditions:block_misc@9"
            ]
        },
        {
            "x": -7,
            "y": 0,
            "z": -3,
            "elements": [
                "twilightforest:aurora_block@0"
            ]
        },
        {
            "x": -7,
            "y": 0,
            "z": -4,
            "elements": [
                "twilightforest:aurora_block@0"
            ]
        },
        {
            "x": -6,
            "y": 1,
            "z": 4,
            "elements": [
                "actuallyadditions:block_misc@9"
            ]
        },
        {
            "x": -4,
            "y": -6,
            "z": 0,
            "elements": [
                "twilightforest:aurora_block@0"
            ]
        },
        {
            "x": 0,
            "y": 2,
            "z": -6,
            "elements": [
                "twilightforest:aurora_block@0"
            ]
        },
        {
            "x": -4,
            "y": -6,
            "z": -1,
            "elements": [
                "twilightforest:aurora_block@0"
            ]
        },
        {
            "x": -4,
            "y": -6,
            "z": -2,
            "elements": [
                "twilightforest:aurora_block@0"
            ]
        },
        {
            "x": -4,
            "y": -6,
            "z": -3,
            "elements": [
                "twilightforest:aurora_block@0"
            ]
        },
        {
            "x": 0,
            "y": 2,
            "z": -5,
            "elements": [
                "actuallyadditions:block_misc@9"
            ]
        },
        {
            "x": -1,
            "y": 1,
            "z": 2,
            "elements": [
                "techreborn:machine_frame@2"
            ]
        },
        {
            "x": -4,
            "y": -6,
            "z": -4,
            "elements": [
                "twilightforest:aurora_block@0"
            ]
        },
        {
            "x": -1,
            "y": 1,
            "z": 1,
            "elements": [
                "techreborn:machine_frame@2"
            ]
        },
        {
            "x": -4,
            "y": -6,
            "z": -5,
            "elements": [
                "twilightforest:aurora_block@0"
            ]
        },
        {
            "x": -1,
            "y": 1,
            "z": 0,
            "elements": [
                "techreborn:machine_frame@2"
            ]
        },
        {
            "x": -4,
            "y": -6,
            "z": -6,
            "elements": [
                "twilightforest:aurora_block@0"
            ]
        },
        {
            "x": -7,
            "y": 0,
            "z": 7,
            "elements": [
                "twilightforest:aurora_block@0"
            ]
        },
        {
            "x": -7,
            "y": 0,
            "z": 6,
            "elements": [
                "twilightforest:aurora_block@0"
            ]
        },
        {
            "x": -1,
            "y": 1,
            "z": -5,
            "elements": [
                "actuallyadditions:block_misc@9"
            ]
        },
        {
            "x": -7,
            "y": 0,
            "z": 8,
            "elements": [
                "twilightforest:aurora_block@0"
            ]
        },
        {
            "x": -1,
            "y": 1,
            "z": -6,
            "elements": [
                "twilightforest:aurora_block@0"
            ]
        },
        {
            "x": -4,
            "y": -6,
            "z": 8,
            "elements": [
                "twilightforest:aurora_block@0"
            ]
        },
        {
            "x": -4,
            "y": -6,
            "z": 7,
            "elements": [
                "twilightforest:aurora_block@0"
            ]
        },
        {
            "x": -4,
            "y": -6,
            "z": 6,
            "elements": [
                "twilightforest:aurora_block@0"
            ]
        },
        {
            "x": -4,
            "y": -6,
            "z": 5,
            "elements": [
                "twilightforest:aurora_block@0"
            ]
        },
        {
            "x": -4,
            "y": -6,
            "z": 4,
            "elements": [
                "twilightforest:aurora_block@0"
            ]
        },
        {
            "x": -4,
            "y": -6,
            "z": 3,
            "elements": [
                "twilightforest:aurora_block@0"
            ]
        },
        {
            "x": -4,
            "y": -6,
            "z": 2,
            "elements": [
                "twilightforest:aurora_block@0"
            ]
        },
        {
            "x": -4,
            "y": -6,
            "z": 1,
            "elements": [
                "twilightforest:aurora_block@0"
            ]
        },
        {
            "x": -3,
            "y": 8,
            "z": 8,
            "elements": [
                "twilightforest:aurora_block@0"
            ]
        },
        {
            "x": -3,
            "y": 8,
            "z": 7,
            "elements": [
                "twilightforest:aurora_block@0"
            ]
        },
        {
            "x": -3,
            "y": 8,
            "z": 6,
            "elements": [
                "twilightforest:aurora_block@0"
            ]
        },
        {
            "x": -3,
            "y": 8,
            "z": 5,
            "elements": [
                "twilightforest:aurora_block@0"
            ]
        },
        {
            "x": -3,
            "y": 8,
            "z": 4,
            "elements": [
                "twilightforest:aurora_block@0"
            ]
        },
        {
            "x": -3,
            "y": 8,
            "z": 3,
            "elements": [
                "twilightforest:aurora_block@0"
            ]
        },
        {
            "x": -3,
            "y": 8,
            "z": 2,
            "elements": [
                "twilightforest:aurora_block@0"
            ]
        },
        {
            "x": -3,
            "y": 8,
            "z": 1,
            "elements": [
                "twilightforest:aurora_block@0"
            ]
        },
        {
            "x": -3,
            "y": 8,
            "z": 0,
            "elements": [
                "twilightforest:aurora_block@0"
            ]
        },
        {
            "x": -3,
            "y": 8,
            "z": -1,
            "elements": [
                "twilightforest:aurora_block@0"
            ]
        },
        {
            "x": -3,
            "y": 8,
            "z": -2,
            "elements": [
                "twilightforest:aurora_block@0"
            ]
        },
        {
            "x": -3,
            "y": 8,
            "z": -3,
            "elements": [
                "twilightforest:aurora_block@0"
            ]
        },
        {
            "x": -3,
            "y": 8,
            "z": -4,
            "elements": [
                "twilightforest:aurora_block@0"
            ]
        },
        {
            "x": -3,
            "y": 8,
            "z": -5,
            "elements": [
                "twilightforest:aurora_block@0"
            ]
        },
        {
            "x": -3,
            "y": 8,
            "z": -6,
            "elements": [
                "twilightforest:aurora_block@0"
            ]
        },
        {
            "x": 5,
            "y": 1,
            "z": -6,
            "elements": [
                "twilightforest:aurora_block@0"
            ]
        },
        {
            "x": 5,
            "y": 1,
            "z": -5,
            "elements": [
                "actuallyadditions:block_misc@9"
            ]
        },
        {
            "x": 3,
            "y": -3,
            "z": -5,
            "elements": [
                "actuallyadditions:block_misc@9"
            ]
        },
        {
            "x": 3,
            "y": -3,
            "z": -6,
            "elements": [
                "twilightforest:aurora_block@0"
            ]
        },
        {
            "x": 5,
            "y": 1,
            "z": 8,
            "elements": [
                "twilightforest:aurora_block@0"
            ]
        },
        {
            "x": 5,
            "y": 1,
            "z": 7,
            "elements": [
                "actuallyadditions:block_misc@9"
            ]
        },
        {
            "x": -5,
            "y": 4,
            "z": -6,
            "elements": [
                "twilightforest:aurora_block@0"
            ]
        },
        {
            "x": -5,
            "y": 4,
            "z": -5,
            "elements": [
                "actuallyadditions:block_misc@9"
            ]
        },
        {
            "x": 0,
            "y": 7,
            "z": 8,
            "elements": [
                "twilightforest:aurora_block@0"
            ]
        },
        {
            "x": -5,
            "y": 1,
            "z": -6,
            "elements": [
                "twilightforest:aurora_block@0"
            ]
        },
        {
            "x": 0,
            "y": 7,
            "z": -6,
            "elements": [
                "twilightforest:aurora_block@0"
            ]
        },
        {
            "x": 0,
            "y": 7,
            "z": -5,
            "elements": [
                "actuallyadditions:block_misc@9"
            ]
        },
        {
            "x": -5,
            "y": 1,
            "z": 7,
            "elements": [
                "actuallyadditions:block_misc@9"
            ]
        },
        {
            "x": -3,
            "y": 3,
            "z": 7,
            "elements": [
                "actuallyadditions:block_misc@9"
            ]
        },
        {
            "x": 0,
            "y": 7,
            "z": -4,
            "elements": [
                "actuallyadditions:block_misc@9"
            ]
        },
        {
            "x": -5,
            "y": 1,
            "z": 8,
            "elements": [
                "twilightforest:aurora_block@0"
            ]
        },
        {
            "x": 0,
            "y": 7,
            "z": -3,
            "elements": [
                "actuallyadditions:block_misc@9"
            ]
        },
        {
            "x": -3,
            "y": 3,
            "z": 8,
            "elements": [
                "twilightforest:aurora_block@0"
            ]
        },
        {
            "x": 0,
            "y": 7,
            "z": -2,
            "elements": [
                "actuallyadditions:block_misc@9"
            ]
        },
        {
            "x": 0,
            "y": 7,
            "z": -1,
            "elements": [
                "actuallyadditions:block_misc@9"
            ]
        },
        {
            "x": -5,
            "y": 1,
            "z": -5,
            "elements": [
                "actuallyadditions:block_misc@9"
            ]
        },
        {
            "x": 0,
            "y": 7,
            "z": 0,
            "elements": [
                "actuallyadditions:block_misc@9"
            ]
        },
        {
            "x": 0,
            "y": 7,
            "z": 1,
            "elements": [
                "actuallyadditions:block_misc@9"
            ]
        },
        {
            "x": -2,
            "y": 5,
            "z": -5,
            "elements": [
                "actuallyadditions:block_misc@9"
            ]
        },
        {
            "x": 0,
            "y": 7,
            "z": 2,
            "elements": [
                "actuallyadditions:block_misc@9"
            ]
        },
        {
            "x": -2,
            "y": 5,
            "z": -6,
            "elements": [
                "twilightforest:aurora_block@0"
            ]
        },
        {
            "x": 0,
            "y": 7,
            "z": 3,
            "elements": [
                "actuallyadditions:block_misc@9"
            ]
        },
        {
            "x": 0,
            "y": 7,
            "z": 4,
            "elements": [
                "actuallyadditions:block_misc@9"
            ]
        },
        {
            "x": 0,
            "y": 7,
            "z": 5,
            "elements": [
                "actuallyadditions:block_misc@9"
            ]
        },
        {
            "x": 0,
            "y": 7,
            "z": 6,
            "elements": [
                "actuallyadditions:block_misc@9"
            ]
        },
        {
            "x": 0,
            "y": 7,
            "z": 7,
            "elements": [
                "actuallyadditions:block_misc@9"
            ]
        },
        {
            "x": -6,
            "y": -1,
            "z": 8,
            "elements": [
                "twilightforest:aurora_block@0"
            ]
        },
        {
            "x": -6,
            "y": -1,
            "z": 7,
            "elements": [
                "actuallyadditions:block_misc@9"
            ]
        },
        {
            "x": -6,
            "y": -1,
            "z": 6,
            "elements": [
                "actuallyadditions:block_misc@9"
            ]
        },
        {
            "x": -6,
            "y": -1,
            "z": -3,
            "elements": [
                "actuallyadditions:block_misc@9"
            ]
        },
        {
            "x": -6,
            "y": -1,
            "z": -4,
            "elements": [
                "actuallyadditions:block_misc@9"
            ]
        },
        {
            "x": -6,
            "y": -1,
            "z": -5,
            "elements": [
                "actuallyadditions:block_misc@9"
            ]
        },
        {
            "x": -6,
            "y": -1,
            "z": -6,
            "elements": [
                "twilightforest:aurora_block@0"
            ]
        },
        {
            "x": -6,
            "y": -1,
            "z": 5,
            "elements": [
                "actuallyadditions:block_misc@9"
            ]
        },
        {
            "x": -6,
            "y": -1,
            "z": 4,
            "elements": [
                "actuallyadditions:block_misc@9"
            ]
        },
        {
            "x": -6,
            "y": -1,
            "z": 3,
            "elements": [
                "actuallyadditions:block_misc@9"
            ]
        },
        {
            "x": -6,
            "y": -1,
            "z": 2,
            "elements": [
                "actuallyadditions:block_misc@9"
            ]
        },
        {
            "x": -6,
            "y": -1,
            "z": 1,
            "elements": [
                "actuallyadditions:block_misc@9"
            ]
        },
        {
            "x": -6,
            "y": -1,
            "z": 0,
            "elements": [
                "actuallyadditions:block_misc@9"
            ]
        },
        {
            "x": -6,
            "y": -1,
            "z": -1,
            "elements": [
                "actuallyadditions:block_misc@9"
            ]
        },
        {
            "x": -6,
            "y": -1,
            "z": -2,
            "elements": [
                "actuallyadditions:block_misc@9"
            ]
        },
        {
            "x": -7,
            "y": -1,
            "z": 8,
            "elements": [
                "twilightforest:aurora_block@0"
            ]
        },
        {
            "x": -7,
            "y": -1,
            "z": 7,
            "elements": [
                "twilightforest:aurora_block@0"
            ]
        },
        {
            "x": -7,
            "y": -1,
            "z": 4,
            "elements": [
                "twilightforest:aurora_block@0"
            ]
        },
        {
            "x": -7,
            "y": -1,
            "z": 3,
            "elements": [
                "twilightforest:aurora_block@0"
            ]
        },
        {
            "x": -7,
            "y": -1,
            "z": 6,
            "elements": [
                "twilightforest:aurora_block@0"
            ]
        },
        {
            "x": -7,
            "y": -1,
            "z": 5,
            "elements": [
                "twilightforest:aurora_block@0"
            ]
        },
        {
            "x": -7,
            "y": -1,
            "z": 0,
            "elements": [
                "twilightforest:aurora_block@0"
            ]
        },
        {
            "x": -7,
            "y": -1,
            "z": -1,
            "elements": [
                "twilightforest:aurora_block@0"
            ]
        },
        {
            "x": -7,
            "y": -1,
            "z": 2,
            "elements": [
                "twilightforest:aurora_block@0"
            ]
        },
        {
            "x": -7,
            "y": -1,
            "z": 1,
            "elements": [
                "twilightforest:aurora_block@0"
            ]
        },
        {
            "x": -7,
            "y": -1,
            "z": -4,
            "elements": [
                "twilightforest:aurora_block@0"
            ]
        },
        {
            "x": -7,
            "y": -1,
            "z": -5,
            "elements": [
                "twilightforest:aurora_block@0"
            ]
        },
        {
            "x": -7,
            "y": -1,
            "z": -2,
            "elements": [
                "twilightforest:aurora_block@0"
            ]
        },
        {
            "x": -7,
            "y": -1,
            "z": -3,
            "elements": [
                "twilightforest:aurora_block@0"
            ]
        },
        {
            "x": -7,
            "y": -1,
            "z": -6,
            "elements": [
                "twilightforest:aurora_block@0"
            ]
        },
        {
            "x": -3,
            "y": 3,
            "z": -5,
            "elements": [
                "actuallyadditions:block_misc@9"
            ]
        },
        {
            "x": -7,
            "y": -3,
            "z": 7,
            "elements": [
                "twilightforest:aurora_block@0"
            ]
        },
        {
            "x": -7,
            "y": -3,
            "z": 8,
            "elements": [
                "twilightforest:aurora_block@0"
            ]
        },
        {
            "x": -7,
            "y": -3,
            "z": 5,
            "elements": [
                "twilightforest:aurora_block@0"
            ]
        },
        {
            "x": 1,
            "y": 7,
            "z": 7,
            "elements": [
                "actuallyadditions:block_misc@9"
            ]
        },
        {
            "x": 1,
            "y": 7,
            "z": 8,
            "elements": [
                "twilightforest:aurora_block@0"
            ]
        },
        {
            "x": -7,
            "y": -3,
            "z": 6,
            "elements": [
                "twilightforest:aurora_block@0"
            ]
        },
        {
            "x": -7,
            "y": -3,
            "z": 3,
            "elements": [
                "twilightforest:aurora_block@0"
            ]
        },
        {
            "x": -7,
            "y": -3,
            "z": 4,
            "elements": [
                "twilightforest:aurora_block@0"
            ]
        },
        {
            "x": -7,
            "y": -3,
            "z": 1,
            "elements": [
                "twilightforest:aurora_block@0"
            ]
        },
        {
            "x": -7,
            "y": -3,
            "z": 2,
            "elements": [
                "twilightforest:aurora_block@0"
            ]
        },
        {
            "x": -3,
            "y": 3,
            "z": -6,
            "elements": [
                "twilightforest:aurora_block@0"
            ]
        },
        {
            "x": 1,
            "y": 7,
            "z": 1,
            "elements": [
                "actuallyadditions:block_misc@9"
            ]
        },
        {
            "x": 1,
            "y": 7,
            "z": 2,
            "elements": [
                "actuallyadditions:block_misc@9"
            ]
        },
        {
            "x": -2,
            "y": 5,
            "z": 8,
            "elements": [
                "twilightforest:aurora_block@0"
            ]
        },
        {
            "x": 1,
            "y": 7,
            "z": -1,
            "elements": [
                "actuallyadditions:block_misc@9"
            ]
        },
        {
            "x": 1,
            "y": 7,
            "z": 0,
            "elements": [
                "actuallyadditions:block_misc@9"
            ]
        },
        {
            "x": 1,
            "y": 7,
            "z": 5,
            "elements": [
                "actuallyadditions:block_misc@9"
            ]
        },
        {
            "x": 1,
            "y": 7,
            "z": 6,
            "elements": [
                "actuallyadditions:block_misc@9"
            ]
        },
        {
            "x": 1,
            "y": 7,
            "z": 3,
            "elements": [
                "actuallyadditions:block_misc@9"
            ]
        },
        {
            "x": -2,
            "y": 5,
            "z": 7,
            "elements": [
                "actuallyadditions:block_misc@9"
            ]
        },
        {
            "x": 1,
            "y": 7,
            "z": 4,
            "elements": [
                "actuallyadditions:block_misc@9"
            ]
        },
        {
            "x": -6,
            "y": 1,
            "z": 3,
            "elements": [
                "actuallyadditions:block_misc@9"
            ]
        },
        {
            "x": -6,
            "y": 1,
            "z": 2,
            "elements": [
                "actuallyadditions:block_misc@9"
            ]
        },
        {
            "x": -6,
            "y": 1,
            "z": 1,
            "elements": [
                "actuallyadditions:block_misc@9"
            ]
        },
        {
            "x": -6,
            "y": 1,
            "z": 0,
            "elements": [
                "actuallyadditions:block_misc@9"
            ]
        },
        {
            "x": -6,
            "y": 1,
            "z": -1,
            "elements": [
                "actuallyadditions:block_misc@9"
            ]
        },
        {
            "x": -6,
            "y": 1,
            "z": -2,
            "elements": [
                "actuallyadditions:block_misc@9"
            ]
        },
        {
            "x": -6,
            "y": 1,
            "z": -3,
            "elements": [
                "actuallyadditions:block_misc@9"
            ]
        },
        {
            "x": -6,
            "y": 1,
            "z": -4,
            "elements": [
                "actuallyadditions:block_misc@9"
            ]
        },
        {
            "x": -6,
            "y": 1,
            "z": -5,
            "elements": [
                "actuallyadditions:block_misc@9"
            ]
        },
        {
            "x": -6,
            "y": 1,
            "z": -6,
            "elements": [
                "twilightforest:aurora_block@0"
            ]
        },
        {
            "x": -2,
            "y": 3,
            "z": -5,
            "elements": [
                "actuallyadditions:block_misc@9"
            ]
        },
        {
            "x": -2,
            "y": 3,
            "z": -6,
            "elements": [
                "twilightforest:aurora_block@0"
            ]
        },
        {
            "x": 1,
            "y": 7,
            "z": -6,
            "elements": [
                "twilightforest:aurora_block@0"
            ]
        },
        {
            "x": 1,
            "y": 7,
            "z": -3,
            "elements": [
                "actuallyadditions:block_misc@9"
            ]
        },
        {
            "x": -2,
            "y": 3,
            "z": 7,
            "elements": [
                "actuallyadditions:block_misc@9"
            ]
        },
        {
            "x": 1,
            "y": 7,
            "z": -2,
            "elements": [
                "actuallyadditions:block_misc@9"
            ]
        },
        {
            "x": 1,
            "y": 7,
            "z": -5,
            "elements": [
                "actuallyadditions:block_misc@9"
            ]
        },
        {
            "x": -2,
            "y": 3,
            "z": 8,
            "elements": [
                "twilightforest:aurora_block@0"
            ]
        },
        {
            "x": 1,
            "y": 7,
            "z": -4,
            "elements": [
                "actuallyadditions:block_misc@9"
            ]
        },
        {
            "x": -5,
            "y": -1,
            "z": 8,
            "elements": [
                "twilightforest:aurora_block@0"
            ]
        },
        {
            "x": -5,
            "y": -1,
            "z": 7,
            "elements": [
                "actuallyadditions:block_misc@9"
            ]
        },
        {
            "x": -4,
            "y": 1,
            "z": -6,
            "elements": [
                "twilightforest:aurora_block@0"
            ]
        },
        {
            "x": -4,
            "y": 1,
            "z": -5,
            "elements": [
                "actuallyadditions:block_misc@9"
            ]
        },
        {
            "x": -5,
            "y": -1,
            "z": -6,
            "elements": [
                "twilightforest:aurora_block@0"
            ]
        },
        {
            "x": -5,
            "y": -1,
            "z": -5,
            "elements": [
                "actuallyadditions:block_misc@9"
            ]
        },
        {
            "x": -3,
            "y": 1,
            "z": 7,
            "elements": [
                "actuallyadditions:block_misc@9"
            ]
        },
        {
            "x": -3,
            "y": 1,
            "z": 8,
            "elements": [
                "twilightforest:aurora_block@0"
            ]
        },
        {
            "x": -4,
            "y": 1,
            "z": 8,
            "elements": [
                "twilightforest:aurora_block@0"
            ]
        },
        {
            "x": -4,
            "y": 1,
            "z": 7,
            "elements": [
                "actuallyadditions:block_misc@9"
            ]
        },
        {
            "x": -3,
            "y": 1,
            "z": -6,
            "elements": [
                "twilightforest:aurora_block@0"
            ]
        },
        {
            "x": -3,
            "y": 1,
            "z": -5,
            "elements": [
                "actuallyadditions:block_misc@9"
            ]
        },
        {
            "x": -6,
            "y": -3,
            "z": 7,
            "elements": [
                "actuallyadditions:block_misc@9"
            ]
        },
        {
            "x": -6,
            "y": -3,
            "z": 6,
            "elements": [
                "actuallyadditions:block_misc@9"
            ]
        },
        {
            "x": -6,
            "y": -3,
            "z": 5,
            "elements": [
                "actuallyadditions:block_misc@9"
            ]
        },
        {
            "x": -6,
            "y": -3,
            "z": 4,
            "elements": [
                "actuallyadditions:block_misc@9"
            ]
        },
        {
            "x": -6,
            "y": -3,
            "z": 3,
            "elements": [
                "actuallyadditions:block_misc@9"
            ]
        },
        {
            "x": -6,
            "y": -3,
            "z": 2,
            "elements": [
                "actuallyadditions:block_misc@9"
            ]
        },
        {
            "x": -6,
            "y": -3,
            "z": 1,
            "elements": [
                "actuallyadditions:block_misc@9"
            ]
        },
        {
            "x": -1,
            "y": 5,
            "z": -5,
            "elements": [
                "actuallyadditions:block_misc@9"
            ]
        },
        {
            "x": -6,
            "y": -3,
            "z": 0,
            "elements": [
                "actuallyadditions:block_misc@9"
            ]
        },
        {
            "x": -6,
            "y": -3,
            "z": -1,
            "elements": [
                "actuallyadditions:block_misc@9"
            ]
        },
        {
            "x": -1,
            "y": 5,
            "z": -6,
            "elements": [
                "twilightforest:aurora_block@0"
            ]
        },
        {
            "x": -6,
            "y": -3,
            "z": -2,
            "elements": [
                "actuallyadditions:block_misc@9"
            ]
        },
        {
            "x": -6,
            "y": -3,
