{
    "registryname": "tree_of_life",
    "localizedname": "Tree of Life",
	"color": "303030",
    "parts": [
        {
            "x": 5,
            "y": 0,
            "z": 8,
            "elements": [
                "tconstruct:slime_grass"
            ]
        },
        {
            "x": 5,
            "y": 0,
            "z": 9,
            "elements": [
                "tconstruct:slime_grass"
            ]
        },
        {
            "x": 5,
            "y": 0,
            "z": 6,
            "elements": [
                "tconstruct:slime_grass"
            ]
        },
        {
            "x": 5,
            "y": 0,
            "z": 7,
            "elements": [
                "tconstruct:slime_grass"
            ]
        },
        {
            "x": 5,
            "y": 0,
            "z": 4,
            "elements": [
                "unlimitedchiselworks:chisel_stonebrick1_appliedenergistics2_sky_stone_brick_0@0"
            ]
        },
        {
            "x": -5,
            "y": 14,
            "z": 12,
            "elements": [
                "contenttweaker:leaves_of_life"
            ]
        },
        {
            "x": 5,
            "y": 0,
            "z": 5,
            "elements": [
                "unlimitedchiselworks:chisel_stonebrick1_appliedenergistics2_sky_stone_brick_0@0"
            ]
        },
        {
            "x": 5,
            "y": 0,
            "z": 2,
            "elements": [
                "unlimitedchiselworks:chisel_stonebrick2_appliedenergistics2_sky_stone_brick_0@1"
            ]
        },
        {
            "x": -5,
            "y": 14,
            "z": 10,
            "elements": [
                "contenttweaker:leaves_of_life"
            ]
        },
        {
            "x": 5,
            "y": 0,
            "z": 3,
            "elements": [
                "unlimitedchiselworks:chisel_stonebrick2_appliedenergistics2_sky_stone_brick_0@1"
            ]
        },
        {
            "x": -5,
            "y": 14,
            "z": 11,
            "elements": [
                "contenttweaker:leaves_of_life"
            ]
        },
        {
            "x": -9,
            "y": 9,
            "z": 15,
            "elements": [
                "contenttweaker:innerved_sky_stone@0"
            ]
        },
        {
            "x": -4,
            "y": 15,
            "z": 3,
            "elements": [
                "contenttweaker:leaves_of_life"
            ]
        },
        {
            "x": 7,
            "y": 2,
            "z": 7,
            "elements": [
                "unlimitedchiselworks:chisel_stonebrick2_appliedenergistics2_sky_stone_brick_0@2"
            ]
        },
        {
            "x": -6,
            "y": 13,
            "z": 13,
            "elements": [
                "contenttweaker:leaves_of_life"
            ]
        },
        {
            "x": -10,
            "y": 8,
            "z": 12,
            "elements": [
                "contenttweaker:innerved_sky_stone@0"
            ]
        },
        {
            "x": 11,
            "y": 8,
            "z": 11,
            "elements": [
                "contenttweaker:innerved_sky_stone@0"
            ]
        },
        {
            "x": -6,
            "y": 13,
            "z": 12,
            "elements": [
                "contenttweaker:leaves_of_life"
            ]
        },
        {
            "x": 11,
            "y": 7,
            "z": 7,
            "elements": [
                "contenttweaker:innerved_sky_stone@0"
            ]
        },
        {
            "x": -10,
            "y": 8,
            "z": 11,
            "elements": [
                "contenttweaker:innerved_sky_stone@0"
            ]
        },
        {
            "x": 11,
            "y": 8,
            "z": 10,
            "elements": [
                "contenttweaker:innerved_sky_stone@0"
            ]
        },
        {
            "x": 11,
            "y": 8,
            "z": 9,
            "elements": [
                "contenttweaker:innerved_sky_stone@0"
            ]
        },
        {
            "x": 7,
            "y": 3,
            "z": 11,
            "elements": [
                "unlimitedchiselworks:chisel_stonebrick2_appliedenergistics2_sky_stone_brick_0@2"
            ]
        },
        {
            "x": -6,
            "y": 13,
            "z": 14,
            "elements": [
                "contenttweaker:leaves_of_life"
            ]
        },
        {
            "x": 11,
            "y": 8,
            "z": 8,
            "elements": [
                "contenttweaker:innerved_sky_stone@0"
            ]
        },
        {
            "x": 7,
            "y": 2,
            "z": 11,
            "elements": [
                "unlimitedchiselworks:chisel_stonebrick2_appliedenergistics2_sky_stone_brick_0@2"
            ]
        },
        {
            "x": -6,
            "y": 13,
            "z": 9,
            "elements": [
                "contenttweaker:leaves_of_life"
            ]
        },
        {
            "x": 11,
            "y": 8,
            "z": 7,
            "elements": [
                "contenttweaker:innerved_sky_stone@0"
            ]
        },
        {
            "x": -6,
            "y": 13,
            "z": 8,
            "elements": [
                "contenttweaker:leaves_of_life"
            ]
        },
        {
            "x": 11,
            "y": 7,
            "z": 11,
            "elements": [
                "contenttweaker:innerved_sky_stone@0"
            ]
        },
        {
            "x": -6,
            "y": 13,
            "z": 11,
            "elements": [
                "contenttweaker:leaves_of_life"
            ]
        },
        {
            "x": 7,
            "y": 3,
            "z": 7,
            "elements": [
                "unlimitedchiselworks:chisel_stonebrick2_appliedenergistics2_sky_stone_brick_0@2"
            ]
        },
        {
            "x": -6,
            "y": 13,
            "z": 10,
            "elements": [
                "contenttweaker:leaves_of_life"
            ]
        },
        {
            "x": 11,
            "y": 7,
            "z": 9,
            "elements": [
                "contenttweaker:innerved_sky_stone@0"
            ]
        },
        {
            "x": -10,
            "y": 8,
            "z": 13,
            "elements": [
                "contenttweaker:innerved_sky_stone@0"
            ]
        },
        {
            "x": -2,
            "y": 17,
            "z": 18,
            "elements": [
                "contenttweaker:leaves_of_life"
            ]
        },
        {
            "x": -10,
            "y": 8,
            "z": 7,
            "elements": [
                "contenttweaker:innerved_sky_stone@0"
            ]
        },
        {
            "x": -6,
            "y": 13,
            "z": 3,
            "elements": [
                "contenttweaker:leaves_of_life"
            ]
        },
        {
            "x": -10,
            "y": 8,
            "z": 6,
            "elements": [
                "contenttweaker:innerved_sky_stone@0"
            ]
        },
        {
            "x": -10,
            "y": 8,
            "z": 5,
            "elements": [
                "contenttweaker:innerved_sky_stone@0"
            ]
        },
        {
            "x": 5,
            "y": 0,
            "z": 16,
            "elements": [
                "unlimitedchiselworks:chisel_stonebrick2_appliedenergistics2_sky_stone_brick_0@1"
            ]
        },
        {
            "x": 5,
            "y": 0,
            "z": 14,
            "elements": [
                "unlimitedchiselworks:chisel_stonebrick1_appliedenergistics2_sky_stone_brick_0@0"
            ]
        },
        {
            "x": 5,
            "y": 0,
            "z": 15,
            "elements": [
                "unlimitedchiselworks:chisel_stonebrick2_appliedenergistics2_sky_stone_brick_0@1"
            ]
        },
        {
            "x": 5,
            "y": 0,
            "z": 12,
            "elements": [
                "tconstruct:slime_grass"
            ]
        },
        {
            "x": 5,
            "y": 0,
            "z": 13,
            "elements": [
                "unlimitedchiselworks:chisel_stonebrick1_appliedenergistics2_sky_stone_brick_0@0"
            ]
        },
        {
            "x": 5,
            "y": 0,
            "z": 10,
            "elements": [
                "tconstruct:slime_grass"
            ]
        },
        {
            "x": 5,
            "y": 0,
            "z": 11,
            "elements": [
                "tconstruct:slime_grass"
            ]
        },
        {
            "x": -6,
            "y": 12,
            "z": 11,
            "elements": [
                "contenttweaker:sacred_eucalyptus"
            ]
        },
        {
            "x": -1,
            "y": 18,
            "z": 18,
            "elements": [
                "contenttweaker:leaves_of_life"
            ]
        },
        {
            "x": 5,
            "y": -1,
            "z": 5,
            "elements": [
                "unlimitedchiselworks:chisel_stonebrick1_appliedenergistics2_sky_stone_brick_0@0"
            ]
        },
        {
            "x": -9,
            "y": 8,
            "z": 5,
            "elements": [
                "contenttweaker:innerved_sky_stone@0"
            ]
        },
        {
            "x": 5,
            "y": -1,
            "z": 6,
            "elements": [
                "unlimitedchiselworks:chisel_stonebrick_appliedenergistics2_sky_stone_brick_0@8"
            ]
        },
        {
            "x": -9,
            "y": 8,
            "z": 4,
            "elements": [
                "contenttweaker:innerved_sky_stone@0"
            ]
        },
        {
            "x": 5,
            "y": -1,
            "z": 3,
            "elements": [
                "unlimitedchiselworks:chisel_stonebrick2_appliedenergistics2_sky_stone_brick_0@1"
            ]
        },
        {
            "x": 5,
            "y": -1,
            "z": 4,
            "elements": [
                "unlimitedchiselworks:chisel_stonebrick1_appliedenergistics2_sky_stone_brick_0@0"
            ]
        },
        {
            "x": 5,
            "y": -1,
            "z": 9,
            "elements": [
                "unlimitedchiselworks:chisel_stonebrick_appliedenergistics2_sky_stone_brick_0@8"
            ]
        },
        {
            "x": 5,
            "y": -1,
            "z": 10,
            "elements": [
                "unlimitedchiselworks:chisel_stonebrick_appliedenergistics2_sky_stone_brick_0@8"
            ]
        },
        {
            "x": -11,
            "y": 7,
            "z": 11,
            "elements": [
                "contenttweaker:innerved_sky_stone@0"
            ]
        },
        {
            "x": 5,
            "y": -1,
            "z": 7,
            "elements": [
                "unlimitedchiselworks:chisel_stonebrick_appliedenergistics2_sky_stone_brick_0@8"
            ]
        },
        {
            "x": 10,
            "y": 7,
            "z": 5,
            "elements": [
                "contenttweaker:innerved_sky_stone@0"
            ]
        },
        {
            "x": -9,
            "y": 8,
            "z": 3,
            "elements": [
                "contenttweaker:innerved_sky_stone@0"
            ]
        },
        {
            "x": 5,
            "y": -1,
            "z": 8,
            "elements": [
                "unlimitedchiselworks:chisel_stonebrick_appliedenergistics2_sky_stone_brick_0@8"
            ]
        },
        {
            "x": 5,
            "y": -1,
            "z": 13,
            "elements": [
                "unlimitedchiselworks:chisel_stonebrick1_appliedenergistics2_sky_stone_brick_0@0"
            ]
        },
        {
            "x": -9,
            "y": 8,
            "z": 13,
            "elements": [
                "contenttweaker:innerved_sky_stone@0"
            ]
        },
        {
            "x": 5,
            "y": -1,
            "z": 14,
            "elements": [
                "unlimitedchiselworks:chisel_stonebrick1_appliedenergistics2_sky_stone_brick_0@0"
            ]
        },
        {
            "x": -8,
            "y": 9,
            "z": 17,
            "elements": [
                "contenttweaker:innerved_sky_stone@0"
            ]
        },
        {
            "x": 5,
            "y": -1,
            "z": 11,
            "elements": [
                "unlimitedchiselworks:chisel_stonebrick_appliedenergistics2_sky_stone_brick_0@8"
            ]
        },
        {
            "x": -9,
            "y": 8,
            "z": 15,
            "elements": [
                "contenttweaker:innerved_sky_stone@0"
            ]
        },
        {
            "x": 5,
            "y": -1,
            "z": 12,
            "elements": [
                "unlimitedchiselworks:chisel_stonebrick_appliedenergistics2_sky_stone_brick_0@8"
            ]
        },
        {
            "x": 4,
            "y": 0,
            "z": 2,
            "elements": [
                "modularmachinery:blockinputbus@6"
            ]
        },
        {
            "x": -9,
            "y": 8,
            "z": 14,
            "elements": [
                "contenttweaker:innerved_sky_stone@0"
            ]
        },
        {
            "x": 5,
            "y": -1,
            "z": 15,
            "elements": [
                "unlimitedchiselworks:chisel_stonebrick2_appliedenergistics2_sky_stone_brick_0@1"
            ]
        },
        {
            "x": 10,
            "y": 7,
            "z": 13,
            "elements": [
                "contenttweaker:innerved_sky_stone@0"
            ]
        },
        {
            "x": 5,
            "y": -1,
            "z": 16,
            "elements": [
                "unlimitedchiselworks:chisel_stonebrick2_appliedenergistics2_sky_stone_brick_0@1"
            ]
        },
        {
            "x": -10,
            "y": 9,
            "z": 5,
            "elements": [
                "contenttweaker:innerved_sky_stone@0"
            ]
        },
        {
            "x": 6,
            "y": 1,
            "z": 3,
            "elements": [
                "unlimitedchiselworks:chisel_stonebrick2_appliedenergistics2_sky_stone_brick_0@1"
            ]
        },
        {
            "x": -8,
            "y": 9,
            "z": 1,
            "elements": [
                "contenttweaker:innerved_sky_stone@0"
            ]
        },
        {
            "x": -11,
            "y": 7,
            "z": 7,
            "elements": [
                "contenttweaker:innerved_sky_stone@0"
            ]
        },
        {
            "x": -10,
            "y": 9,
            "z": 13,
            "elements": [
                "contenttweaker:innerved_sky_stone@0"
            ]
        },
        {
            "x": -11,
            "y": 7,
            "z": 9,
            "elements": [
                "contenttweaker:innerved_sky_stone@0"
            ]
        },
        {
            "x": 5,
            "y": -1,
            "z": 2,
            "elements": [
                "unlimitedchiselworks:chisel_stonebrick2_appliedenergistics2_sky_stone_brick_0@1"
            ]
        },
        {
            "x": 6,
            "y": 1,
            "z": 4,
            "elements": [
                "unlimitedchiselworks:chisel_stonebrick2_appliedenergistics2_sky_stone_brick_0@1"
            ]
        },
        {
            "x": 6,
            "y": 1,
            "z": 15,
            "elements": [
                "unlimitedchiselworks:chisel_stonebrick2_appliedenergistics2_sky_stone_brick_0@1"
            ]
        },
        {
            "x": 11,
            "y": 9,
            "z": 9,
            "elements": [
                "contenttweaker:innerved_sky_stone@0"
            ]
        },
        {
            "x": 6,
            "y": 1,
            "z": 14,
            "elements": [
                "unlimitedchiselworks:chisel_stonebrick2_appliedenergistics2_sky_stone_brick_0@1"
            ]
        },
        {
            "x": 11,
            "y": 9,
            "z": 7,
            "elements": [
                "contenttweaker:innerved_sky_stone@0"
            ]
        },
        {
            "x": 11,
            "y": 9,
            "z": 11,
            "elements": [
                "contenttweaker:innerved_sky_stone@0"
            ]
        },
        {
            "x": -5,
            "y": 14,
            "z": 3,
            "elements": [
                "contenttweaker:leaves_of_life"
            ]
        },
        {
            "x": 3,
            "y": -1,
            "z": 17,
            "elements": [
                "unlimitedchiselworks:chisel_stonebrick2_appliedenergistics2_sky_stone_brick_0@1"
            ]
        },
        {
            "x": 3,
            "y": -1,
            "z": 15,
            "elements": [
                "unlimitedchiselworks:chisel_stonebrick1_appliedenergistics2_sky_stone_brick_0@0"
            ]
        },
        {
            "x": 3,
            "y": -1,
            "z": 16,
            "elements": [
                "unlimitedchiselworks:chisel_stonebrick2_appliedenergistics2_sky_stone_brick_0@1"
            ]
        },
        {
            "x": 3,
            "y": -1,
            "z": 13,
            "elements": [
                "unlimitedchiselworks:chisel_stonebrick_appliedenergistics2_sky_stone_brick_0@8"
            ]
        },
        {
            "x": 3,
            "y": -1,
            "z": 14,
            "elements": [
                "unlimitedchiselworks:chisel_stonebrick_appliedenergistics2_sky_stone_brick_0@8"
            ]
        },
        {
            "x": 3,
            "y": -1,
            "z": 11,
            "elements": [
                "unlimitedchiselworks:chisel_stonebrick_appliedenergistics2_sky_stone_brick_0@8"
            ]
        },
        {
            "x": 3,
            "y": -1,
            "z": 12,
            "elements": [
                "unlimitedchiselworks:chisel_stonebrick_appliedenergistics2_sky_stone_brick_0@8"
            ]
        },
        {
            "x": 3,
            "y": -1,
            "z": 9,
            "elements": [
                "unlimitedchiselworks:chisel_stonebrick_appliedenergistics2_sky_stone_brick_0@8"
            ]
        },
        {
            "x": 3,
            "y": -1,
            "z": 10,
            "elements": [
                "unlimitedchiselworks:chisel_stonebrick_appliedenergistics2_sky_stone_brick_0@8"
            ]
        },
        {
            "x": 3,
            "y": -1,
            "z": 7,
            "elements": [
                "unlimitedchiselworks:chisel_stonebrick_appliedenergistics2_sky_stone_brick_0@8"
            ]
        },
        {
            "x": 3,
            "y": -1,
            "z": 8,
            "elements": [
                "unlimitedchiselworks:chisel_stonebrick_appliedenergistics2_sky_stone_brick_0@8"
            ]
        },
        {
            "x": 3,
            "y": -1,
            "z": 5,
            "elements": [
                "unlimitedchiselworks:chisel_stonebrick_appliedenergistics2_sky_stone_brick_0@8"
            ]
        },
        {
            "x": 3,
            "y": -1,
            "z": 6,
            "elements": [
                "unlimitedchiselworks:chisel_stonebrick_appliedenergistics2_sky_stone_brick_0@8"
            ]
        },
        {
            "x": 3,
            "y": -1,
            "z": 3,
            "elements": [
                "unlimitedchiselworks:chisel_stonebrick1_appliedenergistics2_sky_stone_brick_0@0"
            ]
        },
        {
            "x": 3,
            "y": -1,
            "z": 4,
            "elements": [
                "unlimitedchiselworks:chisel_stonebrick_appliedenergistics2_sky_stone_brick_0@8"
            ]
        },
        {
            "x": 3,
            "y": -1,
            "z": 1,
            "elements": [
                "unlimitedchiselworks:chisel_stonebrick2_appliedenergistics2_sky_stone_brick_0@1"
            ]
        },
        {
            "x": 3,
            "y": -1,
            "z": 2,
            "elements": [
                "unlimitedchiselworks:chisel_stonebrick2_appliedenergistics2_sky_stone_brick_0@1"
            ]
        },
        {
            "x": 4,
            "y": 0,
            "z": 7,
            "elements": [
                "chisel:futura@2"
            ]
        },
        {
            "x": -5,
            "y": 12,
            "z": 3,
            "elements": [
                "contenttweaker:leaves_of_life"
            ]
        },
        {
            "x": 4,
            "y": 0,
            "z": 8,
            "elements": [
                "chisel:futura@2"
            ]
        },
        {
            "x": 4,
            "y": 0,
            "z": 9,
            "elements": [
                "chisel:futura@2"
            ]
        },
        {
            "x": 4,
            "y": 0,
            "z": 10,
            "elements": [
                "chisel:futura@2"
            ]
        },
        {
            "x": 4,
            "y": 0,
            "z": 3,
            "elements": [
                "unlimitedchiselworks:chisel_stonebrick1_appliedenergistics2_sky_stone_brick_0@0"
            ]
        },
        {
            "x": 4,
            "y": 0,
            "z": 4,
            "elements": [
                "unlimitedchiselworks:chisel_stonebrick1_appliedenergistics2_sky_stone_brick_0@0"
            ]
        },
        {
            "x": 4,
            "y": 0,
            "z": 5,
            "elements": [
                "tconstruct:slime_grass"
            ]
        },
        {
            "x": 4,
            "y": 0,
            "z": 6,
            "elements": [
                "tconstruct:slime_grass"
            ]
        },
        {
            "x": 6,
            "y": -1,
            "z": 13,
            "elements": [
                "unlimitedchiselworks:chisel_stonebrick1_appliedenergistics2_sky_stone_brick_0@0"
            ]
        },
        {
            "x": 4,
            "y": 1,
            "z": 2,
            "elements": [
                "unlimitedchiselworks:chisel_stonebrick2_appliedenergistics2_sky_stone_brick_0@1"
            ]
        },
        {
            "x": 4,
            "y": 0,
            "z": 15,
            "elements": [
                "unlimitedchiselworks:chisel_stonebrick1_appliedenergistics2_sky_stone_brick_0@0"
            ]
        },
        {
            "x": 6,
            "y": -1,
            "z": 12,
            "elements": [
                "unlimitedchiselworks:chisel_stonebrick1_appliedenergistics2_sky_stone_brick_0@0"
            ]
        },
        {
            "x": 4,
            "y": 0,
            "z": 16,
            "elements": [
                "modularmachinery:blockoutputbus@6"
            ]
        },
        {
            "x": 6,
            "y": -1,
            "z": 11,
            "elements": [
                "unlimitedchiselworks:chisel_stonebrick1_appliedenergistics2_sky_stone_brick_0@0"
            ]
        },
        {
            "x": 6,
            "y": -1,
            "z": 10,
            "elements": [
                "unlimitedchiselworks:chisel_stonebrick_appliedenergistics2_sky_stone_brick_0@8"
            ]
        },
        {
            "x": 4,
            "y": 0,
            "z": 11,
            "elements": [
                "chisel:futura@2"
            ]
        },
        {
            "x": 4,
            "y": 0,
            "z": 12,
            "elements": [
                "tconstruct:slime_grass"
            ]
        },
        {
            "x": 6,
            "y": -1,
            "z": 15,
            "elements": [
                "unlimitedchiselworks:chisel_stonebrick2_appliedenergistics2_sky_stone_brick_0@1"
            ]
        },
        {
            "x": 4,
            "y": 0,
            "z": 13,
            "elements": [
                "tconstruct:slime_grass"
            ]
        },
        {
            "x": 6,
            "y": -1,
            "z": 14,
            "elements": [
                "unlimitedchiselworks:chisel_stonebrick2_appliedenergistics2_sky_stone_brick_0@1"
            ]
        },
        {
            "x": 4,
            "y": 0,
            "z": 14,
            "elements": [
                "unlimitedchiselworks:chisel_stonebrick1_appliedenergistics2_sky_stone_brick_0@0"
            ]
        },
        {
            "x": -1,
            "y": 17,
            "z": 19,
            "elements": [
                "contenttweaker:leaves_of_life"
            ]
        },
        {
            "x": -11,
            "y": 8,
            "z": 7,
            "elements": [
                "contenttweaker:innerved_sky_stone@0"
            ]
        },
        {
            "x": 10,
            "y": 8,
            "z": 13,
            "elements": [
                "contenttweaker:innerved_sky_stone@0"
            ]
        },
        {
            "x": -1,
            "y": 17,
            "z": 18,
            "elements": [
                "contenttweaker:leaves_of_life"
            ]
        },
        {
            "x": -11,
            "y": 8,
            "z": 9,
            "elements": [
                "contenttweaker:innerved_sky_stone@0"
            ]
        },
        {
            "x": -1,
            "y": 17,
            "z": 17,
            "elements": [
                "contenttweaker:leaves_of_life"
            ]
        },
        {
            "x": -11,
            "y": 8,
            "z": 8,
            "elements": [
                "contenttweaker:innerved_sky_stone@0"
            ]
        },
        {
            "x": -7,
            "y": 13,
            "z": 12,
            "elements": [
                "contenttweaker:leaves_of_life"
            ]
        },
        {
            "x": -11,
            "y": 8,
            "z": 11,
            "elements": [
                "contenttweaker:innerved_sky_stone@0"
            ]
        },
        {
            "x": -7,
            "y": 13,
            "z": 11,
            "elements": [
                "contenttweaker:sacred_eucalyptus"
            ]
        },
        {
            "x": -5,
            "y": 12,
            "z": 10,
            "elements": [
                "contenttweaker:leaves_of_life"
            ]
        },
        {
            "x": -11,
            "y": 8,
            "z": 10,
            "elements": [
                "contenttweaker:innerved_sky_stone@0"
            ]
        },
        {
            "x": -5,
            "y": 12,
            "z": 9,
            "elements": [
                "contenttweaker:leaves_of_life"
            ]
        },
        {
            "x": -7,
            "y": 13,
            "z": 10,
            "elements": [
                "contenttweaker:leaves_of_life"
            ]
        },
        {
            "x": 10,
            "y": 8,
            "z": 12,
            "elements": [
                "contenttweaker:innerved_sky_stone@0"
            ]
        },
        {
            "x": -7,
            "y": 13,
            "z": 9,
            "elements": [
                "contenttweaker:leaves_of_life"
            ]
        },
        {
            "x": 10,
            "y": 8,
            "z": 11,
            "elements": [
                "contenttweaker:innerved_sky_stone@0"
            ]
        },
        {
            "x": 10,
            "y": 8,
            "z": 6,
            "elements": [
                "contenttweaker:innerved_sky_stone@0"
            ]
        },
        {
            "x": -7,
            "y": 13,
            "z": 15,
            "elements": [
                "contenttweaker:leaves_of_life"
            ]
        },
        {
            "x": 10,
            "y": 8,
            "z": 5,
            "elements": [
                "contenttweaker:innerved_sky_stone@0"
            ]
        },
        {
            "x": -7,
            "y": 13,
            "z": 14,
            "elements": [
                "contenttweaker:leaves_of_life"
            ]
        },
        {
            "x": -7,
            "y": 13,
            "z": 13,
            "elements": [
                "contenttweaker:leaves_of_life"
            ]
        },
        {
            "x": 10,
            "y": 8,
            "z": 7,
            "elements": [
                "contenttweaker:innerved_sky_stone@0"
            ]
        },
        {
            "x": -2,
            "y": 15,
            "z": 18,
            "elements": [
                "contenttweaker:leaves_of_life"
            ]
        },
        {
            "x": 6,
            "y": -1,
            "z": 5,
            "elements": [
                "unlimitedchiselworks:chisel_stonebrick1_appliedenergistics2_sky_stone_brick_0@0"
            ]
        },
        {
            "x": 2,
            "y": -1,
            "z": 3,
            "elements": [
                "unlimitedchiselworks:chisel_stonebrick1_appliedenergistics2_sky_stone_brick_0@0"
            ]
        },
        {
            "x": -5,
            "y": 15,
            "z": 11,
            "elements": [
                "contenttweaker:leaves_of_life"
            ]
        },
        {
            "x": 2,
            "y": -1,
            "z": 2,
            "elements": [
                "unlimitedchiselworks:chisel_stonebrick1_appliedenergistics2_sky_stone_brick_0@0"
            ]
        },
        {
            "x": 6,
            "y": -1,
            "z": 4,
            "elements": [
                "unlimitedchiselworks:chisel_stonebrick2_appliedenergistics2_sky_stone_brick_0@1"
            ]
        },
        {
            "x": 2,
            "y": -1,
            "z": 5,
            "elements": [
                "unlimitedchiselworks:chisel_stonebrick_appliedenergistics2_sky_stone_brick_0@8"
            ]
        },
        {
            "x": 6,
            "y": -1,
            "z": 3,
            "elements": [
                "unlimitedchiselworks:chisel_stonebrick2_appliedenergistics2_sky_stone_brick_0@1"
            ]
        },
        {
            "x": -8,
            "y": 8,
            "z": 3,
            "elements": [
                "contenttweaker:innerved_sky_stone@0"
            ]
        },
        {
            "x": 2,
            "y": -1,
            "z": 4,
            "elements": [
                "unlimitedchiselworks:chisel_stonebrick_appliedenergistics2_sky_stone_brick_0@8"
            ]
        },
        {
            "x": 6,
            "y": -1,
            "z": 9,
            "elements": [
                "unlimitedchiselworks:chisel_stonebrick_appliedenergistics2_sky_stone_brick_0@8"
            ]
        },
        {
            "x": -2,
            "y": 15,
            "z": 17,
            "elements": [
                "contenttweaker:leaves_of_life"
            ]
        },
        {
            "x": -10,
            "y": 7,
            "z": 13,
            "elements": [
                "contenttweaker:innerved_sky_stone@0"
            ]
        },
        {
            "x": -8,
            "y": 8,
            "z": 1,
            "elements": [
                "contenttweaker:innerved_sky_stone@0"
            ]
        },
        {
            "x": 6,
            "y": -1,
            "z": 8,
            "elements": [
                "unlimitedchiselworks:chisel_stonebrick_appliedenergistics2_sky_stone_brick_0@8"
            ]
        },
        {
            "x": -2,
            "y": 15,
            "z": 16,
            "elements": [
                "contenttweaker:leaves_of_life"
            ]
        },
        {
            "x": -8,
            "y": 8,
            "z": 2,
            "elements": [
                "contenttweaker:innerved_sky_stone@0"
            ]
        },
        {
            "x": 6,
            "y": -1,
            "z": 7,
            "elements": [
                "unlimitedchiselworks:chisel_stonebrick1_appliedenergistics2_sky_stone_brick_0@0"
            ]
        },
        {
            "x": 2,
            "y": -1,
            "z": 1,
            "elements": [
                "unlimitedchiselworks:chisel_stonebrick2_appliedenergistics2_sky_stone_brick_0@1"
            ]
        },
        {
            "x": 6,
            "y": -1,
            "z": 6,
            "elements": [
                "unlimitedchiselworks:chisel_stonebrick1_appliedenergistics2_sky_stone_brick_0@0"
            ]
        },
        {
            "x": 2,
            "y": -1,
            "z": 11,
            "elements": [
                "unlimitedchiselworks:chisel_stonebrick_appliedenergistics2_sky_stone_brick_0@8"
            ]
        },
        {
            "x": -2,
            "y": 15,
            "z": 5,
            "elements": [
                "contenttweaker:leaves_of_life"
            ]
        },
        {
            "x": 2,
            "y": -1,
            "z": 10,
            "elements": [
                "unlimitedchiselworks:chisel_stonebrick_appliedenergistics2_sky_stone_brick_0@8"
            ]
        },
        {
            "x": -2,
            "y": 15,
            "z": 4,
            "elements": [
                "contenttweaker:leaves_of_life"
            ]
        },
        {
            "x": 2,
            "y": -1,
            "z": 13,
            "elements": [
                "unlimitedchiselworks:chisel_stonebrick_appliedenergistics2_sky_stone_brick_0@8"
            ]
        },
        {
            "x": -2,
            "y": 15,
            "z": 3,
            "elements": [
                "contenttweaker:leaves_of_life"
            ]
        },
        {
            "x": 2,
            "y": -1,
            "z": 12,
            "elements": [
                "unlimitedchiselworks:chisel_stonebrick_appliedenergistics2_sky_stone_brick_0@8"
            ]
        },
        {
            "x": -2,
            "y": 15,
            "z": 2,
            "elements": [
                "contenttweaker:leaves_of_life"
            ]
        },
        {
            "x": 2,
            "y": -1,
            "z": 7,
            "elements": [
                "unlimitedchiselworks:chisel_stonebrick_appliedenergistics2_sky_stone_brick_0@8"
            ]
        },
        {
            "x": -10,
            "y": 7,
            "z": 5,
            "elements": [
                "contenttweaker:innerved_sky_stone@0"
            ]
        },
        {
            "x": 2,
            "y": -1,
            "z": 6,
            "elements": [
                "unlimitedchiselworks:chisel_stonebrick_appliedenergistics2_sky_stone_brick_0@8"
            ]
        },
        {
            "x": 2,
            "y": -1,
            "z": 9,
            "elements": [
                "unlimitedchiselworks:chisel_stonebrick_appliedenergistics2_sky_stone_brick_0@8"
            ]
        },
        {
            "x": 2,
            "y": -1,
            "z": 8,
            "elements": [
                "unlimitedchiselworks:chisel_stonebrick_appliedenergistics2_sky_stone_brick_0@8"
            ]
        },
        {
            "x": -4,
            "y": 14,
            "z": 11,
            "elements": [
                "contenttweaker:leaves_of_life"
            ]
        },
        {
            "x": 2,
            "y": -1,
            "z": 15,
            "elements": [
                "unlimitedchiselworks:chisel_stonebrick1_appliedenergistics2_sky_stone_brick_0@0"
            ]
        },
        {
            "x": -8,
            "y": 8,
            "z": 17,
            "elements": [
                "contenttweaker:innerved_sky_stone@0"
            ]
        },
        {
            "x": 2,
            "y": -1,
            "z": 14,
            "elements": [
                "unlimitedchiselworks:chisel_stonebrick_appliedenergistics2_sky_stone_brick_0@8"
            ]
        },
        {
            "x": 2,
            "y": -1,
            "z": 17,
            "elements": [
                "unlimitedchiselworks:chisel_stonebrick2_appliedenergistics2_sky_stone_brick_0@1"
            ]
        },
        {
            "x": -8,
            "y": 8,
            "z": 15,
            "elements": [
                "contenttweaker:innerved_sky_stone@0"
            ]
        },
        {
            "x": 2,
            "y": -1,
            "z": 16,
            "elements": [
                "unlimitedchiselworks:chisel_stonebrick1_appliedenergistics2_sky_stone_brick_0@0"
            ]
        },
        {
            "x": -8,
            "y": 8,
            "z": 16,
            "elements": [
                "contenttweaker:innerved_sky_stone@0"
            ]
        },
        {
            "x": -4,
            "y": 14,
            "z": 2,
            "elements": [
                "contenttweaker:leaves_of_life"
            ]
        },
        {
            "x": -4,
            "y": 14,
            "z": 3,
            "elements": [
                "contenttweaker:leaves_of_life"
            ]
        },
        {
            "x": -4,
            "y": 14,
            "z": 4,
            "elements": [
                "contenttweaker:leaves_of_life"
            ]
        },
        {
            "x": 7,
            "y": 1,
            "z": 12,
            "elements": [
                "unlimitedchiselworks:chisel_stonebrick2_appliedenergistics2_sky_stone_brick_0@1"
            ]
        },
        {
            "x": 7,
            "y": 1,
            "z": 11,
            "elements": [
                "unlimitedchiselworks:chisel_stonebrick2_appliedenergistics2_sky_stone_brick_0@2"
            ]
        },
        {
            "x": 7,
            "y": 1,
            "z": 14,
            "elements": [
                "unlimitedchiselworks:chisel_stonebrick2_appliedenergistics2_sky_stone_brick_0@1"
            ]
        },
        {
            "x": 7,
            "y": 1,
            "z": 13,
            "elements": [
                "unlimitedchiselworks:chisel_stonebrick2_appliedenergistics2_sky_stone_brick_0@1"
            ]
        },
        {
            "x": 7,
            "y": 4,
            "z": 7,
            "elements": [
                "thaumadditions:mithrillium_block@0"
            ]
        },
        {
            "x": 7,
            "y": 1,
            "z": 7,
            "elements": [
                "unlimitedchiselworks:chisel_stonebrick2_appliedenergistics2_sky_stone_brick_0@2"
            ]
        },
        {
            "x": 7,
            "y": 4,
            "z": 11,
            "elements": [
                "thaumadditions:mithrillium_block@0"
            ]
        },
        {
            "x": 7,
            "y": 1,
            "z": 4,
            "elements": [
                "unlimitedchiselworks:chisel_stonebrick2_appliedenergistics2_sky_stone_brick_0@1"
            ]
        },
        {
            "x": 7,
            "y": 1,
            "z": 6,
            "elements": [
                "unlimitedchiselworks:chisel_stonebrick2_appliedenergistics2_sky_stone_brick_0@1"
            ]
        },
        {
            "x": 7,
            "y": 1,
            "z": 5,
            "elements": [
                "unlimitedchiselworks:chisel_stonebrick2_appliedenergistics2_sky_stone_brick_0@1"
            ]
        },
        {
            "x": -9,
            "y": 9,
            "z": 3,
            "elements": [
                "contenttweaker:innerved_sky_stone@0"
            ]
        },
        {
            "x": -3,
            "y": 16,
            "z": 18,
            "elements": [
                "contenttweaker:leaves_of_life"
            ]
        },
        {
            "x": -8,
            "y": 7,
            "z": 1,
            "elements": [
                "contenttweaker:innerved_sky_stone@0"
            ]
        },
        {
            "x": 3,
            "y": 1,
            "z": 1,
            "elements": [
                "unlimitedchiselworks:chisel_stonebrick2_appliedenergistics2_sky_stone_brick_0@1"
            ]
        },
        {
            "x": 3,
            "y": 1,
            "z": 2,
            "elements": [
                "unlimitedchiselworks:chisel_stonebrick2_appliedenergistics2_sky_stone_brick_0@1"
            ]
        },
        {
            "x": -7,
            "y": 8,
            "z": 17,
            "elements": [
                "contenttweaker:innerved_sky_stone@0"
            ]
        },
        {
            "x": 0,
            "y": 17,
            "z": 20,
            "elements": [
                "contenttweaker:leaves_of_life"
            ]
        },
        {
            "x": 0,
            "y": 17,
            "z": 18,
            "elements": [
                "contenttweaker:leaves_of_life"
            ]
        },
        {
            "x": 0,
            "y": 17,
            "z": 19,
            "elements": [
                "contenttweaker:leaves_of_life"
            ]
        },
        {
            "x": -8,
            "y": 7,
            "z": 17,
            "elements": [
                "contenttweaker:innerved_sky_stone@0"
            ]
        },
        {
            "x": 0,
            "y": 17,
            "z": 16,
            "elements": [
                "contenttweaker:leaves_of_life"
            ]
        },
        {
            "x": 0,
            "y": 17,
            "z": 17,
            "elements": [
                "contenttweaker:leaves_of_life"
            ]
        },
        {
            "x": -1,
            "y": 16,
            "z": 17,
            "elements": [
                "contenttweaker:leaves_of_life"
            ]
        },
        {
            "x": -1,
            "y": 16,
            "z": 16,
            "elements": [
                "contenttweaker:leaves_of_life"
            ]
        },
        {
            "x": -1,
            "y": 16,
            "z": 19,
            "elements": [
                "contenttweaker:leaves_of_life"
            ]
        },
        {
            "x": -8,
            "y": 14,
            "z": 8,
            "elements": [
                "contenttweaker:leaves_of_life"
            ]
        },
        {
            "x": -1,
            "y": 16,
            "z": 18,
            "elements": [
                "contenttweaker:leaves_of_life"
            ]
        },
        {
            "x": -8,
            "y": 14,
            "z": 7,
            "elements": [
                "contenttweaker:leaves_of_life"
            ]
        },
        {
            "x": 5,
            "y": 3,
            "z": 4,
            "elements": [
                "unlimitedchiselworks:chisel_stonebrick2_appliedenergistics2_sky_stone_brick_0@2"
            ]
        },
        {
            "x": -2,
            "y": 15,
            "z": 1,
            "elements": [
                "contenttweaker:leaves_of_life"
            ]
        },
        {
            "x": 9,
            "y": 8,
            "z": 5,
            "elements": [
                "contenttweaker:innerved_sky_stone@0"
            ]
        },
        {
            "x": -1,
            "y": 16,
            "z": 20,
            "elements": [
                "contenttweaker:leaves_of_life"
            ]
        },
        {
            "x": 9,
            "y": 8,
            "z": 4,
            "elements": [
                "contenttweaker:innerved_sky_stone@0"
            ]
        },
        {
            "x": 9,
            "y": 8,
            "z": 3,
            "elements": [
                "contenttweaker:innerved_sky_stone@0"
            ]
        },
        {
            "x": -8,
            "y": 13,
            "z": 12,
            "elements": [
                "contenttweaker:leaves_of_life"
            ]
        },
        {
            "x": -8,
            "y": 14,
            "z": 14,
            "elements": [
                "contenttweaker:leaves_of_life"
            ]
        },
        {
            "x": -8,
            "y": 13,
            "z": 13,
            "elements": [
                "contenttweaker:leaves_of_life"
            ]
        },
        {
            "x": -8,
            "y": 14,
            "z": 13,
            "elements": [
                "contenttweaker:leaves_of_life"
            ]
        },
        {
            "x": -8,
            "y": 13,
            "z": 10,
            "elements": [
                "contenttweaker:leaves_of_life"
            ]
        },
        {
            "x": -8,
            "y": 13,
            "z": 11,
            "elements": [
                "contenttweaker:leaves_of_life"
            ]
        },
        {
            "x": -8,
            "y": 14,
            "z": 15,
            "elements": [
                "contenttweaker:leaves_of_life"
            ]
        },
        {
            "x": -8,
            "y": 14,
            "z": 10,
            "elements": [
                "contenttweaker:leaves_of_life"
            ]
        },
        {
            "x": 9,
            "y": 8,
            "z": 13,
            "elements": [
                "contenttweaker:innerved_sky_stone@0"
            ]
        },
        {
            "x": -8,
            "y": 14,
            "z": 9,
            "elements": [
                "contenttweaker:leaves_of_life"
            ]
        },
        {
            "x": 5,
            "y": 3,
            "z": 14,
            "elements": [
                "unlimitedchiselworks:chisel_stonebrick2_appliedenergistics2_sky_stone_brick_0@2"
            ]
        },
        {
            "x": -8,
            "y": 13,
            "z": 14,
            "elements": [
                "contenttweaker:leaves_of_life"
            ]
        },
        {
            "x": -8,
            "y": 14,
            "z": 12,
            "elements": [
                "contenttweaker:leaves_of_life"
            ]
        },
        {
            "x": -8,
            "y": 14,
            "z": 11,
            "elements": [
                "contenttweaker:sacred_eucalyptus"
            ]
        },
        {
            "x": 9,
            "y": 8,
            "z": 15,
            "elements": [
                "contenttweaker:innerved_sky_stone@0"
            ]
        },
        {
            "x": 5,
            "y": 4,
            "z": 4,
            "elements": [
                "thaumadditions:mithrillium_block@0"
            ]
        },
        {
            "x": 9,
            "y": 8,
            "z": 14,
            "elements": [
                "contenttweaker:innerved_sky_stone@0"
            ]
        },
        {
            "x": -2,
            "y": 14,
            "z": 0,
            "elements": [
                "contenttweaker:leaves_of_life"
            ]
        },
        {
            "x": -2,
            "y": 14,
            "z": 1,
            "elements": [
                "contenttweaker:leaves_of_life"
            ]
        },
        {
            "x": -2,
            "y": 14,
            "z": 2,
            "elements": [
                "contenttweaker:leaves_of_life"
            ]
        },
        {
            "x": 3,
            "y": 1,
            "z": 17,
            "elements": [
                "unlimitedchiselworks:chisel_stonebrick2_appliedenergistics2_sky_stone_brick_0@1"
            ]
        },
        {
            "x": -2,
            "y": 14,
            "z": 3,
            "elements": [
                "contenttweaker:leaves_of_life"
            ]
        },
        {
            "x": -2,
            "y": 14,
            "z": 4,
            "elements": [
                "contenttweaker:leaves_of_life"
            ]
        },
        {
            "x": -2,
            "y": 14,
            "z": 5,
            "elements": [
                "contenttweaker:leaves_of_life"
            ]
        },
        {
            "x": 3,
            "y": 1,
            "z": 16,
            "elements": [
                "unlimitedchiselworks:chisel_stonebrick2_appliedenergistics2_sky_stone_brick_0@1"
            ]
        },
        {
            "x": -2,
            "y": 14,
            "z": 6,
            "elements": [
                "contenttweaker:leaves_of_life"
            ]
        },
        {
            "x": -6,
            "y": 16,
            "z": 11,
            "elements": [
                "contenttweaker:leaves_of_life"
            ]
        },
        {
            "x": -1,
            "y": 15,
            "z": 2,
            "elements": [
                "contenttweaker:leaves_of_life"
            ]
        },
        {
            "x": -1,
            "y": 15,
            "z": 4,
            "elements": [
                "contenttweaker:leaves_of_life"
            ]
        },
        {
            "x": -1,
            "y": 15,
            "z": 3,
            "elements": [
                "contenttweaker:leaves_of_life"
            ]
        },
        {
            "x": 4,
            "y": 1,
            "z": 16,
            "elements": [
                "unlimitedchiselworks:chisel_stonebrick2_appliedenergistics2_sky_stone_brick_0@1"
            ]
        },
        {
            "x": -3,
            "y": 12,
            "z": 13,
            "elements": [
                "contenttweaker:leaves_of_life"
            ]
        },
        {
            "x": -7,
            "y": 14,
            "z": 14,
            "elements": [
                "contenttweaker:leaves_of_life"
            ]
        },
        {
            "x": -3,
            "y": 12,
            "z": 10,
            "elements": [
                "contenttweaker:leaves_of_life"
            ]
        },
        {
            "x": -7,
            "y": 14,
            "z": 13,
            "elements": [
                "contenttweaker:leaves_of_life"
            ]
        },
        {
            "x": -3,
            "y": 12,
            "z": 11,
            "elements": [
                "contenttweaker:leaves_of_life"
            ]
        },
        {
            "x": -7,
            "y": 14,
            "z": 12,
            "elements": [
                "contenttweaker:leaves_of_life"
            ]
        },
        {
            "x": -3,
            "y": 12,
            "z": 8,
            "elements": [
                "contenttweaker:leaves_of_life"
            ]
        },
        {
            "x": -7,
            "y": 14,
            "z": 11,
            "elements": [
                "contenttweaker:leaves_of_life"
            ]
        },
        {
            "x": -3,
            "y": 12,
            "z": 9,
            "elements": [
                "contenttweaker:leaves_of_life"
            ]
        },
        {
            "x": -7,
            "y": 14,
            "z": 10,
            "elements": [
                "contenttweaker:leaves_of_life"
            ]
        },
        {
            "x": -3,
            "y": 12,
            "z": 6,
            "elements": [
                "contenttweaker:leaves_of_life"
            ]
        },
        {
            "x": -7,
            "y": 14,
            "z": 9,
            "elements": [
                "contenttweaker:leaves_of_life"
            ]
        },
        {
            "x": -3,
            "y": 12,
            "z": 7,
            "elements": [
                "contenttweaker:leaves_of_life"
            ]
        },
        {
            "x": -7,
            "y": 14,
            "z": 8,
            "elements": [
                "contenttweaker:leaves_of_life"
            ]
        },
        {
            "x": -1,
            "y": 15,
            "z": 16,
            "elements": [
                "contenttweaker:leaves_of_life"
            ]
        },
        {
            "x": -1,
            "y": 15,
            "z": 15,
            "elements": [
                "contenttweaker:leaves_of_life"
            ]
        },
        {
            "x": -7,
            "y": 8,
            "z": 1,
            "elements": [
                "contenttweaker:innerved_sky_stone@0"
            ]
        },
        {
            "x": -1,
            "y": 15,
            "z": 18,
            "elements": [
                "contenttweaker:leaves_of_life"
            ]
        },
        {
            "x": -1,
            "y": 15,
            "z": 17,
            "elements": [
                "contenttweaker:leaves_of_life"
            ]
        },
        {
            "x": -1,
            "y": 15,
            "z": 19,
            "elements": [
                "contenttweaker:leaves_of_life"
            ]
        },
        {
            "x": 9,
            "y": 0,
            "z": 10,
            "elements": [
                "appliedenergistics2:sky_stone_brick_stairs@1"
            ]
        },
        {
            "x": -6,
            "y": 11,
            "z": 11,
            "elements": [
                "contenttweaker:sacred_eucalyptus"
            ]
        },
        {
            "x": -6,
            "y": 11,
            "z": 10,
            "elements": [
                "contenttweaker:sacred_eucalyptus"
            ]
        },
        {
            "x": 9,
            "y": 0,
            "z": 8,
            "elements": [
                "appliedenergistics2:sky_stone_brick_stairs@1"
            ]
        },
        {
            "x": 9,
            "y": 0,
            "z": 9,
            "elements": [
                "appliedenergistics2:sky_stone_brick_stairs@1"
            ]
        },
        {
            "x": -2,
            "y": 13,
            "z": 0,
            "elements": [
                "contenttweaker:leaves_of_life"
            ]
        },
        {
            "x": -2,
            "y": 13,
            "z": 1,
            "elements": [
                "contenttweaker:leaves_of_life"
            ]
        },
        {
            "x": -2,
            "y": 13,
            "z": 2,
            "elements": [
                "contenttweaker:leaves_of_life"
            ]
        },
        {
            "x": -2,
            "y": 13,
            "z": 3,
            "elements": [
                "contenttweaker:sacred_eucalyptus"
            ]
        },
        {
            "x": 0,
            "y": -1,
            "z": -1,
            "elements": [
                "appliedenergistics2:sky_stone_brick_stairs@2"
            ]
        },
        {
            "x": -2,
            "y": 13,
            "z": -1,
            "elements": [
                "contenttweaker:leaves_of_life"
            ]
        },
        {
            "x": -2,
            "y": 13,
            "z": 5,
            "elements": [
                "contenttweaker:leaves_of_life"
            ]
        },
        {
            "x": -2,
            "y": 13,
            "z": 7,
            "elements": [
                "contenttweaker:leaves_of_life"
            ]
        },
        {
            "x": 0,
            "y": -1,
            "z": 17,
            "elements": [
                "unlimitedchiselworks:chisel_stonebrick2_appliedenergistics2_sky_stone_brick_0@1"
            ]
        },
        {
            "x": 6,
            "y": 0,
            "z": 8,
            "elements": [
                "tconstruct:slime_grass"
            ]
        },
        {
            "x": -3,
            "y": 12,
            "z": 4,
            "elements": [
                "contenttweaker:leaves_of_life"
            ]
        },
        {
            "x": 0,
            "y": -1,
            "z": 16,
            "elements": [
                "unlimitedchiselworks:chisel_stonebrick1_appliedenergistics2_sky_stone_brick_0@0"
            ]
        },
        {
            "x": 6,
            "y": 0,
            "z": 7,
            "elements": [
                "unlimitedchiselworks:chisel_stonebrick1_appliedenergistics2_sky_stone_brick_0@0"
            ]
        },
        {
            "x": -3,
            "y": 12,
            "z": 5,
            "elements": [
                "contenttweaker:leaves_of_life"
            ]
        },
        {
            "x": 0,
            "y": -1,
            "z": 19,
            "elements": [
                "appliedenergistics2:sky_stone_brick_stairs@3"
            ]
        },
        {
            "x": 6,
            "y": 0,
            "z": 6,
            "elements": [
                "unlimitedchiselworks:chisel_stonebrick1_appliedenergistics2_sky_stone_brick_0@0"
            ]
        },
        {
            "x": -3,
            "y": 12,
            "z": 2,
            "elements": [
                "contenttweaker:leaves_of_life"
            ]
        },
        {
            "x": 0,
            "y": -1,
            "z": 18,
            "elements": [
                "unlimitedchiselworks:chisel_stonebrick2_appliedenergistics2_sky_stone_brick_0@1"
            ]
        },
        {
            "x": 6,
            "y": 0,
            "z": 5,
            "elements": [
                "unlimitedchiselworks:chisel_stonebrick1_appliedenergistics2_sky_stone_brick_0@0"
            ]
        },
        {
            "x": -3,
            "y": 12,
            "z": 3,
            "elements": [
                "contenttweaker:leaves_of_life"
            ]
        },
        {
            "x": 6,
            "y": 0,
            "z": 4,
            "elements": [
                "unlimitedchiselworks:chisel_stonebrick2_appliedenergistics2_sky_stone_brick_0@1"
            ]
        },
        {
            "x": 6,
            "y": 0,
            "z": 3,
            "elements": [
                "modularmachinery:blockenergyoutputhatch@7"
            ]
        },
        {
            "x": -3,
            "y": 12,
            "z": 1,
            "elements": [
                "contenttweaker:leaves_of_life"
            ]
        },
        {
            "x": 6,
            "y": 0,
            "z": 15,
            "elements": [
                "modularmachinery:blockenergyinputhatch@7"
            ]
        },
        {
            "x": 6,
            "y": 0,
            "z": 14,
            "elements": [
                "unlimitedchiselworks:chisel_stonebrick2_appliedenergistics2_sky_stone_brick_0@1"
            ]
        },
        {
            "x": 8,
            "y": -1,
            "z": 12,
            "elements": [
                "unlimitedchiselworks:chisel_stonebrick2_appliedenergistics2_sky_stone_brick_0@1"
            ]
        },
        {
            "x": 6,
            "y": 0,
            "z": 13,
            "elements": [
                "unlimitedchiselworks:chisel_stonebrick1_appliedenergistics2_sky_stone_brick_0@0"
            ]
        },
        {
            "x": 8,
            "y": -1,
            "z": 11,
            "elements": [
                "unlimitedchiselworks:chisel_stonebrick2_appliedenergistics2_sky_stone_brick_0@1"
            ]
        },
        {
            "x": 6,
            "y": 0,
            "z": 12,
            "elements": [
                "unlimitedchiselworks:chisel_stonebrick1_appliedenergistics2_sky_stone_brick_0@0"
            ]
        },
        {
            "x": 8,
            "y": -1,
            "z": 10,
            "elements": [
                "unlimitedchiselworks:chisel_stonebrick2_appliedenergistics2_sky_stone_brick_0@1"
            ]
        },
        {
            "x": 6,
            "y": 0,
            "z": 11,
            "elements": [
                "unlimitedchiselworks:chisel_stonebrick1_appliedenergistics2_sky_stone_brick_0@0"
            ]
        },
        {
            "x": 8,
            "y": -1,
            "z": 9,
            "elements": [
                "unlimitedchiselworks:chisel_stonebrick2_appliedenergistics2_sky_stone_brick_0@1"
            ]
        },
        {
            "x": 6,
            "y": 0,
            "z": 10,
            "elements": [
                "tconstruct:slime_grass"
            ]
        },
        {
            "x": 8,
            "y": -1,
            "z": 8,
            "elements": [
                "unlimitedchiselworks:chisel_stonebrick2_appliedenergistics2_sky_stone_brick_0@1"
            ]
        },
        {
            "x": 6,
            "y": 0,
            "z": 9,
            "elements": [
                "tconstruct:slime_grass"
            ]
        },
        {
            "x": 8,
            "y": -1,
            "z": 7,
            "elements": [
                "unlimitedchiselworks:chisel_stonebrick2_appliedenergistics2_sky_stone_brick_0@1"
            ]
        },
        {
            "x": 0,
            "y": -1,
            "z": 1,
            "elements": [
                "unlimitedchiselworks:chisel_stonebrick2_appliedenergistics2_sky_stone_brick_0@1"
            ]
        },
        {
            "x": 8,
            "y": -1,
            "z": 6,
            "elements": [
                "unlimitedchiselworks:chisel_stonebrick2_appliedenergistics2_sky_stone_brick_0@1"
            ]
        },
        {
            "x": 0,
            "y": -1,
            "z": 0,
            "elements": [
                "unlimitedchiselworks:chisel_stonebrick2_appliedenergistics2_sky_stone_brick_0@1"
            ]
        },
        {
            "x": 0,
            "y": -1,
            "z": 3,
            "elements": [
                "unlimitedchiselworks:chisel_stonebrick_appliedenergistics2_sky_stone_brick_0@8"
            ]
        },
        {
            "x": 0,
            "y": -1,
            "z": 2,
            "elements": [
                "unlimitedchiselworks:chisel_stonebrick1_appliedenergistics2_sky_stone_brick_0@0"
            ]
        },
        {
            "x": 0,
            "y": -1,
            "z": 5,
            "elements": [
                "unlimitedchiselworks:chisel_stonebrick_appliedenergistics2_sky_stone_brick_0@8"
            ]
        },
        {
            "x": 6,
            "y": 7,
            "z": 0,
            "elements": [
                "contenttweaker:innerved_sky_stone@0"
            ]
        },
        {
            "x": 0,
            "y": -1,
            "z": 4,
            "elements": [
                "unlimitedchiselworks:chisel_stonebrick_appliedenergistics2_sky_stone_brick_0@8"
            ]
        },
        {
            "x": -3,
            "y": 11,
            "z": 6,
            "elements": [
                "contenttweaker:leaves_of_life"
            ]
        },
        {
            "x": 0,
            "y": -1,
            "z": 7,
            "elements": [
                "unlimitedchiselworks:chisel_stonebrick_appliedenergistics2_sky_stone_brick_0@8"
            ]
        },
        {
            "x": 0,
            "y": -1,
            "z": 6,
            "elements": [
                "unlimitedchiselworks:chisel_stonebrick_appliedenergistics2_sky_stone_brick_0@8"
            ]
        },
        {
            "x": 0,
            "y": -1,
            "z": 9,
            "elements": [
                "unlimitedchiselworks:chisel_stonebrick_appliedenergistics2_sky_stone_brick_0@8"
            ]
        },
        {
            "x": -3,
            "y": 11,
            "z": 9,
            "elements": [
                "contenttweaker:leaves_of_life"
            ]
        },
        {
            "x": 0,
            "y": -1,
            "z": 8,
            "elements": [
                "unlimitedchiselworks:chisel_stonebrick_appliedenergistics2_sky_stone_brick_0@8"
            ]
        },
        {
            "x": -3,
            "y": 11,
            "z": 10,
            "elements": [
                "contenttweaker:leaves_of_life"
            ]
        },
        {
            "x": 0,
            "y": -1,
            "z": 11,
            "elements": [
                "unlimitedchiselworks:chisel_stonebrick_appliedenergistics2_sky_stone_brick_0@8"
            ]
        },
        {
            "x": 0,
            "y": -1,
            "z": 10,
            "elements": [
                "unlimitedchiselworks:chisel_stonebrick_appliedenergistics2_sky_stone_brick_0@8"
            ]
        },
        {
            "x": -3,
            "y": 11,
            "z": 8,
            "elements": [
                "contenttweaker:leaves_of_life"
            ]
        },
        {
            "x": 0,
            "y": -1,
            "z": 13,
            "elements": [
                "unlimitedchiselworks:chisel_stonebrick_appliedenergistics2_sky_stone_brick_0@8"
            ]
        },
        {
            "x": 0,
            "y": -1,
            "z": 12,
            "elements": [
                "unlimitedchiselworks:chisel_stonebrick_appliedenergistics2_sky_stone_brick_0@8"
            ]
        },
        {
            "x": 0,
            "y": -1,
            "z": 15,
            "elements": [
                "unlimitedchiselworks:chisel_stonebrick_appliedenergistics2_sky_stone_brick_0@8"
            ]
        },
        {
            "x": -3,
            "y": 11,
            "z": 11,
            "elements": [
                "minecraft:air@0"
            ]
        },
        {
            "x": 0,
            "y": -1,
            "z": 14,
            "elements": [
                "unlimitedchiselworks:chisel_stonebrick_appliedenergistics2_sky_stone_brick_0@8"
            ]
        },
        {
            "x": -3,
            "y": 11,
            "z": 12,
            "elements": [
                "minecraft:air@0"
            ]
        },
        {
            "x": 3,
            "y": 0,
            "z": 6,
            "elements": [
                "chisel:futura@2"
            ]
        },
        {
            "x": 3,
            "y": 0,
            "z": 7,
            "elements": [
                "chisel:futura@2"
            ]
        },
        {
            "x": 3,
            "y": 0,
            "z": 4,
            "elements": [
                "tconstruct:slime_grass"
            ]
        },
        {
            "x": 3,
            "y": 0,
            "z": 5,
            "elements": [
                "tconstruct:slime_grass"
            ]
        },
        {
            "x": 3,
            "y": 0,
            "z": 10,
            "elements": [
                "tconstruct:slime_grass"
            ]
        },
        {
            "x": 5,
            "y": 4,
            "z": 14,
            "elements": [
                "thaumadditions:mithrillium_block@0"
            ]
        },
        {
            "x": 3,
            "y": 0,
            "z": 11,
            "elements": [
                "chisel:futura@2"
            ]
        },
        {
            "x": 3,
            "y": 0,
            "z": 8,
            "elements": [
                "tconstruct:slime_grass"
            ]
        },
        {
            "x": 3,
            "y": 0,
            "z": 9,
            "elements": [
                "tconstruct:slime_grass"
            ]
        },
        {
            "x": 3,
            "y": 0,
            "z": 2,
            "elements": [
                "unlimitedchiselworks:chisel_stonebrick2_appliedenergistics2_sky_stone_brick_0@1"
            ]
        },
        {
            "x": 3,
            "y": 0,
            "z": 3,
            "elements": [
                "unlimitedchiselworks:chisel_stonebrick1_appliedenergistics2_sky_stone_brick_0@0"
            ]
        },
        {
            "x": 3,
            "y": 0,
            "z": 1,
            "elements": [
                "unlimitedchiselworks:chisel_stonebrick2_appliedenergistics2_sky_stone_brick_0@1"
            ]
        },
        {
            "x": 10,
            "y": 9,
            "z": 5,
            "elements": [
                "contenttweaker:innerved_sky_stone@0"
            ]
        },
        {
            "x": -5,
            "y": 13,
            "z": 4,
            "elements": [
                "contenttweaker:leaves_of_life"
            ]
        },
        {
            "x": -5,
            "y": 13,
            "z": 3,
            "elements": [
                "contenttweaker:leaves_of_life"
            ]
        },
        {
            "x": -5,
            "y": 13,
            "z": 2,
            "elements": [
                "contenttweaker:leaves_of_life"
            ]
        },
        {
            "x": -8,
            "y": 13,
            "z": 8,
            "elements": [
                "contenttweaker:leaves_of_life"
            ]
        },
        {
            "x": -8,
            "y": 13,
            "z": 9,
            "elements": [
                "contenttweaker:leaves_of_life"
            ]
        },
        {
            "x": 3,
            "y": 0,
            "z": 14,
            "elements": [
                "tconstruct:slime_grass"
            ]
        },
        {
            "x": 3,
            "y": 0,
            "z": 15,
            "elements": [
                "unlimitedchiselworks:chisel_stonebrick1_appliedenergistics2_sky_stone_brick_0@0"
            ]
        },
        {
            "x": -5,
            "y": 13,
            "z": 13,
            "elements": [
                "contenttweaker:leaves_of_life"
            ]
        },
        {
            "x": 3,
            "y": 0,
            "z": 12,
            "elements": [
                "chisel:futura@2"
            ]
        },
        {
            "x": -5,
            "y": 13,
            "z": 12,
            "elements": [
                "contenttweaker:leaves_of_life"
            ]
        },
        {
            "x": 3,
            "y": 0,
            "z": 13,
            "elements": [
                "tconstruct:slime_grass"
            ]
        },
        {
            "x": -5,
            "y": 13,
            "z": 11,
            "elements": [
                "contenttweaker:leaves_of_life"
            ]
        },
        {
            "x": -5,
            "y": 13,
            "z": 10,
            "elements": [
                "contenttweaker:leaves_of_life"
            ]
        },
        {
            "x": -5,
            "y": 13,
            "z": 9,
            "elements": [
                "contenttweaker:leaves_of_life"
            ]
        },
        {
            "x": 3,
            "y": 0,
            "z": 16,
            "elements": [
                "unlimitedchiselworks:chisel_stonebrick2_appliedenergistics2_sky_stone_brick_0@1"
            ]
        },
        {
            "x": 13,
            "y": 16,
            "z": 9,
            "elements": [
                "contenttweaker:leaves_of_life"
            ]
        },
        {
            "x": 3,
            "y": 0,
            "z": 17,
            "elements": [
                "unlimitedchiselworks:chisel_stonebrick2_appliedenergistics2_sky_stone_brick_0@1"
            ]
        },
        {
            "x": -4,
            "y": 9,
            "z": 10,
            "elements": [
                "contenttweaker:sacred_eucalyptus"
            ]
        },
        {
            "x": -4,
            "y": 9,
            "z": 19,
            "elements": [
                "contenttweaker:innerved_sky_stone@0"
            ]
        },
        {
            "x": 10,
            "y": 9,
            "z": 13,
            "elements": [
                "contenttweaker:innerved_sky_stone@0"
            ]
        },
        {
            "x": 9,
            "y": 7,
            "z": 15,
            "elements": [
                "contenttweaker:innerved_sky_stone@0"
            ]
        },
        {
            "x": -7,
            "y": 15,
            "z": 10,
            "elements": [
                "contenttweaker:leaves_of_life"
            ]
        },
        {
            "x": -7,
            "y": 15,
            "z": 9,
            "elements": [
                "contenttweaker:leaves_of_life"
            ]
        },
        {
            "x": -7,
            "y": 15,
            "z": 13,
            "elements": [
                "contenttweaker:leaves_of_life"
            ]
        },
        {
            "x": -7,
            "y": 15,
            "z": 12,
            "elements": [
                "contenttweaker:leaves_of_life"
            ]
        },
        {
            "x": -7,
            "y": 15,
            "z": 11,
            "elements": [
                "contenttweaker:leaves_of_life"
            ]
        },
        {
            "x": 9,
            "y": 7,
            "z": 3,
            "elements": [
                "contenttweaker:innerved_sky_stone@0"
            ]
        },
        {
            "x": 0,
            "y": 18,
            "z": 19,
            "elements": [
                "contenttweaker:leaves_of_life"
            ]
        },
        {
            "x": 0,
            "y": 18,
            "z": 17,
            "elements": [
                "contenttweaker:leaves_of_life"
            ]
        },
        {
            "x": 0,
            "y": 18,
            "z": 18,
            "elements": [
                "contenttweaker:leaves_of_life"
            ]
        },
        {
            "x": -1,
            "y": -1,
            "z": 17,
            "elements": [
                "unlimitedchiselworks:chisel_stonebrick2_appliedenergistics2_sky_stone_brick_0@1"
            ]
        },
        {
            "x": -1,
            "y": -1,
            "z": 18,
            "elements": [
                "unlimitedchiselworks:chisel_stonebrick2_appliedenergistics2_sky_stone_brick_0@1"
            ]
        },
        {
            "x": -1,
            "y": -1,
            "z": 19,
            "elements": [
                "appliedenergistics2:sky_stone_brick_stairs@3"
            ]
        },
        {
            "x": -1,
            "y": -1,
            "z": 9,
            "elements": [
                "unlimitedchiselworks:chisel_stonebrick_appliedenergistics2_sky_stone_brick_0@8"
            ]
        },
        {
            "x": -2,
            "y": 11,
            "z": 10,
            "elements": [
                "contenttweaker:leaves_of_life"
            ]
        },
        {
            "x": -1,
            "y": -1,
            "z": 10,
            "elements": [
                "unlimitedchiselworks:chisel_stonebrick_appliedenergistics2_sky_stone_brick_0@8"
            ]
        },
        {
            "x": -2,
            "y": 11,
            "z": 11,
            "elements": [
                "contenttweaker:leaves_of_life"
            ]
        },
        {
            "x": -1,
            "y": -1,
            "z": 11,
            "elements": [
                "unlimitedchiselworks:chisel_stonebrick_appliedenergistics2_sky_stone_brick_0@8"
            ]
        },
        {
            "x": -11,
            "y": 13,
            "z": 11,
            "elements": [
                "contenttweaker:leaves_of_life"
            ]
        },
        {
            "x": -1,
            "y": -1,
            "z": 12,
            "elements": [
                "unlimitedchiselworks:chisel_stonebrick_appliedenergistics2_sky_stone_brick_0@8"
            ]
        },
        {
            "x": -1,
            "y": -1,
            "z": 13,
            "elements": [
                "unlimitedchiselworks:chisel_stonebrick_appliedenergistics2_sky_stone_brick_0@8"
            ]
        },
        {
            "x": -2,
            "y": 11,
            "z": 6,
            "elements": [
                "contenttweaker:leaves_of_life"
            ]
        },
        {
            "x": -1,
            "y": -1,
            "z": 14,
            "elements": [
                "unlimitedchiselworks:chisel_stonebrick_appliedenergistics2_sky_stone_brick_0@8"
            ]
        },
        {
            "x": -2,
            "y": 11,
            "z": 7,
            "elements": [
                "contenttweaker:leaves_of_life"
            ]
        },
        {
            "x": -1,
            "y": -1,
            "z": 15,
            "elements": [
                "unlimitedchiselworks:chisel_stonebrick_appliedenergistics2_sky_stone_brick_0@8"
            ]
        },
        {
            "x": -2,
            "y": 11,
            "z": 8,
            "elements": [
                "contenttweaker:leaves_of_life"
            ]
        },
        {
            "x": -1,
            "y": -1,
            "z": 16,
            "elements": [
                "unlimitedchiselworks:chisel_stonebrick1_appliedenergistics2_sky_stone_brick_0@0"
            ]
        },
        {
            "x": -2,
            "y": 11,
            "z": 9,
            "elements": [
                "contenttweaker:leaves_of_life"
            ]
        },
        {
            "x": -1,
            "y": -1,
            "z": 1,
            "elements": [
                "unlimitedchiselworks:chisel_stonebrick2_appliedenergistics2_sky_stone_brick_0@1"
            ]
        },
        {
            "x": 1,
            "y": 15,
            "z": 16,
            "elements": [
                "contenttweaker:leaves_of_life"
            ]
        },
        {
            "x": -1,
            "y": -1,
            "z": 2,
            "elements": [
                "unlimitedchiselworks:chisel_stonebrick1_appliedenergistics2_sky_stone_brick_0@0"
            ]
        },
        {
            "x": 1,
            "y": 15,
            "z": 15,
            "elements": [
                "contenttweaker:leaves_of_life"
            ]
        },
        {
            "x": -1,
            "y": -1,
            "z": 3,
            "elements": [
                "unlimitedchiselworks:chisel_stonebrick_appliedenergistics2_sky_stone_brick_0@8"
            ]
        },
        {
            "x": 1,
            "y": 15,
            "z": 18,
            "elements": [
                "contenttweaker:leaves_of_life"
            ]
        },
        {
            "x": -1,
            "y": -1,
            "z": 4,
            "elements": [
                "unlimitedchiselworks:chisel_stonebrick_appliedenergistics2_sky_stone_brick_0@8"
            ]
        },
        {
            "x": 1,
            "y": 15,
            "z": 17,
            "elements": [
                "contenttweaker:sacred_eucalyptus"
            ]
        },
        {
            "x": -1,
            "y": -1,
            "z": 5,
            "elements": [
                "unlimitedchiselworks:chisel_stonebrick_appliedenergistics2_sky_stone_brick_0@8"
            ]
        },
        {
            "x": 0,
            "y": 0,
            "z": 16,
            "elements": [
                "unlimitedchiselworks:chisel_stonebrick1_appliedenergistics2_sky_stone_brick_0@0"
            ]
        },
        {
            "x": 1,
            "y": 15,
            "z": 20,
            "elements": [
                "contenttweaker:leaves_of_life"
            ]
        },
        {
            "x": -4,
            "y": 9,
            "z": -1,
            "elements": [
                "contenttweaker:innerved_sky_stone@0"
            ]
        },
        {
            "x": -1,
            "y": -1,
            "z": 6,
            "elements": [
                "unlimitedchiselworks:chisel_stonebrick_appliedenergistics2_sky_stone_brick_0@8"
            ]
        },
        {
            "x": 0,
            "y": 0,
            "z": 15,
            "elements": [
                "tconstruct:slime_grass"
            ]
        },
        {
            "x": 1,
            "y": 15,
            "z": 19,
            "elements": [
                "contenttweaker:leaves_of_life"
            ]
        },
        {
            "x": -1,
            "y": -1,
            "z": 7,
            "elements": [
                "unlimitedchiselworks:chisel_stonebrick_appliedenergistics2_sky_stone_brick_0@8"
            ]
        },
        {
            "x": 0,
            "y": 0,
            "z": 18,
            "elements": [
                "appliedenergistics2:sky_stone_brick_stairs@3"
            ]
        },
        {
            "x": -1,
            "y": -1,
            "z": 8,
            "elements": [
                "unlimitedchiselworks:chisel_stonebrick_appliedenergistics2_sky_stone_brick_0@8"
            ]
        },
        {
            "x": 0,
            "y": 0,
            "z": 17,
            "elements": [
                "unlimitedchiselworks:chisel_stonebrick2_appliedenergistics2_sky_stone_brick_0@1"
            ]
        },
        {
            "x": 1,
            "y": 15,
            "z": 21,
            "elements": [
                "contenttweaker:leaves_of_life"
            ]
        },
        {
            "x": 0,
            "y": 0,
            "z": 12,
            "elements": [
                "tconstruct:slime_grass"
            ]
        },
        {
            "x": 0,
            "y": 14,
            "z": 4,
            "elements": [
                "contenttweaker:leaves_of_life"
            ]
        },
        {
            "x": 0,
            "y": 0,
            "z": 11,
            "elements": [
                "tconstruct:slime_grass"
            ]
        },
        {
            "x": 0,
            "y": 14,
            "z": 3,
            "elements": [
                "contenttweaker:leaves_of_life"
            ]
        },
        {
            "x": 0,
            "y": 0,
            "z": 14,
            "elements": [
                "tconstruct:slime_grass"
            ]
        },
        {
            "x": 0,
            "y": 14,
            "z": 2,
            "elements": [
                "contenttweaker:leaves_of_life"
            ]
        },
        {
            "x": 0,
            "y": 0,
            "z": 13,
            "elements": [
                "chisel:futura@2"
            ]
        },
        {
            "x": 0,
            "y": 0,
            "z": 8,
            "elements": [
                "tconstruct:slime_grass"
            ]
        },
        {
            "x": 0,
            "y": 0,
            "z": 7,
            "elements": [
                "tconstruct:slime_grass"
            ]
        },
        {
            "x": -1,
            "y": -1,
            "z": -1,
            "elements": [
                "appliedenergistics2:sky_stone_brick_stairs@2"
            ]
        },
        {
            "x": 0,
            "y": 0,
            "z": 10,
            "elements": [
                "tconstruct:slime_grass"
            ]
        },
        {
            "x": 1,
            "y": 15,
            "z": 14,
            "elements": [
                "contenttweaker:leaves_of_life"
            ]
        },
        {
            "x": -1,
            "y": -1,
            "z": 0,
            "elements": [
                "unlimitedchiselworks:chisel_stonebrick2_appliedenergistics2_sky_stone_brick_0@1"
            ]
        },
        {
            "x": 0,
            "y": 0,
            "z": 9,
            "elements": [
                "tconstruct:slime_grass"
            ]
        },
        {
            "x": 0,
            "y": 0,
            "z": 4,
            "elements": [
                "tconstruct:slime_grass"
            ]
        },
        {
            "x": 0,
            "y": 0,
            "z": 3,
            "elements": [
                "tconstruct:slime_grass"
            ]
        },
        {
            "x": 0,
            "y": 0,
            "z": 6,
            "elements": [
                "tconstruct:slime_grass"
            ]
        },
        {
            "x": 1,
            "y": 2,
            "z": 9,
            "elements": [
                "contenttweaker:sacred_eucalyptus"
            ]
        },
        {
            "x": 0,
            "y": 0,
            "z": 5,
            "elements": [
                "chisel:futura@2"
            ]
        },
        {
            "x": -4,
            "y": 8,
            "z": 19,
            "elements": [
                "contenttweaker:innerved_sky_stone@0"
            ]
        },
        {
            "x": 0,
            "y": 0,
            "z": 2,
            "elements": [
                "unlimitedchiselworks:chisel_stonebrick1_appliedenergistics2_sky_stone_brick_0@0"
            ]
        },
        {
            "x": 0,
            "y": 0,
            "z": 1,
            "elements": [
                "unlimitedchiselworks:chisel_stonebrick2_appliedenergistics2_sky_stone_brick_0@1"
            ]
        },
        {
            "x": 0,
            "y": 13,
            "z": 9,
            "elements": [
                "contenttweaker:leaves_of_life"
            ]
        },
        {
            "x": 0,
            "y": 13,
            "z": 8,
            "elements": [
                "contenttweaker:leaves_of_life"
            ]
        },
        {
            "x": -4,
            "y": 8,
            "z": 10,
            "elements": [
                "contenttweaker:sacred_eucalyptus"
            ]
        },
        {
            "x": -2,
            "y": 11,
            "z": 4,
            "elements": [
                "contenttweaker:sacred_eucalyptus"
            ]
        },
        {
            "x": 0,
            "y": 13,
            "z": 6,
            "elements": [
                "contenttweaker:leaves_of_life"
            ]
        },
        {
            "x": 0,
            "y": 13,
            "z": 5,
            "elements": [
                "contenttweaker:leaves_of_life"
            ]
        },
        {
            "x": 0,
            "y": 13,
            "z": 4,
            "elements": [
                "contenttweaker:leaves_of_life"
            ]
        },
        {
            "x": 0,
            "y": 13,
            "z": 3,
            "elements": [
                "contenttweaker:leaves_of_life"
            ]
        },
        {
            "x": 0,
            "y": 13,
            "z": 2,
            "elements": [
                "contenttweaker:leaves_of_life"
            ]
        },
        {
            "x": -4,
            "y": 8,
            "z": 18,
            "elements": [
                "contenttweaker:innerved_sky_stone@0"
            ]
        },
        {
            "x": 0,
            "y": 13,
            "z": 13,
            "elements": [
                "contenttweaker:leaves_of_life"
            ]
        },
        {
            "x": 0,
            "y": 13,
            "z": 12,
            "elements": [
                "contenttweaker:leaves_of_life"
            ]
        },
        {
            "x": 0,
            "y": 13,
            "z": 11,
            "elements": [
                "contenttweaker:leaves_of_life"
            ]
        },
        {
            "x": 0,
            "y": 13,
            "z": 10,
            "elements": [
                "contenttweaker:leaves_of_life"
            ]
        },
        {
            "x": 11,
            "y": 15,
            "z": 8,
            "elements": [
                "contenttweaker:leaves_of_life"
            ]
        },
        {
            "x": 11,
            "y": 15,
            "z": 10,
            "elements": [
                "contenttweaker:leaves_of_life"
            ]
        },
        {
            "x": 11,
            "y": 15,
            "z": 9,
            "elements": [
                "contenttweaker:leaves_of_life"
            ]
        },
        {
            "x": 0,
            "y": 13,
            "z": 1,
            "elements": [
                "contenttweaker:leaves_of_life"
            ]
        },
        {
            "x": -10,
            "y": 15,
            "z": 12,
            "elements": [
                "contenttweaker:leaves_of_life"
            ]
        },
        {
            "x": -10,
            "y": 15,
            "z": 10,
            "elements": [
                "contenttweaker:leaves_of_life"
            ]
        },
        {
            "x": -10,
            "y": 15,
            "z": 11,
            "elements": [
                "contenttweaker:leaves_of_life"
            ]
        },
        {
            "x": 7,
            "y": 8,
            "z": 17,
            "elements": [
                "contenttweaker:innerved_sky_stone@0"
            ]
        },
        {
            "x": -2,
            "y": -1,
            "z": 16,
            "elements": [
                "unlimitedchiselworks:chisel_stonebrick1_appliedenergistics2_sky_stone_brick_0@0"
            ]
        },
        {
            "x": -1,
            "y": 12,
            "z": 6,
            "elements": [
                "contenttweaker:leaves_of_life"
            ]
        },
        {
            "x": -2,
            "y": -1,
            "z": 17,
            "elements": [
                "unlimitedchiselworks:chisel_stonebrick2_appliedenergistics2_sky_stone_brick_0@1"
            ]
        },
        {
            "x": -1,
            "y": 12,
            "z": 7,
            "elements": [
                "contenttweaker:leaves_of_life"
            ]
        },
        {
            "x": 7,
            "y": 8,
            "z": 1,
            "elements": [
                "contenttweaker:innerved_sky_stone@0"
            ]
        },
        {
            "x": -2,
            "y": -1,
            "z": 14,
            "elements": [
                "unlimitedchiselworks:chisel_stonebrick_appliedenergistics2_sky_stone_brick_0@8"
            ]
        },
        {
            "x": -1,
            "y": 12,
            "z": 4,
            "elements": [
                "contenttweaker:leaves_of_life"
            ]
        },
        {
            "x": -2,
            "y": -1,
            "z": 15,
            "elements": [
                "unlimitedchiselworks:chisel_stonebrick1_appliedenergistics2_sky_stone_brick_0@0"
            ]
        },
        {
            "x": -1,
            "y": 12,
            "z": 5,
            "elements": [
                "contenttweaker:leaves_of_life"
            ]
        },
        {
            "x": -2,
            "y": -1,
            "z": 12,
            "elements": [
                "unlimitedchiselworks:chisel_stonebrick_appliedenergistics2_sky_stone_brick_0@8"
            ]
        },
        {
            "x": -1,
            "y": 12,
            "z": 10,
            "elements": [
                "contenttweaker:leaves_of_life"
            ]
        },
        {
            "x": -2,
            "y": -1,
            "z": 13,
            "elements": [
                "unlimitedchiselworks:chisel_stonebrick_appliedenergistics2_sky_stone_brick_0@8"
            ]
        },
        {
            "x": -1,
            "y": 12,
            "z": 11,
            "elements": [
                "contenttweaker:leaves_of_life"
            ]
        },
        {
            "x": -2,
            "y": -1,
            "z": 10,
            "elements": [
                "unlimitedchiselworks:chisel_stonebrick_appliedenergistics2_sky_stone_brick_0@8"
            ]
        },
        {
            "x": -1,
            "y": 12,
            "z": 8,
            "elements": [
                "contenttweaker:leaves_of_life"
            ]
        },
        {
            "x": -2,
            "y": -1,
            "z": 11,
            "elements": [
                "unlimitedchiselworks:chisel_stonebrick_appliedenergistics2_sky_stone_brick_0@8"
            ]
        },
        {
            "x": -1,
            "y": 12,
            "z": 9,
            "elements": [
                "contenttweaker:leaves_of_life"
            ]
        },
        {
            "x": -2,
            "y": -1,
            "z": 8,
            "elements": [
                "unlimitedchiselworks:chisel_stonebrick_appliedenergistics2_sky_stone_brick_0@8"
            ]
        },
        {
            "x": -1,
            "y": 12,
            "z": 14,
            "elements": [
                "contenttweaker:leaves_of_life"
            ]
        },
        {
            "x": -2,
            "y": -1,
            "z": 9,
            "elements": [
                "unlimitedchiselworks:chisel_stonebrick_appliedenergistics2_sky_stone_brick_0@8"
            ]
        },
        {
            "x": -2,
            "y": -1,
            "z": 6,
            "elements": [
                "unlimitedchiselworks:chisel_stonebrick_appliedenergistics2_sky_stone_brick_0@8"
            ]
        },
        {
            "x": -1,
            "y": 12,
            "z": 12,
            "elements": [
                "contenttweaker:leaves_of_life"
            ]
        },
        {
            "x": -2,
            "y": -1,
            "z": 7,
            "elements": [
                "unlimitedchiselworks:chisel_stonebrick_appliedenergistics2_sky_stone_brick_0@8"
            ]
        },
        {
            "x": -1,
            "y": 12,
            "z": 13,
            "elements": [
                "contenttweaker:leaves_of_life"
            ]
        },
        {
            "x": -2,
            "y": -1,
            "z": 4,
            "elements": [
                "unlimitedchiselworks:chisel_stonebrick_appliedenergistics2_sky_stone_brick_0@8"
            ]
        },
        {
            "x": -2,
            "y": -1,
            "z": 5,
            "elements": [
                "unlimitedchiselworks:chisel_stonebrick_appliedenergistics2_sky_stone_brick_0@8"
            ]
        },
        {
            "x": -2,
            "y": -1,
            "z": 2,
            "elements": [
                "unlimitedchiselworks:chisel_stonebrick1_appliedenergistics2_sky_stone_brick_0@0"
            ]
        },
        {
            "x": -2,
            "y": -1,
            "z": 3,
            "elements": [
                "unlimitedchiselworks:chisel_stonebrick1_appliedenergistics2_sky_stone_brick_0@0"
            ]
        },
        {
            "x": 10,
            "y": -1,
            "z": 8,
            "elements": [
                "appliedenergistics2:sky_stone_brick_stairs@1"
            ]
        },
        {
            "x": 12,
            "y": 16,
            "z": 10,
            "elements": [
                "contenttweaker:leaves_of_life"
            ]
        },
        {
            "x": -2,
            "y": -1,
            "z": 1,
            "elements": [
                "unlimitedchiselworks:chisel_stonebrick2_appliedenergistics2_sky_stone_brick_0@1"
            ]
        },
        {
            "x": 10,
            "y": -1,
            "z": 9,
            "elements": [
                "appliedenergistics2:sky_stone_brick_stairs@1"
            ]
        },
        {
            "x": 12,
            "y": 16,
            "z": 9,
            "elements": [
                "contenttweaker:leaves_of_life"
            ]
        },
        {
            "x": 12,
            "y": 16,
            "z": 8,
            "elements": [
                "contenttweaker:leaves_of_life"
            ]
        },
        {
            "x": 2,
            "y": 17,
            "z": 20,
            "elements": [
                "contenttweaker:leaves_of_life"
            ]
        },
        {
            "x": 10,
            "y": -1,
            "z": 10,
            "elements": [
                "appliedenergistics2:sky_stone_brick_stairs@1"
            ]
        },
        {
            "x": -1,
            "y": 12,
            "z": 2,
            "elements": [
                "contenttweaker:leaves_of_life"
            ]
        },
        {
            "x": 2,
            "y": 17,
            "z": 18,
            "elements": [
                "contenttweaker:leaves_of_life"
            ]
        },
        {
            "x": -1,
            "y": 12,
            "z": 3,
            "elements": [
                "contenttweaker:leaves_of_life"
            ]
        },
        {
            "x": 2,
            "y": 17,
            "z": 19,
            "elements": [
                "contenttweaker:leaves_of_life"
            ]
        },
        {
            "x": 2,
            "y": 17,
            "z": 16,
            "elements": [
                "contenttweaker:leaves_of_life"
            ]
        },
        {
            "x": -1,
            "y": 12,
            "z": 1,
            "elements": [
                "contenttweaker:leaves_of_life"
            ]
        },
        {
            "x": 2,
            "y": 17,
            "z": 17,
            "elements": [
                "contenttweaker:leaves_of_life"
            ]
        },
        {
            "x": -10,
            "y": 16,
            "z": 11,
            "elements": [
                "contenttweaker:leaves_of_life"
            ]
        },
        {
            "x": -1,
            "y": 14,
            "z": 3,
            "elements": [
                "contenttweaker:leaves_of_life"
            ]
        },
        {
            "x": -1,
            "y": 14,
            "z": 2,
            "elements": [
                "contenttweaker:leaves_of_life"
            ]
        },
        {
            "x": -1,
            "y": 14,
            "z": 5,
            "elements": [
                "contenttweaker:leaves_of_life"
            ]
        },
        {
            "x": -4,
            "y": 7,
            "z": -1,
            "elements": [
                "contenttweaker:innerved_sky_stone@0"
            ]
        },
        {
            "x": -1,
            "y": 14,
            "z": 4,
            "elements": [
                "contenttweaker:leaves_of_life"
            ]
        },
        {
            "x": -1,
            "y": 11,
            "z": 11,
            "elements": [
                "contenttweaker:leaves_of_life"
            ]
        },
        {
            "x": 2,
            "y": 18,
            "z": 17,
            "elements": [
                "contenttweaker:leaves_of_life"
            ]
        },
        {
            "x": -1,
            "y": 11,
            "z": 12,
            "elements": [
                "contenttweaker:leaves_of_life"
            ]
        },
        {
            "x": 2,
            "y": 18,
            "z": 18,
            "elements": [
                "contenttweaker:leaves_of_life"
            ]
        },
        {
            "x": -1,
            "y": 11,
            "z": 9,
            "elements": [
                "contenttweaker:leaves_of_life"
            ]
        },
        {
            "x": -1,
            "y": 11,
            "z": 10,
            "elements": [
                "contenttweaker:leaves_of_life"
            ]
        },
        {
            "x": -1,
            "y": 11,
            "z": 7,
            "elements": [
                "contenttweaker:leaves_of_life"
            ]
        },
        {
            "x": -1,
            "y": 11,
            "z": 8,
            "elements": [
                "contenttweaker:leaves_of_life"
            ]
        },
        {
            "x": -1,
            "y": 11,
            "z": 5,
            "elements": [
                "contenttweaker:sacred_eucalyptus"
            ]
        },
        {
            "x": -4,
            "y": 7,
            "z": 19,
            "elements": [
                "contenttweaker:innerved_sky_stone@0"
            ]
        },
        {
            "x": -1,
            "y": 11,
            "z": 6,
            "elements": [
                "contenttweaker:leaves_of_life"
            ]
        },
        {
            "x": -2,
            "y": 0,
            "z": 3,
            "elements": [
                "unlimitedchiselworks:chisel_stonebrick1_appliedenergistics2_sky_stone_brick_0@0"
            ]
        },
        {
            "x": 1,
            "y": 16,
            "z": 18,
            "elements": [
                "contenttweaker:sacred_eucalyptus"
            ]
        },
        {
            "x": -2,
