{
    "registryname": "vengeance_tesseract",
    "localizedname": "Vengeance Tesseract",
	"color": "cbcca5",
    "parts": [
        {
            "x": 3,
            "y": 14,
            "z": 6,
            "elements": [
                "botania:elfglass@0"
            ]
        },
        {
            "x": 3,
            "y": 6,
            "z": -4,
            "elements": [
                "botania:elfglass@0"
            ]
        },
        {
            "x": 2,
            "y": -1,
            "z": -5,
            "elements": [
                "unlimitedchiselworks:chisel_stonebrick_botania_livingrock_1@4"
            ]
        },
        {
            "x": 0,
            "y": 19,
            "z": 6,
            "elements": [
                "botania:elfglass@0"
            ]
        },
        {
            "x": -6,
            "y": 14,
            "z": 3,
            "elements": [
                "botania:elfglass@0"
            ]
        },
        {
            "x": -4,
            "y": 17,
            "z": -3,
            "elements": [
                "botania:elfglass@0"
            ]
        },
        {
            "x": 0,
            "y": 14,
            "z": 7,
            "elements": [
                "botania:elfglass@0"
            ]
        },
        {
            "x": 1,
            "y": 19,
            "z": 2,
            "elements": [
                "botania:elfglass@0"
            ]
        },
        {
            "x": -6,
            "y": 16,
            "z": 3,
            "elements": [
                "botania:elfglass@0"
            ]
        },
        {
            "x": -2,
            "y": 7,
            "z": -5,
            "elements": [
                "botania:elfglass@0"
            ]
        },
        {
            "x": -4,
            "y": 19,
            "z": 4,
            "elements": [
                "botania:elfglass@0"
            ]
        },
        {
            "x": 7,
            "y": 6,
            "z": 2,
            "elements": [
                "botania:elfglass@0"
            ]
        },
        {
            "x": 7,
            "y": 5,
            "z": 2,
            "elements": [
                "unlimitedchiselworks:chisel_stonebrick2_botania_livingrock_1@1"
            ]
        },
        {
            "x": 6,
            "y": 6,
            "z": 3,
            "elements": [
                "botania:elfglass@0"
            ]
        },
        {
            "x": -1,
            "y": 5,
            "z": -5,
            "elements": [
                "botania:elfglass@0"
            ]
        },
        {
            "x": 0,
            "y": 15,
            "z": 7,
            "elements": [
                "botania:elfglass@0"
            ]
        },
        {
            "x": -6,
            "y": 0,
            "z": -1,
            "elements": [
                "unlimitedchiselworks:chisel_stonebrick2_botania_livingrock_1@1"
            ]
        },
        {
            "x": 5,
            "y": -1,
            "z": 1,
            "elements": [
                "unlimitedchiselworks:chisel_planks_oak_botania_dreamwood_1@7"
            ]
        },
        {
            "x": 0,
            "y": 9,
            "z": 4,
            "elements": [
                "botania:elfglass@0"
            ]
        },
        {
            "x": -4,
            "y": 19,
            "z": -3,
            "elements": [
                "unlimitedchiselworks:chisel_stonebrick2_botania_livingrock_1@1"
            ]
        },
        {
            "x": 1,
            "y": 0,
            "z": 0,
            "elements": [
                "unlimitedchiselworks:chisel_stonebrick2_botania_livingrock_1@1"
            ]
        },
        {
            "x": 3,
            "y": 19,
            "z": 6,
            "elements": [
                "unlimitedchiselworks:chisel_stonebrick2_botania_livingrock_1@1"
            ]
        },
        {
            "x": 0,
            "y": 19,
            "z": -1,
            "elements": [
                "botania:elfglass@0"
            ]
        },
        {
            "x": 0,
            "y": 19,
            "z": 8,
            "elements": [
                "botania:elfglass@0"
            ]
        },
        {
            "x": 0,
            "y": 16,
            "z": 7,
            "elements": [
                "botania:elfglass@0"
            ]
        },
        {
            "x": -6,
            "y": 12,
            "z": 3,
            "elements": [
                "botania:elfglass@0"
            ]
        },
        {
            "x": 3,
            "y": 8,
            "z": -4,
            "elements": [
                "botania:elfglass@0"
            ]
        },
        {
            "x": -4,
            "y": 6,
            "z": 5,
            "elements": [
                "botania:elfglass@0"
            ]
        },
        {
            "x": 1,
            "y": -1,
            "z": -5,
            "elements": [
                "unlimitedchiselworks:chisel_planks_oak_botania_dreamwood_1@7"
            ]
        },
        {
            "x": -1,
            "y": 15,
            "z": 4,
            "elements": [
                "unlimitedchiselworks:chisel_stonebrick2_botania_livingrock_1@1"
            ]
        },
        {
            "x": 7,
            "y": 7,
            "z": 2,
            "elements": [
                "botania:elfglass@0"
            ]
        },
        {
            "x": -2,
            "y": 9,
            "z": -5,
            "elements": [
                "botania:elfglass@0"
            ]
        },
        {
            "x": -6,
            "y": 18,
            "z": 3,
            "elements": [
                "botania:elfglass@0"
            ]
        },
        {
            "x": 0,
            "y": 12,
            "z": -4,
            "elements": [
                "botania:elfglass@0"
            ]
        },
        {
            "x": 3,
            "y": 18,
            "z": 6,
            "elements": [
                "botania:elfglass@0"
            ]
        },
        {
            "x": 0,
            "y": 5,
            "z": -5,
            "elements": [
                "botania:elfglass@0"
            ]
        },
        {
            "x": 0,
            "y": 17,
            "z": 7,
            "elements": [
                "unlimitedchiselworks:chisel_stonebrick2_botania_livingrock_1@1"
            ]
        },
        {
            "x": 0,
            "y": 18,
            "z": 8,
            "elements": [
                "unlimitedchiselworks:chisel_stonebrick2_botania_livingrock_1@1"
            ]
        },
        {
            "x": -4,
            "y": 8,
            "z": 5,
            "elements": [
                "botania:elfglass@0"
            ]
        },
        {
            "x": -1,
            "y": 13,
            "z": 4,
            "elements": [
                "botania:elfglass@0"
            ]
        },
        {
            "x": 7,
            "y": 8,
            "z": 2,
            "elements": [
                "botania:elfglass@0"
            ]
        },
        {
            "x": 7,
            "y": 9,
            "z": 2,
            "elements": [
                "botania:elfglass@0"
            ]
        },
        {
            "x": 3,
            "y": 10,
            "z": 6,
            "elements": [
                "botania:elfglass@0"
            ]
        },
        {
            "x": -2,
            "y": 11,
            "z": -5,
            "elements": [
                "botania:elfglass@0"
            ]
        },
        {
            "x": 0,
            "y": 17,
            "z": 8,
            "elements": [
                "botania:elfglass@0"
            ]
        },
        {
            "x": 3,
            "y": 12,
            "z": -4,
            "elements": [
                "botania:elfglass@0"
            ]
        },
        {
            "x": 0,
            "y": 12,
            "z": 7,
            "elements": [
                "botania:elfglass@0"
            ]
        },
        {
            "x": -4,
            "y": 13,
            "z": -3,
            "elements": [
                "botania:elfglass@0"
            ]
        },
        {
            "x": 6,
            "y": 10,
            "z": 3,
            "elements": [
                "botania:elfglass@0"
            ]
        },
        {
            "x": 8,
            "y": -1,
            "z": 1,
            "elements": [
                "modularmachinery:blockmanaproviderinput@0"
            ]
        },
        {
            "x": 6,
            "y": 0,
            "z": -1,
            "elements": [
                "unlimitedchiselworks:chisel_stonebrick2_botania_livingrock_1@1"
            ]
        },
        {
            "x": 3,
            "y": 11,
            "z": 6,
            "elements": [
                "botania:elfglass@0"
            ]
        },
        {
            "x": 2,
            "y": 19,
            "z": -3,
            "elements": [
                "botania:elfglass@0"
            ]
        },
        {
            "x": -3,
            "y": 10,
            "z": 0,
            "elements": [
                "botania:elfglass@0"
            ]
        },
        {
            "x": 0,
            "y": 16,
            "z": 8,
            "elements": [
                "botania:elfglass@0"
            ]
        },
        {
            "x": 0,
            "y": 14,
            "z": -4,
            "elements": [
                "botania:elfglass@0"
            ]
        },
        {
            "x": 3,
            "y": 12,
            "z": 6,
            "elements": [
                "botania:elfglass@0"
            ]
        },
        {
            "x": -3,
            "y": 19,
            "z": -1,
            "elements": [
                "botania:elfglass@0"
            ]
        },
        {
            "x": -1,
            "y": 0,
            "z": 0,
            "elements": [
                "unlimitedchiselworks:chisel_stonebrick2_botania_livingrock_1@1"
            ]
        },
        {
            "x": 0,
            "y": 14,
            "z": 8,
            "elements": [
                "botania:elfglass@0"
            ]
        },
        {
            "x": 1,
            "y": 15,
            "z": 2,
            "elements": [
                "botania:elfglass@0"
            ]
        },
        {
            "x": -2,
            "y": 13,
            "z": -5,
            "elements": [
                "botania:elfglass@0"
            ]
        },
        {
            "x": -3,
            "y": 19,
            "z": 6,
            "elements": [
                "unlimitedchiselworks:chisel_stonebrick2_botania_livingrock_1@1"
            ]
        },
        {
            "x": -1,
            "y": 11,
            "z": 4,
            "elements": [
                "botania:elfglass@0"
            ]
        },
        {
            "x": -7,
            "y": -1,
            "z": 1,
            "elements": [
                "unlimitedchiselworks:chisel_planks_oak_botania_dreamwood_1@7"
            ]
        },
        {
            "x": 0,
            "y": 11,
            "z": 7,
            "elements": [
                "botania:elfglass@0"
            ]
        },
        {
            "x": 0,
            "y": 14,
            "z": 6,
            "elements": [
                "botania:elfglass@0"
            ]
        },
        {
            "x": -7,
            "y": -1,
            "z": -1,
            "elements": [
                "unlimitedchiselworks:chisel_stonebrick_botania_livingrock_1@4"
            ]
        },
        {
            "x": -1,
            "y": -1,
            "z": -5,
            "elements": [
                "unlimitedchiselworks:chisel_planks_oak_botania_dreamwood_1@7"
            ]
        },
        {
            "x": 7,
            "y": 11,
            "z": 2,
            "elements": [
                "botania:elfglass@0"
            ]
        },
        {
            "x": 7,
            "y": 10,
            "z": 2,
            "elements": [
                "botania:elfglass@0"
            ]
        },
        {
            "x": 5,
            "y": -1,
            "z": 4,
            "elements": [
                "unlimitedchiselworks:chisel_stonebrick_botania_livingrock_1@4"
            ]
        },
        {
            "x": 2,
            "y": 5,
            "z": -3,
            "elements": [
                "botania:elfglass@0"
            ]
        },
        {
            "x": 3,
            "y": 13,
            "z": 6,
            "elements": [
                "botania:elfglass@0"
            ]
        },
        {
            "x": -4,
            "y": -1,
            "z": -3,
            "elements": [
                "unlimitedchiselworks:chisel_stonebrick_botania_livingrock_1@4"
            ]
        },
        {
            "x": 0,
            "y": 15,
            "z": 6,
            "elements": [
                "botania:elfglass@0"
            ]
        },
        {
            "x": 0,
            "y": 15,
            "z": -1,
            "elements": [
                "botania:elfglass@0"
            ]
        },
        {
            "x": 3,
            "y": 10,
            "z": -4,
            "elements": [
                "botania:elfglass@0"
            ]
        },
        {
            "x": -2,
            "y": 19,
            "z": 2,
            "elements": [
                "botania:elfglass@0"
            ]
        },
        {
            "x": 2,
            "y": 5,
            "z": -5,
            "elements": [
                "unlimitedchiselworks:chisel_stonebrick2_botania_livingrock_1@1"
            ]
        },
        {
            "x": 0,
            "y": 15,
            "z": 8,
            "elements": [
                "botania:elfglass@0"
            ]
        },
        {
            "x": -4,
            "y": 15,
            "z": -3,
            "elements": [
                "botania:elfglass@0"
            ]
        },
        {
            "x": 0,
            "y": 10,
            "z": 7,
            "elements": [
                "botania:elfglass@0"
            ]
        },
        {
            "x": 6,
            "y": 8,
            "z": 3,
            "elements": [
                "botania:elfglass@0"
            ]
        },
        {
            "x": 3,
            "y": 5,
            "z": 4,
            "elements": [
                "botania:elfglass@0"
            ]
        },
        {
            "x": -3,
            "y": 12,
            "z": 0,
            "elements": [
                "botania:elfglass@0"
            ]
        },
        {
            "x": 0,
            "y": 16,
            "z": -4,
            "elements": [
                "unlimitedchiselworks:chisel_stonebrick2_botania_livingrock_1@1"
            ]
        },
        {
            "x": 0,
            "y": 13,
            "z": 7,
            "elements": [
                "botania:elfglass@0"
            ]
        },
        {
            "x": -3,
            "y": 18,
            "z": 6,
            "elements": [
                "botania:elfglass@0"
            ]
        },
        {
            "x": 0,
            "y": 16,
            "z": 6,
            "elements": [
                "unlimitedchiselworks:chisel_stonebrick2_botania_livingrock_1@1"
            ]
        },
        {
            "x": 6,
            "y": 7,
            "z": -1,
            "elements": [
                "botania:elfglass@0"
            ]
        },
        {
            "x": 3,
            "y": 7,
            "z": 6,
            "elements": [
                "botania:elfglass@0"
            ]
        },
        {
            "x": -3,
            "y": 11,
            "z": 6,
            "elements": [
                "botania:elfglass@0"
            ]
        },
        {
            "x": 7,
            "y": 13,
            "z": 2,
            "elements": [
                "botania:elfglass@0"
            ]
        },
        {
            "x": 2,
            "y": -1,
            "z": 4,
            "elements": [
                "unlimitedchiselworks:chisel_planks_oak_botania_dreamwood_1@7"
            ]
        },
        {
            "x": 1,
            "y": 19,
            "z": -6,
            "elements": [
                "unlimitedchiselworks:chisel_stonebrick2_botania_livingrock_1@1"
            ]
        },
        {
            "x": -7,
            "y": 6,
            "z": 0,
            "elements": [
                "botania:elfglass@0"
            ]
        },
        {
            "x": 0,
            "y": 12,
            "z": 6,
            "elements": [
                "botania:elfglass@0"
            ]
        },
        {
            "x": 0,
            "y": 9,
            "z": 7,
            "elements": [
                "botania:elfglass@0"
            ]
        },
        {
            "x": -6,
            "y": 15,
            "z": -1,
            "elements": [
                "botania:elfglass@0"
            ]
        },
        {
            "x": -3,
            "y": 0,
            "z": -4,
            "elements": [
                "unlimitedchiselworks:chisel_stonebrick2_botania_livingrock_1@1"
            ]
        },
        {
            "x": -3,
            "y": 17,
            "z": 6,
            "elements": [
                "botania:elfglass@0"
            ]
        },
        {
            "x": 7,
            "y": 12,
            "z": 2,
            "elements": [
                "botania:elfglass@0"
            ]
        },
        {
            "x": -3,
            "y": 10,
            "z": 6,
            "elements": [
                "botania:elfglass@0"
            ]
        },
        {
            "x": 2,
            "y": 7,
            "z": -5,
            "elements": [
                "botania:elfglass@0"
            ]
        },
        {
            "x": 7,
            "y": 15,
            "z": 2,
            "elements": [
                "botania:elfglass@0"
            ]
        },
        {
            "x": 6,
            "y": 6,
            "z": -1,
            "elements": [
                "botania:elfglass@0"
            ]
        },
        {
            "x": 0,
            "y": 13,
            "z": 6,
            "elements": [
                "botania:elfglass@0"
            ]
        },
        {
            "x": 3,
            "y": 6,
            "z": 6,
            "elements": [
                "botania:elfglass@0"
            ]
        },
        {
            "x": -1,
            "y": -1,
            "z": 4,
            "elements": [
                "unlimitedchiselworks:chisel_planks_oak_botania_dreamwood_1@7"
            ]
        },
        {
            "x": 3,
            "y": 5,
            "z": -1,
            "elements": [
                "botania:elfglass@0"
            ]
        },
        {
            "x": -6,
            "y": 14,
            "z": -1,
            "elements": [
                "botania:elfglass@0"
            ]
        },
        {
            "x": 1,
            "y": 18,
            "z": -6,
            "elements": [
                "botania:elfglass@0"
            ]
        },
        {
            "x": -4,
            "y": 10,
            "z": 5,
            "elements": [
                "botania:elfglass@0"
            ]
        },
        {
            "x": 0,
            "y": -1,
            "z": 9,
            "elements": [
                "modularmachinery:blockmanaproviderinput@0"
            ]
        },
        {
            "x": 0,
            "y": 8,
            "z": 7,
            "elements": [
                "botania:elfglass@0"
            ]
        },
        {
            "x": 3,
            "y": 9,
            "z": 6,
            "elements": [
                "botania:elfglass@0"
            ]
        },
        {
            "x": 0,
            "y": 9,
            "z": -1,
            "elements": [
                "botania:elfglass@0"
            ]
        },
        {
            "x": -3,
            "y": 5,
            "z": 4,
            "elements": [
                "botania:elfglass@0"
            ]
        },
        {
            "x": -7,
            "y": 18,
            "z": 0,
            "elements": [
                "botania:elfglass@0"
            ]
        },
        {
            "x": 2,
            "y": 9,
            "z": -5,
            "elements": [
                "botania:elfglass@0"
            ]
        },
        {
            "x": -6,
            "y": 13,
            "z": -1,
            "elements": [
                "botania:elfglass@0"
            ]
        },
        {
            "x": -7,
            "y": 8,
            "z": 0,
            "elements": [
                "botania:elfglass@0"
            ]
        },
        {
            "x": -3,
            "y": 12,
            "z": 6,
            "elements": [
                "botania:elfglass@0"
            ]
        },
        {
            "x": -3,
            "y": -1,
            "z": -5,
            "elements": [
                "unlimitedchiselworks:chisel_stonebrick_botania_livingrock_1@4"
            ]
        },
        {
            "x": 3,
            "y": 0,
            "z": -4,
            "elements": [
                "unlimitedchiselworks:chisel_stonebrick2_botania_livingrock_1@1"
            ]
        },
        {
            "x": 0,
            "y": 7,
            "z": 7,
            "elements": [
                "unlimitedchiselworks:chisel_stonebrick2_botania_livingrock_1@1"
            ]
        },
        {
            "x": -6,
            "y": 12,
            "z": -1,
            "elements": [
                "botania:elfglass@0"
            ]
        },
        {
            "x": 0,
            "y": 10,
            "z": 6,
            "elements": [
                "botania:elfglass@0"
            ]
        },
        {
            "x": -4,
            "y": -1,
            "z": 4,
            "elements": [
                "unlimitedchiselworks:chisel_planks_oak_botania_dreamwood_1@7"
            ]
        },
        {
            "x": 7,
            "y": 14,
            "z": 2,
            "elements": [
                "botania:elfglass@0"
            ]
        },
        {
            "x": 6,
            "y": 5,
            "z": -1,
            "elements": [
                "unlimitedchiselworks:chisel_stonebrick2_botania_livingrock_1@1"
            ]
        },
        {
            "x": 3,
            "y": 8,
            "z": 6,
            "elements": [
                "botania:elfglass@0"
            ]
        },
        {
            "x": -3,
            "y": 13,
            "z": 6,
            "elements": [
                "botania:elfglass@0"
            ]
        },
        {
            "x": 4,
            "y": 19,
            "z": 2,
            "elements": [
                "botania:elfglass@0"
            ]
        },
        {
            "x": 0,
            "y": 11,
            "z": 6,
            "elements": [
                "botania:elfglass@0"
            ]
        },
        {
            "x": 2,
            "y": 11,
            "z": -5,
            "elements": [
                "botania:elfglass@0"
            ]
        },
        {
            "x": 1,
            "y": 19,
            "z": 8,
            "elements": [
                "unlimitedchiselworks:chisel_stonebrick2_botania_livingrock_1@1"
            ]
        },
        {
            "x": 1,
            "y": 16,
            "z": -6,
            "elements": [
                "botania:elfglass@0"
            ]
        },
        {
            "x": -7,
            "y": 16,
            "z": 0,
            "elements": [
                "botania:elfglass@0"
            ]
        },
        {
            "x": -6,
            "y": 16,
            "z": -1,
            "elements": [
                "botania:elfglass@0"
            ]
        },
        {
            "x": -1,
            "y": 19,
            "z": -3,
            "elements": [
                "botania:elfglass@0"
            ]
        },
        {
            "x": 0,
            "y": 9,
            "z": 6,
            "elements": [
                "botania:elfglass@0"
            ]
        },
        {
            "x": -3,
            "y": 14,
            "z": 6,
            "elements": [
                "botania:elfglass@0"
            ]
        },
        {
            "x": 0,
            "y": -1,
            "z": -5,
            "elements": [
                "unlimitedchiselworks:chisel_planks_oak_botania_dreamwood_1@7"
            ]
        },
        {
            "x": 6,
            "y": 11,
            "z": -1,
            "elements": [
                "botania:elfglass@0"
            ]
        },
        {
            "x": 7,
            "y": 18,
            "z": 2,
            "elements": [
                "botania:elfglass@0"
            ]
        },
        {
            "x": 7,
            "y": 19,
            "z": 2,
            "elements": [
                "unlimitedchiselworks:chisel_stonebrick2_botania_livingrock_1@1"
            ]
        },
        {
            "x": 1,
            "y": 18,
            "z": 8,
            "elements": [
                "botania:elfglass@0"
            ]
        },
        {
            "x": 0,
            "y": 8,
            "z": 6,
            "elements": [
                "unlimitedchiselworks:chisel_stonebrick2_botania_livingrock_1@1"
            ]
        },
        {
            "x": 6,
            "y": 0,
            "z": 3,
            "elements": [
                "unlimitedchiselworks:chisel_stonebrick2_botania_livingrock_1@1"
            ]
        },
        {
            "x": -3,
            "y": 15,
            "z": 6,
            "elements": [
                "botania:elfglass@0"
            ]
        },
        {
            "x": -7,
            "y": 10,
            "z": 0,
            "elements": [
                "botania:elfglass@0"
            ]
        },
        {
            "x": -6,
            "y": 17,
            "z": -1,
            "elements": [
                "botania:elfglass@0"
            ]
        },
        {
            "x": 0,
            "y": 5,
            "z": 7,
            "elements": [
                "botania:elfglass@0"
            ]
        },
        {
            "x": 6,
            "y": 10,
            "z": -1,
            "elements": [
                "botania:elfglass@0"
            ]
        },
        {
            "x": 1,
            "y": 5,
            "z": -5,
            "elements": [
                "botania:elfglass@0"
            ]
        },
        {
            "x": 0,
            "y": 5,
            "z": 4,
            "elements": [
                "botania:elfglass@0"
            ]
        },
        {
            "x": 7,
            "y": 16,
            "z": 2,
            "elements": [
                "botania:elfglass@0"
            ]
        },
        {
            "x": 5,
            "y": -1,
            "z": -1,
            "elements": [
                "unlimitedchiselworks:chisel_planks_oak_botania_dreamwood_1@7"
            ]
        },
        {
            "x": 3,
            "y": -1,
            "z": -5,
            "elements": [
                "unlimitedchiselworks:chisel_stonebrick_botania_livingrock_1@4"
            ]
        },
        {
            "x": 1,
            "y": 14,
            "z": -6,
            "elements": [
                "botania:elfglass@0"
            ]
        },
        {
            "x": 2,
            "y": -1,
            "z": 7,
            "elements": [
                "unlimitedchiselworks:chisel_stonebrick_botania_livingrock_1@4"
            ]
        },
        {
            "x": -4,
            "y": 0,
            "z": 5,
            "elements": [
                "unlimitedchiselworks:chisel_stonebrick2_botania_livingrock_1@1"
            ]
        },
        {
            "x": -3,
            "y": 16,
            "z": 6,
            "elements": [
                "botania:elfglass@0"
            ]
        },
        {
            "x": -7,
            "y": 14,
            "z": 0,
            "elements": [
                "botania:elfglass@0"
            ]
        },
        {
            "x": -6,
            "y": 18,
            "z": -1,
            "elements": [
                "botania:elfglass@0"
            ]
        },
        {
            "x": 2,
            "y": 13,
            "z": -5,
            "elements": [
                "botania:elfglass@0"
            ]
        },
        {
            "x": 6,
            "y": 9,
            "z": -1,
            "elements": [
                "botania:elfglass@0"
            ]
        },
        {
            "x": 3,
            "y": 5,
            "z": 6,
            "elements": [
                "unlimitedchiselworks:chisel_stonebrick2_botania_livingrock_1@1"
            ]
        },
        {
            "x": 1,
            "y": 17,
            "z": -6,
            "elements": [
                "botania:elfglass@0"
            ]
        },
        {
            "x": 6,
            "y": 8,
            "z": -1,
            "elements": [
                "botania:elfglass@0"
            ]
        },
        {
            "x": 1,
            "y": 15,
            "z": -6,
            "elements": [
                "botania:elfglass@0"
            ]
        },
        {
            "x": -4,
            "y": -1,
            "z": 1,
            "elements": [
                "unlimitedchiselworks:chisel_planks_oak_botania_dreamwood_1@7"
            ]
        },
        {
            "x": -1,
            "y": 19,
            "z": 4,
            "elements": [
                "botania:elfglass@0"
            ]
        },
        {
            "x": -7,
            "y": 12,
            "z": 0,
            "elements": [
                "botania:elfglass@0"
            ]
        },
        {
            "x": -6,
            "y": 19,
            "z": -1,
            "elements": [
                "unlimitedchiselworks:chisel_stonebrick2_botania_livingrock_1@1"
            ]
        },
        {
            "x": -2,
            "y": 5,
            "z": -5,
            "elements": [
                "unlimitedchiselworks:chisel_stonebrick2_botania_livingrock_1@1"
            ]
        },
        {
            "x": 7,
            "y": 17,
            "z": 2,
            "elements": [
                "botania:elfglass@0"
            ]
        },
        {
            "x": 6,
            "y": 13,
            "z": 1,
            "elements": [
                "botania:elfglass@0"
            ]
        },
        {
            "x": 0,
            "y": 5,
            "z": -1,
            "elements": [
                "botania:elfglass@0"
            ]
        },
        {
            "x": 3,
            "y": 19,
            "z": -1,
            "elements": [
                "botania:elfglass@0"
            ]
        },
        {
            "x": -4,
            "y": 18,
            "z": 5,
            "elements": [
                "botania:elfglass@0"
            ]
        },
        {
            "x": 0,
            "y": 8,
            "z": -4,
            "elements": [
                "unlimitedchiselworks:chisel_stonebrick2_botania_livingrock_1@1"
            ]
        },
        {
            "x": 2,
            "y": -1,
            "z": 8,
            "elements": [
                "unlimitedchiselworks:chisel_stonebrick_botania_livingrock_1@4"
            ]
        },
        {
            "x": -2,
            "y": 5,
            "z": 4,
            "elements": [
                "botania:elfglass@0"
            ]
        },
        {
            "x": 6,
            "y": 12,
            "z": -1,
            "elements": [
                "botania:elfglass@0"
            ]
        },
        {
            "x": 7,
            "y": 10,
            "z": 1,
            "elements": [
                "botania:elfglass@0"
            ]
        },
        {
            "x": 6,
            "y": 19,
            "z": 1,
            "elements": [
                "botania:elfglass@0"
            ]
        },
        {
            "x": -3,
            "y": 10,
            "z": -4,
            "elements": [
                "botania:elfglass@0"
            ]
        },
        {
            "x": 3,
            "y": 5,
            "z": -3,
            "elements": [
                "botania:elfglass@0"
            ]
        },
        {
            "x": 6,
            "y": 13,
            "z": -1,
            "elements": [
                "botania:elfglass@0"
            ]
        },
        {
            "x": -5,
            "y": -1,
            "z": -3,
            "elements": [
                "unlimitedchiselworks:chisel_stonebrick_botania_livingrock_1@4"
            ]
        },
        {
            "x": 6,
            "y": 12,
            "z": 1,
            "elements": [
                "botania:elfglass@0"
            ]
        },
        {
            "x": 0,
            "y": 17,
            "z": -5,
            "elements": [
                "unlimitedchiselworks:chisel_stonebrick2_botania_livingrock_1@1"
            ]
        },
        {
            "x": -5,
            "y": -1,
            "z": 4,
            "elements": [
                "unlimitedchiselworks:chisel_stonebrick_botania_livingrock_1@4"
            ]
        },
        {
            "x": -5,
            "y": 7,
            "z": 4,
            "elements": [
                "botania:elfglass@0"
            ]
        },
        {
            "x": 0,
            "y": 9,
            "z": -3,
            "elements": [
                "unlimitedchiselworks:chisel_stonebrick_botania_livingrock_1@4"
            ]
        },
        {
            "x": -1,
            "y": 19,
            "z": -5,
            "elements": [
                "botania:elfglass@0"
            ]
        },
        {
            "x": -7,
            "y": 0,
            "z": 0,
            "elements": [
                "unlimitedchiselworks:chisel_stonebrick2_botania_livingrock_1@1"
            ]
        },
        {
            "x": 0,
            "y": 10,
            "z": 5,
            "elements": [
                "unlimitedchiselworks:chisel_stonebrick2_botania_livingrock_1@1"
            ]
        },
        {
            "x": 7,
            "y": 11,
            "z": 1,
            "elements": [
                "botania:elfglass@0"
            ]
        },
        {
            "x": 6,
            "y": 14,
            "z": -1,
            "elements": [
                "botania:elfglass@0"
            ]
        },
        {
            "x": 0,
            "y": 5,
            "z": -3,
            "elements": [
                "botania:elfglass@0"
            ]
        },
        {
            "x": 7,
            "y": 8,
            "z": 1,
            "elements": [
                "botania:elfglass@0"
            ]
        },
        {
            "x": 6,
            "y": 15,
            "z": 1,
            "elements": [
                "botania:elfglass@0"
            ]
        },
        {
            "x": -3,
            "y": 12,
            "z": -4,
            "elements": [
                "botania:elfglass@0"
            ]
        },
        {
            "x": -4,
            "y": 16,
            "z": 5,
            "elements": [
                "botania:elfglass@0"
            ]
        },
        {
            "x": 3,
            "y": 19,
            "z": 1,
            "elements": [
                "botania:elfglass@0"
            ]
        },
        {
            "x": -5,
            "y": 9,
            "z": 4,
            "elements": [
                "botania:elfglass@0"
            ]
        },
        {
            "x": 6,
            "y": 14,
            "z": 1,
            "elements": [
                "botania:elfglass@0"
            ]
        },
        {
            "x": -2,
            "y": -1,
            "z": -3,
            "elements": [
                "unlimitedchiselworks:chisel_planks_oak_botania_dreamwood_1@7"
            ]
        },
        {
            "x": 7,
            "y": 9,
            "z": 1,
            "elements": [
                "botania:elfglass@0"
            ]
        },
        {
            "x": 0,
            "y": 15,
            "z": -5,
            "elements": [
                "botania:elfglass@0"
            ]
        },
        {
            "x": 0,
            "y": 11,
            "z": -3,
            "elements": [
                "unlimitedchiselworks:chisel_stonebrick2_botania_livingrock_1@1"
            ]
        },
        {
            "x": 6,
            "y": 15,
            "z": -1,
            "elements": [
                "botania:elfglass@0"
            ]
        },
        {
            "x": 6,
            "y": 17,
            "z": -1,
            "elements": [
                "botania:elfglass@0"
            ]
        },
        {
            "x": -4,
            "y": 5,
            "z": 4,
            "elements": [
                "botania:elfglass@0"
            ]
        },
        {
            "x": 7,
            "y": 15,
            "z": 1,
            "elements": [
                "botania:elfglass@0"
            ]
        },
        {
            "x": 0,
            "y": 19,
            "z": -2,
            "elements": [
                "botania:elfglass@0"
            ]
        },
        {
            "x": 6,
            "y": 17,
            "z": 1,
            "elements": [
                "unlimitedchiselworks:chisel_stonebrick2_botania_livingrock_1@1"
            ]
        },
        {
            "x": 6,
            "y": 16,
            "z": -1,
            "elements": [
                "botania:elfglass@0"
            ]
        },
        {
            "x": 4,
            "y": 19,
            "z": 1,
            "elements": [
                "botania:elfglass@0"
            ]
        },
        {
            "x": -3,
            "y": -1,
            "z": 4,
            "elements": [
                "unlimitedchiselworks:chisel_planks_oak_botania_dreamwood_1@7"
            ]
        },
        {
            "x": 7,
            "y": 14,
            "z": 1,
            "elements": [
                "botania:elfglass@0"
            ]
        },
        {
            "x": -4,
            "y": 14,
            "z": 5,
            "elements": [
                "botania:elfglass@0"
            ]
        },
        {
            "x": -3,
            "y": 6,
            "z": -4,
            "elements": [
                "botania:elfglass@0"
            ]
        },
        {
            "x": 6,
            "y": 16,
            "z": 1,
            "elements": [
                "botania:elfglass@0"
            ]
        },
        {
            "x": -2,
            "y": 10,
            "z": 3,
            "elements": [
                "botania:elfglass@0"
            ]
        },
        {
            "x": 5,
            "y": -1,
            "z": -3,
            "elements": [
                "unlimitedchiselworks:chisel_stonebrick_botania_livingrock_1@4"
            ]
        },
        {
            "x": -6,
            "y": 0,
            "z": 3,
            "elements": [
                "unlimitedchiselworks:chisel_stonebrick2_botania_livingrock_1@1"
            ]
        },
        {
            "x": -5,
            "y": 5,
            "z": 4,
            "elements": [
                "unlimitedchiselworks:chisel_stonebrick2_botania_livingrock_1@1"
            ]
        },
        {
            "x": -1,
            "y": -1,
            "z": 8,
            "elements": [
                "unlimitedchiselworks:chisel_stonebrick_botania_livingrock_1@4"
            ]
        },
        {
            "x": -3,
            "y": 8,
            "z": -4,
            "elements": [
                "botania:elfglass@0"
            ]
        },
        {
            "x": 7,
            "y": 13,
            "z": 1,
            "elements": [
                "botania:elfglass@0"
            ]
        },
        {
            "x": 3,
            "y": 19,
            "z": -2,
            "elements": [
                "botania:elfglass@0"
            ]
        },
        {
            "x": 6,
            "y": 19,
            "z": -1,
            "elements": [
                "unlimitedchiselworks:chisel_stonebrick2_botania_livingrock_1@1"
            ]
        },
        {
            "x": 7,
            "y": 0,
            "z": 0,
            "elements": [
                "unlimitedchiselworks:chisel_stonebrick2_botania_livingrock_1@1"
            ]
        },
        {
            "x": 6,
            "y": 18,
            "z": -1,
            "elements": [
                "botania:elfglass@0"
            ]
        },
        {
            "x": 7,
            "y": 12,
            "z": 1,
            "elements": [
                "botania:elfglass@0"
            ]
        },
        {
            "x": -2,
            "y": -1,
            "z": 4,
            "elements": [
                "unlimitedchiselworks:chisel_planks_oak_botania_dreamwood_1@7"
            ]
        },
        {
            "x": 0,
            "y": 0,
            "z": 8,
            "elements": [
                "contenttweaker:vengeful_steel_molten"
            ]
        },
        {
            "x": 0,
            "y": 19,
            "z": -5,
            "elements": [
                "botania:elfglass@0"
            ]
        },
        {
            "x": -4,
            "y": 12,
            "z": 5,
            "elements": [
                "botania:elfglass@0"
            ]
        },
        {
            "x": 4,
            "y": -1,
            "z": -3,
            "elements": [
                "unlimitedchiselworks:chisel_stonebrick_botania_livingrock_1@4"
            ]
        },
        {
            "x": -1,
            "y": 5,
            "z": -3,
            "elements": [
                "botania:elfglass@0"
            ]
        },
        {
            "x": 0,
            "y": 11,
            "z": 8,
            "elements": [
                "botania:elfglass@0"
            ]
        },
        {
            "x": -6,
            "y": 6,
            "z": 3,
            "elements": [
                "botania:elfglass@0"
            ]
        },
        {
            "x": -4,
            "y": 7,
            "z": -3,
            "elements": [
                "botania:elfglass@0"
            ]
        },
        {
            "x": 0,
            "y": 11,
            "z": -5,
            "elements": [
                "botania:elfglass@0"
            ]
        },
        {
            "x": 0,
            "y": 12,
            "z": 8,
            "elements": [
                "botania:elfglass@0"
            ]
        },
        {
            "x": 0,
            "y": 13,
            "z": 8,
            "elements": [
                "botania:elfglass@0"
            ]
        },
        {
            "x": -1,
            "y": -1,
            "z": -3,
            "elements": [
                "unlimitedchiselworks:chisel_planks_oak_botania_dreamwood_1@7"
            ]
        },
        {
            "x": 2,
            "y": 5,
            "z": 4,
            "elements": [
                "botania:elfglass@0"
            ]
        },
        {
            "x": 0,
            "y": 9,
            "z": 8,
            "elements": [
                "botania:elfglass@0"
            ]
        },
        {
            "x": 7,
            "y": 18,
            "z": 1,
            "elements": [
                "unlimitedchiselworks:chisel_stonebrick2_botania_livingrock_1@1"
            ]
        },
        {
            "x": 0,
            "y": 13,
            "z": -5,
            "elements": [
                "botania:elfglass@0"
            ]
        },
        {
            "x": -4,
            "y": 5,
            "z": -3,
            "elements": [
                "unlimitedchiselworks:chisel_stonebrick2_botania_livingrock_1@1"
            ]
        },
        {
            "x": 6,
            "y": 5,
            "z": 1,
            "elements": [
                "botania:elfglass@0"
            ]
        },
        {
            "x": -3,
            "y": 19,
            "z": -2,
            "elements": [
                "botania:elfglass@0"
            ]
        },
        {
            "x": 7,
            "y": 17,
            "z": 1,
            "elements": [
                "botania:elfglass@0"
            ]
        },
        {
            "x": -4,
            "y": 11,
            "z": -3,
            "elements": [
                "botania:elfglass@0"
            ]
        },
        {
            "x": 0,
            "y": 15,
            "z": -2,
            "elements": [
                "botania:elfglass@0"
            ]
        },
        {
            "x": 0,
            "y": 10,
            "z": 8,
            "elements": [
                "botania:elfglass@0"
            ]
        },
        {
            "x": 7,
            "y": 19,
            "z": 1,
            "elements": [
                "botania:elfglass@0"
            ]
        },
        {
            "x": 6,
            "y": 7,
            "z": 1,
            "elements": [
                "unlimitedchiselworks:chisel_stonebrick2_botania_livingrock_1@1"
            ]
        },
        {
            "x": 3,
            "y": 9,
            "z": 1,
            "elements": [
                "botania:elfglass@0"
            ]
        },
        {
            "x": -3,
            "y": 18,
            "z": -4,
            "elements": [
                "botania:elfglass@0"
            ]
        },
        {
            "x": 2,
            "y": -1,
            "z": -3,
            "elements": [
                "unlimitedchiselworks:chisel_planks_oak_botania_dreamwood_1@7"
            ]
        },
        {
            "x": 7,
            "y": 16,
            "z": 1,
            "elements": [
                "botania:elfglass@0"
            ]
        },
        {
            "x": -1,
            "y": 9,
            "z": 4,
            "elements": [
                "unlimitedchiselworks:chisel_stonebrick2_botania_livingrock_1@1"
            ]
        },
        {
            "x": -3,
            "y": 5,
            "z": -3,
            "elements": [
                "botania:elfglass@0"
            ]
        },
        {
            "x": 4,
            "y": 13,
            "z": 1,
            "elements": [
                "unlimitedchiselworks:chisel_stonebrick2_botania_livingrock_1@1"
            ]
        },
        {
            "x": 0,
            "y": 6,
            "z": 8,
            "elements": [
                "unlimitedchiselworks:chisel_stonebrick2_botania_livingrock_1@1"
            ]
        },
        {
            "x": 0,
            "y": 19,
            "z": 7,
            "elements": [
                "botania:elfglass@0"
            ]
        },
        {
            "x": 6,
            "y": 8,
            "z": 1,
            "elements": [
                "botania:elfglass@0"
            ]
        },
        {
            "x": 3,
            "y": 17,
            "z": 6,
            "elements": [
                "botania:elfglass@0"
            ]
        },
        {
            "x": 0,
            "y": 9,
            "z": -2,
            "elements": [
                "botania:elfglass@0"
            ]
        },
        {
            "x": 3,
            "y": 15,
            "z": 1,
            "elements": [
                "botania:elfglass@0"
            ]
        },
        {
            "x": 0,
            "y": -1,
            "z": 4,
            "elements": [
                "unlimitedchiselworks:chisel_planks_oak_botania_dreamwood_1@7"
            ]
        },
        {
            "x": 7,
            "y": 12,
            "z": 0,
            "elements": [
                "botania:elfglass@0"
            ]
        },
        {
            "x": 4,
            "y": 12,
            "z": 1,
            "elements": [
                "unlimitedchiselworks:chisel_stonebrick2_botania_livingrock_1@1"
            ]
        },
        {
            "x": 1,
            "y": 19,
            "z": 1,
            "elements": [
                "botania:elfglass@0"
            ]
        },
        {
            "x": 6,
            "y": 9,
            "z": 1,
            "elements": [
                "botania:elfglass@0"
            ]
        },
        {
            "x": 0,
            "y": 7,
            "z": -5,
            "elements": [
                "unlimitedchiselworks:chisel_stonebrick2_botania_livingrock_1@1"
            ]
        },
        {
            "x": 0,
            "y": 5,
            "z": 8,
            "elements": [
                "botania:elfglass@0"
            ]
        },
        {
            "x": 7,
            "y": 6,
            "z": 0,
            "elements": [
                "botania:elfglass@0"
            ]
        },
        {
            "x": 1,
            "y": -1,
            "z": -3,
            "elements": [
                "unlimitedchiselworks:chisel_planks_oak_botania_dreamwood_1@7"
            ]
        },
        {
            "x": 3,
            "y": 16,
            "z": 6,
            "elements": [
                "botania:elfglass@0"
            ]
        },
        {
            "x": -3,
            "y": 16,
            "z": -4,
            "elements": [
                "botania:elfglass@0"
            ]
        },
        {
            "x": -6,
            "y": 10,
            "z": 3,
            "elements": [
                "botania:elfglass@0"
            ]
        },
        {
            "x": 7,
            "y": 10,
            "z": 0,
            "elements": [
                "botania:elfglass@0"
            ]
        },
        {
            "x": -2,
            "y": 5,
            "z": -3,
            "elements": [
                "botania:elfglass@0"
            ]
        },
        {
            "x": -6,
            "y": 8,
            "z": 3,
            "elements": [
                "botania:elfglass@0"
            ]
        },
        {
            "x": -1,
            "y": 5,
            "z": 4,
            "elements": [
                "botania:elfglass@0"
            ]
        },
        {
            "x": 6,
            "y": 10,
            "z": 1,
            "elements": [
                "botania:elfglass@0"
            ]
        },
        {
            "x": 4,
            "y": 15,
            "z": 1,
            "elements": [
                "unlimitedchiselworks:chisel_stonebrick_botania_livingrock_1@4"
            ]
        },
        {
            "x": -4,
            "y": 9,
            "z": -3,
            "elements": [
                "botania:elfglass@0"
            ]
        },
        {
            "x": 1,
            "y": -1,
            "z": 4,
            "elements": [
                "unlimitedchiselworks:chisel_planks_oak_botania_dreamwood_1@7"
            ]
        },
        {
            "x": 0,
            "y": 10,
            "z": -4,
            "elements": [
                "botania:elfglass@0"
            ]
        },
        {
            "x": 3,
            "y": 15,
            "z": 6,
            "elements": [
                "botania:elfglass@0"
            ]
        },
        {
            "x": 0,
            "y": 9,
            "z": -5,
            "elements": [
                "botania:elfglass@0"
            ]
        },
        {
            "x": 0,
            "y": 8,
            "z": 8,
            "elements": [
                "botania:elfglass@0"
            ]
        },
        {
            "x": 3,
            "y": 5,
            "z": -2,
            "elements": [
                "botania:elfglass@0"
            ]
        },
        {
            "x": -3,
            "y": 14,
            "z": -4,
            "elements": [
                "botania:elfglass@0"
            ]
        },
        {
            "x": -6,
            "y": -1,
            "z": 4,
            "elements": [
                "unlimitedchiselworks:chisel_stonebrick_botania_livingrock_1@4"
            ]
        },
        {
            "x": 4,
            "y": 14,
            "z": 1,
            "elements": [
                "unlimitedchiselworks:chisel_stonebrick2_botania_livingrock_1@1"
            ]
        },
        {
            "x": -7,
            "y": -1,
            "z": 2,
            "elements": [
                "unlimitedchiselworks:chisel_stonebrick_botania_livingrock_1@4"
            ]
        },
        {
            "x": 0,
            "y": -1,
            "z": -3,
            "elements": [
                "unlimitedchiselworks:chisel_planks_oak_botania_dreamwood_1@7"
            ]
        },
        {
            "x": 0,
            "y": 7,
            "z": 8,
            "elements": [
                "botania:elfglass@0"
            ]
        },
        {
            "x": 1,
            "y": -1,
            "z": 9,
            "elements": [
                "unlimitedchiselworks:chisel_stonebrick_botania_livingrock_1@4"
            ]
        },
        {
            "x": 7,
            "y": 8,
            "z": 0,
            "elements": [
                "botania:elfglass@0"
            ]
        },
        {
            "x": 6,
            "y": 11,
            "z": 1,
            "elements": [
                "botania:elfglass@0"
            ]
        },
        {
            "x": 1,
            "y": -1,
            "z": 7,
            "elements": [
                "unlimitedchiselworks:chisel_planks_oak_botania_dreamwood_1@7"
            ]
        },
        {
            "x": 1,
            "y": 9,
            "z": -1,
            "elements": [
                "botania:elfglass@0"
            ]
        },
        {
            "x": 0,
            "y": 5,
            "z": 2,
            "elements": [
                "botania:elfglass@0"
            ]
        },
        {
            "x": 0,
            "y": 8,
            "z": 9,
            "elements": [
                "unlimitedchiselworks:chisel_stonebrick2_botania_livingrock_1@1"
            ]
        },
        {
            "x": 2,
            "y": 19,
            "z": 5,
            "elements": [
                "botania:elfglass@0"
            ]
        },
        {
            "x": 5,
            "y": 19,
            "z": 0,
            "elements": [
                "botania:elfglass@0"
            ]
        },
        {
            "x": -1,
            "y": 8,
            "z": 8,
            "elements": [
                "botania:elfglass@0"
            ]
        },
        {
            "x": 6,
            "y": -1,
            "z": 4,
            "elements": [
                "unlimitedchiselworks:chisel_stonebrick_botania_livingrock_1@4"
            ]
        },
        {
            "x": 0,
            "y": 5,
            "z": 9,
            "elements": [
                "unlimitedchiselworks:chisel_stonebrick_botania_livingrock_1@4"
            ]
        },
        {
            "x": 1,
            "y": 15,
            "z": -1,
            "elements": [
                "botania:elfglass@0"
            ]
        },
        {
            "x": 0,
            "y": 7,
            "z": 9,
            "elements": [
                "unlimitedchiselworks:chisel_stonebrick2_botania_livingrock_1@1"
            ]
        },
        {
            "x": 0,
            "y": 15,
            "z": -6,
            "elements": [
                "botania:elfglass@0"
            ]
        },
        {
            "x": 4,
            "y": 17,
            "z": 5,
            "elements": [
                "botania:elfglass@0"
            ]
        },
        {
            "x": -4,
            "y": -1,
            "z": 2,
            "elements": [
                "unlimitedchiselworks:chisel_planks_oak_botania_dreamwood_1@7"
            ]
        },
        {
            "x": -5,
            "y": 19,
            "z": -1,
            "elements": [
                "botania:elfglass@0"
            ]
        },
        {
            "x": 0,
            "y": 6,
            "z": 9,
            "elements": [
                "unlimitedchiselworks:chisel_stonebrick2_botania_livingrock_1@1"
            ]
        },
        {
            "x": -3,
            "y": 9,
            "z": 2,
            "elements": [
                "unlimitedchiselworks:chisel_stonebrick2_botania_livingrock_1@1"
            ]
        },
        {
            "x": -2,
            "y": 19,
            "z": 7,
            "elements": [
                "unlimitedchiselworks:chisel_stonebrick2_botania_livingrock_1@1"
            ]
        },
        {
            "x": 4,
            "y": 16,
            "z": 5,
            "elements": [
                "botania:elfglass@0"
            ]
        },
        {
            "x": -5,
            "y": 18,
            "z": -2,
            "elements": [
                "botania:elfglass@0"
            ]
        },
        {
            "x": -1,
            "y": 6,
            "z": 8,
            "elements": [
                "botania:elfglass@0"
            ]
        },
        {
            "x": 7,
            "y": -1,
            "z": -1,
            "elements": [
                "unlimitedchiselworks:chisel_stonebrick_botania_livingrock_1@4"
            ]
        },
        {
            "x": -8,
            "y": 0,
            "z": 1,
            "elements": [
                "unlimitedchiselworks:chisel_stonebrick_botania_livingrock_1@4"
            ]
        },
        {
            "x": 4,
            "y": 10,
            "z": 1,
            "elements": [
                "unlimitedchiselworks:chisel_stonebrick2_botania_livingrock_1@1"
            ]
        },
        {
            "x": -2,
            "y": 13,
            "z": -1,
            "elements": [
                "botania:elfglass@0"
            ]
        },
        {
            "x": 1,
            "y": 19,
            "z": 5,
            "elements": [
                "botania:elfglass@0"
            ]
        },
        {
            "x": 3,
            "y": -1,
            "z": 4,
            "elements": [
                "unlimitedchiselworks:chisel_planks_oak_botania_dreamwood_1@7"
            ]
        },
        {
            "x": 0,
            "y": 19,
            "z": -6,
            "elements": [
                "botania:elfglass@0"
            ]
        },
        {
            "x": 4,
            "y": 15,
            "z": 5,
            "elements": [
                "botania:elfglass@0"
            ]
        },
        {
            "x": -5,
            "y": 16,
            "z": 1,
            "elements": [
                "unlimitedchiselworks:chisel_stonebrick2_botania_livingrock_1@1"
            ]
        },
        {
            "x": 0,
            "y": 17,
            "z": -6,
            "elements": [
                "botania:elfglass@0"
            ]
        },
        {
            "x": -2,
            "y": 9,
            "z": 2,
            "elements": [
                "botania:elfglass@0"
            ]
        },
        {
            "x": -3,
            "y": 11,
            "z": 2,
            "elements": [
                "botania:elfglass@0"
            ]
        },
        {
            "x": -5,
            "y": -1,
            "z": 2,
            "elements": [
                "unlimitedchiselworks:chisel_planks_oak_botania_dreamwood_1@7"
            ]
        },
        {
            "x": -1,
            "y": 5,
            "z": 7,
            "elements": [
                "botania:elfglass@0"
            ]
        },
        {
            "x": -2,
            "y": 15,
            "z": -1,
            "elements": [
                "unlimitedchiselworks:chisel_stonebrick2_botania_livingrock_1@1"
            ]
        },
        {
            "x": 4,
            "y": 18,
            "z": 5,
            "elements": [
                "botania:elfglass@0"
            ]
        },
        {
            "x": 1,
            "y": 5,
            "z": 4,
            "elements": [
                "botania:elfglass@0"
            ]
        },
        {
            "x": 2,
            "y": 5,
            "z": -1,
            "elements": [
                "botania:elfglass@0"
            ]
        },
        {
            "x": -2,
            "y": 15,
            "z": 2,
            "elements": [
                "botania:elfglass@0"
            ]
        },
        {
            "x": -6,
            "y": 5,
            "z": 2,
            "elements": [
                "botania:elfglass@0"
            ]
        },
        {
            "x": -5,
            "y": 16,
            "z": -2,
            "elements": [
                "botania:elfglass@0"
            ]
        },
        {
            "x": 1,
            "y": 12,
            "z": -2,
            "elements": [
                "botania:elfglass@0"
            ]
        },
        {
            "x": 0,
            "y": 11,
            "z": -6,
            "elements": [
                "botania:elfglass@0"
            ]
        },
        {
            "x": 0,
            "y": 12,
            "z": 1,
            "elements": [
                "contenttweaker:vengeful_asgardian_crystal@0"
            ]
        },
        {
            "x": 7,
            "y": 0,
            "z": 1,
            "elements": [
                "contenttweaker:vengeful_steel_molten"
            ]
        },
        {
            "x": 4,
            "y": 14,
            "z": 5,
            "elements": [
                "botania:elfglass@0"
            ]
        },
        {
            "x": 2,
            "y": -1,
            "z": 2,
            "elements": [
                "unlimitedchiselworks:chisel_stonebrick2_botania_livingrock_1@1"
            ]
        },
        {
            "x": 0,
            "y": 1,
            "z": 2,
            "elements": [
                "unlimitedchiselworks:chisel_stonebrick_botania_livingrock_1@4"
            ]
        },
        {
            "x": 2,
            "y": 11,
            "z": -1,
            "elements": [
                "botania:elfglass@0"
            ]
        },
        {
            "x": 1,
            "y": 19,
            "z": 3,
            "elements": [
                "botania:elfglass@0"
            ]
        },
        {
            "x": -5,
            "y": 19,
            "z": 2,
            "elements": [
                "botania:elfglass@0"
            ]
        },
        {
            "x": 1,
            "y": 0,
            "z": 8,
            "elements": [
                "unlimitedchiselworks:chisel_stonebrick2_botania_livingrock_1@1"
            ]
        },
        {
            "x": -1,
            "y": 15,
            "z": -1,
            "elements": [
                "botania:elfglass@0"
            ]
        },
        {
            "x": 5,
            "y": 5,
            "z": -1,
            "elements": [
                "botania:elfglass@0"
            ]
        },
        {
            "x": 4,
            "y": 13,
            "z": 5,
            "elements": [
                "botania:elfglass@0"
            ]
        },
        {
            "x": 4,
            "y": 5,
            "z": 4,
            "elements": [
                "botania:elfglass@0"
            ]
        },
        {
            "x": 2,
            "y": 9,
            "z": -1,
            "elements": [
                "unlimitedchiselworks:chisel_stonebrick2_botania_livingrock_1@1"
            ]
        },
        {
            "x": 4,
            "y": 11,
            "z": 5,
            "elements": [
                "botania:elfglass@0"
            ]
        },
        {
            "x": 5,
            "y": -1,
            "z": 2,
            "elements": [
                "unlimitedchiselworks:chisel_planks_oak_botania_dreamwood_1@7"
            ]
        },
        {
            "x": -5,
            "y": 14,
            "z": -2,
            "elements": [
                "botania:elfglass@0"
            ]
        },
        {
            "x": 1,
            "y": 10,
            "z": 4,
            "elements": [
                "botania:elfglass@0"
            ]
        },
        {
            "x": 4,
            "y": 12,
            "z": 5,
            "elements": [
                "botania:elfglass@0"
            ]
        },
        {
            "x": -2,
            "y": -1,
            "z": 7,
            "elements": [
                "unlimitedchiselworks:chisel_stonebrick_botania_livingrock_1@4"
            ]
        },
        {
            "x": -5,
            "y": 19,
            "z": 4,
            "elements": [
                "unlimitedchiselworks:chisel_stonebrick2_botania_livingrock_1@1"
            ]
        },
        {
            "x": 1,
            "y": 10,
            "z": -2,
            "elements": [
                "botania:elfglass@0"
            ]
        },
        {
            "x": 1,
            "y": 9,
            "z": 4,
            "elements": [
                "unlimitedchiselworks:chisel_stonebrick2_botania_livingrock_1@1"
            ]
        },
        {
            "x": 4,
            "y": 5,
            "z": -1,
            "elements": [
                "botania:elfglass@0"
            ]
        },
        {
            "x": 0,
            "y": 13,
            "z": -6,
            "elements": [
                "botania:elfglass@0"
            ]
        },
        {
            "x": -2,
            "y": 19,
            "z": -1,
            "elements": [
                "botania:elfglass@0"
            ]
        },
        {
            "x": 1,
            "y": 13,
            "z": 4,
            "elements": [
                "botania:elfglass@0"
            ]
        },
        {
            "x": -4,
            "y": 5,
            "z": 2,
            "elements": [
                "botania:elfglass@0"
            ]
        },
        {
            "x": -2,
            "y": 13,
            "z": 7,
            "elements": [
                "botania:elfglass@0"
            ]
        },
        {
            "x": 1,
            "y": 15,
            "z": 3,
            "elements": [
                "botania:elfglass@0"
            ]
        },
        {
            "x": -5,
            "y": 18,
            "z": 4,
            "elements": [
                "botania:elfglass@0"
            ]
        },
        {
            "x": -3,
            "y": 19,
            "z": -3,
            "elements": [
                "botania:elfglass@0"
            ]
        },
        {
            "x": -5,
            "y": 19,
            "z": 3,
            "elements": [
                "botania:elfglass@0"
            ]
        },
        {
            "x": -5,
            "y": 17,
            "z": 4,
            "elements": [
                "botania:elfglass@0"
            ]
        },
        {
            "x": -2,
            "y": -1,
            "z": -1,
            "elements": [
                "unlimitedchiselworks:chisel_stonebrick2_botania_livingrock_1@1"
            ]
        },
        {
            "x": -2,
            "y": 14,
            "z": 3,
            "elements": [
                "botania:elfglass@0"
            ]
        },
        {
            "x": 1,
            "y": 0,
            "z": 1,
            "elements": [
                "unlimitedchiselworks:chisel_stonebrick_botania_livingrock_1@4"
            ]
        },
        {
            "x": -1,
            "y": 0,
            "z": 8,
            "elements": [
                "unlimitedchiselworks:chisel_stonebrick2_botania_livingrock_1@1"
            ]
        },
        {
            "x": -5,
            "y": 12,
            "z": -2,
            "elements": [
                "botania:elfglass@0"
            ]
        },
        {
            "x": 0,
            "y": -1,
            "z": 2,
            "elements": [
                "generalized_input_item"
            ]
        },
        {
            "x": 2,
            "y": 5,
            "z": 7,
            "elements": [
                "unlimitedchiselworks:chisel_stonebrick2_botania_livingrock_1@1"
            ]
        },
        {
            "x": -7,
            "y": 9,
            "z": 2,
            "elements": [
                "botania:elfglass@0"
            ]
        },
        {
            "x": 1,
            "y": 14,
            "z": 4,
            "elements": [
                "botania:elfglass@0"
            ]
        },
        {
            "x": -8,
            "y": 10,
            "z": 1,
            "elements": [
                "unlimitedchiselworks:chisel_stonebrick2_botania_livingrock_1@1"
            ]
        },
        {
            "x": -5,
            "y": 15,
            "z": 4,
            "elements": [
                "botania:elfglass@0"
            ]
        },
        {
            "x": -5,
            "y": 8,
            "z": -2,
            "elements": [
                "botania:elfglass@0"
            ]
        },
        {
            "x": 4,
            "y": 19,
            "z": -1,
            "elements": [
                "botania:elfglass@0"
            ]
        },
        {
            "x": -2,
            "y": 11,
            "z": 7,
            "elements": [
                "botania:elfglass@0"
            ]
        },
        {
            "x": 0,
            "y": 19,
            "z": -3,
            "elements": [
                "botania:elfglass@0"
            ]
        },
        {
            "x": -3,
            "y": 5,
            "z": 2,
            "elements": [
                "botania:elfglass@0"
            ]
        },
        {
            "x": 1,
            "y": 11,
            "z": 4,
            "elements": [
                "botania:elfglass@0"
            ]
        },
        {
            "x": 2,
            "y": 18,
            "z": -5,
            "elements": [
                "botania:elfglass@0"
            ]
        },
        {
            "x": 2,
            "y": 19,
            "z": -5,
            "elements": [
                "unlimitedchiselworks:chisel_stonebrick2_botania_livingrock_1@1"
            ]
        },
        {
            "x": -2,
            "y": 12,
            "z": 3,
            "elements": [
                "botania:elfglass@0"
            ]
        },
        {
            "x": 0,
            "y": 0,
            "z": 9,
            "elements": [
                "unlimitedchiselworks:chisel_stonebrick_botania_livingrock_1@4"
            ]
        },
        {
            "x": -5,
            "y": -1,
            "z": -1,
            "elements": [
                "unlimitedchiselworks:chisel_planks_oak_botania_dreamwood_1@7"
            ]
        },
        {
            "x": -2,
            "y": 19,
            "z": 3,
            "elements": [
                "botania:elfglass@0"
            ]
        },
        {
            "x": 1,
            "y": 12,
            "z": 4,
            "elements": [
                "botania:elfglass@0"
            ]
        },
        {
            "x": -7,
            "y": 11,
            "z": 2,
            "elements": [
                "botania:elfglass@0"
            ]
        },
        {
            "x": -1,
            "y": -1,
            "z": 2,
            "elements": [
                "unlimitedchiselworks:chisel_stonebrick2_botania_livingrock_1@1"
            ]
        },
        {
            "x": -8,
            "y": 8,
            "z": 1,
            "elements": [
                "unlimitedchiselworks:chisel_stonebrick2_botania_livingrock_1@1"
            ]
        },
        {
            "x": -5,
            "y": 10,
            "z": -2,
            "elements": [
                "botania:elfglass@0"
            ]
        },
        {
            "x": -2,
            "y": 19,
            "z": 5,
            "elements": [
                "botania:elfglass@0"
            ]
        },
        {
            "x": -5,
            "y": 16,
            "z": 4,
            "elements": [
                "botania:elfglass@0"
            ]
        },
        {
            "x": -2,
            "y": 13,
            "z": 3,
            "elements": [
                "botania:elfglass@0"
            ]
        },
        {
            "x": -1,
            "y": -1,
            "z": 9,
            "elements": [
                "unlimitedchiselworks:chisel_stonebrick_botania_livingrock_1@4"
            ]
        },
        {
            "x": 1,
            "y": 19,
            "z": -1,
            "elements": [
                "botania:elfglass@0"
            ]
        },
        {
            "x": 7,
            "y": 6,
            "z": 1,
            "elements": [
                "unlimitedchiselworks:chisel_stonebrick2_botania_livingrock_1@1"
            ]
        },
        {
            "x": 4,
            "y": -1,
            "z": -1,
            "elements": [
                "unlimitedchiselworks:chisel_planks_oak_botania_dreamwood_1@7"
            ]
        },
        {
            "x": -5,
            "y": 13,
            "z": 4,
            "elements": [
                "botania:elfglass@0"
            ]
        },
        {
            "x": -2,
            "y": 5,
            "z": 2,
            "elements": [
                "botania:elfglass@0"
            ]
        },
        {
            "x": 2,
            "y": 9,
            "z": 7,
            "elements": [
                "botania:elfglass@0"
            ]
        },
        {
            "x": 4,
            "y": 19,
            "z": 5,
            "elements": [
                "unlimitedchiselworks:chisel_stonebrick2_botania_livingrock_1@1"
            ]
        },
        {
            "x": -5,
            "y": 14,
            "z": 1,
            "elements": [
                "botania:elfglass@0"
            ]
        },
        {
            "x": -5,
            "y": 12,
            "z": 4,
            "elements": [
                "botania:elfglass@0"
            ]
        },
        {
            "x": 0,
            "y": 16,
            "z": -7,
            "elements": [
                "unlimitedchiselworks:chisel_stonebrick2_botania_livingrock_1@1"
            ]
        },
        {
            "x": 2,
            "y": 16,
            "z": -5,
            "elements": [
                "botania:elfglass@0"
            ]
        },
        {
            "x": 2,
            "y": 17,
            "z": -5,
            "elements": [
                "botania:elfglass@0"
            ]
        },
        {
            "x": -2,
            "y": -1,
            "z": 2,
            "elements": [
                "unlimitedchiselworks:chisel_stonebrick2_botania_livingrock_1@1"
            ]
        },
        {
            "x": 4,
            "y": 5,
            "z": 3,
            "elements": [
                "botania:elfglass@0"
            ]
        },
        {
            "x": -5,
            "y": 14,
            "z": 4,
            "elements": [
                "botania:elfglass@0"
            ]
        },
        {
            "x": -2,
            "y": 15,
            "z": 7,
            "elements": [
                "botania:elfglass@0"
            ]
        },
        {
            "x": -8,
            "y": 6,
            "z": 1,
            "elements": [
                "unlimitedchiselworks:chisel_stonebrick2_botania_livingrock_1@1"
            ]
        },
        {
            "x": -2,
            "y": 19,
            "z": 4,
            "elements": [
                "botania:elfglass@0"
            ]
        },
        {
            "x": 0,
            "y": 13,
            "z": -3,
            "elements": [
                "unlimitedchiselworks:chisel_stonebrick2_botania_livingrock_1@1"
            ]
        },
        {
            "x": -5,
            "y": 11,
            "z": 4,
            "elements": [
                "botania:elfglass@0"
            ]
        },
        {
            "x": 0,
            "y": 14,
            "z": -3,
            "elements": [
                "unlimitedchiselworks:chisel_stonebrick2_botania_livingrock_1@1"
            ]
        },
        {
            "x": -5,
            "y": 5,
            "z": 2,
            "elements": [
                "botania:elfglass@0"
            ]
        },
        {
            "x": 6,
            "y": -1,
            "z": 3,
            "elements": [
                "unlimitedchiselworks:chisel_stonebrick_botania_livingrock_1@4"
            ]
        },
        {
            "x": 0,
            "y": 18,
            "z": -7,
            "elements": [
                "unlimitedchiselworks:chisel_stonebrick2_botania_livingrock_1@1"
            ]
        },
        {
            "x": -2,
            "y": 15,
            "z": 3,
            "elements": [
                "unlimitedchiselworks:chisel_stonebrick2_botania_livingrock_1@1"
            ]
        },
        {
            "x": -5,
            "y": 12,
            "z": 1,
            "elements": [
                "botania:elfglass@0"
            ]
        },
        {
            "x": 2,
            "y": 14,
            "z": -5,
            "elements": [
                "botania:elfglass@0"
            ]
        },
        {
            "x": 1,
            "y": 15,
            "z": 4,
            "elements": [
                "unlimitedchiselworks:chisel_stonebrick2_botania_livingrock_1@1"
            ]
        },
        {
            "x": 0,
            "y": 15,
            "z": -3,
            "elements": [
                "unlimitedchiselworks:chisel_stonebrick_botania_livingrock_1@4"
            ]
        },
        {
            "x": 1,
            "y": 9,
            "z": 3,
            "elements": [
                "botania:elfglass@0"
            ]
        },
        {
            "x": 1,
            "y": -1,
            "z": 2,
            "elements": [
                "unlimitedchiselworks:chisel_stonebrick2_botania_livingrock_1@1"
            ]
        },
        {
            "x": 2,
            "y": 7,
            "z": 7,
            "elements": [
                "botania:elfglass@0"
            ]
        },
        {
            "x": -2,
            "y": 17,
            "z": 7,
            "elements": [
                "botania:elfglass@0"
            ]
        },
        {
            "x": 2,
            "y": 15,
            "z": -5,
            "elements": [
                "botania:elfglass@0"
            ]
        },
        {
            "x": -5,
            "y": 6,
            "z": -2,
            "elements": [
                "botania:elfglass@0"
            ]
        },
        {
            "x": 5,
            "y": 5,
            "z": 0,
            "elements": [
                "botania:elfglass@0"
            ]
        },
        {
            "x": 3,
            "y": 13,
            "z": 2,
            "elements": [
                "botania:elfglass@0"
            ]
        },
        {
            "x": 2,
            "y": -1,
            "z": -1,
            "elements": [
                "unlimitedchiselworks:chisel_stonebrick2_botania_livingrock_1@1"
            ]
        },
        {
            "x": 1,
            "y": 14,
            "z": 8,
            "elements": [
                "botania:elfglass@0"
            ]
        },
        {
            "x": -7,
            "y": 14,
            "z": 1,
            "elements": [
                "botania:elfglass@0"
            ]
        },
        {
            "x": 0,
            "y": 2,
            "z": 1,
            "elements": [
                "unlimitedchiselworks:chisel_stonebrick2_botania_livingrock_1@1"
            ]
        },
        {
            "x": 3,
            "y": 0,
            "z": 6,
            "elements": [
                "unlimitedchiselworks:chisel_stonebrick2_botania_livingrock_1@1"
            ]
        },
        {
            "x": -1,
            "y": 12,
            "z": -2,
            "elements": [
                "botania:elfglass@0"
            ]
        },
        {
            "x": -8,
            "y": 16,
            "z": 1,
            "elements": [
                "unlimitedchiselworks:chisel_stonebrick2_botania_livingrock_1@1"
            ]
        },
        {
            "x": -1,
            "y": 5,
            "z": -1,
            "elements": [
                "botania:elfglass@0"
            ]
        },
        {
            "x": 0,
            "y": 12,
            "z": -7,
            "elements": [
                "unlimitedchiselworks:chisel_stonebrick2_botania_livingrock_1@1"
            ]
        },
        {
            "x": -2,
            "y": 5,
            "z": 7,
            "elements": [
                "unlimitedchiselworks:chisel_stonebrick2_botania_livingrock_1@1"
            ]
        },
        {
            "x": 4,
            "y": 19,
            "z": 4,
            "elements": [
                "botania:elfglass@0"
            ]
        },
        {
            "x": -7,
            "y": 8,
            "z": 1,
            "elements": [
                "botania:elfglass@0"
            ]
        },
        {
            "x": 1,
            "y": 13,
            "z": -6,
            "elements": [
                "botania:elfglass@0"
            ]
        },
        {
            "x": -1,
            "y": 15,
            "z": 0,
            "elements": [
                "botania:elfglass@0"
            ]
        },
        {
            "x": -6,
            "y": 7,
            "z": -1,
            "elements": [
                "botania:elfglass@0"
            ]
        },
        {
            "x": -7,
            "y": 12,
            "z": 1,
            "elements": [
                "botania:elfglass@0"
            ]
        },
        {
            "x": 0,
            "y": -1,
            "z": 7,
            "elements": [
                "unlimitedchiselworks:chisel_planks_oak_botania_dreamwood_1@7"
            ]
        },
        {
            "x": 4,
            "y": 6,
            "z": 5,
            "elements": [
                "botania:elfglass@0"
            ]
        },
        {
            "x": -4,
            "y": 10,
            "z": 1,
            "elements": [
                "unlimitedchiselworks:chisel_stonebrick2_botania_livingrock_1@1"
            ]
        },
        {
            "x": 1,
            "y": 11,
            "z": -6,
            "elements": [
                "botania:elfglass@0"
            ]
        },
        {
            "x": 3,
            "y": 15,
            "z": 2,
            "elements": [
                "unlimitedchiselworks:chisel_stonebrick2_botania_livingrock_1@1"
            ]
        },
        {
            "x": -1,
            "y": -1,
            "z": -6,
            "elements": [
                "unlimitedchiselworks:chisel_stonebrick_botania_livingrock_1@4"
            ]
        },
        {
            "x": 2,
            "y": 9,
            "z": 0,
            "elements": [
                "botania:elfglass@0"
            ]
        },
        {
            "x": 4,
            "y": 5,
            "z": 5,
            "elements": [
                "unlimitedchiselworks:chisel_stonebrick2_botania_livingrock_1@1"
            ]
        },
        {
            "x": 3,
            "y": -1,
            "z": 2,
            "elements": [
                "unlimitedchiselworks:chisel_planks_oak_botania_dreamwood_1@7"
            ]
        },
        {
            "x": 0,
            "y": 0,
            "z": 1,
            "elements": [
                "unlimitedchiselworks:chisel_stonebrick_botania_livingrock_1@4"
            ]
        },
        {
            "x": -1,
            "y": -1,
            "z": -1,
            "elements": [
                "unlimitedchiselworks:chisel_stonebrick2_botania_livingrock_1@1"
            ]
        },
        {
            "x": -1,
            "y": 10,
            "z": -2,
            "elements": [
                "botania:elfglass@0"
            ]
        },
        {
            "x": 0,
            "y": 19,
            "z": 2,
            "elements": [
                "botania:elfglass@0"
            ]
        },
        {
            "x": -8,
            "y": 18,
            "z": 1,
            "elements": [
                "unlimitedchiselworks:chisel_stonebrick2_botania_livingrock_1@1"
            ]
        },
        {
            "x": -6,
            "y": 5,
            "z": -1,
            "elements": [
                "unlimitedchiselworks:chisel_stonebrick2_botania_livingrock_1@1"
            ]
        },
        {
            "x": 0,
            "y": 14,
            "z": -7,
            "elements": [
                "unlimitedchiselworks:chisel_stonebrick2_botania_livingrock_1@1"
            ]
        },
        {
            "x": 1,
            "y": 16,
            "z": 8,
            "elements": [
                "botania:elfglass@0"
            ]
        },
        {
            "x": 1,
            "y": 19,
            "z": 4,
            "elements": [
                "botania:elfglass@0"
            ]
        },
        {
            "x": 0,
            "y": 19,
            "z": 9,
            "elements": [
                "unlimitedchiselworks:chisel_stonebrick_botania_livingrock_1@4"
            ]
        },
        {
            "x": -7,
            "y": 10,
            "z": 1,
            "elements": [
                "botania:elfglass@0"
            ]
        },
        {
            "x": -8,
            "y": 12,
            "z": 1,
            "elements": [
                "unlimitedchiselworks:chisel_stonebrick2_botania_livingrock_1@1"
            ]
        },
        {
            "x": 0,
            "y": -1,
            "z": -1,
            "elements": [
                "unlimitedchiselworks:chisel_stonebrick_botania_livingrock_1@4"
            ]
        },
        {
            "x": -1,
            "y": 0,
            "z": 1,
            "elements": [
                "unlimitedchiselworks:chisel_stonebrick_botania_livingrock_1@4"
            ]
        },
        {
            "x": -1,
            "y": 19,
            "z": 0,
            "elements": [
                "botania:elfglass@0"
            ]
        },
        {
            "x": 1,
            "y": 9,
            "z": -6,
            "elements": [
                "botania:elfglass@0"
            ]
        },
        {
            "x": 3,
            "y": -1,
            "z": 7,
            "elements": [
                "unlimitedchiselworks:chisel_stonebrick_botania_livingrock_1@4"
            ]
        },
        {
            "x": -6,
            "y": 11,
            "z": -1,
            "elements": [
                "botania:elfglass@0"
            ]
        },
        {
            "x": -2,
            "y": 9,
            "z": 7,
            "elements": [
                "botania:elfglass@0"
            ]
        },
        {
            "x": -3,
            "y": 5,
            "z": -1,
            "elements": [
                "botania:elfglass@0"
            ]
        },
        {
            "x": -6,
            "y": -1,
            "z": 2,
            "elements": [
                "unlimitedchiselworks:chisel_planks_oak_botania_dreamwood_1@7"
            ]
        },
        {
            "x": 1,
            "y": 10,
            "z": 8,
            "elements": [
                "botania:elfglass@0"
            ]
        },
        {
            "x": 5,
            "y": 0,
            "z": -2,
            "elements": [
                "unlimitedchiselworks:chisel_stonebrick2_botania_livingrock_1@1"
            ]
        },
        {
            "x": -5,
            "y": 8,
            "z": 1,
            "elements": [
                "unlimitedchiselworks:chisel_stonebrick2_botania_livingrock_1@1"
            ]
        },
        {
            "x": -3,
            "y": 6,
            "z": 6,
            "elements": [
                "botania:elfglass@0"
            ]
        },
        {
            "x": -6,
            "y": 10,
            "z": 1,
            "elements": [
                "botania:elfglass@0"
            ]
        },
        {
            "x": 3,
            "y": 19,
            "z": 2,
            "elements": [
                "botania:elfglass@0"
            ]
        },
        {
            "x": 1,
            "y": -1,
            "z": -1,
            "elements": [
                "unlimitedchiselworks:chisel_stonebrick2_botania_livingrock_1@1"
            ]
        },
        {
            "x": 0,
            "y": 17,
            "z": 9,
            "elements": [
                "unlimitedchiselworks:chisel_stonebrick2_botania_livingrock_1@1"
            ]
        },
        {
            "x": 0,
            "y": 8,
            "z": -7,
            "elements": [
                "unlimitedchiselworks:chisel_stonebrick2_botania_livingrock_1@1"
            ]
        },
        {
            "x": -4,
            "y": 19,
            "z": 0,
            "elements": [
                "botania:elfglass@0"
            ]
        },
        {
            "x": -8,
            "y": 14,
            "z": 1,
            "elements": [
                "unlimitedchiselworks:chisel_stonebrick2_botania_livingrock_1@1"
            ]
        },
        {
            "x": 1,
            "y": 7,
            "z": -6,
            "elements": [
                "botania:elfglass@0"
            ]
        },
        {
            "x": -3,
            "y": -1,
            "z": 2,
            "elements": [
                "unlimitedchiselworks:chisel_planks_oak_botania_dreamwood_1@7"
            ]
        },
        {
            "x": 1,
            "y": 12,
            "z": 8,
            "elements": [
                "botania:elfglass@0"
            ]
        },
        {
            "x": -4,
            "y": 5,
            "z": -1,
            "elements": [
                "botania:elfglass@0"
            ]
        },
        {
            "x": -2,
            "y": 7,
            "z": 7,
            "elements": [
                "botania:elfglass@0"
            ]
        },
        {
            "x": 1,
            "y": 5,
            "z": 7,
            "elements": [
                "botania:elfglass@0"
            ]
        },
        {
            "x": 2,
            "y": 15,
            "z": 0,
            "elements": [
                "botania:elfglass@0"
            ]
        },
        {
            "x": 0,
            "y": 18,
            "z": 9,
            "elements": [
                "unlimitedchiselworks:chisel_stonebrick2_botania_livingrock_1@1"
            ]
        },
        {
            "x": -6,
            "y": 9,
            "z": -1,
            "elements": [
                "botania:elfglass@0"
            ]
        },
        {
            "x": 0,
            "y": 10,
            "z": -7,
            "elements": [
                "unlimitedchiselworks:chisel_stonebrick2_botania_livingrock_1@1"
            ]
        },
        {
            "x": -6,
            "y": 8,
            "z": 1,
            "elements": [
                "botania:elfglass@0"
            ]
        },
        {
            "x": -5,
            "y": 10,
            "z": 1,
            "elements": [
                "botania:elfglass@0"
            ]
        },
        {
            "x": 0,
            "y": 6,
            "z": -7,
            "elements": [
                "unlimitedchiselworks:chisel_stonebrick2_botania_livingrock_1@1"
            ]
        },
        {
            "x": -3,
            "y": 8,
            "z": 6,
            "elements": [
                "botania:elfglass@0"
            ]
        },
        {
            "x": 6,
            "y": -1,
            "z": -1,
            "elements": [
                "unlimitedchiselworks:chisel_stonebrick_botania_livingrock_1@4"
            ]
        },
        {
            "x": 5,
            "y": 6,
            "z": -2,
            "elements": [
                "botania:elfglass@0"
            ]
        },
        {
            "x": 0,
            "y": 15,
            "z": 2,
            "elements": [
                "botania:elfglass@0"
            ]
        },
        {
            "x": 4,
            "y": 9,
            "z": 5,
            "elements": [
                "botania:elfglass@0"
            ]
        },
        {
            "x": 3,
            "y": 16,
            "z": -4,
            "elements": [
                "botania:elfglass@0"
            ]
        },
        {
            "x": 0,
            "y": -1,
            "z": -6,
            "elements": [
                "unlimitedchiselworks:chisel_planks_oak_botania_dreamwood_1@7"
            ]
        },
        {
            "x": -6,
            "y": 12,
            "z": 1,
            "elements": [
                "botania:elfglass@0"
            ]
        },
        {
            "x": -7,
            "y": 0,
            "z": 1,
            "elements": [
                "contenttweaker:vengeful_steel_molten"
            ]
        },
        {
            "x": -2,
            "y": -1,
            "z": -5,
            "elements": [
                "unlimitedchiselworks:chisel_stonebrick_botania_livingrock_1@4"
            ]
        },
        {
            "x": 0,
            "y": 7,
            "z": -6,
            "elements": [
                "botania:elfglass@0"
            ]
        },
        {
            "x": 8,
            "y": -1,
            "z": 2,
            "elements": [
                "unlimitedchiselworks:chisel_stonebrick_botania_livingrock_1@4"
            ]
        },
        {
            "x": 3,
            "y": 15,
            "z": -4,
            "elements": [
                "botania:elfglass@0"
            ]
        },
        {
            "x": 0,
            "y": 19,
            "z": -4,
            "elements": [
                "botania:elfglass@0"
            ]
        },
        {
            "x": -3,
            "y": -1,
            "z": 7,
            "elements": [
                "unlimitedchiselworks:chisel_stonebrick_botania_livingrock_1@4"
            ]
        },
        {
            "x": 0,
            "y": 15,
            "z": 9,
            "elements": [
                "unlimitedchiselworks:chisel_stonebrick2_botania_livingrock_1@1"
            ]
        },
        {
            "x": 1,
            "y": 9,
            "z": 2,
            "elements": [
                "botania:elfglass@0"
            ]
        },
        {
            "x": 4,
            "y": 10,
            "z": 5,
            "elements": [
                "botania:elfglass@0"
            ]
        },
        {
            "x": 0,
            "y": 16,
            "z": 9,
            "elements": [
                "unlimitedchiselworks:chisel_stonebrick2_botania_livingrock_1@1"
            ]
        },
        {
            "x": -3,
            "y": 19,
            "z": 2,
            "elements": [
                "botania:elfglass@0"
            ]
        },
        {
            "x": -5,
            "y": 5,
            "z": -1,
            "elements": [
                "botania:elfglass@0"
            ]
        },
        {
            "x": 3,
            "y": 5,
            "z": 2,
            "elements": [
                "botania:elfglass@0"
            ]
        },
        {
            "x": 0,
            "y": 9,
            "z": -6,
            "elements": [
                "botania:elfglass@0"
            ]
        },
        {
            "x": 2,
            "y": 19,
            "z": 0,
            "elements": [
                "botania:elfglass@0"
            ]
        },
        {
            "x": 3,
            "y": -1,
            "z": -1,
            "elements": [
                "unlimitedchiselworks:chisel_planks_oak_botania_dreamwood_1@7"
            ]
        },
        {
            "x": 1,
            "y": 14,
            "z": -2,
            "elements": [
                "botania:elfglass@0"
            ]
        },
        {
            "x": -6,
            "y": 14,
            "z": 1,
            "elements": [
                "botania:elfglass@0"
            ]
        },
        {
            "x": 0,
            "y": 13,
            "z": 9,
            "elements": [
                "unlimitedchiselworks:chisel_stonebrick2_botania_livingrock_1@1"
            ]
        },
        {
            "x": 3,
            "y": 13,
            "z": -4,
            "elements": [
                "botania:elfglass@0"
            ]
        },
        {
            "x": 4,
            "y": 7,
            "z": 5,
            "elements": [
                "botania:elfglass@0"
            ]
        },
        {
            "x": -2,
            "y": 5,
            "z": -1,
            "elements": [
                "botania:elfglass@0"
            ]
        },
        {
            "x": 4,
            "y": 8,
            "z": 5,
            "elements": [
                "botania:elfglass@0"
            ]
        },
        {
            "x": 4,
            "y": 5,
            "z": 2,
            "elements": [
                "botania:elfglass@0"
            ]
        },
        {
            "x": 3,
            "y": 19,
            "z": -3,
            "elements": [
                "botania:elfglass@0"
            ]
        },
        {
            "x": 0,
            "y": -1,
            "z": 5,
            "elements": [
                "unlimitedchiselworks:chisel_planks_oak_botania_dreamwood_1@7"
            ]
        },
        {
            "x": 0,
            "y": 14,
            "z": 9,
            "elements": [
                "unlimitedchiselworks:chisel_stonebrick2_botania_livingrock_1@1"
            ]
        },
        {
            "x": 3,
            "y": 14,
            "z": -4,
            "elements": [
                "botania:elfglass@0"
            ]
        },
        {
            "x": -4,
            "y": 19,
            "z": -1,
            "elements": [
                "botania:elfglass@0"
            ]
        },
        {
            "x": -1,
            "y": -1,
            "z": 7,
            "elements": [
                "unlimitedchiselworks:chisel_planks_oak_botania_dreamwood_1@7"
            ]
        },
        {
            "x": 0,
            "y": 0,
            "z": -7,
            "elements": [
                "unlimitedchiselworks:chisel_stonebrick_botania_livingrock_1@4"
            ]
        },
        {
            "x": 5,
            "y": 12,
            "z": -2,
            "elements": [
                "botania:elfglass@0"
            ]
        },
        {
            "x": -2,
            "y": 11,
            "z": -1,
            "elements": [
                "botania:elfglass@0"
            ]
        },
        {
            "x": 0,
            "y": 12,
            "z": 9,
            "elements": [
                "unlimitedchiselworks:chisel_stonebrick2_botania_livingrock_1@1"
            ]
        },
        {
            "x": -1,
            "y": 9,
            "z": -1,
            "elements": [
                "botania:elfglass@0"
            ]
        },
        {
            "x": -3,
            "y": 0,
            "z": 6,
            "elements": [
                "unlimitedchiselworks:chisel_stonebrick2_botania_livingrock_1@1"
            ]
        },
        {
            "x": 6,
            "y": -1,
            "z": 2,
            "elements": [
                "unlimitedchiselworks:chisel_planks_oak_botania_dreamwood_1@7"
            ]
        },
        {
            "x": 2,
            "y": -1,
