{
    "registryname": "mythical_resource_miner_tier25",
    "localizedname": "Immortallis Mythical Void Resource Miner",
	"color": "383836",
    "parts": [
        {
            "x": -2,
            "y": 0,
            "z": 2,
            "elements": [
                "environmentaltech:structure_frame_6@0"
            ]
        },
        {
            "x": -3,
            "y": 0,
            "z": 0,
            "elements": [
                "environmentaltech:structure_frame_6@0"
            ]
        },
        {
            "x": 3,
            "y": 0,
            "z": 0,
            "elements": [
                "environmentaltech:structure_frame_6@0"
            ]
        },
        {
            "x": -2,
            "y": 0,
            "z": -2,
            "elements": [
                "environmentaltech:structure_frame_6@0"
            ]
        },
        {
            "x": 2,
            "y": 0,
            "z": 2,
            "elements": [
                "environmentaltech:structure_frame_6@0"
            ]
        },
        {
            "x": 3,
            "y": -1,
            "z": 0,
            "elements": [
                "environmentaltech:structure_frame_6@0"
            ]
        },
        {
            "x": 2,
            "y": -1,
            "z": 0,
            "elements": [
                "contenttweaker:chaotic_bricks@0"
            ]
        },
        {
            "x": -3,
            "y": 1,
            "z": 0,
            "elements": [
                "contenttweaker:immortallis_cap@0"
            ]
        },
        {
            "x": 1,
            "y": -1,
            "z": 0,
            "elements": [
                "modularmachinery:blockfluidinputhatch@7"
            ]
        },
        {
            "x": 0,
            "y": -1,
            "z": 0,
            "elements": [
                "modularmachinery:blockenergyinputhatch@7"
            ]
        },
        {
            "x": 2,
            "y": -1,
            "z": -2,
            "elements": [
                "environmentaltech:structure_frame_6@0"
            ]
        },
        {
            "x": -3,
            "y": -1,
            "z": 1,
            "elements": [
                "environmentaltech:structure_frame_6@0"
            ]
        },
        {
            "x": -1,
            "y": -1,
            "z": 0,
            "elements": [
                "modularmachinery:blockfluidinputhatch@7"
            ]
        },
        {
            "x": 1,
            "y": -1,
            "z": -2,
            "elements": [
                "environmentaltech:structure_frame_6@0"
            ]
        },
        {
            "x": -2,
            "y": 1,
            "z": 2,
            "elements": [
                "contenttweaker:mythic_excavation_reactor@0"
            ]
        },
        {
            "x": -2,
            "y": -1,
            "z": 0,
            "elements": [
                "contenttweaker:chaotic_bricks@0"
            ]
        },
        {
            "x": -2,
            "y": -1,
            "z": 1,
            "elements": [
                "environmentaltech:structure_frame_6@0"
            ]
        },
        {
            "x": 0,
            "y": -1,
            "z": -2,
            "elements": [
                "contenttweaker:chaotic_bricks@0"
            ]
        },
        {
            "x": -3,
            "y": -1,
            "z": 0,
            "elements": [
                "environmentaltech:structure_frame_6@0"
            ]
        },
        {
            "x": -1,
            "y": -1,
            "z": 1,
            "elements": [
                "contenttweaker:chaotic_bricks@0"
            ]
        },
        {
            "x": -1,
            "y": -1,
            "z": -2,
            "elements": [
                "environmentaltech:structure_frame_6@0"
            ]
        },
        {
            "x": -2,
            "y": -1,
            "z": -2,
            "elements": [
                "environmentaltech:structure_frame_6@0"
            ]
        },
        {
            "x": 0,
            "y": -1,
            "z": 1,
            "elements": [
                "modularmachinery:blockoutputbus@6"
            ]
        },
        {
            "x": 3,
            "y": 1,
            "z": 0,
            "elements": [
                "contenttweaker:immortallis_cap@0"
            ]
        },
        {
            "x": -1,
            "y": -1,
            "z": 3,
            "elements": [
                "environmentaltech:structure_frame_6@0"
            ]
        },
        {
            "x": 1,
            "y": -1,
            "z": 1,
            "elements": [
                "contenttweaker:chaotic_bricks@0"
            ]
        },
        {
            "x": 0,
            "y": 1,
            "z": -3,
            "elements": [
                "contenttweaker:immortallis_cap@0"
            ]
        },
        {
            "x": 2,
            "y": 1,
            "z": 2,
            "elements": [
                "contenttweaker:mythic_excavation_reactor@0"
            ]
        },
        {
            "x": 0,
            "y": -1,
            "z": 3,
            "elements": [
                "environmentaltech:structure_frame_6@0"
            ]
        },
        {
            "x": 2,
            "y": -1,
            "z": 1,
            "elements": [
                "environmentaltech:structure_frame_6@0"
            ]
        },
        {
            "x": 3,
            "y": -1,
            "z": 1,
            "elements": [
                "environmentaltech:structure_frame_6@0"
            ]
        },
        {
            "x": 1,
            "y": -1,
            "z": 3,
            "elements": [
                "environmentaltech:structure_frame_6@0"
            ]
        },
        {
            "x": 0,
            "y": 0,
            "z": -3,
            "elements": [
                "environmentaltech:structure_frame_6@0"
            ]
        },
        {
            "x": 0,
            "y": 0,
            "z": 3,
            "elements": [
                "environmentaltech:structure_frame_6@0"
            ]
        },
        {
            "x": 3,
            "y": -1,
            "z": -1,
            "elements": [
                "environmentaltech:structure_frame_6@0"
            ]
        },
        {
            "x": 2,
            "y": -1,
            "z": -1,
            "elements": [
                "environmentaltech:structure_frame_6@0"
            ]
        },
        {
            "x": 1,
            "y": -1,
            "z": -1,
            "elements": [
                "contenttweaker:chaotic_bricks@0"
            ]
        },
        {
            "x": 0,
            "y": -1,
            "z": -1,
            "elements": [
                "modularmachinery:blockoutputbus@6"
            ]
        },
        {
            "x": -1,
            "y": -1,
            "z": -1,
            "elements": [
                "contenttweaker:chaotic_bricks@0"
            ]
        },
        {
            "x": 1,
            "y": -1,
            "z": -3,
            "elements": [
                "environmentaltech:structure_frame_6@0"
            ]
        },
        {
            "x": 2,
            "y": 1,
            "z": -2,
            "elements": [
                "contenttweaker:mythic_excavation_reactor@0"
            ]
        },
        {
            "x": -2,
            "y": -1,
            "z": -1,
            "elements": [
                "environmentaltech:structure_frame_6@0"
            ]
        },
        {
            "x": -2,
            "y": -1,
            "z": 2,
            "elements": [
                "environmentaltech:structure_frame_6@0"
            ]
        },
        {
            "x": 0,
            "y": -1,
            "z": -3,
            "elements": [
                "environmentaltech:structure_frame_6@0"
            ]
        },
        {
            "x": -3,
            "y": -1,
            "z": -1,
            "elements": [
                "environmentaltech:structure_frame_6@0"
            ]
        },
        {
            "x": -1,
            "y": -1,
            "z": 2,
            "elements": [
                "environmentaltech:structure_frame_6@0"
            ]
        },
        {
            "x": -1,
            "y": -1,
            "z": -3,
            "elements": [
                "environmentaltech:structure_frame_6@0"
            ]
        },
        {
            "x": 0,
            "y": 1,
            "z": 3,
            "elements": [
                "contenttweaker:immortallis_cap@0"
            ]
        },
        {
            "x": 0,
            "y": -1,
            "z": 2,
            "elements": [
                "contenttweaker:chaotic_bricks@0"
            ]
        },
        {
            "x": 1,
            "y": -1,
            "z": 2,
            "elements": [
                "environmentaltech:structure_frame_6@0"
            ]
        },
        {
            "x": -2,
            "y": 1,
            "z": -2,
            "elements": [
                "contenttweaker:mythic_excavation_reactor@0"
            ]
        },
        {
            "x": 2,
            "y": -1,
            "z": 2,
            "elements": [
                "environmentaltech:structure_frame_6@0"
            ]
        },
        {
            "x": 2,
            "y": 0,
            "z": -2,
            "elements": [
                "environmentaltech:structure_frame_6@0"
            ]
        }
    ]}