{
    "registryname": "mythical_resource_miner_tier8",
    "localizedname": "赫尔维蒂神话虚空资源采掘机",
	"color": "383836",
    "parts": [
        {
            "x": -2,
            "y": 0,
            "z": 2,
            "elements": [
                "environmentaltech:structure_frame_4@0"
            ]
        },
        {
            "x": -3,
            "y": 0,
            "z": 0,
            "elements": [
                "environmentaltech:structure_frame_4@0"
            ]
        },
        {
            "x": 3,
            "y": 0,
            "z": 0,
            "elements": [
                "environmentaltech:structure_frame_4@0"
            ]
        },
        {
            "x": -2,
            "y": 0,
            "z": -2,
            "elements": [
                "environmentaltech:structure_frame_4@0"
            ]
        },
        {
            "x": 2,
            "y": 0,
            "z": 2,
            "elements": [
                "environmentaltech:structure_frame_4@0"
            ]
        },
        {
            "x": 3,
            "y": -1,
            "z": 0,
            "elements": [
                "environmentaltech:structure_frame_4@0"
            ]
        },
        {
            "x": -3,
            "y": 1,
            "z": 0,
            "elements": [
                "aoa3:lelyetia_bricks@0"
            ]
        },
        {
            "x": 2,
            "y": -1,
            "z": 0,
            "elements": [
                "botania:quartztypesunny@0"
            ]
        },
        {
            "x": 1,
            "y": -1,
            "z": 0,
            "elements": [
                "generalized_input_fluid"
            ]
        },
        {
            "x": 0,
            "y": -1,
            "z": 0,
            "elements": [
                "modularmachinery:blockenergyinputhatch"
            ]
        },
        {
            "x": 2,
            "y": -1,
            "z": -2,
            "elements": [
                "environmentaltech:structure_frame_4@0"
            ]
        },
        {
            "x": -2,
            "y": 1,
            "z": 2,
            "elements": [
                "contenttweaker:lelyetian_cap@0"
            ]
        },
        {
            "x": -3,
            "y": -1,
            "z": 1,
            "elements": [
                "environmentaltech:structure_frame_4@0"
            ]
        },
        {
            "x": -1,
            "y": -1,
            "z": 0,
            "elements": [
                "generalized_input_fluid"
            ]
        },
        {
            "x": 1,
            "y": -1,
            "z": -2,
            "elements": [
                "environmentaltech:structure_frame_4@0"
            ]
        },
        {
            "x": -2,
            "y": -1,
            "z": 1,
            "elements": [
                "environmentaltech:structure_frame_4@0"
            ]
        },
        {
            "x": -2,
            "y": -1,
            "z": 0,
            "elements": [
                "botania:quartztypesunny@0"
            ]
        },
        {
            "x": 0,
            "y": -1,
            "z": -2,
            "elements": [
                "botania:quartztypesunny@0"
            ]
        },
        {
            "x": -1,
            "y": -1,
            "z": -2,
            "elements": [
                "environmentaltech:structure_frame_4@0"
            ]
        },
        {
            "x": -3,
            "y": -1,
            "z": 0,
            "elements": [
                "environmentaltech:structure_frame_4@0"
            ]
        },
        {
            "x": -1,
            "y": -1,
            "z": 1,
            "elements": [
                "botania:quartztypesunny@0"
            ]
        },
        {
            "x": 3,
            "y": 1,
            "z": 0,
            "elements": [
                "aoa3:lelyetia_bricks@0"
            ]
        },
        {
            "x": -2,
            "y": -1,
            "z": -2,
            "elements": [
                "environmentaltech:structure_frame_4@0"
            ]
        },
        {
            "x": 0,
            "y": -1,
            "z": 1,
            "elements": [
                "generalized_output_item"
            ]
        },
        {
            "x": 0,
            "y": 1,
            "z": -3,
            "elements": [
                "aoa3:lelyetia_bricks@0"
            ]
        },
        {
            "x": 2,
            "y": 1,
            "z": 2,
            "elements": [
                "contenttweaker:lelyetian_cap@0"
            ]
        },
        {
            "x": -1,
            "y": -1,
            "z": 3,
            "elements": [
                "environmentaltech:structure_frame_4@0"
            ]
        },
        {
            "x": 1,
            "y": -1,
            "z": 1,
            "elements": [
                "botania:quartztypesunny@0"
            ]
        },
        {
            "x": 0,
            "y": -1,
            "z": 3,
            "elements": [
                "environmentaltech:structure_frame_4@0"
            ]
        },
        {
            "x": 2,
            "y": -1,
            "z": 1,
            "elements": [
                "environmentaltech:structure_frame_4@0"
            ]
        },
        {
            "x": 1,
            "y": -1,
            "z": 3,
            "elements": [
                "environmentaltech:structure_frame_4@0"
            ]
        },
        {
            "x": 3,
            "y": -1,
            "z": 1,
            "elements": [
                "environmentaltech:structure_frame_4@0"
            ]
        },
        {
            "x": 0,
            "y": 0,
            "z": -3,
            "elements": [
                "environmentaltech:structure_frame_4@0"
            ]
        },
        {
            "x": 0,
            "y": 0,
            "z": 3,
            "elements": [
                "environmentaltech:structure_frame_4@0"
            ]
        },
        {
            "x": 3,
            "y": -1,
            "z": -1,
            "elements": [
                "environmentaltech:structure_frame_4@0"
            ]
        },
        {
            "x": 2,
            "y": -1,
            "z": -1,
            "elements": [
                "environmentaltech:structure_frame_4@0"
            ]
        },
        {
            "x": 1,
            "y": -1,
            "z": -1,
            "elements": [
                "botania:quartztypesunny@0"
            ]
        },
        {
            "x": 0,
            "y": -1,
            "z": -1,
            "elements": [
                "generalized_output_item"
            ]
        },
        {
            "x": 2,
            "y": 1,
            "z": -2,
            "elements": [
                "contenttweaker:lelyetian_cap@0"
            ]
        },
        {
            "x": -1,
            "y": -1,
            "z": -1,
            "elements": [
                "botania:quartztypesunny@0"
            ]
        },
        {
            "x": 1,
            "y": -1,
            "z": -3,
            "elements": [
                "environmentaltech:structure_frame_4@0"
            ]
        },
        {
            "x": -2,
            "y": -1,
            "z": 2,
            "elements": [
                "environmentaltech:structure_frame_4@0"
            ]
        },
        {
            "x": -2,
            "y": -1,
            "z": -1,
            "elements": [
                "environmentaltech:structure_frame_4@0"
            ]
        },
        {
            "x": 0,
            "y": -1,
            "z": -3,
            "elements": [
                "environmentaltech:structure_frame_4@0"
            ]
        },
        {
            "x": 0,
            "y": 1,
            "z": 3,
            "elements": [
                "aoa3:lelyetia_bricks@0"
            ]
        },
        {
            "x": -3,
            "y": -1,
            "z": -1,
            "elements": [
                "environmentaltech:structure_frame_4@0"
            ]
        },
        {
            "x": -1,
            "y": -1,
            "z": -3,
            "elements": [
                "environmentaltech:structure_frame_4@0"
            ]
        },
        {
            "x": -1,
            "y": -1,
            "z": 2,
            "elements": [
                "environmentaltech:structure_frame_4@0"
            ]
        },
        {
            "x": 0,
            "y": -1,
            "z": 2,
            "elements": [
                "botania:quartztypesunny@0"
            ]
        },
        {
            "x": -2,
            "y": 1,
            "z": -2,
            "elements": [
                "contenttweaker:lelyetian_cap@0"
            ]
        },
        {
            "x": 1,
            "y": -1,
            "z": 2,
            "elements": [
                "environmentaltech:structure_frame_4@0"
            ]
        },
        {
            "x": 2,
            "y": -1,
            "z": 2,
            "elements": [
                "environmentaltech:structure_frame_4@0"
            ]
        },
        {
            "x": 2,
            "y": 0,
            "z": -2,
            "elements": [
                "environmentaltech:structure_frame_4@0"
            ]
        }
    ]}